Workbook

Sheet 梅 横長
C2: 漢字氏名 | D2: かな氏名
B3: 1
B4: 2
B5: 3
B6: 4
B7: 5
B8: 6
B9: 7
B10: 8
B11: 9
B12: 10
B13: 11
B14: 12
... B37: 35

Sheet 名前カード
A1: =IF('梅 横長'!D3="","",'梅 横長'!D3) | B1: =IF('梅 横長'!D4="","",'梅 横長'!D4) | C1: =IF('梅 横長'!D5="","",'梅 横長'!D5)
A2: =IF('梅 横長'!C3="","",'梅 横長'!C3) | B2: =IF('梅 横長'!C4="","",'梅 横長'!C4) | C2: =IF('梅 横長'!C5="","",'梅 横長'!C5)
A3: =IF('梅 横長'!D6="","",'梅 横長'!D6) | B3: =IF('梅 横長'!D7="","",'梅 横長'!D7) | C3: =IF('梅 横長'!D8="","",'梅 横長'!D8)
A4: =IF('梅 横長'!C6="","",'梅 横長'!C6) | B4: =IF('梅 横長'!C7="","",'梅 横長'!C7) | C4: =IF('梅 横長'!C8="","",'梅 横長'!C8)
A5: =IF('梅 横長'!D9="","",'梅 横長'!D9) | B5: =IF('梅 横長'!D10="","",'梅 横長'!D10) | C5: =IF('梅 横長'!D11="","",'梅 横長'!D11)
A6: =IF('梅 横長'!C9="","",'梅 横長'!C9) | B6: =IF('梅 横長'!C10="","",'梅 横長'!C10) | C6: =IF('梅 横長'!C11="","",'梅 横長'!C11)
A7: =IF('梅 横長'!D12="","",'梅 横長'!D12) | B7: =IF('梅 横長'!D13="","",'梅 横長'!D13) | C7: =IF('梅 横長'!D14="","",'梅 横長'!D14)
A8: =IF('梅 横長'!C12="","",'梅 横長'!C12) | B8: =IF('梅 横長'!C13="","",'梅 横長'!C13) | C8: =IF('梅 横長'!C14="","",'梅 横長'!C14)
A9: =IF('梅 横長'!D15="","",'梅 横長'!D15) | B9: =IF('梅 横長'!D16="","",'梅 横長'!D16) | C9: =IF('梅 横長'!D17="","",'梅 横長'!D17)
A10: =IF('梅 横長'!C15="","",'梅 横長'!C15) | B10: =IF('梅 横長'!C16="","",'梅 横長'!C16) | C10: =IF('梅 横長'!C17="","",'梅 横長'!C17)
A11: =IF('梅 横長'!D18="","",'梅 横長'!D18) | B11: =IF('梅 横長'!D19="","",'梅 横長'!D19) | C11: =IF('梅 横長'!D20="","",'梅 横長'!D20)
A12: =IF('梅 横長'!C18="","",'梅 横長'!C18) | B12: =IF('梅 横長'!C19="","",'梅 横長'!C19) | C12: =IF('梅 横長'!C20="","",'梅 横長'!C20)
A13: =IF('梅 横長'!D21="","",'梅 横長'!D21) | B13: =IF('梅 横長'!D22="","",'梅 横長'!D22) | C13: =IF('梅 横長'!D23="","",'梅 横長'!D23)
A14: =IF('梅 横長'!C21="","",'梅 横長'!C21) | B14: =IF('梅 横長'!C22="","",'梅 横長'!C22) | C14: =IF('梅 横長'!C23="","",'梅 横長'!C23)
A15: =IF('梅 横長'!D24="","",'梅 横長'!D24) | B15: =IF('梅 横長'!D25="","",'梅 横長'!D25) | C15: =IF('梅 横長'!D26="","",'梅 横長'!D26)
A16: =IF('梅 横長'!C24="","",'梅 横長'!C24) | B16: =IF('梅 横長'!C25="","",'梅 横長'!C25) | C16: =IF('梅 横長'!C26="","",'梅 横長'!C26)
A17: =IF('梅 横長'!D27="","",'梅 横長'!D27) | B17: =IF('梅 横長'!D28="","",'梅 横長'!D28) | C17: =IF('梅 横長'!D29="","",'梅 横長'!D29)
A18: =IF('梅 横長'!C27="","",'梅 横長'!C27) | B18: =IF('梅 横長'!C28="","",'梅 横長'!C28) | C18: =IF('梅 横長'!C29="","",'梅 横長'!C29)
A19: =IF('梅 横長'!D30="","",'梅 横長'!D30) | B19: =IF('梅 横長'!D31="","",'梅 横長'!D31) | C19: =IF('梅 横長'!D32="","",'梅 横長'!D32)
A20: =IF('梅 横長'!C30="","",'梅 横長'!C30) | B20: =IF('梅 横長'!C31="","",'梅 横長'!C31) | C20: =IF('梅 横長'!C32="","",'梅 横長'!C32)
A21: =IF('梅 横長'!D33="","",'梅 横長'!D33) | B21: =IF('梅 横長'!D34="","",'梅 横長'!D34) | C21: =IF('梅 横長'!D35="","",'梅 横長'!D35)
A22: =IF('梅 横長'!C33="","",'梅 横長'!C33) | B22: =IF('梅 横長'!C34="","",'梅 横長'!C34) | C22: =IF('梅 横長'!C35="","",'梅 横長'!C35)
A23: =IF('梅 横長'!D36="","",'梅 横長'!D36) | B23: =IF('梅 横長'!D37="","",'梅 横長'!D37)
A24: =IF('梅 横長'!C36="","",'梅 横長'!C36) | B24: =IF('梅 横長'!C37="","",'梅 横長'!C37)

Sheet 名前カード (松組)
A1: =IF('梅 横長'!D3="","",'梅 横長'!D3) | B1: =IF('梅 横長'!D4="","",'梅 横長'!D4) | C1: =IF('梅 横長'!D5="","",'梅 横長'!D5)
A2: =IF('梅 横長'!C3="","",'梅 横長'!C3) | B2: =IF('梅 横長'!C4="","",'梅 横長'!C4) | C2: =IF('梅 横長'!C5="","",'梅 横長'!C5)
A3: =IF('梅 横長'!D6="","",'梅 横長'!D6) | B3: =IF('梅 横長'!D7="","",'梅 横長'!D7) | C3: =IF('梅 横長'!D8="","",'梅 横長'!D8)
A4: =IF('梅 横長'!C6="","",'梅 横長'!C6) | B4: =IF('梅 横長'!C7="","",'梅 横長'!C7) | C4: =IF('梅 横長'!C8="","",'梅 横長'!C8)
A5: =IF('梅 横長'!D9="","",'梅 横長'!D9) | B5: =IF('梅 横長'!D10="","",'梅 横長'!D10) | C5: =IF('梅 横長'!D11="","",'梅 横長'!D11)
A6: =IF('梅 横長'!C9="","",'梅 横長'!C9) | B6: =IF('梅 横長'!C10="","",'梅 横長'!C10) | C6: =IF('梅 横長'!C11="","",'梅 横長'!C11)
A7: =IF('梅 横長'!D12="","",'梅 横長'!D12) | B7: =IF('梅 横長'!D13="","",'梅 横長'!D13) | C7: =IF('梅 横長'!D14="","",'梅 横長'!D14)
A8: =IF('梅 横長'!C12="","",'梅 横長'!C12) | B8: =IF('梅 横長'!C13="","",'梅 横長'!C13) | C8: =IF('梅 横長'!C14="","",'梅 横長'!C14)
A9: =IF('梅 横長'!D15="","",'梅 横長'!D15) | B9: =IF('梅 横長'!D16="","",'梅 横長'!D16) | C9: =IF('梅 横長'!D17="","",'梅 横長'!D17)
A10: =IF('梅 横長'!C15="","",'梅 横長'!C15) | B10: =IF('梅 横長'!C16="","",'梅 横長'!C16) | C10: =IF('梅 横長'!C17="","",'梅 横長'!C17)
A11: =IF('梅 横長'!D18="","",'梅 横長'!D18) | B11: =IF('梅 横長'!D19="","",'梅 横長'!D19) | C11: =IF('梅 横長'!D20="","",'梅 横長'!D20)
A12: =IF('梅 横長'!C18="","",'梅 横長'!C18) | B12: =IF('梅 横長'!C19="","",'梅 横長'!C19) | C12: =IF('梅 横長'!C20="","",'梅 横長'!C20)
A13: =IF('梅 横長'!D21="","",'梅 横長'!D21) | B13: =IF('梅 横長'!D22="","",'梅 横長'!D22) | C13: =IF('梅 横長'!D23="","",'梅 横長'!D23)
A14: =IF('梅 横長'!C21="","",'梅 横長'!C21) | B14: =IF('梅 横長'!C22="","",'梅 横長'!C22) | C14: =IF('梅 横長'!C23="","",'梅 横長'!C23)
A15: =IF('梅 横長'!D24="","",'梅 横長'!D24) | B15: =IF('梅 横長'!D25="","",'梅 横長'!D25) | C15: =IF('梅 横長'!D26="","",'梅 横長'!D26)
A16: =IF('梅 横長'!C24="","",'梅 横長'!C24) | B16: =IF('梅 横長'!C25="","",'梅 横長'!C25) | C16: =IF('梅 横長'!C26="","",'梅 横長'!C26)
A17: =IF('梅 横長'!D27="","",'梅 横長'!D27) | B17: =IF('梅 横長'!D28="","",'梅 横長'!D28) | C17: =IF('梅 横長'!D29="","",'梅 横長'!D29)
A18: =IF('梅 横長'!C27="","",'梅 横長'!C27) | B18: =IF('梅 横長'!C28="","",'梅 横長'!C28) | C18: =IF('梅 横長'!C29="","",'梅 横長'!C29)
A19: =IF('梅 横長'!D30="","",'梅 横長'!D30) | B19: =IF('梅 横長'!D31="","",'梅 横長'!D31) | C19: =IF('梅 横長'!D32="","",'梅 横長'!D32)
A20: =IF('梅 横長'!C30="","",'梅 横長'!C30) | B20: =IF('梅 横長'!C31="","",'梅 横長'!C31) | C20: =IF('梅 横長'!C32="","",'梅 横長'!C32)
A21: =IF('梅 横長'!D33="","",'梅 横長'!D33) | B21: =IF('梅 横長'!D34="","",'梅 横長'!D34) | C21: =IF('梅 横長'!D35="","",'梅 横長'!D35)
A22: =IF('梅 横長'!C33="","",'梅 横長'!C33) | B22: =IF('梅 横長'!C34="","",'梅 横長'!C34) | C22: =IF('梅 横長'!C35="","",'梅 横長'!C35)
A23: =IF('梅 横長'!D36="","",'梅 横長'!D36) | B23: =IF('梅 横長'!D37="","",'梅 横長'!D37)
A24: =IF('梅 横長'!C36="","",'梅 横長'!C36) | B24: =IF('梅 横長'!C37="","",'梅 横長'!C37)

Sheet 名前カード (竹組)
A1: =IF('梅 横長'!D3="","",'梅 横長'!D3) | B1: =IF('梅 横長'!D4="","",'梅 横長'!D4) | C1: =IF('梅 横長'!D5="","",'梅 横長'!D5)
A2: =IF('梅 横長'!C3="","",'梅 横長'!C3) | B2: =IF('梅 横長'!C4="","",'梅 横長'!C4) | C2: =IF('梅 横長'!C5="","",'梅 横長'!C5)
A3: =IF('梅 横長'!D6="","",'梅 横長'!D6) | B3: =IF('梅 横長'!D7="","",'梅 横長'!D7) | C3: =IF('梅 横長'!D8="","",'梅 横長'!D8)
A4: =IF('梅 横長'!C6="","",'梅 横長'!C6) | B4: =IF('梅 横長'!C7="","",'梅 横長'!C7) | C4: =IF('梅 横長'!C8="","",'梅 横長'!C8)
A5: =IF('梅 横長'!D9="","",'梅 横長'!D9) | B5: =IF('梅 横長'!D10="","",'梅 横長'!D10) | C5: =IF('梅 横長'!D11="","",'梅 横長'!D11)
A6: =IF('梅 横長'!C9="","",'梅 横長'!C9) | B6: =IF('梅 横長'!C10="","",'梅 横長'!C10) | C6: =IF('梅 横長'!C11="","",'梅 横長'!C11)
A7: =IF('梅 横長'!D12="","",'梅 横長'!D12) | B7: =IF('梅 横長'!D13="","",'梅 横長'!D13) | C7: =IF('梅 横長'!D14="","",'梅 横長'!D14)
A8: =IF('梅 横長'!C12="","",'梅 横長'!C12) | B8: =IF('梅 横長'!C13="","",'梅 横長'!C13) | C8: =IF('梅 横長'!C14="","",'梅 横長'!C14)
A9: =IF('梅 横長'!D15="","",'梅 横長'!D15) | B9: =IF('梅 横長'!D16="","",'梅 横長'!D16) | C9: =IF('梅 横長'!D17="","",'梅 横長'!D17)
A10: =IF('梅 横長'!C15="","",'梅 横長'!C15) | B10: =IF('梅 横長'!C16="","",'梅 横長'!C16) | C10: =IF('梅 横長'!C17="","",'梅 横長'!C17)
A11: =IF('梅 横長'!D18="","",'梅 横長'!D18) | B11: =IF('梅 横長'!D19="","",'梅 横長'!D19) | C11: =IF('梅 横長'!D20="","",'梅 横長'!D20)
A12: =IF('梅 横長'!C18="","",'梅 横長'!C18) | B12: =IF('梅 横長'!C19="","",'梅 横長'!C19) | C12: =IF('梅 横長'!C20="","",'梅 横長'!C20)
A13: =IF('梅 横長'!D21="","",'梅 横長'!D21) | B13: =IF('梅 横長'!D22="","",'梅 横長'!D22) | C13: =IF('梅 横長'!D23="","",'梅 横長'!D23)
A14: =IF('梅 横長'!C21="","",'梅 横長'!C21) | B14: =IF('梅 横長'!C22="","",'梅 横長'!C22) | C14: =IF('梅 横長'!C23="","",'梅 横長'!C23)
A15: =IF('梅 横長'!D24="","",'梅 横長'!D24) | B15: =IF('梅 横長'!D25="","",'梅 横長'!D25) | C15: =IF('梅 横長'!D26="","",'梅 横長'!D26)
A16: =IF('梅 横長'!C24="","",'梅 横長'!C24) | B16: =IF('梅 横長'!C25="","",'梅 横長'!C25) | C16: =IF('梅 横長'!C26="","",'梅 横長'!C26)
A17: =IF('梅 横長'!D27="","",'梅 横長'!D27) | B17: =IF('梅 横長'!D28="","",'梅 横長'!D28) | C17: =IF('梅 横長'!D29="","",'梅 横長'!D29)
A18: =IF('梅 横長'!C27="","",'梅 横長'!C27) | B18: =IF('梅 横長'!C28="","",'梅 横長'!C28) | C18: =IF('梅 横長'!C29="","",'梅 横長'!C29)
A19: =IF('梅 横長'!D30="","",'梅 横長'!D30) | B19: =IF('梅 横長'!D31="","",'梅 横長'!D31) | C19: =IF('梅 横長'!D32="","",'梅 横長'!D32)
A20: =IF('梅 横長'!C30="","",'梅 横長'!C30) | B20: =IF('梅 横長'!C31="","",'梅 横長'!C31) | C20: =IF('梅 横長'!C32="","",'梅 横長'!C32)
A21: =IF('梅 横長'!D33="","",'梅 横長'!D33) | B21: =IF('梅 横長'!D34="","",'梅 横長'!D34) | C21: =IF('梅 横長'!D35="","",'梅 横長'!D35)
A22: =IF('梅 横長'!C33="","",'梅 横長'!C33) | B22: =IF('梅 横長'!C34="","",'梅 横長'!C34) | C22: =IF('梅 横長'!C35="","",'梅 横長'!C35)
A23: =IF('梅 横長'!D36="","",'梅 横長'!D36) | B23: =IF('梅 横長'!D37="","",'梅 横長'!D37)
A24: =IF('梅 横長'!C36="","",'梅 横長'!C36) | B24: =IF('梅 横長'!C37="","",'梅 横長'!C37)

Sheet 名前カード (梅組)
A1: =IF('梅 横長'!D3="","",'梅 横長'!D3) | B1: =IF('梅 横長'!D4="","",'梅 横長'!D4) | C1: =IF('梅 横長'!D5="","",'梅 横長'!D5)
A2: =IF('梅 横長'!C3="","",'梅 横長'!C3) | B2: =IF('梅 横長'!C4="","",'梅 横長'!C4) | C2: =IF('梅 横長'!C5="","",'梅 横長'!C5)
A3: =IF('梅 横長'!D6="","",'梅 横長'!D6) | B3: =IF('梅 横長'!D7="","",'梅 横長'!D7) | C3: =IF('梅 横長'!D8="","",'梅 横長'!D8)
A4: =IF('梅 横長'!C6="","",'梅 横長'!C6) | B4: =IF('梅 横長'!C7="","",'梅 横長'!C7) | C4: =IF('梅 横長'!C8="","",'梅 横長'!C8)
A5: =IF('梅 横長'!D9="","",'梅 横長'!D9) | B5: =IF('梅 横長'!D10="","",'梅 横長'!D10) | C5: =IF('梅 横長'!D11="","",'梅 横長'!D11)
A6: =IF('梅 横長'!C9="","",'梅 横長'!C9) | B6: =IF('梅 横長'!C10="","",'梅 横長'!C10) | C6: =IF('梅 横長'!C11="","",'梅 横長'!C11)
A7: =IF('梅 横長'!D12="","",'梅 横長'!D12) | B7: =IF('梅 横長'!D13="","",'梅 横長'!D13) | C7: =IF('梅 横長'!D14="","",'梅 横長'!D14)
A8: =IF('梅 横長'!C12="","",'梅 横長'!C12) | B8: =IF('梅 横長'!C13="","",'梅 横長'!C13) | C8: =IF('梅 横長'!C14="","",'梅 横長'!C14)
A9: =IF('梅 横長'!D15="","",'梅 横長'!D15) | B9: =IF('梅 横長'!D16="","",'梅 横長'!D16) | C9: =IF('梅 横長'!D17="","",'梅 横長'!D17)
A10: =IF('梅 横長'!C15="","",'梅 横長'!C15) | B10: =IF('梅 横長'!C16="","",'梅 横長'!C16) | C10: =IF('梅 横長'!C17="","",'梅 横長'!C17)
A11: =IF('梅 横長'!D18="","",'梅 横長'!D18) | B11: =IF('梅 横長'!D19="","",'梅 横長'!D19) | C11: =IF('梅 横長'!D20="","",'梅 横長'!D20)
A12: =IF('梅 横長'!C18="","",'梅 横長'!C18) | B12: =IF('梅 横長'!C19="","",'梅 横長'!C19) | C12: =IF('梅 横長'!C20="","",'梅 横長'!C20)
A13: =IF('梅 横長'!D21="","",'梅 横長'!D21) | B13: =IF('梅 横長'!D22="","",'梅 横長'!D22) | C13: =IF('梅 横長'!D23="","",'梅 横長'!D23)
A14: =IF('梅 横長'!C21="","",'梅 横長'!C21) | B14: =IF('梅 横長'!C22="","",'梅 横長'!C22) | C14: =IF('梅 横長'!C23="","",'梅 横長'!C23)
A15: =IF('梅 横長'!D24="","",'梅 横長'!D24) | B15: =IF('梅 横長'!D25="","",'梅 横長'!D25) | C15: =IF('梅 横長'!D26="","",'梅 横長'!D26)
A16: =IF('梅 横長'!C24="","",'梅 横長'!C24) | B16: =IF('梅 横長'!C25="","",'梅 横長'!C25) | C16: =IF('梅 横長'!C26="","",'梅 横長'!C26)
A17: =IF('梅 横長'!D27="","",'梅 横長'!D27) | B17: =IF('梅 横長'!D28="","",'梅 横長'!D28) | C17: =IF('梅 横長'!D29="","",'梅 横長'!D29)
A18: =IF('梅 横長'!C27="","",'梅 横長'!C27) | B18: =IF('梅 横長'!C28="","",'梅 横長'!C28) | C18: =IF('梅 横長'!C29="","",'梅 横長'!C29)
A19: =IF('梅 横長'!D30="","",'梅 横長'!D30) | B19: =IF('梅 横長'!D31="","",'梅 横長'!D31) | C19: =IF('梅 横長'!D32="","",'梅 横長'!D32)
A20: =IF('梅 横長'!C30="","",'梅 横長'!C30) | B20: =IF('梅 横長'!C31="","",'梅 横長'!C31) | C20: =IF('梅 横長'!C32="","",'梅 横長'!C32)
A21: =IF('梅 横長'!D33="","",'梅 横長'!D33) | B21: =IF('梅 横長'!D34="","",'梅 横長'!D34) | C21: =IF('梅 横長'!D35="","",'梅 横長'!D35)
A22: =IF('梅 横長'!C33="","",'梅 横長'!C33) | B22: =IF('梅 横長'!C34="","",'梅 横長'!C34) | C22: =IF('梅 横長'!C35="","",'梅 横長'!C35)
A23: =IF('梅 横長'!D36="","",'梅 横長'!D36) | B23: =IF('梅 横長'!D37="","",'梅 横長'!D37)
A24: =IF('梅 横長'!C36="","",'梅 横長'!C36) | B24: =IF('梅 横長'!C37="","",'梅 横長'!C37)

Sheet 名前カード (月組)
A1: =IF('梅 横長'!D3="","",'梅 横長'!D3) | B1: =IF('梅 横長'!D4="","",'梅 横長'!D4) | C1: =IF('梅 横長'!D5="","",'梅 横長'!D5)
A2: =IF('梅 横長'!C3="","",'梅 横長'!C3) | B2: =IF('梅 横長'!C4="","",'梅 横長'!C4) | C2: =IF('梅 横長'!C5="","",'梅 横長'!C5)
A3: =IF('梅 横長'!D6="","",'梅 横長'!D6) | B3: =IF('梅 横長'!D7="","",'梅 横長'!D7) | C3: =IF('梅 横長'!D8="","",'梅 横長'!D8)
A4: =IF('梅 横長'!C6="","",'梅 横長'!C6) | B4: =IF('梅 横長'!C7="","",'梅 横長'!C7) | C4: =IF('梅 横長'!C8="","",'梅 横長'!C8)
A5: =IF('梅 横長'!D9="","",'梅 横長'!D9) | B5: =IF('梅 横長'!D10="","",'梅 横長'!D10) | C5: =IF('梅 横長'!D11="","",'梅 横長'!D11)
A6: =IF('梅 横長'!C9="","",'梅 横長'!C9) | B6: =IF('梅 横長'!C10="","",'梅 横長'!C10) | C6: =IF('梅 横長'!C11="","",'梅 横長'!C11)
A7: =IF('梅 横長'!D12="","",'梅 横長'!D12) | B7: =IF('梅 横長'!D13="","",'梅 横長'!D13) | C7: =IF('梅 横長'!D14="","",'梅 横長'!D14)
A8: =IF('梅 横長'!C12="","",'梅 横長'!C12) | B8: =IF('梅 横長'!C13="","",'梅 横長'!C13) | C8: =IF('梅 横長'!C14="","",'梅 横長'!C14)
A9: =IF('梅 横長'!D15="","",'梅 横長'!D15) | B9: =IF('梅 横長'!D16="","",'梅 横長'!D16) | C9: =IF('梅 横長'!D17="","",'梅 横長'!D17)
A10: =IF('梅 横長'!C15="","",'梅 横長'!C15) | B10: =IF('梅 横長'!C16="","",'梅 横長'!C16) | C10: =IF('梅 横長'!C17="","",'梅 横長'!C17)
A11: =IF('梅 横長'!D18="","",'梅 横長'!D18) | B11: =IF('梅 横長'!D19="","",'梅 横長'!D19) | C11: =IF('梅 横長'!D20="","",'梅 横長'!D20)
A12: =IF('梅 横長'!C18="","",'梅 横長'!C18) | B12: =IF('梅 横長'!C19="","",'梅 横長'!C19) | C12: =IF('梅 横長'!C20="","",'梅 横長'!C20)
A13: =IF('梅 横長'!D21="","",'梅 横長'!D21) | B13: =IF('梅 横長'!D22="","",'梅 横長'!D22) | C13: =IF('梅 横長'!D23="","",'梅 横長'!D23)
A14: =IF('梅 横長'!C21="","",'梅 横長'!C21) | B14: =IF('梅 横長'!C22="","",'梅 横長'!C22) | C14: =IF('梅 横長'!C23="","",'梅 横長'!C23)
A15: =IF('梅 横長'!D24="","",'梅 横長'!D24) | B15: =IF('梅 横長'!D25="","",'梅 横長'!D25) | C15: =IF('梅 横長'!D26="","",'梅 横長'!D26)
A16: =IF('梅 横長'!C24="","",'梅 横長'!C24) | B16: =IF('梅 横長'!C25="","",'梅 横長'!C25) | C16: =IF('梅 横長'!C26="","",'梅 横長'!C26)
A17: =IF('梅 横長'!D27="","",'梅 横長'!D27) | B17: =IF('梅 横長'!D28="","",'梅 横長'!D28) | C17: =IF('梅 横長'!D29="","",'梅 横長'!D29)
A18: =IF('梅 横長'!C27="","",'梅 横長'!C27) | B18: =IF('梅 横長'!C28="","",'梅 横長'!C28) | C18: =IF('梅 横長'!C29="","",'梅 横長'!C29)
A19: =IF('梅 横長'!D30="","",'梅 横長'!D30) | B19: =IF('梅 横長'!D31="","",'梅 横長'!D31) | C19: =IF('梅 横長'!D32="","",'梅 横長'!D32)
A20: =IF('梅 横長'!C30="","",'梅 横長'!C30) | B20: =IF('梅 横長'!C31="","",'梅 横長'!C31) | C20: =IF('梅 横長'!C32="","",'梅 横長'!C32)
A21: =IF('梅 横長'!D33="","",'梅 横長'!D33) | B21: =IF('梅 横長'!D34="","",'梅 横長'!D34) | C21: =IF('梅 横長'!D35="","",'梅 横長'!D35)
A22: =IF('梅 横長'!C33="","",'梅 横長'!C33) | B22: =IF('梅 横長'!C34="","",'梅 横長'!C34) | C22: =IF('梅 横長'!C35="","",'梅 横長'!C35)
A23: =IF('梅 横長'!D36="","",'梅 横長'!D36) | B23: =IF('梅 横長'!D37="","",'梅 横長'!D37)
A24: =IF('梅 横長'!C36="","",'梅 横長'!C36) | B24: =IF('梅 横長'!C37="","",'梅 横長'!C37)

Sheet 名前カード (ひらがな)
A1: =IF('梅 横長'!D3="","", '梅 横長'!D3) | B1: =IF('梅 横長'!D4="","", '梅 横長'!D4) | C1: =IF('梅 横長'!D5="","", '梅 横長'!D5)
A2: =IF('梅 横長'!D6="","", '梅 横長'!D6) | B2: =IF('梅 横長'!D7="","", '梅 横長'!D7) | C2: =IF('梅 横長'!D8="","", '梅 横長'!D8)
A3: =IF('梅 横長'!D9="","", '梅 横長'!D9) | B3: =IF('梅 横長'!D10="","", '梅 横長'!D10) | C3: =IF('梅 横長'!D11="","", '梅 横長'!D11)
A4: =IF('梅 横長'!D12="","", '梅 横長'!D12) | B4: =IF('梅 横長'!D13="","", '梅 横長'!D13) | C4: =IF('梅 横長'!D14="","", '梅 横長'!D14)
A5: =IF('梅 横長'!D15="","", '梅 横長'!D15) | B5: =IF('梅 横長'!D16="","", '梅 横長'!D16) | C5: =IF('梅 横長'!D17="","", '梅 横長'!D17)
A6: =IF('梅 横長'!D18="","", '梅 横長'!D18) | B6: =IF('梅 横長'!D19="","", '梅 横長'!D19) | C6: =IF('梅 横長'!D20="","", '梅 横長'!D20)
A7: =IF('梅 横長'!D21="","", '梅 横長'!D21) | B7: =IF('梅 横長'!D22="","", '梅 横長'!D22) | C7: =IF('梅 横長'!D23="","", '梅 横長'!D23)
A8: =IF('梅 横長'!D24="","", '梅 横長'!D24) | B8: =IF('梅 横長'!D25="","", '梅 横長'!D25) | C8: =IF('梅 横長'!D26="","", '梅 横長'!D26)
A9: =IF('梅 横長'!D27="","", '梅 横長'!D27) | B9: =IF('梅 横長'!D28="","", '梅 横長'!D28) | C9: =IF('梅 横長'!D29="","", '梅 横長'!D29)
A10: =IF('梅 横長'!D30="","", '梅 横長'!D30) | B10: =IF('梅 横長'!D31="","", '梅 横長'!D31) | C10: =IF('梅 横長'!D32="","", '梅 横長'!D32)
A11: =IF('梅 横長'!D33="","", '梅 横長'!D33) | B11: =IF('梅 横長'!D34="","", '梅 横長'!D34) | C11: =IF('梅 横長'!D35="","", '梅 横長'!D35)
A12: =IF('梅 横長'!D36="","", '梅 横長'!D36) | B12: =IF('梅 横長'!D37="","", '梅 横長'!D37)

Sheet 名前カード (特大)
A1: =IF('梅 横長'!D3="","",'梅 横長'!D3)
A2: =IF('梅 横長'!C3="","",'梅 横長'!C3)
A3: =IF('梅 横長'!D4="","",'梅 横長'!D4)
A4: =IF('梅 横長'!C4="","",'梅 横長'!C4)
A5: =IF('梅 横長'!D5="","",'梅 横長'!D5)
A6: =IF('梅 横長'!C5="","",'梅 横長'!C5)
A7: =IF('梅 横長'!D6="","",'梅 横長'!D6)
A8: =IF('梅 横長'!C6="","",'梅 横長'!C6)
A9: =IF('梅 横長'!D7="","",'梅 横長'!D7)
A10: =IF('梅 横長'!C7="","",'梅 横長'!C7)
A11: =IF('梅 横長'!D8="","",'梅 横長'!D8)
A12: =IF('梅 横長'!C8="","",'梅 横長'!C8)
A13: =IF('梅 横長'!D9="","",'梅 横長'!D9)
A14: =IF('梅 横長'!C9="","",'梅 横長'!C9)
A15: =IF('梅 横長'!D10="","",'梅 横長'!D10)
A16: =IF('梅 横長'!C10="","",'梅 横長'!C10)
A17: =IF('梅 横長'!D11="","",'梅 横長'!D11)
A18: =IF('梅 横長'!C11="","",'梅 横長'!C11)
A19: =IF('梅 横長'!D12="","",'梅 横長'!D12)
A20: =IF('梅 横長'!C12="","",'梅 横長'!C12)
A21: =IF('梅 横長'!D13="","",'梅 横長'!D13)
A22: =IF('梅 横長'!C13="","",'梅 横長'!C13)
A23: =IF('梅 横長'!D14="","",'梅 横長'!D14)
A24: =IF('梅 横長'!C14="","",'梅 横長'!C14)
A25: =IF('梅 横長'!D15="","",'梅 横長'!D15)
A26: =IF('梅 横長'!C15="","",'梅 横長'!C15)
A27: =IF('梅 横長'!D16="","",'梅 横長'!D16)
A28: =IF('梅 横長'!C16="","",'梅 横長'!C16)
A29: =IF('梅 横長'!D17="","",'梅 横長'!D17)
A30: =IF('梅 横長'!C17="","",'梅 横長'!C17)
A31: =IF('梅 横長'!D18="","",'梅 横長'!D18)
A32: =IF('梅 横長'!C18="","",'梅 横長'!C18)
A33: =IF('梅 横長'!D19="","",'梅 横長'!D19)
A34: =IF('梅 横長'!C19="","",'梅 横長'!C19)
A35: =IF('梅 横長'!D20="","",'梅 横長'!D20)
A36: =IF('梅 横長'!C20="","",'梅 横長'!C20)
A37: =IF('梅 横長'!D21="","",'梅 横長'!D21)
A38: =IF('梅 横長'!C21="","",'梅 横長'!C21)
A39: =IF('梅 横長'!D22="","",'梅 横長'!D22)
A40: =IF('梅 横長'!C22="","",'梅 横長'!C22)
...

Sheet 名前カード (大)
A1: =IF('梅 横長'!D3="","",'梅 横長'!D3) | B1: =IF('梅 横長'!D4="","",'梅 横長'!D4)
A2: =IF('梅 横長'!C3="","",'梅 横長'!C3) | B2: =IF('梅 横長'!C4="","",'梅 横長'!C4)
A3: =IF('梅 横長'!D5="","",'梅 横長'!D5) | B3: =IF('梅 横長'!D6="","",'梅 横長'!D6)
A4: =IF('梅 横長'!C5="","",'梅 横長'!C5) | B4: =IF('梅 横長'!C6="","",'梅 横長'!C6)
A5: =IF('梅 横長'!D7="","",'梅 横長'!D7) | B5: =IF('梅 横長'!D8="","",'梅 横長'!D8)
A6: =IF('梅 横長'!C7="","",'梅 横長'!C7) | B6: =IF('梅 横長'!C8="","",'梅 横長'!C8)
A7: =IF('梅 横長'!D9="","",'梅 横長'!D9) | B7: =IF('梅 横長'!D10="","",'梅 横長'!D10)
A8: =IF('梅 横長'!C9="","",'梅 横長'!C9) | B8: =IF('梅 横長'!C10="","",'梅 横長'!C10)
A9: =IF('梅 横長'!D11="","",'梅 横長'!D11) | B9: =IF('梅 横長'!D12="","",'梅 横長'!D12)
A10: =IF('梅 横長'!C11="","",'梅 横長'!C11) | B10: =IF('梅 横長'!C12="","",'梅 横長'!C12)
A11: =IF('梅 横長'!D13="","",'梅 横長'!D13) | B11: =IF('梅 横長'!D14="","",'梅 横長'!D14)
A12: =IF('梅 横長'!C13="","",'梅 横長'!C13) | B12: =IF('梅 横長'!C14="","",'梅 横長'!C14)
A13: =IF('梅 横長'!D15="","",'梅 横長'!D15) | B13: =IF('梅 横長'!D16="","",'梅 横長'!D16)
A14: =IF('梅 横長'!C15="","",'梅 横長'!C15) | B14: =IF('梅 横長'!C16="","",'梅 横長'!C16)
A15: =IF('梅 横長'!D17="","",'梅 横長'!D17) | B15: =IF('梅 横長'!D18="","",'梅 横長'!D18)
A16: =IF('梅 横長'!C17="","",'梅 横長'!C17) | B16: =IF('梅 横長'!C18="","",'梅 横長'!C18)
A17: =IF('梅 横長'!D19="","",'梅 横長'!D19) | B17: =IF('梅 横長'!D20="","",'梅 横長'!D20)
A18: =IF('梅 横長'!C19="","",'梅 横長'!C19) | B18: =IF('梅 横長'!C20="","",'梅 横長'!C20)
A19: =IF('梅 横長'!D21="","",'梅 横長'!D21) | B19: =IF('梅 横長'!D22="","",'梅 横長'!D22)
A20: =IF('梅 横長'!C21="","",'梅 横長'!C21) | B20: =IF('梅 横長'!C22="","",'梅 横長'!C22)
A21: =IF('梅 横長'!D23="","",'梅 横長'!D23) | B21: =IF('梅 横長'!D24="","",'梅 横長'!D24)
A22: =IF('梅 横長'!C23="","",'梅 横長'!C23) | B22: =IF('梅 横長'!C24="","",'梅 横長'!C24)
A23: =IF('梅 横長'!D25="","",'梅 横長'!D25) | B23: =IF('梅 横長'!D26="","",'梅 横長'!D26)
A24: =IF('梅 横長'!C25="","",'梅 横長'!C25) | B24: =IF('梅 横長'!C26="","",'梅 横長'!C26)
A25: =IF('梅 横長'!D27="","",'梅 横長'!D27) | B25: =IF('梅 横長'!D28="","",'梅 横長'!D28)
A26: =IF('梅 横長'!C27="","",'梅 横長'!C27) | B26: =IF('梅 横長'!C28="","",'梅 横長'!C28)
A27: =IF('梅 横長'!D29="","",'梅 横長'!D29) | B27: =IF('梅 横長'!D30="","",'梅 横長'!D30)
A28: =IF('梅 横長'!C29="","",'梅 横長'!C29) | B28: =IF('梅 横長'!C30="","",'梅 横長'!C30)
A29: =IF('梅 横長'!D31="","",'梅 横長'!D31) | B29: =IF('梅 横長'!D32="","",'梅 横長'!D32)
A30: =IF('梅 横長'!C31="","",'梅 横長'!C31) | B30: =IF('梅 横長'!C32="","",'梅 横長'!C32)
A31: =IF('梅 横長'!D33="","",'梅 横長'!D33) | B31: =IF('梅 横長'!D34="","",'梅 横長'!D34)
A32: =IF('梅 横長'!C33="","",'梅 横長'!C33) | B32: =IF('梅 横長'!C34="","",'梅 横長'!C34)
A33: =IF('梅 横長'!D35="","",'梅 横長'!D35) | B33: =IF('梅 横長'!D36="","",'梅 横長'!D36)
A34: =IF('梅 横長'!C35="","",'梅 横長'!C35) | B34: =IF('梅 横長'!C36="","",'梅 横長'!C36)
A35: =IF('梅 横長'!D37="","",'梅 横長'!D37)
A36: =IF('梅 横長'!C37="","",'梅 横長'!C37)

Sheet 名前カード (小)
A1: =IF('梅 横長'!D3="","",'梅 横長'!D3) | B1: =IF('梅 横長'!D4="","",'梅 横長'!D4) | C1: =IF('梅 横長'!D5="","",'梅 横長'!D5) | D1: =IF('梅 横長'!D6="","",'梅 横長'!D6)
A2: =IF('梅 横長'!C3="","",'梅 横長'!C3) | B2: =IF('梅 横長'!C4="","",'梅 横長'!C4) | C2: =IF('梅 横長'!C5="","",'梅 横長'!C5) | D2: =IF('梅 横長'!C6="","",'梅 横長'!C6)
A3: =IF('梅 横長'!D7="","",'梅 横長'!D7) | B3: =IF('梅 横長'!D8="","",'梅 横長'!D8) | C3: =IF('梅 横長'!D9="","",'梅 横長'!D9) | D3: =IF('梅 横長'!D10="","",'梅 横長'!D10)
A4: =IF('梅 横長'!C7="","",'梅 横長'!C7) | B4: =IF('梅 横長'!C8="","",'梅 横長'!C8) | C4: =IF('梅 横長'!C9="","",'梅 横長'!C9) | D4: =IF('梅 横長'!C10="","",'梅 横長'!C10)
A5: =IF('梅 横長'!D11="","",'梅 横長'!D11) | B5: =IF('梅 横長'!D12="","",'梅 横長'!D12) | C5: =IF('梅 横長'!D13="","",'梅 横長'!D13) | D5: =IF('梅 横長'!D14="","",'梅 横長'!D14)
A6: =IF('梅 横長'!C11="","",'梅 横長'!C11) | B6: =IF('梅 横長'!C12="","",'梅 横長'!C12) | C6: =IF('梅 横長'!C13="","",'梅 横長'!C13) | D6: =IF('梅 横長'!C14="","",'梅 横長'!C14)
A7: =IF('梅 横長'!D15="","",'梅 横長'!D15) | B7: =IF('梅 横長'!D16="","",'梅 横長'!D16) | C7: =IF('梅 横長'!D17="","",'梅 横長'!D17) | D7: =IF('梅 横長'!D18="","",'梅 横長'!D18)
A8: =IF('梅 横長'!C15="","",'梅 横長'!C15) | B8: =IF('梅 横長'!C16="","",'梅 横長'!C16) | C8: =IF('梅 横長'!C17="","",'梅 横長'!C17) | D8: =IF('梅 横長'!C18="","",'梅 横長'!C18)
A9: =IF('梅 横長'!D19="","",'梅 横長'!D19) | B9: =IF('梅 横長'!D20="","",'梅 横長'!D20) | C9: =IF('梅 横長'!D21="","",'梅 横長'!D21) | D9: =IF('梅 横長'!D22="","",'梅 横長'!D22)
A10: =IF('梅 横長'!C19="","",'梅 横長'!C19) | B10: =IF('梅 横長'!C20="","",'梅 横長'!C20) | C10: =IF('梅 横長'!C21="","",'梅 横長'!C21) | D10: =IF('梅 横長'!C22="","",'梅 横長'!C22)
A11: =IF('梅 横長'!D23="","",'梅 横長'!D23) | B11: =IF('梅 横長'!D24="","",'梅 横長'!D24) | C11: =IF('梅 横長'!D25="","",'梅 横長'!D25) | D11: =IF('梅 横長'!D26="","",'梅 横長'!D26)
A12: =IF('梅 横長'!C23="","",'梅 横長'!C23) | B12: =IF('梅 横長'!C24="","",'梅 横長'!C24) | C12: =IF('梅 横長'!C25="","",'梅 横長'!C25) | D12: =IF('梅 横長'!C26="","",'梅 横長'!C26)
A13: =IF('梅 横長'!D27="","",'梅 横長'!D27) | B13: =IF('梅 横長'!D28="","",'梅 横長'!D28) | C13: =IF('梅 横長'!D29="","",'梅 横長'!D29) | D13: =IF('梅 横長'!D30="","",'梅 横長'!D30)
A14: =IF('梅 横長'!C27="","",'梅 横長'!C27) | B14: =IF('梅 横長'!C28="","",'梅 横長'!C28) | C14: =IF('梅 横長'!C29="","",'梅 横長'!C29) | D14: =IF('梅 横長'!C30="","",'梅 横長'!C30)
A15: =IF('梅 横長'!D31="","",'梅 横長'!D31) | B15: =IF('梅 横長'!D32="","",'梅 横長'!D32) | C15: =IF('梅 横長'!D33="","",'梅 横長'!D33) | D15: =IF('梅 横長'!D34="","",'梅 横長'!D34)
A16: =IF('梅 横長'!C31="","",'梅 横長'!C31) | B16: =IF('梅 横長'!C32="","",'梅 横長'!C32) | C16: =IF('梅 横長'!C33="","",'梅 横長'!C33) | D16: =IF('梅 横長'!C34="","",'梅 横長'!C34)
A17: =IF('梅 横長'!D35="","",'梅 横長'!D35) | B17: =IF('梅 横長'!D36="","",'梅 横長'!D36) | C17: =IF('梅 横長'!D37="","",'梅 横長'!D37)
A18: =IF('梅 横長'!C35="","",'梅 横長'!C35) | B18: =IF('梅 横長'!C36="","",'梅 横長'!C36) | C18: =IF('梅 横長'!C37="","",'梅 横長'!C37)

Sheet 名前カード (縦書き)
A1: =IF('梅 横長'!C3="","",'梅 横長'!C3) | B1: =IF('梅 横長'!D3="","",'梅 横長'!D3) | C1: =IF('梅 横長'!C4="","",'梅 横長'!C4) | D1: =IF('梅 横長'!D4="","",'梅 横長'!D4) | E1: =IF('梅 横長'!C5="","",'梅 横長'!C5) | F1: =IF('梅 横長'!D5="","",'梅 横長'!D5) | G1: =IF('梅 横長'!C6="","",'梅 横長'!C6) | H1: =IF('梅 横長'!D6="","",'梅 横長'!D6) | I1: =IF('梅 横長'!C7="","",'梅 横長'!C7) | J1: =IF('梅 横長'!D7="","",'梅 横長'!D7) | K1: =IF('梅 横長'!C8="","",'梅 横長'!C8) | L1: =IF('梅 横長'!D8="","",'梅 横長'!D8) | M1: =IF('梅 横長'!C9="","",'梅 横長'!C9) | N1: =IF('梅 横長'!D9="","",'梅 横長'!D9) | O1: =IF('梅 横長'!C10="","",'梅 横長'!C10) | P1: =IF('梅 横長'!D10="","",'梅 横長'!D10) | Q1: =IF('梅 横長'!C11="","",'梅 横長'!C11) | R1: =IF('梅 横長'!D11="","",'梅 横長'!D11) | S1: =IF('梅 横長'!C12="","",'梅 横長'!C12) | T1: =IF('梅 横長'!D12="","",'梅 横長'!D12) | U1: =IF('梅 横長'!C13="","",'梅 横長'!C13) | V1: =IF('梅 横長'!D13="","",'梅 横長'!D13) | W1: =IF('梅 横長'!C14="","",'梅 横長'!C14) | X1: =IF('梅 横長'!D14="","",'梅 横長'!D14)
A2: =IF('梅 横長'!C15="","",'梅 横長'!C15) | B2: =IF('梅 横長'!D15="","",'梅 横長'!D15) | C2: =IF('梅 横長'!C16="","",'梅 横長'!C16) | D2: =IF('梅 横長'!D16="","",'梅 横長'!D16) | E2: =IF('梅 横長'!C17="","",'梅 横長'!C17) | F2: =IF('梅 横長'!D17="","",'梅 横長'!D17) | G2: =IF('梅 横長'!C18="","",'梅 横長'!C18) | H2: =IF('梅 横長'!D18="","",'梅 横長'!D18) | I2: =IF('梅 横長'!C19="","",'梅 横長'!C19) | J2: =IF('梅 横長'!D19="","",'梅 横長'!D19) | K2: =IF('梅 横長'!C20="","",'梅 横長'!C20) | L2: =IF('梅 横長'!D20="","",'梅 横長'!D20) | M2: =IF('梅 横長'!C21="","",'梅 横長'!C21) | N2: =IF('梅 横長'!D21="","",'梅 横長'!D21) | O2: =IF('梅 横長'!C22="","",'梅 横長'!C22) | P2: =IF('梅 横長'!D22="","",'梅 横長'!D22) | Q2: =IF('梅 横長'!C23="","",'梅 横長'!C23) | R2: =IF('梅 横長'!D23="","",'梅 横長'!D23) | S2: =IF('梅 横長'!C24="","",'梅 横長'!C24) | T2: =IF('梅 横長'!D24="","",'梅 横長'!D24) | U2: =IF('梅 横長'!C25="","",'梅 横長'!C25) | V2: =IF('梅 横長'!D25="","",'梅 横長'!D25) | W2: =IF('梅 横長'!C26="","",'梅 横長'!C26) | X2: =IF('梅 横長'!D26="","",'梅 横長'!D26)
A3: =IF('梅 横長'!C27="","",'梅 横長'!C27) | B3: =IF('梅 横長'!D27="","",'梅 横長'!D27) | C3: =IF('梅 横長'!C28="","",'梅 横長'!C28) | D3: =IF('梅 横長'!D28="","",'梅 横長'!D28) | E3: =IF('梅 横長'!C29="","",'梅 横長'!C29) | F3: =IF('梅 横長'!D29="","",'梅 横長'!D29) | G3: =IF('梅 横長'!C30="","",'梅 横長'!C30) | H3: =IF('梅 横長'!D30="","",'梅 横長'!D30) | I3: =IF('梅 横長'!C31="","",'梅 横長'!C31) | J3: =IF('梅 横長'!D31="","",'梅 横長'!D31) | K3: =IF('梅 横長'!C32="","",'梅 横長'!C32) | L3: =IF('梅 横長'!D32="","",'梅 横長'!D32) | M3: =IF('梅 横長'!C33="","",'梅 横長'!C33) | N3: =IF('梅 横長'!D33="","",'梅 横長'!D33) | O3: =IF('梅 横長'!C34="","",'梅 横長'!C34) | P3: =IF('梅 横長'!D34="","",'梅 横長'!D34) | Q3: =IF('梅 横長'!C35="","",'梅 横長'!C35) | R3: =IF('梅 横長'!D35="","",'梅 横長'!D35) | S3: =IF('梅 横長'!C36="","",'梅 横長'!C36) | T3: =IF('梅 横長'!D36="","",'梅 横長'!D36) | U3: =IF('梅 横長'!C37="","",'梅 横長'!C37) | V3: =IF('梅 横長'!D37="","",'梅 横長'!D37)

Sheet 座席表
G1: 黒板 | S1: 【入力用】出席番号を入力（↑黒板側）
T2: 列1 | U2: 列2 | V2: 列3 | W2: 列4 | X2: 列5 | Y2: 列6
T3: 列1 | U3: 列2 | V3: 列3 | W3: 列4 | X3: 列5 | Y3: 列6
A4: =IF(T4="","",IFERROR(VLOOKUP(T4,'梅 横長'!$B$3:$D$37,3,FALSE()),"")) | D4: =IF(U4="","",IFERROR(VLOOKUP(U4,'梅 横長'!$B$3:$D$37,3,FALSE()),"")) | G4: =IF(V4="","",IFERROR(VLOOKUP(V4,'梅 横長'!$B$3:$D$37,3,FALSE()),"")) | J4: =IF(W4="","",IFERROR(VLOOKUP(W4,'梅 横長'!$B$3:$D$37,3,FALSE()),"")) | M4: =IF(X4="","",IFERROR(VLOOKUP(X4,'梅 横長'!$B$3:$D$37,3,FALSE()),"")) | P4: =IF(Y4="","",IFERROR(VLOOKUP(Y4,'梅 横長'!$B$3:$D$37,3,FALSE()),"")) | S4: 1列目
A5: =IF(T4="","",IFERROR(VLOOKUP(T4,'梅 横長'!$B$3:$D$37,2,FALSE()),"")) | D5: =IF(U4="","",IFERROR(VLOOKUP(U4,'梅 横長'!$B$3:$D$37,2,FALSE()),"")) | G5: =IF(V4="","",IFERROR(VLOOKUP(V4,'梅 横長'!$B$3:$D$37,2,FALSE()),"")) | J5: =IF(W4="","",IFERROR(VLOOKUP(W4,'梅 横長'!$B$3:$D$37,2,FALSE()),"")) | M5: =IF(X4="","",IFERROR(VLOOKUP(X4,'梅 横長'!$B$3:$D$37,2,FALSE()),"")) | P5: =IF(Y4="","",IFERROR(VLOOKUP(Y4,'梅 横長'!$B$3:$D$37,2,FALSE()),"")) | S5: 2列目
S6: 3列目
S7: 4列目
A8: =IF(T5="","",IFERROR(VLOOKUP(T5,'梅 横長'!$B$3:$D$37,3,FALSE()),"")) | D8: =IF(U5="","",IFERROR(VLOOKUP(U5,'梅 横長'!$B$3:$D$37,3,FALSE()),"")) | G8: =IF(V5="","",IFERROR(VLOOKUP(V5,'梅 横長'!$B$3:$D$37,3,FALSE()),"")) | J8: =IF(W5="","",IFERROR(VLOOKUP(W5,'梅 横長'!$B$3:$D$37,3,FALSE()),"")) | M8: =IF(X5="","",IFERROR(VLOOKUP(X5,'梅 横長'!$B$3:$D$37,3,FALSE()),"")) | P8: =IF(Y5="","",IFERROR(VLOOKUP(Y5,'梅 横長'!$B$3:$D$37,3,FALSE()),"")) | S8: 5列目
A9: =IF(T5="","",IFERROR(VLOOKUP(T5,'梅 横長'!$B$3:$D$37,2,FALSE()),"")) | D9: =IF(U5="","",IFERROR(VLOOKUP(U5,'梅 横長'!$B$3:$D$37,2,FALSE()),"")) | G9: =IF(V5="","",IFERROR(VLOOKUP(V5,'梅 横長'!$B$3:$D$37,2,FALSE()),"")) | J9: =IF(W5="","",IFERROR(VLOOKUP(W5,'梅 横長'!$B$3:$D$37,2,FALSE()),"")) | M9: =IF(X5="","",IFERROR(VLOOKUP(X5,'梅 横長'!$B$3:$D$37,2,FALSE()),"")) | P9: =IF(Y5="","",IFERROR(VLOOKUP(Y5,'梅 横長'!$B$3:$D$37,2,FALSE()),"")) | S9: 6列目
A12: =IF(T6="","",IFERROR(VLOOKUP(T6,'梅 横長'!$B$3:$D$37,3,FALSE()),"")) | D12: =IF(U6="","",IFERROR(VLOOKUP(U6,'梅 横長'!$B$3:$D$37,3,FALSE()),"")) | G12: =IF(V6="","",IFERROR(VLOOKUP(V6,'梅 横長'!$B$3:$D$37,3,FALSE()),"")) | J12: =IF(W6="","",IFERROR(VLOOKUP(W6,'梅 横長'!$B$3:$D$37,3,FALSE()),"")) | M12: =IF(X6="","",IFERROR(VLOOKUP(X6,'梅 横長'!$B$3:$D$37,3,FALSE()),"")) | P12: =IF(Y6="","",IFERROR(VLOOKUP(Y6,'梅 横長'!$B$3:$D$37,3,FALSE()),""))
A13: =IF(T6="","",IFERROR(VLOOKUP(T6,'梅 横長'!$B$3:$D$37,2,FALSE()),"")) | D13: =IF(U6="","",IFERROR(VLOOKUP(U6,'梅 横長'!$B$3:$D$37,2,FALSE()),"")) | G13: =IF(V6="","",IFERROR(VLOOKUP(V6,'梅 横長'!$B$3:$D$37,2,FALSE()),"")) | J13: =IF(W6="","",IFERROR(VLOOKUP(W6,'梅 横長'!$B$3:$D$37,2,FALSE()),"")) | M13: =IF(X6="","",IFERROR(VLOOKUP(X6,'梅 横長'!$B$3:$D$37,2,FALSE()),"")) | P13: =IF(Y6="","",IFERROR(VLOOKUP(Y6,'梅 横長'!$B$3:$D$37,2,FALSE()),""))
A16: =IF(T7="","",IFERROR(VLOOKUP(T7,'梅 横長'!$B$3:$D$37,3,FALSE()),"")) | D16: =IF(U7="","",IFERROR(VLOOKUP(U7,'梅 横長'!$B$3:$D$37,3,FALSE()),"")) | G16: =IF(V7="","",IFERROR(VLOOKUP(V7,'梅 横長'!$B$3:$D$37,3,FALSE()),"")) | J16: =IF(W7="","",IFERROR(VLOOKUP(W7,'梅 横長'!$B$3:$D$37,3,FALSE()),"")) | M16: =IF(X7="","",IFERROR(VLOOKUP(X7,'梅 横長'!$B$3:$D$37,3,FALSE()),"")) | P16: =IF(Y7="","",IFERROR(VLOOKUP(Y7,'梅 横長'!$B$3:$D$37,3,FALSE()),""))
A17: =IF(T7="","",IFERROR(VLOOKUP(T7,'梅 横長'!$B$3:$D$37,2,FALSE()),"")) | D17: =IF(U7="","",IFERROR(VLOOKUP(U7,'梅 横長'!$B$3:$D$37,2,FALSE()),"")) | G17: =IF(V7="","",IFERROR(VLOOKUP(V7,'梅 横長'!$B$3:$D$37,2,FALSE()),"")) | J17: =IF(W7="","",IFERROR(VLOOKUP(W7,'梅 横長'!$B$3:$D$37,2,FALSE()),"")) | M17: =IF(X7="","",IFERROR(VLOOKUP(X7,'梅 横長'!$B$3:$D$37,2,FALSE()),"")) | P17: =IF(Y7="","",IFERROR(VLOOKUP(Y7,'梅 横長'!$B$3:$D$37,2,FALSE()),""))
A20: =IF(T8="","",IFERROR(VLOOKUP(T8,'梅 横長'!$B$3:$D$37,3,FALSE()),"")) | D20: =IF(U8="","",IFERROR(VLOOKUP(U8,'梅 横長'!$B$3:$D$37,3,FALSE()),"")) | G20: =IF(V8="","",IFERROR(VLOOKUP(V8,'梅 横長'!$B$3:$D$37,3,FALSE()),"")) | J20: =IF(W8="","",IFERROR(VLOOKUP(W8,'梅 横長'!$B$3:$D$37,3,FALSE()),"")) | M20: =IF(X8="","",IFERROR(VLOOKUP(X8,'梅 横長'!$B$3:$D$37,3,FALSE()),"")) | P20: =IF(Y8="","",IFERROR(VLOOKUP(Y8,'梅 横長'!$B$3:$D$37,3,FALSE()),""))
A21: =IF(T8="","",IFERROR(VLOOKUP(T8,'梅 横長'!$B$3:$D$37,2,FALSE()),"")) | D21: =IF(U8="","",IFERROR(VLOOKUP(U8,'梅 横長'!$B$3:$D$37,2,FALSE()),"")) | G21: =IF(V8="","",IFERROR(VLOOKUP(V8,'梅 横長'!$B$3:$D$37,2,FALSE()),"")) | J21: =IF(W8="","",IFERROR(VLOOKUP(W8,'梅 横長'!$B$3:$D$37,2,FALSE()),"")) | M21: =IF(X8="","",IFERROR(VLOOKUP(X8,'梅 横長'!$B$3:$D$37,2,FALSE()),"")) | P21: =IF(Y8="","",IFERROR(VLOOKUP(Y8,'梅 横長'!$B$3:$D$37,2,FALSE()),""))
A24: =IF(T9="","",IFERROR(VLOOKUP(T9,'梅 横長'!$B$3:$D$37,3,FALSE()),"")) | D24: =IF(U9="","",IFERROR(VLOOKUP(U9,'梅 横長'!$B$3:$D$37,3,FALSE()),"")) | G24: =IF(V9="","",IFERROR(VLOOKUP(V9,'梅 横長'!$B$3:$D$37,3,FALSE()),"")) | J24: =IF(W9="","",IFERROR(VLOOKUP(W9,'梅 横長'!$B$3:$D$37,3,FALSE()),"")) | M24: =IF(X9="","",IFERROR(VLOOKUP(X9,'梅 横長'!$B$3:$D$37,3,FALSE()),"")) | P24: =IF(Y9="","",IFERROR(VLOOKUP(Y9,'梅 横長'!$B$3:$D$37,3,FALSE()),""))
A25: =IF(T9="","",IFERROR(VLOOKUP(T9,'梅 横長'!$B$3:$D$37,2,FALSE()),"")) | D25: =IF(U9="","",IFERROR(VLOOKUP(U9,'梅 横長'!$B$3:$D$37,2,FALSE()),"")) | G25: =IF(V9="","",IFERROR(VLOOKUP(V9,'梅 横長'!$B$3:$D$37,2,FALSE()),"")) | J25: =IF(W9="","",IFERROR(VLOOKUP(W9,'梅 横長'!$B$3:$D$37,2,FALSE()),"")) | M25: =IF(X9="","",IFERROR(VLOOKUP(X9,'梅 横長'!$B$3:$D$37,2,FALSE()),"")) | P25: =IF(Y9="","",IFERROR(VLOOKUP(Y9,'梅 横長'!$B$3:$D$37,2,FALSE()),""))

Sheet 座席表 （低学年用）
G1: 黒板 | S1: 【入力用】出席番号を入力（↑黒板側）
T2: 列1 | U2: 列2 | V2: 列3 | W2: 列4 | X2: 列5 | Y2: 列6
T3: 列1 | U3: 列2 | V3: 列3 | W3: 列4 | X3: 列5 | Y3: 列6
A4: =IF(T4="","",IFERROR(VLOOKUP(T4,'梅 横長'!$B$3:$D$37,3,FALSE()),"")) | D4: =IF(U4="","",IFERROR(VLOOKUP(U4,'梅 横長'!$B$3:$D$37,3,FALSE()),"")) | G4: =IF(V4="","",IFERROR(VLOOKUP(V4,'梅 横長'!$B$3:$D$37,3,FALSE()),"")) | J4: =IF(W4="","",IFERROR(VLOOKUP(W4,'梅 横長'!$B$3:$D$37,3,FALSE()),"")) | M4: =IF(X4="","",IFERROR(VLOOKUP(X4,'梅 横長'!$B$3:$D$37,3,FALSE()),"")) | P4: =IF(Y4="","",IFERROR(VLOOKUP(Y4,'梅 横長'!$B$3:$D$37,3,FALSE()),"")) | S4: 1列目
S5: 2列目
S6: 3列目
S7: 4列目
A8: =IF(T5="","",IFERROR(VLOOKUP(T5,'梅 横長'!$B$3:$D$37,3,FALSE()),"")) | D8: =IF(U5="","",IFERROR(VLOOKUP(U5,'梅 横長'!$B$3:$D$37,3,FALSE()),"")) | G8: =IF(V5="","",IFERROR(VLOOKUP(V5,'梅 横長'!$B$3:$D$37,3,FALSE()),"")) | J8: =IF(W5="","",IFERROR(VLOOKUP(W5,'梅 横長'!$B$3:$D$37,3,FALSE()),"")) | M8: =IF(X5="","",IFERROR(VLOOKUP(X5,'梅 横長'!$B$3:$D$37,3,FALSE()),"")) | P8: =IF(Y5="","",IFERROR(VLOOKUP(Y5,'梅 横長'!$B$3:$D$37,3,FALSE()),"")) | S8: 5列目
S9: 6列目
A12: =IF(T6="","",IFERROR(VLOOKUP(T6,'梅 横長'!$B$3:$D$37,3,FALSE()),"")) | D12: =IF(U6="","",IFERROR(VLOOKUP(U6,'梅 横長'!$B$3:$D$37,3,FALSE()),"")) | G12: =IF(V6="","",IFERROR(VLOOKUP(V6,'梅 横長'!$B$3:$D$37,3,FALSE()),"")) | J12: =IF(W6="","",IFERROR(VLOOKUP(W6,'梅 横長'!$B$3:$D$37,3,FALSE()),"")) | M12: =IF(X6="","",IFERROR(VLOOKUP(X6,'梅 横長'!$B$3:$D$37,3,FALSE()),"")) | P12: =IF(Y6="","",IFERROR(VLOOKUP(Y6,'梅 横長'!$B$3:$D$37,3,FALSE()),""))
A16: =IF(T7="","",IFERROR(VLOOKUP(T7,'梅 横長'!$B$3:$D$37,3,FALSE()),"")) | D16: =IF(U7="","",IFERROR(VLOOKUP(U7,'梅 横長'!$B$3:$D$37,3,FALSE()),"")) | G16: =IF(V7="","",IFERROR(VLOOKUP(V7,'梅 横長'!$B$3:$D$37,3,FALSE()),"")) | J16: =IF(W7="","",IFERROR(VLOOKUP(W7,'梅 横長'!$B$3:$D$37,3,FALSE()),"")) | M16: =IF(X7="","",IFERROR(VLOOKUP(X7,'梅 横長'!$B$3:$D$37,3,FALSE()),"")) | P16: =IF(Y7="","",IFERROR(VLOOKUP(Y7,'梅 横長'!$B$3:$D$37,3,FALSE()),""))
A20: =IF(T8="","",IFERROR(VLOOKUP(T8,'梅 横長'!$B$3:$D$37,3,FALSE()),"")) | D20: =IF(U8="","",IFERROR(VLOOKUP(U8,'梅 横長'!$B$3:$D$37,3,FALSE()),"")) | G20: =IF(V8="","",IFERROR(VLOOKUP(V8,'梅 横長'!$B$3:$D$37,3,FALSE()),"")) | J20: =IF(W8="","",IFERROR(VLOOKUP(W8,'梅 横長'!$B$3:$D$37,3,FALSE()),"")) | M20: =IF(X8="","",IFERROR(VLOOKUP(X8,'梅 横長'!$B$3:$D$37,3,FALSE()),"")) | P20: =IF(Y8="","",IFERROR(VLOOKUP(Y8,'梅 横長'!$B$3:$D$37,3,FALSE()),""))
A24: =IF(T9="","",IFERROR(VLOOKUP(T9,'梅 横長'!$B$3:$D$37,3,FALSE()),"")) | D24: =IF(U9="","",IFERROR(VLOOKUP(U9,'梅 横長'!$B$3:$D$37,3,FALSE()),"")) | G24: =IF(V9="","",IFERROR(VLOOKUP(V9,'梅 横長'!$B$3:$D$37,3,FALSE()),"")) | J24: =IF(W9="","",IFERROR(VLOOKUP(W9,'梅 横長'!$B$3:$D$37,3,FALSE()),"")) | M24: =IF(X9="","",IFERROR(VLOOKUP(X9,'梅 横長'!$B$3:$D$37,3,FALSE()),"")) | P24: =IF(Y9="","",IFERROR(VLOOKUP(Y9,'梅 横長'!$B$3:$D$37,3,FALSE()),""))

Sheet 提出物チェック表
A1: 提出物チェック表
A3: 番号 | B3: 名前 | R3: 未提出
A4: ='梅 横長'!B3 | B4: =IF('梅 横長'!C3="","",'梅 横長'!C3) | R4: =IF($B4="","",COUNTA($C$3:$Q$3)-COUNTA(C4:Q4))
A5: ='梅 横長'!B4 | B5: =IF('梅 横長'!C4="","",'梅 横長'!C4) | R5: =IF($B5="","",COUNTA($C$3:$Q$3)-COUNTA(C5:Q5))
A6: ='梅 横長'!B5 | B6: =IF('梅 横長'!C5="","",'梅 横長'!C5) | R6: =IF($B6="","",COUNTA($C$3:$Q$3)-COUNTA(C6:Q6))
A7: ='梅 横長'!B6 | B7: =IF('梅 横長'!C6="","",'梅 横長'!C6) | R7: =IF($B7="","",COUNTA($C$3:$Q$3)-COUNTA(C7:Q7))
A8: ='梅 横長'!B7 | B8: =IF('梅 横長'!C7="","",'梅 横長'!C7) | R8: =IF($B8="","",COUNTA($C$3:$Q$3)-COUNTA(C8:Q8))
A9: ='梅 横長'!B8 | B9: =IF('梅 横長'!C8="","",'梅 横長'!C8) | R9: =IF($B9="","",COUNTA($C$3:$Q$3)-COUNTA(C9:Q9))
A10: ='梅 横長'!B9 | B10: =IF('梅 横長'!C9="","",'梅 横長'!C9) | R10: =IF($B10="","",COUNTA($C$3:$Q$3)-COUNTA(C10:Q10))
A11: ='梅 横長'!B10 | B11: =IF('梅 横長'!C10="","",'梅 横長'!C10) | R11: =IF($B11="","",COUNTA($C$3:$Q$3)-COUNTA(C11:Q11))
A12: ='梅 横長'!B11 | B12: =IF('梅 横長'!C11="","",'梅 横長'!C11) | R12: =IF($B12="","",COUNTA($C$3:$Q$3)-COUNTA(C12:Q12))
A13: ='梅 横長'!B12 | B13: =IF('梅 横長'!C12="","",'梅 横長'!C12) | R13: =IF($B13="","",COUNTA($C$3:$Q$3)-COUNTA(C13:Q13))
A14: ='梅 横長'!B13 | B14: =IF('梅 横長'!C13="","",'梅 横長'!C13) | R14: =IF($B14="","",COUNTA($C$3:$Q$3)-COUNTA(C14:Q14))
A15: ='梅 横長'!B14 | B15: =IF('梅 横長'!C14="","",'梅 横長'!C14) | R15: =IF($B15="","",COUNTA($C$3:$Q$3)-COUNTA(C15:Q15))
... A38: ='梅 横長'!B37 | B38: =IF('梅 横長'!C37="","",'梅 横長'!C37) | R38: =IF($B38="","",COUNTA($C$3:$Q$3)-COUNTA(C38:Q38))
A39: 提出数 | C39: =IF(C$3="","",COUNTA(C4:C38)) | D39: =IF(D$3="","",COUNTA(D4:D38)) | E39: =IF(E$3="","",COUNTA(E4:E38)) | F39: =IF(F$3="","",COUNTA(F4:F38)) | G39: =IF(G$3="","",COUNTA(G4:G38)) | H39: =IF(H$3="","",COUNTA(H4:H38)) | I39: =IF(I$3="","",COUNTA(I4:I38)) | J39: =IF(J$3="","",COUNTA(J4:J38)) | ... Q39: =IF(Q$3="","",COUNTA(Q4:Q38))
A40: 未提出 | C40: =IF(C$3="","",COUNTIF($B$4:$B$38,"?*")-COUNTA(C4:C38)) | D40: =IF(D$3="","",COUNTIF($B$4:$B$38,"?*")-COUNTA(D4:D38)) | E40: =IF(E$3="","",COUNTIF($B$4:$B$38,"?*")-COUNTA(E4:E38)) | F40: =IF(F$3="","",COUNTIF($B$4:$B$38,"?*")-COUNTA(F4:F38)) | G40: =IF(G$3="","",COUNTIF($B$4:$B$38,"?*")-COUNTA(G4:G38)) | H40: =IF(H$3="","",COUNTIF($B$4:$B$38,"?*")-COUNTA(H4:H38)) | I40: =IF(I$3="","",COUNTIF($B$4:$B$38,"?*")-COUNTA(I4:I38)) | J40: =IF(J$3="","",COUNTIF($B$4:$B$38,"?*")-COUNTA(J4:J38)) | ... Q40: =IF(Q$3="","",COUNTIF($B$4:$B$38,"?*")-COUNTA(Q4:Q38))
A42: 黄色のセルに題名・提出物名を入力。提出したら○などを入れると「未提出」が自動で数えられます。

Sheet 班分け表
A1: 【入力用】班の番号（1〜8）を入力 | F1: 班分け表
A3: 番号 | B3: 名前 | C3: 班 | F3: =1&"班（"&COUNTIF($D$4:$D$38,"1-*")&"人）" | I3: =2&"班（"&COUNTIF($D$4:$D$38,"2-*")&"人）" | L3: =3&"班（"&COUNTIF($D$4:$D$38,"3-*")&"人）" | O3: =4&"班（"&COUNTIF($D$4:$D$38,"4-*")&"人）"
A4: ='梅 横長'!B3 | B4: =IF('梅 横長'!C3="","",'梅 横長'!C3) | D4: =IF(OR($B4="",$C4=""),"",$C4&"-"&COUNTIFS($C$4:$C4,$C4,$B$4:$B4,"?*")) | F4: =IFERROR(INDEX($A$4:$A$38,MATCH("1-1",$D$4:$D$38,0)),"") | G4: =IFERROR(INDEX($B$4:$B$38,MATCH("1-1",$D$4:$D$38,0)),"") | I4: =IFERROR(INDEX($A$4:$A$38,MATCH("2-1",$D$4:$D$38,0)),"") | J4: =IFERROR(INDEX($B$4:$B$38,MATCH("2-1",$D$4:$D$38,0)),"") | L4: =IFERROR(INDEX($A$4:$A$38,MATCH("3-1",$D$4:$D$38,0)),"") | M4: =IFERROR(INDEX($B$4:$B$38,MATCH("3-1",$D$4:$D$38,0)),"") | O4: =IFERROR(INDEX($A$4:$A$38,MATCH("4-1",$D$4:$D$38,0)),"") | P4: =IFERROR(INDEX($B$4:$B$38,MATCH("4-1",$D$4:$D$38,0)),"")
A5: ='梅 横長'!B4 | B5: =IF('梅 横長'!C4="","",'梅 横長'!C4) | D5: =IF(OR($B5="",$C5=""),"",$C5&"-"&COUNTIFS($C$4:$C5,$C5,$B$4:$B5,"?*")) | F5: =IFERROR(INDEX($A$4:$A$38,MATCH("1-2",$D$4:$D$38,0)),"") | G5: =IFERROR(INDEX($B$4:$B$38,MATCH("1-2",$D$4:$D$38,0)),"") | I5: =IFERROR(INDEX($A$4:$A$38,MATCH("2-2",$D$4:$D$38,0)),"") | J5: =IFERROR(INDEX($B$4:$B$38,MATCH("2-2",$D$4:$D$38,0)),"") | L5: =IFERROR(INDEX($A$4:$A$38,MATCH("3-2",$D$4:$D$38,0)),"") | M5: =IFERROR(INDEX($B$4:$B$38,MATCH("3-2",$D$4:$D$38,0)),"") | O5: =IFERROR(INDEX($A$4:$A$38,MATCH("4-2",$D$4:$D$38,0)),"") | P5: =IFERROR(INDEX($B$4:$B$38,MATCH("4-2",$D$4:$D$38,0)),"")
A6: ='梅 横長'!B5 | B6: =IF('梅 横長'!C5="","",'梅 横長'!C5) | D6: =IF(OR($B6="",$C6=""),"",$C6&"-"&COUNTIFS($C$4:$C6,$C6,$B$4:$B6,"?*")) | F6: =IFERROR(INDEX($A$4:$A$38,MATCH("1-3",$D$4:$D$38,0)),"") | G6: =IFERROR(INDEX($B$4:$B$38,MATCH("1-3",$D$4:$D$38,0)),"") | I6: =IFERROR(INDEX($A$4:$A$38,MATCH("2-3",$D$4:$D$38,0)),"") | J6: =IFERROR(INDEX($B$4:$B$38,MATCH("2-3",$D$4:$D$38,0)),"") | L6: =IFERROR(INDEX($A$4:$A$38,MATCH("3-3",$D$4:$D$38,0)),"") | M6: =IFERROR(INDEX($B$4:$B$38,MATCH("3-3",$D$4:$D$38,0)),"") | O6: =IFERROR(INDEX($A$4:$A$38,MATCH("4-3",$D$4:$D$38,0)),"") | P6: =IFERROR(INDEX($B$4:$B$38,MATCH("4-3",$D$4:$D$38,0)),"")
A7: ='梅 横長'!B6 | B7: =IF('梅 横長'!C6="","",'梅 横長'!C6) | D7: =IF(OR($B7="",$C7=""),"",$C7&"-"&COUNTIFS($C$4:$C7,$C7,$B$4:$B7,"?*")) | F7: =IFERROR(INDEX($A$4:$A$38,MATCH("1-4",$D$4:$D$38,0)),"") | G7: =IFERROR(INDEX($B$4:$B$38,MATCH("1-4",$D$4:$D$38,0)),"") | I7: =IFERROR(INDEX($A$4:$A$38,MATCH("2-4",$D$4:$D$38,0)),"") | J7: =IFERROR(INDEX($B$4:$B$38,MATCH("2-4",$D$4:$D$38,0)),"") | L7: =IFERROR(INDEX($A$4:$A$38,MATCH("3-4",$D$4:$D$38,0)),"") | M7: =IFERROR(INDEX($B$4:$B$38,MATCH("3-4",$D$4:$D$38,0)),"") | O7: =IFERROR(INDEX($A$4:$A$38,MATCH("4-4",$D$4:$D$38,0)),"") | P7: =IFERROR(INDEX($B$4:$B$38,MATCH("4-4",$D$4:$D$38,0)),"")
A8: ='梅 横長'!B7 | B8: =IF('梅 横長'!C7="","",'梅 横長'!C7) | D8: =IF(OR($B8="",$C8=""),"",$C8&"-"&COUNTIFS($C$4:$C8,$C8,$B$4:$B8,"?*")) | F8: =IFERROR(INDEX($A$4:$A$38,MATCH("1-5",$D$4:$D$38,0)),"") | G8: =IFERROR(INDEX($B$4:$B$38,MATCH("1-5",$D$4:$D$38,0)),"") | I8: =IFERROR(INDEX($A$4:$A$38,MATCH("2-5",$D$4:$D$38,0)),"") | J8: =IFERROR(INDEX($B$4:$B$38,MATCH("2-5",$D$4:$D$38,0)),"") | L8: =IFERROR(INDEX($A$4:$A$38,MATCH("3-5",$D$4:$D$38,0)),"") | M8: =IFERROR(INDEX($B$4:$B$38,MATCH("3-5",$D$4:$D$38,0)),"") | O8: =IFERROR(INDEX($A$4:$A$38,MATCH("4-5",$D$4:$D$38,0)),"") | P8: =IFERROR(INDEX($B$4:$B$38,MATCH("4-5",$D$4:$D$38,0)),"")
A9: ='梅 横長'!B8 | B9: =IF('梅 横長'!C8="","",'梅 横長'!C8) | D9: =IF(OR($B9="",$C9=""),"",$C9&"-"&COUNTIFS($C$4:$C9,$C9,$B$4:$B9,"?*")) | F9: =IFERROR(INDEX($A$4:$A$38,MATCH("1-6",$D$4:$D$38,0)),"") | G9: =IFERROR(INDEX($B$4:$B$38,MATCH("1-6",$D$4:$D$38,0)),"") | I9: =IFERROR(INDEX($A$4:$A$38,MATCH("2-6",$D$4:$D$38,0)),"") | J9: =IFERROR(INDEX($B$4:$B$38,MATCH("2-6",$D$4:$D$38,0)),"") | L9: =IFERROR(INDEX($A$4:$A$38,MATCH("3-6",$D$4:$D$38,0)),"") | M9: =IFERROR(INDEX($B$4:$B$38,MATCH("3-6",$D$4:$D$38,0)),"") | O9: =IFERROR(INDEX($A$4:$A$38,MATCH("4-6",$D$4:$D$38,0)),"") | P9: =IFERROR(INDEX($B$4:$B$38,MATCH("4-6",$D$4:$D$38,0)),"")
A10: ='梅 横長'!B9 | B10: =IF('梅 横長'!C9="","",'梅 横長'!C9) | D10: =IF(OR($B10="",$C10=""),"",$C10&"-"&COUNTIFS($C$4:$C10,$C10,$B$4:$B10,"?*")) | F10: =IFERROR(INDEX($A$4:$A$38,MATCH("1-7",$D$4:$D$38,0)),"") | G10: =IFERROR(INDEX($B$4:$B$38,MATCH("1-7",$D$4:$D$38,0)),"") | I10: =IFERROR(INDEX($A$4:$A$38,MATCH("2-7",$D$4:$D$38,0)),"") | J10: =IFERROR(INDEX($B$4:$B$38,MATCH("2-7",$D$4:$D$38,0)),"") | L10: =IFERROR(INDEX($A$4:$A$38,MATCH("3-7",$D$4:$D$38,0)),"") | M10: =IFERROR(INDEX($B$4:$B$38,MATCH("3-7",$D$4:$D$38,0)),"") | O10: =IFERROR(INDEX($A$4:$A$38,MATCH("4-7",$D$4:$D$38,0)),"") | P10: =IFERROR(INDEX($B$4:$B$38,MATCH("4-7",$D$4:$D$38,0)),"")
A11: ='梅 横長'!B10 | B11: =IF('梅 横長'!C10="","",'梅 横長'!C10) | D11: =IF(OR($B11="",$C11=""),"",$C11&"-"&COUNTIFS($C$4:$C11,$C11,$B$4:$B11,"?*")) | F11: =IFERROR(INDEX($A$4:$A$38,MATCH("1-8",$D$4:$D$38,0)),"") | G11: =IFERROR(INDEX($B$4:$B$38,MATCH("1-8",$D$4:$D$38,0)),"") | I11: =IFERROR(INDEX($A$4:$A$38,MATCH("2-8",$D$4:$D$38,0)),"") | J11: =IFERROR(INDEX($B$4:$B$38,MATCH("2-8",$D$4:$D$38,0)),"") | L11: =IFERROR(INDEX($A$4:$A$38,MATCH("3-8",$D$4:$D$38,0)),"") | M11: =IFERROR(INDEX($B$4:$B$38,MATCH("3-8",$D$4:$D$38,0)),"") | O11: =IFERROR(INDEX($A$4:$A$38,MATCH("4-8",$D$4:$D$38,0)),"") | P11: =IFERROR(INDEX($B$4:$B$38,MATCH("4-8",$D$4:$D$38,0)),"")
A12: ='梅 横長'!B11 | B12: =IF('梅 横長'!C11="","",'梅 横長'!C11) | D12: =IF(OR($B12="",$C12=""),"",$C12&"-"&COUNTIFS($C$4:$C12,$C12,$B$4:$B12,"?*"))
A13: ='梅 横長'!B12 | B13: =IF('梅 横長'!C12="","",'梅 横長'!C12) | D13: =IF(OR($B13="",$C13=""),"",$C13&"-"&COUNTIFS($C$4:$C13,$C13,$B$4:$B13,"?*")) | F13: =5&"班（"&COUNTIF($D$4:$D$38,"5-*")&"人）" | I13: =6&"班（"&COUNTIF($D$4:$D$38,"6-*")&"人）" | L13: =7&"班（"&COUNTIF($D$4:$D$38,"7-*")&"人）" | O13: =8&"班（"&COUNTIF($D$4:$D$38,"8-*")&"人）"
A14: ='梅 横長'!B13 | B14: =IF('梅 横長'!C13="","",'梅 横長'!C13) | D14: =IF(OR($B14="",$C14=""),"",$C14&"-"&COUNTIFS($C$4:$C14,$C14,$B$4:$B14,"?*")) | F14: =IFERROR(INDEX($A$4:$A$38,MATCH("5-1",$D$4:$D$38,0)),"") | G14: =IFERROR(INDEX($B$4:$B$38,MATCH("5-1",$D$4:$D$38,0)),"") | I14: =IFERROR(INDEX($A$4:$A$38,MATCH("6-1",$D$4:$D$38,0)),"") | J14: =IFERROR(INDEX($B$4:$B$38,MATCH("6-1",$D$4:$D$38,0)),"") | L14: =IFERROR(INDEX($A$4:$A$38,MATCH("7-1",$D$4:$D$38,0)),"") | M14: =IFERROR(INDEX($B$4:$B$38,MATCH("7-1",$D$4:$D$38,0)),"") | O14: =IFERROR(INDEX($A$4:$A$38,MATCH("8-1",$D$4:$D$38,0)),"") | P14: =IFERROR(INDEX($B$4:$B$38,MATCH("8-1",$D$4:$D$38,0)),"")
A15: ='梅 横長'!B14 | B15: =IF('梅 横長'!C14="","",'梅 横長'!C14) | D15: =IF(OR($B15="",$C15=""),"",$C15&"-"&COUNTIFS($C$4:$C15,$C15,$B$4:$B15,"?*")) | F15: =IFERROR(INDEX($A$4:$A$38,MATCH("5-2",$D$4:$D$38,0)),"") | G15: =IFERROR(INDEX($B$4:$B$38,MATCH("5-2",$D$4:$D$38,0)),"") | I15: =IFERROR(INDEX($A$4:$A$38,MATCH("6-2",$D$4:$D$38,0)),"") | J15: =IFERROR(INDEX($B$4:$B$38,MATCH("6-2",$D$4:$D$38,0)),"") | L15: =IFERROR(INDEX($A$4:$A$38,MATCH("7-2",$D$4:$D$38,0)),"") | M15: =IFERROR(INDEX($B$4:$B$38,MATCH("7-2",$D$4:$D$38,0)),"") | O15: =IFERROR(INDEX($A$4:$A$38,MATCH("8-2",$D$4:$D$38,0)),"") | P15: =IFERROR(INDEX($B$4:$B$38,MATCH("8-2",$D$4:$D$38,0)),"")
A16: ='梅 横長'!B15 | B16: =IF('梅 横長'!C15="","",'梅 横長'!C15) | D16: =IF(OR($B16="",$C16=""),"",$C16&"-"&COUNTIFS($C$4:$C16,$C16,$B$4:$B16,"?*")) | F16: =IFERROR(INDEX($A$4:$A$38,MATCH("5-3",$D$4:$D$38,0)),"") | G16: =IFERROR(INDEX($B$4:$B$38,MATCH("5-3",$D$4:$D$38,0)),"") | I16: =IFERROR(INDEX($A$4:$A$38,MATCH("6-3",$D$4:$D$38,0)),"") | J16: =IFERROR(INDEX($B$4:$B$38,MATCH("6-3",$D$4:$D$38,0)),"") | L16: =IFERROR(INDEX($A$4:$A$38,MATCH("7-3",$D$4:$D$38,0)),"") | M16: =IFERROR(INDEX($B$4:$B$38,MATCH("7-3",$D$4:$D$38,0)),"") | O16: =IFERROR(INDEX($A$4:$A$38,MATCH("8-3",$D$4:$D$38,0)),"") | P16: =IFERROR(INDEX($B$4:$B$38,MATCH("8-3",$D$4:$D$38,0)),"")
A17: ='梅 横長'!B16 | B17: =IF('梅 横長'!C16="","",'梅 横長'!C16) | D17: =IF(OR($B17="",$C17=""),"",$C17&"-"&COUNTIFS($C$4:$C17,$C17,$B$4:$B17,"?*")) | F17: =IFERROR(INDEX($A$4:$A$38,MATCH("5-4",$D$4:$D$38,0)),"") | G17: =IFERROR(INDEX($B$4:$B$38,MATCH("5-4",$D$4:$D$38,0)),"") | I17: =IFERROR(INDEX($A$4:$A$38,MATCH("6-4",$D$4:$D$38,0)),"") | J17: =IFERROR(INDEX($B$4:$B$38,MATCH("6-4",$D$4:$D$38,0)),"") | L17: =IFERROR(INDEX($A$4:$A$38,MATCH("7-4",$D$4:$D$38,0)),"") | M17: =IFERROR(INDEX($B$4:$B$38,MATCH("7-4",$D$4:$D$38,0)),"") | O17: =IFERROR(INDEX($A$4:$A$38,MATCH("8-4",$D$4:$D$38,0)),"") | P17: =IFERROR(INDEX($B$4:$B$38,MATCH("8-4",$D$4:$D$38,0)),"")
A18: ='梅 横長'!B17 | B18: =IF('梅 横長'!C17="","",'梅 横長'!C17) | D18: =IF(OR($B18="",$C18=""),"",$C18&"-"&COUNTIFS($C$4:$C18,$C18,$B$4:$B18,"?*")) | F18: =IFERROR(INDEX($A$4:$A$38,MATCH("5-5",$D$4:$D$38,0)),"") | G18: =IFERROR(INDEX($B$4:$B$38,MATCH("5-5",$D$4:$D$38,0)),"") | I18: =IFERROR(INDEX($A$4:$A$38,MATCH("6-5",$D$4:$D$38,0)),"") | J18: =IFERROR(INDEX($B$4:$B$38,MATCH("6-5",$D$4:$D$38,0)),"") | L18: =IFERROR(INDEX($A$4:$A$38,MATCH("7-5",$D$4:$D$38,0)),"") | M18: =IFERROR(INDEX($B$4:$B$38,MATCH("7-5",$D$4:$D$38,0)),"") | O18: =IFERROR(INDEX($A$4:$A$38,MATCH("8-5",$D$4:$D$38,0)),"") | P18: =IFERROR(INDEX($B$4:$B$38,MATCH("8-5",$D$4:$D$38,0)),"")
A19: ='梅 横長'!B18 | B19: =IF('梅 横長'!C18="","",'梅 横長'!C18) | D19: =IF(OR($B19="",$C19=""),"",$C19&"-"&COUNTIFS($C$4:$C19,$C19,$B$4:$B19,"?*")) | F19: =IFERROR(INDEX($A$4:$A$38,MATCH("5-6",$D$4:$D$38,0)),"") | G19: =IFERROR(INDEX($B$4:$B$38,MATCH("5-6",$D$4:$D$38,0)),"") | I19: =IFERROR(INDEX($A$4:$A$38,MATCH("6-6",$D$4:$D$38,0)),"") | J19: =IFERROR(INDEX($B$4:$B$38,MATCH("6-6",$D$4:$D$38,0)),"") | L19: =IFERROR(INDEX($A$4:$A$38,MATCH("7-6",$D$4:$D$38,0)),"") | M19: =IFERROR(INDEX($B$4:$B$38,MATCH("7-6",$D$4:$D$38,0)),"") | O19: =IFERROR(INDEX($A$4:$A$38,MATCH("8-6",$D$4:$D$38,0)),"") | P19: =IFERROR(INDEX($B$4:$B$38,MATCH("8-6",$D$4:$D$38,0)),"")
A20: ='梅 横長'!B19 | B20: =IF('梅 横長'!C19="","",'梅 横長'!C19) | D20: =IF(OR($B20="",$C20=""),"",$C20&"-"&COUNTIFS($C$4:$C20,$C20,$B$4:$B20,"?*")) | F20: =IFERROR(INDEX($A$4:$A$38,MATCH("5-7",$D$4:$D$38,0)),"") | G20: =IFERROR(INDEX($B$4:$B$38,MATCH("5-7",$D$4:$D$38,0)),"") | I20: =IFERROR(INDEX($A$4:$A$38,MATCH("6-7",$D$4:$D$38,0)),"") | J20: =IFERROR(INDEX($B$4:$B$38,MATCH("6-7",$D$4:$D$38,0)),"") | L20: =IFERROR(INDEX($A$4:$A$38,MATCH("7-7",$D$4:$D$38,0)),"") | M20: =IFERROR(INDEX($B$4:$B$38,MATCH("7-7",$D$4:$D$38,0)),"") | O20: =IFERROR(INDEX($A$4:$A$38,MATCH("8-7",$D$4:$D$38,0)),"") | P20: =IFERROR(INDEX($B$4:$B$38,MATCH("8-7",$D$4:$D$38,0)),"")
A21: ='梅 横長'!B20 | B21: =IF('梅 横長'!C20="","",'梅 横長'!C20) | D21: =IF(OR($B21="",$C21=""),"",$C21&"-"&COUNTIFS($C$4:$C21,$C21,$B$4:$B21,"?*")) | F21: =IFERROR(INDEX($A$4:$A$38,MATCH("5-8",$D$4:$D$38,0)),"") | G21: =IFERROR(INDEX($B$4:$B$38,MATCH("5-8",$D$4:$D$38,0)),"") | I21: =IFERROR(INDEX($A$4:$A$38,MATCH("6-8",$D$4:$D$38,0)),"") | J21: =IFERROR(INDEX($B$4:$B$38,MATCH("6-8",$D$4:$D$38,0)),"") | L21: =IFERROR(INDEX($A$4:$A$38,MATCH("7-8",$D$4:$D$38,0)),"") | M21: =IFERROR(INDEX($B$4:$B$38,MATCH("7-8",$D$4:$D$38,0)),"") | O21: =IFERROR(INDEX($A$4:$A$38,MATCH("8-8",$D$4:$D$38,0)),"") | P21: =IFERROR(INDEX($B$4:$B$38,MATCH("8-8",$D$4:$D$38,0)),"")
A22: ='梅 横長'!B21 | B22: =IF('梅 横長'!C21="","",'梅 横長'!C21) | D22: =IF(OR($B22="",$C22=""),"",$C22&"-"&COUNTIFS($C$4:$C22,$C22,$B$4:$B22,"?*"))
A23: ='梅 横長'!B22 | B23: =IF('梅 横長'!C22="","",'梅 横長'!C22) | D23: =IF(OR($B23="",$C23=""),"",$C23&"-"&COUNTIFS($C$4:$C23,$C23,$B$4:$B23,"?*"))
A24: ='梅 横長'!B23 | B24: =IF('梅 横長'!C23="","",'梅 横長'!C23) | D24: =IF(OR($B24="",$C24=""),"",$C24&"-"&COUNTIFS($C$4:$C24,$C24,$B$4:$B24,"?*"))
A25: ='梅 横長'!B24 | B25: =IF('梅 横長'!C24="","",'梅 横長'!C24) | D25: =IF(OR($B25="",$C25=""),"",$C25&"-"&COUNTIFS($C$4:$C25,$C25,$B$4:$B25,"?*"))
A26: ='梅 横長'!B25 | B26: =IF('梅 横長'!C25="","",'梅 横長'!C25) | D26: =IF(OR($B26="",$C26=""),"",$C26&"-"&COUNTIFS($C$4:$C26,$C26,$B$4:$B26,"?*"))
A27: ='梅 横長'!B26 | B27: =IF('梅 横長'!C26="","",'梅 横長'!C26) | D27: =IF(OR($B27="",$C27=""),"",$C27&"-"&COUNTIFS($C$4:$C27,$C27,$B$4:$B27,"?*"))
A28: ='梅 横長'!B27 | B28: =IF('梅 横長'!C27="","",'梅 横長'!C27) | D28: =IF(OR($B28="",$C28=""),"",$C28&"-"&COUNTIFS($C$4:$C28,$C28,$B$4:$B28,"?*"))
A29: ='梅 横長'!B28 | B29: =IF('梅 横長'!C28="","",'梅 横長'!C28) | D29: =IF(OR($B29="",$C29=""),"",$C29&"-"&COUNTIFS($C$4:$C29,$C29,$B$4:$B29,"?*"))
A30: ='梅 横長'!B29 | B30: =IF('梅 横長'!C29="","",'梅 横長'!C29) | D30: =IF(OR($B30="",$C30=""),"",$C30&"-"&COUNTIFS($C$4:$C30,$C30,$B$4:$B30,"?*"))
A31: ='梅 横長'!B30 | B31: =IF('梅 横長'!C30="","",'梅 横長'!C30) | D31: =IF(OR($B31="",$C31=""),"",$C31&"-"&COUNTIFS($C$4:$C31,$C31,$B$4:$B31,"?*"))
A32: ='梅 横長'!B31 | B32: =IF('梅 横長'!C31="","",'梅 横長'!C31) | D32: =IF(OR($B32="",$C32=""),"",$C32&"-"&COUNTIFS($C$4:$C32,$C32,$B$4:$B32,"?*"))
A33: ='梅 横長'!B32 | B33: =IF('梅 横長'!C32="","",'梅 横長'!C32) | D33: =IF(OR($B33="",$C33=""),"",$C33&"-"&COUNTIFS($C$4:$C33,$C33,$B$4:$B33,"?*"))
... A38: ='梅 横長'!B37 | B38: =IF('梅 横長'!C37="","",'梅 横長'!C37) | D38: =IF(OR($B38="",$C38=""),"",$C38&"-"&COUNTIFS($C$4:$C38,$C38,$B$4:$B38,"?*"))
A39: 未入力 | C39: =SUMPRODUCT(($B$4:$B$38<>"")*($C$4:$C$38=""))&"人"

Sheet 使い方
B1: 使い方
B3: ① 名簿を入力 | C3: 「梅 横長」シートに、漢字氏名とかな氏名を入力します。ほかのシートには自動で名前が入ります。
B4: ② 印刷したいシートを開く | C4: 下の表から、使いたいシートを選んで印刷します。
B6: シート名 | C6: 用途・用紙
B7: 名前カード | C7: A3縦・1枚に36人（今までのもの）
B8: 名前カード (松組/竹組/梅組/月組) | C8: A3縦・クラスのマーク入り
B9: 名前カード (ひらがな) | C9: A3縦・ひらがなだけ
B10: 名前カード (特大) | C10: A4横・1枚に1人。机の上や掲示用。名前のある人数分だけ印刷されます。
B11: 名前カード (大) | C11: A4縦・1枚に10人。名前のあるページだけ印刷されます。
B12: 名前カード (小) | C12: A4縦・1枚に40人。小さな名札・シール用。
B13: 名前カード (縦書き) | C13: A4横・1枚に36人の縦書き。靴箱・ロッカー用。
B14: 座席表 / 座席表 （低学年用） | C14: 黄色の欄に出席番号を入力すると座席表ができます。
B15: 提出物チェック表 | C15: 黄色の欄に題名と提出物名を入力。未提出の数を自動で数えます。
... B18: メモ | C18: 黄色のセルが入力するところです。それ以外のセルには数式が入っているので、消さないようにしてください。
C19: 名前の長い人は、カードの枠に入るように文字が自動で小さくなります。
C20: 名前が入っていないカードは枠も印刷されません。
