Workbook

Sheet 入力シート
A1: 名前 | B1: 身長(cm) | C1: 自動の順番 | D1: 手動の順番 (入れ替えたい時だけ) | E1: 決定の順番 | F1: チェック | H1: 使い方
A2: 青木 あおい | B2: 130.9 | C2: =IF(OR(A2="",B2=""),"",COUNTIF($B$2:$B$41,"<"&B2)+COUNTIF($B$2:B2,B2)) | E2: =IF(C2="","",IF(D2="",C2,D2)) | F2: =IF(E2="","",IF(COUNTIF($E$2:$E$41,E2)>1,"⚠ 順番が重複",IF(E2>COUNT($E$2:$E$41),"⚠ 番号が大きすぎ",""))) | H2: ① 黄色の「名前」「身長」を入れる（コピー＆貼り付けOK・最大40人）
A3: 石川 はると | B3: 138.6 | C3: =IF(OR(A3="",B3=""),"",COUNTIF($B$2:$B$41,"<"&B3)+COUNTIF($B$2:B3,B3)) | E3: =IF(C3="","",IF(D3="",C3,D3)) | F3: =IF(E3="","",IF(COUNTIF($E$2:$E$41,E3)>1,"⚠ 順番が重複",IF(E3>COUNT($E$2:$E$41),"⚠ 番号が大きすぎ",""))) | H3: ② 他のシートに 2列・4列 の背の順が自動でできる
A4: 上田 ゆい | B4: 134.2 | C4: =IF(OR(A4="",B4=""),"",COUNTIF($B$2:$B$41,"<"&B4)+COUNTIF($B$2:B4,B4)) | E4: =IF(C4="","",IF(D4="",C4,D4)) | F4: =IF(E4="","",IF(COUNTIF($E$2:$E$41,E4)>1,"⚠ 順番が重複",IF(E4>COUNT($E$2:$E$41),"⚠ 番号が大きすぎ",""))) | H4: ・「横に」…前から 1,2 / 3,4 … と横に並べる
A5: 江藤 そうた | B5: 145.9 | C5: =IF(OR(A5="",B5=""),"",COUNTIF($B$2:$B$41,"<"&B5)+COUNTIF($B$2:B5,B5)) | E5: =IF(C5="","",IF(D5="",C5,D5)) | F5: =IF(E5="","",IF(COUNTIF($E$2:$E$41,E5)>1,"⚠ 順番が重複",IF(E5>COUNT($E$2:$E$41),"⚠ 番号が大きすぎ",""))) | H5: ・「縦に」…1列目を前から後ろまで埋めてから次の列へ
A6: 大野 めい | B6: 140.6 | C6: =IF(OR(A6="",B6=""),"",COUNTIF($B$2:$B$41,"<"&B6)+COUNTIF($B$2:B6,B6)) | E6: =IF(C6="","",IF(D6="",C6,D6)) | F6: =IF(E6="","",IF(COUNTIF($E$2:$E$41,E6)>1,"⚠ 順番が重複",IF(E6>COUNT($E$2:$E$41),"⚠ 番号が大きすぎ",""))) | H6: ③ 入れ替えたい子がいる時は「手動の順番」に番号を入れる
A7: 加藤 りく | B7: 126.6 | C7: =IF(OR(A7="",B7=""),"",COUNTIF($B$2:$B$41,"<"&B7)+COUNTIF($B$2:B7,B7)) | E7: =IF(C7="","",IF(D7="",C7,D7)) | F7: =IF(E7="","",IF(COUNTIF($E$2:$E$41,E7)>1,"⚠ 順番が重複",IF(E7>COUNT($E$2:$E$41),"⚠ 番号が大きすぎ",""))) | H7: 例：5番と6番を入れ替える → 5番の子に 6、6番の子に 5
A8: 木村 さくら | B8: 125.3 | C8: =IF(OR(A8="",B8=""),"",COUNTIF($B$2:$B$41,"<"&B8)+COUNTIF($B$2:B8,B8)) | E8: =IF(C8="","",IF(D8="",C8,D8)) | F8: =IF(E8="","",IF(COUNTIF($E$2:$E$41,E8)>1,"⚠ 順番が重複",IF(E8>COUNT($E$2:$E$41),"⚠ 番号が大きすぎ",""))) | H8: 「チェック」に ⚠ が出たら番号が重なっています
A9: 工藤 ゆうと | B9: 145.9 | C9: =IF(OR(A9="",B9=""),"",COUNTIF($B$2:$B$41,"<"&B9)+COUNTIF($B$2:B9,B9)) | E9: =IF(C9="","",IF(D9="",C9,D9)) | F9: =IF(E9="","",IF(COUNTIF($E$2:$E$41,E9)>1,"⚠ 順番が重複",IF(E9>COUNT($E$2:$E$41),"⚠ 番号が大きすぎ",""))) | H9: ※ 同じ身長の子は、上の行に書いた子が前になります
A10: 小林 ひなた | B10: 131.5 | C10: =IF(OR(A10="",B10=""),"",COUNTIF($B$2:$B$41,"<"&B10)+COUNTIF($B$2:B10,B10)) | E10: =IF(C10="","",IF(D10="",C10,D10)) | F10: =IF(E10="","",IF(COUNTIF($E$2:$E$41,E10)>1,"⚠ 順番が重複",IF(E10>COUNT($E$2:$E$41),"⚠ 番号が大きすぎ",""))) | H10: ※ 灰色のセルは自動計算です（さわらないでください）
A11: 佐藤 れん | B11: 130.9 | C11: =IF(OR(A11="",B11=""),"",COUNTIF($B$2:$B$41,"<"&B11)+COUNTIF($B$2:B11,B11)) | E11: =IF(C11="","",IF(D11="",C11,D11)) | F11: =IF(E11="","",IF(COUNTIF($E$2:$E$41,E11)>1,"⚠ 順番が重複",IF(E11>COUNT($E$2:$E$41),"⚠ 番号が大きすぎ","")))
A12: 清水 こはる | B12: 149.9 | C12: =IF(OR(A12="",B12=""),"",COUNTIF($B$2:$B$41,"<"&B12)+COUNTIF($B$2:B12,B12)) | E12: =IF(C12="","",IF(D12="",C12,D12)) | F12: =IF(E12="","",IF(COUNTIF($E$2:$E$41,E12)>1,"⚠ 順番が重複",IF(E12>COUNT($E$2:$E$41),"⚠ 番号が大きすぎ",""))) | H12: 入力した人数 | J12: =COUNT(E2:E41)
A13: 鈴木 たいが | B13: 136.8 | C13: =IF(OR(A13="",B13=""),"",COUNTIF($B$2:$B$41,"<"&B13)+COUNTIF($B$2:B13,B13)) | E13: =IF(C13="","",IF(D13="",C13,D13)) | F13: =IF(E13="","",IF(COUNTIF($E$2:$E$41,E13)>1,"⚠ 順番が重複",IF(E13>COUNT($E$2:$E$41),"⚠ 番号が大きすぎ",""))) | H13: 順番の重複 | J13: =IF(COUNTIF(F2:F41,"⚠*")=0,"なし","あり（チェック欄を見てください）")
A14: 田中 みお | B14: 145.9 | C14: =IF(OR(A14="",B14=""),"",COUNTIF($B$2:$B$41,"<"&B14)+COUNTIF($B$2:B14,B14)) | E14: =IF(C14="","",IF(D14="",C14,D14)) | F14: =IF(E14="","",IF(COUNTIF($E$2:$E$41,E14)>1,"⚠ 順番が重複",IF(E14>COUNT($E$2:$E$41),"⚠ 番号が大きすぎ","")))
A15: 千葉 かいと | B15: 136.9 | C15: =IF(OR(A15="",B15=""),"",COUNTIF($B$2:$B$41,"<"&B15)+COUNTIF($B$2:B15,B15)) | E15: =IF(C15="","",IF(D15="",C15,D15)) | F15: =IF(E15="","",IF(COUNTIF($E$2:$E$41,E15)>1,"⚠ 順番が重複",IF(E15>COUNT($E$2:$E$41),"⚠ 番号が大きすぎ","")))
A16: 土屋 ゆな | B16: 141 | C16: =IF(OR(A16="",B16=""),"",COUNTIF($B$2:$B$41,"<"&B16)+COUNTIF($B$2:B16,B16)) | E16: =IF(C16="","",IF(D16="",C16,D16)) | F16: =IF(E16="","",IF(COUNTIF($E$2:$E$41,E16)>1,"⚠ 順番が重複",IF(E16>COUNT($E$2:$E$41),"⚠ 番号が大きすぎ","")))
A17: 中村 あおと | B17: 128.8 | C17: =IF(OR(A17="",B17=""),"",COUNTIF($B$2:$B$41,"<"&B17)+COUNTIF($B$2:B17,B17)) | E17: =IF(C17="","",IF(D17="",C17,D17)) | F17: =IF(E17="","",IF(COUNTIF($E$2:$E$41,E17)>1,"⚠ 順番が重複",IF(E17>COUNT($E$2:$E$41),"⚠ 番号が大きすぎ","")))
A18: 西田 りこ | B18: 140.9 | C18: =IF(OR(A18="",B18=""),"",COUNTIF($B$2:$B$41,"<"&B18)+COUNTIF($B$2:B18,B18)) | E18: =IF(C18="","",IF(D18="",C18,D18)) | F18: =IF(E18="","",IF(COUNTIF($E$2:$E$41,E18)>1,"⚠ 順番が重複",IF(E18>COUNT($E$2:$E$41),"⚠ 番号が大きすぎ","")))
A19: 野口 そら | B19: 146.7 | C19: =IF(OR(A19="",B19=""),"",COUNTIF($B$2:$B$41,"<"&B19)+COUNTIF($B$2:B19,B19)) | E19: =IF(C19="","",IF(D19="",C19,D19)) | F19: =IF(E19="","",IF(COUNTIF($E$2:$E$41,E19)>1,"⚠ 順番が重複",IF(E19>COUNT($E$2:$E$41),"⚠ 番号が大きすぎ","")))
A20: 橋本 いろは | B20: 138.1 | C20: =IF(OR(A20="",B20=""),"",COUNTIF($B$2:$B$41,"<"&B20)+COUNTIF($B$2:B20,B20)) | E20: =IF(C20="","",IF(D20="",C20,D20)) | F20: =IF(E20="","",IF(COUNTIF($E$2:$E$41,E20)>1,"⚠ 順番が重複",IF(E20>COUNT($E$2:$E$41),"⚠ 番号が大きすぎ","")))
A21: 平野 ひろと | B21: 143.5 | C21: =IF(OR(A21="",B21=""),"",COUNTIF($B$2:$B$41,"<"&B21)+COUNTIF($B$2:B21,B21)) | E21: =IF(C21="","",IF(D21="",C21,D21)) | F21: =IF(E21="","",IF(COUNTIF($E$2:$E$41,E21)>1,"⚠ 順番が重複",IF(E21>COUNT($E$2:$E$41),"⚠ 番号が大きすぎ","")))
A22: 藤井 ことね | B22: 141.8 | C22: =IF(OR(A22="",B22=""),"",COUNTIF($B$2:$B$41,"<"&B22)+COUNTIF($B$2:B22,B22)) | E22: =IF(C22="","",IF(D22="",C22,D22)) | F22: =IF(E22="","",IF(COUNTIF($E$2:$E$41,E22)>1,"⚠ 順番が重複",IF(E22>COUNT($E$2:$E$41),"⚠ 番号が大きすぎ","")))
A23: 星野 だいき | B23: 126.6 | C23: =IF(OR(A23="",B23=""),"",COUNTIF($B$2:$B$41,"<"&B23)+COUNTIF($B$2:B23,B23)) | E23: =IF(C23="","",IF(D23="",C23,D23)) | F23: =IF(E23="","",IF(COUNTIF($E$2:$E$41,E23)>1,"⚠ 順番が重複",IF(E23>COUNT($E$2:$E$41),"⚠ 番号が大きすぎ","")))
A24: 松本 ゆずき | B24: 144 | C24: =IF(OR(A24="",B24=""),"",COUNTIF($B$2:$B$41,"<"&B24)+COUNTIF($B$2:B24,B24)) | E24: =IF(C24="","",IF(D24="",C24,D24)) | F24: =IF(E24="","",IF(COUNTIF($E$2:$E$41,E24)>1,"⚠ 順番が重複",IF(E24>COUNT($E$2:$E$41),"⚠ 番号が大きすぎ","")))
A25: 三浦 けんた | B25: 139.8 | C25: =IF(OR(A25="",B25=""),"",COUNTIF($B$2:$B$41,"<"&B25)+COUNTIF($B$2:B25,B25)) | E25: =IF(C25="","",IF(D25="",C25,D25)) | F25: =IF(E25="","",IF(COUNTIF($E$2:$E$41,E25)>1,"⚠ 順番が重複",IF(E25>COUNT($E$2:$E$41),"⚠ 番号が大きすぎ","")))
... A36: 川口 さら | B36: 136.1 | C36: =IF(OR(A36="",B36=""),"",COUNTIF($B$2:$B$41,"<"&B36)+COUNTIF($B$2:B36,B36)) | E36: =IF(C36="","",IF(D36="",C36,D36)) | F36: =IF(E36="","",IF(COUNTIF($E$2:$E$41,E36)>1,"⚠ 順番が重複",IF(E36>COUNT($E$2:$E$41),"⚠ 番号が大きすぎ","")))
C37: =IF(OR(A37="",B37=""),"",COUNTIF($B$2:$B$41,"<"&B37)+COUNTIF($B$2:B37,B37)) | E37: =IF(C37="","",IF(D37="",C37,D37)) | F37: =IF(E37="","",IF(COUNTIF($E$2:$E$41,E37)>1,"⚠ 順番が重複",IF(E37>COUNT($E$2:$E$41),"⚠ 番号が大きすぎ","")))
C38: =IF(OR(A38="",B38=""),"",COUNTIF($B$2:$B$41,"<"&B38)+COUNTIF($B$2:B38,B38)) | E38: =IF(C38="","",IF(D38="",C38,D38)) | F38: =IF(E38="","",IF(COUNTIF($E$2:$E$41,E38)>1,"⚠ 順番が重複",IF(E38>COUNT($E$2:$E$41),"⚠ 番号が大きすぎ","")))
C39: =IF(OR(A39="",B39=""),"",COUNTIF($B$2:$B$41,"<"&B39)+COUNTIF($B$2:B39,B39)) | E39: =IF(C39="","",IF(D39="",C39,D39)) | F39: =IF(E39="","",IF(COUNTIF($E$2:$E$41,E39)>1,"⚠ 順番が重複",IF(E39>COUNT($E$2:$E$41),"⚠ 番号が大きすぎ","")))
C40: =IF(OR(A40="",B40=""),"",COUNTIF($B$2:$B$41,"<"&B40)+COUNTIF($B$2:B40,B40)) | E40: =IF(C40="","",IF(D40="",C40,D40)) | F40: =IF(E40="","",IF(COUNTIF($E$2:$E$41,E40)>1,"⚠ 順番が重複",IF(E40>COUNT($E$2:$E$41),"⚠ 番号が大きすぎ","")))
C41: =IF(OR(A41="",B41=""),"",COUNTIF($B$2:$B$41,"<"&B41)+COUNTIF($B$2:B41,B41)) | E41: =IF(C41="","",IF(D41="",C41,D41)) | F41: =IF(E41="","",IF(COUNTIF($E$2:$E$41,E41)>1,"⚠ 順番が重複",IF(E41>COUNT($E$2:$E$41),"⚠ 番号が大きすぎ","")))

Sheet 2列_横に
A1: 背の順 2列・横に | E1: 人数 | F1: =COUNT('入力シート'!$E$2:$E$41)
E2: 行数 | F2: =ROUNDUP(F1/2,0)
B3: 前
B4: 1列目 | C4: 2列目
A5: =IF(1<=$F$2,"1","") | B5: =IFERROR(INDEX('入力シート'!$A$2:$A$41,MATCH((1-1)*2+1,'入力シート'!$E$2:$E$41,0)),"") | C5: =IFERROR(INDEX('入力シート'!$A$2:$A$41,MATCH((1-1)*2+2,'入力シート'!$E$2:$E$41,0)),"")
A6: =IF(2<=$F$2,"2","") | B6: =IFERROR(INDEX('入力シート'!$A$2:$A$41,MATCH((2-1)*2+1,'入力シート'!$E$2:$E$41,0)),"") | C6: =IFERROR(INDEX('入力シート'!$A$2:$A$41,MATCH((2-1)*2+2,'入力シート'!$E$2:$E$41,0)),"")
A7: =IF(3<=$F$2,"3","") | B7: =IFERROR(INDEX('入力シート'!$A$2:$A$41,MATCH((3-1)*2+1,'入力シート'!$E$2:$E$41,0)),"") | C7: =IFERROR(INDEX('入力シート'!$A$2:$A$41,MATCH((3-1)*2+2,'入力シート'!$E$2:$E$41,0)),"")
A8: =IF(4<=$F$2,"4","") | B8: =IFERROR(INDEX('入力シート'!$A$2:$A$41,MATCH((4-1)*2+1,'入力シート'!$E$2:$E$41,0)),"") | C8: =IFERROR(INDEX('入力シート'!$A$2:$A$41,MATCH((4-1)*2+2,'入力シート'!$E$2:$E$41,0)),"")
A9: =IF(5<=$F$2,"5","") | B9: =IFERROR(INDEX('入力シート'!$A$2:$A$41,MATCH((5-1)*2+1,'入力シート'!$E$2:$E$41,0)),"") | C9: =IFERROR(INDEX('入力シート'!$A$2:$A$41,MATCH((5-1)*2+2,'入力シート'!$E$2:$E$41,0)),"")
A10: =IF(6<=$F$2,"6","") | B10: =IFERROR(INDEX('入力シート'!$A$2:$A$41,MATCH((6-1)*2+1,'入力シート'!$E$2:$E$41,0)),"") | C10: =IFERROR(INDEX('入力シート'!$A$2:$A$41,MATCH((6-1)*2+2,'入力シート'!$E$2:$E$41,0)),"")
A11: =IF(7<=$F$2,"7","") | B11: =IFERROR(INDEX('入力シート'!$A$2:$A$41,MATCH((7-1)*2+1,'入力シート'!$E$2:$E$41,0)),"") | C11: =IFERROR(INDEX('入力シート'!$A$2:$A$41,MATCH((7-1)*2+2,'入力シート'!$E$2:$E$41,0)),"")
A12: =IF(8<=$F$2,"8","") | B12: =IFERROR(INDEX('入力シート'!$A$2:$A$41,MATCH((8-1)*2+1,'入力シート'!$E$2:$E$41,0)),"") | C12: =IFERROR(INDEX('入力シート'!$A$2:$A$41,MATCH((8-1)*2+2,'入力シート'!$E$2:$E$41,0)),"")
A13: =IF(9<=$F$2,"9","") | B13: =IFERROR(INDEX('入力シート'!$A$2:$A$41,MATCH((9-1)*2+1,'入力シート'!$E$2:$E$41,0)),"") | C13: =IFERROR(INDEX('入力シート'!$A$2:$A$41,MATCH((9-1)*2+2,'入力シート'!$E$2:$E$41,0)),"")
A14: =IF(10<=$F$2,"10","") | B14: =IFERROR(INDEX('入力シート'!$A$2:$A$41,MATCH((10-1)*2+1,'入力シート'!$E$2:$E$41,0)),"") | C14: =IFERROR(INDEX('入力シート'!$A$2:$A$41,MATCH((10-1)*2+2,'入力シート'!$E$2:$E$41,0)),"")
A15: =IF(11<=$F$2,"11","") | B15: =IFERROR(INDEX('入力シート'!$A$2:$A$41,MATCH((11-1)*2+1,'入力シート'!$E$2:$E$41,0)),"") | C15: =IFERROR(INDEX('入力シート'!$A$2:$A$41,MATCH((11-1)*2+2,'入力シート'!$E$2:$E$41,0)),"")
A16: =IF(12<=$F$2,"12","") | B16: =IFERROR(INDEX('入力シート'!$A$2:$A$41,MATCH((12-1)*2+1,'入力シート'!$E$2:$E$41,0)),"") | C16: =IFERROR(INDEX('入力シート'!$A$2:$A$41,MATCH((12-1)*2+2,'入力シート'!$E$2:$E$41,0)),"")
A17: =IF(13<=$F$2,"13","") | B17: =IFERROR(INDEX('入力シート'!$A$2:$A$41,MATCH((13-1)*2+1,'入力シート'!$E$2:$E$41,0)),"") | C17: =IFERROR(INDEX('入力シート'!$A$2:$A$41,MATCH((13-1)*2+2,'入力シート'!$E$2:$E$41,0)),"")
A18: =IF(14<=$F$2,"14","") | B18: =IFERROR(INDEX('入力シート'!$A$2:$A$41,MATCH((14-1)*2+1,'入力シート'!$E$2:$E$41,0)),"") | C18: =IFERROR(INDEX('入力シート'!$A$2:$A$41,MATCH((14-1)*2+2,'入力シート'!$E$2:$E$41,0)),"")
A19: =IF(15<=$F$2,"15","") | B19: =IFERROR(INDEX('入力シート'!$A$2:$A$41,MATCH((15-1)*2+1,'入力シート'!$E$2:$E$41,0)),"") | C19: =IFERROR(INDEX('入力シート'!$A$2:$A$41,MATCH((15-1)*2+2,'入力シート'!$E$2:$E$41,0)),"")
A20: =IF(16<=$F$2,"16","") | B20: =IFERROR(INDEX('入力シート'!$A$2:$A$41,MATCH((16-1)*2+1,'入力シート'!$E$2:$E$41,0)),"") | C20: =IFERROR(INDEX('入力シート'!$A$2:$A$41,MATCH((16-1)*2+2,'入力シート'!$E$2:$E$41,0)),"")
A21: =IF(17<=$F$2,"17","") | B21: =IFERROR(INDEX('入力シート'!$A$2:$A$41,MATCH((17-1)*2+1,'入力シート'!$E$2:$E$41,0)),"") | C21: =IFERROR(INDEX('入力シート'!$A$2:$A$41,MATCH((17-1)*2+2,'入力シート'!$E$2:$E$41,0)),"")
A22: =IF(18<=$F$2,"18","") | B22: =IFERROR(INDEX('入力シート'!$A$2:$A$41,MATCH((18-1)*2+1,'入力シート'!$E$2:$E$41,0)),"") | C22: =IFERROR(INDEX('入力シート'!$A$2:$A$41,MATCH((18-1)*2+2,'入力シート'!$E$2:$E$41,0)),"")
A23: =IF(19<=$F$2,"19","") | B23: =IFERROR(INDEX('入力シート'!$A$2:$A$41,MATCH((19-1)*2+1,'入力シート'!$E$2:$E$41,0)),"") | C23: =IFERROR(INDEX('入力シート'!$A$2:$A$41,MATCH((19-1)*2+2,'入力シート'!$E$2:$E$41,0)),"")
A24: =IF(20<=$F$2,"20","") | B24: =IFERROR(INDEX('入力シート'!$A$2:$A$41,MATCH((20-1)*2+1,'入力シート'!$E$2:$E$41,0)),"") | C24: =IFERROR(INDEX('入力シート'!$A$2:$A$41,MATCH((20-1)*2+2,'入力シート'!$E$2:$E$41,0)),"")
B25: 後ろ

Sheet 2列_縦に
A1: 背の順 2列・縦に | E1: 人数 | F1: =COUNT('入力シート'!$E$2:$E$41)
E2: 行数 | F2: =ROUNDUP(F1/2,0)
B3: 前
B4: 1列目 | C4: 2列目
A5: =IF(1<=$F$2,"1","") | B5: =IF(1>$F$2,"",IFERROR(INDEX('入力シート'!$A$2:$A$41,MATCH((1-1)*$F$2+1,'入力シート'!$E$2:$E$41,0)),"")) | C5: =IF(1>$F$2,"",IFERROR(INDEX('入力シート'!$A$2:$A$41,MATCH((2-1)*$F$2+1,'入力シート'!$E$2:$E$41,0)),""))
A6: =IF(2<=$F$2,"2","") | B6: =IF(2>$F$2,"",IFERROR(INDEX('入力シート'!$A$2:$A$41,MATCH((1-1)*$F$2+2,'入力シート'!$E$2:$E$41,0)),"")) | C6: =IF(2>$F$2,"",IFERROR(INDEX('入力シート'!$A$2:$A$41,MATCH((2-1)*$F$2+2,'入力シート'!$E$2:$E$41,0)),""))
A7: =IF(3<=$F$2,"3","") | B7: =IF(3>$F$2,"",IFERROR(INDEX('入力シート'!$A$2:$A$41,MATCH((1-1)*$F$2+3,'入力シート'!$E$2:$E$41,0)),"")) | C7: =IF(3>$F$2,"",IFERROR(INDEX('入力シート'!$A$2:$A$41,MATCH((2-1)*$F$2+3,'入力シート'!$E$2:$E$41,0)),""))
A8: =IF(4<=$F$2,"4","") | B8: =IF(4>$F$2,"",IFERROR(INDEX('入力シート'!$A$2:$A$41,MATCH((1-1)*$F$2+4,'入力シート'!$E$2:$E$41,0)),"")) | C8: =IF(4>$F$2,"",IFERROR(INDEX('入力シート'!$A$2:$A$41,MATCH((2-1)*$F$2+4,'入力シート'!$E$2:$E$41,0)),""))
A9: =IF(5<=$F$2,"5","") | B9: =IF(5>$F$2,"",IFERROR(INDEX('入力シート'!$A$2:$A$41,MATCH((1-1)*$F$2+5,'入力シート'!$E$2:$E$41,0)),"")) | C9: =IF(5>$F$2,"",IFERROR(INDEX('入力シート'!$A$2:$A$41,MATCH((2-1)*$F$2+5,'入力シート'!$E$2:$E$41,0)),""))
A10: =IF(6<=$F$2,"6","") | B10: =IF(6>$F$2,"",IFERROR(INDEX('入力シート'!$A$2:$A$41,MATCH((1-1)*$F$2+6,'入力シート'!$E$2:$E$41,0)),"")) | C10: =IF(6>$F$2,"",IFERROR(INDEX('入力シート'!$A$2:$A$41,MATCH((2-1)*$F$2+6,'入力シート'!$E$2:$E$41,0)),""))
A11: =IF(7<=$F$2,"7","") | B11: =IF(7>$F$2,"",IFERROR(INDEX('入力シート'!$A$2:$A$41,MATCH((1-1)*$F$2+7,'入力シート'!$E$2:$E$41,0)),"")) | C11: =IF(7>$F$2,"",IFERROR(INDEX('入力シート'!$A$2:$A$41,MATCH((2-1)*$F$2+7,'入力シート'!$E$2:$E$41,0)),""))
A12: =IF(8<=$F$2,"8","") | B12: =IF(8>$F$2,"",IFERROR(INDEX('入力シート'!$A$2:$A$41,MATCH((1-1)*$F$2+8,'入力シート'!$E$2:$E$41,0)),"")) | C12: =IF(8>$F$2,"",IFERROR(INDEX('入力シート'!$A$2:$A$41,MATCH((2-1)*$F$2+8,'入力シート'!$E$2:$E$41,0)),""))
A13: =IF(9<=$F$2,"9","") | B13: =IF(9>$F$2,"",IFERROR(INDEX('入力シート'!$A$2:$A$41,MATCH((1-1)*$F$2+9,'入力シート'!$E$2:$E$41,0)),"")) | C13: =IF(9>$F$2,"",IFERROR(INDEX('入力シート'!$A$2:$A$41,MATCH((2-1)*$F$2+9,'入力シート'!$E$2:$E$41,0)),""))
A14: =IF(10<=$F$2,"10","") | B14: =IF(10>$F$2,"",IFERROR(INDEX('入力シート'!$A$2:$A$41,MATCH((1-1)*$F$2+10,'入力シート'!$E$2:$E$41,0)),"")) | C14: =IF(10>$F$2,"",IFERROR(INDEX('入力シート'!$A$2:$A$41,MATCH((2-1)*$F$2+10,'入力シート'!$E$2:$E$41,0)),""))
A15: =IF(11<=$F$2,"11","") | B15: =IF(11>$F$2,"",IFERROR(INDEX('入力シート'!$A$2:$A$41,MATCH((1-1)*$F$2+11,'入力シート'!$E$2:$E$41,0)),"")) | C15: =IF(11>$F$2,"",IFERROR(INDEX('入力シート'!$A$2:$A$41,MATCH((2-1)*$F$2+11,'入力シート'!$E$2:$E$41,0)),""))
A16: =IF(12<=$F$2,"12","") | B16: =IF(12>$F$2,"",IFERROR(INDEX('入力シート'!$A$2:$A$41,MATCH((1-1)*$F$2+12,'入力シート'!$E$2:$E$41,0)),"")) | C16: =IF(12>$F$2,"",IFERROR(INDEX('入力シート'!$A$2:$A$41,MATCH((2-1)*$F$2+12,'入力シート'!$E$2:$E$41,0)),""))
A17: =IF(13<=$F$2,"13","") | B17: =IF(13>$F$2,"",IFERROR(INDEX('入力シート'!$A$2:$A$41,MATCH((1-1)*$F$2+13,'入力シート'!$E$2:$E$41,0)),"")) | C17: =IF(13>$F$2,"",IFERROR(INDEX('入力シート'!$A$2:$A$41,MATCH((2-1)*$F$2+13,'入力シート'!$E$2:$E$41,0)),""))
A18: =IF(14<=$F$2,"14","") | B18: =IF(14>$F$2,"",IFERROR(INDEX('入力シート'!$A$2:$A$41,MATCH((1-1)*$F$2+14,'入力シート'!$E$2:$E$41,0)),"")) | C18: =IF(14>$F$2,"",IFERROR(INDEX('入力シート'!$A$2:$A$41,MATCH((2-1)*$F$2+14,'入力シート'!$E$2:$E$41,0)),""))
A19: =IF(15<=$F$2,"15","") | B19: =IF(15>$F$2,"",IFERROR(INDEX('入力シート'!$A$2:$A$41,MATCH((1-1)*$F$2+15,'入力シート'!$E$2:$E$41,0)),"")) | C19: =IF(15>$F$2,"",IFERROR(INDEX('入力シート'!$A$2:$A$41,MATCH((2-1)*$F$2+15,'入力シート'!$E$2:$E$41,0)),""))
A20: =IF(16<=$F$2,"16","") | B20: =IF(16>$F$2,"",IFERROR(INDEX('入力シート'!$A$2:$A$41,MATCH((1-1)*$F$2+16,'入力シート'!$E$2:$E$41,0)),"")) | C20: =IF(16>$F$2,"",IFERROR(INDEX('入力シート'!$A$2:$A$41,MATCH((2-1)*$F$2+16,'入力シート'!$E$2:$E$41,0)),""))
A21: =IF(17<=$F$2,"17","") | B21: =IF(17>$F$2,"",IFERROR(INDEX('入力シート'!$A$2:$A$41,MATCH((1-1)*$F$2+17,'入力シート'!$E$2:$E$41,0)),"")) | C21: =IF(17>$F$2,"",IFERROR(INDEX('入力シート'!$A$2:$A$41,MATCH((2-1)*$F$2+17,'入力シート'!$E$2:$E$41,0)),""))
A22: =IF(18<=$F$2,"18","") | B22: =IF(18>$F$2,"",IFERROR(INDEX('入力シート'!$A$2:$A$41,MATCH((1-1)*$F$2+18,'入力シート'!$E$2:$E$41,0)),"")) | C22: =IF(18>$F$2,"",IFERROR(INDEX('入力シート'!$A$2:$A$41,MATCH((2-1)*$F$2+18,'入力シート'!$E$2:$E$41,0)),""))
A23: =IF(19<=$F$2,"19","") | B23: =IF(19>$F$2,"",IFERROR(INDEX('入力シート'!$A$2:$A$41,MATCH((1-1)*$F$2+19,'入力シート'!$E$2:$E$41,0)),"")) | C23: =IF(19>$F$2,"",IFERROR(INDEX('入力シート'!$A$2:$A$41,MATCH((2-1)*$F$2+19,'入力シート'!$E$2:$E$41,0)),""))
A24: =IF(20<=$F$2,"20","") | B24: =IF(20>$F$2,"",IFERROR(INDEX('入力シート'!$A$2:$A$41,MATCH((1-1)*$F$2+20,'入力シート'!$E$2:$E$41,0)),"")) | C24: =IF(20>$F$2,"",IFERROR(INDEX('入力シート'!$A$2:$A$41,MATCH((2-1)*$F$2+20,'入力シート'!$E$2:$E$41,0)),""))
B25: 後ろ

Sheet 4列_横に
A1: 背の順 4列・横に | G1: 人数 | H1: =COUNT('入力シート'!$E$2:$E$41)
G2: 行数 | H2: =ROUNDUP(H1/4,0)
B3: 前
B4: 1列目 | C4: 2列目 | D4: 3列目 | E4: 4列目
A5: =IF(1<=$H$2,"1","") | B5: =IFERROR(INDEX('入力シート'!$A$2:$A$41,MATCH((1-1)*4+1,'入力シート'!$E$2:$E$41,0)),"") | C5: =IFERROR(INDEX('入力シート'!$A$2:$A$41,MATCH((1-1)*4+2,'入力シート'!$E$2:$E$41,0)),"") | D5: =IFERROR(INDEX('入力シート'!$A$2:$A$41,MATCH((1-1)*4+3,'入力シート'!$E$2:$E$41,0)),"") | E5: =IFERROR(INDEX('入力シート'!$A$2:$A$41,MATCH((1-1)*4+4,'入力シート'!$E$2:$E$41,0)),"")
A6: =IF(2<=$H$2,"2","") | B6: =IFERROR(INDEX('入力シート'!$A$2:$A$41,MATCH((2-1)*4+1,'入力シート'!$E$2:$E$41,0)),"") | C6: =IFERROR(INDEX('入力シート'!$A$2:$A$41,MATCH((2-1)*4+2,'入力シート'!$E$2:$E$41,0)),"") | D6: =IFERROR(INDEX('入力シート'!$A$2:$A$41,MATCH((2-1)*4+3,'入力シート'!$E$2:$E$41,0)),"") | E6: =IFERROR(INDEX('入力シート'!$A$2:$A$41,MATCH((2-1)*4+4,'入力シート'!$E$2:$E$41,0)),"")
A7: =IF(3<=$H$2,"3","") | B7: =IFERROR(INDEX('入力シート'!$A$2:$A$41,MATCH((3-1)*4+1,'入力シート'!$E$2:$E$41,0)),"") | C7: =IFERROR(INDEX('入力シート'!$A$2:$A$41,MATCH((3-1)*4+2,'入力シート'!$E$2:$E$41,0)),"") | D7: =IFERROR(INDEX('入力シート'!$A$2:$A$41,MATCH((3-1)*4+3,'入力シート'!$E$2:$E$41,0)),"") | E7: =IFERROR(INDEX('入力シート'!$A$2:$A$41,MATCH((3-1)*4+4,'入力シート'!$E$2:$E$41,0)),"")
A8: =IF(4<=$H$2,"4","") | B8: =IFERROR(INDEX('入力シート'!$A$2:$A$41,MATCH((4-1)*4+1,'入力シート'!$E$2:$E$41,0)),"") | C8: =IFERROR(INDEX('入力シート'!$A$2:$A$41,MATCH((4-1)*4+2,'入力シート'!$E$2:$E$41,0)),"") | D8: =IFERROR(INDEX('入力シート'!$A$2:$A$41,MATCH((4-1)*4+3,'入力シート'!$E$2:$E$41,0)),"") | E8: =IFERROR(INDEX('入力シート'!$A$2:$A$41,MATCH((4-1)*4+4,'入力シート'!$E$2:$E$41,0)),"")
A9: =IF(5<=$H$2,"5","") | B9: =IFERROR(INDEX('入力シート'!$A$2:$A$41,MATCH((5-1)*4+1,'入力シート'!$E$2:$E$41,0)),"") | C9: =IFERROR(INDEX('入力シート'!$A$2:$A$41,MATCH((5-1)*4+2,'入力シート'!$E$2:$E$41,0)),"") | D9: =IFERROR(INDEX('入力シート'!$A$2:$A$41,MATCH((5-1)*4+3,'入力シート'!$E$2:$E$41,0)),"") | E9: =IFERROR(INDEX('入力シート'!$A$2:$A$41,MATCH((5-1)*4+4,'入力シート'!$E$2:$E$41,0)),"")
A10: =IF(6<=$H$2,"6","") | B10: =IFERROR(INDEX('入力シート'!$A$2:$A$41,MATCH((6-1)*4+1,'入力シート'!$E$2:$E$41,0)),"") | C10: =IFERROR(INDEX('入力シート'!$A$2:$A$41,MATCH((6-1)*4+2,'入力シート'!$E$2:$E$41,0)),"") | D10: =IFERROR(INDEX('入力シート'!$A$2:$A$41,MATCH((6-1)*4+3,'入力シート'!$E$2:$E$41,0)),"") | E10: =IFERROR(INDEX('入力シート'!$A$2:$A$41,MATCH((6-1)*4+4,'入力シート'!$E$2:$E$41,0)),"")
A11: =IF(7<=$H$2,"7","") | B11: =IFERROR(INDEX('入力シート'!$A$2:$A$41,MATCH((7-1)*4+1,'入力シート'!$E$2:$E$41,0)),"") | C11: =IFERROR(INDEX('入力シート'!$A$2:$A$41,MATCH((7-1)*4+2,'入力シート'!$E$2:$E$41,0)),"") | D11: =IFERROR(INDEX('入力シート'!$A$2:$A$41,MATCH((7-1)*4+3,'入力シート'!$E$2:$E$41,0)),"") | E11: =IFERROR(INDEX('入力シート'!$A$2:$A$41,MATCH((7-1)*4+4,'入力シート'!$E$2:$E$41,0)),"")
A12: =IF(8<=$H$2,"8","") | B12: =IFERROR(INDEX('入力シート'!$A$2:$A$41,MATCH((8-1)*4+1,'入力シート'!$E$2:$E$41,0)),"") | C12: =IFERROR(INDEX('入力シート'!$A$2:$A$41,MATCH((8-1)*4+2,'入力シート'!$E$2:$E$41,0)),"") | D12: =IFERROR(INDEX('入力シート'!$A$2:$A$41,MATCH((8-1)*4+3,'入力シート'!$E$2:$E$41,0)),"") | E12: =IFERROR(INDEX('入力シート'!$A$2:$A$41,MATCH((8-1)*4+4,'入力シート'!$E$2:$E$41,0)),"")
A13: =IF(9<=$H$2,"9","") | B13: =IFERROR(INDEX('入力シート'!$A$2:$A$41,MATCH((9-1)*4+1,'入力シート'!$E$2:$E$41,0)),"") | C13: =IFERROR(INDEX('入力シート'!$A$2:$A$41,MATCH((9-1)*4+2,'入力シート'!$E$2:$E$41,0)),"") | D13: =IFERROR(INDEX('入力シート'!$A$2:$A$41,MATCH((9-1)*4+3,'入力シート'!$E$2:$E$41,0)),"") | E13: =IFERROR(INDEX('入力シート'!$A$2:$A$41,MATCH((9-1)*4+4,'入力シート'!$E$2:$E$41,0)),"")
A14: =IF(10<=$H$2,"10","") | B14: =IFERROR(INDEX('入力シート'!$A$2:$A$41,MATCH((10-1)*4+1,'入力シート'!$E$2:$E$41,0)),"") | C14: =IFERROR(INDEX('入力シート'!$A$2:$A$41,MATCH((10-1)*4+2,'入力シート'!$E$2:$E$41,0)),"") | D14: =IFERROR(INDEX('入力シート'!$A$2:$A$41,MATCH((10-1)*4+3,'入力シート'!$E$2:$E$41,0)),"") | E14: =IFERROR(INDEX('入力シート'!$A$2:$A$41,MATCH((10-1)*4+4,'入力シート'!$E$2:$E$41,0)),"")
B15: 後ろ

Sheet 4列_縦に
A1: 背の順 4列・縦に | G1: 人数 | H1: =COUNT('入力シート'!$E$2:$E$41)
G2: 行数 | H2: =ROUNDUP(H1/4,0)
B3: 前
B4: 1列目 | C4: 2列目 | D4: 3列目 | E4: 4列目
A5: =IF(1<=$H$2,"1","") | B5: =IF(1>$H$2,"",IFERROR(INDEX('入力シート'!$A$2:$A$41,MATCH((1-1)*$H$2+1,'入力シート'!$E$2:$E$41,0)),"")) | C5: =IF(1>$H$2,"",IFERROR(INDEX('入力シート'!$A$2:$A$41,MATCH((2-1)*$H$2+1,'入力シート'!$E$2:$E$41,0)),"")) | D5: =IF(1>$H$2,"",IFERROR(INDEX('入力シート'!$A$2:$A$41,MATCH((3-1)*$H$2+1,'入力シート'!$E$2:$E$41,0)),"")) | E5: =IF(1>$H$2,"",IFERROR(INDEX('入力シート'!$A$2:$A$41,MATCH((4-1)*$H$2+1,'入力シート'!$E$2:$E$41,0)),""))
A6: =IF(2<=$H$2,"2","") | B6: =IF(2>$H$2,"",IFERROR(INDEX('入力シート'!$A$2:$A$41,MATCH((1-1)*$H$2+2,'入力シート'!$E$2:$E$41,0)),"")) | C6: =IF(2>$H$2,"",IFERROR(INDEX('入力シート'!$A$2:$A$41,MATCH((2-1)*$H$2+2,'入力シート'!$E$2:$E$41,0)),"")) | D6: =IF(2>$H$2,"",IFERROR(INDEX('入力シート'!$A$2:$A$41,MATCH((3-1)*$H$2+2,'入力シート'!$E$2:$E$41,0)),"")) | E6: =IF(2>$H$2,"",IFERROR(INDEX('入力シート'!$A$2:$A$41,MATCH((4-1)*$H$2+2,'入力シート'!$E$2:$E$41,0)),""))
A7: =IF(3<=$H$2,"3","") | B7: =IF(3>$H$2,"",IFERROR(INDEX('入力シート'!$A$2:$A$41,MATCH((1-1)*$H$2+3,'入力シート'!$E$2:$E$41,0)),"")) | C7: =IF(3>$H$2,"",IFERROR(INDEX('入力シート'!$A$2:$A$41,MATCH((2-1)*$H$2+3,'入力シート'!$E$2:$E$41,0)),"")) | D7: =IF(3>$H$2,"",IFERROR(INDEX('入力シート'!$A$2:$A$41,MATCH((3-1)*$H$2+3,'入力シート'!$E$2:$E$41,0)),"")) | E7: =IF(3>$H$2,"",IFERROR(INDEX('入力シート'!$A$2:$A$41,MATCH((4-1)*$H$2+3,'入力シート'!$E$2:$E$41,0)),""))
A8: =IF(4<=$H$2,"4","") | B8: =IF(4>$H$2,"",IFERROR(INDEX('入力シート'!$A$2:$A$41,MATCH((1-1)*$H$2+4,'入力シート'!$E$2:$E$41,0)),"")) | C8: =IF(4>$H$2,"",IFERROR(INDEX('入力シート'!$A$2:$A$41,MATCH((2-1)*$H$2+4,'入力シート'!$E$2:$E$41,0)),"")) | D8: =IF(4>$H$2,"",IFERROR(INDEX('入力シート'!$A$2:$A$41,MATCH((3-1)*$H$2+4,'入力シート'!$E$2:$E$41,0)),"")) | E8: =IF(4>$H$2,"",IFERROR(INDEX('入力シート'!$A$2:$A$41,MATCH((4-1)*$H$2+4,'入力シート'!$E$2:$E$41,0)),""))
A9: =IF(5<=$H$2,"5","") | B9: =IF(5>$H$2,"",IFERROR(INDEX('入力シート'!$A$2:$A$41,MATCH((1-1)*$H$2+5,'入力シート'!$E$2:$E$41,0)),"")) | C9: =IF(5>$H$2,"",IFERROR(INDEX('入力シート'!$A$2:$A$41,MATCH((2-1)*$H$2+5,'入力シート'!$E$2:$E$41,0)),"")) | D9: =IF(5>$H$2,"",IFERROR(INDEX('入力シート'!$A$2:$A$41,MATCH((3-1)*$H$2+5,'入力シート'!$E$2:$E$41,0)),"")) | E9: =IF(5>$H$2,"",IFERROR(INDEX('入力シート'!$A$2:$A$41,MATCH((4-1)*$H$2+5,'入力シート'!$E$2:$E$41,0)),""))
A10: =IF(6<=$H$2,"6","") | B10: =IF(6>$H$2,"",IFERROR(INDEX('入力シート'!$A$2:$A$41,MATCH((1-1)*$H$2+6,'入力シート'!$E$2:$E$41,0)),"")) | C10: =IF(6>$H$2,"",IFERROR(INDEX('入力シート'!$A$2:$A$41,MATCH((2-1)*$H$2+6,'入力シート'!$E$2:$E$41,0)),"")) | D10: =IF(6>$H$2,"",IFERROR(INDEX('入力シート'!$A$2:$A$41,MATCH((3-1)*$H$2+6,'入力シート'!$E$2:$E$41,0)),"")) | E10: =IF(6>$H$2,"",IFERROR(INDEX('入力シート'!$A$2:$A$41,MATCH((4-1)*$H$2+6,'入力シート'!$E$2:$E$41,0)),""))
A11: =IF(7<=$H$2,"7","") | B11: =IF(7>$H$2,"",IFERROR(INDEX('入力シート'!$A$2:$A$41,MATCH((1-1)*$H$2+7,'入力シート'!$E$2:$E$41,0)),"")) | C11: =IF(7>$H$2,"",IFERROR(INDEX('入力シート'!$A$2:$A$41,MATCH((2-1)*$H$2+7,'入力シート'!$E$2:$E$41,0)),"")) | D11: =IF(7>$H$2,"",IFERROR(INDEX('入力シート'!$A$2:$A$41,MATCH((3-1)*$H$2+7,'入力シート'!$E$2:$E$41,0)),"")) | E11: =IF(7>$H$2,"",IFERROR(INDEX('入力シート'!$A$2:$A$41,MATCH((4-1)*$H$2+7,'入力シート'!$E$2:$E$41,0)),""))
A12: =IF(8<=$H$2,"8","") | B12: =IF(8>$H$2,"",IFERROR(INDEX('入力シート'!$A$2:$A$41,MATCH((1-1)*$H$2+8,'入力シート'!$E$2:$E$41,0)),"")) | C12: =IF(8>$H$2,"",IFERROR(INDEX('入力シート'!$A$2:$A$41,MATCH((2-1)*$H$2+8,'入力シート'!$E$2:$E$41,0)),"")) | D12: =IF(8>$H$2,"",IFERROR(INDEX('入力シート'!$A$2:$A$41,MATCH((3-1)*$H$2+8,'入力シート'!$E$2:$E$41,0)),"")) | E12: =IF(8>$H$2,"",IFERROR(INDEX('入力シート'!$A$2:$A$41,MATCH((4-1)*$H$2+8,'入力シート'!$E$2:$E$41,0)),""))
A13: =IF(9<=$H$2,"9","") | B13: =IF(9>$H$2,"",IFERROR(INDEX('入力シート'!$A$2:$A$41,MATCH((1-1)*$H$2+9,'入力シート'!$E$2:$E$41,0)),"")) | C13: =IF(9>$H$2,"",IFERROR(INDEX('入力シート'!$A$2:$A$41,MATCH((2-1)*$H$2+9,'入力シート'!$E$2:$E$41,0)),"")) | D13: =IF(9>$H$2,"",IFERROR(INDEX('入力シート'!$A$2:$A$41,MATCH((3-1)*$H$2+9,'入力シート'!$E$2:$E$41,0)),"")) | E13: =IF(9>$H$2,"",IFERROR(INDEX('入力シート'!$A$2:$A$41,MATCH((4-1)*$H$2+9,'入力シート'!$E$2:$E$41,0)),""))
A14: =IF(10<=$H$2,"10","") | B14: =IF(10>$H$2,"",IFERROR(INDEX('入力シート'!$A$2:$A$41,MATCH((1-1)*$H$2+10,'入力シート'!$E$2:$E$41,0)),"")) | C14: =IF(10>$H$2,"",IFERROR(INDEX('入力シート'!$A$2:$A$41,MATCH((2-1)*$H$2+10,'入力シート'!$E$2:$E$41,0)),"")) | D14: =IF(10>$H$2,"",IFERROR(INDEX('入力シート'!$A$2:$A$41,MATCH((3-1)*$H$2+10,'入力シート'!$E$2:$E$41,0)),"")) | E14: =IF(10>$H$2,"",IFERROR(INDEX('入力シート'!$A$2:$A$41,MATCH((4-1)*$H$2+10,'入力シート'!$E$2:$E$41,0)),""))
B15: 後ろ

Sheet 1列_背の順
A1: 背の順 1列・背の順 | D1: 人数 | E1: =COUNT('入力シート'!$E$2:$E$41)
D2: 行数 | E2: =ROUNDUP(E1/1,0)
B3: 前
B4: 1列目
A5: =IF(1<=$E$2,"1","") | B5: =IFERROR(INDEX('入力シート'!$A$2:$A$41,MATCH((1-1)*1+1,'入力シート'!$E$2:$E$41,0)),"")
A6: =IF(2<=$E$2,"2","") | B6: =IFERROR(INDEX('入力シート'!$A$2:$A$41,MATCH((2-1)*1+1,'入力シート'!$E$2:$E$41,0)),"")
A7: =IF(3<=$E$2,"3","") | B7: =IFERROR(INDEX('入力シート'!$A$2:$A$41,MATCH((3-1)*1+1,'入力シート'!$E$2:$E$41,0)),"")
A8: =IF(4<=$E$2,"4","") | B8: =IFERROR(INDEX('入力シート'!$A$2:$A$41,MATCH((4-1)*1+1,'入力シート'!$E$2:$E$41,0)),"")
A9: =IF(5<=$E$2,"5","") | B9: =IFERROR(INDEX('入力シート'!$A$2:$A$41,MATCH((5-1)*1+1,'入力シート'!$E$2:$E$41,0)),"")
A10: =IF(6<=$E$2,"6","") | B10: =IFERROR(INDEX('入力シート'!$A$2:$A$41,MATCH((6-1)*1+1,'入力シート'!$E$2:$E$41,0)),"")
A11: =IF(7<=$E$2,"7","") | B11: =IFERROR(INDEX('入力シート'!$A$2:$A$41,MATCH((7-1)*1+1,'入力シート'!$E$2:$E$41,0)),"")
A12: =IF(8<=$E$2,"8","") | B12: =IFERROR(INDEX('入力シート'!$A$2:$A$41,MATCH((8-1)*1+1,'入力シート'!$E$2:$E$41,0)),"")
A13: =IF(9<=$E$2,"9","") | B13: =IFERROR(INDEX('入力シート'!$A$2:$A$41,MATCH((9-1)*1+1,'入力シート'!$E$2:$E$41,0)),"")
A14: =IF(10<=$E$2,"10","") | B14: =IFERROR(INDEX('入力シート'!$A$2:$A$41,MATCH((10-1)*1+1,'入力シート'!$E$2:$E$41,0)),"")
A15: =IF(11<=$E$2,"11","") | B15: =IFERROR(INDEX('入力シート'!$A$2:$A$41,MATCH((11-1)*1+1,'入力シート'!$E$2:$E$41,0)),"")
A16: =IF(12<=$E$2,"12","") | B16: =IFERROR(INDEX('入力シート'!$A$2:$A$41,MATCH((12-1)*1+1,'入力シート'!$E$2:$E$41,0)),"")
A17: =IF(13<=$E$2,"13","") | B17: =IFERROR(INDEX('入力シート'!$A$2:$A$41,MATCH((13-1)*1+1,'入力シート'!$E$2:$E$41,0)),"")
A18: =IF(14<=$E$2,"14","") | B18: =IFERROR(INDEX('入力シート'!$A$2:$A$41,MATCH((14-1)*1+1,'入力シート'!$E$2:$E$41,0)),"")
A19: =IF(15<=$E$2,"15","") | B19: =IFERROR(INDEX('入力シート'!$A$2:$A$41,MATCH((15-1)*1+1,'入力シート'!$E$2:$E$41,0)),"")
A20: =IF(16<=$E$2,"16","") | B20: =IFERROR(INDEX('入力シート'!$A$2:$A$41,MATCH((16-1)*1+1,'入力シート'!$E$2:$E$41,0)),"")
A21: =IF(17<=$E$2,"17","") | B21: =IFERROR(INDEX('入力シート'!$A$2:$A$41,MATCH((17-1)*1+1,'入力シート'!$E$2:$E$41,0)),"")
A22: =IF(18<=$E$2,"18","") | B22: =IFERROR(INDEX('入力シート'!$A$2:$A$41,MATCH((18-1)*1+1,'入力シート'!$E$2:$E$41,0)),"")
A23: =IF(19<=$E$2,"19","") | B23: =IFERROR(INDEX('入力シート'!$A$2:$A$41,MATCH((19-1)*1+1,'入力シート'!$E$2:$E$41,0)),"")
A24: =IF(20<=$E$2,"20","") | B24: =IFERROR(INDEX('入力シート'!$A$2:$A$41,MATCH((20-1)*1+1,'入力シート'!$E$2:$E$41,0)),"")
A25: =IF(21<=$E$2,"21","") | B25: =IFERROR(INDEX('入力シート'!$A$2:$A$41,MATCH((21-1)*1+1,'入力シート'!$E$2:$E$41,0)),"")
A26: =IF(22<=$E$2,"22","") | B26: =IFERROR(INDEX('入力シート'!$A$2:$A$41,MATCH((22-1)*1+1,'入力シート'!$E$2:$E$41,0)),"")
A27: =IF(23<=$E$2,"23","") | B27: =IFERROR(INDEX('入力シート'!$A$2:$A$41,MATCH((23-1)*1+1,'入力シート'!$E$2:$E$41,0)),"")
A28: =IF(24<=$E$2,"24","") | B28: =IFERROR(INDEX('入力シート'!$A$2:$A$41,MATCH((24-1)*1+1,'入力シート'!$E$2:$E$41,0)),"")
A29: =IF(25<=$E$2,"25","") | B29: =IFERROR(INDEX('入力シート'!$A$2:$A$41,MATCH((25-1)*1+1,'入力シート'!$E$2:$E$41,0)),"")
A30: =IF(26<=$E$2,"26","") | B30: =IFERROR(INDEX('入力シート'!$A$2:$A$41,MATCH((26-1)*1+1,'入力シート'!$E$2:$E$41,0)),"")
A31: =IF(27<=$E$2,"27","") | B31: =IFERROR(INDEX('入力シート'!$A$2:$A$41,MATCH((27-1)*1+1,'入力シート'!$E$2:$E$41,0)),"")
A32: =IF(28<=$E$2,"28","") | B32: =IFERROR(INDEX('入力シート'!$A$2:$A$41,MATCH((28-1)*1+1,'入力シート'!$E$2:$E$41,0)),"")
A33: =IF(29<=$E$2,"29","") | B33: =IFERROR(INDEX('入力シート'!$A$2:$A$41,MATCH((29-1)*1+1,'入力シート'!$E$2:$E$41,0)),"")
A34: =IF(30<=$E$2,"30","") | B34: =IFERROR(INDEX('入力シート'!$A$2:$A$41,MATCH((30-1)*1+1,'入力シート'!$E$2:$E$41,0)),"")
A35: =IF(31<=$E$2,"31","") | B35: =IFERROR(INDEX('入力シート'!$A$2:$A$41,MATCH((31-1)*1+1,'入力シート'!$E$2:$E$41,0)),"")
A36: =IF(32<=$E$2,"32","") | B36: =IFERROR(INDEX('入力シート'!$A$2:$A$41,MATCH((32-1)*1+1,'入力シート'!$E$2:$E$41,0)),"")
A37: =IF(33<=$E$2,"33","") | B37: =IFERROR(INDEX('入力シート'!$A$2:$A$41,MATCH((33-1)*1+1,'入力シート'!$E$2:$E$41,0)),"")
A38: =IF(34<=$E$2,"34","") | B38: =IFERROR(INDEX('入力シート'!$A$2:$A$41,MATCH((34-1)*1+1,'入力シート'!$E$2:$E$41,0)),"")
A39: =IF(35<=$E$2,"35","") | B39: =IFERROR(INDEX('入力シート'!$A$2:$A$41,MATCH((35-1)*1+1,'入力シート'!$E$2:$E$41,0)),"")
A40: =IF(36<=$E$2,"36","") | B40: =IFERROR(INDEX('入力シート'!$A$2:$A$41,MATCH((36-1)*1+1,'入力シート'!$E$2:$E$41,0)),"")
...
