Workbook

Sheet 入力シート
A1: 名前 | B1: 身長(cm) | C1: 男女 | D1: 自動の順番 | E1: 手動の順番 (入れ替えたい時だけ) | F1: 決定の順番 | G1: 男女別の順番 | H1: チェック | I1: 計算用 | K1: 使い方
D2: =IF(OR(A2="",B2=""),"",COUNTIF($B$2:$B$41,"<"&B2)+COUNTIF($B$2:B2,B2)) | F2: =IF(D2="","",IF(E2="",D2,E2)) | G2: =IF(OR(F2="",AND(C2<>"男",C2<>"女")),"",COUNTIFS($C$2:$C$41,C2,$F$2:$F$41,"<"&F2)+1) | H2: =IF(F2="","",IF(COUNTIF($F$2:$F$41,F2)>1,"⚠ 順番が重複",IF(F2>COUNT($F$2:$F$41),"⚠ 番号が大きすぎ",IF(G2="","男女が未入力","")))) | I2: =IF(G2="","",C2&G2) | K2: ① 黄色の「名前」「身長」「男女」を入れる（貼り付けOK・最大40人）
D3: =IF(OR(A3="",B3=""),"",COUNTIF($B$2:$B$41,"<"&B3)+COUNTIF($B$2:B3,B3)) | F3: =IF(D3="","",IF(E3="",D3,E3)) | G3: =IF(OR(F3="",AND(C3<>"男",C3<>"女")),"",COUNTIFS($C$2:$C$41,C3,$F$2:$F$41,"<"&F3)+1) | H3: =IF(F3="","",IF(COUNTIF($F$2:$F$41,F3)>1,"⚠ 順番が重複",IF(F3>COUNT($F$2:$F$41),"⚠ 番号が大きすぎ",IF(G3="","男女が未入力","")))) | I3: =IF(G3="","",C3&G3) | K3: ② 「1・2列」「4列」シートに背の順が自動でできる（上が前・下が前の両方）
D4: =IF(OR(A4="",B4=""),"",COUNTIF($B$2:$B$41,"<"&B4)+COUNTIF($B$2:B4,B4)) | F4: =IF(D4="","",IF(E4="",D4,E4)) | G4: =IF(OR(F4="",AND(C4<>"男",C4<>"女")),"",COUNTIFS($C$2:$C$41,C4,$F$2:$F$41,"<"&F4)+1) | H4: =IF(F4="","",IF(COUNTIF($F$2:$F$41,F4)>1,"⚠ 順番が重複",IF(F4>COUNT($F$2:$F$41),"⚠ 番号が大きすぎ",IF(G4="","男女が未入力","")))) | I4: =IF(G4="","",C4&G4) | K4: ③ 印刷したい並びの黄色いマスに ○ を入れる → 「印刷用」シートにまとまる
D5: =IF(OR(A5="",B5=""),"",COUNTIF($B$2:$B$41,"<"&B5)+COUNTIF($B$2:B5,B5)) | F5: =IF(D5="","",IF(E5="",D5,E5)) | G5: =IF(OR(F5="",AND(C5<>"男",C5<>"女")),"",COUNTIFS($C$2:$C$41,C5,$F$2:$F$41,"<"&F5)+1) | H5: =IF(F5="","",IF(COUNTIF($F$2:$F$41,F5)>1,"⚠ 順番が重複",IF(F5>COUNT($F$2:$F$41),"⚠ 番号が大きすぎ",IF(G5="","男女が未入力","")))) | I5: =IF(G5="","",C5&G5) | K5: 印刷用は A4 1枚：2列は2つまで、4列は4つまで
D6: =IF(OR(A6="",B6=""),"",COUNTIF($B$2:$B$41,"<"&B6)+COUNTIF($B$2:B6,B6)) | F6: =IF(D6="","",IF(E6="",D6,E6)) | G6: =IF(OR(F6="",AND(C6<>"男",C6<>"女")),"",COUNTIFS($C$2:$C$41,C6,$F$2:$F$41,"<"&F6)+1) | H6: =IF(F6="","",IF(COUNTIF($F$2:$F$41,F6)>1,"⚠ 順番が重複",IF(F6>COUNT($F$2:$F$41),"⚠ 番号が大きすぎ",IF(G6="","男女が未入力","")))) | I6: =IF(G6="","",C6&G6) | K6: ④ 入れ替えたい時は「手動の順番」に番号を入れる
D7: =IF(OR(A7="",B7=""),"",COUNTIF($B$2:$B$41,"<"&B7)+COUNTIF($B$2:B7,B7)) | F7: =IF(D7="","",IF(E7="",D7,E7)) | G7: =IF(OR(F7="",AND(C7<>"男",C7<>"女")),"",COUNTIFS($C$2:$C$41,C7,$F$2:$F$41,"<"&F7)+1) | H7: =IF(F7="","",IF(COUNTIF($F$2:$F$41,F7)>1,"⚠ 順番が重複",IF(F7>COUNT($F$2:$F$41),"⚠ 番号が大きすぎ",IF(G7="","男女が未入力","")))) | I7: =IF(G7="","",C7&G7) | K7: 例：5番と6番を入れ替える → 5番の子に 6、6番の子に 5
D8: =IF(OR(A8="",B8=""),"",COUNTIF($B$2:$B$41,"<"&B8)+COUNTIF($B$2:B8,B8)) | F8: =IF(D8="","",IF(E8="",D8,E8)) | G8: =IF(OR(F8="",AND(C8<>"男",C8<>"女")),"",COUNTIFS($C$2:$C$41,C8,$F$2:$F$41,"<"&F8)+1) | H8: =IF(F8="","",IF(COUNTIF($F$2:$F$41,F8)>1,"⚠ 順番が重複",IF(F8>COUNT($F$2:$F$41),"⚠ 番号が大きすぎ",IF(G8="","男女が未入力","")))) | I8: =IF(G8="","",C8&G8) | K8: 「チェック」に ⚠ が出たら番号が重なっています
D9: =IF(OR(A9="",B9=""),"",COUNTIF($B$2:$B$41,"<"&B9)+COUNTIF($B$2:B9,B9)) | F9: =IF(D9="","",IF(E9="",D9,E9)) | G9: =IF(OR(F9="",AND(C9<>"男",C9<>"女")),"",COUNTIFS($C$2:$C$41,C9,$F$2:$F$41,"<"&F9)+1) | H9: =IF(F9="","",IF(COUNTIF($F$2:$F$41,F9)>1,"⚠ 順番が重複",IF(F9>COUNT($F$2:$F$41),"⚠ 番号が大きすぎ",IF(G9="","男女が未入力","")))) | I9: =IF(G9="","",C9&G9) | K9: ※ 同じ身長の子は、上の行に書いた子が前になります
D10: =IF(OR(A10="",B10=""),"",COUNTIF($B$2:$B$41,"<"&B10)+COUNTIF($B$2:B10,B10)) | F10: =IF(D10="","",IF(E10="",D10,E10)) | G10: =IF(OR(F10="",AND(C10<>"男",C10<>"女")),"",COUNTIFS($C$2:$C$41,C10,$F$2:$F$41,"<"&F10)+1) | H10: =IF(F10="","",IF(COUNTIF($F$2:$F$41,F10)>1,"⚠ 順番が重複",IF(F10>COUNT($F$2:$F$41),"⚠ 番号が大きすぎ",IF(G10="","男女が未入力","")))) | I10: =IF(G10="","",C10&G10) | K10: ※ 灰色のセルは自動計算です（さわらないでください）
D11: =IF(OR(A11="",B11=""),"",COUNTIF($B$2:$B$41,"<"&B11)+COUNTIF($B$2:B11,B11)) | F11: =IF(D11="","",IF(E11="",D11,E11)) | G11: =IF(OR(F11="",AND(C11<>"男",C11<>"女")),"",COUNTIFS($C$2:$C$41,C11,$F$2:$F$41,"<"&F11)+1) | H11: =IF(F11="","",IF(COUNTIF($F$2:$F$41,F11)>1,"⚠ 順番が重複",IF(F11>COUNT($F$2:$F$41),"⚠ 番号が大きすぎ",IF(G11="","男女が未入力","")))) | I11: =IF(G11="","",C11&G11)
D12: =IF(OR(A12="",B12=""),"",COUNTIF($B$2:$B$41,"<"&B12)+COUNTIF($B$2:B12,B12)) | F12: =IF(D12="","",IF(E12="",D12,E12)) | G12: =IF(OR(F12="",AND(C12<>"男",C12<>"女")),"",COUNTIFS($C$2:$C$41,C12,$F$2:$F$41,"<"&F12)+1) | H12: =IF(F12="","",IF(COUNTIF($F$2:$F$41,F12)>1,"⚠ 順番が重複",IF(F12>COUNT($F$2:$F$41),"⚠ 番号が大きすぎ",IF(G12="","男女が未入力","")))) | I12: =IF(G12="","",C12&G12)
D13: =IF(OR(A13="",B13=""),"",COUNTIF($B$2:$B$41,"<"&B13)+COUNTIF($B$2:B13,B13)) | F13: =IF(D13="","",IF(E13="",D13,E13)) | G13: =IF(OR(F13="",AND(C13<>"男",C13<>"女")),"",COUNTIFS($C$2:$C$41,C13,$F$2:$F$41,"<"&F13)+1) | H13: =IF(F13="","",IF(COUNTIF($F$2:$F$41,F13)>1,"⚠ 順番が重複",IF(F13>COUNT($F$2:$F$41),"⚠ 番号が大きすぎ",IF(G13="","男女が未入力","")))) | I13: =IF(G13="","",C13&G13) | K13: 入力した人数 | M13: =COUNT($F$2:$F$41)
D14: =IF(OR(A14="",B14=""),"",COUNTIF($B$2:$B$41,"<"&B14)+COUNTIF($B$2:B14,B14)) | F14: =IF(D14="","",IF(E14="",D14,E14)) | G14: =IF(OR(F14="",AND(C14<>"男",C14<>"女")),"",COUNTIFS($C$2:$C$41,C14,$F$2:$F$41,"<"&F14)+1) | H14: =IF(F14="","",IF(COUNTIF($F$2:$F$41,F14)>1,"⚠ 順番が重複",IF(F14>COUNT($F$2:$F$41),"⚠ 番号が大きすぎ",IF(G14="","男女が未入力","")))) | I14: =IF(G14="","",C14&G14) | K14: 男子 | M14: =COUNTIF($I$2:$I$41,"男*")
D15: =IF(OR(A15="",B15=""),"",COUNTIF($B$2:$B$41,"<"&B15)+COUNTIF($B$2:B15,B15)) | F15: =IF(D15="","",IF(E15="",D15,E15)) | G15: =IF(OR(F15="",AND(C15<>"男",C15<>"女")),"",COUNTIFS($C$2:$C$41,C15,$F$2:$F$41,"<"&F15)+1) | H15: =IF(F15="","",IF(COUNTIF($F$2:$F$41,F15)>1,"⚠ 順番が重複",IF(F15>COUNT($F$2:$F$41),"⚠ 番号が大きすぎ",IF(G15="","男女が未入力","")))) | I15: =IF(G15="","",C15&G15) | K15: 女子 | M15: =COUNTIF($I$2:$I$41,"女*")
D16: =IF(OR(A16="",B16=""),"",COUNTIF($B$2:$B$41,"<"&B16)+COUNTIF($B$2:B16,B16)) | F16: =IF(D16="","",IF(E16="",D16,E16)) | G16: =IF(OR(F16="",AND(C16<>"男",C16<>"女")),"",COUNTIFS($C$2:$C$41,C16,$F$2:$F$41,"<"&F16)+1) | H16: =IF(F16="","",IF(COUNTIF($F$2:$F$41,F16)>1,"⚠ 順番が重複",IF(F16>COUNT($F$2:$F$41),"⚠ 番号が大きすぎ",IF(G16="","男女が未入力","")))) | I16: =IF(G16="","",C16&G16) | K16: 男女が未入力 | M16: =M13-M14-M15
D17: =IF(OR(A17="",B17=""),"",COUNTIF($B$2:$B$41,"<"&B17)+COUNTIF($B$2:B17,B17)) | F17: =IF(D17="","",IF(E17="",D17,E17)) | G17: =IF(OR(F17="",AND(C17<>"男",C17<>"女")),"",COUNTIFS($C$2:$C$41,C17,$F$2:$F$41,"<"&F17)+1) | H17: =IF(F17="","",IF(COUNTIF($F$2:$F$41,F17)>1,"⚠ 順番が重複",IF(F17>COUNT($F$2:$F$41),"⚠ 番号が大きすぎ",IF(G17="","男女が未入力","")))) | I17: =IF(G17="","",C17&G17) | K17: 順番の重複 | M17: =IF(COUNTIF($H$2:$H$41,"⚠*")=0,"なし","あり（チェック欄を見てください）")
D18: =IF(OR(A18="",B18=""),"",COUNTIF($B$2:$B$41,"<"&B18)+COUNTIF($B$2:B18,B18)) | F18: =IF(D18="","",IF(E18="",D18,E18)) | G18: =IF(OR(F18="",AND(C18<>"男",C18<>"女")),"",COUNTIFS($C$2:$C$41,C18,$F$2:$F$41,"<"&F18)+1) | H18: =IF(F18="","",IF(COUNTIF($F$2:$F$41,F18)>1,"⚠ 順番が重複",IF(F18>COUNT($F$2:$F$41),"⚠ 番号が大きすぎ",IF(G18="","男女が未入力","")))) | I18: =IF(G18="","",C18&G18)
D19: =IF(OR(A19="",B19=""),"",COUNTIF($B$2:$B$41,"<"&B19)+COUNTIF($B$2:B19,B19)) | F19: =IF(D19="","",IF(E19="",D19,E19)) | G19: =IF(OR(F19="",AND(C19<>"男",C19<>"女")),"",COUNTIFS($C$2:$C$41,C19,$F$2:$F$41,"<"&F19)+1) | H19: =IF(F19="","",IF(COUNTIF($F$2:$F$41,F19)>1,"⚠ 順番が重複",IF(F19>COUNT($F$2:$F$41),"⚠ 番号が大きすぎ",IF(G19="","男女が未入力","")))) | I19: =IF(G19="","",C19&G19)
D20: =IF(OR(A20="",B20=""),"",COUNTIF($B$2:$B$41,"<"&B20)+COUNTIF($B$2:B20,B20)) | F20: =IF(D20="","",IF(E20="",D20,E20)) | G20: =IF(OR(F20="",AND(C20<>"男",C20<>"女")),"",COUNTIFS($C$2:$C$41,C20,$F$2:$F$41,"<"&F20)+1) | H20: =IF(F20="","",IF(COUNTIF($F$2:$F$41,F20)>1,"⚠ 順番が重複",IF(F20>COUNT($F$2:$F$41),"⚠ 番号が大きすぎ",IF(G20="","男女が未入力","")))) | I20: =IF(G20="","",C20&G20)
D21: =IF(OR(A21="",B21=""),"",COUNTIF($B$2:$B$41,"<"&B21)+COUNTIF($B$2:B21,B21)) | F21: =IF(D21="","",IF(E21="",D21,E21)) | G21: =IF(OR(F21="",AND(C21<>"男",C21<>"女")),"",COUNTIFS($C$2:$C$41,C21,$F$2:$F$41,"<"&F21)+1) | H21: =IF(F21="","",IF(COUNTIF($F$2:$F$41,F21)>1,"⚠ 順番が重複",IF(F21>COUNT($F$2:$F$41),"⚠ 番号が大きすぎ",IF(G21="","男女が未入力","")))) | I21: =IF(G21="","",C21&G21)
D22: =IF(OR(A22="",B22=""),"",COUNTIF($B$2:$B$41,"<"&B22)+COUNTIF($B$2:B22,B22)) | F22: =IF(D22="","",IF(E22="",D22,E22)) | G22: =IF(OR(F22="",AND(C22<>"男",C22<>"女")),"",COUNTIFS($C$2:$C$41,C22,$F$2:$F$41,"<"&F22)+1) | H22: =IF(F22="","",IF(COUNTIF($F$2:$F$41,F22)>1,"⚠ 順番が重複",IF(F22>COUNT($F$2:$F$41),"⚠ 番号が大きすぎ",IF(G22="","男女が未入力","")))) | I22: =IF(G22="","",C22&G22)
D23: =IF(OR(A23="",B23=""),"",COUNTIF($B$2:$B$41,"<"&B23)+COUNTIF($B$2:B23,B23)) | F23: =IF(D23="","",IF(E23="",D23,E23)) | G23: =IF(OR(F23="",AND(C23<>"男",C23<>"女")),"",COUNTIFS($C$2:$C$41,C23,$F$2:$F$41,"<"&F23)+1) | H23: =IF(F23="","",IF(COUNTIF($F$2:$F$41,F23)>1,"⚠ 順番が重複",IF(F23>COUNT($F$2:$F$41),"⚠ 番号が大きすぎ",IF(G23="","男女が未入力","")))) | I23: =IF(G23="","",C23&G23)
D24: =IF(OR(A24="",B24=""),"",COUNTIF($B$2:$B$41,"<"&B24)+COUNTIF($B$2:B24,B24)) | F24: =IF(D24="","",IF(E24="",D24,E24)) | G24: =IF(OR(F24="",AND(C24<>"男",C24<>"女")),"",COUNTIFS($C$2:$C$41,C24,$F$2:$F$41,"<"&F24)+1) | H24: =IF(F24="","",IF(COUNTIF($F$2:$F$41,F24)>1,"⚠ 順番が重複",IF(F24>COUNT($F$2:$F$41),"⚠ 番号が大きすぎ",IF(G24="","男女が未入力","")))) | I24: =IF(G24="","",C24&G24)
D25: =IF(OR(A25="",B25=""),"",COUNTIF($B$2:$B$41,"<"&B25)+COUNTIF($B$2:B25,B25)) | F25: =IF(D25="","",IF(E25="",D25,E25)) | G25: =IF(OR(F25="",AND(C25<>"男",C25<>"女")),"",COUNTIFS($C$2:$C$41,C25,$F$2:$F$41,"<"&F25)+1) | H25: =IF(F25="","",IF(COUNTIF($F$2:$F$41,F25)>1,"⚠ 順番が重複",IF(F25>COUNT($F$2:$F$41),"⚠ 番号が大きすぎ",IF(G25="","男女が未入力","")))) | I25: =IF(G25="","",C25&G25)
D26: =IF(OR(A26="",B26=""),"",COUNTIF($B$2:$B$41,"<"&B26)+COUNTIF($B$2:B26,B26)) | F26: =IF(D26="","",IF(E26="",D26,E26)) | G26: =IF(OR(F26="",AND(C26<>"男",C26<>"女")),"",COUNTIFS($C$2:$C$41,C26,$F$2:$F$41,"<"&F26)+1) | H26: =IF(F26="","",IF(COUNTIF($F$2:$F$41,F26)>1,"⚠ 順番が重複",IF(F26>COUNT($F$2:$F$41),"⚠ 番号が大きすぎ",IF(G26="","男女が未入力","")))) | I26: =IF(G26="","",C26&G26)
D27: =IF(OR(A27="",B27=""),"",COUNTIF($B$2:$B$41,"<"&B27)+COUNTIF($B$2:B27,B27)) | F27: =IF(D27="","",IF(E27="",D27,E27)) | G27: =IF(OR(F27="",AND(C27<>"男",C27<>"女")),"",COUNTIFS($C$2:$C$41,C27,$F$2:$F$41,"<"&F27)+1) | H27: =IF(F27="","",IF(COUNTIF($F$2:$F$41,F27)>1,"⚠ 順番が重複",IF(F27>COUNT($F$2:$F$41),"⚠ 番号が大きすぎ",IF(G27="","男女が未入力","")))) | I27: =IF(G27="","",C27&G27)
D28: =IF(OR(A28="",B28=""),"",COUNTIF($B$2:$B$41,"<"&B28)+COUNTIF($B$2:B28,B28)) | F28: =IF(D28="","",IF(E28="",D28,E28)) | G28: =IF(OR(F28="",AND(C28<>"男",C28<>"女")),"",COUNTIFS($C$2:$C$41,C28,$F$2:$F$41,"<"&F28)+1) | H28: =IF(F28="","",IF(COUNTIF($F$2:$F$41,F28)>1,"⚠ 順番が重複",IF(F28>COUNT($F$2:$F$41),"⚠ 番号が大きすぎ",IF(G28="","男女が未入力","")))) | I28: =IF(G28="","",C28&G28)
D29: =IF(OR(A29="",B29=""),"",COUNTIF($B$2:$B$41,"<"&B29)+COUNTIF($B$2:B29,B29)) | F29: =IF(D29="","",IF(E29="",D29,E29)) | G29: =IF(OR(F29="",AND(C29<>"男",C29<>"女")),"",COUNTIFS($C$2:$C$41,C29,$F$2:$F$41,"<"&F29)+1) | H29: =IF(F29="","",IF(COUNTIF($F$2:$F$41,F29)>1,"⚠ 順番が重複",IF(F29>COUNT($F$2:$F$41),"⚠ 番号が大きすぎ",IF(G29="","男女が未入力","")))) | I29: =IF(G29="","",C29&G29)
... D41: =IF(OR(A41="",B41=""),"",COUNTIF($B$2:$B$41,"<"&B41)+COUNTIF($B$2:B41,B41)) | F41: =IF(D41="","",IF(E41="",D41,E41)) | G41: =IF(OR(F41="",AND(C41<>"男",C41<>"女")),"",COUNTIFS($C$2:$C$41,C41,$F$2:$F$41,"<"&F41)+1) | H41: =IF(F41="","",IF(COUNTIF($F$2:$F$41,F41)>1,"⚠ 順番が重複",IF(F41>COUNT($F$2:$F$41),"⚠ 番号が大きすぎ",IF(G41="","男女が未入力","")))) | I41: =IF(G41="","",C41&G41)

Sheet 1・2列
A1: 背の順 1・2列
A2: 上が前・下が前を両方出しています。印刷したい並びの黄色いマスに ○ を入れると「印刷用」シートに出ます。
A4: 1列
B5: 上が前 | F5: 下が前
A7: =IF(0=1,"後ろ","前") | B7: =IF(ISNUMBER($A7),IFERROR(INDEX('入力シート'!$A$2:$A$41,MATCH($A7,'入力シート'!$F$2:$F$41,0)),""),"") | E7: =IF(1=1,"後ろ","前") | F7: =IF(ISNUMBER($E7),IFERROR(INDEX('入力シート'!$A$2:$A$41,MATCH($E7,'入力シート'!$F$2:$F$41,0)),""),"")
A8: =IF(1<='入力シート'!$M$13,IF(0=1,'入力シート'!$M$13+1-1,1),IF(1='入力シート'!$M$13+1,IF(0=1,"前","後ろ"),"")) | B8: =IF(ISNUMBER($A8),IFERROR(INDEX('入力シート'!$A$2:$A$41,MATCH($A8,'入力シート'!$F$2:$F$41,0)),""),"") | E8: =IF(1<='入力シート'!$M$13,IF(1=1,'入力シート'!$M$13+1-1,1),IF(1='入力シート'!$M$13+1,IF(1=1,"前","後ろ"),"")) | F8: =IF(ISNUMBER($E8),IFERROR(INDEX('入力シート'!$A$2:$A$41,MATCH($E8,'入力シート'!$F$2:$F$41,0)),""),"")
A9: =IF(2<='入力シート'!$M$13,IF(0=1,'入力シート'!$M$13+1-2,2),IF(2='入力シート'!$M$13+1,IF(0=1,"前","後ろ"),"")) | B9: =IF(ISNUMBER($A9),IFERROR(INDEX('入力シート'!$A$2:$A$41,MATCH($A9,'入力シート'!$F$2:$F$41,0)),""),"") | E9: =IF(2<='入力シート'!$M$13,IF(1=1,'入力シート'!$M$13+1-2,2),IF(2='入力シート'!$M$13+1,IF(1=1,"前","後ろ"),"")) | F9: =IF(ISNUMBER($E9),IFERROR(INDEX('入力シート'!$A$2:$A$41,MATCH($E9,'入力シート'!$F$2:$F$41,0)),""),"")
A10: =IF(3<='入力シート'!$M$13,IF(0=1,'入力シート'!$M$13+1-3,3),IF(3='入力シート'!$M$13+1,IF(0=1,"前","後ろ"),"")) | B10: =IF(ISNUMBER($A10),IFERROR(INDEX('入力シート'!$A$2:$A$41,MATCH($A10,'入力シート'!$F$2:$F$41,0)),""),"") | E10: =IF(3<='入力シート'!$M$13,IF(1=1,'入力シート'!$M$13+1-3,3),IF(3='入力シート'!$M$13+1,IF(1=1,"前","後ろ"),"")) | F10: =IF(ISNUMBER($E10),IFERROR(INDEX('入力シート'!$A$2:$A$41,MATCH($E10,'入力シート'!$F$2:$F$41,0)),""),"")
A11: =IF(4<='入力シート'!$M$13,IF(0=1,'入力シート'!$M$13+1-4,4),IF(4='入力シート'!$M$13+1,IF(0=1,"前","後ろ"),"")) | B11: =IF(ISNUMBER($A11),IFERROR(INDEX('入力シート'!$A$2:$A$41,MATCH($A11,'入力シート'!$F$2:$F$41,0)),""),"") | E11: =IF(4<='入力シート'!$M$13,IF(1=1,'入力シート'!$M$13+1-4,4),IF(4='入力シート'!$M$13+1,IF(1=1,"前","後ろ"),"")) | F11: =IF(ISNUMBER($E11),IFERROR(INDEX('入力シート'!$A$2:$A$41,MATCH($E11,'入力シート'!$F$2:$F$41,0)),""),"")
A12: =IF(5<='入力シート'!$M$13,IF(0=1,'入力シート'!$M$13+1-5,5),IF(5='入力シート'!$M$13+1,IF(0=1,"前","後ろ"),"")) | B12: =IF(ISNUMBER($A12),IFERROR(INDEX('入力シート'!$A$2:$A$41,MATCH($A12,'入力シート'!$F$2:$F$41,0)),""),"") | E12: =IF(5<='入力シート'!$M$13,IF(1=1,'入力シート'!$M$13+1-5,5),IF(5='入力シート'!$M$13+1,IF(1=1,"前","後ろ"),"")) | F12: =IF(ISNUMBER($E12),IFERROR(INDEX('入力シート'!$A$2:$A$41,MATCH($E12,'入力シート'!$F$2:$F$41,0)),""),"")
A13: =IF(6<='入力シート'!$M$13,IF(0=1,'入力シート'!$M$13+1-6,6),IF(6='入力シート'!$M$13+1,IF(0=1,"前","後ろ"),"")) | B13: =IF(ISNUMBER($A13),IFERROR(INDEX('入力シート'!$A$2:$A$41,MATCH($A13,'入力シート'!$F$2:$F$41,0)),""),"") | E13: =IF(6<='入力シート'!$M$13,IF(1=1,'入力シート'!$M$13+1-6,6),IF(6='入力シート'!$M$13+1,IF(1=1,"前","後ろ"),"")) | F13: =IF(ISNUMBER($E13),IFERROR(INDEX('入力シート'!$A$2:$A$41,MATCH($E13,'入力シート'!$F$2:$F$41,0)),""),"")
A14: =IF(7<='入力シート'!$M$13,IF(0=1,'入力シート'!$M$13+1-7,7),IF(7='入力シート'!$M$13+1,IF(0=1,"前","後ろ"),"")) | B14: =IF(ISNUMBER($A14),IFERROR(INDEX('入力シート'!$A$2:$A$41,MATCH($A14,'入力シート'!$F$2:$F$41,0)),""),"") | E14: =IF(7<='入力シート'!$M$13,IF(1=1,'入力シート'!$M$13+1-7,7),IF(7='入力シート'!$M$13+1,IF(1=1,"前","後ろ"),"")) | F14: =IF(ISNUMBER($E14),IFERROR(INDEX('入力シート'!$A$2:$A$41,MATCH($E14,'入力シート'!$F$2:$F$41,0)),""),"")
A15: =IF(8<='入力シート'!$M$13,IF(0=1,'入力シート'!$M$13+1-8,8),IF(8='入力シート'!$M$13+1,IF(0=1,"前","後ろ"),"")) | B15: =IF(ISNUMBER($A15),IFERROR(INDEX('入力シート'!$A$2:$A$41,MATCH($A15,'入力シート'!$F$2:$F$41,0)),""),"") | E15: =IF(8<='入力シート'!$M$13,IF(1=1,'入力シート'!$M$13+1-8,8),IF(8='入力シート'!$M$13+1,IF(1=1,"前","後ろ"),"")) | F15: =IF(ISNUMBER($E15),IFERROR(INDEX('入力シート'!$A$2:$A$41,MATCH($E15,'入力シート'!$F$2:$F$41,0)),""),"")
A16: =IF(9<='入力シート'!$M$13,IF(0=1,'入力シート'!$M$13+1-9,9),IF(9='入力シート'!$M$13+1,IF(0=1,"前","後ろ"),"")) | B16: =IF(ISNUMBER($A16),IFERROR(INDEX('入力シート'!$A$2:$A$41,MATCH($A16,'入力シート'!$F$2:$F$41,0)),""),"") | E16: =IF(9<='入力シート'!$M$13,IF(1=1,'入力シート'!$M$13+1-9,9),IF(9='入力シート'!$M$13+1,IF(1=1,"前","後ろ"),"")) | F16: =IF(ISNUMBER($E16),IFERROR(INDEX('入力シート'!$A$2:$A$41,MATCH($E16,'入力シート'!$F$2:$F$41,0)),""),"")
A17: =IF(10<='入力シート'!$M$13,IF(0=1,'入力シート'!$M$13+1-10,10),IF(10='入力シート'!$M$13+1,IF(0=1,"前","後ろ"),"")) | B17: =IF(ISNUMBER($A17),IFERROR(INDEX('入力シート'!$A$2:$A$41,MATCH($A17,'入力シート'!$F$2:$F$41,0)),""),"") | E17: =IF(10<='入力シート'!$M$13,IF(1=1,'入力シート'!$M$13+1-10,10),IF(10='入力シート'!$M$13+1,IF(1=1,"前","後ろ"),"")) | F17: =IF(ISNUMBER($E17),IFERROR(INDEX('入力シート'!$A$2:$A$41,MATCH($E17,'入力シート'!$F$2:$F$41,0)),""),"")
A18: =IF(11<='入力シート'!$M$13,IF(0=1,'入力シート'!$M$13+1-11,11),IF(11='入力シート'!$M$13+1,IF(0=1,"前","後ろ"),"")) | B18: =IF(ISNUMBER($A18),IFERROR(INDEX('入力シート'!$A$2:$A$41,MATCH($A18,'入力シート'!$F$2:$F$41,0)),""),"") | E18: =IF(11<='入力シート'!$M$13,IF(1=1,'入力シート'!$M$13+1-11,11),IF(11='入力シート'!$M$13+1,IF(1=1,"前","後ろ"),"")) | F18: =IF(ISNUMBER($E18),IFERROR(INDEX('入力シート'!$A$2:$A$41,MATCH($E18,'入力シート'!$F$2:$F$41,0)),""),"")
A19: =IF(12<='入力シート'!$M$13,IF(0=1,'入力シート'!$M$13+1-12,12),IF(12='入力シート'!$M$13+1,IF(0=1,"前","後ろ"),"")) | B19: =IF(ISNUMBER($A19),IFERROR(INDEX('入力シート'!$A$2:$A$41,MATCH($A19,'入力シート'!$F$2:$F$41,0)),""),"") | E19: =IF(12<='入力シート'!$M$13,IF(1=1,'入力シート'!$M$13+1-12,12),IF(12='入力シート'!$M$13+1,IF(1=1,"前","後ろ"),"")) | F19: =IF(ISNUMBER($E19),IFERROR(INDEX('入力シート'!$A$2:$A$41,MATCH($E19,'入力シート'!$F$2:$F$41,0)),""),"")
A20: =IF(13<='入力シート'!$M$13,IF(0=1,'入力シート'!$M$13+1-13,13),IF(13='入力シート'!$M$13+1,IF(0=1,"前","後ろ"),"")) | B20: =IF(ISNUMBER($A20),IFERROR(INDEX('入力シート'!$A$2:$A$41,MATCH($A20,'入力シート'!$F$2:$F$41,0)),""),"") | E20: =IF(13<='入力シート'!$M$13,IF(1=1,'入力シート'!$M$13+1-13,13),IF(13='入力シート'!$M$13+1,IF(1=1,"前","後ろ"),"")) | F20: =IF(ISNUMBER($E20),IFERROR(INDEX('入力シート'!$A$2:$A$41,MATCH($E20,'入力シート'!$F$2:$F$41,0)),""),"")
A21: =IF(14<='入力シート'!$M$13,IF(0=1,'入力シート'!$M$13+1-14,14),IF(14='入力シート'!$M$13+1,IF(0=1,"前","後ろ"),"")) | B21: =IF(ISNUMBER($A21),IFERROR(INDEX('入力シート'!$A$2:$A$41,MATCH($A21,'入力シート'!$F$2:$F$41,0)),""),"") | E21: =IF(14<='入力シート'!$M$13,IF(1=1,'入力シート'!$M$13+1-14,14),IF(14='入力シート'!$M$13+1,IF(1=1,"前","後ろ"),"")) | F21: =IF(ISNUMBER($E21),IFERROR(INDEX('入力シート'!$A$2:$A$41,MATCH($E21,'入力シート'!$F$2:$F$41,0)),""),"")
A22: =IF(15<='入力シート'!$M$13,IF(0=1,'入力シート'!$M$13+1-15,15),IF(15='入力シート'!$M$13+1,IF(0=1,"前","後ろ"),"")) | B22: =IF(ISNUMBER($A22),IFERROR(INDEX('入力シート'!$A$2:$A$41,MATCH($A22,'入力シート'!$F$2:$F$41,0)),""),"") | E22: =IF(15<='入力シート'!$M$13,IF(1=1,'入力シート'!$M$13+1-15,15),IF(15='入力シート'!$M$13+1,IF(1=1,"前","後ろ"),"")) | F22: =IF(ISNUMBER($E22),IFERROR(INDEX('入力シート'!$A$2:$A$41,MATCH($E22,'入力シート'!$F$2:$F$41,0)),""),"")
A23: =IF(16<='入力シート'!$M$13,IF(0=1,'入力シート'!$M$13+1-16,16),IF(16='入力シート'!$M$13+1,IF(0=1,"前","後ろ"),"")) | B23: =IF(ISNUMBER($A23),IFERROR(INDEX('入力シート'!$A$2:$A$41,MATCH($A23,'入力シート'!$F$2:$F$41,0)),""),"") | E23: =IF(16<='入力シート'!$M$13,IF(1=1,'入力シート'!$M$13+1-16,16),IF(16='入力シート'!$M$13+1,IF(1=1,"前","後ろ"),"")) | F23: =IF(ISNUMBER($E23),IFERROR(INDEX('入力シート'!$A$2:$A$41,MATCH($E23,'入力シート'!$F$2:$F$41,0)),""),"")
A24: =IF(17<='入力シート'!$M$13,IF(0=1,'入力シート'!$M$13+1-17,17),IF(17='入力シート'!$M$13+1,IF(0=1,"前","後ろ"),"")) | B24: =IF(ISNUMBER($A24),IFERROR(INDEX('入力シート'!$A$2:$A$41,MATCH($A24,'入力シート'!$F$2:$F$41,0)),""),"") | E24: =IF(17<='入力シート'!$M$13,IF(1=1,'入力シート'!$M$13+1-17,17),IF(17='入力シート'!$M$13+1,IF(1=1,"前","後ろ"),"")) | F24: =IF(ISNUMBER($E24),IFERROR(INDEX('入力シート'!$A$2:$A$41,MATCH($E24,'入力シート'!$F$2:$F$41,0)),""),"")
A25: =IF(18<='入力シート'!$M$13,IF(0=1,'入力シート'!$M$13+1-18,18),IF(18='入力シート'!$M$13+1,IF(0=1,"前","後ろ"),"")) | B25: =IF(ISNUMBER($A25),IFERROR(INDEX('入力シート'!$A$2:$A$41,MATCH($A25,'入力シート'!$F$2:$F$41,0)),""),"") | E25: =IF(18<='入力シート'!$M$13,IF(1=1,'入力シート'!$M$13+1-18,18),IF(18='入力シート'!$M$13+1,IF(1=1,"前","後ろ"),"")) | F25: =IF(ISNUMBER($E25),IFERROR(INDEX('入力シート'!$A$2:$A$41,MATCH($E25,'入力シート'!$F$2:$F$41,0)),""),"")
A26: =IF(19<='入力シート'!$M$13,IF(0=1,'入力シート'!$M$13+1-19,19),IF(19='入力シート'!$M$13+1,IF(0=1,"前","後ろ"),"")) | B26: =IF(ISNUMBER($A26),IFERROR(INDEX('入力シート'!$A$2:$A$41,MATCH($A26,'入力シート'!$F$2:$F$41,0)),""),"") | E26: =IF(19<='入力シート'!$M$13,IF(1=1,'入力シート'!$M$13+1-19,19),IF(19='入力シート'!$M$13+1,IF(1=1,"前","後ろ"),"")) | F26: =IF(ISNUMBER($E26),IFERROR(INDEX('入力シート'!$A$2:$A$41,MATCH($E26,'入力シート'!$F$2:$F$41,0)),""),"")
A27: =IF(20<='入力シート'!$M$13,IF(0=1,'入力シート'!$M$13+1-20,20),IF(20='入力シート'!$M$13+1,IF(0=1,"前","後ろ"),"")) | B27: =IF(ISNUMBER($A27),IFERROR(INDEX('入力シート'!$A$2:$A$41,MATCH($A27,'入力シート'!$F$2:$F$41,0)),""),"") | E27: =IF(20<='入力シート'!$M$13,IF(1=1,'入力シート'!$M$13+1-20,20),IF(20='入力シート'!$M$13+1,IF(1=1,"前","後ろ"),"")) | F27: =IF(ISNUMBER($E27),IFERROR(INDEX('入力シート'!$A$2:$A$41,MATCH($E27,'入力シート'!$F$2:$F$41,0)),""),"")
A28: =IF(21<='入力シート'!$M$13,IF(0=1,'入力シート'!$M$13+1-21,21),IF(21='入力シート'!$M$13+1,IF(0=1,"前","後ろ"),"")) | B28: =IF(ISNUMBER($A28),IFERROR(INDEX('入力シート'!$A$2:$A$41,MATCH($A28,'入力シート'!$F$2:$F$41,0)),""),"") | E28: =IF(21<='入力シート'!$M$13,IF(1=1,'入力シート'!$M$13+1-21,21),IF(21='入力シート'!$M$13+1,IF(1=1,"前","後ろ"),"")) | F28: =IF(ISNUMBER($E28),IFERROR(INDEX('入力シート'!$A$2:$A$41,MATCH($E28,'入力シート'!$F$2:$F$41,0)),""),"")
A29: =IF(22<='入力シート'!$M$13,IF(0=1,'入力シート'!$M$13+1-22,22),IF(22='入力シート'!$M$13+1,IF(0=1,"前","後ろ"),"")) | B29: =IF(ISNUMBER($A29),IFERROR(INDEX('入力シート'!$A$2:$A$41,MATCH($A29,'入力シート'!$F$2:$F$41,0)),""),"") | E29: =IF(22<='入力シート'!$M$13,IF(1=1,'入力シート'!$M$13+1-22,22),IF(22='入力シート'!$M$13+1,IF(1=1,"前","後ろ"),"")) | F29: =IF(ISNUMBER($E29),IFERROR(INDEX('入力シート'!$A$2:$A$41,MATCH($E29,'入力シート'!$F$2:$F$41,0)),""),"")
A30: =IF(23<='入力シート'!$M$13,IF(0=1,'入力シート'!$M$13+1-23,23),IF(23='入力シート'!$M$13+1,IF(0=1,"前","後ろ"),"")) | B30: =IF(ISNUMBER($A30),IFERROR(INDEX('入力シート'!$A$2:$A$41,MATCH($A30,'入力シート'!$F$2:$F$41,0)),""),"") | E30: =IF(23<='入力シート'!$M$13,IF(1=1,'入力シート'!$M$13+1-23,23),IF(23='入力シート'!$M$13+1,IF(1=1,"前","後ろ"),"")) | F30: =IF(ISNUMBER($E30),IFERROR(INDEX('入力シート'!$A$2:$A$41,MATCH($E30,'入力シート'!$F$2:$F$41,0)),""),"")
A31: =IF(24<='入力シート'!$M$13,IF(0=1,'入力シート'!$M$13+1-24,24),IF(24='入力シート'!$M$13+1,IF(0=1,"前","後ろ"),"")) | B31: =IF(ISNUMBER($A31),IFERROR(INDEX('入力シート'!$A$2:$A$41,MATCH($A31,'入力シート'!$F$2:$F$41,0)),""),"") | E31: =IF(24<='入力シート'!$M$13,IF(1=1,'入力シート'!$M$13+1-24,24),IF(24='入力シート'!$M$13+1,IF(1=1,"前","後ろ"),"")) | F31: =IF(ISNUMBER($E31),IFERROR(INDEX('入力シート'!$A$2:$A$41,MATCH($E31,'入力シート'!$F$2:$F$41,0)),""),"")
A32: =IF(25<='入力シート'!$M$13,IF(0=1,'入力シート'!$M$13+1-25,25),IF(25='入力シート'!$M$13+1,IF(0=1,"前","後ろ"),"")) | B32: =IF(ISNUMBER($A32),IFERROR(INDEX('入力シート'!$A$2:$A$41,MATCH($A32,'入力シート'!$F$2:$F$41,0)),""),"") | E32: =IF(25<='入力シート'!$M$13,IF(1=1,'入力シート'!$M$13+1-25,25),IF(25='入力シート'!$M$13+1,IF(1=1,"前","後ろ"),"")) | F32: =IF(ISNUMBER($E32),IFERROR(INDEX('入力シート'!$A$2:$A$41,MATCH($E32,'入力シート'!$F$2:$F$41,0)),""),"")
A33: =IF(26<='入力シート'!$M$13,IF(0=1,'入力シート'!$M$13+1-26,26),IF(26='入力シート'!$M$13+1,IF(0=1,"前","後ろ"),"")) | B33: =IF(ISNUMBER($A33),IFERROR(INDEX('入力シート'!$A$2:$A$41,MATCH($A33,'入力シート'!$F$2:$F$41,0)),""),"") | E33: =IF(26<='入力シート'!$M$13,IF(1=1,'入力シート'!$M$13+1-26,26),IF(26='入力シート'!$M$13+1,IF(1=1,"前","後ろ"),"")) | F33: =IF(ISNUMBER($E33),IFERROR(INDEX('入力シート'!$A$2:$A$41,MATCH($E33,'入力シート'!$F$2:$F$41,0)),""),"")
A34: =IF(27<='入力シート'!$M$13,IF(0=1,'入力シート'!$M$13+1-27,27),IF(27='入力シート'!$M$13+1,IF(0=1,"前","後ろ"),"")) | B34: =IF(ISNUMBER($A34),IFERROR(INDEX('入力シート'!$A$2:$A$41,MATCH($A34,'入力シート'!$F$2:$F$41,0)),""),"") | E34: =IF(27<='入力シート'!$M$13,IF(1=1,'入力シート'!$M$13+1-27,27),IF(27='入力シート'!$M$13+1,IF(1=1,"前","後ろ"),"")) | F34: =IF(ISNUMBER($E34),IFERROR(INDEX('入力シート'!$A$2:$A$41,MATCH($E34,'入力シート'!$F$2:$F$41,0)),""),"")
A35: =IF(28<='入力シート'!$M$13,IF(0=1,'入力シート'!$M$13+1-28,28),IF(28='入力シート'!$M$13+1,IF(0=1,"前","後ろ"),"")) | B35: =IF(ISNUMBER($A35),IFERROR(INDEX('入力シート'!$A$2:$A$41,MATCH($A35,'入力シート'!$F$2:$F$41,0)),""),"") | E35: =IF(28<='入力シート'!$M$13,IF(1=1,'入力シート'!$M$13+1-28,28),IF(28='入力シート'!$M$13+1,IF(1=1,"前","後ろ"),"")) | F35: =IF(ISNUMBER($E35),IFERROR(INDEX('入力シート'!$A$2:$A$41,MATCH($E35,'入力シート'!$F$2:$F$41,0)),""),"")
A36: =IF(29<='入力シート'!$M$13,IF(0=1,'入力シート'!$M$13+1-29,29),IF(29='入力シート'!$M$13+1,IF(0=1,"前","後ろ"),"")) | B36: =IF(ISNUMBER($A36),IFERROR(INDEX('入力シート'!$A$2:$A$41,MATCH($A36,'入力シート'!$F$2:$F$41,0)),""),"") | E36: =IF(29<='入力シート'!$M$13,IF(1=1,'入力シート'!$M$13+1-29,29),IF(29='入力シート'!$M$13+1,IF(1=1,"前","後ろ"),"")) | F36: =IF(ISNUMBER($E36),IFERROR(INDEX('入力シート'!$A$2:$A$41,MATCH($E36,'入力シート'!$F$2:$F$41,0)),""),"")
A37: =IF(30<='入力シート'!$M$13,IF(0=1,'入力シート'!$M$13+1-30,30),IF(30='入力シート'!$M$13+1,IF(0=1,"前","後ろ"),"")) | B37: =IF(ISNUMBER($A37),IFERROR(INDEX('入力シート'!$A$2:$A$41,MATCH($A37,'入力シート'!$F$2:$F$41,0)),""),"") | E37: =IF(30<='入力シート'!$M$13,IF(1=1,'入力シート'!$M$13+1-30,30),IF(30='入力シート'!$M$13+1,IF(1=1,"前","後ろ"),"")) | F37: =IF(ISNUMBER($E37),IFERROR(INDEX('入力シート'!$A$2:$A$41,MATCH($E37,'入力シート'!$F$2:$F$41,0)),""),"")
A38: =IF(31<='入力シート'!$M$13,IF(0=1,'入力シート'!$M$13+1-31,31),IF(31='入力シート'!$M$13+1,IF(0=1,"前","後ろ"),"")) | B38: =IF(ISNUMBER($A38),IFERROR(INDEX('入力シート'!$A$2:$A$41,MATCH($A38,'入力シート'!$F$2:$F$41,0)),""),"") | E38: =IF(31<='入力シート'!$M$13,IF(1=1,'入力シート'!$M$13+1-31,31),IF(31='入力シート'!$M$13+1,IF(1=1,"前","後ろ"),"")) | F38: =IF(ISNUMBER($E38),IFERROR(INDEX('入力シート'!$A$2:$A$41,MATCH($E38,'入力シート'!$F$2:$F$41,0)),""),"")
A39: =IF(32<='入力シート'!$M$13,IF(0=1,'入力シート'!$M$13+1-32,32),IF(32='入力シート'!$M$13+1,IF(0=1,"前","後ろ"),"")) | B39: =IF(ISNUMBER($A39),IFERROR(INDEX('入力シート'!$A$2:$A$41,MATCH($A39,'入力シート'!$F$2:$F$41,0)),""),"") | E39: =IF(32<='入力シート'!$M$13,IF(1=1,'入力シート'!$M$13+1-32,32),IF(32='入力シート'!$M$13+1,IF(1=1,"前","後ろ"),"")) | F39: =IF(ISNUMBER($E39),IFERROR(INDEX('入力シート'!$A$2:$A$41,MATCH($E39,'入力シート'!$F$2:$F$41,0)),""),"")
A40: =IF(33<='入力シート'!$M$13,IF(0=1,'入力シート'!$M$13+1-33,33),IF(33='入力シート'!$M$13+1,IF(0=1,"前","後ろ"),"")) | B40: =IF(ISNUMBER($A40),IFERROR(INDEX('入力シート'!$A$2:$A$41,MATCH($A40,'入力シート'!$F$2:$F$41,0)),""),"") | E40: =IF(33<='入力シート'!$M$13,IF(1=1,'入力シート'!$M$13+1-33,33),IF(33='入力シート'!$M$13+1,IF(1=1,"前","後ろ"),"")) | F40: =IF(ISNUMBER($E40),IFERROR(INDEX('入力シート'!$A$2:$A$41,MATCH($E40,'入力シート'!$F$2:$F$41,0)),""),"")
A41: =IF(34<='入力シート'!$M$13,IF(0=1,'入力シート'!$M$13+1-34,34),IF(34='入力シート'!$M$13+1,IF(0=1,"前","後ろ"),"")) | B41: =IF(ISNUMBER($A41),IFERROR(INDEX('入力シート'!$A$2:$A$41,MATCH($A41,'入力シート'!$F$2:$F$41,0)),""),"") | E41: =IF(34<='入力シート'!$M$13,IF(1=1,'入力シート'!$M$13+1-34,34),IF(34='入力シート'!$M$13+1,IF(1=1,"前","後ろ"),"")) | F41: =IF(ISNUMBER($E41),IFERROR(INDEX('入力シート'!$A$2:$A$41,MATCH($E41,'入力シート'!$F$2:$F$41,0)),""),"")
A42: =IF(35<='入力シート'!$M$13,IF(0=1,'入力シート'!$M$13+1-35,35),IF(35='入力シート'!$M$13+1,IF(0=1,"前","後ろ"),"")) | B42: =IF(ISNUMBER($A42),IFERROR(INDEX('入力シート'!$A$2:$A$41,MATCH($A42,'入力シート'!$F$2:$F$41,0)),""),"") | E42: =IF(35<='入力シート'!$M$13,IF(1=1,'入力シート'!$M$13+1-35,35),IF(35='入力シート'!$M$13+1,IF(1=1,"前","後ろ"),"")) | F42: =IF(ISNUMBER($E42),IFERROR(INDEX('入力シート'!$A$2:$A$41,MATCH($E42,'入力シート'!$F$2:$F$41,0)),""),"")
...

Sheet 4列
A1: 背の順 4列
A2: 上が前・下が前を両方出しています。印刷したい並びの黄色いマスに ○ を入れると「印刷用」シートに出ます。
A4: 4列① 横に順番（1・2・3・4／5・6・7・8）
B5: 上が前 ← ○で印刷 | H5: 下が前 ← ○で印刷
A7: =IF(0=1,"後ろ","前") | B7: =IF(ISNUMBER($A7),IFERROR(INDEX('入力シート'!$A$2:$A$41,MATCH(($A7-1)*4+1,'入力シート'!$F$2:$F$41,0)),""),"") | C7: =IF(ISNUMBER($A7),IFERROR(INDEX('入力シート'!$A$2:$A$41,MATCH(($A7-1)*4+2,'入力シート'!$F$2:$F$41,0)),""),"") | D7: =IF(ISNUMBER($A7),IFERROR(INDEX('入力シート'!$A$2:$A$41,MATCH(($A7-1)*4+3,'入力シート'!$F$2:$F$41,0)),""),"") | E7: =IF(ISNUMBER($A7),IFERROR(INDEX('入力シート'!$A$2:$A$41,MATCH(($A7-1)*4+4,'入力シート'!$F$2:$F$41,0)),""),"") | G7: =IF(1=1,"後ろ","前") | H7: =IF(ISNUMBER($G7),IFERROR(INDEX('入力シート'!$A$2:$A$41,MATCH(($G7-1)*4+1,'入力シート'!$F$2:$F$41,0)),""),"") | I7: =IF(ISNUMBER($G7),IFERROR(INDEX('入力シート'!$A$2:$A$41,MATCH(($G7-1)*4+2,'入力シート'!$F$2:$F$41,0)),""),"") | J7: =IF(ISNUMBER($G7),IFERROR(INDEX('入力シート'!$A$2:$A$41,MATCH(($G7-1)*4+3,'入力シート'!$F$2:$F$41,0)),""),"") | K7: =IF(ISNUMBER($G7),IFERROR(INDEX('入力シート'!$A$2:$A$41,MATCH(($G7-1)*4+4,'入力シート'!$F$2:$F$41,0)),""),"")
A8: =IF(1<=ROUNDUP('入力シート'!$M$13/4,0),IF(0=1,ROUNDUP('入力シート'!$M$13/4,0)+1-1,1),IF(1=ROUNDUP('入力シート'!$M$13/4,0)+1,IF(0=1,"前","後ろ"),"")) | B8: =IF(ISNUMBER($A8),IFERROR(INDEX('入力シート'!$A$2:$A$41,MATCH(($A8-1)*4+1,'入力シート'!$F$2:$F$41,0)),""),"") | C8: =IF(ISNUMBER($A8),IFERROR(INDEX('入力シート'!$A$2:$A$41,MATCH(($A8-1)*4+2,'入力シート'!$F$2:$F$41,0)),""),"") | D8: =IF(ISNUMBER($A8),IFERROR(INDEX('入力シート'!$A$2:$A$41,MATCH(($A8-1)*4+3,'入力シート'!$F$2:$F$41,0)),""),"") | E8: =IF(ISNUMBER($A8),IFERROR(INDEX('入力シート'!$A$2:$A$41,MATCH(($A8-1)*4+4,'入力シート'!$F$2:$F$41,0)),""),"") | G8: =IF(1<=ROUNDUP('入力シート'!$M$13/4,0),IF(1=1,ROUNDUP('入力シート'!$M$13/4,0)+1-1,1),IF(1=ROUNDUP('入力シート'!$M$13/4,0)+1,IF(1=1,"前","後ろ"),"")) | H8: =IF(ISNUMBER($G8),IFERROR(INDEX('入力シート'!$A$2:$A$41,MATCH(($G8-1)*4+1,'入力シート'!$F$2:$F$41,0)),""),"") | I8: =IF(ISNUMBER($G8),IFERROR(INDEX('入力シート'!$A$2:$A$41,MATCH(($G8-1)*4+2,'入力シート'!$F$2:$F$41,0)),""),"") | J8: =IF(ISNUMBER($G8),IFERROR(INDEX('入力シート'!$A$2:$A$41,MATCH(($G8-1)*4+3,'入力シート'!$F$2:$F$41,0)),""),"") | K8: =IF(ISNUMBER($G8),IFERROR(INDEX('入力シート'!$A$2:$A$41,MATCH(($G8-1)*4+4,'入力シート'!$F$2:$F$41,0)),""),"")
A9: =IF(2<=ROUNDUP('入力シート'!$M$13/4,0),IF(0=1,ROUNDUP('入力シート'!$M$13/4,0)+1-2,2),IF(2=ROUNDUP('入力シート'!$M$13/4,0)+1,IF(0=1,"前","後ろ"),"")) | B9: =IF(ISNUMBER($A9),IFERROR(INDEX('入力シート'!$A$2:$A$41,MATCH(($A9-1)*4+1,'入力シート'!$F$2:$F$41,0)),""),"") | C9: =IF(ISNUMBER($A9),IFERROR(INDEX('入力シート'!$A$2:$A$41,MATCH(($A9-1)*4+2,'入力シート'!$F$2:$F$41,0)),""),"") | D9: =IF(ISNUMBER($A9),IFERROR(INDEX('入力シート'!$A$2:$A$41,MATCH(($A9-1)*4+3,'入力シート'!$F$2:$F$41,0)),""),"") | E9: =IF(ISNUMBER($A9),IFERROR(INDEX('入力シート'!$A$2:$A$41,MATCH(($A9-1)*4+4,'入力シート'!$F$2:$F$41,0)),""),"") | G9: =IF(2<=ROUNDUP('入力シート'!$M$13/4,0),IF(1=1,ROUNDUP('入力シート'!$M$13/4,0)+1-2,2),IF(2=ROUNDUP('入力シート'!$M$13/4,0)+1,IF(1=1,"前","後ろ"),"")) | H9: =IF(ISNUMBER($G9),IFERROR(INDEX('入力シート'!$A$2:$A$41,MATCH(($G9-1)*4+1,'入力シート'!$F$2:$F$41,0)),""),"") | I9: =IF(ISNUMBER($G9),IFERROR(INDEX('入力シート'!$A$2:$A$41,MATCH(($G9-1)*4+2,'入力シート'!$F$2:$F$41,0)),""),"") | J9: =IF(ISNUMBER($G9),IFERROR(INDEX('入力シート'!$A$2:$A$41,MATCH(($G9-1)*4+3,'入力シート'!$F$2:$F$41,0)),""),"") | K9: =IF(ISNUMBER($G9),IFERROR(INDEX('入力シート'!$A$2:$A$41,MATCH(($G9-1)*4+4,'入力シート'!$F$2:$F$41,0)),""),"")
A10: =IF(3<=ROUNDUP('入力シート'!$M$13/4,0),IF(0=1,ROUNDUP('入力シート'!$M$13/4,0)+1-3,3),IF(3=ROUNDUP('入力シート'!$M$13/4,0)+1,IF(0=1,"前","後ろ"),"")) | B10: =IF(ISNUMBER($A10),IFERROR(INDEX('入力シート'!$A$2:$A$41,MATCH(($A10-1)*4+1,'入力シート'!$F$2:$F$41,0)),""),"") | C10: =IF(ISNUMBER($A10),IFERROR(INDEX('入力シート'!$A$2:$A$41,MATCH(($A10-1)*4+2,'入力シート'!$F$2:$F$41,0)),""),"") | D10: =IF(ISNUMBER($A10),IFERROR(INDEX('入力シート'!$A$2:$A$41,MATCH(($A10-1)*4+3,'入力シート'!$F$2:$F$41,0)),""),"") | E10: =IF(ISNUMBER($A10),IFERROR(INDEX('入力シート'!$A$2:$A$41,MATCH(($A10-1)*4+4,'入力シート'!$F$2:$F$41,0)),""),"") | G10: =IF(3<=ROUNDUP('入力シート'!$M$13/4,0),IF(1=1,ROUNDUP('入力シート'!$M$13/4,0)+1-3,3),IF(3=ROUNDUP('入力シート'!$M$13/4,0)+1,IF(1=1,"前","後ろ"),"")) | H10: =IF(ISNUMBER($G10),IFERROR(INDEX('入力シート'!$A$2:$A$41,MATCH(($G10-1)*4+1,'入力シート'!$F$2:$F$41,0)),""),"") | I10: =IF(ISNUMBER($G10),IFERROR(INDEX('入力シート'!$A$2:$A$41,MATCH(($G10-1)*4+2,'入力シート'!$F$2:$F$41,0)),""),"") | J10: =IF(ISNUMBER($G10),IFERROR(INDEX('入力シート'!$A$2:$A$41,MATCH(($G10-1)*4+3,'入力シート'!$F$2:$F$41,0)),""),"") | K10: =IF(ISNUMBER($G10),IFERROR(INDEX('入力シート'!$A$2:$A$41,MATCH(($G10-1)*4+4,'入力シート'!$F$2:$F$41,0)),""),"")
A11: =IF(4<=ROUNDUP('入力シート'!$M$13/4,0),IF(0=1,ROUNDUP('入力シート'!$M$13/4,0)+1-4,4),IF(4=ROUNDUP('入力シート'!$M$13/4,0)+1,IF(0=1,"前","後ろ"),"")) | B11: =IF(ISNUMBER($A11),IFERROR(INDEX('入力シート'!$A$2:$A$41,MATCH(($A11-1)*4+1,'入力シート'!$F$2:$F$41,0)),""),"") | C11: =IF(ISNUMBER($A11),IFERROR(INDEX('入力シート'!$A$2:$A$41,MATCH(($A11-1)*4+2,'入力シート'!$F$2:$F$41,0)),""),"") | D11: =IF(ISNUMBER($A11),IFERROR(INDEX('入力シート'!$A$2:$A$41,MATCH(($A11-1)*4+3,'入力シート'!$F$2:$F$41,0)),""),"") | E11: =IF(ISNUMBER($A11),IFERROR(INDEX('入力シート'!$A$2:$A$41,MATCH(($A11-1)*4+4,'入力シート'!$F$2:$F$41,0)),""),"") | G11: =IF(4<=ROUNDUP('入力シート'!$M$13/4,0),IF(1=1,ROUNDUP('入力シート'!$M$13/4,0)+1-4,4),IF(4=ROUNDUP('入力シート'!$M$13/4,0)+1,IF(1=1,"前","後ろ"),"")) | H11: =IF(ISNUMBER($G11),IFERROR(INDEX('入力シート'!$A$2:$A$41,MATCH(($G11-1)*4+1,'入力シート'!$F$2:$F$41,0)),""),"") | I11: =IF(ISNUMBER($G11),IFERROR(INDEX('入力シート'!$A$2:$A$41,MATCH(($G11-1)*4+2,'入力シート'!$F$2:$F$41,0)),""),"") | J11: =IF(ISNUMBER($G11),IFERROR(INDEX('入力シート'!$A$2:$A$41,MATCH(($G11-1)*4+3,'入力シート'!$F$2:$F$41,0)),""),"") | K11: =IF(ISNUMBER($G11),IFERROR(INDEX('入力シート'!$A$2:$A$41,MATCH(($G11-1)*4+4,'入力シート'!$F$2:$F$41,0)),""),"")
A12: =IF(5<=ROUNDUP('入力シート'!$M$13/4,0),IF(0=1,ROUNDUP('入力シート'!$M$13/4,0)+1-5,5),IF(5=ROUNDUP('入力シート'!$M$13/4,0)+1,IF(0=1,"前","後ろ"),"")) | B12: =IF(ISNUMBER($A12),IFERROR(INDEX('入力シート'!$A$2:$A$41,MATCH(($A12-1)*4+1,'入力シート'!$F$2:$F$41,0)),""),"") | C12: =IF(ISNUMBER($A12),IFERROR(INDEX('入力シート'!$A$2:$A$41,MATCH(($A12-1)*4+2,'入力シート'!$F$2:$F$41,0)),""),"") | D12: =IF(ISNUMBER($A12),IFERROR(INDEX('入力シート'!$A$2:$A$41,MATCH(($A12-1)*4+3,'入力シート'!$F$2:$F$41,0)),""),"") | E12: =IF(ISNUMBER($A12),IFERROR(INDEX('入力シート'!$A$2:$A$41,MATCH(($A12-1)*4+4,'入力シート'!$F$2:$F$41,0)),""),"") | G12: =IF(5<=ROUNDUP('入力シート'!$M$13/4,0),IF(1=1,ROUNDUP('入力シート'!$M$13/4,0)+1-5,5),IF(5=ROUNDUP('入力シート'!$M$13/4,0)+1,IF(1=1,"前","後ろ"),"")) | H12: =IF(ISNUMBER($G12),IFERROR(INDEX('入力シート'!$A$2:$A$41,MATCH(($G12-1)*4+1,'入力シート'!$F$2:$F$41,0)),""),"") | I12: =IF(ISNUMBER($G12),IFERROR(INDEX('入力シート'!$A$2:$A$41,MATCH(($G12-1)*4+2,'入力シート'!$F$2:$F$41,0)),""),"") | J12: =IF(ISNUMBER($G12),IFERROR(INDEX('入力シート'!$A$2:$A$41,MATCH(($G12-1)*4+3,'入力シート'!$F$2:$F$41,0)),""),"") | K12: =IF(ISNUMBER($G12),IFERROR(INDEX('入力シート'!$A$2:$A$41,MATCH(($G12-1)*4+4,'入力シート'!$F$2:$F$41,0)),""),"")
A13: =IF(6<=ROUNDUP('入力シート'!$M$13/4,0),IF(0=1,ROUNDUP('入力シート'!$M$13/4,0)+1-6,6),IF(6=ROUNDUP('入力シート'!$M$13/4,0)+1,IF(0=1,"前","後ろ"),"")) | B13: =IF(ISNUMBER($A13),IFERROR(INDEX('入力シート'!$A$2:$A$41,MATCH(($A13-1)*4+1,'入力シート'!$F$2:$F$41,0)),""),"") | C13: =IF(ISNUMBER($A13),IFERROR(INDEX('入力シート'!$A$2:$A$41,MATCH(($A13-1)*4+2,'入力シート'!$F$2:$F$41,0)),""),"") | D13: =IF(ISNUMBER($A13),IFERROR(INDEX('入力シート'!$A$2:$A$41,MATCH(($A13-1)*4+3,'入力シート'!$F$2:$F$41,0)),""),"") | E13: =IF(ISNUMBER($A13),IFERROR(INDEX('入力シート'!$A$2:$A$41,MATCH(($A13-1)*4+4,'入力シート'!$F$2:$F$41,0)),""),"") | G13: =IF(6<=ROUNDUP('入力シート'!$M$13/4,0),IF(1=1,ROUNDUP('入力シート'!$M$13/4,0)+1-6,6),IF(6=ROUNDUP('入力シート'!$M$13/4,0)+1,IF(1=1,"前","後ろ"),"")) | H13: =IF(ISNUMBER($G13),IFERROR(INDEX('入力シート'!$A$2:$A$41,MATCH(($G13-1)*4+1,'入力シート'!$F$2:$F$41,0)),""),"") | I13: =IF(ISNUMBER($G13),IFERROR(INDEX('入力シート'!$A$2:$A$41,MATCH(($G13-1)*4+2,'入力シート'!$F$2:$F$41,0)),""),"") | J13: =IF(ISNUMBER($G13),IFERROR(INDEX('入力シート'!$A$2:$A$41,MATCH(($G13-1)*4+3,'入力シート'!$F$2:$F$41,0)),""),"") | K13: =IF(ISNUMBER($G13),IFERROR(INDEX('入力シート'!$A$2:$A$41,MATCH(($G13-1)*4+4,'入力シート'!$F$2:$F$41,0)),""),"")
A14: =IF(7<=ROUNDUP('入力シート'!$M$13/4,0),IF(0=1,ROUNDUP('入力シート'!$M$13/4,0)+1-7,7),IF(7=ROUNDUP('入力シート'!$M$13/4,0)+1,IF(0=1,"前","後ろ"),"")) | B14: =IF(ISNUMBER($A14),IFERROR(INDEX('入力シート'!$A$2:$A$41,MATCH(($A14-1)*4+1,'入力シート'!$F$2:$F$41,0)),""),"") | C14: =IF(ISNUMBER($A14),IFERROR(INDEX('入力シート'!$A$2:$A$41,MATCH(($A14-1)*4+2,'入力シート'!$F$2:$F$41,0)),""),"") | D14: =IF(ISNUMBER($A14),IFERROR(INDEX('入力シート'!$A$2:$A$41,MATCH(($A14-1)*4+3,'入力シート'!$F$2:$F$41,0)),""),"") | E14: =IF(ISNUMBER($A14),IFERROR(INDEX('入力シート'!$A$2:$A$41,MATCH(($A14-1)*4+4,'入力シート'!$F$2:$F$41,0)),""),"") | G14: =IF(7<=ROUNDUP('入力シート'!$M$13/4,0),IF(1=1,ROUNDUP('入力シート'!$M$13/4,0)+1-7,7),IF(7=ROUNDUP('入力シート'!$M$13/4,0)+1,IF(1=1,"前","後ろ"),"")) | H14: =IF(ISNUMBER($G14),IFERROR(INDEX('入力シート'!$A$2:$A$41,MATCH(($G14-1)*4+1,'入力シート'!$F$2:$F$41,0)),""),"") | I14: =IF(ISNUMBER($G14),IFERROR(INDEX('入力シート'!$A$2:$A$41,MATCH(($G14-1)*4+2,'入力シート'!$F$2:$F$41,0)),""),"") | J14: =IF(ISNUMBER($G14),IFERROR(INDEX('入力シート'!$A$2:$A$41,MATCH(($G14-1)*4+3,'入力シート'!$F$2:$F$41,0)),""),"") | K14: =IF(ISNUMBER($G14),IFERROR(INDEX('入力シート'!$A$2:$A$41,MATCH(($G14-1)*4+4,'入力シート'!$F$2:$F$41,0)),""),"")
A15: =IF(8<=ROUNDUP('入力シート'!$M$13/4,0),IF(0=1,ROUNDUP('入力シート'!$M$13/4,0)+1-8,8),IF(8=ROUNDUP('入力シート'!$M$13/4,0)+1,IF(0=1,"前","後ろ"),"")) | B15: =IF(ISNUMBER($A15),IFERROR(INDEX('入力シート'!$A$2:$A$41,MATCH(($A15-1)*4+1,'入力シート'!$F$2:$F$41,0)),""),"") | C15: =IF(ISNUMBER($A15),IFERROR(INDEX('入力シート'!$A$2:$A$41,MATCH(($A15-1)*4+2,'入力シート'!$F$2:$F$41,0)),""),"") | D15: =IF(ISNUMBER($A15),IFERROR(INDEX('入力シート'!$A$2:$A$41,MATCH(($A15-1)*4+3,'入力シート'!$F$2:$F$41,0)),""),"") | E15: =IF(ISNUMBER($A15),IFERROR(INDEX('入力シート'!$A$2:$A$41,MATCH(($A15-1)*4+4,'入力シート'!$F$2:$F$41,0)),""),"") | G15: =IF(8<=ROUNDUP('入力シート'!$M$13/4,0),IF(1=1,ROUNDUP('入力シート'!$M$13/4,0)+1-8,8),IF(8=ROUNDUP('入力シート'!$M$13/4,0)+1,IF(1=1,"前","後ろ"),"")) | H15: =IF(ISNUMBER($G15),IFERROR(INDEX('入力シート'!$A$2:$A$41,MATCH(($G15-1)*4+1,'入力シート'!$F$2:$F$41,0)),""),"") | I15: =IF(ISNUMBER($G15),IFERROR(INDEX('入力シート'!$A$2:$A$41,MATCH(($G15-1)*4+2,'入力シート'!$F$2:$F$41,0)),""),"") | J15: =IF(ISNUMBER($G15),IFERROR(INDEX('入力シート'!$A$2:$A$41,MATCH(($G15-1)*4+3,'入力シート'!$F$2:$F$41,0)),""),"") | K15: =IF(ISNUMBER($G15),IFERROR(INDEX('入力シート'!$A$2:$A$41,MATCH(($G15-1)*4+4,'入力シート'!$F$2:$F$41,0)),""),"")
A16: =IF(9<=ROUNDUP('入力シート'!$M$13/4,0),IF(0=1,ROUNDUP('入力シート'!$M$13/4,0)+1-9,9),IF(9=ROUNDUP('入力シート'!$M$13/4,0)+1,IF(0=1,"前","後ろ"),"")) | B16: =IF(ISNUMBER($A16),IFERROR(INDEX('入力シート'!$A$2:$A$41,MATCH(($A16-1)*4+1,'入力シート'!$F$2:$F$41,0)),""),"") | C16: =IF(ISNUMBER($A16),IFERROR(INDEX('入力シート'!$A$2:$A$41,MATCH(($A16-1)*4+2,'入力シート'!$F$2:$F$41,0)),""),"") | D16: =IF(ISNUMBER($A16),IFERROR(INDEX('入力シート'!$A$2:$A$41,MATCH(($A16-1)*4+3,'入力シート'!$F$2:$F$41,0)),""),"") | E16: =IF(ISNUMBER($A16),IFERROR(INDEX('入力シート'!$A$2:$A$41,MATCH(($A16-1)*4+4,'入力シート'!$F$2:$F$41,0)),""),"") | G16: =IF(9<=ROUNDUP('入力シート'!$M$13/4,0),IF(1=1,ROUNDUP('入力シート'!$M$13/4,0)+1-9,9),IF(9=ROUNDUP('入力シート'!$M$13/4,0)+1,IF(1=1,"前","後ろ"),"")) | H16: =IF(ISNUMBER($G16),IFERROR(INDEX('入力シート'!$A$2:$A$41,MATCH(($G16-1)*4+1,'入力シート'!$F$2:$F$41,0)),""),"") | I16: =IF(ISNUMBER($G16),IFERROR(INDEX('入力シート'!$A$2:$A$41,MATCH(($G16-1)*4+2,'入力シート'!$F$2:$F$41,0)),""),"") | J16: =IF(ISNUMBER($G16),IFERROR(INDEX('入力シート'!$A$2:$A$41,MATCH(($G16-1)*4+3,'入力シート'!$F$2:$F$41,0)),""),"") | K16: =IF(ISNUMBER($G16),IFERROR(INDEX('入力シート'!$A$2:$A$41,MATCH(($G16-1)*4+4,'入力シート'!$F$2:$F$41,0)),""),"")
A17: =IF(10<=ROUNDUP('入力シート'!$M$13/4,0),IF(0=1,ROUNDUP('入力シート'!$M$13/4,0)+1-10,10),IF(10=ROUNDUP('入力シート'!$M$13/4,0)+1,IF(0=1,"前","後ろ"),"")) | B17: =IF(ISNUMBER($A17),IFERROR(INDEX('入力シート'!$A$2:$A$41,MATCH(($A17-1)*4+1,'入力シート'!$F$2:$F$41,0)),""),"") | C17: =IF(ISNUMBER($A17),IFERROR(INDEX('入力シート'!$A$2:$A$41,MATCH(($A17-1)*4+2,'入力シート'!$F$2:$F$41,0)),""),"") | D17: =IF(ISNUMBER($A17),IFERROR(INDEX('入力シート'!$A$2:$A$41,MATCH(($A17-1)*4+3,'入力シート'!$F$2:$F$41,0)),""),"") | E17: =IF(ISNUMBER($A17),IFERROR(INDEX('入力シート'!$A$2:$A$41,MATCH(($A17-1)*4+4,'入力シート'!$F$2:$F$41,0)),""),"") | G17: =IF(10<=ROUNDUP('入力シート'!$M$13/4,0),IF(1=1,ROUNDUP('入力シート'!$M$13/4,0)+1-10,10),IF(10=ROUNDUP('入力シート'!$M$13/4,0)+1,IF(1=1,"前","後ろ"),"")) | H17: =IF(ISNUMBER($G17),IFERROR(INDEX('入力シート'!$A$2:$A$41,MATCH(($G17-1)*4+1,'入力シート'!$F$2:$F$41,0)),""),"") | I17: =IF(ISNUMBER($G17),IFERROR(INDEX('入力シート'!$A$2:$A$41,MATCH(($G17-1)*4+2,'入力シート'!$F$2:$F$41,0)),""),"") | J17: =IF(ISNUMBER($G17),IFERROR(INDEX('入力シート'!$A$2:$A$41,MATCH(($G17-1)*4+3,'入力シート'!$F$2:$F$41,0)),""),"") | K17: =IF(ISNUMBER($G17),IFERROR(INDEX('入力シート'!$A$2:$A$41,MATCH(($G17-1)*4+4,'入力シート'!$F$2:$F$41,0)),""),"")
A18: =IF(11<=ROUNDUP('入力シート'!$M$13/4,0),IF(0=1,ROUNDUP('入力シート'!$M$13/4,0)+1-11,11),IF(11=ROUNDUP('入力シート'!$M$13/4,0)+1,IF(0=1,"前","後ろ"),"")) | B18: =IF(ISNUMBER($A18),IFERROR(INDEX('入力シート'!$A$2:$A$41,MATCH(($A18-1)*4+1,'入力シート'!$F$2:$F$41,0)),""),"") | C18: =IF(ISNUMBER($A18),IFERROR(INDEX('入力シート'!$A$2:$A$41,MATCH(($A18-1)*4+2,'入力シート'!$F$2:$F$41,0)),""),"") | D18: =IF(ISNUMBER($A18),IFERROR(INDEX('入力シート'!$A$2:$A$41,MATCH(($A18-1)*4+3,'入力シート'!$F$2:$F$41,0)),""),"") | E18: =IF(ISNUMBER($A18),IFERROR(INDEX('入力シート'!$A$2:$A$41,MATCH(($A18-1)*4+4,'入力シート'!$F$2:$F$41,0)),""),"") | G18: =IF(11<=ROUNDUP('入力シート'!$M$13/4,0),IF(1=1,ROUNDUP('入力シート'!$M$13/4,0)+1-11,11),IF(11=ROUNDUP('入力シート'!$M$13/4,0)+1,IF(1=1,"前","後ろ"),"")) | H18: =IF(ISNUMBER($G18),IFERROR(INDEX('入力シート'!$A$2:$A$41,MATCH(($G18-1)*4+1,'入力シート'!$F$2:$F$41,0)),""),"") | I18: =IF(ISNUMBER($G18),IFERROR(INDEX('入力シート'!$A$2:$A$41,MATCH(($G18-1)*4+2,'入力シート'!$F$2:$F$41,0)),""),"") | J18: =IF(ISNUMBER($G18),IFERROR(INDEX('入力シート'!$A$2:$A$41,MATCH(($G18-1)*4+3,'入力シート'!$F$2:$F$41,0)),""),"") | K18: =IF(ISNUMBER($G18),IFERROR(INDEX('入力シート'!$A$2:$A$41,MATCH(($G18-1)*4+4,'入力シート'!$F$2:$F$41,0)),""),"")
A19: =IF((ROUNDUP('入力シート'!$M$13/4,0))>10,"⚠ 入りきらない子がいます ","") | G19: =IF((ROUNDUP('入力シート'!$M$13/4,0))>10,"⚠ 入りきらない子がいます ","")
A21: 4列② 蛇腹方式（1・2・3・4／8・7・6・5）
B22: 上が前 ← ○で印刷 | H22: 下が前 ← ○で印刷
A24: =IF(0=1,"後ろ","前") | B24: =IF(ISNUMBER($A24),IFERROR(INDEX('入力シート'!$A$2:$A$41,MATCH(IF(MOD($A24,2)=1,($A24-1)*4+1,($A24-1)*4+4),'入力シート'!$F$2:$F$41,0)),""),"") | C24: =IF(ISNUMBER($A24),IFERROR(INDEX('入力シート'!$A$2:$A$41,MATCH(IF(MOD($A24,2)=1,($A24-1)*4+2,($A24-1)*4+3),'入力シート'!$F$2:$F$41,0)),""),"") | D24: =IF(ISNUMBER($A24),IFERROR(INDEX('入力シート'!$A$2:$A$41,MATCH(IF(MOD($A24,2)=1,($A24-1)*4+3,($A24-1)*4+2),'入力シート'!$F$2:$F$41,0)),""),"") | E24: =IF(ISNUMBER($A24),IFERROR(INDEX('入力シート'!$A$2:$A$41,MATCH(IF(MOD($A24,2)=1,($A24-1)*4+4,($A24-1)*4+1),'入力シート'!$F$2:$F$41,0)),""),"") | G24: =IF(1=1,"後ろ","前") | H24: =IF(ISNUMBER($G24),IFERROR(INDEX('入力シート'!$A$2:$A$41,MATCH(IF(MOD($G24,2)=1,($G24-1)*4+1,($G24-1)*4+4),'入力シート'!$F$2:$F$41,0)),""),"") | I24: =IF(ISNUMBER($G24),IFERROR(INDEX('入力シート'!$A$2:$A$41,MATCH(IF(MOD($G24,2)=1,($G24-1)*4+2,($G24-1)*4+3),'入力シート'!$F$2:$F$41,0)),""),"") | J24: =IF(ISNUMBER($G24),IFERROR(INDEX('入力シート'!$A$2:$A$41,MATCH(IF(MOD($G24,2)=1,($G24-1)*4+3,($G24-1)*4+2),'入力シート'!$F$2:$F$41,0)),""),"") | K24: =IF(ISNUMBER($G24),IFERROR(INDEX('入力シート'!$A$2:$A$41,MATCH(IF(MOD($G24,2)=1,($G24-1)*4+4,($G24-1)*4+1),'入力シート'!$F$2:$F$41,0)),""),"")
A25: =IF(1<=ROUNDUP('入力シート'!$M$13/4,0),IF(0=1,ROUNDUP('入力シート'!$M$13/4,0)+1-1,1),IF(1=ROUNDUP('入力シート'!$M$13/4,0)+1,IF(0=1,"前","後ろ"),"")) | B25: =IF(ISNUMBER($A25),IFERROR(INDEX('入力シート'!$A$2:$A$41,MATCH(IF(MOD($A25,2)=1,($A25-1)*4+1,($A25-1)*4+4),'入力シート'!$F$2:$F$41,0)),""),"") | C25: =IF(ISNUMBER($A25),IFERROR(INDEX('入力シート'!$A$2:$A$41,MATCH(IF(MOD($A25,2)=1,($A25-1)*4+2,($A25-1)*4+3),'入力シート'!$F$2:$F$41,0)),""),"") | D25: =IF(ISNUMBER($A25),IFERROR(INDEX('入力シート'!$A$2:$A$41,MATCH(IF(MOD($A25,2)=1,($A25-1)*4+3,($A25-1)*4+2),'入力シート'!$F$2:$F$41,0)),""),"") | E25: =IF(ISNUMBER($A25),IFERROR(INDEX('入力シート'!$A$2:$A$41,MATCH(IF(MOD($A25,2)=1,($A25-1)*4+4,($A25-1)*4+1),'入力シート'!$F$2:$F$41,0)),""),"") | G25: =IF(1<=ROUNDUP('入力シート'!$M$13/4,0),IF(1=1,ROUNDUP('入力シート'!$M$13/4,0)+1-1,1),IF(1=ROUNDUP('入力シート'!$M$13/4,0)+1,IF(1=1,"前","後ろ"),"")) | H25: =IF(ISNUMBER($G25),IFERROR(INDEX('入力シート'!$A$2:$A$41,MATCH(IF(MOD($G25,2)=1,($G25-1)*4+1,($G25-1)*4+4),'入力シート'!$F$2:$F$41,0)),""),"") | I25: =IF(ISNUMBER($G25),IFERROR(INDEX('入力シート'!$A$2:$A$41,MATCH(IF(MOD($G25,2)=1,($G25-1)*4+2,($G25-1)*4+3),'入力シート'!$F$2:$F$41,0)),""),"") | J25: =IF(ISNUMBER($G25),IFERROR(INDEX('入力シート'!$A$2:$A$41,MATCH(IF(MOD($G25,2)=1,($G25-1)*4+3,($G25-1)*4+2),'入力シート'!$F$2:$F$41,0)),""),"") | K25: =IF(ISNUMBER($G25),IFERROR(INDEX('入力シート'!$A$2:$A$41,MATCH(IF(MOD($G25,2)=1,($G25-1)*4+4,($G25-1)*4+1),'入力シート'!$F$2:$F$41,0)),""),"")
A26: =IF(2<=ROUNDUP('入力シート'!$M$13/4,0),IF(0=1,ROUNDUP('入力シート'!$M$13/4,0)+1-2,2),IF(2=ROUNDUP('入力シート'!$M$13/4,0)+1,IF(0=1,"前","後ろ"),"")) | B26: =IF(ISNUMBER($A26),IFERROR(INDEX('入力シート'!$A$2:$A$41,MATCH(IF(MOD($A26,2)=1,($A26-1)*4+1,($A26-1)*4+4),'入力シート'!$F$2:$F$41,0)),""),"") | C26: =IF(ISNUMBER($A26),IFERROR(INDEX('入力シート'!$A$2:$A$41,MATCH(IF(MOD($A26,2)=1,($A26-1)*4+2,($A26-1)*4+3),'入力シート'!$F$2:$F$41,0)),""),"") | D26: =IF(ISNUMBER($A26),IFERROR(INDEX('入力シート'!$A$2:$A$41,MATCH(IF(MOD($A26,2)=1,($A26-1)*4+3,($A26-1)*4+2),'入力シート'!$F$2:$F$41,0)),""),"") | E26: =IF(ISNUMBER($A26),IFERROR(INDEX('入力シート'!$A$2:$A$41,MATCH(IF(MOD($A26,2)=1,($A26-1)*4+4,($A26-1)*4+1),'入力シート'!$F$2:$F$41,0)),""),"") | G26: =IF(2<=ROUNDUP('入力シート'!$M$13/4,0),IF(1=1,ROUNDUP('入力シート'!$M$13/4,0)+1-2,2),IF(2=ROUNDUP('入力シート'!$M$13/4,0)+1,IF(1=1,"前","後ろ"),"")) | H26: =IF(ISNUMBER($G26),IFERROR(INDEX('入力シート'!$A$2:$A$41,MATCH(IF(MOD($G26,2)=1,($G26-1)*4+1,($G26-1)*4+4),'入力シート'!$F$2:$F$41,0)),""),"") | I26: =IF(ISNUMBER($G26),IFERROR(INDEX('入力シート'!$A$2:$A$41,MATCH(IF(MOD($G26,2)=1,($G26-1)*4+2,($G26-1)*4+3),'入力シート'!$F$2:$F$41,0)),""),"") | J26: =IF(ISNUMBER($G26),IFERROR(INDEX('入力シート'!$A$2:$A$41,MATCH(IF(MOD($G26,2)=1,($G26-1)*4+3,($G26-1)*4+2),'入力シート'!$F$2:$F$41,0)),""),"") | K26: =IF(ISNUMBER($G26),IFERROR(INDEX('入力シート'!$A$2:$A$41,MATCH(IF(MOD($G26,2)=1,($G26-1)*4+4,($G26-1)*4+1),'入力シート'!$F$2:$F$41,0)),""),"")
A27: =IF(3<=ROUNDUP('入力シート'!$M$13/4,0),IF(0=1,ROUNDUP('入力シート'!$M$13/4,0)+1-3,3),IF(3=ROUNDUP('入力シート'!$M$13/4,0)+1,IF(0=1,"前","後ろ"),"")) | B27: =IF(ISNUMBER($A27),IFERROR(INDEX('入力シート'!$A$2:$A$41,MATCH(IF(MOD($A27,2)=1,($A27-1)*4+1,($A27-1)*4+4),'入力シート'!$F$2:$F$41,0)),""),"") | C27: =IF(ISNUMBER($A27),IFERROR(INDEX('入力シート'!$A$2:$A$41,MATCH(IF(MOD($A27,2)=1,($A27-1)*4+2,($A27-1)*4+3),'入力シート'!$F$2:$F$41,0)),""),"") | D27: =IF(ISNUMBER($A27),IFERROR(INDEX('入力シート'!$A$2:$A$41,MATCH(IF(MOD($A27,2)=1,($A27-1)*4+3,($A27-1)*4+2),'入力シート'!$F$2:$F$41,0)),""),"") | E27: =IF(ISNUMBER($A27),IFERROR(INDEX('入力シート'!$A$2:$A$41,MATCH(IF(MOD($A27,2)=1,($A27-1)*4+4,($A27-1)*4+1),'入力シート'!$F$2:$F$41,0)),""),"") | G27: =IF(3<=ROUNDUP('入力シート'!$M$13/4,0),IF(1=1,ROUNDUP('入力シート'!$M$13/4,0)+1-3,3),IF(3=ROUNDUP('入力シート'!$M$13/4,0)+1,IF(1=1,"前","後ろ"),"")) | H27: =IF(ISNUMBER($G27),IFERROR(INDEX('入力シート'!$A$2:$A$41,MATCH(IF(MOD($G27,2)=1,($G27-1)*4+1,($G27-1)*4+4),'入力シート'!$F$2:$F$41,0)),""),"") | I27: =IF(ISNUMBER($G27),IFERROR(INDEX('入力シート'!$A$2:$A$41,MATCH(IF(MOD($G27,2)=1,($G27-1)*4+2,($G27-1)*4+3),'入力シート'!$F$2:$F$41,0)),""),"") | J27: =IF(ISNUMBER($G27),IFERROR(INDEX('入力シート'!$A$2:$A$41,MATCH(IF(MOD($G27,2)=1,($G27-1)*4+3,($G27-1)*4+2),'入力シート'!$F$2:$F$41,0)),""),"") | K27: =IF(ISNUMBER($G27),IFERROR(INDEX('入力シート'!$A$2:$A$41,MATCH(IF(MOD($G27,2)=1,($G27-1)*4+4,($G27-1)*4+1),'入力シート'!$F$2:$F$41,0)),""),"")
A28: =IF(4<=ROUNDUP('入力シート'!$M$13/4,0),IF(0=1,ROUNDUP('入力シート'!$M$13/4,0)+1-4,4),IF(4=ROUNDUP('入力シート'!$M$13/4,0)+1,IF(0=1,"前","後ろ"),"")) | B28: =IF(ISNUMBER($A28),IFERROR(INDEX('入力シート'!$A$2:$A$41,MATCH(IF(MOD($A28,2)=1,($A28-1)*4+1,($A28-1)*4+4),'入力シート'!$F$2:$F$41,0)),""),"") | C28: =IF(ISNUMBER($A28),IFERROR(INDEX('入力シート'!$A$2:$A$41,MATCH(IF(MOD($A28,2)=1,($A28-1)*4+2,($A28-1)*4+3),'入力シート'!$F$2:$F$41,0)),""),"") | D28: =IF(ISNUMBER($A28),IFERROR(INDEX('入力シート'!$A$2:$A$41,MATCH(IF(MOD($A28,2)=1,($A28-1)*4+3,($A28-1)*4+2),'入力シート'!$F$2:$F$41,0)),""),"") | E28: =IF(ISNUMBER($A28),IFERROR(INDEX('入力シート'!$A$2:$A$41,MATCH(IF(MOD($A28,2)=1,($A28-1)*4+4,($A28-1)*4+1),'入力シート'!$F$2:$F$41,0)),""),"") | G28: =IF(4<=ROUNDUP('入力シート'!$M$13/4,0),IF(1=1,ROUNDUP('入力シート'!$M$13/4,0)+1-4,4),IF(4=ROUNDUP('入力シート'!$M$13/4,0)+1,IF(1=1,"前","後ろ"),"")) | H28: =IF(ISNUMBER($G28),IFERROR(INDEX('入力シート'!$A$2:$A$41,MATCH(IF(MOD($G28,2)=1,($G28-1)*4+1,($G28-1)*4+4),'入力シート'!$F$2:$F$41,0)),""),"") | I28: =IF(ISNUMBER($G28),IFERROR(INDEX('入力シート'!$A$2:$A$41,MATCH(IF(MOD($G28,2)=1,($G28-1)*4+2,($G28-1)*4+3),'入力シート'!$F$2:$F$41,0)),""),"") | J28: =IF(ISNUMBER($G28),IFERROR(INDEX('入力シート'!$A$2:$A$41,MATCH(IF(MOD($G28,2)=1,($G28-1)*4+3,($G28-1)*4+2),'入力シート'!$F$2:$F$41,0)),""),"") | K28: =IF(ISNUMBER($G28),IFERROR(INDEX('入力シート'!$A$2:$A$41,MATCH(IF(MOD($G28,2)=1,($G28-1)*4+4,($G28-1)*4+1),'入力シート'!$F$2:$F$41,0)),""),"")
A29: =IF(5<=ROUNDUP('入力シート'!$M$13/4,0),IF(0=1,ROUNDUP('入力シート'!$M$13/4,0)+1-5,5),IF(5=ROUNDUP('入力シート'!$M$13/4,0)+1,IF(0=1,"前","後ろ"),"")) | B29: =IF(ISNUMBER($A29),IFERROR(INDEX('入力シート'!$A$2:$A$41,MATCH(IF(MOD($A29,2)=1,($A29-1)*4+1,($A29-1)*4+4),'入力シート'!$F$2:$F$41,0)),""),"") | C29: =IF(ISNUMBER($A29),IFERROR(INDEX('入力シート'!$A$2:$A$41,MATCH(IF(MOD($A29,2)=1,($A29-1)*4+2,($A29-1)*4+3),'入力シート'!$F$2:$F$41,0)),""),"") | D29: =IF(ISNUMBER($A29),IFERROR(INDEX('入力シート'!$A$2:$A$41,MATCH(IF(MOD($A29,2)=1,($A29-1)*4+3,($A29-1)*4+2),'入力シート'!$F$2:$F$41,0)),""),"") | E29: =IF(ISNUMBER($A29),IFERROR(INDEX('入力シート'!$A$2:$A$41,MATCH(IF(MOD($A29,2)=1,($A29-1)*4+4,($A29-1)*4+1),'入力シート'!$F$2:$F$41,0)),""),"") | G29: =IF(5<=ROUNDUP('入力シート'!$M$13/4,0),IF(1=1,ROUNDUP('入力シート'!$M$13/4,0)+1-5,5),IF(5=ROUNDUP('入力シート'!$M$13/4,0)+1,IF(1=1,"前","後ろ"),"")) | H29: =IF(ISNUMBER($G29),IFERROR(INDEX('入力シート'!$A$2:$A$41,MATCH(IF(MOD($G29,2)=1,($G29-1)*4+1,($G29-1)*4+4),'入力シート'!$F$2:$F$41,0)),""),"") | I29: =IF(ISNUMBER($G29),IFERROR(INDEX('入力シート'!$A$2:$A$41,MATCH(IF(MOD($G29,2)=1,($G29-1)*4+2,($G29-1)*4+3),'入力シート'!$F$2:$F$41,0)),""),"") | J29: =IF(ISNUMBER($G29),IFERROR(INDEX('入力シート'!$A$2:$A$41,MATCH(IF(MOD($G29,2)=1,($G29-1)*4+3,($G29-1)*4+2),'入力シート'!$F$2:$F$41,0)),""),"") | K29: =IF(ISNUMBER($G29),IFERROR(INDEX('入力シート'!$A$2:$A$41,MATCH(IF(MOD($G29,2)=1,($G29-1)*4+4,($G29-1)*4+1),'入力シート'!$F$2:$F$41,0)),""),"")
A30: =IF(6<=ROUNDUP('入力シート'!$M$13/4,0),IF(0=1,ROUNDUP('入力シート'!$M$13/4,0)+1-6,6),IF(6=ROUNDUP('入力シート'!$M$13/4,0)+1,IF(0=1,"前","後ろ"),"")) | B30: =IF(ISNUMBER($A30),IFERROR(INDEX('入力シート'!$A$2:$A$41,MATCH(IF(MOD($A30,2)=1,($A30-1)*4+1,($A30-1)*4+4),'入力シート'!$F$2:$F$41,0)),""),"") | C30: =IF(ISNUMBER($A30),IFERROR(INDEX('入力シート'!$A$2:$A$41,MATCH(IF(MOD($A30,2)=1,($A30-1)*4+2,($A30-1)*4+3),'入力シート'!$F$2:$F$41,0)),""),"") | D30: =IF(ISNUMBER($A30),IFERROR(INDEX('入力シート'!$A$2:$A$41,MATCH(IF(MOD($A30,2)=1,($A30-1)*4+3,($A30-1)*4+2),'入力シート'!$F$2:$F$41,0)),""),"") | E30: =IF(ISNUMBER($A30),IFERROR(INDEX('入力シート'!$A$2:$A$41,MATCH(IF(MOD($A30,2)=1,($A30-1)*4+4,($A30-1)*4+1),'入力シート'!$F$2:$F$41,0)),""),"") | G30: =IF(6<=ROUNDUP('入力シート'!$M$13/4,0),IF(1=1,ROUNDUP('入力シート'!$M$13/4,0)+1-6,6),IF(6=ROUNDUP('入力シート'!$M$13/4,0)+1,IF(1=1,"前","後ろ"),"")) | H30: =IF(ISNUMBER($G30),IFERROR(INDEX('入力シート'!$A$2:$A$41,MATCH(IF(MOD($G30,2)=1,($G30-1)*4+1,($G30-1)*4+4),'入力シート'!$F$2:$F$41,0)),""),"") | I30: =IF(ISNUMBER($G30),IFERROR(INDEX('入力シート'!$A$2:$A$41,MATCH(IF(MOD($G30,2)=1,($G30-1)*4+2,($G30-1)*4+3),'入力シート'!$F$2:$F$41,0)),""),"") | J30: =IF(ISNUMBER($G30),IFERROR(INDEX('入力シート'!$A$2:$A$41,MATCH(IF(MOD($G30,2)=1,($G30-1)*4+3,($G30-1)*4+2),'入力シート'!$F$2:$F$41,0)),""),"") | K30: =IF(ISNUMBER($G30),IFERROR(INDEX('入力シート'!$A$2:$A$41,MATCH(IF(MOD($G30,2)=1,($G30-1)*4+4,($G30-1)*4+1),'入力シート'!$F$2:$F$41,0)),""),"")
A31: =IF(7<=ROUNDUP('入力シート'!$M$13/4,0),IF(0=1,ROUNDUP('入力シート'!$M$13/4,0)+1-7,7),IF(7=ROUNDUP('入力シート'!$M$13/4,0)+1,IF(0=1,"前","後ろ"),"")) | B31: =IF(ISNUMBER($A31),IFERROR(INDEX('入力シート'!$A$2:$A$41,MATCH(IF(MOD($A31,2)=1,($A31-1)*4+1,($A31-1)*4+4),'入力シート'!$F$2:$F$41,0)),""),"") | C31: =IF(ISNUMBER($A31),IFERROR(INDEX('入力シート'!$A$2:$A$41,MATCH(IF(MOD($A31,2)=1,($A31-1)*4+2,($A31-1)*4+3),'入力シート'!$F$2:$F$41,0)),""),"") | D31: =IF(ISNUMBER($A31),IFERROR(INDEX('入力シート'!$A$2:$A$41,MATCH(IF(MOD($A31,2)=1,($A31-1)*4+3,($A31-1)*4+2),'入力シート'!$F$2:$F$41,0)),""),"") | E31: =IF(ISNUMBER($A31),IFERROR(INDEX('入力シート'!$A$2:$A$41,MATCH(IF(MOD($A31,2)=1,($A31-1)*4+4,($A31-1)*4+1),'入力シート'!$F$2:$F$41,0)),""),"") | G31: =IF(7<=ROUNDUP('入力シート'!$M$13/4,0),IF(1=1,ROUNDUP('入力シート'!$M$13/4,0)+1-7,7),IF(7=ROUNDUP('入力シート'!$M$13/4,0)+1,IF(1=1,"前","後ろ"),"")) | H31: =IF(ISNUMBER($G31),IFERROR(INDEX('入力シート'!$A$2:$A$41,MATCH(IF(MOD($G31,2)=1,($G31-1)*4+1,($G31-1)*4+4),'入力シート'!$F$2:$F$41,0)),""),"") | I31: =IF(ISNUMBER($G31),IFERROR(INDEX('入力シート'!$A$2:$A$41,MATCH(IF(MOD($G31,2)=1,($G31-1)*4+2,($G31-1)*4+3),'入力シート'!$F$2:$F$41,0)),""),"") | J31: =IF(ISNUMBER($G31),IFERROR(INDEX('入力シート'!$A$2:$A$41,MATCH(IF(MOD($G31,2)=1,($G31-1)*4+3,($G31-1)*4+2),'入力シート'!$F$2:$F$41,0)),""),"") | K31: =IF(ISNUMBER($G31),IFERROR(INDEX('入力シート'!$A$2:$A$41,MATCH(IF(MOD($G31,2)=1,($G31-1)*4+4,($G31-1)*4+1),'入力シート'!$F$2:$F$41,0)),""),"")
A32: =IF(8<=ROUNDUP('入力シート'!$M$13/4,0),IF(0=1,ROUNDUP('入力シート'!$M$13/4,0)+1-8,8),IF(8=ROUNDUP('入力シート'!$M$13/4,0)+1,IF(0=1,"前","後ろ"),"")) | B32: =IF(ISNUMBER($A32),IFERROR(INDEX('入力シート'!$A$2:$A$41,MATCH(IF(MOD($A32,2)=1,($A32-1)*4+1,($A32-1)*4+4),'入力シート'!$F$2:$F$41,0)),""),"") | C32: =IF(ISNUMBER($A32),IFERROR(INDEX('入力シート'!$A$2:$A$41,MATCH(IF(MOD($A32,2)=1,($A32-1)*4+2,($A32-1)*4+3),'入力シート'!$F$2:$F$41,0)),""),"") | D32: =IF(ISNUMBER($A32),IFERROR(INDEX('入力シート'!$A$2:$A$41,MATCH(IF(MOD($A32,2)=1,($A32-1)*4+3,($A32-1)*4+2),'入力シート'!$F$2:$F$41,0)),""),"") | E32: =IF(ISNUMBER($A32),IFERROR(INDEX('入力シート'!$A$2:$A$41,MATCH(IF(MOD($A32,2)=1,($A32-1)*4+4,($A32-1)*4+1),'入力シート'!$F$2:$F$41,0)),""),"") | G32: =IF(8<=ROUNDUP('入力シート'!$M$13/4,0),IF(1=1,ROUNDUP('入力シート'!$M$13/4,0)+1-8,8),IF(8=ROUNDUP('入力シート'!$M$13/4,0)+1,IF(1=1,"前","後ろ"),"")) | H32: =IF(ISNUMBER($G32),IFERROR(INDEX('入力シート'!$A$2:$A$41,MATCH(IF(MOD($G32,2)=1,($G32-1)*4+1,($G32-1)*4+4),'入力シート'!$F$2:$F$41,0)),""),"") | I32: =IF(ISNUMBER($G32),IFERROR(INDEX('入力シート'!$A$2:$A$41,MATCH(IF(MOD($G32,2)=1,($G32-1)*4+2,($G32-1)*4+3),'入力シート'!$F$2:$F$41,0)),""),"") | J32: =IF(ISNUMBER($G32),IFERROR(INDEX('入力シート'!$A$2:$A$41,MATCH(IF(MOD($G32,2)=1,($G32-1)*4+3,($G32-1)*4+2),'入力シート'!$F$2:$F$41,0)),""),"") | K32: =IF(ISNUMBER($G32),IFERROR(INDEX('入力シート'!$A$2:$A$41,MATCH(IF(MOD($G32,2)=1,($G32-1)*4+4,($G32-1)*4+1),'入力シート'!$F$2:$F$41,0)),""),"")
A33: =IF(9<=ROUNDUP('入力シート'!$M$13/4,0),IF(0=1,ROUNDUP('入力シート'!$M$13/4,0)+1-9,9),IF(9=ROUNDUP('入力シート'!$M$13/4,0)+1,IF(0=1,"前","後ろ"),"")) | B33: =IF(ISNUMBER($A33),IFERROR(INDEX('入力シート'!$A$2:$A$41,MATCH(IF(MOD($A33,2)=1,($A33-1)*4+1,($A33-1)*4+4),'入力シート'!$F$2:$F$41,0)),""),"") | C33: =IF(ISNUMBER($A33),IFERROR(INDEX('入力シート'!$A$2:$A$41,MATCH(IF(MOD($A33,2)=1,($A33-1)*4+2,($A33-1)*4+3),'入力シート'!$F$2:$F$41,0)),""),"") | D33: =IF(ISNUMBER($A33),IFERROR(INDEX('入力シート'!$A$2:$A$41,MATCH(IF(MOD($A33,2)=1,($A33-1)*4+3,($A33-1)*4+2),'入力シート'!$F$2:$F$41,0)),""),"") | E33: =IF(ISNUMBER($A33),IFERROR(INDEX('入力シート'!$A$2:$A$41,MATCH(IF(MOD($A33,2)=1,($A33-1)*4+4,($A33-1)*4+1),'入力シート'!$F$2:$F$41,0)),""),"") | G33: =IF(9<=ROUNDUP('入力シート'!$M$13/4,0),IF(1=1,ROUNDUP('入力シート'!$M$13/4,0)+1-9,9),IF(9=ROUNDUP('入力シート'!$M$13/4,0)+1,IF(1=1,"前","後ろ"),"")) | H33: =IF(ISNUMBER($G33),IFERROR(INDEX('入力シート'!$A$2:$A$41,MATCH(IF(MOD($G33,2)=1,($G33-1)*4+1,($G33-1)*4+4),'入力シート'!$F$2:$F$41,0)),""),"") | I33: =IF(ISNUMBER($G33),IFERROR(INDEX('入力シート'!$A$2:$A$41,MATCH(IF(MOD($G33,2)=1,($G33-1)*4+2,($G33-1)*4+3),'入力シート'!$F$2:$F$41,0)),""),"") | J33: =IF(ISNUMBER($G33),IFERROR(INDEX('入力シート'!$A$2:$A$41,MATCH(IF(MOD($G33,2)=1,($G33-1)*4+3,($G33-1)*4+2),'入力シート'!$F$2:$F$41,0)),""),"") | K33: =IF(ISNUMBER($G33),IFERROR(INDEX('入力シート'!$A$2:$A$41,MATCH(IF(MOD($G33,2)=1,($G33-1)*4+4,($G33-1)*4+1),'入力シート'!$F$2:$F$41,0)),""),"")
A34: =IF(10<=ROUNDUP('入力シート'!$M$13/4,0),IF(0=1,ROUNDUP('入力シート'!$M$13/4,0)+1-10,10),IF(10=ROUNDUP('入力シート'!$M$13/4,0)+1,IF(0=1,"前","後ろ"),"")) | B34: =IF(ISNUMBER($A34),IFERROR(INDEX('入力シート'!$A$2:$A$41,MATCH(IF(MOD($A34,2)=1,($A34-1)*4+1,($A34-1)*4+4),'入力シート'!$F$2:$F$41,0)),""),"") | C34: =IF(ISNUMBER($A34),IFERROR(INDEX('入力シート'!$A$2:$A$41,MATCH(IF(MOD($A34,2)=1,($A34-1)*4+2,($A34-1)*4+3),'入力シート'!$F$2:$F$41,0)),""),"") | D34: =IF(ISNUMBER($A34),IFERROR(INDEX('入力シート'!$A$2:$A$41,MATCH(IF(MOD($A34,2)=1,($A34-1)*4+3,($A34-1)*4+2),'入力シート'!$F$2:$F$41,0)),""),"") | E34: =IF(ISNUMBER($A34),IFERROR(INDEX('入力シート'!$A$2:$A$41,MATCH(IF(MOD($A34,2)=1,($A34-1)*4+4,($A34-1)*4+1),'入力シート'!$F$2:$F$41,0)),""),"") | G34: =IF(10<=ROUNDUP('入力シート'!$M$13/4,0),IF(1=1,ROUNDUP('入力シート'!$M$13/4,0)+1-10,10),IF(10=ROUNDUP('入力シート'!$M$13/4,0)+1,IF(1=1,"前","後ろ"),"")) | H34: =IF(ISNUMBER($G34),IFERROR(INDEX('入力シート'!$A$2:$A$41,MATCH(IF(MOD($G34,2)=1,($G34-1)*4+1,($G34-1)*4+4),'入力シート'!$F$2:$F$41,0)),""),"") | I34: =IF(ISNUMBER($G34),IFERROR(INDEX('入力シート'!$A$2:$A$41,MATCH(IF(MOD($G34,2)=1,($G34-1)*4+2,($G34-1)*4+3),'入力シート'!$F$2:$F$41,0)),""),"") | J34: =IF(ISNUMBER($G34),IFERROR(INDEX('入力シート'!$A$2:$A$41,MATCH(IF(MOD($G34,2)=1,($G34-1)*4+3,($G34-1)*4+2),'入力シート'!$F$2:$F$41,0)),""),"") | K34: =IF(ISNUMBER($G34),IFERROR(INDEX('入力シート'!$A$2:$A$41,MATCH(IF(MOD($G34,2)=1,($G34-1)*4+4,($G34-1)*4+1),'入力シート'!$F$2:$F$41,0)),""),"")
A35: =IF(11<=ROUNDUP('入力シート'!$M$13/4,0),IF(0=1,ROUNDUP('入力シート'!$M$13/4,0)+1-11,11),IF(11=ROUNDUP('入力シート'!$M$13/4,0)+1,IF(0=1,"前","後ろ"),"")) | B35: =IF(ISNUMBER($A35),IFERROR(INDEX('入力シート'!$A$2:$A$41,MATCH(IF(MOD($A35,2)=1,($A35-1)*4+1,($A35-1)*4+4),'入力シート'!$F$2:$F$41,0)),""),"") | C35: =IF(ISNUMBER($A35),IFERROR(INDEX('入力シート'!$A$2:$A$41,MATCH(IF(MOD($A35,2)=1,($A35-1)*4+2,($A35-1)*4+3),'入力シート'!$F$2:$F$41,0)),""),"") | D35: =IF(ISNUMBER($A35),IFERROR(INDEX('入力シート'!$A$2:$A$41,MATCH(IF(MOD($A35,2)=1,($A35-1)*4+3,($A35-1)*4+2),'入力シート'!$F$2:$F$41,0)),""),"") | E35: =IF(ISNUMBER($A35),IFERROR(INDEX('入力シート'!$A$2:$A$41,MATCH(IF(MOD($A35,2)=1,($A35-1)*4+4,($A35-1)*4+1),'入力シート'!$F$2:$F$41,0)),""),"") | G35: =IF(11<=ROUNDUP('入力シート'!$M$13/4,0),IF(1=1,ROUNDUP('入力シート'!$M$13/4,0)+1-11,11),IF(11=ROUNDUP('入力シート'!$M$13/4,0)+1,IF(1=1,"前","後ろ"),"")) | H35: =IF(ISNUMBER($G35),IFERROR(INDEX('入力シート'!$A$2:$A$41,MATCH(IF(MOD($G35,2)=1,($G35-1)*4+1,($G35-1)*4+4),'入力シート'!$F$2:$F$41,0)),""),"") | I35: =IF(ISNUMBER($G35),IFERROR(INDEX('入力シート'!$A$2:$A$41,MATCH(IF(MOD($G35,2)=1,($G35-1)*4+2,($G35-1)*4+3),'入力シート'!$F$2:$F$41,0)),""),"") | J35: =IF(ISNUMBER($G35),IFERROR(INDEX('入力シート'!$A$2:$A$41,MATCH(IF(MOD($G35,2)=1,($G35-1)*4+3,($G35-1)*4+2),'入力シート'!$F$2:$F$41,0)),""),"") | K35: =IF(ISNUMBER($G35),IFERROR(INDEX('入力シート'!$A$2:$A$41,MATCH(IF(MOD($G35,2)=1,($G35-1)*4+4,($G35-1)*4+1),'入力シート'!$F$2:$F$41,0)),""),"")
A36: =IF((ROUNDUP('入力シート'!$M$13/4,0))>10,"⚠ 入りきらない子がいます ","") | G36: =IF((ROUNDUP('入力シート'!$M$13/4,0))>10,"⚠ 入りきらない子がいます ","")
A38: 4列③ 2列から広げる（3・1・2・4／7・5・6・8）
B39: 上が前 ← ○で印刷 | H39: 下が前 ← ○で印刷
A41: =IF(0=1,"後ろ","前") | B41: =IF(ISNUMBER($A41),IFERROR(INDEX('入力シート'!$A$2:$A$41,MATCH(($A41-1)*4+3,'入力シート'!$F$2:$F$41,0)),""),"") | C41: =IF(ISNUMBER($A41),IFERROR(INDEX('入力シート'!$A$2:$A$41,MATCH(($A41-1)*4+1,'入力シート'!$F$2:$F$41,0)),""),"") | D41: =IF(ISNUMBER($A41),IFERROR(INDEX('入力シート'!$A$2:$A$41,MATCH(($A41-1)*4+2,'入力シート'!$F$2:$F$41,0)),""),"") | E41: =IF(ISNUMBER($A41),IFERROR(INDEX('入力シート'!$A$2:$A$41,MATCH(($A41-1)*4+4,'入力シート'!$F$2:$F$41,0)),""),"") | G41: =IF(1=1,"後ろ","前") | H41: =IF(ISNUMBER($G41),IFERROR(INDEX('入力シート'!$A$2:$A$41,MATCH(($G41-1)*4+3,'入力シート'!$F$2:$F$41,0)),""),"") | I41: =IF(ISNUMBER($G41),IFERROR(INDEX('入力シート'!$A$2:$A$41,MATCH(($G41-1)*4+1,'入力シート'!$F$2:$F$41,0)),""),"") | J41: =IF(ISNUMBER($G41),IFERROR(INDEX('入力シート'!$A$2:$A$41,MATCH(($G41-1)*4+2,'入力シート'!$F$2:$F$41,0)),""),"") | K41: =IF(ISNUMBER($G41),IFERROR(INDEX('入力シート'!$A$2:$A$41,MATCH(($G41-1)*4+4,'入力シート'!$F$2:$F$41,0)),""),"")
A42: =IF(1<=ROUNDUP('入力シート'!$M$13/4,0),IF(0=1,ROUNDUP('入力シート'!$M$13/4,0)+1-1,1),IF(1=ROUNDUP('入力シート'!$M$13/4,0)+1,IF(0=1,"前","後ろ"),"")) | B42: =IF(ISNUMBER($A42),IFERROR(INDEX('入力シート'!$A$2:$A$41,MATCH(($A42-1)*4+3,'入力シート'!$F$2:$F$41,0)),""),"") | C42: =IF(ISNUMBER($A42),IFERROR(INDEX('入力シート'!$A$2:$A$41,MATCH(($A42-1)*4+1,'入力シート'!$F$2:$F$41,0)),""),"") | D42: =IF(ISNUMBER($A42),IFERROR(INDEX('入力シート'!$A$2:$A$41,MATCH(($A42-1)*4+2,'入力シート'!$F$2:$F$41,0)),""),"") | E42: =IF(ISNUMBER($A42),IFERROR(INDEX('入力シート'!$A$2:$A$41,MATCH(($A42-1)*4+4,'入力シート'!$F$2:$F$41,0)),""),"") | G42: =IF(1<=ROUNDUP('入力シート'!$M$13/4,0),IF(1=1,ROUNDUP('入力シート'!$M$13/4,0)+1-1,1),IF(1=ROUNDUP('入力シート'!$M$13/4,0)+1,IF(1=1,"前","後ろ"),"")) | H42: =IF(ISNUMBER($G42),IFERROR(INDEX('入力シート'!$A$2:$A$41,MATCH(($G42-1)*4+3,'入力シート'!$F$2:$F$41,0)),""),"") | I42: =IF(ISNUMBER($G42),IFERROR(INDEX('入力シート'!$A$2:$A$41,MATCH(($G42-1)*4+1,'入力シート'!$F$2:$F$41,0)),""),"") | J42: =IF(ISNUMBER($G42),IFERROR(INDEX('入力シート'!$A$2:$A$41,MATCH(($G42-1)*4+2,'入力シート'!$F$2:$F$41,0)),""),"") | K42: =IF(ISNUMBER($G42),IFERROR(INDEX('入力シート'!$A$2:$A$41,MATCH(($G42-1)*4+4,'入力シート'!$F$2:$F$41,0)),""),"")
A43: =IF(2<=ROUNDUP('入力シート'!$M$13/4,0),IF(0=1,ROUNDUP('入力シート'!$M$13/4,0)+1-2,2),IF(2=ROUNDUP('入力シート'!$M$13/4,0)+1,IF(0=1,"前","後ろ"),"")) | B43: =IF(ISNUMBER($A43),IFERROR(INDEX('入力シート'!$A$2:$A$41,MATCH(($A43-1)*4+3,'入力シート'!$F$2:$F$41,0)),""),"") | C43: =IF(ISNUMBER($A43),IFERROR(INDEX('入力シート'!$A$2:$A$41,MATCH(($A43-1)*4+1,'入力シート'!$F$2:$F$41,0)),""),"") | D43: =IF(ISNUMBER($A43),IFERROR(INDEX('入力シート'!$A$2:$A$41,MATCH(($A43-1)*4+2,'入力シート'!$F$2:$F$41,0)),""),"") | E43: =IF(ISNUMBER($A43),IFERROR(INDEX('入力シート'!$A$2:$A$41,MATCH(($A43-1)*4+4,'入力シート'!$F$2:$F$41,0)),""),"") | G43: =IF(2<=ROUNDUP('入力シート'!$M$13/4,0),IF(1=1,ROUNDUP('入力シート'!$M$13/4,0)+1-2,2),IF(2=ROUNDUP('入力シート'!$M$13/4,0)+1,IF(1=1,"前","後ろ"),"")) | H43: =IF(ISNUMBER($G43),IFERROR(INDEX('入力シート'!$A$2:$A$41,MATCH(($G43-1)*4+3,'入力シート'!$F$2:$F$41,0)),""),"") | I43: =IF(ISNUMBER($G43),IFERROR(INDEX('入力シート'!$A$2:$A$41,MATCH(($G43-1)*4+1,'入力シート'!$F$2:$F$41,0)),""),"") | J43: =IF(ISNUMBER($G43),IFERROR(INDEX('入力シート'!$A$2:$A$41,MATCH(($G43-1)*4+2,'入力シート'!$F$2:$F$41,0)),""),"") | K43: =IF(ISNUMBER($G43),IFERROR(INDEX('入力シート'!$A$2:$A$41,MATCH(($G43-1)*4+4,'入力シート'!$F$2:$F$41,0)),""),"")
