Workbook

Sheet 名簿
A1: 名簿（ここに入れた名前が全教科のシートに入ります）
A2: 番 | B2: 名前
A3: 1 | B3: 石井 湊
A4: 2 | B4: 池田 さくら
A5: 3 | B5: 林 陽翔
A6: 4 | B6: 村上 凛
A7: 5 | B7: 中村 蓮
A8: 6 | B8: 小川 彩花
A9: 7 | B9: 近藤 蒼
A10: 8 | B10: 清水 莉子
A11: 9 | B11: 鈴木 海斗
A12: 10 | B12: 松本 さくら
A13: 11 | B13: 岡田 健太
A14: 12 | B14: 佐々木 彩花
... A37: 35 | B37: 渡辺 健太

Sheet 設定
A1: 設定
A5: Ａ・Ｂ・Ｃの区切り（到達率〔％〕）
A6: 全教科共通 | B6: Ａの区切り | C6: Ｂの区切り
A7: 共通 | B7: 90 | C7: 60
A8: 到達率が「Ａの区切り」以上でＡ、「Ｂの区切り」以上でＢ、 それより下はＣになります。
A10: 教科 | B10: Ａの区切り （教科ごと） | C10: Ｂの区切り （教科ごと） | D10: 使われる Ａの区切り | E10: 使われる Ｂの区切り
A11: 国語 | D11: =IF(B11="",$B$7,B11) -> 90 | E11: =IF(C11="",$C$7,C11) -> 60
A12: 算数 | B12: 85 | C12: 55 | D12: =IF(B12="",$B$7,B12) -> 85 | E12: =IF(C12="",$C$7,C12) -> 55
A13: 社会 | D13: =IF(B13="",$B$7,B13) -> 90 | E13: =IF(C13="",$C$7,C13) -> 60
A14: 理科 | D14: =IF(B14="",$B$7,B14) -> 90 | E14: =IF(C14="",$C$7,C14) -> 60
A15: 英語 | D15: =IF(B15="",$B$7,B15) -> 90 | E15: =IF(C15="",$C$7,C15) -> 60
A16: 保健 | D16: =IF(B16="",$B$7,B16) -> 90 | E16: =IF(C16="",$C$7,C16) -> 60
A17: 教科ごとの欄が空欄の教科は、「全教科共通」の区切りが使われます。
A18: 区切りは前期・後期・1年間のすべてに使われます。
A19: 1年間の到達率は、前期と後期の到達率の平均です。
A20: （片方の期しか点数がないときは、その期の到達率になります）
A21: 黄色の欄だけ入力してください。

Sheet 国語（前期）
A1: 観点別得点集計表（国語・前期）
A2: 観 点 | C2: 知識・技能 | Q2: 思考・判断・表現 | AD2: 合 計
A3: 単元名 | C3: 帰り道 | D3: 漢字の形と音・意味 | E3: 笑うから楽しい | F3: 時計の時間と心の時間 | G3: やまなし | H3: 鳥獣戯画を読む | N3: 観点合計 | O3: 観点到達率 | P3: 観点別学習状況評価 | Q3: 帰り道 | R3: 漢字の形と音・意味 | S3: 笑うから楽しい | T3: 時計の時間と心の時間 | U3: やまなし | V3: 鳥獣戯画を読む | AA3: 観点合計 | AB3: 観点到達率 | AC3: 観点別学習状況評価 | AD3: 総得点 | AE3: 総得点到達率 | AF3: 総得点学習状況評価
A4: 番 | B4: 名前/配点 | C4: 50 | D4: 50 | E4: 50 | F4: 50 | G4: 50 | H4: 50 | N4: =SUM(C4:M4) -> 300 | Q4: 50 | R4: 50 | S4: 50 | T4: 50 | U4: 50 | V4: 50 | AA4: =SUM(Q4:Z4) -> 300 | AD4: =N4+AA4 -> 600
A5: 1 | B5: =IF(名簿!B3="","",名簿!B3) -> 石井 湊 | C5: 50 | D5: 49 | E5: 50 | F5: 50 | G5: 50 | H5: 50 | N5: =IF(COUNT(C5:M5)=0,"",SUM(C5:M5)) -> 299 | O5: =IF(OR(N5="",$N$4-SUMIF(C5:M5,"欠",$C$4:$M$4)<=0),"",ROUND(N5/($N$4-SUMIF(C5:M5,"欠",$C$4:$M$4))*100,0)) -> 100 | P5: =IF(O5="","",IF(O5>=設定!$D$11,"A",IF(O5>=設定!$E$11,"B","C"))) -> A | Q5: 48 | R5: 50 | S5: 49 | T5: 50 | U5: 49 | V5: 50 | AA5: =IF(COUNT(Q5:Z5)=0,"",SUM(Q5:Z5)) -> 296 | AB5: =IF(OR(AA5="",$AA$4-SUMIF(Q5:Z5,"欠",$Q$4:$Z$4)<=0),"",ROUND(AA5/($AA$4-SUMIF(Q5:Z5,"欠",$Q$4:$Z$4))*100,0)) -> 99 | AC5: =IF(AB5="","",IF(AB5>=設定!$D$11,"A",IF(AB5>=設定!$E$11,"B","C"))) -> A | AD5: =IF(AND(N5="",AA5=""),"",IF(N5="",0,N5)+IF(AA5="",0,AA5)) -> 595 | AE5: =IF(AD5="","",IF($AD$4-SUMIF(C5:M5,"欠",$C$4:$M$4)-SUMIF(Q5:Z5,"欠",$Q$4:$Z$4)<=0,"",ROUND(AD5/($AD$4-SUMIF(C5:M5,"欠",$C$4:$M$4)-SUMIF(Q5:Z5,"欠",$Q$4:$Z$4))*100,0))) -> 99 | AF5: =IF(AE5="","",IF(AE5>=設定!$D$11,"A",IF(AE5>=設定!$E$11,"B","C"))) -> A
A6: 2 | B6: =IF(名簿!B4="","",名簿!B4) -> 池田 さくら | C6: 47 | D6: 38 | E6: 36 | F6: 42 | G6: 47 | H6: 47 | N6: =IF(COUNT(C6:M6)=0,"",SUM(C6:M6)) -> 257 | O6: =IF(OR(N6="",$N$4-SUMIF(C6:M6,"欠",$C$4:$M$4)<=0),"",ROUND(N6/($N$4-SUMIF(C6:M6,"欠",$C$4:$M$4))*100,0)) -> 86 | P6: =IF(O6="","",IF(O6>=設定!$D$11,"A",IF(O6>=設定!$E$11,"B","C"))) -> B | Q6: 41 | R6: 33 | S6: 43 | T6: 33 | U6: 34 | V6: 35 | AA6: =IF(COUNT(Q6:Z6)=0,"",SUM(Q6:Z6)) -> 219 | AB6: =IF(OR(AA6="",$AA$4-SUMIF(Q6:Z6,"欠",$Q$4:$Z$4)<=0),"",ROUND(AA6/($AA$4-SUMIF(Q6:Z6,"欠",$Q$4:$Z$4))*100,0)) -> 73 | AC6: =IF(AB6="","",IF(AB6>=設定!$D$11,"A",IF(AB6>=設定!$E$11,"B","C"))) -> B | AD6: =IF(AND(N6="",AA6=""),"",IF(N6="",0,N6)+IF(AA6="",0,AA6)) -> 476 | AE6: =IF(AD6="","",IF($AD$4-SUMIF(C6:M6,"欠",$C$4:$M$4)-SUMIF(Q6:Z6,"欠",$Q$4:$Z$4)<=0,"",ROUND(AD6/($AD$4-SUMIF(C6:M6,"欠",$C$4:$M$4)-SUMIF(Q6:Z6,"欠",$Q$4:$Z$4))*100,0))) -> 79 | AF6: =IF(AE6="","",IF(AE6>=設定!$D$11,"A",IF(AE6>=設定!$E$11,"B","C"))) -> B
A7: 3 | B7: =IF(名簿!B5="","",名簿!B5) -> 林 陽翔 | C7: 45 | D7: 42 | E7: 47 | F7: 50 | G7: 39 | H7: 50 | N7: =IF(COUNT(C7:M7)=0,"",SUM(C7:M7)) -> 273 | O7: =IF(OR(N7="",$N$4-SUMIF(C7:M7,"欠",$C$4:$M$4)<=0),"",ROUND(N7/($N$4-SUMIF(C7:M7,"欠",$C$4:$M$4))*100,0)) -> 91 | P7: =IF(O7="","",IF(O7>=設定!$D$11,"A",IF(O7>=設定!$E$11,"B","C"))) -> A | Q7: 38 | R7: 37 | S7: 41 | T7: 41 | U7: 42 | V7: 47 | AA7: =IF(COUNT(Q7:Z7)=0,"",SUM(Q7:Z7)) -> 246 | AB7: =IF(OR(AA7="",$AA$4-SUMIF(Q7:Z7,"欠",$Q$4:$Z$4)<=0),"",ROUND(AA7/($AA$4-SUMIF(Q7:Z7,"欠",$Q$4:$Z$4))*100,0)) -> 82 | AC7: =IF(AB7="","",IF(AB7>=設定!$D$11,"A",IF(AB7>=設定!$E$11,"B","C"))) -> B | AD7: =IF(AND(N7="",AA7=""),"",IF(N7="",0,N7)+IF(AA7="",0,AA7)) -> 519 | AE7: =IF(AD7="","",IF($AD$4-SUMIF(C7:M7,"欠",$C$4:$M$4)-SUMIF(Q7:Z7,"欠",$Q$4:$Z$4)<=0,"",ROUND(AD7/($AD$4-SUMIF(C7:M7,"欠",$C$4:$M$4)-SUMIF(Q7:Z7,"欠",$Q$4:$Z$4))*100,0))) -> 87 | AF7: =IF(AE7="","",IF(AE7>=設定!$D$11,"A",IF(AE7>=設定!$E$11,"B","C"))) -> B
A8: 4 | B8: =IF(名簿!B6="","",名簿!B6) -> 村上 凛 | C8: 39 | D8: 33 | E8: 44 | F8: 47 | G8: 33 | H8: 40 | N8: =IF(COUNT(C8:M8)=0,"",SUM(C8:M8)) -> 236 | O8: =IF(OR(N8="",$N$4-SUMIF(C8:M8,"欠",$C$4:$M$4)<=0),"",ROUND(N8/($N$4-SUMIF(C8:M8,"欠",$C$4:$M$4))*100,0)) -> 79 | P8: =IF(O8="","",IF(O8>=設定!$D$11,"A",IF(O8>=設定!$E$11,"B","C"))) -> B | Q8: 36 | R8: 36 | S8: 40 | T8: 37 | U8: 40 | V8: 33 | AA8: =IF(COUNT(Q8:Z8)=0,"",SUM(Q8:Z8)) -> 222 | AB8: =IF(OR(AA8="",$AA$4-SUMIF(Q8:Z8,"欠",$Q$4:$Z$4)<=0),"",ROUND(AA8/($AA$4-SUMIF(Q8:Z8,"欠",$Q$4:$Z$4))*100,0)) -> 74 | AC8: =IF(AB8="","",IF(AB8>=設定!$D$11,"A",IF(AB8>=設定!$E$11,"B","C"))) -> B | AD8: =IF(AND(N8="",AA8=""),"",IF(N8="",0,N8)+IF(AA8="",0,AA8)) -> 458 | AE8: =IF(AD8="","",IF($AD$4-SUMIF(C8:M8,"欠",$C$4:$M$4)-SUMIF(Q8:Z8,"欠",$Q$4:$Z$4)<=0,"",ROUND(AD8/($AD$4-SUMIF(C8:M8,"欠",$C$4:$M$4)-SUMIF(Q8:Z8,"欠",$Q$4:$Z$4))*100,0))) -> 76 | AF8: =IF(AE8="","",IF(AE8>=設定!$D$11,"A",IF(AE8>=設定!$E$11,"B","C"))) -> B
A9: 5 | B9: =IF(名簿!B7="","",名簿!B7) -> 中村 蓮 | C9: 44 | D9: 50 | E9: 48 | F9: 50 | G9: 50 | H9: 50 | N9: =IF(COUNT(C9:M9)=0,"",SUM(C9:M9)) -> 292 | O9: =IF(OR(N9="",$N$4-SUMIF(C9:M9,"欠",$C$4:$M$4)<=0),"",ROUND(N9/($N$4-SUMIF(C9:M9,"欠",$C$4:$M$4))*100,0)) -> 97 | P9: =IF(O9="","",IF(O9>=設定!$D$11,"A",IF(O9>=設定!$E$11,"B","C"))) -> A | Q9: 42 | R9: 44 | S9: 44 | T9: 48 | U9: 43 | V9: 45 | AA9: =IF(COUNT(Q9:Z9)=0,"",SUM(Q9:Z9)) -> 266 | AB9: =IF(OR(AA9="",$AA$4-SUMIF(Q9:Z9,"欠",$Q$4:$Z$4)<=0),"",ROUND(AA9/($AA$4-SUMIF(Q9:Z9,"欠",$Q$4:$Z$4))*100,0)) -> 89 | AC9: =IF(AB9="","",IF(AB9>=設定!$D$11,"A",IF(AB9>=設定!$E$11,"B","C"))) -> B | AD9: =IF(AND(N9="",AA9=""),"",IF(N9="",0,N9)+IF(AA9="",0,AA9)) -> 558 | AE9: =IF(AD9="","",IF($AD$4-SUMIF(C9:M9,"欠",$C$4:$M$4)-SUMIF(Q9:Z9,"欠",$Q$4:$Z$4)<=0,"",ROUND(AD9/($AD$4-SUMIF(C9:M9,"欠",$C$4:$M$4)-SUMIF(Q9:Z9,"欠",$Q$4:$Z$4))*100,0))) -> 93 | AF9: =IF(AE9="","",IF(AE9>=設定!$D$11,"A",IF(AE9>=設定!$E$11,"B","C"))) -> A
A10: 6 | B10: =IF(名簿!B8="","",名簿!B8) -> 小川 彩花 | C10: 38 | D10: 34 | E10: 32 | F10: 42 | G10: 36 | H10: 35 | N10: =IF(COUNT(C10:M10)=0,"",SUM(C10:M10)) -> 217 | O10: =IF(OR(N10="",$N$4-SUMIF(C10:M10,"欠",$C$4:$M$4)<=0),"",ROUND(N10/($N$4-SUMIF(C10:M10,"欠",$C$4:$M$4))*100,0)) -> 72 | P10: =IF(O10="","",IF(O10>=設定!$D$11,"A",IF(O10>=設定!$E$11,"B","C"))) -> B | Q10: 30 | R10: 30 | S10: 24 | T10: 31 | U10: 35 | V10: 35 | AA10: =IF(COUNT(Q10:Z10)=0,"",SUM(Q10:Z10)) -> 185 | AB10: =IF(OR(AA10="",$AA$4-SUMIF(Q10:Z10,"欠",$Q$4:$Z$4)<=0),"",ROUND(AA10/($AA$4-SUMIF(Q10:Z10,"欠",$Q$4:$Z$4))*100,0)) -> 62 | AC10: =IF(AB10="","",IF(AB10>=設定!$D$11,"A",IF(AB10>=設定!$E$11,"B","C"))) -> B | AD10: =IF(AND(N10="",AA10=""),"",IF(N10="",0,N10)+IF(AA10="",0,AA10)) -> 402 | AE10: =IF(AD10="","",IF($AD$4-SUMIF(C10:M10,"欠",$C$4:$M$4)-SUMIF(Q10:Z10,"欠",$Q$4:$Z$4)<=0,"",ROUND(AD10/($AD$4-SUMIF(C10:M10,"欠",$C$4:$M$4)-SUMIF(Q10:Z10,"欠",$Q$4:$Z$4))*100,0))) -> 67 | AF10: =IF(AE10="","",IF(AE10>=設定!$D$11,"A",IF(AE10>=設定!$E$11,"B","C"))) -> B
A11: 7 | B11: =IF(名簿!B9="","",名簿!B9) -> 近藤 蒼 | C11: 43 | D11: 39 | E11: 41 | F11: 49 | G11: 43 | H11: 42 | N11: =IF(COUNT(C11:M11)=0,"",SUM(C11:M11)) -> 257 | O11: =IF(OR(N11="",$N$4-SUMIF(C11:M11,"欠",$C$4:$M$4)<=0),"",ROUND(N11/($N$4-SUMIF(C11:M11,"欠",$C$4:$M$4))*100,0)) -> 86 | P11: =IF(O11="","",IF(O11>=設定!$D$11,"A",IF(O11>=設定!$E$11,"B","C"))) -> B | Q11: 37 | R11: 35 | S11: 40 | T11: 31 | U11: 29 | V11: 36 | AA11: =IF(COUNT(Q11:Z11)=0,"",SUM(Q11:Z11)) -> 208 | AB11: =IF(OR(AA11="",$AA$4-SUMIF(Q11:Z11,"欠",$Q$4:$Z$4)<=0),"",ROUND(AA11/($AA$4-SUMIF(Q11:Z11,"欠",$Q$4:$Z$4))*100,0)) -> 69 | AC11: =IF(AB11="","",IF(AB11>=設定!$D$11,"A",IF(AB11>=設定!$E$11,"B","C"))) -> B | AD11: =IF(AND(N11="",AA11=""),"",IF(N11="",0,N11)+IF(AA11="",0,AA11)) -> 465 | AE11: =IF(AD11="","",IF($AD$4-SUMIF(C11:M11,"欠",$C$4:$M$4)-SUMIF(Q11:Z11,"欠",$Q$4:$Z$4)<=0,"",ROUND(AD11/($AD$4-SUMIF(C11:M11,"欠",$C$4:$M$4)-SUMIF(Q11:Z11,"欠",$Q$4:$Z$4))*100,0))) -> 78 | AF11: =IF(AE11="","",IF(AE11>=設定!$D$11,"A",IF(AE11>=設定!$E$11,"B","C"))) -> B
A12: 8 | B12: =IF(名簿!B10="","",名簿!B10) -> 清水 莉子 | C12: 46 | D12: 50 | E12: 46 | F12: 欠 | G12: 47 | H12: 48 | N12: =IF(COUNT(C12:M12)=0,"",SUM(C12:M12)) -> 237 | O12: =IF(OR(N12="",$N$4-SUMIF(C12:M12,"欠",$C$4:$M$4)<=0),"",ROUND(N12/($N$4-SUMIF(C12:M12,"欠",$C$4:$M$4))*100,0)) -> 95 | P12: =IF(O12="","",IF(O12>=設定!$D$11,"A",IF(O12>=設定!$E$11,"B","C"))) -> A | Q12: 45 | R12: 36 | S12: 42 | T12: 欠 | U12: 36 | V12: 33 | AA12: =IF(COUNT(Q12:Z12)=0,"",SUM(Q12:Z12)) -> 192 | AB12: =IF(OR(AA12="",$AA$4-SUMIF(Q12:Z12,"欠",$Q$4:$Z$4)<=0),"",ROUND(AA12/($AA$4-SUMIF(Q12:Z12,"欠",$Q$4:$Z$4))*100,0)) -> 77 | AC12: =IF(AB12="","",IF(AB12>=設定!$D$11,"A",IF(AB12>=設定!$E$11,"B","C"))) -> B | AD12: =IF(AND(N12="",AA12=""),"",IF(N12="",0,N12)+IF(AA12="",0,AA12)) -> 429 | AE12: =IF(AD12="","",IF($AD$4-SUMIF(C12:M12,"欠",$C$4:$M$4)-SUMIF(Q12:Z12,"欠",$Q$4:$Z$4)<=0,"",ROUND(AD12/($AD$4-SUMIF(C12:M12,"欠",$C$4:$M$4)-SUMIF(Q12:Z12,"欠",$Q$4:$Z$4))*100,0))) -> 86 | AF12: =IF(AE12="","",IF(AE12>=設定!$D$11,"A",IF(AE12>=設定!$E$11,"B","C"))) -> B
A13: 9 | B13: =IF(名簿!B11="","",名簿!B11) -> 鈴木 海斗 | C13: 38 | D13: 40 | E13: 37 | F13: 42 | G13: 41 | H13: 39 | N13: =IF(COUNT(C13:M13)=0,"",SUM(C13:M13)) -> 237 | O13: =IF(OR(N13="",$N$4-SUMIF(C13:M13,"欠",$C$4:$M$4)<=0),"",ROUND(N13/($N$4-SUMIF(C13:M13,"欠",$C$4:$M$4))*100,0)) -> 79 | P13: =IF(O13="","",IF(O13>=設定!$D$11,"A",IF(O13>=設定!$E$11,"B","C"))) -> B | Q13: 28 | R13: 37 | S13: 38 | T13: 35 | U13: 32 | V13: 32 | AA13: =IF(COUNT(Q13:Z13)=0,"",SUM(Q13:Z13)) -> 202 | AB13: =IF(OR(AA13="",$AA$4-SUMIF(Q13:Z13,"欠",$Q$4:$Z$4)<=0),"",ROUND(AA13/($AA$4-SUMIF(Q13:Z13,"欠",$Q$4:$Z$4))*100,0)) -> 67 | AC13: =IF(AB13="","",IF(AB13>=設定!$D$11,"A",IF(AB13>=設定!$E$11,"B","C"))) -> B | AD13: =IF(AND(N13="",AA13=""),"",IF(N13="",0,N13)+IF(AA13="",0,AA13)) -> 439 | AE13: =IF(AD13="","",IF($AD$4-SUMIF(C13:M13,"欠",$C$4:$M$4)-SUMIF(Q13:Z13,"欠",$Q$4:$Z$4)<=0,"",ROUND(AD13/($AD$4-SUMIF(C13:M13,"欠",$C$4:$M$4)-SUMIF(Q13:Z13,"欠",$Q$4:$Z$4))*100,0))) -> 73 | AF13: =IF(AE13="","",IF(AE13>=設定!$D$11,"A",IF(AE13>=設定!$E$11,"B","C"))) -> B
A14: 10 | B14: =IF(名簿!B12="","",名簿!B12) -> 松本 さくら | C14: 50 | D14: 41 | E14: 43 | F14: 35 | G14: 48 | H14: 46 | N14: =IF(COUNT(C14:M14)=0,"",SUM(C14:M14)) -> 263 | O14: =IF(OR(N14="",$N$4-SUMIF(C14:M14,"欠",$C$4:$M$4)<=0),"",ROUND(N14/($N$4-SUMIF(C14:M14,"欠",$C$4:$M$4))*100,0)) -> 88 | P14: =IF(O14="","",IF(O14>=設定!$D$11,"A",IF(O14>=設定!$E$11,"B","C"))) -> B | Q14: 40 | R14: 47 | S14: 38 | T14: 43 | U14: 38 | V14: 36 | AA14: =IF(COUNT(Q14:Z14)=0,"",SUM(Q14:Z14)) -> 242 | AB14: =IF(OR(AA14="",$AA$4-SUMIF(Q14:Z14,"欠",$Q$4:$Z$4)<=0),"",ROUND(AA14/($AA$4-SUMIF(Q14:Z14,"欠",$Q$4:$Z$4))*100,0)) -> 81 | AC14: =IF(AB14="","",IF(AB14>=設定!$D$11,"A",IF(AB14>=設定!$E$11,"B","C"))) -> B | AD14: =IF(AND(N14="",AA14=""),"",IF(N14="",0,N14)+IF(AA14="",0,AA14)) -> 505 | AE14: =IF(AD14="","",IF($AD$4-SUMIF(C14:M14,"欠",$C$4:$M$4)-SUMIF(Q14:Z14,"欠",$Q$4:$Z$4)<=0,"",ROUND(AD14/($AD$4-SUMIF(C14:M14,"欠",$C$4:$M$4)-SUMIF(Q14:Z14,"欠",$Q$4:$Z$4))*100,0))) -> 84 | AF14: =IF(AE14="","",IF(AE14>=設定!$D$11,"A",IF(AE14>=設定!$E$11,"B","C"))) -> B
A15: 11 | B15: =IF(名簿!B13="","",名簿!B13) -> 岡田 健太 | C15: 46 | D15: 46 | E15: 50 | F15: 38 | G15: 43 | H15: 46 | N15: =IF(COUNT(C15:M15)=0,"",SUM(C15:M15)) -> 269 | O15: =IF(OR(N15="",$N$4-SUMIF(C15:M15,"欠",$C$4:$M$4)<=0),"",ROUND(N15/($N$4-SUMIF(C15:M15,"欠",$C$4:$M$4))*100,0)) -> 90 | P15: =IF(O15="","",IF(O15>=設定!$D$11,"A",IF(O15>=設定!$E$11,"B","C"))) -> A | Q15: 41 | R15: 39 | S15: 45 | T15: 42 | U15: 36 | V15: 39 | AA15: =IF(COUNT(Q15:Z15)=0,"",SUM(Q15:Z15)) -> 242 | AB15: =IF(OR(AA15="",$AA$4-SUMIF(Q15:Z15,"欠",$Q$4:$Z$4)<=0),"",ROUND(AA15/($AA$4-SUMIF(Q15:Z15,"欠",$Q$4:$Z$4))*100,0)) -> 81 | AC15: =IF(AB15="","",IF(AB15>=設定!$D$11,"A",IF(AB15>=設定!$E$11,"B","C"))) -> B | AD15: =IF(AND(N15="",AA15=""),"",IF(N15="",0,N15)+IF(AA15="",0,AA15)) -> 511 | AE15: =IF(AD15="","",IF($AD$4-SUMIF(C15:M15,"欠",$C$4:$M$4)-SUMIF(Q15:Z15,"欠",$Q$4:$Z$4)<=0,"",ROUND(AD15/($AD$4-SUMIF(C15:M15,"欠",$C$4:$M$4)-SUMIF(Q15:Z15,"欠",$Q$4:$Z$4))*100,0))) -> 85 | AF15: =IF(AE15="","",IF(AE15>=設定!$D$11,"A",IF(AE15>=設定!$E$11,"B","C"))) -> B
A16: 12 | B16: =IF(名簿!B14="","",名簿!B14) -> 佐々木 彩花 | C16: 35 | D16: 44 | E16: 46 | F16: 39 | G16: 41 | H16: 44 | N16: =IF(COUNT(C16:M16)=0,"",SUM(C16:M16)) -> 249 | O16: =IF(OR(N16="",$N$4-SUMIF(C16:M16,"欠",$C$4:$M$4)<=0),"",ROUND(N16/($N$4-SUMIF(C16:M16,"欠",$C$4:$M$4))*100,0)) -> 83 | P16: =IF(O16="","",IF(O16>=設定!$D$11,"A",IF(O16>=設定!$E$11,"B","C"))) -> B | Q16: 35 | R16: 34 | S16: 38 | T16: 34 | U16: 32 | V16: 33 | AA16: =IF(COUNT(Q16:Z16)=0,"",SUM(Q16:Z16)) -> 206 | AB16: =IF(OR(AA16="",$AA$4-SUMIF(Q16:Z16,"欠",$Q$4:$Z$4)<=0),"",ROUND(AA16/($AA$4-SUMIF(Q16:Z16,"欠",$Q$4:$Z$4))*100,0)) -> 69 | AC16: =IF(AB16="","",IF(AB16>=設定!$D$11,"A",IF(AB16>=設定!$E$11,"B","C"))) -> B | AD16: =IF(AND(N16="",AA16=""),"",IF(N16="",0,N16)+IF(AA16="",0,AA16)) -> 455 | AE16: =IF(AD16="","",IF($AD$4-SUMIF(C16:M16,"欠",$C$4:$M$4)-SUMIF(Q16:Z16,"欠",$Q$4:$Z$4)<=0,"",ROUND(AD16/($AD$4-SUMIF(C16:M16,"欠",$C$4:$M$4)-SUMIF(Q16:Z16,"欠",$Q$4:$Z$4))*100,0))) -> 76 | AF16: =IF(AE16="","",IF(AE16>=設定!$D$11,"A",IF(AE16>=設定!$E$11,"B","C"))) -> B
A17: 13 | B17: =IF(名簿!B15="","",名簿!B15) -> 石川 健太 | C17: 32 | D17: 30 | E17: 30 | F17: 37 | G17: 30 | H17: 27 | N17: =IF(COUNT(C17:M17)=0,"",SUM(C17:M17)) -> 186 | O17: =IF(OR(N17="",$N$4-SUMIF(C17:M17,"欠",$C$4:$M$4)<=0),"",ROUND(N17/($N$4-SUMIF(C17:M17,"欠",$C$4:$M$4))*100,0)) -> 62 | P17: =IF(O17="","",IF(O17>=設定!$D$11,"A",IF(O17>=設定!$E$11,"B","C"))) -> B | Q17: 26 | R17: 22 | S17: 29 | T17: 24 | U17: 20 | V17: 31 | AA17: =IF(COUNT(Q17:Z17)=0,"",SUM(Q17:Z17)) -> 152 | AB17: =IF(OR(AA17="",$AA$4-SUMIF(Q17:Z17,"欠",$Q$4:$Z$4)<=0),"",ROUND(AA17/($AA$4-SUMIF(Q17:Z17,"欠",$Q$4:$Z$4))*100,0)) -> 51 | AC17: =IF(AB17="","",IF(AB17>=設定!$D$11,"A",IF(AB17>=設定!$E$11,"B","C"))) -> C | AD17: =IF(AND(N17="",AA17=""),"",IF(N17="",0,N17)+IF(AA17="",0,AA17)) -> 338 | AE17: =IF(AD17="","",IF($AD$4-SUMIF(C17:M17,"欠",$C$4:$M$4)-SUMIF(Q17:Z17,"欠",$Q$4:$Z$4)<=0,"",ROUND(AD17/($AD$4-SUMIF(C17:M17,"欠",$C$4:$M$4)-SUMIF(Q17:Z17,"欠",$Q$4:$Z$4))*100,0))) -> 56 | AF17: =IF(AE17="","",IF(AE17>=設定!$D$11,"A",IF(AE17>=設定!$E$11,"B","C"))) -> C
A18: 14 | B18: =IF(名簿!B16="","",名簿!B16) -> 山崎 陽葵 | C18: 44 | D18: 44 | E18: 37 | F18: 46 | G18: 50 | H18: 44 | N18: =IF(COUNT(C18:M18)=0,"",SUM(C18:M18)) -> 265 | O18: =IF(OR(N18="",$N$4-SUMIF(C18:M18,"欠",$C$4:$M$4)<=0),"",ROUND(N18/($N$4-SUMIF(C18:M18,"欠",$C$4:$M$4))*100,0)) -> 88 | P18: =IF(O18="","",IF(O18>=設定!$D$11,"A",IF(O18>=設定!$E$11,"B","C"))) -> B | Q18: 47 | R18: 40 | S18: 45 | T18: 42 | U18: 40 | V18: 39 | AA18: =IF(COUNT(Q18:Z18)=0,"",SUM(Q18:Z18)) -> 253 | AB18: =IF(OR(AA18="",$AA$4-SUMIF(Q18:Z18,"欠",$Q$4:$Z$4)<=0),"",ROUND(AA18/($AA$4-SUMIF(Q18:Z18,"欠",$Q$4:$Z$4))*100,0)) -> 84 | AC18: =IF(AB18="","",IF(AB18>=設定!$D$11,"A",IF(AB18>=設定!$E$11,"B","C"))) -> B | AD18: =IF(AND(N18="",AA18=""),"",IF(N18="",0,N18)+IF(AA18="",0,AA18)) -> 518 | AE18: =IF(AD18="","",IF($AD$4-SUMIF(C18:M18,"欠",$C$4:$M$4)-SUMIF(Q18:Z18,"欠",$Q$4:$Z$4)<=0,"",ROUND(AD18/($AD$4-SUMIF(C18:M18,"欠",$C$4:$M$4)-SUMIF(Q18:Z18,"欠",$Q$4:$Z$4))*100,0))) -> 86 | AF18: =IF(AE18="","",IF(AE18>=設定!$D$11,"A",IF(AE18>=設定!$E$11,"B","C"))) -> B
A19: 15 | B19: =IF(名簿!B17="","",名簿!B17) -> 加藤 朝陽 | C19: 28 | D19: 24 | E19: 27 | F19: 31 | G19: 24 | H19: 32 | N19: =IF(COUNT(C19:M19)=0,"",SUM(C19:M19)) -> 166 | O19: =IF(OR(N19="",$N$4-SUMIF(C19:M19,"欠",$C$4:$M$4)<=0),"",ROUND(N19/($N$4-SUMIF(C19:M19,"欠",$C$4:$M$4))*100,0)) -> 55 | P19: =IF(O19="","",IF(O19>=設定!$D$11,"A",IF(O19>=設定!$E$11,"B","C"))) -> C | Q19: 19 | R19: 30 | S19: 21 | T19: 19 | U19: 21 | V19: 27 | AA19: =IF(COUNT(Q19:Z19)=0,"",SUM(Q19:Z19)) -> 137 | AB19: =IF(OR(AA19="",$AA$4-SUMIF(Q19:Z19,"欠",$Q$4:$Z$4)<=0),"",ROUND(AA19/($AA$4-SUMIF(Q19:Z19,"欠",$Q$4:$Z$4))*100,0)) -> 46 | AC19: =IF(AB19="","",IF(AB19>=設定!$D$11,"A",IF(AB19>=設定!$E$11,"B","C"))) -> C | AD19: =IF(AND(N19="",AA19=""),"",IF(N19="",0,N19)+IF(AA19="",0,AA19)) -> 303 | AE19: =IF(AD19="","",IF($AD$4-SUMIF(C19:M19,"欠",$C$4:$M$4)-SUMIF(Q19:Z19,"欠",$Q$4:$Z$4)<=0,"",ROUND(AD19/($AD$4-SUMIF(C19:M19,"欠",$C$4:$M$4)-SUMIF(Q19:Z19,"欠",$Q$4:$Z$4))*100,0))) -> 51 | AF19: =IF(AE19="","",IF(AE19>=設定!$D$11,"A",IF(AE19>=設定!$E$11,"B","C"))) -> C
A20: 16 | B20: =IF(名簿!B18="","",名簿!B18) -> 藤田 結愛 | C20: 49 | D20: 48 | E20: 50 | F20: 50 | G20: 50 | H20: 50 | N20: =IF(COUNT(C20:M20)=0,"",SUM(C20:M20)) -> 297 | O20: =IF(OR(N20="",$N$4-SUMIF(C20:M20,"欠",$C$4:$M$4)<=0),"",ROUND(N20/($N$4-SUMIF(C20:M20,"欠",$C$4:$M$4))*100,0)) -> 99 | P20: =IF(O20="","",IF(O20>=設定!$D$11,"A",IF(O20>=設定!$E$11,"B","C"))) -> A | Q20: 47 | R20: 47 | S20: 50 | T20: 48 | U20: 48 | V20: 49 | AA20: =IF(COUNT(Q20:Z20)=0,"",SUM(Q20:Z20)) -> 289 | AB20: =IF(OR(AA20="",$AA$4-SUMIF(Q20:Z20,"欠",$Q$4:$Z$4)<=0),"",ROUND(AA20/($AA$4-SUMIF(Q20:Z20,"欠",$Q$4:$Z$4))*100,0)) -> 96 | AC20: =IF(AB20="","",IF(AB20>=設定!$D$11,"A",IF(AB20>=設定!$E$11,"B","C"))) -> A | AD20: =IF(AND(N20="",AA20=""),"",IF(N20="",0,N20)+IF(AA20="",0,AA20)) -> 586 | AE20: =IF(AD20="","",IF($AD$4-SUMIF(C20:M20,"欠",$C$4:$M$4)-SUMIF(Q20:Z20,"欠",$Q$4:$Z$4)<=0,"",ROUND(AD20/($AD$4-SUMIF(C20:M20,"欠",$C$4:$M$4)-SUMIF(Q20:Z20,"欠",$Q$4:$Z$4))*100,0))) -> 98 | AF20: =IF(AE20="","",IF(AE20>=設定!$D$11,"A",IF(AE20>=設定!$E$11,"B","C"))) -> A
A21: 17 | B21: =IF(名簿!B19="","",名簿!B19) -> 田中 大和 | C21: 40 | D21: 43 | E21: 30 | F21: 50 | G21: 45 | H21: 47 | N21: =IF(COUNT(C21:M21)=0,"",SUM(C21:M21)) -> 255 | O21: =IF(OR(N21="",$N$4-SUMIF(C21:M21,"欠",$C$4:$M$4)<=0),"",ROUND(N21/($N$4-SUMIF(C21:M21,"欠",$C$4:$M$4))*100,0)) -> 85 | P21: =IF(O21="","",IF(O21>=設定!$D$11,"A",IF(O21>=設定!$E$11,"B","C"))) -> B | Q21: 31 | R21: 33 | S21: 34 | T21: 40 | U21: 37 | V21: 34 | AA21: =IF(COUNT(Q21:Z21)=0,"",SUM(Q21:Z21)) -> 209 | AB21: =IF(OR(AA21="",$AA$4-SUMIF(Q21:Z21,"欠",$Q$4:$Z$4)<=0),"",ROUND(AA21/($AA$4-SUMIF(Q21:Z21,"欠",$Q$4:$Z$4))*100,0)) -> 70 | AC21: =IF(AB21="","",IF(AB21>=設定!$D$11,"A",IF(AB21>=設定!$E$11,"B","C"))) -> B | AD21: =IF(AND(N21="",AA21=""),"",IF(N21="",0,N21)+IF(AA21="",0,AA21)) -> 464 | AE21: =IF(AD21="","",IF($AD$4-SUMIF(C21:M21,"欠",$C$4:$M$4)-SUMIF(Q21:Z21,"欠",$Q$4:$Z$4)<=0,"",ROUND(AD21/($AD$4-SUMIF(C21:M21,"欠",$C$4:$M$4)-SUMIF(Q21:Z21,"欠",$Q$4:$Z$4))*100,0))) -> 77 | AF21: =IF(AE21="","",IF(AE21>=設定!$D$11,"A",IF(AE21>=設定!$E$11,"B","C"))) -> B
A22: 18 | B22: =IF(名簿!B20="","",名簿!B20) -> 山口 心春 | C22: 50 | D22: 50 | E22: 50 | F22: 50 | G22: 50 | H22: 50 | N22: =IF(COUNT(C22:M22)=0,"",SUM(C22:M22)) -> 300 | O22: =IF(OR(N22="",$N$4-SUMIF(C22:M22,"欠",$C$4:$M$4)<=0),"",ROUND(N22/($N$4-SUMIF(C22:M22,"欠",$C$4:$M$4))*100,0)) -> 100 | P22: =IF(O22="","",IF(O22>=設定!$D$11,"A",IF(O22>=設定!$E$11,"B","C"))) -> A | Q22: 50 | R22: 50 | S22: 47 | T22: 50 | U22: 50 | V22: 50 | AA22: =IF(COUNT(Q22:Z22)=0,"",SUM(Q22:Z22)) -> 297 | AB22: =IF(OR(AA22="",$AA$4-SUMIF(Q22:Z22,"欠",$Q$4:$Z$4)<=0),"",ROUND(AA22/($AA$4-SUMIF(Q22:Z22,"欠",$Q$4:$Z$4))*100,0)) -> 99 | AC22: =IF(AB22="","",IF(AB22>=設定!$D$11,"A",IF(AB22>=設定!$E$11,"B","C"))) -> A | AD22: =IF(AND(N22="",AA22=""),"",IF(N22="",0,N22)+IF(AA22="",0,AA22)) -> 597 | AE22: =IF(AD22="","",IF($AD$4-SUMIF(C22:M22,"欠",$C$4:$M$4)-SUMIF(Q22:Z22,"欠",$Q$4:$Z$4)<=0,"",ROUND(AD22/($AD$4-SUMIF(C22:M22,"欠",$C$4:$M$4)-SUMIF(Q22:Z22,"欠",$Q$4:$Z$4))*100,0))) -> 100 | AF22: =IF(AE22="","",IF(AE22>=設定!$D$11,"A",IF(AE22>=設定!$E$11,"B","C"))) -> A
A23: 19 | B23: =IF(名簿!B21="","",名簿!B21) -> 山本 朝陽 | C23: 42 | D23: 44 | E23: 47 | F23: 49 | G23: 45 | H23: 47 | N23: =IF(COUNT(C23:M23)=0,"",SUM(C23:M23)) -> 274 | O23: =IF(OR(N23="",$N$4-SUMIF(C23:M23,"欠",$C$4:$M$4)<=0),"",ROUND(N23/($N$4-SUMIF(C23:M23,"欠",$C$4:$M$4))*100,0)) -> 91 | P23: =IF(O23="","",IF(O23>=設定!$D$11,"A",IF(O23>=設定!$E$11,"B","C"))) -> A | Q23: 48 | R23: 48 | S23: 41 | T23: 39 | U23: 48 | V23: 41 | AA23: =IF(COUNT(Q23:Z23)=0,"",SUM(Q23:Z23)) -> 265 | AB23: =IF(OR(AA23="",$AA$4-SUMIF(Q23:Z23,"欠",$Q$4:$Z$4)<=0),"",ROUND(AA23/($AA$4-SUMIF(Q23:Z23,"欠",$Q$4:$Z$4))*100,0)) -> 88 | AC23: =IF(AB23="","",IF(AB23>=設定!$D$11,"A",IF(AB23>=設定!$E$11,"B","C"))) -> B | AD23: =IF(AND(N23="",AA23=""),"",IF(N23="",0,N23)+IF(AA23="",0,AA23)) -> 539 | AE23: =IF(AD23="","",IF($AD$4-SUMIF(C23:M23,"欠",$C$4:$M$4)-SUMIF(Q23:Z23,"欠",$Q$4:$Z$4)<=0,"",ROUND(AD23/($AD$4-SUMIF(C23:M23,"欠",$C$4:$M$4)-SUMIF(Q23:Z23,"欠",$Q$4:$Z$4))*100,0))) -> 90 | AF23: =IF(AE23="","",IF(AE23>=設定!$D$11,"A",IF(AE23>=設定!$E$11,"B","C"))) -> A
A24: 20 | B24: =IF(名簿!B22="","",名簿!B22) -> 前田 彩花 | C24: 33 | D24: 39 | E24: 35 | F24: 35 | G24: 29 | H24: 37 | N24: =IF(COUNT(C24:M24)=0,"",SUM(C24:M24)) -> 208 | O24: =IF(OR(N24="",$N$4-SUMIF(C24:M24,"欠",$C$4:$M$4)<=0),"",ROUND(N24/($N$4-SUMIF(C24:M24,"欠",$C$4:$M$4))*100,0)) -> 69 | P24: =IF(O24="","",IF(O24>=設定!$D$11,"A",IF(O24>=設定!$E$11,"B","C"))) -> B | Q24: 26 | R24: 35 | S24: 28 | T24: 29 | U24: 27 | V24: 33 | AA24: =IF(COUNT(Q24:Z24)=0,"",SUM(Q24:Z24)) -> 178 | AB24: =IF(OR(AA24="",$AA$4-SUMIF(Q24:Z24,"欠",$Q$4:$Z$4)<=0),"",ROUND(AA24/($AA$4-SUMIF(Q24:Z24,"欠",$Q$4:$Z$4))*100,0)) -> 59 | AC24: =IF(AB24="","",IF(AB24>=設定!$D$11,"A",IF(AB24>=設定!$E$11,"B","C"))) -> C | AD24: =IF(AND(N24="",AA24=""),"",IF(N24="",0,N24)+IF(AA24="",0,AA24)) -> 386 | AE24: =IF(AD24="","",IF($AD$4-SUMIF(C24:M24,"欠",$C$4:$M$4)-SUMIF(Q24:Z24,"欠",$Q$4:$Z$4)<=0,"",ROUND(AD24/($AD$4-SUMIF(C24:M24,"欠",$C$4:$M$4)-SUMIF(Q24:Z24,"欠",$Q$4:$Z$4))*100,0))) -> 64 | AF24: =IF(AE24="","",IF(AE24>=設定!$D$11,"A",IF(AE24>=設定!$E$11,"B","C"))) -> B
... A39: 35 | B39: =IF(名簿!B37="","",名簿!B37) -> 渡辺 健太 | C39: 40 | D39: 39 | E39: 46 | F39: 50 | G39: 50 | H39: 39 | N39: =IF(COUNT(C39:M39)=0,"",SUM(C39:M39)) -> 264 | O39: =IF(OR(N39="",$N$4-SUMIF(C39:M39,"欠",$C$4:$M$4)<=0),"",ROUND(N39/($N$4-SUMIF(C39:M39,"欠",$C$4:$M$4))*100,0)) -> 88 | P39: =IF(O39="","",IF(O39>=設定!$D$11,"A",IF(O39>=設定!$E$11,"B","C"))) -> B | Q39: 43 | R39: 41 | S39: 37 | T39: 43 | U39: 45 | V39: 40 | AA39: =IF(COUNT(Q39:Z39)=0,"",SUM(Q39:Z39)) -> 249 | AB39: =IF(OR(AA39="",$AA$4-SUMIF(Q39:Z39,"欠",$Q$4:$Z$4)<=0),"",ROUND(AA39/($AA$4-SUMIF(Q39:Z39,"欠",$Q$4:$Z$4))*100,0)) -> 83 | AC39: =IF(AB39="","",IF(AB39>=設定!$D$11,"A",IF(AB39>=設定!$E$11,"B","C"))) -> B | AD39: =IF(AND(N39="",AA39=""),"",IF(N39="",0,N39)+IF(AA39="",0,AA39)) -> 513 | AE39: =IF(AD39="","",IF($AD$4-SUMIF(C39:M39,"欠",$C$4:$M$4)-SUMIF(Q39:Z39,"欠",$Q$4:$Z$4)<=0,"",ROUND(AD39/($AD$4-SUMIF(C39:M39,"欠",$C$4:$M$4)-SUMIF(Q39:Z39,"欠",$Q$4:$Z$4))*100,0))) -> 86 | AF39: =IF(AE39="","",IF(AE39>=設定!$D$11,"A",IF(AE39>=設定!$E$11,"B","C"))) -> B
B40: 平 均 | C40: =IF(COUNT(C5:C39)=0,"",ROUND(AVERAGE(C5:C39),1)) -> 41.4 | D40: =IF(COUNT(D5:D39)=0,"",ROUND(AVERAGE(D5:D39),1)) -> 41.2 | E40: =IF(COUNT(E5:E39)=0,"",ROUND(AVERAGE(E5:E39),1)) -> 41.7 | F40: =IF(COUNT(F5:F39)=0,"",ROUND(AVERAGE(F5:F39),1)) -> 42.8 | G40: =IF(COUNT(G5:G39)=0,"",ROUND(AVERAGE(G5:G39),1)) -> 41.5 | H40: =IF(COUNT(H5:H39)=0,"",ROUND(AVERAGE(H5:H39),1)) -> 42.2 | I40: =IF(COUNT(I5:I39)=0,"",ROUND(AVERAGE(I5:I39),1)) | J40: =IF(COUNT(J5:J39)=0,"",ROUND(AVERAGE(J5:J39),1)) | ... O40: =IF(COUNT(O5:O39)=0,"",ROUND(AVERAGE(O5:O39),1)) -> 83.6 | Q40: =IF(COUNT(Q5:Q39)=0,"",ROUND(AVERAGE(Q5:Q39),1)) -> 36.9 | R40: =IF(COUNT(R5:R39)=0,"",ROUND(AVERAGE(R5:R39),1)) -> 37.6 | S40: =IF(COUNT(S5:S39)=0,"",ROUND(AVERAGE(S5:S39),1)) -> 38.1 | T40: =IF(COUNT(T5:T39)=0,"",ROUND(AVERAGE(T5:T39),1)) -> 37.3 | U40: =IF(COUNT(U5:U39)=0,"",ROUND(AVERAGE(U5:U39),1)) -> 37.4 | V40: =IF(COUNT(V5:V39)=0,"",ROUND(AVERAGE(V5:V39),1)) -> 37.3 | W40: =IF(COUNT(W5:W39)=0,"",ROUND(AVERAGE(W5:W39),1)) | X40: =IF(COUNT(X5:X39)=0,"",ROUND(AVERAGE(X5:X39),1)) | ... AB40: =IF(COUNT(AB5:AB39)=0,"",ROUND(AVERAGE(AB5:AB39),1)) -> 74.9 | AD40: =IF(COUNT(AD5:AD39)=0,"",ROUND(AVERAGE(AD5:AD39),1)) -> 472.9 | AE40: =IF(COUNT(AE5:AE39)=0,"",ROUND(AVERAGE(AE5:AE39),1)) -> 79.3
B41: Ａの人数 | P41: =COUNTIF(P5:P39,"A") -> 13 | AC41: =COUNTIF(AC5:AC39,"A") -> 4 | AF41: =COUNTIF(AF5:AF39,"A") -> 8
B42: Ｂの人数 | P42: =COUNTIF(P5:P39,"B") -> 21 | AC42: =COUNTIF(AC5:AC39,"B") -> 26 | AF42: =COUNTIF(AF5:AF39,"B") -> 25
B43: Ｃの人数 | P43: =COUNTIF(P5:P39,"C") -> 1 | AC43: =COUNTIF(AC5:AC39,"C") -> 5 | AF43: =COUNTIF(AF5:AF39,"C") -> 2

Sheet 算数（前期）
A1: 観点別得点集計表（算数・前期）
A2: 観 点 | C2: 知識・技能 | Q2: 思考・判断・表現 | AD2: 合 計
A3: 単元名 | C3: 対称な図形 | D3: 文字と式 | E3: 分数のかけ算 | F3: 分数のわり算 | G3: 比 | H3: 拡大図と縮図 | N3: 観点合計 | O3: 観点到達率 | P3: 観点別学習状況評価 | Q3: 対称な図形 | R3: 文字と式 | S3: 分数のかけ算 | T3: 分数のわり算 | U3: 比 | V3: 拡大図と縮図 | AA3: 観点合計 | AB3: 観点到達率 | AC3: 観点別学習状況評価 | AD3: 総得点 | AE3: 総得点到達率 | AF3: 総得点学習状況評価
A4: 番 | B4: 名前/配点 | C4: 50 | D4: 50 | E4: 50 | F4: 50 | G4: 50 | H4: 50 | N4: =SUM(C4:M4) -> 300 | Q4: 50 | R4: 50 | S4: 50 | T4: 50 | U4: 50 | V4: 50 | AA4: =SUM(Q4:Z4) -> 300 | AD4: =N4+AA4 -> 600
A5: 1 | B5: =IF(名簿!B3="","",名簿!B3) -> 石井 湊 | C5: 50 | D5: 50 | E5: 50 | F5: 50 | G5: 50 | H5: 50 | N5: =IF(COUNT(C5:M5)=0,"",SUM(C5:M5)) -> 300 | O5: =IF(OR(N5="",$N$4-SUMIF(C5:M5,"欠",$C$4:$M$4)<=0),"",ROUND(N5/($N$4-SUMIF(C5:M5,"欠",$C$4:$M$4))*100,0)) -> 100 | P5: =IF(O5="","",IF(O5>=設定!$D$12,"A",IF(O5>=設定!$E$12,"B","C"))) -> A | Q5: 43 | R5: 50 | S5: 45 | T5: 47 | U5: 50 | V5: 45 | AA5: =IF(COUNT(Q5:Z5)=0,"",SUM(Q5:Z5)) -> 280 | AB5: =IF(OR(AA5="",$AA$4-SUMIF(Q5:Z5,"欠",$Q$4:$Z$4)<=0),"",ROUND(AA5/($AA$4-SUMIF(Q5:Z5,"欠",$Q$4:$Z$4))*100,0)) -> 93 | AC5: =IF(AB5="","",IF(AB5>=設定!$D$12,"A",IF(AB5>=設定!$E$12,"B","C"))) -> A | AD5: =IF(AND(N5="",AA5=""),"",IF(N5="",0,N5)+IF(AA5="",0,AA5)) -> 580 | AE5: =IF(AD5="","",IF($AD$4-SUMIF(C5:M5,"欠",$C$4:$M$4)-SUMIF(Q5:Z5,"欠",$Q$4:$Z$4)<=0,"",ROUND(AD5/($AD$4-SUMIF(C5:M5,"欠",$C$4:$M$4)-SUMIF(Q5:Z5,"欠",$Q$4:$Z$4))*100,0))) -> 97 | AF5: =IF(AE5="","",IF(AE5>=設定!$D$12,"A",IF(AE5>=設定!$E$12,"B","C"))) -> A
A6: 2 | B6: =IF(名簿!B4="","",名簿!B4) -> 池田 さくら | C6: 50 | D6: 50 | E6: 41 | F6: 44 | G6: 43 | H6: 49 | N6: =IF(COUNT(C6:M6)=0,"",SUM(C6:M6)) -> 277 | O6: =IF(OR(N6="",$N$4-SUMIF(C6:M6,"欠",$C$4:$M$4)<=0),"",ROUND(N6/($N$4-SUMIF(C6:M6,"欠",$C$4:$M$4))*100,0)) -> 92 | P6: =IF(O6="","",IF(O6>=設定!$D$12,"A",IF(O6>=設定!$E$12,"B","C"))) -> A | Q6: 35 | R6: 39 | S6: 36 | T6: 39 | U6: 39 | V6: 34 | AA6: =IF(COUNT(Q6:Z6)=0,"",SUM(Q6:Z6)) -> 222 | AB6: =IF(OR(AA6="",$AA$4-SUMIF(Q6:Z6,"欠",$Q$4:$Z$4)<=0),"",ROUND(AA6/($AA$4-SUMIF(Q6:Z6,"欠",$Q$4:$Z$4))*100,0)) -> 74 | AC6: =IF(AB6="","",IF(AB6>=設定!$D$12,"A",IF(AB6>=設定!$E$12,"B","C"))) -> B | AD6: =IF(AND(N6="",AA6=""),"",IF(N6="",0,N6)+IF(AA6="",0,AA6)) -> 499 | AE6: =IF(AD6="","",IF($AD$4-SUMIF(C6:M6,"欠",$C$4:$M$4)-SUMIF(Q6:Z6,"欠",$Q$4:$Z$4)<=0,"",ROUND(AD6/($AD$4-SUMIF(C6:M6,"欠",$C$4:$M$4)-SUMIF(Q6:Z6,"欠",$Q$4:$Z$4))*100,0))) -> 83 | AF6: =IF(AE6="","",IF(AE6>=設定!$D$12,"A",IF(AE6>=設定!$E$12,"B","C"))) -> B
A7: 3 | B7: =IF(名簿!B5="","",名簿!B5) -> 林 陽翔 | C7: 49 | D7: 50 | E7: 47 | F7: 43 | G7: 48 | H7: 49 | N7: =IF(COUNT(C7:M7)=0,"",SUM(C7:M7)) -> 286 | O7: =IF(OR(N7="",$N$4-SUMIF(C7:M7,"欠",$C$4:$M$4)<=0),"",ROUND(N7/($N$4-SUMIF(C7:M7,"欠",$C$4:$M$4))*100,0)) -> 95 | P7: =IF(O7="","",IF(O7>=設定!$D$12,"A",IF(O7>=設定!$E$12,"B","C"))) -> A | Q7: 48 | R7: 39 | S7: 49 | T7: 49 | U7: 41 | V7: 33 | AA7: =IF(COUNT(Q7:Z7)=0,"",SUM(Q7:Z7)) -> 259 | AB7: =IF(OR(AA7="",$AA$4-SUMIF(Q7:Z7,"欠",$Q$4:$Z$4)<=0),"",ROUND(AA7/($AA$4-SUMIF(Q7:Z7,"欠",$Q$4:$Z$4))*100,0)) -> 86 | AC7: =IF(AB7="","",IF(AB7>=設定!$D$12,"A",IF(AB7>=設定!$E$12,"B","C"))) -> A | AD7: =IF(AND(N7="",AA7=""),"",IF(N7="",0,N7)+IF(AA7="",0,AA7)) -> 545 | AE7: =IF(AD7="","",IF($AD$4-SUMIF(C7:M7,"欠",$C$4:$M$4)-SUMIF(Q7:Z7,"欠",$Q$4:$Z$4)<=0,"",ROUND(AD7/($AD$4-SUMIF(C7:M7,"欠",$C$4:$M$4)-SUMIF(Q7:Z7,"欠",$Q$4:$Z$4))*100,0))) -> 91 | AF7: =IF(AE7="","",IF(AE7>=設定!$D$12,"A",IF(AE7>=設定!$E$12,"B","C"))) -> A
A8: 4 | B8: =IF(名簿!B6="","",名簿!B6) -> 村上 凛 | C8: 43 | D8: 44 | E8: 40 | F8: 45 | G8: 33 | H8: 36 | N8: =IF(COUNT(C8:M8)=0,"",SUM(C8:M8)) -> 241 | O8: =IF(OR(N8="",$N$4-SUMIF(C8:M8,"欠",$C$4:$M$4)<=0),"",ROUND(N8/($N$4-SUMIF(C8:M8,"欠",$C$4:$M$4))*100,0)) -> 80 | P8: =IF(O8="","",IF(O8>=設定!$D$12,"A",IF(O8>=設定!$E$12,"B","C"))) -> B | Q8: 46 | R8: 39 | S8: 34 | T8: 33 | U8: 39 | V8: 39 | AA8: =IF(COUNT(Q8:Z8)=0,"",SUM(Q8:Z8)) -> 230 | AB8: =IF(OR(AA8="",$AA$4-SUMIF(Q8:Z8,"欠",$Q$4:$Z$4)<=0),"",ROUND(AA8/($AA$4-SUMIF(Q8:Z8,"欠",$Q$4:$Z$4))*100,0)) -> 77 | AC8: =IF(AB8="","",IF(AB8>=設定!$D$12,"A",IF(AB8>=設定!$E$12,"B","C"))) -> B | AD8: =IF(AND(N8="",AA8=""),"",IF(N8="",0,N8)+IF(AA8="",0,AA8)) -> 471 | AE8: =IF(AD8="","",IF($AD$4-SUMIF(C8:M8,"欠",$C$4:$M$4)-SUMIF(Q8:Z8,"欠",$Q$4:$Z$4)<=0,"",ROUND(AD8/($AD$4-SUMIF(C8:M8,"欠",$C$4:$M$4)-SUMIF(Q8:Z8,"欠",$Q$4:$Z$4))*100,0))) -> 79 | AF8: =IF(AE8="","",IF(AE8>=設定!$D$12,"A",IF(AE8>=設定!$E$12,"B","C"))) -> B
A9: 5 | B9: =IF(名簿!B7="","",名簿!B7) -> 中村 蓮 | C9: 50 | D9: 50 | E9: 49 | F9: 43 | G9: 47 | H9: 50 | N9: =IF(COUNT(C9:M9)=0,"",SUM(C9:M9)) -> 289 | O9: =IF(OR(N9="",$N$4-SUMIF(C9:M9,"欠",$C$4:$M$4)<=0),"",ROUND(N9/($N$4-SUMIF(C9:M9,"欠",$C$4:$M$4))*100,0)) -> 96 | P9: =IF(O9="","",IF(O9>=設定!$D$12,"A",IF(O9>=設定!$E$12,"B","C"))) -> A | Q9: 43 | R9: 45 | S9: 49 | T9: 50 | U9: 46 | V9: 46 | AA9: =IF(COUNT(Q9:Z9)=0,"",SUM(Q9:Z9)) -> 279 | AB9: =IF(OR(AA9="",$AA$4-SUMIF(Q9:Z9,"欠",$Q$4:$Z$4)<=0),"",ROUND(AA9/($AA$4-SUMIF(Q9:Z9,"欠",$Q$4:$Z$4))*100,0)) -> 93 | AC9: =IF(AB9="","",IF(AB9>=設定!$D$12,"A",IF(AB9>=設定!$E$12,"B","C"))) -> A | AD9: =IF(AND(N9="",AA9=""),"",IF(N9="",0,N9)+IF(AA9="",0,AA9)) -> 568 | AE9: =IF(AD9="","",IF($AD$4-SUMIF(C9:M9,"欠",$C$4:$M$4)-SUMIF(Q9:Z9,"欠",$Q$4:$Z$4)<=0,"",ROUND(AD9/($AD$4-SUMIF(C9:M9,"欠",$C$4:$M$4)-SUMIF(Q9:Z9,"欠",$Q$4:$Z$4))*100,0))) -> 95 | AF9: =IF(AE9="","",IF(AE9>=設定!$D$12,"A",IF(AE9>=設定!$E$12,"B","C"))) -> A
A10: 6 | B10: =IF(名簿!B8="","",名簿!B8) -> 小川 彩花 | C10: 43 | D10: 39 | E10: 36 | F10: 40 | G10: 32 | H10: 36 | N10: =IF(COUNT(C10:M10)=0,"",SUM(C10:M10)) -> 226 | O10: =IF(OR(N10="",$N$4-SUMIF(C10:M10,"欠",$C$4:$M$4)<=0),"",ROUND(N10/($N$4-SUMIF(C10:M10,"欠",$C$4:$M$4))*100,0)) -> 75 | P10: =IF(O10="","",IF(O10>=設定!$D$12,"A",IF(O10>=設定!$E$12,"B","C"))) -> B | Q10: 31 | R10: 30 | S10: 30 | T10: 26 | U10: 34 | V10: 33 | AA10: =IF(COUNT(Q10:Z10)=0,"",SUM(Q10:Z10)) -> 184 | AB10: =IF(OR(AA10="",$AA$4-SUMIF(Q10:Z10,"欠",$Q$4:$Z$4)<=0),"",ROUND(AA10/($AA$4-SUMIF(Q10:Z10,"欠",$Q$4:$Z$4))*100,0)) -> 61 | AC10: =IF(AB10="","",IF(AB10>=設定!$D$12,"A",IF(AB10>=設定!$E$12,"B","C"))) -> B | AD10: =IF(AND(N10="",AA10=""),"",IF(N10="",0,N10)+IF(AA10="",0,AA10)) -> 410 | AE10: =IF(AD10="","",IF($AD$4-SUMIF(C10:M10,"欠",$C$4:$M$4)-SUMIF(Q10:Z10,"欠",$Q$4:$Z$4)<=0,"",ROUND(AD10/($AD$4-SUMIF(C10:M10,"欠",$C$4:$M$4)-SUMIF(Q10:Z10,"欠",$Q$4:$Z$4))*100,0))) -> 68 | AF10: =IF(AE10="","",IF(AE10>=設定!$D$12,"A",IF(AE10>=設定!$E$12,"B","C"))) -> B
A11: 7 | B11: =IF(名簿!B9="","",名簿!B9) -> 近藤 蒼 | C11: 44 | D11: 41 | E11: 44 | F11: 44 | G11: 36 | H11: 38 | N11: =IF(COUNT(C11:M11)=0,"",SUM(C11:M11)) -> 247 | O11: =IF(OR(N11="",$N$4-SUMIF(C11:M11,"欠",$C$4:$M$4)<=0),"",ROUND(N11/($N$4-SUMIF(C11:M11,"欠",$C$4:$M$4))*100,0)) -> 82 | P11: =IF(O11="","",IF(O11>=設定!$D$12,"A",IF(O11>=設定!$E$12,"B","C"))) -> B | Q11: 41 | R11: 38 | S11: 40 | T11: 30 | U11: 40 | V11: 40 | AA11: =IF(COUNT(Q11:Z11)=0,"",SUM(Q11:Z11)) -> 229 | AB11: =IF(OR(AA11="",$AA$4-SUMIF(Q11:Z11,"欠",$Q$4:$Z$4)<=0),"",ROUND(AA11/($AA$4-SUMIF(Q11:Z11,"欠",$Q$4:$Z$4))*100,0)) -> 76 | AC11: =IF(AB11="","",IF(AB11>=設定!$D$12,"A",IF(AB11>=設定!$E$12,"B","C"))) -> B | AD11: =IF(AND(N11="",AA11=""),"",IF(N11="",0,N11)+IF(AA11="",0,AA11)) -> 476 | AE11: =IF(AD11="","",IF($AD$4-SUMIF(C11:M11,"欠",$C$4:$M$4)-SUMIF(Q11:Z11,"欠",$Q$4:$Z$4)<=0,"",ROUND(AD11/($AD$4-SUMIF(C11:M11,"欠",$C$4:$M$4)-SUMIF(Q11:Z11,"欠",$Q$4:$Z$4))*100,0))) -> 79 | AF11: =IF(AE11="","",IF(AE11>=設定!$D$12,"A",IF(AE11>=設定!$E$12,"B","C"))) -> B
A12: 8 | B12: =IF(名簿!B10="","",名簿!B10) -> 清水 莉子 | C12: 47 | D12: 50 | E12: 欠 | F12: 46 | G12: 43 | H12: 45 | N12: =IF(COUNT(C12:M12)=0,"",SUM(C12:M12)) -> 231 | O12: =IF(OR(N12="",$N$4-SUMIF(C12:M12,"欠",$C$4:$M$4)<=0),"",ROUND(N12/($N$4-SUMIF(C12:M12,"欠",$C$4:$M$4))*100,0)) -> 92 | P12: =IF(O12="","",IF(O12>=設定!$D$12,"A",IF(O12>=設定!$E$12,"B","C"))) -> A | Q12: 32 | R12: 45 | S12: 欠 | T12: 40 | U12: 39 | V12: 42 | AA12: =IF(COUNT(Q12:Z12)=0,"",SUM(Q12:Z12)) -> 198 | AB12: =IF(OR(AA12="",$AA$4-SUMIF(Q12:Z12,"欠",$Q$4:$Z$4)<=0),"",ROUND(AA12/($AA$4-SUMIF(Q12:Z12,"欠",$Q$4:$Z$4))*100,0)) -> 79 | AC12: =IF(AB12="","",IF(AB12>=設定!$D$12,"A",IF(AB12>=設定!$E$12,"B","C"))) -> B | AD12: =IF(AND(N12="",AA12=""),"",IF(N12="",0,N12)+IF(AA12="",0,AA12)) -> 429 | AE12: =IF(AD12="","",IF($AD$4-SUMIF(C12:M12,"欠",$C$4:$M$4)-SUMIF(Q12:Z12,"欠",$Q$4:$Z$4)<=0,"",ROUND(AD12/($AD$4-SUMIF(C12:M12,"欠",$C$4:$M$4)-SUMIF(Q12:Z12,"欠",$Q$4:$Z$4))*100,0))) -> 86 | AF12: =IF(AE12="","",IF(AE12>=設定!$D$12,"A",IF(AE12>=設定!$E$12,"B","C"))) -> A
A13: 9 | B13: =IF(名簿!B11="","",名簿!B11) -> 鈴木 海斗 | C13: 41 | D13: 43 | E13: 35 | F13: 34 | G13: 41 | H13: 34 | N13: =IF(COUNT(C13:M13)=0,"",SUM(C13:M13)) -> 228 | O13: =IF(OR(N13="",$N$4-SUMIF(C13:M13,"欠",$C$4:$M$4)<=0),"",ROUND(N13/($N$4-SUMIF(C13:M13,"欠",$C$4:$M$4))*100,0)) -> 76 | P13: =IF(O13="","",IF(O13>=設定!$D$12,"A",IF(O13>=設定!$E$12,"B","C"))) -> B | Q13: 38 | R13: 35 | S13: 32 | T13: 36 | U13: 34 | V13: 41 | AA13: =IF(COUNT(Q13:Z13)=0,"",SUM(Q13:Z13)) -> 216 | AB13: =IF(OR(AA13="",$AA$4-SUMIF(Q13:Z13,"欠",$Q$4:$Z$4)<=0),"",ROUND(AA13/($AA$4-SUMIF(Q13:Z13,"欠",$Q$4:$Z$4))*100,0)) -> 72 | AC13: =IF(AB13="","",IF(AB13>=設定!$D$12,"A",IF(AB13>=設定!$E$12,"B","C"))) -> B | AD13: =IF(AND(N13="",AA13=""),"",IF(N13="",0,N13)+IF(AA13="",0,AA13)) -> 444 | AE13: =IF(AD13="","",IF($AD$4-SUMIF(C13:M13,"欠",$C$4:$M$4)-SUMIF(Q13:Z13,"欠",$Q$4:$Z$4)<=0,"",ROUND(AD13/($AD$4-SUMIF(C13:M13,"欠",$C$4:$M$4)-SUMIF(Q13:Z13,"欠",$Q$4:$Z$4))*100,0))) -> 74 | AF13: =IF(AE13="","",IF(AE13>=設定!$D$12,"A",IF(AE13>=設定!$E$12,"B","C"))) -> B
A14: 10 | B14: =IF(名簿!B12="","",名簿!B12) -> 松本 さくら | C14: 42 | D14: 50 | E14: 45 | F14: 44 | G14: 41 | H14: 38 | N14: =IF(COUNT(C14:M14)=0,"",SUM(C14:M14)) -> 260 | O14: =IF(OR(N14="",$N$4-SUMIF(C14:M14,"欠",$C$4:$M$4)<=0),"",ROUND(N14/($N$4-SUMIF(C14:M14,"欠",$C$4:$M$4))*100,0)) -> 87 | P14: =IF(O14="","",IF(O14>=設定!$D$12,"A",IF(O14>=設定!$E$12,"B","C"))) -> A | Q14: 40 | R14: 39 | S14: 32 | T14: 43 | U14: 42 | V14: 39 | AA14: =IF(COUNT(Q14:Z14)=0,"",SUM(Q14:Z14)) -> 235 | AB14: =IF(OR(AA14="",$AA$4-SUMIF(Q14:Z14,"欠",$Q$4:$Z$4)<=0),"",ROUND(AA14/($AA$4-SUMIF(Q14:Z14,"欠",$Q$4:$Z$4))*100,0)) -> 78 | AC14: =IF(AB14="","",IF(AB14>=設定!$D$12,"A",IF(AB14>=設定!$E$12,"B","C"))) -> B | AD14: =IF(AND(N14="",AA14=""),"",IF(N14="",0,N14)+IF(AA14="",0,AA14)) -> 495 | AE14: =IF(AD14="","",IF($AD$4-SUMIF(C14:M14,"欠",$C$4:$M$4)-SUMIF(Q14:Z14,"欠",$Q$4:$Z$4)<=0,"",ROUND(AD14/($AD$4-SUMIF(C14:M14,"欠",$C$4:$M$4)-SUMIF(Q14:Z14,"欠",$Q$4:$Z$4))*100,0))) -> 83 | AF14: =IF(AE14="","",IF(AE14>=設定!$D$12,"A",IF(AE14>=設定!$E$12,"B","C"))) -> B
A15: 11 | B15: =IF(名簿!B13="","",名簿!B13) -> 岡田 健太 | C15: 46 | D15: 45 | E15: 47 | F15: 39 | G15: 35 | H15: 45 | N15: =IF(COUNT(C15:M15)=0,"",SUM(C15:M15)) -> 257 | O15: =IF(OR(N15="",$N$4-SUMIF(C15:M15,"欠",$C$4:$M$4)<=0),"",ROUND(N15/($N$4-SUMIF(C15:M15,"欠",$C$4:$M$4))*100,0)) -> 86 | P15: =IF(O15="","",IF(O15>=設定!$D$12,"A",IF(O15>=設定!$E$12,"B","C"))) -> A | Q15: 42 | R15: 29 | S15: 37 | T15: 46 | U15: 46 | V15: 35 | AA15: =IF(COUNT(Q15:Z15)=0,"",SUM(Q15:Z15)) -> 235 | AB15: =IF(OR(AA15="",$AA$4-SUMIF(Q15:Z15,"欠",$Q$4:$Z$4)<=0),"",ROUND(AA15/($AA$4-SUMIF(Q15:Z15,"欠",$Q$4:$Z$4))*100,0)) -> 78 | AC15: =IF(AB15="","",IF(AB15>=設定!$D$12,"A",IF(AB15>=設定!$E$12,"B","C"))) -> B | AD15: =IF(AND(N15="",AA15=""),"",IF(N15="",0,N15)+IF(AA15="",0,AA15)) -> 492 | AE15: =IF(AD15="","",IF($AD$4-SUMIF(C15:M15,"欠",$C$4:$M$4)-SUMIF(Q15:Z15,"欠",$Q$4:$Z$4)<=0,"",ROUND(AD15/($AD$4-SUMIF(C15:M15,"欠",$C$4:$M$4)-SUMIF(Q15:Z15,"欠",$Q$4:$Z$4))*100,0))) -> 82 | AF15: =IF(AE15="","",IF(AE15>=設定!$D$12,"A",IF(AE15>=設定!$E$12,"B","C"))) -> B
A16: 12 | B16: =IF(名簿!B14="","",名簿!B14) -> 佐々木 彩花 | C16: 41 | D16: 48 | E16: 42 | F16: 43 | G16: 44 | H16: 39 | N16: =IF(COUNT(C16:M16)=0,"",SUM(C16:M16)) -> 257 | O16: =IF(OR(N16="",$N$4-SUMIF(C16:M16,"欠",$C$4:$M$4)<=0),"",ROUND(N16/($N$4-SUMIF(C16:M16,"欠",$C$4:$M$4))*100,0)) -> 86 | P16: =IF(O16="","",IF(O16>=設定!$D$12,"A",IF(O16>=設定!$E$12,"B","C"))) -> A | Q16: 30 | R16: 30 | S16: 41 | T16: 36 | U16: 41 | V16: 29 | AA16: =IF(COUNT(Q16:Z16)=0,"",SUM(Q16:Z16)) -> 207 | AB16: =IF(OR(AA16="",$AA$4-SUMIF(Q16:Z16,"欠",$Q$4:$Z$4)<=0),"",ROUND(AA16/($AA$4-SUMIF(Q16:Z16,"欠",$Q$4:$Z$4))*100,0)) -> 69 | AC16: =IF(AB16="","",IF(AB16>=設定!$D$12,"A",IF(AB16>=設定!$E$12,"B","C"))) -> B | AD16: =IF(AND(N16="",AA16=""),"",IF(N16="",0,N16)+IF(AA16="",0,AA16)) -> 464 | AE16: =IF(AD16="","",IF($AD$4-SUMIF(C16:M16,"欠",$C$4:$M$4)-SUMIF(Q16:Z16,"欠",$Q$4:$Z$4)<=0,"",ROUND(AD16/($AD$4-SUMIF(C16:M16,"欠",$C$4:$M$4)-SUMIF(Q16:Z16,"欠",$Q$4:$Z$4))*100,0))) -> 77 | AF16: =IF(AE16="","",IF(AE16>=設定!$D$12,"A",IF(AE16>=設定!$E$12,"B","C"))) -> B
A17: 13 | B17: =IF(名簿!B15="","",名簿!B15) -> 石川 健太 | C17: 34 | D17: 27 | E17: 31 | F17: 32 | G17: 37 | H17: 33 | N17: =IF(COUNT(C17:M17)=0,"",SUM(C17:M17)) -> 194 | O17: =IF(OR(N17="",$N$4-SUMIF(C17:M17,"欠",$C$4:$M$4)<=0),"",ROUND(N17/($N$4-SUMIF(C17:M17,"欠",$C$4:$M$4))*100,0)) -> 65 | P17: =IF(O17="","",IF(O17>=設定!$D$12,"A",IF(O17>=設定!$E$12,"B","C"))) -> B | Q17: 26 | R17: 30 | S17: 26 | T17: 28 | U17: 17 | V17: 28 | AA17: =IF(COUNT(Q17:Z17)=0,"",SUM(Q17:Z17)) -> 155 | AB17: =IF(OR(AA17="",$AA$4-SUMIF(Q17:Z17,"欠",$Q$4:$Z$4)<=0),"",ROUND(AA17/($AA$4-SUMIF(Q17:Z17,"欠",$Q$4:$Z$4))*100,0)) -> 52 | AC17: =IF(AB17="","",IF(AB17>=設定!$D$12,"A",IF(AB17>=設定!$E$12,"B","C"))) -> C | AD17: =IF(AND(N17="",AA17=""),"",IF(N17="",0,N17)+IF(AA17="",0,AA17)) -> 349 | AE17: =IF(AD17="","",IF($AD$4-SUMIF(C17:M17,"欠",$C$4:$M$4)-SUMIF(Q17:Z17,"欠",$Q$4:$Z$4)<=0,"",ROUND(AD17/($AD$4-SUMIF(C17:M17,"欠",$C$4:$M$4)-SUMIF(Q17:Z17,"欠",$Q$4:$Z$4))*100,0))) -> 58 | AF17: =IF(AE17="","",IF(AE17>=設定!$D$12,"A",IF(AE17>=設定!$E$12,"B","C"))) -> B
A18: 14 | B18: =IF(名簿!B16="","",名簿!B16) -> 山崎 陽葵 | C18: 44 | D18: 46 | E18: 49 | F18: 48 | G18: 42 | H18: 43 | N18: =IF(COUNT(C18:M18)=0,"",SUM(C18:M18)) -> 272 | O18: =IF(OR(N18="",$N$4-SUMIF(C18:M18,"欠",$C$4:$M$4)<=0),"",ROUND(N18/($N$4-SUMIF(C18:M18,"欠",$C$4:$M$4))*100,0)) -> 91 | P18: =IF(O18="","",IF(O18>=設定!$D$12,"A",IF(O18>=設定!$E$12,"B","C"))) -> A | Q18: 36 | R18: 42 | S18: 45 | T18: 37 | U18: 41 | V18: 39 | AA18: =IF(COUNT(Q18:Z18)=0,"",SUM(Q18:Z18)) -> 240 | AB18: =IF(OR(AA18="",$AA$4-SUMIF(Q18:Z18,"欠",$Q$4:$Z$4)<=0),"",ROUND(AA18/($AA$4-SUMIF(Q18:Z18,"欠",$Q$4:$Z$4))*100,0)) -> 80 | AC18: =IF(AB18="","",IF(AB18>=設定!$D$12,"A",IF(AB18>=設定!$E$12,"B","C"))) -> B | AD18: =IF(AND(N18="",AA18=""),"",IF(N18="",0,N18)+IF(AA18="",0,AA18)) -> 512 | AE18: =IF(AD18="","",IF($AD$4-SUMIF(C18:M18,"欠",$C$4:$M$4)-SUMIF(Q18:Z18,"欠",$Q$4:$Z$4)<=0,"",ROUND(AD18/($AD$4-SUMIF(C18:M18,"欠",$C$4:$M$4)-SUMIF(Q18:Z18,"欠",$Q$4:$Z$4))*100,0))) -> 85 | AF18: =IF(AE18="","",IF(AE18>=設定!$D$12,"A",IF(AE18>=設定!$E$12,"B","C"))) -> A
A19: 15 | B19: =IF(名簿!B17="","",名簿!B17) -> 加藤 朝陽 | C19: 27 | D19: 28 | E19: 25 | F19: 35 | G19: 23 | H19: 29 | N19: =IF(COUNT(C19:M19)=0,"",SUM(C19:M19)) -> 167 | O19: =IF(OR(N19="",$N$4-SUMIF(C19:M19,"欠",$C$4:$M$4)<=0),"",ROUND(N19/($N$4-SUMIF(C19:M19,"欠",$C$4:$M$4))*100,0)) -> 56 | P19: =IF(O19="","",IF(O19>=設定!$D$12,"A",IF(O19>=設定!$E$12,"B","C"))) -> B | Q19: 18 | R19: 27 | S19: 22 | T19: 22 | U19: 18 | V19: 23 | AA19: =IF(COUNT(Q19:Z19)=0,"",SUM(Q19:Z19)) -> 130 | AB19: =IF(OR(AA19="",$AA$4-SUMIF(Q19:Z19,"欠",$Q$4:$Z$4)<=0),"",ROUND(AA19/($AA$4-SUMIF(Q19:Z19,"欠",$Q$4:$Z$4))*100,0)) -> 43 | AC19: =IF(AB19="","",IF(AB19>=設定!$D$12,"A",IF(AB19>=設定!$E$12,"B","C"))) -> C | AD19: =IF(AND(N19="",AA19=""),"",IF(N19="",0,N19)+IF(AA19="",0,AA19)) -> 297 | AE19: =IF(AD19="","",IF($AD$4-SUMIF(C19:M19,"欠",$C$4:$M$4)-SUMIF(Q19:Z19,"欠",$Q$4:$Z$4)<=0,"",ROUND(AD19/($AD$4-SUMIF(C19:M19,"欠",$C$4:$M$4)-SUMIF(Q19:Z19,"欠",$Q$4:$Z$4))*100,0))) -> 50 | AF19: =IF(AE19="","",IF(AE19>=設定!$D$12,"A",IF(AE19>=設定!$E$12,"B","C"))) -> C
A20: 16 | B20: =IF(名簿!B18="","",名簿!B18) -> 藤田 結愛 | C20: 50 | D20: 49 | E20: 50 | F20: 50 | G20: 50 | H20: 47 | N20: =IF(COUNT(C20:M20)=0,"",SUM(C20:M20)) -> 296 | O20: =IF(OR(N20="",$N$4-SUMIF(C20:M20,"欠",$C$4:$M$4)<=0),"",ROUND(N20/($N$4-SUMIF(C20:M20,"欠",$C$4:$M$4))*100,0)) -> 99 | P20: =IF(O20="","",IF(O20>=設定!$D$12,"A",IF(O20>=設定!$E$12,"B","C"))) -> A | Q20: 50 | R20: 49 | S20: 49 | T20: 44 | U20: 50 | V20: 44 | AA20: =IF(COUNT(Q20:Z20)=0,"",SUM(Q20:Z20)) -> 286 | AB20: =IF(OR(AA20="",$AA$4-SUMIF(Q20:Z20,"欠",$Q$4:$Z$4)<=0),"",ROUND(AA20/($AA$4-SUMIF(Q20:Z20,"欠",$Q$4:$Z$4))*100,0)) -> 95 | AC20: =IF(AB20="","",IF(AB20>=設定!$D$12,"A",IF(AB20>=設定!$E$12,"B","C"))) -> A | AD20: =IF(AND(N20="",AA20=""),"",IF(N20="",0,N20)+IF(AA20="",0,AA20)) -> 582 | AE20: =IF(AD20="","",IF($AD$4-SUMIF(C20:M20,"欠",$C$4:$M$4)-SUMIF(Q20:Z20,"欠",$Q$4:$Z$4)<=0,"",ROUND(AD20/($AD$4-SUMIF(C20:M20,"欠",$C$4:$M$4)-SUMIF(Q20:Z20,"欠",$Q$4:$Z$4))*100,0))) -> 97 | AF20: =IF(AE20="","",IF(AE20>=設定!$D$12,"A",IF(AE20>=設定!$E$12,"B","C"))) -> A
A21: 17 | B21: =IF(名簿!B19="","",名簿!B19) -> 田中 大和 | C21: 40 | D21: 39 | E21: 45 | F21: 45 | G21: 44 | H21: 43 | N21: =IF(COUNT(C21:M21)=0,"",SUM(C21:M21)) -> 256 | O21: =IF(OR(N21="",$N$4-SUMIF(C21:M21,"欠",$C$4:$M$4)<=0),"",ROUND(N21/($N$4-SUMIF(C21:M21,"欠",$C$4:$M$4))*100,0)) -> 85 | P21: =IF(O21="","",IF(O21>=設定!$D$12,"A",IF(O21>=設定!$E$12,"B","C"))) -> A | Q21: 34 | R21: 37 | S21: 35 | T21: 36 | U21: 34 | V21: 35 | AA21: =IF(COUNT(Q21:Z21)=0,"",SUM(Q21:Z21)) -> 211 | AB21: =IF(OR(AA21="",$AA$4-SUMIF(Q21:Z21,"欠",$Q$4:$Z$4)<=0),"",ROUND(AA21/($AA$4-SUMIF(Q21:Z21,"欠",$Q$4:$Z$4))*100,0)) -> 70 | AC21: =IF(AB21="","",IF(AB21>=設定!$D$12,"A",IF(AB21>=設定!$E$12,"B","C"))) -> B | AD21: =IF(AND(N21="",AA21=""),"",IF(N21="",0,N21)+IF(AA21="",0,AA21)) -> 467 | AE21: =IF(AD21="","",IF($AD$4-SUMIF(C21:M21,"欠",$C$4:$M$4)-SUMIF(Q21:Z21,"欠",$Q$4:$Z$4)<=0,"",ROUND(AD21/($AD$4-SUMIF(C21:M21,"欠",$C$4:$M$4)-SUMIF(Q21:Z21,"欠",$Q$4:$Z$4))*100,0))) -> 78 | AF21: =IF(AE21="","",IF(AE21>=設定!$D$12,"A",IF(AE21>=設定!$E$12,"B","C"))) -> B
A22: 18 | B22: =IF(名簿!B20="","",名簿!B20) -> 山口 心春 | C22: 50 | D22: 50 | E22: 50 | F22: 50 | G22: 50 | H22: 50 | N22: =IF(COUNT(C22:M22)=0,"",SUM(C22:M22)) -> 300 | O22: =IF(OR(N22="",$N$4-SUMIF(C22:M22,"欠",$C$4:$M$4)<=0),"",ROUND(N22/($N$4-SUMIF(C22:M22,"欠",$C$4:$M$4))*100,0)) -> 100 | P22: =IF(O22="","",IF(O22>=設定!$D$12,"A",IF(O22>=設定!$E$12,"B","C"))) -> A | Q22: 50 | R22: 50 | S22: 50 | T22: 50 | U22: 50 | V22: 50 | AA22: =IF(COUNT(Q22:Z22)=0,"",SUM(Q22:Z22)) -> 300 | AB22: =IF(OR(AA22="",$AA$4-SUMIF(Q22:Z22,"欠",$Q$4:$Z$4)<=0),"",ROUND(AA22/($AA$4-SUMIF(Q22:Z22,"欠",$Q$4:$Z$4))*100,0)) -> 100 | AC22: =IF(AB22="","",IF(AB22>=設定!$D$12,"A",IF(AB22>=設定!$E$12,"B","C"))) -> A | AD22: =IF(AND(N22="",AA22=""),"",IF(N22="",0,N22)+IF(AA22="",0,AA22)) -> 600 | AE22: =IF(AD22="","",IF($AD$4-SUMIF(C22:M22,"欠",$C$4:$M$4)-SUMIF(Q22:Z22,"欠",$Q$4:$Z$4)<=0,"",ROUND(AD22/($AD$4-SUMIF(C22:M22,"欠",$C$4:$M$4)-SUMIF(Q22:Z22,"欠",$Q$4:$Z$4))*100,0))) -> 100 | AF22: =IF(AE22="","",IF(AE22>=設定!$D$12,"A",IF(AE22>=設定!$E$12,"B","C"))) -> A
A23: 19 | B23: =IF(名簿!B21="","",名簿!B21) -> 山本 朝陽 | C23: 50 | D23: 50 | E23: 50 | F23: 50 | G23: 50 | H23: 46 | N23: =IF(COUNT(C23:M23)=0,"",SUM(C23:M23)) -> 296 | O23: =IF(OR(N23="",$N$4-SUMIF(C23:M23,"欠",$C$4:$M$4)<=0),"",ROUND(N23/($N$4-SUMIF(C23:M23,"欠",$C$4:$M$4))*100,0)) -> 99 | P23: =IF(O23="","",IF(O23>=設定!$D$12,"A",IF(O23>=設定!$E$12,"B","C"))) -> A | Q23: 44 | R23: 42 | S23: 44 | T23: 47 | U23: 43 | V23: 49 | AA23: =IF(COUNT(Q23:Z23)=0,"",SUM(Q23:Z23)) -> 269 | AB23: =IF(OR(AA23="",$AA$4-SUMIF(Q23:Z23,"欠",$Q$4:$Z$4)<=0),"",ROUND(AA23/($AA$4-SUMIF(Q23:Z23,"欠",$Q$4:$Z$4))*100,0)) -> 90 | AC23: =IF(AB23="","",IF(AB23>=設定!$D$12,"A",IF(AB23>=設定!$E$12,"B","C"))) -> A | AD23: =IF(AND(N23="",AA23=""),"",IF(N23="",0,N23)+IF(AA23="",0,AA23)) -> 565 | AE23: =IF(AD23="","",IF($AD$4-SUMIF(C23:M23,"欠",$C$4:$M$4)-SUMIF(Q23:Z23,"欠",$Q$4:$Z$4)<=0,"",ROUND(AD23/($AD$4-SUMIF(C23:M23,"欠",$C$4:$M$4)-SUMIF(Q23:Z23,"欠",$Q$4:$Z$4))*100,0))) -> 94 | AF23: =IF(AE23="","",IF(AE23>=設定!$D$12,"A",IF(AE23>=設定!$E$12,"B","C"))) -> A
A24: 20 | B24: =IF(名簿!B22="","",名簿!B22) -> 前田 彩花 | C24: 35 | D24: 38 | E24: 36 | F24: 30 | G24: 37 | H24: 27 | N24: =IF(COUNT(C24:M24)=0,"",SUM(C24:M24)) -> 203 | O24: =IF(OR(N24="",$N$4-SUMIF(C24:M24,"欠",$C$4:$M$4)<=0),"",ROUND(N24/($N$4-SUMIF(C24:M24,"欠",$C$4:$M$4))*100,0)) -> 68 | P24: =IF(O24="","",IF(O24>=設定!$D$12,"A",IF(O24>=設定!$E$12,"B","C"))) -> B | Q24: 32 | R24: 32 | S24: 25 | T24: 29 | U24: 32 | V24: 34 | AA24: =IF(COUNT(Q24:Z24)=0,"",SUM(Q24:Z24)) -> 184 | AB24: =IF(OR(AA24="",$AA$4-SUMIF(Q24:Z24,"欠",$Q$4:$Z$4)<=0),"",ROUND(AA24/($AA$4-SUMIF(Q24:Z24,"欠",$Q$4:$Z$4))*100,0)) -> 61 | AC24: =IF(AB24="","",IF(AB24>=設定!$D$12,"A",IF(AB24>=設定!$E$12,"B","C"))) -> B | AD24: =IF(AND(N24="",AA24=""),"",IF(N24="",0,N24)+IF(AA24="",0,AA24)) -> 387 | AE24: =IF(AD24="","",IF($AD$4-SUMIF(C24:M24,"欠",$C$4:$M$4)-SUMIF(Q24:Z24,"欠",$Q$4:$Z$4)<=0,"",ROUND(AD24/($AD$4-SUMIF(C24:M24,"欠",$C$4:$M$4)-SUMIF(Q24:Z24,"欠",$Q$4:$Z$4))*100,0))) -> 65 | AF24: =IF(AE24="","",IF(AE24>=設定!$D$12,"A",IF(AE24>=設定!$E$12,"B","C"))) -> B
... A34: 30 | B34: =IF(名簿!B32="","",名簿!B32) -> 伊藤 咲良 | C34: 48 | D34: 45 | E34: 50 | F34: 47 | G34: 50 | H34: 50 | N34: =IF(COUNT(C34:M34)=0,"",SUM(C34:M34)) -> 290 | O34: =IF(OR(N34="",$N$4-SUMIF(C34:M34,"欠",$C$4:$M$4)<=0),"",ROUND(N34/($N$4-SUMIF(C34:M34,"欠",$C$4:$M$4))*100,0)) -> 97 | P34: =IF(O34="","",IF(O34>=設定!$D$12,"A",IF(O34>=設定!$E$12,"B","C"))) -> A | Q34: 43 | R34: 36 | S34: 43 | T34: 39 | U34: 46 | V34: 48 | AA34: =IF(COUNT(Q34:Z34)=0,"",SUM(Q34:Z34)) -> 255 | AB34: =IF(OR(AA34="",$AA$4-SUMIF(Q34:Z34,"欠",$Q$4:$Z$4)<=0),"",ROUND(AA34/($AA$4-SUMIF(Q34:Z34,"欠",$Q$4:$Z$4))*100,0)) -> 85 | AC34: =IF(AB34="","",IF(AB34>=設定!$D$12,"A",IF(AB34>=設定!$E$12,"B","C"))) -> A | AD34: =IF(AND(N34="",AA34=""),"",IF(N34="",0,N34)+IF(AA34="",0,AA34)) -> 545 | AE34: =IF(AD34="","",IF($AD$4-SUMIF(C34:M34,"欠",$C$4:$M$4)-SUMIF(Q34:Z34,"欠",$Q$4:$Z$4)<=0,"",ROUND(AD34/($AD$4-SUMIF(C34:M34,"欠",$C$4:$M$4)-SUMIF(Q34:Z34,"欠",$Q$4:$Z$4))*100,0))) -> 91 | AF34: =IF(AE34="","",IF(AE34>=設定!$D$12,"A",IF(AE34>=設定!$E$12,"B","C"))) -> A
A35: 31 | B35: =IF(名簿!B33="","",名簿!B33) -> 佐藤 海斗 | C35: 41 | D35: 40 | E35: 40 | F35: 42 | G35: 43 | H35: 欠 | N35: =IF(COUNT(C35:M35)=0,"",SUM(C35:M35)) -> 206 | O35: =IF(OR(N35="",$N$4-SUMIF(C35:M35,"欠",$C$4:$M$4)<=0),"",ROUND(N35/($N$4-SUMIF(C35:M35,"欠",$C$4:$M$4))*100,0)) -> 82 | P35: =IF(O35="","",IF(O35>=設定!$D$12,"A",IF(O35>=設定!$E$12,"B","C"))) -> B | Q35: 39 | R35: 33 | S35: 37 | T35: 41 | U35: 38 | V35: 欠 | AA35: =IF(COUNT(Q35:Z35)=0,"",SUM(Q35:Z35)) -> 188 | AB35: =IF(OR(AA35="",$AA$4-SUMIF(Q35:Z35,"欠",$Q$4:$Z$4)<=0),"",ROUND(AA35/($AA$4-SUMIF(Q35:Z35,"欠",$Q$4:$Z$4))*100,0)) -> 75 | AC35: =IF(AB35="","",IF(AB35>=設定!$D$12,"A",IF(AB35>=設定!$E$12,"B","C"))) -> B | AD35: =IF(AND(N35="",AA35=""),"",IF(N35="",0,N35)+IF(AA35="",0,AA35)) -> 394 | AE35: =IF(AD35="","",IF($AD$4-SUMIF(C35:M35,"欠",$C$4:$M$4)-SUMIF(Q35:Z35,"欠",$Q$4:$Z$4)<=0,"",ROUND(AD35/($AD$4-SUMIF(C35:M35,"欠",$C$4:$M$4)-SUMIF(Q35:Z35,"欠",$Q$4:$Z$4))*100,0))) -> 79 | AF35: =IF(AE35="","",IF(AE35>=設定!$D$12,"A",IF(AE35>=設定!$E$12,"B","C"))) -> B
A36: 32 | B36: =IF(名簿!B34="","",名簿!B34) -> 高橋 結愛 | C36: 48 | D36: 47 | E36: 50 | F36: 49 | G36: 49 | H36: 46 | N36: =IF(COUNT(C36:M36)=0,"",SUM(C36:M36)) -> 289 | O36: =IF(OR(N36="",$N$4-SUMIF(C36:M36,"欠",$C$4:$M$4)<=0),"",ROUND(N36/($N$4-SUMIF(C36:M36,"欠",$C$4:$M$4))*100,0)) -> 96 | P36: =IF(O36="","",IF(O36>=設定!$D$12,"A",IF(O36>=設定!$E$12,"B","C"))) -> A | Q36: 47 | R36: 46 | S36: 43 | T36: 43 | U36: 41 | V36: 47 | AA36: =IF(COUNT(Q36:Z36)=0,"",SUM(Q36:Z36)) -> 267 | AB36: =IF(OR(AA36="",$AA$4-SUMIF(Q36:Z36,"欠",$Q$4:$Z$4)<=0),"",ROUND(AA36/($AA$4-SUMIF(Q36:Z36,"欠",$Q$4:$Z$4))*100,0)) -> 89 | AC36: =IF(AB36="","",IF(AB36>=設定!$D$12,"A",IF(AB36>=設定!$E$12,"B","C"))) -> A | AD36: =IF(AND(N36="",AA36=""),"",IF(N36="",0,N36)+IF(AA36="",0,AA36)) -> 556 | AE36: =IF(AD36="","",IF($AD$4-SUMIF(C36:M36,"欠",$C$4:$M$4)-SUMIF(Q36:Z36,"欠",$Q$4:$Z$4)<=0,"",ROUND(AD36/($AD$4-SUMIF(C36:M36,"欠",$C$4:$M$4)-SUMIF(Q36:Z36,"欠",$Q$4:$Z$4))*100,0))) -> 93 | AF36: =IF(AE36="","",IF(AE36>=設定!$D$12,"A",IF(AE36>=設定!$E$12,"B","C"))) -> A
A37: 33 | B37: =IF(名簿!B35="","",名簿!B35) -> 木村 陽太 | C37: 44 | D37: 40 | E37: 40 | F37: 36 | G37: 41 | H37: 43 | N37: =IF(COUNT(C37:M37)=0,"",SUM(C37:M37)) -> 244 | O37: =IF(OR(N37="",$N$4-SUMIF(C37:M37,"欠",$C$4:$M$4)<=0),"",ROUND(N37/($N$4-SUMIF(C37:M37,"欠",$C$4:$M$4))*100,0)) -> 81 | P37: =IF(O37="","",IF(O37>=設定!$D$12,"A",IF(O37>=設定!$E$12,"B","C"))) -> B | Q37: 34 | R37: 40 | S37: 42 | T37: 35 | U37: 42 | V37: 33 | AA37: =IF(COUNT(Q37:Z37)=0,"",SUM(Q37:Z37)) -> 226 | AB37: =IF(OR(AA37="",$AA$4-SUMIF(Q37:Z37,"欠",$Q$4:$Z$4)<=0),"",ROUND(AA37/($AA$4-SUMIF(Q37:Z37,"欠",$Q$4:$Z$4))*100,0)) -> 75 | AC37: =IF(AB37="","",IF(AB37>=設定!$D$12,"A",IF(AB37>=設定!$E$12,"B","C"))) -> B | AD37: =IF(AND(N37="",AA37=""),"",IF(N37="",0,N37)+IF(AA37="",0,AA37)) -> 470 | AE37: =IF(AD37="","",IF($AD$4-SUMIF(C37:M37,"欠",$C$4:$M$4)-SUMIF(Q37:Z37,"欠",$Q$4:$Z$4)<=0,"",ROUND(AD37/($AD$4-SUMIF(C37:M37,"欠",$C$4:$M$4)-SUMIF(Q37:Z37,"欠",$Q$4:$Z$4))*100,0))) -> 78 | AF37: =IF(AE37="","",IF(AE37>=設定!$D$12,"A",IF(AE37>=設定!$E$12,"B","C"))) -> B
A38: 34 | B38: =IF(名簿!B36="","",名簿!B36) -> 長谷川 さくら | C38: 37 | D38: 43 | E38: 33 | F38: 31 | G38: 42 | H38: 29 | N38: =IF(COUNT(C38:M38)=0,"",SUM(C38:M38)) -> 215 | O38: =IF(OR(N38="",$N$4-SUMIF(C38:M38,"欠",$C$4:$M$4)<=0),"",ROUND(N38/($N$4-SUMIF(C38:M38,"欠",$C$4:$M$4))*100,0)) -> 72 | P38: =IF(O38="","",IF(O38>=設定!$D$12,"A",IF(O38>=設定!$E$12,"B","C"))) -> B | Q38: 24 | R38: 32 | S38: 32 | T38: 39 | U38: 29 | V38: 28 | AA38: =IF(COUNT(Q38:Z38)=0,"",SUM(Q38:Z38)) -> 184 | AB38: =IF(OR(AA38="",$AA$4-SUMIF(Q38:Z38,"欠",$Q$4:$Z$4)<=0),"",ROUND(AA38/($AA$4-SUMIF(Q38:Z38,"欠",$Q$4:$Z$4))*100,0)) -> 61 | AC38: =IF(AB38="","",IF(AB38>=設定!$D$12,"A",IF(AB38>=設定!$E$12,"B","C"))) -> B | AD38: =IF(AND(N38="",AA38=""),"",IF(N38="",0,N38)+IF(AA38="",0,AA38)) -> 399 | AE38: =IF(AD38="","",IF($AD$4-SUMIF(C38:M38,"欠",$C$4:$M$4)-SUMIF(Q38:Z38,"欠",$Q$4:$Z$4)<=0,"",ROUND(AD38/($AD$4-SUMIF(C38:M38,"欠",$C$4:$M$4)-SUMIF(Q38:Z38,"欠",$Q$4:$Z$4))*100,0))) -> 67 | AF38: =IF(AE38="","",IF(AE38>=設定!$D$12,"A",IF(AE38>=設定!$E$12,"B","C"))) -> B
A39: 35 | B39: =IF(名簿!B37="","",名簿!B37) -> 渡辺 健太 | C39: 42 | D39: 45 | E39: 45 | F39: 47 | G39: 48 | H39: 47 | N39: =IF(COUNT(C39:M39)=0,"",SUM(C39:M39)) -> 274 | O39: =IF(OR(N39="",$N$4-SUMIF(C39:M39,"欠",$C$4:$M$4)<=0),"",ROUND(N39/($N$4-SUMIF(C39:M39,"欠",$C$4:$M$4))*100,0)) -> 91 | P39: =IF(O39="","",IF(O39>=設定!$D$12,"A",IF(O39>=設定!$E$12,"B","C"))) -> A | Q39: 41 | R39: 42 | S39: 44 | T39: 36 | U39: 32 | V39: 43 | AA39: =IF(COUNT(Q39:Z39)=0,"",SUM(Q39:Z39)) -> 238 | AB39: =IF(OR(AA39="",$AA$4-SUMIF(Q39:Z39,"欠",$Q$4:$Z$4)<=0),"",ROUND(AA39/($AA$4-SUMIF(Q39:Z39,"欠",$Q$4:$Z$4))*100,0)) -> 79 | AC39: =IF(AB39="","",IF(AB39>=設定!$D$12,"A",IF(AB39>=設定!$E$12,"B","C"))) -> B | AD39: =IF(AND(N39="",AA39=""),"",IF(N39="",0,N39)+IF(AA39="",0,AA39)) -> 512 | AE39: =IF(AD39="","",IF($AD$4-SUMIF(C39:M39,"欠",$C$4:$M$4)-SUMIF(Q39:Z39,"欠",$Q$4:$Z$4)<=0,"",ROUND(AD39/($AD$4-SUMIF(C39:M39,"欠",$C$4:$M$4)-SUMIF(Q39:Z39,"欠",$Q$4:$Z$4))*100,0))) -> 85 | AF39: =IF(AE39="","",IF(AE39>=設定!$D$12,"A",IF(AE39>=設定!$E$12,"B","C"))) -> A
B40: 平 均 | C40: =IF(COUNT(C5:C39)=0,"",ROUND(AVERAGE(C5:C39),1)) -> 42.2 | D40: =IF(COUNT(D5:D39)=0,"",ROUND(AVERAGE(D5:D39),1)) -> 42.5 | E40: =IF(COUNT(E5:E39)=0,"",ROUND(AVERAGE(E5:E39),1)) -> 42.1 | F40: =IF(COUNT(F5:F39)=0,"",ROUND(AVERAGE(F5:F39),1)) -> 41.7 | G40: =IF(COUNT(G5:G39)=0,"",ROUND(AVERAGE(G5:G39),1)) -> 41.7 | H40: =IF(COUNT(H5:H39)=0,"",ROUND(AVERAGE(H5:H39),1)) -> 41.2 | I40: =IF(COUNT(I5:I39)=0,"",ROUND(AVERAGE(I5:I39),1)) | J40: =IF(COUNT(J5:J39)=0,"",ROUND(AVERAGE(J5:J39),1)) | ... O40: =IF(COUNT(O5:O39)=0,"",ROUND(AVERAGE(O5:O39),1)) -> 83.9 | Q40: =IF(COUNT(Q5:Q39)=0,"",ROUND(AVERAGE(Q5:Q39),1)) -> 37.2 | R40: =IF(COUNT(R5:R39)=0,"",ROUND(AVERAGE(R5:R39),1)) -> 37.3 | S40: =IF(COUNT(S5:S39)=0,"",ROUND(AVERAGE(S5:S39),1)) -> 37.4 | T40: =IF(COUNT(T5:T39)=0,"",ROUND(AVERAGE(T5:T39),1)) -> 37.4 | U40: =IF(COUNT(U5:U39)=0,"",ROUND(AVERAGE(U5:U39),1)) -> 38 | V40: =IF(COUNT(V5:V39)=0,"",ROUND(AVERAGE(V5:V39),1)) -> 37.7 | W40: =IF(COUNT(W5:W39)=0,"",ROUND(AVERAGE(W5:W39),1)) | X40: =IF(COUNT(X5:X39)=0,"",ROUND(AVERAGE(X5:X39),1)) | ... AB40: =IF(COUNT(AB5:AB39)=0,"",ROUND(AVERAGE(AB5:AB39),1)) -> 74.9 | AD40: =IF(COUNT(AD5:AD39)=0,"",ROUND(AVERAGE(AD5:AD39),1)) -> 471.9 | AE40: =IF(COUNT(AE5:AE39)=0,"",ROUND(AVERAGE(AE5:AE39),1)) -> 79.5
B41: Ａの人数 | P41: =COUNTIF(P5:P39,"A") -> 19 | AC41: =COUNTIF(AC5:AC39,"A") -> 10 | AF41: =COUNTIF(AF5:AF39,"A") -> 14
B42: Ｂの人数 | P42: =COUNTIF(P5:P39,"B") -> 16 | AC42: =COUNTIF(AC5:AC39,"B") -> 22 | AF42: =COUNTIF(AF5:AF39,"B") -> 20
B43: Ｃの人数 | P43: =COUNTIF(P5:P39,"C") -> 0 | AC43: =COUNTIF(AC5:AC39,"C") -> 3 | AF43: =COUNTIF(AF5:AF39,"C") -> 1

Sheet 社会（前期）
A1: 観点別得点集計表（社会・前期）
A2: 観 点 | C2: 知識・技能 | Q2: 思考・判断・表現 | AD2: 合 計
A3: 単元名 | C3: わたしたちの生活と政治 | D3: 縄文のむらから古墳のくにへ | E3: 天皇中心の国づくり | F3: 貴族のくらし | G3: 武士の世の中へ | H3: 今に伝わる室町文化 | N3: 観点合計 | O3: 観点到達率 | P3: 観点別学習状況評価 | Q3: わたしたちの生活と政治 | R3: 縄文のむらから古墳のくにへ | S3: 天皇中心の国づくり | T3: 貴族のくらし | U3: 武士の世の中へ | V3: 今に伝わる室町文化 | AA3: 観点合計 | AB3: 観点到達率 | AC3: 観点別学習状況評価 | AD3: 総得点 | AE3: 総得点到達率 | AF3: 総得点学習状況評価
A4: 番 | B4: 名前/配点 | C4: 50 | D4: 50 | E4: 50 | F4: 50 | G4: 50 | H4: 50 | N4: =SUM(C4:M4) -> 300 | Q4: 50 | R4: 50 | S4: 50 | T4: 50 | U4: 50 | V4: 50 | AA4: =SUM(Q4:Z4) -> 300 | AD4: =N4+AA4 -> 600
A5: 1 | B5: =IF(名簿!B3="","",名簿!B3) -> 石井 湊 | C5: 47 | D5: 43 | E5: 48 | F5: 50 | G5: 47 | H5: 50 | N5: =IF(COUNT(C5:M5)=0,"",SUM(C5:M5)) -> 285 | O5: =IF(OR(N5="",$N$4-SUMIF(C5:M5,"欠",$C$4:$M$4)<=0),"",ROUND(N5/($N$4-SUMIF(C5:M5,"欠",$C$4:$M$4))*100,0)) -> 95 | P5: =IF(O5="","",IF(O5>=設定!$D$13,"A",IF(O5>=設定!$E$13,"B","C"))) -> A | Q5: 49 | R5: 48 | S5: 46 | T5: 48 | U5: 47 | V5: 48 | AA5: =IF(COUNT(Q5:Z5)=0,"",SUM(Q5:Z5)) -> 286 | AB5: =IF(OR(AA5="",$AA$4-SUMIF(Q5:Z5,"欠",$Q$4:$Z$4)<=0),"",ROUND(AA5/($AA$4-SUMIF(Q5:Z5,"欠",$Q$4:$Z$4))*100,0)) -> 95 | AC5: =IF(AB5="","",IF(AB5>=設定!$D$13,"A",IF(AB5>=設定!$E$13,"B","C"))) -> A | AD5: =IF(AND(N5="",AA5=""),"",IF(N5="",0,N5)+IF(AA5="",0,AA5)) -> 571 | AE5: =IF(AD5="","",IF($AD$4-SUMIF(C5:M5,"欠",$C$4:$M$4)-SUMIF(Q5:Z5,"欠",$Q$4:$Z$4)<=0,"",ROUND(AD5/($AD$4-SUMIF(C5:M5,"欠",$C$4:$M$4)-SUMIF(Q5:Z5,"欠",$Q$4:$Z$4))*100,0))) -> 95 | AF5: =IF(AE5="","",IF(AE5>=設定!$D$13,"A",IF(AE5>=設定!$E$13,"B","C"))) -> A
A6: 2 | B6: =IF(名簿!B4="","",名簿!B4) -> 池田 さくら | C6: 44 | D6: 47 | E6: 38 | F6: 41 | G6: 38 | H6: 39 | N6: =IF(COUNT(C6:M6)=0,"",SUM(C6:M6)) -> 247 | O6: =IF(OR(N6="",$N$4-SUMIF(C6:M6,"欠",$C$4:$M$4)<=0),"",ROUND(N6/($N$4-SUMIF(C6:M6,"欠",$C$4:$M$4))*100,0)) -> 82 | P6: =IF(O6="","",IF(O6>=設定!$D$13,"A",IF(O6>=設定!$E$13,"B","C"))) -> B | Q6: 37 | R6: 37 | S6: 36 | T6: 37 | U6: 35 | V6: 40 | AA6: =IF(COUNT(Q6:Z6)=0,"",SUM(Q6:Z6)) -> 222 | AB6: =IF(OR(AA6="",$AA$4-SUMIF(Q6:Z6,"欠",$Q$4:$Z$4)<=0),"",ROUND(AA6/($AA$4-SUMIF(Q6:Z6,"欠",$Q$4:$Z$4))*100,0)) -> 74 | AC6: =IF(AB6="","",IF(AB6>=設定!$D$13,"A",IF(AB6>=設定!$E$13,"B","C"))) -> B | AD6: =IF(AND(N6="",AA6=""),"",IF(N6="",0,N6)+IF(AA6="",0,AA6)) -> 469 | AE6: =IF(AD6="","",IF($AD$4-SUMIF(C6:M6,"欠",$C$4:$M$4)-SUMIF(Q6:Z6,"欠",$Q$4:$Z$4)<=0,"",ROUND(AD6/($AD$4-SUMIF(C6:M6,"欠",$C$4:$M$4)-SUMIF(Q6:Z6,"欠",$Q$4:$Z$4))*100,0))) -> 78 | AF6: =IF(AE6="","",IF(AE6>=設定!$D$13,"A",IF(AE6>=設定!$E$13,"B","C"))) -> B
A7: 3 | B7: =IF(名簿!B5="","",名簿!B5) -> 林 陽翔 | C7: 45 | D7: 48 | E7: 50 | F7: 49 | G7: 43 | H7: 50 | N7: =IF(COUNT(C7:M7)=0,"",SUM(C7:M7)) -> 285 | O7: =IF(OR(N7="",$N$4-SUMIF(C7:M7,"欠",$C$4:$M$4)<=0),"",ROUND(N7/($N$4-SUMIF(C7:M7,"欠",$C$4:$M$4))*100,0)) -> 95 | P7: =IF(O7="","",IF(O7>=設定!$D$13,"A",IF(O7>=設定!$E$13,"B","C"))) -> A | Q7: 45 | R7: 38 | S7: 46 | T7: 44 | U7: 41 | V7: 43 | AA7: =IF(COUNT(Q7:Z7)=0,"",SUM(Q7:Z7)) -> 257 | AB7: =IF(OR(AA7="",$AA$4-SUMIF(Q7:Z7,"欠",$Q$4:$Z$4)<=0),"",ROUND(AA7/($AA$4-SUMIF(Q7:Z7,"欠",$Q$4:$Z$4))*100,0)) -> 86 | AC7: =IF(AB7="","",IF(AB7>=設定!$D$13,"A",IF(AB7>=設定!$E$13,"B","C"))) -> B | AD7: =IF(AND(N7="",AA7=""),"",IF(N7="",0,N7)+IF(AA7="",0,AA7)) -> 542 | AE7: =IF(AD7="","",IF($AD$4-SUMIF(C7:M7,"欠",$C$4:$M$4)-SUMIF(Q7:Z7,"欠",$Q$4:$Z$4)<=0,"",ROUND(AD7/($AD$4-SUMIF(C7:M7,"欠",$C$4:$M$4)-SUMIF(Q7:Z7,"欠",$Q$4:$Z$4))*100,0))) -> 90 | AF7: =IF(AE7="","",IF(AE7>=設定!$D$13,"A",IF(AE7>=設定!$E$13,"B","C"))) -> A
A8: 4 | B8: =IF(名簿!B6="","",名簿!B6) -> 村上 凛 | C8: 43 | D8: 36 | E8: 40 | F8: 50 | G8: 42 | H8: 41 | N8: =IF(COUNT(C8:M8)=0,"",SUM(C8:M8)) -> 252 | O8: =IF(OR(N8="",$N$4-SUMIF(C8:M8,"欠",$C$4:$M$4)<=0),"",ROUND(N8/($N$4-SUMIF(C8:M8,"欠",$C$4:$M$4))*100,0)) -> 84 | P8: =IF(O8="","",IF(O8>=設定!$D$13,"A",IF(O8>=設定!$E$13,"B","C"))) -> B | Q8: 34 | R8: 40 | S8: 32 | T8: 34 | U8: 41 | V8: 43 | AA8: =IF(COUNT(Q8:Z8)=0,"",SUM(Q8:Z8)) -> 224 | AB8: =IF(OR(AA8="",$AA$4-SUMIF(Q8:Z8,"欠",$Q$4:$Z$4)<=0),"",ROUND(AA8/($AA$4-SUMIF(Q8:Z8,"欠",$Q$4:$Z$4))*100,0)) -> 75 | AC8: =IF(AB8="","",IF(AB8>=設定!$D$13,"A",IF(AB8>=設定!$E$13,"B","C"))) -> B | AD8: =IF(AND(N8="",AA8=""),"",IF(N8="",0,N8)+IF(AA8="",0,AA8)) -> 476 | AE8: =IF(AD8="","",IF($AD$4-SUMIF(C8:M8,"欠",$C$4:$M$4)-SUMIF(Q8:Z8,"欠",$Q$4:$Z$4)<=0,"",ROUND(AD8/($AD$4-SUMIF(C8:M8,"欠",$C$4:$M$4)-SUMIF(Q8:Z8,"欠",$Q$4:$Z$4))*100,0))) -> 79 | AF8: =IF(AE8="","",IF(AE8>=設定!$D$13,"A",IF(AE8>=設定!$E$13,"B","C"))) -> B
A9: 5 | B9: =IF(名簿!B7="","",名簿!B7) -> 中村 蓮 | C9: 47 | D9: 49 | E9: 46 | F9: 42 | G9: 50 | H9: 50 | N9: =IF(COUNT(C9:M9)=0,"",SUM(C9:M9)) -> 284 | O9: =IF(OR(N9="",$N$4-SUMIF(C9:M9,"欠",$C$4:$M$4)<=0),"",ROUND(N9/($N$4-SUMIF(C9:M9,"欠",$C$4:$M$4))*100,0)) -> 95 | P9: =IF(O9="","",IF(O9>=設定!$D$13,"A",IF(O9>=設定!$E$13,"B","C"))) -> A | Q9: 38 | R9: 48 | S9: 45 | T9: 39 | U9: 46 | V9: 44 | AA9: =IF(COUNT(Q9:Z9)=0,"",SUM(Q9:Z9)) -> 260 | AB9: =IF(OR(AA9="",$AA$4-SUMIF(Q9:Z9,"欠",$Q$4:$Z$4)<=0),"",ROUND(AA9/($AA$4-SUMIF(Q9:Z9,"欠",$Q$4:$Z$4))*100,0)) -> 87 | AC9: =IF(AB9="","",IF(AB9>=設定!$D$13,"A",IF(AB9>=設定!$E$13,"B","C"))) -> B | AD9: =IF(AND(N9="",AA9=""),"",IF(N9="",0,N9)+IF(AA9="",0,AA9)) -> 544 | AE9: =IF(AD9="","",IF($AD$4-SUMIF(C9:M9,"欠",$C$4:$M$4)-SUMIF(Q9:Z9,"欠",$Q$4:$Z$4)<=0,"",ROUND(AD9/($AD$4-SUMIF(C9:M9,"欠",$C$4:$M$4)-SUMIF(Q9:Z9,"欠",$Q$4:$Z$4))*100,0))) -> 91 | AF9: =IF(AE9="","",IF(AE9>=設定!$D$13,"A",IF(AE9>=設定!$E$13,"B","C"))) -> A
A10: 6 | B10: =IF(名簿!B8="","",名簿!B8) -> 小川 彩花 | C10: 36 | D10: 36 | E10: 28 | F10: 30 | G10: 43 | H10: 36 | N10: =IF(COUNT(C10:M10)=0,"",SUM(C10:M10)) -> 209 | O10: =IF(OR(N10="",$N$4-SUMIF(C10:M10,"欠",$C$4:$M$4)<=0),"",ROUND(N10/($N$4-SUMIF(C10:M10,"欠",$C$4:$M$4))*100,0)) -> 70 | P10: =IF(O10="","",IF(O10>=設定!$D$13,"A",IF(O10>=設定!$E$13,"B","C"))) -> B | Q10: 31 | R10: 31 | S10: 42 | T10: 31 | U10: 38 | V10: 25 | AA10: =IF(COUNT(Q10:Z10)=0,"",SUM(Q10:Z10)) -> 198 | AB10: =IF(OR(AA10="",$AA$4-SUMIF(Q10:Z10,"欠",$Q$4:$Z$4)<=0),"",ROUND(AA10/($AA$4-SUMIF(Q10:Z10,"欠",$Q$4:$Z$4))*100,0)) -> 66 | AC10: =IF(AB10="","",IF(AB10>=設定!$D$13,"A",IF(AB10>=設定!$E$13,"B","C"))) -> B | AD10: =IF(AND(N10="",AA10=""),"",IF(N10="",0,N10)+IF(AA10="",0,AA10)) -> 407 | AE10: =IF(AD10="","",IF($AD$4-SUMIF(C10:M10,"欠",$C$4:$M$4)-SUMIF(Q10:Z10,"欠",$Q$4:$Z$4)<=0,"",ROUND(AD10/($AD$4-SUMIF(C10:M10,"欠",$C$4:$M$4)-SUMIF(Q10:Z10,"欠",$Q$4:$Z$4))*100,0))) -> 68 | AF10: =IF(AE10="","",IF(AE10>=設定!$D$13,"A",IF(AE10>=設定!$E$13,"B","C"))) -> B
