Workbook

Sheet データ入力
A1: 組み方 | C1: 男女別 | F1: 先に走る | G1: 女子 | J1: 始めのコース | K1: 2 | N1: =IF(計算用!$U$21>0,"※名前はあるのに、性別かタイムが入っていない人が"&計算用!$U$21&"人います（組に入りません）","")
A2: 名簿から名前・性別（1=男子 2=女子）・タイム（秒）を貼り付けてください。クラス名（3行目）は書きかえられます。男女混合（2年生）のときは性別は空欄でかまいません。
A3: No. | B3: 松組 | F3: 竹組 | J3: 梅組 | N3: 月組
B4: 名前 | C4: 性別 | D4: タイム | F4: 名前 | G4: 性別 | H4: タイム | J4: 名前 | K4: 性別 | L4: タイム | N4: 名前 | O4: 性別 | P4: タイム
A5: 1
A6: 2
A7: 3
A8: 4
A9: 5
A10: 6
A11: 7
A12: 8
A13: 9
A14: 10
A15: 11
A16: 12
... A41: 37

Sheet 組分け
A1: 組分け（自動） | E1: 各クラスのタイム順位が同じ子どうしで1レースにします。直すときは「手直し」シートで。
A2: =IF(計算用!$U$2,"男女混合","男子") | K2: =IF(計算用!$U$2,"（使いません）","女子")
A3: 順位 | B3: =データ入力!$B$3 | D3: =データ入力!$F$3 | F3: =データ入力!$J$3 | H3: =データ入力!$N$3 | K3: 順位 | L3: =データ入力!$B$3 | N3: =データ入力!$F$3 | P3: =データ入力!$J$3 | R3: =データ入力!$N$3
B4: 名前 | C4: タイム | D4: 名前 | E4: タイム | F4: 名前 | G4: タイム | H4: 名前 | I4: タイム | L4: 名前 | M4: タイム | N4: 名前 | O4: タイム | P4: 名前 | Q4: タイム | R4: 名前 | S4: タイム
A5: =IF(1<=計算用!$U$9,1,"") | B5: =IF($A5="","",IFERROR(INDEX(計算用!$D$2:$D$149,MATCH(計算用!$U$3&1&"-"&$A5,計算用!$K$2:$K$149,0)),"")) | C5: =IF($A5="","",IFERROR(INDEX(計算用!$G$2:$G$149,MATCH(計算用!$U$3&1&"-"&$A5,計算用!$K$2:$K$149,0)),"")) | D5: =IF($A5="","",IFERROR(INDEX(計算用!$D$2:$D$149,MATCH(計算用!$U$3&2&"-"&$A5,計算用!$K$2:$K$149,0)),"")) | E5: =IF($A5="","",IFERROR(INDEX(計算用!$G$2:$G$149,MATCH(計算用!$U$3&2&"-"&$A5,計算用!$K$2:$K$149,0)),"")) | F5: =IF($A5="","",IFERROR(INDEX(計算用!$D$2:$D$149,MATCH(計算用!$U$3&3&"-"&$A5,計算用!$K$2:$K$149,0)),"")) | G5: =IF($A5="","",IFERROR(INDEX(計算用!$G$2:$G$149,MATCH(計算用!$U$3&3&"-"&$A5,計算用!$K$2:$K$149,0)),"")) | H5: =IF($A5="","",IFERROR(INDEX(計算用!$D$2:$D$149,MATCH(計算用!$U$3&4&"-"&$A5,計算用!$K$2:$K$149,0)),"")) | I5: =IF($A5="","",IFERROR(INDEX(計算用!$G$2:$G$149,MATCH(計算用!$U$3&4&"-"&$A5,計算用!$K$2:$K$149,0)),"")) | K5: =IF(1<=計算用!$U$10,1,"") | L5: =IF($K5="","",IFERROR(INDEX(計算用!$D$2:$D$149,MATCH("女"&1&"-"&$K5,計算用!$K$2:$K$149,0)),"")) | M5: =IF($K5="","",IFERROR(INDEX(計算用!$G$2:$G$149,MATCH("女"&1&"-"&$K5,計算用!$K$2:$K$149,0)),"")) | N5: =IF($K5="","",IFERROR(INDEX(計算用!$D$2:$D$149,MATCH("女"&2&"-"&$K5,計算用!$K$2:$K$149,0)),"")) | O5: =IF($K5="","",IFERROR(INDEX(計算用!$G$2:$G$149,MATCH("女"&2&"-"&$K5,計算用!$K$2:$K$149,0)),"")) | P5: =IF($K5="","",IFERROR(INDEX(計算用!$D$2:$D$149,MATCH("女"&3&"-"&$K5,計算用!$K$2:$K$149,0)),"")) | Q5: =IF($K5="","",IFERROR(INDEX(計算用!$G$2:$G$149,MATCH("女"&3&"-"&$K5,計算用!$K$2:$K$149,0)),"")) | R5: =IF($K5="","",IFERROR(INDEX(計算用!$D$2:$D$149,MATCH("女"&4&"-"&$K5,計算用!$K$2:$K$149,0)),"")) | S5: =IF($K5="","",IFERROR(INDEX(計算用!$G$2:$G$149,MATCH("女"&4&"-"&$K5,計算用!$K$2:$K$149,0)),""))
A6: =IF(2<=計算用!$U$9,2,"") | B6: =IF($A6="","",IFERROR(INDEX(計算用!$D$2:$D$149,MATCH(計算用!$U$3&1&"-"&$A6,計算用!$K$2:$K$149,0)),"")) | C6: =IF($A6="","",IFERROR(INDEX(計算用!$G$2:$G$149,MATCH(計算用!$U$3&1&"-"&$A6,計算用!$K$2:$K$149,0)),"")) | D6: =IF($A6="","",IFERROR(INDEX(計算用!$D$2:$D$149,MATCH(計算用!$U$3&2&"-"&$A6,計算用!$K$2:$K$149,0)),"")) | E6: =IF($A6="","",IFERROR(INDEX(計算用!$G$2:$G$149,MATCH(計算用!$U$3&2&"-"&$A6,計算用!$K$2:$K$149,0)),"")) | F6: =IF($A6="","",IFERROR(INDEX(計算用!$D$2:$D$149,MATCH(計算用!$U$3&3&"-"&$A6,計算用!$K$2:$K$149,0)),"")) | G6: =IF($A6="","",IFERROR(INDEX(計算用!$G$2:$G$149,MATCH(計算用!$U$3&3&"-"&$A6,計算用!$K$2:$K$149,0)),"")) | H6: =IF($A6="","",IFERROR(INDEX(計算用!$D$2:$D$149,MATCH(計算用!$U$3&4&"-"&$A6,計算用!$K$2:$K$149,0)),"")) | I6: =IF($A6="","",IFERROR(INDEX(計算用!$G$2:$G$149,MATCH(計算用!$U$3&4&"-"&$A6,計算用!$K$2:$K$149,0)),"")) | K6: =IF(2<=計算用!$U$10,2,"") | L6: =IF($K6="","",IFERROR(INDEX(計算用!$D$2:$D$149,MATCH("女"&1&"-"&$K6,計算用!$K$2:$K$149,0)),"")) | M6: =IF($K6="","",IFERROR(INDEX(計算用!$G$2:$G$149,MATCH("女"&1&"-"&$K6,計算用!$K$2:$K$149,0)),"")) | N6: =IF($K6="","",IFERROR(INDEX(計算用!$D$2:$D$149,MATCH("女"&2&"-"&$K6,計算用!$K$2:$K$149,0)),"")) | O6: =IF($K6="","",IFERROR(INDEX(計算用!$G$2:$G$149,MATCH("女"&2&"-"&$K6,計算用!$K$2:$K$149,0)),"")) | P6: =IF($K6="","",IFERROR(INDEX(計算用!$D$2:$D$149,MATCH("女"&3&"-"&$K6,計算用!$K$2:$K$149,0)),"")) | Q6: =IF($K6="","",IFERROR(INDEX(計算用!$G$2:$G$149,MATCH("女"&3&"-"&$K6,計算用!$K$2:$K$149,0)),"")) | R6: =IF($K6="","",IFERROR(INDEX(計算用!$D$2:$D$149,MATCH("女"&4&"-"&$K6,計算用!$K$2:$K$149,0)),"")) | S6: =IF($K6="","",IFERROR(INDEX(計算用!$G$2:$G$149,MATCH("女"&4&"-"&$K6,計算用!$K$2:$K$149,0)),""))
A7: =IF(3<=計算用!$U$9,3,"") | B7: =IF($A7="","",IFERROR(INDEX(計算用!$D$2:$D$149,MATCH(計算用!$U$3&1&"-"&$A7,計算用!$K$2:$K$149,0)),"")) | C7: =IF($A7="","",IFERROR(INDEX(計算用!$G$2:$G$149,MATCH(計算用!$U$3&1&"-"&$A7,計算用!$K$2:$K$149,0)),"")) | D7: =IF($A7="","",IFERROR(INDEX(計算用!$D$2:$D$149,MATCH(計算用!$U$3&2&"-"&$A7,計算用!$K$2:$K$149,0)),"")) | E7: =IF($A7="","",IFERROR(INDEX(計算用!$G$2:$G$149,MATCH(計算用!$U$3&2&"-"&$A7,計算用!$K$2:$K$149,0)),"")) | F7: =IF($A7="","",IFERROR(INDEX(計算用!$D$2:$D$149,MATCH(計算用!$U$3&3&"-"&$A7,計算用!$K$2:$K$149,0)),"")) | G7: =IF($A7="","",IFERROR(INDEX(計算用!$G$2:$G$149,MATCH(計算用!$U$3&3&"-"&$A7,計算用!$K$2:$K$149,0)),"")) | H7: =IF($A7="","",IFERROR(INDEX(計算用!$D$2:$D$149,MATCH(計算用!$U$3&4&"-"&$A7,計算用!$K$2:$K$149,0)),"")) | I7: =IF($A7="","",IFERROR(INDEX(計算用!$G$2:$G$149,MATCH(計算用!$U$3&4&"-"&$A7,計算用!$K$2:$K$149,0)),"")) | K7: =IF(3<=計算用!$U$10,3,"") | L7: =IF($K7="","",IFERROR(INDEX(計算用!$D$2:$D$149,MATCH("女"&1&"-"&$K7,計算用!$K$2:$K$149,0)),"")) | M7: =IF($K7="","",IFERROR(INDEX(計算用!$G$2:$G$149,MATCH("女"&1&"-"&$K7,計算用!$K$2:$K$149,0)),"")) | N7: =IF($K7="","",IFERROR(INDEX(計算用!$D$2:$D$149,MATCH("女"&2&"-"&$K7,計算用!$K$2:$K$149,0)),"")) | O7: =IF($K7="","",IFERROR(INDEX(計算用!$G$2:$G$149,MATCH("女"&2&"-"&$K7,計算用!$K$2:$K$149,0)),"")) | P7: =IF($K7="","",IFERROR(INDEX(計算用!$D$2:$D$149,MATCH("女"&3&"-"&$K7,計算用!$K$2:$K$149,0)),"")) | Q7: =IF($K7="","",IFERROR(INDEX(計算用!$G$2:$G$149,MATCH("女"&3&"-"&$K7,計算用!$K$2:$K$149,0)),"")) | R7: =IF($K7="","",IFERROR(INDEX(計算用!$D$2:$D$149,MATCH("女"&4&"-"&$K7,計算用!$K$2:$K$149,0)),"")) | S7: =IF($K7="","",IFERROR(INDEX(計算用!$G$2:$G$149,MATCH("女"&4&"-"&$K7,計算用!$K$2:$K$149,0)),""))
A8: =IF(4<=計算用!$U$9,4,"") | B8: =IF($A8="","",IFERROR(INDEX(計算用!$D$2:$D$149,MATCH(計算用!$U$3&1&"-"&$A8,計算用!$K$2:$K$149,0)),"")) | C8: =IF($A8="","",IFERROR(INDEX(計算用!$G$2:$G$149,MATCH(計算用!$U$3&1&"-"&$A8,計算用!$K$2:$K$149,0)),"")) | D8: =IF($A8="","",IFERROR(INDEX(計算用!$D$2:$D$149,MATCH(計算用!$U$3&2&"-"&$A8,計算用!$K$2:$K$149,0)),"")) | E8: =IF($A8="","",IFERROR(INDEX(計算用!$G$2:$G$149,MATCH(計算用!$U$3&2&"-"&$A8,計算用!$K$2:$K$149,0)),"")) | F8: =IF($A8="","",IFERROR(INDEX(計算用!$D$2:$D$149,MATCH(計算用!$U$3&3&"-"&$A8,計算用!$K$2:$K$149,0)),"")) | G8: =IF($A8="","",IFERROR(INDEX(計算用!$G$2:$G$149,MATCH(計算用!$U$3&3&"-"&$A8,計算用!$K$2:$K$149,0)),"")) | H8: =IF($A8="","",IFERROR(INDEX(計算用!$D$2:$D$149,MATCH(計算用!$U$3&4&"-"&$A8,計算用!$K$2:$K$149,0)),"")) | I8: =IF($A8="","",IFERROR(INDEX(計算用!$G$2:$G$149,MATCH(計算用!$U$3&4&"-"&$A8,計算用!$K$2:$K$149,0)),"")) | K8: =IF(4<=計算用!$U$10,4,"") | L8: =IF($K8="","",IFERROR(INDEX(計算用!$D$2:$D$149,MATCH("女"&1&"-"&$K8,計算用!$K$2:$K$149,0)),"")) | M8: =IF($K8="","",IFERROR(INDEX(計算用!$G$2:$G$149,MATCH("女"&1&"-"&$K8,計算用!$K$2:$K$149,0)),"")) | N8: =IF($K8="","",IFERROR(INDEX(計算用!$D$2:$D$149,MATCH("女"&2&"-"&$K8,計算用!$K$2:$K$149,0)),"")) | O8: =IF($K8="","",IFERROR(INDEX(計算用!$G$2:$G$149,MATCH("女"&2&"-"&$K8,計算用!$K$2:$K$149,0)),"")) | P8: =IF($K8="","",IFERROR(INDEX(計算用!$D$2:$D$149,MATCH("女"&3&"-"&$K8,計算用!$K$2:$K$149,0)),"")) | Q8: =IF($K8="","",IFERROR(INDEX(計算用!$G$2:$G$149,MATCH("女"&3&"-"&$K8,計算用!$K$2:$K$149,0)),"")) | R8: =IF($K8="","",IFERROR(INDEX(計算用!$D$2:$D$149,MATCH("女"&4&"-"&$K8,計算用!$K$2:$K$149,0)),"")) | S8: =IF($K8="","",IFERROR(INDEX(計算用!$G$2:$G$149,MATCH("女"&4&"-"&$K8,計算用!$K$2:$K$149,0)),""))
A9: =IF(5<=計算用!$U$9,5,"") | B9: =IF($A9="","",IFERROR(INDEX(計算用!$D$2:$D$149,MATCH(計算用!$U$3&1&"-"&$A9,計算用!$K$2:$K$149,0)),"")) | C9: =IF($A9="","",IFERROR(INDEX(計算用!$G$2:$G$149,MATCH(計算用!$U$3&1&"-"&$A9,計算用!$K$2:$K$149,0)),"")) | D9: =IF($A9="","",IFERROR(INDEX(計算用!$D$2:$D$149,MATCH(計算用!$U$3&2&"-"&$A9,計算用!$K$2:$K$149,0)),"")) | E9: =IF($A9="","",IFERROR(INDEX(計算用!$G$2:$G$149,MATCH(計算用!$U$3&2&"-"&$A9,計算用!$K$2:$K$149,0)),"")) | F9: =IF($A9="","",IFERROR(INDEX(計算用!$D$2:$D$149,MATCH(計算用!$U$3&3&"-"&$A9,計算用!$K$2:$K$149,0)),"")) | G9: =IF($A9="","",IFERROR(INDEX(計算用!$G$2:$G$149,MATCH(計算用!$U$3&3&"-"&$A9,計算用!$K$2:$K$149,0)),"")) | H9: =IF($A9="","",IFERROR(INDEX(計算用!$D$2:$D$149,MATCH(計算用!$U$3&4&"-"&$A9,計算用!$K$2:$K$149,0)),"")) | I9: =IF($A9="","",IFERROR(INDEX(計算用!$G$2:$G$149,MATCH(計算用!$U$3&4&"-"&$A9,計算用!$K$2:$K$149,0)),"")) | K9: =IF(5<=計算用!$U$10,5,"") | L9: =IF($K9="","",IFERROR(INDEX(計算用!$D$2:$D$149,MATCH("女"&1&"-"&$K9,計算用!$K$2:$K$149,0)),"")) | M9: =IF($K9="","",IFERROR(INDEX(計算用!$G$2:$G$149,MATCH("女"&1&"-"&$K9,計算用!$K$2:$K$149,0)),"")) | N9: =IF($K9="","",IFERROR(INDEX(計算用!$D$2:$D$149,MATCH("女"&2&"-"&$K9,計算用!$K$2:$K$149,0)),"")) | O9: =IF($K9="","",IFERROR(INDEX(計算用!$G$2:$G$149,MATCH("女"&2&"-"&$K9,計算用!$K$2:$K$149,0)),"")) | P9: =IF($K9="","",IFERROR(INDEX(計算用!$D$2:$D$149,MATCH("女"&3&"-"&$K9,計算用!$K$2:$K$149,0)),"")) | Q9: =IF($K9="","",IFERROR(INDEX(計算用!$G$2:$G$149,MATCH("女"&3&"-"&$K9,計算用!$K$2:$K$149,0)),"")) | R9: =IF($K9="","",IFERROR(INDEX(計算用!$D$2:$D$149,MATCH("女"&4&"-"&$K9,計算用!$K$2:$K$149,0)),"")) | S9: =IF($K9="","",IFERROR(INDEX(計算用!$G$2:$G$149,MATCH("女"&4&"-"&$K9,計算用!$K$2:$K$149,0)),""))
A10: =IF(6<=計算用!$U$9,6,"") | B10: =IF($A10="","",IFERROR(INDEX(計算用!$D$2:$D$149,MATCH(計算用!$U$3&1&"-"&$A10,計算用!$K$2:$K$149,0)),"")) | C10: =IF($A10="","",IFERROR(INDEX(計算用!$G$2:$G$149,MATCH(計算用!$U$3&1&"-"&$A10,計算用!$K$2:$K$149,0)),"")) | D10: =IF($A10="","",IFERROR(INDEX(計算用!$D$2:$D$149,MATCH(計算用!$U$3&2&"-"&$A10,計算用!$K$2:$K$149,0)),"")) | E10: =IF($A10="","",IFERROR(INDEX(計算用!$G$2:$G$149,MATCH(計算用!$U$3&2&"-"&$A10,計算用!$K$2:$K$149,0)),"")) | F10: =IF($A10="","",IFERROR(INDEX(計算用!$D$2:$D$149,MATCH(計算用!$U$3&3&"-"&$A10,計算用!$K$2:$K$149,0)),"")) | G10: =IF($A10="","",IFERROR(INDEX(計算用!$G$2:$G$149,MATCH(計算用!$U$3&3&"-"&$A10,計算用!$K$2:$K$149,0)),"")) | H10: =IF($A10="","",IFERROR(INDEX(計算用!$D$2:$D$149,MATCH(計算用!$U$3&4&"-"&$A10,計算用!$K$2:$K$149,0)),"")) | I10: =IF($A10="","",IFERROR(INDEX(計算用!$G$2:$G$149,MATCH(計算用!$U$3&4&"-"&$A10,計算用!$K$2:$K$149,0)),"")) | K10: =IF(6<=計算用!$U$10,6,"") | L10: =IF($K10="","",IFERROR(INDEX(計算用!$D$2:$D$149,MATCH("女"&1&"-"&$K10,計算用!$K$2:$K$149,0)),"")) | M10: =IF($K10="","",IFERROR(INDEX(計算用!$G$2:$G$149,MATCH("女"&1&"-"&$K10,計算用!$K$2:$K$149,0)),"")) | N10: =IF($K10="","",IFERROR(INDEX(計算用!$D$2:$D$149,MATCH("女"&2&"-"&$K10,計算用!$K$2:$K$149,0)),"")) | O10: =IF($K10="","",IFERROR(INDEX(計算用!$G$2:$G$149,MATCH("女"&2&"-"&$K10,計算用!$K$2:$K$149,0)),"")) | P10: =IF($K10="","",IFERROR(INDEX(計算用!$D$2:$D$149,MATCH("女"&3&"-"&$K10,計算用!$K$2:$K$149,0)),"")) | Q10: =IF($K10="","",IFERROR(INDEX(計算用!$G$2:$G$149,MATCH("女"&3&"-"&$K10,計算用!$K$2:$K$149,0)),"")) | R10: =IF($K10="","",IFERROR(INDEX(計算用!$D$2:$D$149,MATCH("女"&4&"-"&$K10,計算用!$K$2:$K$149,0)),"")) | S10: =IF($K10="","",IFERROR(INDEX(計算用!$G$2:$G$149,MATCH("女"&4&"-"&$K10,計算用!$K$2:$K$149,0)),""))
A11: =IF(7<=計算用!$U$9,7,"") | B11: =IF($A11="","",IFERROR(INDEX(計算用!$D$2:$D$149,MATCH(計算用!$U$3&1&"-"&$A11,計算用!$K$2:$K$149,0)),"")) | C11: =IF($A11="","",IFERROR(INDEX(計算用!$G$2:$G$149,MATCH(計算用!$U$3&1&"-"&$A11,計算用!$K$2:$K$149,0)),"")) | D11: =IF($A11="","",IFERROR(INDEX(計算用!$D$2:$D$149,MATCH(計算用!$U$3&2&"-"&$A11,計算用!$K$2:$K$149,0)),"")) | E11: =IF($A11="","",IFERROR(INDEX(計算用!$G$2:$G$149,MATCH(計算用!$U$3&2&"-"&$A11,計算用!$K$2:$K$149,0)),"")) | F11: =IF($A11="","",IFERROR(INDEX(計算用!$D$2:$D$149,MATCH(計算用!$U$3&3&"-"&$A11,計算用!$K$2:$K$149,0)),"")) | G11: =IF($A11="","",IFERROR(INDEX(計算用!$G$2:$G$149,MATCH(計算用!$U$3&3&"-"&$A11,計算用!$K$2:$K$149,0)),"")) | H11: =IF($A11="","",IFERROR(INDEX(計算用!$D$2:$D$149,MATCH(計算用!$U$3&4&"-"&$A11,計算用!$K$2:$K$149,0)),"")) | I11: =IF($A11="","",IFERROR(INDEX(計算用!$G$2:$G$149,MATCH(計算用!$U$3&4&"-"&$A11,計算用!$K$2:$K$149,0)),"")) | K11: =IF(7<=計算用!$U$10,7,"") | L11: =IF($K11="","",IFERROR(INDEX(計算用!$D$2:$D$149,MATCH("女"&1&"-"&$K11,計算用!$K$2:$K$149,0)),"")) | M11: =IF($K11="","",IFERROR(INDEX(計算用!$G$2:$G$149,MATCH("女"&1&"-"&$K11,計算用!$K$2:$K$149,0)),"")) | N11: =IF($K11="","",IFERROR(INDEX(計算用!$D$2:$D$149,MATCH("女"&2&"-"&$K11,計算用!$K$2:$K$149,0)),"")) | O11: =IF($K11="","",IFERROR(INDEX(計算用!$G$2:$G$149,MATCH("女"&2&"-"&$K11,計算用!$K$2:$K$149,0)),"")) | P11: =IF($K11="","",IFERROR(INDEX(計算用!$D$2:$D$149,MATCH("女"&3&"-"&$K11,計算用!$K$2:$K$149,0)),"")) | Q11: =IF($K11="","",IFERROR(INDEX(計算用!$G$2:$G$149,MATCH("女"&3&"-"&$K11,計算用!$K$2:$K$149,0)),"")) | R11: =IF($K11="","",IFERROR(INDEX(計算用!$D$2:$D$149,MATCH("女"&4&"-"&$K11,計算用!$K$2:$K$149,0)),"")) | S11: =IF($K11="","",IFERROR(INDEX(計算用!$G$2:$G$149,MATCH("女"&4&"-"&$K11,計算用!$K$2:$K$149,0)),""))
A12: =IF(8<=計算用!$U$9,8,"") | B12: =IF($A12="","",IFERROR(INDEX(計算用!$D$2:$D$149,MATCH(計算用!$U$3&1&"-"&$A12,計算用!$K$2:$K$149,0)),"")) | C12: =IF($A12="","",IFERROR(INDEX(計算用!$G$2:$G$149,MATCH(計算用!$U$3&1&"-"&$A12,計算用!$K$2:$K$149,0)),"")) | D12: =IF($A12="","",IFERROR(INDEX(計算用!$D$2:$D$149,MATCH(計算用!$U$3&2&"-"&$A12,計算用!$K$2:$K$149,0)),"")) | E12: =IF($A12="","",IFERROR(INDEX(計算用!$G$2:$G$149,MATCH(計算用!$U$3&2&"-"&$A12,計算用!$K$2:$K$149,0)),"")) | F12: =IF($A12="","",IFERROR(INDEX(計算用!$D$2:$D$149,MATCH(計算用!$U$3&3&"-"&$A12,計算用!$K$2:$K$149,0)),"")) | G12: =IF($A12="","",IFERROR(INDEX(計算用!$G$2:$G$149,MATCH(計算用!$U$3&3&"-"&$A12,計算用!$K$2:$K$149,0)),"")) | H12: =IF($A12="","",IFERROR(INDEX(計算用!$D$2:$D$149,MATCH(計算用!$U$3&4&"-"&$A12,計算用!$K$2:$K$149,0)),"")) | I12: =IF($A12="","",IFERROR(INDEX(計算用!$G$2:$G$149,MATCH(計算用!$U$3&4&"-"&$A12,計算用!$K$2:$K$149,0)),"")) | K12: =IF(8<=計算用!$U$10,8,"") | L12: =IF($K12="","",IFERROR(INDEX(計算用!$D$2:$D$149,MATCH("女"&1&"-"&$K12,計算用!$K$2:$K$149,0)),"")) | M12: =IF($K12="","",IFERROR(INDEX(計算用!$G$2:$G$149,MATCH("女"&1&"-"&$K12,計算用!$K$2:$K$149,0)),"")) | N12: =IF($K12="","",IFERROR(INDEX(計算用!$D$2:$D$149,MATCH("女"&2&"-"&$K12,計算用!$K$2:$K$149,0)),"")) | O12: =IF($K12="","",IFERROR(INDEX(計算用!$G$2:$G$149,MATCH("女"&2&"-"&$K12,計算用!$K$2:$K$149,0)),"")) | P12: =IF($K12="","",IFERROR(INDEX(計算用!$D$2:$D$149,MATCH("女"&3&"-"&$K12,計算用!$K$2:$K$149,0)),"")) | Q12: =IF($K12="","",IFERROR(INDEX(計算用!$G$2:$G$149,MATCH("女"&3&"-"&$K12,計算用!$K$2:$K$149,0)),"")) | R12: =IF($K12="","",IFERROR(INDEX(計算用!$D$2:$D$149,MATCH("女"&4&"-"&$K12,計算用!$K$2:$K$149,0)),"")) | S12: =IF($K12="","",IFERROR(INDEX(計算用!$G$2:$G$149,MATCH("女"&4&"-"&$K12,計算用!$K$2:$K$149,0)),""))
A13: =IF(9<=計算用!$U$9,9,"") | B13: =IF($A13="","",IFERROR(INDEX(計算用!$D$2:$D$149,MATCH(計算用!$U$3&1&"-"&$A13,計算用!$K$2:$K$149,0)),"")) | C13: =IF($A13="","",IFERROR(INDEX(計算用!$G$2:$G$149,MATCH(計算用!$U$3&1&"-"&$A13,計算用!$K$2:$K$149,0)),"")) | D13: =IF($A13="","",IFERROR(INDEX(計算用!$D$2:$D$149,MATCH(計算用!$U$3&2&"-"&$A13,計算用!$K$2:$K$149,0)),"")) | E13: =IF($A13="","",IFERROR(INDEX(計算用!$G$2:$G$149,MATCH(計算用!$U$3&2&"-"&$A13,計算用!$K$2:$K$149,0)),"")) | F13: =IF($A13="","",IFERROR(INDEX(計算用!$D$2:$D$149,MATCH(計算用!$U$3&3&"-"&$A13,計算用!$K$2:$K$149,0)),"")) | G13: =IF($A13="","",IFERROR(INDEX(計算用!$G$2:$G$149,MATCH(計算用!$U$3&3&"-"&$A13,計算用!$K$2:$K$149,0)),"")) | H13: =IF($A13="","",IFERROR(INDEX(計算用!$D$2:$D$149,MATCH(計算用!$U$3&4&"-"&$A13,計算用!$K$2:$K$149,0)),"")) | I13: =IF($A13="","",IFERROR(INDEX(計算用!$G$2:$G$149,MATCH(計算用!$U$3&4&"-"&$A13,計算用!$K$2:$K$149,0)),"")) | K13: =IF(9<=計算用!$U$10,9,"") | L13: =IF($K13="","",IFERROR(INDEX(計算用!$D$2:$D$149,MATCH("女"&1&"-"&$K13,計算用!$K$2:$K$149,0)),"")) | M13: =IF($K13="","",IFERROR(INDEX(計算用!$G$2:$G$149,MATCH("女"&1&"-"&$K13,計算用!$K$2:$K$149,0)),"")) | N13: =IF($K13="","",IFERROR(INDEX(計算用!$D$2:$D$149,MATCH("女"&2&"-"&$K13,計算用!$K$2:$K$149,0)),"")) | O13: =IF($K13="","",IFERROR(INDEX(計算用!$G$2:$G$149,MATCH("女"&2&"-"&$K13,計算用!$K$2:$K$149,0)),"")) | P13: =IF($K13="","",IFERROR(INDEX(計算用!$D$2:$D$149,MATCH("女"&3&"-"&$K13,計算用!$K$2:$K$149,0)),"")) | Q13: =IF($K13="","",IFERROR(INDEX(計算用!$G$2:$G$149,MATCH("女"&3&"-"&$K13,計算用!$K$2:$K$149,0)),"")) | R13: =IF($K13="","",IFERROR(INDEX(計算用!$D$2:$D$149,MATCH("女"&4&"-"&$K13,計算用!$K$2:$K$149,0)),"")) | S13: =IF($K13="","",IFERROR(INDEX(計算用!$G$2:$G$149,MATCH("女"&4&"-"&$K13,計算用!$K$2:$K$149,0)),""))
A14: =IF(10<=計算用!$U$9,10,"") | B14: =IF($A14="","",IFERROR(INDEX(計算用!$D$2:$D$149,MATCH(計算用!$U$3&1&"-"&$A14,計算用!$K$2:$K$149,0)),"")) | C14: =IF($A14="","",IFERROR(INDEX(計算用!$G$2:$G$149,MATCH(計算用!$U$3&1&"-"&$A14,計算用!$K$2:$K$149,0)),"")) | D14: =IF($A14="","",IFERROR(INDEX(計算用!$D$2:$D$149,MATCH(計算用!$U$3&2&"-"&$A14,計算用!$K$2:$K$149,0)),"")) | E14: =IF($A14="","",IFERROR(INDEX(計算用!$G$2:$G$149,MATCH(計算用!$U$3&2&"-"&$A14,計算用!$K$2:$K$149,0)),"")) | F14: =IF($A14="","",IFERROR(INDEX(計算用!$D$2:$D$149,MATCH(計算用!$U$3&3&"-"&$A14,計算用!$K$2:$K$149,0)),"")) | G14: =IF($A14="","",IFERROR(INDEX(計算用!$G$2:$G$149,MATCH(計算用!$U$3&3&"-"&$A14,計算用!$K$2:$K$149,0)),"")) | H14: =IF($A14="","",IFERROR(INDEX(計算用!$D$2:$D$149,MATCH(計算用!$U$3&4&"-"&$A14,計算用!$K$2:$K$149,0)),"")) | I14: =IF($A14="","",IFERROR(INDEX(計算用!$G$2:$G$149,MATCH(計算用!$U$3&4&"-"&$A14,計算用!$K$2:$K$149,0)),"")) | K14: =IF(10<=計算用!$U$10,10,"") | L14: =IF($K14="","",IFERROR(INDEX(計算用!$D$2:$D$149,MATCH("女"&1&"-"&$K14,計算用!$K$2:$K$149,0)),"")) | M14: =IF($K14="","",IFERROR(INDEX(計算用!$G$2:$G$149,MATCH("女"&1&"-"&$K14,計算用!$K$2:$K$149,0)),"")) | N14: =IF($K14="","",IFERROR(INDEX(計算用!$D$2:$D$149,MATCH("女"&2&"-"&$K14,計算用!$K$2:$K$149,0)),"")) | O14: =IF($K14="","",IFERROR(INDEX(計算用!$G$2:$G$149,MATCH("女"&2&"-"&$K14,計算用!$K$2:$K$149,0)),"")) | P14: =IF($K14="","",IFERROR(INDEX(計算用!$D$2:$D$149,MATCH("女"&3&"-"&$K14,計算用!$K$2:$K$149,0)),"")) | Q14: =IF($K14="","",IFERROR(INDEX(計算用!$G$2:$G$149,MATCH("女"&3&"-"&$K14,計算用!$K$2:$K$149,0)),"")) | R14: =IF($K14="","",IFERROR(INDEX(計算用!$D$2:$D$149,MATCH("女"&4&"-"&$K14,計算用!$K$2:$K$149,0)),"")) | S14: =IF($K14="","",IFERROR(INDEX(計算用!$G$2:$G$149,MATCH("女"&4&"-"&$K14,計算用!$K$2:$K$149,0)),""))
A15: =IF(11<=計算用!$U$9,11,"") | B15: =IF($A15="","",IFERROR(INDEX(計算用!$D$2:$D$149,MATCH(計算用!$U$3&1&"-"&$A15,計算用!$K$2:$K$149,0)),"")) | C15: =IF($A15="","",IFERROR(INDEX(計算用!$G$2:$G$149,MATCH(計算用!$U$3&1&"-"&$A15,計算用!$K$2:$K$149,0)),"")) | D15: =IF($A15="","",IFERROR(INDEX(計算用!$D$2:$D$149,MATCH(計算用!$U$3&2&"-"&$A15,計算用!$K$2:$K$149,0)),"")) | E15: =IF($A15="","",IFERROR(INDEX(計算用!$G$2:$G$149,MATCH(計算用!$U$3&2&"-"&$A15,計算用!$K$2:$K$149,0)),"")) | F15: =IF($A15="","",IFERROR(INDEX(計算用!$D$2:$D$149,MATCH(計算用!$U$3&3&"-"&$A15,計算用!$K$2:$K$149,0)),"")) | G15: =IF($A15="","",IFERROR(INDEX(計算用!$G$2:$G$149,MATCH(計算用!$U$3&3&"-"&$A15,計算用!$K$2:$K$149,0)),"")) | H15: =IF($A15="","",IFERROR(INDEX(計算用!$D$2:$D$149,MATCH(計算用!$U$3&4&"-"&$A15,計算用!$K$2:$K$149,0)),"")) | I15: =IF($A15="","",IFERROR(INDEX(計算用!$G$2:$G$149,MATCH(計算用!$U$3&4&"-"&$A15,計算用!$K$2:$K$149,0)),"")) | K15: =IF(11<=計算用!$U$10,11,"") | L15: =IF($K15="","",IFERROR(INDEX(計算用!$D$2:$D$149,MATCH("女"&1&"-"&$K15,計算用!$K$2:$K$149,0)),"")) | M15: =IF($K15="","",IFERROR(INDEX(計算用!$G$2:$G$149,MATCH("女"&1&"-"&$K15,計算用!$K$2:$K$149,0)),"")) | N15: =IF($K15="","",IFERROR(INDEX(計算用!$D$2:$D$149,MATCH("女"&2&"-"&$K15,計算用!$K$2:$K$149,0)),"")) | O15: =IF($K15="","",IFERROR(INDEX(計算用!$G$2:$G$149,MATCH("女"&2&"-"&$K15,計算用!$K$2:$K$149,0)),"")) | P15: =IF($K15="","",IFERROR(INDEX(計算用!$D$2:$D$149,MATCH("女"&3&"-"&$K15,計算用!$K$2:$K$149,0)),"")) | Q15: =IF($K15="","",IFERROR(INDEX(計算用!$G$2:$G$149,MATCH("女"&3&"-"&$K15,計算用!$K$2:$K$149,0)),"")) | R15: =IF($K15="","",IFERROR(INDEX(計算用!$D$2:$D$149,MATCH("女"&4&"-"&$K15,計算用!$K$2:$K$149,0)),"")) | S15: =IF($K15="","",IFERROR(INDEX(計算用!$G$2:$G$149,MATCH("女"&4&"-"&$K15,計算用!$K$2:$K$149,0)),""))
A16: =IF(12<=計算用!$U$9,12,"") | B16: =IF($A16="","",IFERROR(INDEX(計算用!$D$2:$D$149,MATCH(計算用!$U$3&1&"-"&$A16,計算用!$K$2:$K$149,0)),"")) | C16: =IF($A16="","",IFERROR(INDEX(計算用!$G$2:$G$149,MATCH(計算用!$U$3&1&"-"&$A16,計算用!$K$2:$K$149,0)),"")) | D16: =IF($A16="","",IFERROR(INDEX(計算用!$D$2:$D$149,MATCH(計算用!$U$3&2&"-"&$A16,計算用!$K$2:$K$149,0)),"")) | E16: =IF($A16="","",IFERROR(INDEX(計算用!$G$2:$G$149,MATCH(計算用!$U$3&2&"-"&$A16,計算用!$K$2:$K$149,0)),"")) | F16: =IF($A16="","",IFERROR(INDEX(計算用!$D$2:$D$149,MATCH(計算用!$U$3&3&"-"&$A16,計算用!$K$2:$K$149,0)),"")) | G16: =IF($A16="","",IFERROR(INDEX(計算用!$G$2:$G$149,MATCH(計算用!$U$3&3&"-"&$A16,計算用!$K$2:$K$149,0)),"")) | H16: =IF($A16="","",IFERROR(INDEX(計算用!$D$2:$D$149,MATCH(計算用!$U$3&4&"-"&$A16,計算用!$K$2:$K$149,0)),"")) | I16: =IF($A16="","",IFERROR(INDEX(計算用!$G$2:$G$149,MATCH(計算用!$U$3&4&"-"&$A16,計算用!$K$2:$K$149,0)),"")) | K16: =IF(12<=計算用!$U$10,12,"") | L16: =IF($K16="","",IFERROR(INDEX(計算用!$D$2:$D$149,MATCH("女"&1&"-"&$K16,計算用!$K$2:$K$149,0)),"")) | M16: =IF($K16="","",IFERROR(INDEX(計算用!$G$2:$G$149,MATCH("女"&1&"-"&$K16,計算用!$K$2:$K$149,0)),"")) | N16: =IF($K16="","",IFERROR(INDEX(計算用!$D$2:$D$149,MATCH("女"&2&"-"&$K16,計算用!$K$2:$K$149,0)),"")) | O16: =IF($K16="","",IFERROR(INDEX(計算用!$G$2:$G$149,MATCH("女"&2&"-"&$K16,計算用!$K$2:$K$149,0)),"")) | P16: =IF($K16="","",IFERROR(INDEX(計算用!$D$2:$D$149,MATCH("女"&3&"-"&$K16,計算用!$K$2:$K$149,0)),"")) | Q16: =IF($K16="","",IFERROR(INDEX(計算用!$G$2:$G$149,MATCH("女"&3&"-"&$K16,計算用!$K$2:$K$149,0)),"")) | R16: =IF($K16="","",IFERROR(INDEX(計算用!$D$2:$D$149,MATCH("女"&4&"-"&$K16,計算用!$K$2:$K$149,0)),"")) | S16: =IF($K16="","",IFERROR(INDEX(計算用!$G$2:$G$149,MATCH("女"&4&"-"&$K16,計算用!$K$2:$K$149,0)),""))
A17: =IF(13<=計算用!$U$9,13,"") | B17: =IF($A17="","",IFERROR(INDEX(計算用!$D$2:$D$149,MATCH(計算用!$U$3&1&"-"&$A17,計算用!$K$2:$K$149,0)),"")) | C17: =IF($A17="","",IFERROR(INDEX(計算用!$G$2:$G$149,MATCH(計算用!$U$3&1&"-"&$A17,計算用!$K$2:$K$149,0)),"")) | D17: =IF($A17="","",IFERROR(INDEX(計算用!$D$2:$D$149,MATCH(計算用!$U$3&2&"-"&$A17,計算用!$K$2:$K$149,0)),"")) | E17: =IF($A17="","",IFERROR(INDEX(計算用!$G$2:$G$149,MATCH(計算用!$U$3&2&"-"&$A17,計算用!$K$2:$K$149,0)),"")) | F17: =IF($A17="","",IFERROR(INDEX(計算用!$D$2:$D$149,MATCH(計算用!$U$3&3&"-"&$A17,計算用!$K$2:$K$149,0)),"")) | G17: =IF($A17="","",IFERROR(INDEX(計算用!$G$2:$G$149,MATCH(計算用!$U$3&3&"-"&$A17,計算用!$K$2:$K$149,0)),"")) | H17: =IF($A17="","",IFERROR(INDEX(計算用!$D$2:$D$149,MATCH(計算用!$U$3&4&"-"&$A17,計算用!$K$2:$K$149,0)),"")) | I17: =IF($A17="","",IFERROR(INDEX(計算用!$G$2:$G$149,MATCH(計算用!$U$3&4&"-"&$A17,計算用!$K$2:$K$149,0)),"")) | K17: =IF(13<=計算用!$U$10,13,"") | L17: =IF($K17="","",IFERROR(INDEX(計算用!$D$2:$D$149,MATCH("女"&1&"-"&$K17,計算用!$K$2:$K$149,0)),"")) | M17: =IF($K17="","",IFERROR(INDEX(計算用!$G$2:$G$149,MATCH("女"&1&"-"&$K17,計算用!$K$2:$K$149,0)),"")) | N17: =IF($K17="","",IFERROR(INDEX(計算用!$D$2:$D$149,MATCH("女"&2&"-"&$K17,計算用!$K$2:$K$149,0)),"")) | O17: =IF($K17="","",IFERROR(INDEX(計算用!$G$2:$G$149,MATCH("女"&2&"-"&$K17,計算用!$K$2:$K$149,0)),"")) | P17: =IF($K17="","",IFERROR(INDEX(計算用!$D$2:$D$149,MATCH("女"&3&"-"&$K17,計算用!$K$2:$K$149,0)),"")) | Q17: =IF($K17="","",IFERROR(INDEX(計算用!$G$2:$G$149,MATCH("女"&3&"-"&$K17,計算用!$K$2:$K$149,0)),"")) | R17: =IF($K17="","",IFERROR(INDEX(計算用!$D$2:$D$149,MATCH("女"&4&"-"&$K17,計算用!$K$2:$K$149,0)),"")) | S17: =IF($K17="","",IFERROR(INDEX(計算用!$G$2:$G$149,MATCH("女"&4&"-"&$K17,計算用!$K$2:$K$149,0)),""))
A18: =IF(14<=計算用!$U$9,14,"") | B18: =IF($A18="","",IFERROR(INDEX(計算用!$D$2:$D$149,MATCH(計算用!$U$3&1&"-"&$A18,計算用!$K$2:$K$149,0)),"")) | C18: =IF($A18="","",IFERROR(INDEX(計算用!$G$2:$G$149,MATCH(計算用!$U$3&1&"-"&$A18,計算用!$K$2:$K$149,0)),"")) | D18: =IF($A18="","",IFERROR(INDEX(計算用!$D$2:$D$149,MATCH(計算用!$U$3&2&"-"&$A18,計算用!$K$2:$K$149,0)),"")) | E18: =IF($A18="","",IFERROR(INDEX(計算用!$G$2:$G$149,MATCH(計算用!$U$3&2&"-"&$A18,計算用!$K$2:$K$149,0)),"")) | F18: =IF($A18="","",IFERROR(INDEX(計算用!$D$2:$D$149,MATCH(計算用!$U$3&3&"-"&$A18,計算用!$K$2:$K$149,0)),"")) | G18: =IF($A18="","",IFERROR(INDEX(計算用!$G$2:$G$149,MATCH(計算用!$U$3&3&"-"&$A18,計算用!$K$2:$K$149,0)),"")) | H18: =IF($A18="","",IFERROR(INDEX(計算用!$D$2:$D$149,MATCH(計算用!$U$3&4&"-"&$A18,計算用!$K$2:$K$149,0)),"")) | I18: =IF($A18="","",IFERROR(INDEX(計算用!$G$2:$G$149,MATCH(計算用!$U$3&4&"-"&$A18,計算用!$K$2:$K$149,0)),"")) | K18: =IF(14<=計算用!$U$10,14,"") | L18: =IF($K18="","",IFERROR(INDEX(計算用!$D$2:$D$149,MATCH("女"&1&"-"&$K18,計算用!$K$2:$K$149,0)),"")) | M18: =IF($K18="","",IFERROR(INDEX(計算用!$G$2:$G$149,MATCH("女"&1&"-"&$K18,計算用!$K$2:$K$149,0)),"")) | N18: =IF($K18="","",IFERROR(INDEX(計算用!$D$2:$D$149,MATCH("女"&2&"-"&$K18,計算用!$K$2:$K$149,0)),"")) | O18: =IF($K18="","",IFERROR(INDEX(計算用!$G$2:$G$149,MATCH("女"&2&"-"&$K18,計算用!$K$2:$K$149,0)),"")) | P18: =IF($K18="","",IFERROR(INDEX(計算用!$D$2:$D$149,MATCH("女"&3&"-"&$K18,計算用!$K$2:$K$149,0)),"")) | Q18: =IF($K18="","",IFERROR(INDEX(計算用!$G$2:$G$149,MATCH("女"&3&"-"&$K18,計算用!$K$2:$K$149,0)),"")) | R18: =IF($K18="","",IFERROR(INDEX(計算用!$D$2:$D$149,MATCH("女"&4&"-"&$K18,計算用!$K$2:$K$149,0)),"")) | S18: =IF($K18="","",IFERROR(INDEX(計算用!$G$2:$G$149,MATCH("女"&4&"-"&$K18,計算用!$K$2:$K$149,0)),""))
A19: =IF(15<=計算用!$U$9,15,"") | B19: =IF($A19="","",IFERROR(INDEX(計算用!$D$2:$D$149,MATCH(計算用!$U$3&1&"-"&$A19,計算用!$K$2:$K$149,0)),"")) | C19: =IF($A19="","",IFERROR(INDEX(計算用!$G$2:$G$149,MATCH(計算用!$U$3&1&"-"&$A19,計算用!$K$2:$K$149,0)),"")) | D19: =IF($A19="","",IFERROR(INDEX(計算用!$D$2:$D$149,MATCH(計算用!$U$3&2&"-"&$A19,計算用!$K$2:$K$149,0)),"")) | E19: =IF($A19="","",IFERROR(INDEX(計算用!$G$2:$G$149,MATCH(計算用!$U$3&2&"-"&$A19,計算用!$K$2:$K$149,0)),"")) | F19: =IF($A19="","",IFERROR(INDEX(計算用!$D$2:$D$149,MATCH(計算用!$U$3&3&"-"&$A19,計算用!$K$2:$K$149,0)),"")) | G19: =IF($A19="","",IFERROR(INDEX(計算用!$G$2:$G$149,MATCH(計算用!$U$3&3&"-"&$A19,計算用!$K$2:$K$149,0)),"")) | H19: =IF($A19="","",IFERROR(INDEX(計算用!$D$2:$D$149,MATCH(計算用!$U$3&4&"-"&$A19,計算用!$K$2:$K$149,0)),"")) | I19: =IF($A19="","",IFERROR(INDEX(計算用!$G$2:$G$149,MATCH(計算用!$U$3&4&"-"&$A19,計算用!$K$2:$K$149,0)),"")) | K19: =IF(15<=計算用!$U$10,15,"") | L19: =IF($K19="","",IFERROR(INDEX(計算用!$D$2:$D$149,MATCH("女"&1&"-"&$K19,計算用!$K$2:$K$149,0)),"")) | M19: =IF($K19="","",IFERROR(INDEX(計算用!$G$2:$G$149,MATCH("女"&1&"-"&$K19,計算用!$K$2:$K$149,0)),"")) | N19: =IF($K19="","",IFERROR(INDEX(計算用!$D$2:$D$149,MATCH("女"&2&"-"&$K19,計算用!$K$2:$K$149,0)),"")) | O19: =IF($K19="","",IFERROR(INDEX(計算用!$G$2:$G$149,MATCH("女"&2&"-"&$K19,計算用!$K$2:$K$149,0)),"")) | P19: =IF($K19="","",IFERROR(INDEX(計算用!$D$2:$D$149,MATCH("女"&3&"-"&$K19,計算用!$K$2:$K$149,0)),"")) | Q19: =IF($K19="","",IFERROR(INDEX(計算用!$G$2:$G$149,MATCH("女"&3&"-"&$K19,計算用!$K$2:$K$149,0)),"")) | R19: =IF($K19="","",IFERROR(INDEX(計算用!$D$2:$D$149,MATCH("女"&4&"-"&$K19,計算用!$K$2:$K$149,0)),"")) | S19: =IF($K19="","",IFERROR(INDEX(計算用!$G$2:$G$149,MATCH("女"&4&"-"&$K19,計算用!$K$2:$K$149,0)),""))
A20: =IF(16<=計算用!$U$9,16,"") | B20: =IF($A20="","",IFERROR(INDEX(計算用!$D$2:$D$149,MATCH(計算用!$U$3&1&"-"&$A20,計算用!$K$2:$K$149,0)),"")) | C20: =IF($A20="","",IFERROR(INDEX(計算用!$G$2:$G$149,MATCH(計算用!$U$3&1&"-"&$A20,計算用!$K$2:$K$149,0)),"")) | D20: =IF($A20="","",IFERROR(INDEX(計算用!$D$2:$D$149,MATCH(計算用!$U$3&2&"-"&$A20,計算用!$K$2:$K$149,0)),"")) | E20: =IF($A20="","",IFERROR(INDEX(計算用!$G$2:$G$149,MATCH(計算用!$U$3&2&"-"&$A20,計算用!$K$2:$K$149,0)),"")) | F20: =IF($A20="","",IFERROR(INDEX(計算用!$D$2:$D$149,MATCH(計算用!$U$3&3&"-"&$A20,計算用!$K$2:$K$149,0)),"")) | G20: =IF($A20="","",IFERROR(INDEX(計算用!$G$2:$G$149,MATCH(計算用!$U$3&3&"-"&$A20,計算用!$K$2:$K$149,0)),"")) | H20: =IF($A20="","",IFERROR(INDEX(計算用!$D$2:$D$149,MATCH(計算用!$U$3&4&"-"&$A20,計算用!$K$2:$K$149,0)),"")) | I20: =IF($A20="","",IFERROR(INDEX(計算用!$G$2:$G$149,MATCH(計算用!$U$3&4&"-"&$A20,計算用!$K$2:$K$149,0)),"")) | K20: =IF(16<=計算用!$U$10,16,"") | L20: =IF($K20="","",IFERROR(INDEX(計算用!$D$2:$D$149,MATCH("女"&1&"-"&$K20,計算用!$K$2:$K$149,0)),"")) | M20: =IF($K20="","",IFERROR(INDEX(計算用!$G$2:$G$149,MATCH("女"&1&"-"&$K20,計算用!$K$2:$K$149,0)),"")) | N20: =IF($K20="","",IFERROR(INDEX(計算用!$D$2:$D$149,MATCH("女"&2&"-"&$K20,計算用!$K$2:$K$149,0)),"")) | O20: =IF($K20="","",IFERROR(INDEX(計算用!$G$2:$G$149,MATCH("女"&2&"-"&$K20,計算用!$K$2:$K$149,0)),"")) | P20: =IF($K20="","",IFERROR(INDEX(計算用!$D$2:$D$149,MATCH("女"&3&"-"&$K20,計算用!$K$2:$K$149,0)),"")) | Q20: =IF($K20="","",IFERROR(INDEX(計算用!$G$2:$G$149,MATCH("女"&3&"-"&$K20,計算用!$K$2:$K$149,0)),"")) | R20: =IF($K20="","",IFERROR(INDEX(計算用!$D$2:$D$149,MATCH("女"&4&"-"&$K20,計算用!$K$2:$K$149,0)),"")) | S20: =IF($K20="","",IFERROR(INDEX(計算用!$G$2:$G$149,MATCH("女"&4&"-"&$K20,計算用!$K$2:$K$149,0)),""))
A21: =IF(17<=計算用!$U$9,17,"") | B21: =IF($A21="","",IFERROR(INDEX(計算用!$D$2:$D$149,MATCH(計算用!$U$3&1&"-"&$A21,計算用!$K$2:$K$149,0)),"")) | C21: =IF($A21="","",IFERROR(INDEX(計算用!$G$2:$G$149,MATCH(計算用!$U$3&1&"-"&$A21,計算用!$K$2:$K$149,0)),"")) | D21: =IF($A21="","",IFERROR(INDEX(計算用!$D$2:$D$149,MATCH(計算用!$U$3&2&"-"&$A21,計算用!$K$2:$K$149,0)),"")) | E21: =IF($A21="","",IFERROR(INDEX(計算用!$G$2:$G$149,MATCH(計算用!$U$3&2&"-"&$A21,計算用!$K$2:$K$149,0)),"")) | F21: =IF($A21="","",IFERROR(INDEX(計算用!$D$2:$D$149,MATCH(計算用!$U$3&3&"-"&$A21,計算用!$K$2:$K$149,0)),"")) | G21: =IF($A21="","",IFERROR(INDEX(計算用!$G$2:$G$149,MATCH(計算用!$U$3&3&"-"&$A21,計算用!$K$2:$K$149,0)),"")) | H21: =IF($A21="","",IFERROR(INDEX(計算用!$D$2:$D$149,MATCH(計算用!$U$3&4&"-"&$A21,計算用!$K$2:$K$149,0)),"")) | I21: =IF($A21="","",IFERROR(INDEX(計算用!$G$2:$G$149,MATCH(計算用!$U$3&4&"-"&$A21,計算用!$K$2:$K$149,0)),"")) | K21: =IF(17<=計算用!$U$10,17,"") | L21: =IF($K21="","",IFERROR(INDEX(計算用!$D$2:$D$149,MATCH("女"&1&"-"&$K21,計算用!$K$2:$K$149,0)),"")) | M21: =IF($K21="","",IFERROR(INDEX(計算用!$G$2:$G$149,MATCH("女"&1&"-"&$K21,計算用!$K$2:$K$149,0)),"")) | N21: =IF($K21="","",IFERROR(INDEX(計算用!$D$2:$D$149,MATCH("女"&2&"-"&$K21,計算用!$K$2:$K$149,0)),"")) | O21: =IF($K21="","",IFERROR(INDEX(計算用!$G$2:$G$149,MATCH("女"&2&"-"&$K21,計算用!$K$2:$K$149,0)),"")) | P21: =IF($K21="","",IFERROR(INDEX(計算用!$D$2:$D$149,MATCH("女"&3&"-"&$K21,計算用!$K$2:$K$149,0)),"")) | Q21: =IF($K21="","",IFERROR(INDEX(計算用!$G$2:$G$149,MATCH("女"&3&"-"&$K21,計算用!$K$2:$K$149,0)),"")) | R21: =IF($K21="","",IFERROR(INDEX(計算用!$D$2:$D$149,MATCH("女"&4&"-"&$K21,計算用!$K$2:$K$149,0)),"")) | S21: =IF($K21="","",IFERROR(INDEX(計算用!$G$2:$G$149,MATCH("女"&4&"-"&$K21,計算用!$K$2:$K$149,0)),""))
A22: =IF(18<=計算用!$U$9,18,"") | B22: =IF($A22="","",IFERROR(INDEX(計算用!$D$2:$D$149,MATCH(計算用!$U$3&1&"-"&$A22,計算用!$K$2:$K$149,0)),"")) | C22: =IF($A22="","",IFERROR(INDEX(計算用!$G$2:$G$149,MATCH(計算用!$U$3&1&"-"&$A22,計算用!$K$2:$K$149,0)),"")) | D22: =IF($A22="","",IFERROR(INDEX(計算用!$D$2:$D$149,MATCH(計算用!$U$3&2&"-"&$A22,計算用!$K$2:$K$149,0)),"")) | E22: =IF($A22="","",IFERROR(INDEX(計算用!$G$2:$G$149,MATCH(計算用!$U$3&2&"-"&$A22,計算用!$K$2:$K$149,0)),"")) | F22: =IF($A22="","",IFERROR(INDEX(計算用!$D$2:$D$149,MATCH(計算用!$U$3&3&"-"&$A22,計算用!$K$2:$K$149,0)),"")) | G22: =IF($A22="","",IFERROR(INDEX(計算用!$G$2:$G$149,MATCH(計算用!$U$3&3&"-"&$A22,計算用!$K$2:$K$149,0)),"")) | H22: =IF($A22="","",IFERROR(INDEX(計算用!$D$2:$D$149,MATCH(計算用!$U$3&4&"-"&$A22,計算用!$K$2:$K$149,0)),"")) | I22: =IF($A22="","",IFERROR(INDEX(計算用!$G$2:$G$149,MATCH(計算用!$U$3&4&"-"&$A22,計算用!$K$2:$K$149,0)),"")) | K22: =IF(18<=計算用!$U$10,18,"") | L22: =IF($K22="","",IFERROR(INDEX(計算用!$D$2:$D$149,MATCH("女"&1&"-"&$K22,計算用!$K$2:$K$149,0)),"")) | M22: =IF($K22="","",IFERROR(INDEX(計算用!$G$2:$G$149,MATCH("女"&1&"-"&$K22,計算用!$K$2:$K$149,0)),"")) | N22: =IF($K22="","",IFERROR(INDEX(計算用!$D$2:$D$149,MATCH("女"&2&"-"&$K22,計算用!$K$2:$K$149,0)),"")) | O22: =IF($K22="","",IFERROR(INDEX(計算用!$G$2:$G$149,MATCH("女"&2&"-"&$K22,計算用!$K$2:$K$149,0)),"")) | P22: =IF($K22="","",IFERROR(INDEX(計算用!$D$2:$D$149,MATCH("女"&3&"-"&$K22,計算用!$K$2:$K$149,0)),"")) | Q22: =IF($K22="","",IFERROR(INDEX(計算用!$G$2:$G$149,MATCH("女"&3&"-"&$K22,計算用!$K$2:$K$149,0)),"")) | R22: =IF($K22="","",IFERROR(INDEX(計算用!$D$2:$D$149,MATCH("女"&4&"-"&$K22,計算用!$K$2:$K$149,0)),"")) | S22: =IF($K22="","",IFERROR(INDEX(計算用!$G$2:$G$149,MATCH("女"&4&"-"&$K22,計算用!$K$2:$K$149,0)),""))
A23: =IF(19<=計算用!$U$9,19,"") | B23: =IF($A23="","",IFERROR(INDEX(計算用!$D$2:$D$149,MATCH(計算用!$U$3&1&"-"&$A23,計算用!$K$2:$K$149,0)),"")) | C23: =IF($A23="","",IFERROR(INDEX(計算用!$G$2:$G$149,MATCH(計算用!$U$3&1&"-"&$A23,計算用!$K$2:$K$149,0)),"")) | D23: =IF($A23="","",IFERROR(INDEX(計算用!$D$2:$D$149,MATCH(計算用!$U$3&2&"-"&$A23,計算用!$K$2:$K$149,0)),"")) | E23: =IF($A23="","",IFERROR(INDEX(計算用!$G$2:$G$149,MATCH(計算用!$U$3&2&"-"&$A23,計算用!$K$2:$K$149,0)),"")) | F23: =IF($A23="","",IFERROR(INDEX(計算用!$D$2:$D$149,MATCH(計算用!$U$3&3&"-"&$A23,計算用!$K$2:$K$149,0)),"")) | G23: =IF($A23="","",IFERROR(INDEX(計算用!$G$2:$G$149,MATCH(計算用!$U$3&3&"-"&$A23,計算用!$K$2:$K$149,0)),"")) | H23: =IF($A23="","",IFERROR(INDEX(計算用!$D$2:$D$149,MATCH(計算用!$U$3&4&"-"&$A23,計算用!$K$2:$K$149,0)),"")) | I23: =IF($A23="","",IFERROR(INDEX(計算用!$G$2:$G$149,MATCH(計算用!$U$3&4&"-"&$A23,計算用!$K$2:$K$149,0)),"")) | K23: =IF(19<=計算用!$U$10,19,"") | L23: =IF($K23="","",IFERROR(INDEX(計算用!$D$2:$D$149,MATCH("女"&1&"-"&$K23,計算用!$K$2:$K$149,0)),"")) | M23: =IF($K23="","",IFERROR(INDEX(計算用!$G$2:$G$149,MATCH("女"&1&"-"&$K23,計算用!$K$2:$K$149,0)),"")) | N23: =IF($K23="","",IFERROR(INDEX(計算用!$D$2:$D$149,MATCH("女"&2&"-"&$K23,計算用!$K$2:$K$149,0)),"")) | O23: =IF($K23="","",IFERROR(INDEX(計算用!$G$2:$G$149,MATCH("女"&2&"-"&$K23,計算用!$K$2:$K$149,0)),"")) | P23: =IF($K23="","",IFERROR(INDEX(計算用!$D$2:$D$149,MATCH("女"&3&"-"&$K23,計算用!$K$2:$K$149,0)),"")) | Q23: =IF($K23="","",IFERROR(INDEX(計算用!$G$2:$G$149,MATCH("女"&3&"-"&$K23,計算用!$K$2:$K$149,0)),"")) | R23: =IF($K23="","",IFERROR(INDEX(計算用!$D$2:$D$149,MATCH("女"&4&"-"&$K23,計算用!$K$2:$K$149,0)),"")) | S23: =IF($K23="","",IFERROR(INDEX(計算用!$G$2:$G$149,MATCH("女"&4&"-"&$K23,計算用!$K$2:$K$149,0)),""))
A24: =IF(20<=計算用!$U$9,20,"") | B24: =IF($A24="","",IFERROR(INDEX(計算用!$D$2:$D$149,MATCH(計算用!$U$3&1&"-"&$A24,計算用!$K$2:$K$149,0)),"")) | C24: =IF($A24="","",IFERROR(INDEX(計算用!$G$2:$G$149,MATCH(計算用!$U$3&1&"-"&$A24,計算用!$K$2:$K$149,0)),"")) | D24: =IF($A24="","",IFERROR(INDEX(計算用!$D$2:$D$149,MATCH(計算用!$U$3&2&"-"&$A24,計算用!$K$2:$K$149,0)),"")) | E24: =IF($A24="","",IFERROR(INDEX(計算用!$G$2:$G$149,MATCH(計算用!$U$3&2&"-"&$A24,計算用!$K$2:$K$149,0)),"")) | F24: =IF($A24="","",IFERROR(INDEX(計算用!$D$2:$D$149,MATCH(計算用!$U$3&3&"-"&$A24,計算用!$K$2:$K$149,0)),"")) | G24: =IF($A24="","",IFERROR(INDEX(計算用!$G$2:$G$149,MATCH(計算用!$U$3&3&"-"&$A24,計算用!$K$2:$K$149,0)),"")) | H24: =IF($A24="","",IFERROR(INDEX(計算用!$D$2:$D$149,MATCH(計算用!$U$3&4&"-"&$A24,計算用!$K$2:$K$149,0)),"")) | I24: =IF($A24="","",IFERROR(INDEX(計算用!$G$2:$G$149,MATCH(計算用!$U$3&4&"-"&$A24,計算用!$K$2:$K$149,0)),"")) | K24: =IF(20<=計算用!$U$10,20,"") | L24: =IF($K24="","",IFERROR(INDEX(計算用!$D$2:$D$149,MATCH("女"&1&"-"&$K24,計算用!$K$2:$K$149,0)),"")) | M24: =IF($K24="","",IFERROR(INDEX(計算用!$G$2:$G$149,MATCH("女"&1&"-"&$K24,計算用!$K$2:$K$149,0)),"")) | N24: =IF($K24="","",IFERROR(INDEX(計算用!$D$2:$D$149,MATCH("女"&2&"-"&$K24,計算用!$K$2:$K$149,0)),"")) | O24: =IF($K24="","",IFERROR(INDEX(計算用!$G$2:$G$149,MATCH("女"&2&"-"&$K24,計算用!$K$2:$K$149,0)),"")) | P24: =IF($K24="","",IFERROR(INDEX(計算用!$D$2:$D$149,MATCH("女"&3&"-"&$K24,計算用!$K$2:$K$149,0)),"")) | Q24: =IF($K24="","",IFERROR(INDEX(計算用!$G$2:$G$149,MATCH("女"&3&"-"&$K24,計算用!$K$2:$K$149,0)),"")) | R24: =IF($K24="","",IFERROR(INDEX(計算用!$D$2:$D$149,MATCH("女"&4&"-"&$K24,計算用!$K$2:$K$149,0)),"")) | S24: =IF($K24="","",IFERROR(INDEX(計算用!$G$2:$G$149,MATCH("女"&4&"-"&$K24,計算用!$K$2:$K$149,0)),""))
A25: =IF(21<=計算用!$U$9,21,"") | B25: =IF($A25="","",IFERROR(INDEX(計算用!$D$2:$D$149,MATCH(計算用!$U$3&1&"-"&$A25,計算用!$K$2:$K$149,0)),"")) | C25: =IF($A25="","",IFERROR(INDEX(計算用!$G$2:$G$149,MATCH(計算用!$U$3&1&"-"&$A25,計算用!$K$2:$K$149,0)),"")) | D25: =IF($A25="","",IFERROR(INDEX(計算用!$D$2:$D$149,MATCH(計算用!$U$3&2&"-"&$A25,計算用!$K$2:$K$149,0)),"")) | E25: =IF($A25="","",IFERROR(INDEX(計算用!$G$2:$G$149,MATCH(計算用!$U$3&2&"-"&$A25,計算用!$K$2:$K$149,0)),"")) | F25: =IF($A25="","",IFERROR(INDEX(計算用!$D$2:$D$149,MATCH(計算用!$U$3&3&"-"&$A25,計算用!$K$2:$K$149,0)),"")) | G25: =IF($A25="","",IFERROR(INDEX(計算用!$G$2:$G$149,MATCH(計算用!$U$3&3&"-"&$A25,計算用!$K$2:$K$149,0)),"")) | H25: =IF($A25="","",IFERROR(INDEX(計算用!$D$2:$D$149,MATCH(計算用!$U$3&4&"-"&$A25,計算用!$K$2:$K$149,0)),"")) | I25: =IF($A25="","",IFERROR(INDEX(計算用!$G$2:$G$149,MATCH(計算用!$U$3&4&"-"&$A25,計算用!$K$2:$K$149,0)),"")) | K25: =IF(21<=計算用!$U$10,21,"") | L25: =IF($K25="","",IFERROR(INDEX(計算用!$D$2:$D$149,MATCH("女"&1&"-"&$K25,計算用!$K$2:$K$149,0)),"")) | M25: =IF($K25="","",IFERROR(INDEX(計算用!$G$2:$G$149,MATCH("女"&1&"-"&$K25,計算用!$K$2:$K$149,0)),"")) | N25: =IF($K25="","",IFERROR(INDEX(計算用!$D$2:$D$149,MATCH("女"&2&"-"&$K25,計算用!$K$2:$K$149,0)),"")) | O25: =IF($K25="","",IFERROR(INDEX(計算用!$G$2:$G$149,MATCH("女"&2&"-"&$K25,計算用!$K$2:$K$149,0)),"")) | P25: =IF($K25="","",IFERROR(INDEX(計算用!$D$2:$D$149,MATCH("女"&3&"-"&$K25,計算用!$K$2:$K$149,0)),"")) | Q25: =IF($K25="","",IFERROR(INDEX(計算用!$G$2:$G$149,MATCH("女"&3&"-"&$K25,計算用!$K$2:$K$149,0)),"")) | R25: =IF($K25="","",IFERROR(INDEX(計算用!$D$2:$D$149,MATCH("女"&4&"-"&$K25,計算用!$K$2:$K$149,0)),"")) | S25: =IF($K25="","",IFERROR(INDEX(計算用!$G$2:$G$149,MATCH("女"&4&"-"&$K25,計算用!$K$2:$K$149,0)),""))
A26: =IF(22<=計算用!$U$9,22,"") | B26: =IF($A26="","",IFERROR(INDEX(計算用!$D$2:$D$149,MATCH(計算用!$U$3&1&"-"&$A26,計算用!$K$2:$K$149,0)),"")) | C26: =IF($A26="","",IFERROR(INDEX(計算用!$G$2:$G$149,MATCH(計算用!$U$3&1&"-"&$A26,計算用!$K$2:$K$149,0)),"")) | D26: =IF($A26="","",IFERROR(INDEX(計算用!$D$2:$D$149,MATCH(計算用!$U$3&2&"-"&$A26,計算用!$K$2:$K$149,0)),"")) | E26: =IF($A26="","",IFERROR(INDEX(計算用!$G$2:$G$149,MATCH(計算用!$U$3&2&"-"&$A26,計算用!$K$2:$K$149,0)),"")) | F26: =IF($A26="","",IFERROR(INDEX(計算用!$D$2:$D$149,MATCH(計算用!$U$3&3&"-"&$A26,計算用!$K$2:$K$149,0)),"")) | G26: =IF($A26="","",IFERROR(INDEX(計算用!$G$2:$G$149,MATCH(計算用!$U$3&3&"-"&$A26,計算用!$K$2:$K$149,0)),"")) | H26: =IF($A26="","",IFERROR(INDEX(計算用!$D$2:$D$149,MATCH(計算用!$U$3&4&"-"&$A26,計算用!$K$2:$K$149,0)),"")) | I26: =IF($A26="","",IFERROR(INDEX(計算用!$G$2:$G$149,MATCH(計算用!$U$3&4&"-"&$A26,計算用!$K$2:$K$149,0)),"")) | K26: =IF(22<=計算用!$U$10,22,"") | L26: =IF($K26="","",IFERROR(INDEX(計算用!$D$2:$D$149,MATCH("女"&1&"-"&$K26,計算用!$K$2:$K$149,0)),"")) | M26: =IF($K26="","",IFERROR(INDEX(計算用!$G$2:$G$149,MATCH("女"&1&"-"&$K26,計算用!$K$2:$K$149,0)),"")) | N26: =IF($K26="","",IFERROR(INDEX(計算用!$D$2:$D$149,MATCH("女"&2&"-"&$K26,計算用!$K$2:$K$149,0)),"")) | O26: =IF($K26="","",IFERROR(INDEX(計算用!$G$2:$G$149,MATCH("女"&2&"-"&$K26,計算用!$K$2:$K$149,0)),"")) | P26: =IF($K26="","",IFERROR(INDEX(計算用!$D$2:$D$149,MATCH("女"&3&"-"&$K26,計算用!$K$2:$K$149,0)),"")) | Q26: =IF($K26="","",IFERROR(INDEX(計算用!$G$2:$G$149,MATCH("女"&3&"-"&$K26,計算用!$K$2:$K$149,0)),"")) | R26: =IF($K26="","",IFERROR(INDEX(計算用!$D$2:$D$149,MATCH("女"&4&"-"&$K26,計算用!$K$2:$K$149,0)),"")) | S26: =IF($K26="","",IFERROR(INDEX(計算用!$G$2:$G$149,MATCH("女"&4&"-"&$K26,計算用!$K$2:$K$149,0)),""))
A27: =IF(23<=計算用!$U$9,23,"") | B27: =IF($A27="","",IFERROR(INDEX(計算用!$D$2:$D$149,MATCH(計算用!$U$3&1&"-"&$A27,計算用!$K$2:$K$149,0)),"")) | C27: =IF($A27="","",IFERROR(INDEX(計算用!$G$2:$G$149,MATCH(計算用!$U$3&1&"-"&$A27,計算用!$K$2:$K$149,0)),"")) | D27: =IF($A27="","",IFERROR(INDEX(計算用!$D$2:$D$149,MATCH(計算用!$U$3&2&"-"&$A27,計算用!$K$2:$K$149,0)),"")) | E27: =IF($A27="","",IFERROR(INDEX(計算用!$G$2:$G$149,MATCH(計算用!$U$3&2&"-"&$A27,計算用!$K$2:$K$149,0)),"")) | F27: =IF($A27="","",IFERROR(INDEX(計算用!$D$2:$D$149,MATCH(計算用!$U$3&3&"-"&$A27,計算用!$K$2:$K$149,0)),"")) | G27: =IF($A27="","",IFERROR(INDEX(計算用!$G$2:$G$149,MATCH(計算用!$U$3&3&"-"&$A27,計算用!$K$2:$K$149,0)),"")) | H27: =IF($A27="","",IFERROR(INDEX(計算用!$D$2:$D$149,MATCH(計算用!$U$3&4&"-"&$A27,計算用!$K$2:$K$149,0)),"")) | I27: =IF($A27="","",IFERROR(INDEX(計算用!$G$2:$G$149,MATCH(計算用!$U$3&4&"-"&$A27,計算用!$K$2:$K$149,0)),"")) | K27: =IF(23<=計算用!$U$10,23,"") | L27: =IF($K27="","",IFERROR(INDEX(計算用!$D$2:$D$149,MATCH("女"&1&"-"&$K27,計算用!$K$2:$K$149,0)),"")) | M27: =IF($K27="","",IFERROR(INDEX(計算用!$G$2:$G$149,MATCH("女"&1&"-"&$K27,計算用!$K$2:$K$149,0)),"")) | N27: =IF($K27="","",IFERROR(INDEX(計算用!$D$2:$D$149,MATCH("女"&2&"-"&$K27,計算用!$K$2:$K$149,0)),"")) | O27: =IF($K27="","",IFERROR(INDEX(計算用!$G$2:$G$149,MATCH("女"&2&"-"&$K27,計算用!$K$2:$K$149,0)),"")) | P27: =IF($K27="","",IFERROR(INDEX(計算用!$D$2:$D$149,MATCH("女"&3&"-"&$K27,計算用!$K$2:$K$149,0)),"")) | Q27: =IF($K27="","",IFERROR(INDEX(計算用!$G$2:$G$149,MATCH("女"&3&"-"&$K27,計算用!$K$2:$K$149,0)),"")) | R27: =IF($K27="","",IFERROR(INDEX(計算用!$D$2:$D$149,MATCH("女"&4&"-"&$K27,計算用!$K$2:$K$149,0)),"")) | S27: =IF($K27="","",IFERROR(INDEX(計算用!$G$2:$G$149,MATCH("女"&4&"-"&$K27,計算用!$K$2:$K$149,0)),""))
A28: =IF(24<=計算用!$U$9,24,"") | B28: =IF($A28="","",IFERROR(INDEX(計算用!$D$2:$D$149,MATCH(計算用!$U$3&1&"-"&$A28,計算用!$K$2:$K$149,0)),"")) | C28: =IF($A28="","",IFERROR(INDEX(計算用!$G$2:$G$149,MATCH(計算用!$U$3&1&"-"&$A28,計算用!$K$2:$K$149,0)),"")) | D28: =IF($A28="","",IFERROR(INDEX(計算用!$D$2:$D$149,MATCH(計算用!$U$3&2&"-"&$A28,計算用!$K$2:$K$149,0)),"")) | E28: =IF($A28="","",IFERROR(INDEX(計算用!$G$2:$G$149,MATCH(計算用!$U$3&2&"-"&$A28,計算用!$K$2:$K$149,0)),"")) | F28: =IF($A28="","",IFERROR(INDEX(計算用!$D$2:$D$149,MATCH(計算用!$U$3&3&"-"&$A28,計算用!$K$2:$K$149,0)),"")) | G28: =IF($A28="","",IFERROR(INDEX(計算用!$G$2:$G$149,MATCH(計算用!$U$3&3&"-"&$A28,計算用!$K$2:$K$149,0)),"")) | H28: =IF($A28="","",IFERROR(INDEX(計算用!$D$2:$D$149,MATCH(計算用!$U$3&4&"-"&$A28,計算用!$K$2:$K$149,0)),"")) | I28: =IF($A28="","",IFERROR(INDEX(計算用!$G$2:$G$149,MATCH(計算用!$U$3&4&"-"&$A28,計算用!$K$2:$K$149,0)),"")) | K28: =IF(24<=計算用!$U$10,24,"") | L28: =IF($K28="","",IFERROR(INDEX(計算用!$D$2:$D$149,MATCH("女"&1&"-"&$K28,計算用!$K$2:$K$149,0)),"")) | M28: =IF($K28="","",IFERROR(INDEX(計算用!$G$2:$G$149,MATCH("女"&1&"-"&$K28,計算用!$K$2:$K$149,0)),"")) | N28: =IF($K28="","",IFERROR(INDEX(計算用!$D$2:$D$149,MATCH("女"&2&"-"&$K28,計算用!$K$2:$K$149,0)),"")) | O28: =IF($K28="","",IFERROR(INDEX(計算用!$G$2:$G$149,MATCH("女"&2&"-"&$K28,計算用!$K$2:$K$149,0)),"")) | P28: =IF($K28="","",IFERROR(INDEX(計算用!$D$2:$D$149,MATCH("女"&3&"-"&$K28,計算用!$K$2:$K$149,0)),"")) | Q28: =IF($K28="","",IFERROR(INDEX(計算用!$G$2:$G$149,MATCH("女"&3&"-"&$K28,計算用!$K$2:$K$149,0)),"")) | R28: =IF($K28="","",IFERROR(INDEX(計算用!$D$2:$D$149,MATCH("女"&4&"-"&$K28,計算用!$K$2:$K$149,0)),"")) | S28: =IF($K28="","",IFERROR(INDEX(計算用!$G$2:$G$149,MATCH("女"&4&"-"&$K28,計算用!$K$2:$K$149,0)),""))
A29: =IF(25<=計算用!$U$9,25,"") | B29: =IF($A29="","",IFERROR(INDEX(計算用!$D$2:$D$149,MATCH(計算用!$U$3&1&"-"&$A29,計算用!$K$2:$K$149,0)),"")) | C29: =IF($A29="","",IFERROR(INDEX(計算用!$G$2:$G$149,MATCH(計算用!$U$3&1&"-"&$A29,計算用!$K$2:$K$149,0)),"")) | D29: =IF($A29="","",IFERROR(INDEX(計算用!$D$2:$D$149,MATCH(計算用!$U$3&2&"-"&$A29,計算用!$K$2:$K$149,0)),"")) | E29: =IF($A29="","",IFERROR(INDEX(計算用!$G$2:$G$149,MATCH(計算用!$U$3&2&"-"&$A29,計算用!$K$2:$K$149,0)),"")) | F29: =IF($A29="","",IFERROR(INDEX(計算用!$D$2:$D$149,MATCH(計算用!$U$3&3&"-"&$A29,計算用!$K$2:$K$149,0)),"")) | G29: =IF($A29="","",IFERROR(INDEX(計算用!$G$2:$G$149,MATCH(計算用!$U$3&3&"-"&$A29,計算用!$K$2:$K$149,0)),"")) | H29: =IF($A29="","",IFERROR(INDEX(計算用!$D$2:$D$149,MATCH(計算用!$U$3&4&"-"&$A29,計算用!$K$2:$K$149,0)),"")) | I29: =IF($A29="","",IFERROR(INDEX(計算用!$G$2:$G$149,MATCH(計算用!$U$3&4&"-"&$A29,計算用!$K$2:$K$149,0)),"")) | K29: =IF(25<=計算用!$U$10,25,"") | L29: =IF($K29="","",IFERROR(INDEX(計算用!$D$2:$D$149,MATCH("女"&1&"-"&$K29,計算用!$K$2:$K$149,0)),"")) | M29: =IF($K29="","",IFERROR(INDEX(計算用!$G$2:$G$149,MATCH("女"&1&"-"&$K29,計算用!$K$2:$K$149,0)),"")) | N29: =IF($K29="","",IFERROR(INDEX(計算用!$D$2:$D$149,MATCH("女"&2&"-"&$K29,計算用!$K$2:$K$149,0)),"")) | O29: =IF($K29="","",IFERROR(INDEX(計算用!$G$2:$G$149,MATCH("女"&2&"-"&$K29,計算用!$K$2:$K$149,0)),"")) | P29: =IF($K29="","",IFERROR(INDEX(計算用!$D$2:$D$149,MATCH("女"&3&"-"&$K29,計算用!$K$2:$K$149,0)),"")) | Q29: =IF($K29="","",IFERROR(INDEX(計算用!$G$2:$G$149,MATCH("女"&3&"-"&$K29,計算用!$K$2:$K$149,0)),"")) | R29: =IF($K29="","",IFERROR(INDEX(計算用!$D$2:$D$149,MATCH("女"&4&"-"&$K29,計算用!$K$2:$K$149,0)),"")) | S29: =IF($K29="","",IFERROR(INDEX(計算用!$G$2:$G$149,MATCH("女"&4&"-"&$K29,計算用!$K$2:$K$149,0)),""))
A30: =IF(26<=計算用!$U$9,26,"") | B30: =IF($A30="","",IFERROR(INDEX(計算用!$D$2:$D$149,MATCH(計算用!$U$3&1&"-"&$A30,計算用!$K$2:$K$149,0)),"")) | C30: =IF($A30="","",IFERROR(INDEX(計算用!$G$2:$G$149,MATCH(計算用!$U$3&1&"-"&$A30,計算用!$K$2:$K$149,0)),"")) | D30: =IF($A30="","",IFERROR(INDEX(計算用!$D$2:$D$149,MATCH(計算用!$U$3&2&"-"&$A30,計算用!$K$2:$K$149,0)),"")) | E30: =IF($A30="","",IFERROR(INDEX(計算用!$G$2:$G$149,MATCH(計算用!$U$3&2&"-"&$A30,計算用!$K$2:$K$149,0)),"")) | F30: =IF($A30="","",IFERROR(INDEX(計算用!$D$2:$D$149,MATCH(計算用!$U$3&3&"-"&$A30,計算用!$K$2:$K$149,0)),"")) | G30: =IF($A30="","",IFERROR(INDEX(計算用!$G$2:$G$149,MATCH(計算用!$U$3&3&"-"&$A30,計算用!$K$2:$K$149,0)),"")) | H30: =IF($A30="","",IFERROR(INDEX(計算用!$D$2:$D$149,MATCH(計算用!$U$3&4&"-"&$A30,計算用!$K$2:$K$149,0)),"")) | I30: =IF($A30="","",IFERROR(INDEX(計算用!$G$2:$G$149,MATCH(計算用!$U$3&4&"-"&$A30,計算用!$K$2:$K$149,0)),"")) | K30: =IF(26<=計算用!$U$10,26,"") | L30: =IF($K30="","",IFERROR(INDEX(計算用!$D$2:$D$149,MATCH("女"&1&"-"&$K30,計算用!$K$2:$K$149,0)),"")) | M30: =IF($K30="","",IFERROR(INDEX(計算用!$G$2:$G$149,MATCH("女"&1&"-"&$K30,計算用!$K$2:$K$149,0)),"")) | N30: =IF($K30="","",IFERROR(INDEX(計算用!$D$2:$D$149,MATCH("女"&2&"-"&$K30,計算用!$K$2:$K$149,0)),"")) | O30: =IF($K30="","",IFERROR(INDEX(計算用!$G$2:$G$149,MATCH("女"&2&"-"&$K30,計算用!$K$2:$K$149,0)),"")) | P30: =IF($K30="","",IFERROR(INDEX(計算用!$D$2:$D$149,MATCH("女"&3&"-"&$K30,計算用!$K$2:$K$149,0)),"")) | Q30: =IF($K30="","",IFERROR(INDEX(計算用!$G$2:$G$149,MATCH("女"&3&"-"&$K30,計算用!$K$2:$K$149,0)),"")) | R30: =IF($K30="","",IFERROR(INDEX(計算用!$D$2:$D$149,MATCH("女"&4&"-"&$K30,計算用!$K$2:$K$149,0)),"")) | S30: =IF($K30="","",IFERROR(INDEX(計算用!$G$2:$G$149,MATCH("女"&4&"-"&$K30,計算用!$K$2:$K$149,0)),""))
A31: =IF(27<=計算用!$U$9,27,"") | B31: =IF($A31="","",IFERROR(INDEX(計算用!$D$2:$D$149,MATCH(計算用!$U$3&1&"-"&$A31,計算用!$K$2:$K$149,0)),"")) | C31: =IF($A31="","",IFERROR(INDEX(計算用!$G$2:$G$149,MATCH(計算用!$U$3&1&"-"&$A31,計算用!$K$2:$K$149,0)),"")) | D31: =IF($A31="","",IFERROR(INDEX(計算用!$D$2:$D$149,MATCH(計算用!$U$3&2&"-"&$A31,計算用!$K$2:$K$149,0)),"")) | E31: =IF($A31="","",IFERROR(INDEX(計算用!$G$2:$G$149,MATCH(計算用!$U$3&2&"-"&$A31,計算用!$K$2:$K$149,0)),"")) | F31: =IF($A31="","",IFERROR(INDEX(計算用!$D$2:$D$149,MATCH(計算用!$U$3&3&"-"&$A31,計算用!$K$2:$K$149,0)),"")) | G31: =IF($A31="","",IFERROR(INDEX(計算用!$G$2:$G$149,MATCH(計算用!$U$3&3&"-"&$A31,計算用!$K$2:$K$149,0)),"")) | H31: =IF($A31="","",IFERROR(INDEX(計算用!$D$2:$D$149,MATCH(計算用!$U$3&4&"-"&$A31,計算用!$K$2:$K$149,0)),"")) | I31: =IF($A31="","",IFERROR(INDEX(計算用!$G$2:$G$149,MATCH(計算用!$U$3&4&"-"&$A31,計算用!$K$2:$K$149,0)),"")) | K31: =IF(27<=計算用!$U$10,27,"") | L31: =IF($K31="","",IFERROR(INDEX(計算用!$D$2:$D$149,MATCH("女"&1&"-"&$K31,計算用!$K$2:$K$149,0)),"")) | M31: =IF($K31="","",IFERROR(INDEX(計算用!$G$2:$G$149,MATCH("女"&1&"-"&$K31,計算用!$K$2:$K$149,0)),"")) | N31: =IF($K31="","",IFERROR(INDEX(計算用!$D$2:$D$149,MATCH("女"&2&"-"&$K31,計算用!$K$2:$K$149,0)),"")) | O31: =IF($K31="","",IFERROR(INDEX(計算用!$G$2:$G$149,MATCH("女"&2&"-"&$K31,計算用!$K$2:$K$149,0)),"")) | P31: =IF($K31="","",IFERROR(INDEX(計算用!$D$2:$D$149,MATCH("女"&3&"-"&$K31,計算用!$K$2:$K$149,0)),"")) | Q31: =IF($K31="","",IFERROR(INDEX(計算用!$G$2:$G$149,MATCH("女"&3&"-"&$K31,計算用!$K$2:$K$149,0)),"")) | R31: =IF($K31="","",IFERROR(INDEX(計算用!$D$2:$D$149,MATCH("女"&4&"-"&$K31,計算用!$K$2:$K$149,0)),"")) | S31: =IF($K31="","",IFERROR(INDEX(計算用!$G$2:$G$149,MATCH("女"&4&"-"&$K31,計算用!$K$2:$K$149,0)),""))
A32: =IF(28<=計算用!$U$9,28,"") | B32: =IF($A32="","",IFERROR(INDEX(計算用!$D$2:$D$149,MATCH(計算用!$U$3&1&"-"&$A32,計算用!$K$2:$K$149,0)),"")) | C32: =IF($A32="","",IFERROR(INDEX(計算用!$G$2:$G$149,MATCH(計算用!$U$3&1&"-"&$A32,計算用!$K$2:$K$149,0)),"")) | D32: =IF($A32="","",IFERROR(INDEX(計算用!$D$2:$D$149,MATCH(計算用!$U$3&2&"-"&$A32,計算用!$K$2:$K$149,0)),"")) | E32: =IF($A32="","",IFERROR(INDEX(計算用!$G$2:$G$149,MATCH(計算用!$U$3&2&"-"&$A32,計算用!$K$2:$K$149,0)),"")) | F32: =IF($A32="","",IFERROR(INDEX(計算用!$D$2:$D$149,MATCH(計算用!$U$3&3&"-"&$A32,計算用!$K$2:$K$149,0)),"")) | G32: =IF($A32="","",IFERROR(INDEX(計算用!$G$2:$G$149,MATCH(計算用!$U$3&3&"-"&$A32,計算用!$K$2:$K$149,0)),"")) | H32: =IF($A32="","",IFERROR(INDEX(計算用!$D$2:$D$149,MATCH(計算用!$U$3&4&"-"&$A32,計算用!$K$2:$K$149,0)),"")) | I32: =IF($A32="","",IFERROR(INDEX(計算用!$G$2:$G$149,MATCH(計算用!$U$3&4&"-"&$A32,計算用!$K$2:$K$149,0)),"")) | K32: =IF(28<=計算用!$U$10,28,"") | L32: =IF($K32="","",IFERROR(INDEX(計算用!$D$2:$D$149,MATCH("女"&1&"-"&$K32,計算用!$K$2:$K$149,0)),"")) | M32: =IF($K32="","",IFERROR(INDEX(計算用!$G$2:$G$149,MATCH("女"&1&"-"&$K32,計算用!$K$2:$K$149,0)),"")) | N32: =IF($K32="","",IFERROR(INDEX(計算用!$D$2:$D$149,MATCH("女"&2&"-"&$K32,計算用!$K$2:$K$149,0)),"")) | O32: =IF($K32="","",IFERROR(INDEX(計算用!$G$2:$G$149,MATCH("女"&2&"-"&$K32,計算用!$K$2:$K$149,0)),"")) | P32: =IF($K32="","",IFERROR(INDEX(計算用!$D$2:$D$149,MATCH("女"&3&"-"&$K32,計算用!$K$2:$K$149,0)),"")) | Q32: =IF($K32="","",IFERROR(INDEX(計算用!$G$2:$G$149,MATCH("女"&3&"-"&$K32,計算用!$K$2:$K$149,0)),"")) | R32: =IF($K32="","",IFERROR(INDEX(計算用!$D$2:$D$149,MATCH("女"&4&"-"&$K32,計算用!$K$2:$K$149,0)),"")) | S32: =IF($K32="","",IFERROR(INDEX(計算用!$G$2:$G$149,MATCH("女"&4&"-"&$K32,計算用!$K$2:$K$149,0)),""))
A33: =IF(29<=計算用!$U$9,29,"") | B33: =IF($A33="","",IFERROR(INDEX(計算用!$D$2:$D$149,MATCH(計算用!$U$3&1&"-"&$A33,計算用!$K$2:$K$149,0)),"")) | C33: =IF($A33="","",IFERROR(INDEX(計算用!$G$2:$G$149,MATCH(計算用!$U$3&1&"-"&$A33,計算用!$K$2:$K$149,0)),"")) | D33: =IF($A33="","",IFERROR(INDEX(計算用!$D$2:$D$149,MATCH(計算用!$U$3&2&"-"&$A33,計算用!$K$2:$K$149,0)),"")) | E33: =IF($A33="","",IFERROR(INDEX(計算用!$G$2:$G$149,MATCH(計算用!$U$3&2&"-"&$A33,計算用!$K$2:$K$149,0)),"")) | F33: =IF($A33="","",IFERROR(INDEX(計算用!$D$2:$D$149,MATCH(計算用!$U$3&3&"-"&$A33,計算用!$K$2:$K$149,0)),"")) | G33: =IF($A33="","",IFERROR(INDEX(計算用!$G$2:$G$149,MATCH(計算用!$U$3&3&"-"&$A33,計算用!$K$2:$K$149,0)),"")) | H33: =IF($A33="","",IFERROR(INDEX(計算用!$D$2:$D$149,MATCH(計算用!$U$3&4&"-"&$A33,計算用!$K$2:$K$149,0)),"")) | I33: =IF($A33="","",IFERROR(INDEX(計算用!$G$2:$G$149,MATCH(計算用!$U$3&4&"-"&$A33,計算用!$K$2:$K$149,0)),"")) | K33: =IF(29<=計算用!$U$10,29,"") | L33: =IF($K33="","",IFERROR(INDEX(計算用!$D$2:$D$149,MATCH("女"&1&"-"&$K33,計算用!$K$2:$K$149,0)),"")) | M33: =IF($K33="","",IFERROR(INDEX(計算用!$G$2:$G$149,MATCH("女"&1&"-"&$K33,計算用!$K$2:$K$149,0)),"")) | N33: =IF($K33="","",IFERROR(INDEX(計算用!$D$2:$D$149,MATCH("女"&2&"-"&$K33,計算用!$K$2:$K$149,0)),"")) | O33: =IF($K33="","",IFERROR(INDEX(計算用!$G$2:$G$149,MATCH("女"&2&"-"&$K33,計算用!$K$2:$K$149,0)),"")) | P33: =IF($K33="","",IFERROR(INDEX(計算用!$D$2:$D$149,MATCH("女"&3&"-"&$K33,計算用!$K$2:$K$149,0)),"")) | Q33: =IF($K33="","",IFERROR(INDEX(計算用!$G$2:$G$149,MATCH("女"&3&"-"&$K33,計算用!$K$2:$K$149,0)),"")) | R33: =IF($K33="","",IFERROR(INDEX(計算用!$D$2:$D$149,MATCH("女"&4&"-"&$K33,計算用!$K$2:$K$149,0)),"")) | S33: =IF($K33="","",IFERROR(INDEX(計算用!$G$2:$G$149,MATCH("女"&4&"-"&$K33,計算用!$K$2:$K$149,0)),""))
A34: =IF(30<=計算用!$U$9,30,"") | B34: =IF($A34="","",IFERROR(INDEX(計算用!$D$2:$D$149,MATCH(計算用!$U$3&1&"-"&$A34,計算用!$K$2:$K$149,0)),"")) | C34: =IF($A34="","",IFERROR(INDEX(計算用!$G$2:$G$149,MATCH(計算用!$U$3&1&"-"&$A34,計算用!$K$2:$K$149,0)),"")) | D34: =IF($A34="","",IFERROR(INDEX(計算用!$D$2:$D$149,MATCH(計算用!$U$3&2&"-"&$A34,計算用!$K$2:$K$149,0)),"")) | E34: =IF($A34="","",IFERROR(INDEX(計算用!$G$2:$G$149,MATCH(計算用!$U$3&2&"-"&$A34,計算用!$K$2:$K$149,0)),"")) | F34: =IF($A34="","",IFERROR(INDEX(計算用!$D$2:$D$149,MATCH(計算用!$U$3&3&"-"&$A34,計算用!$K$2:$K$149,0)),"")) | G34: =IF($A34="","",IFERROR(INDEX(計算用!$G$2:$G$149,MATCH(計算用!$U$3&3&"-"&$A34,計算用!$K$2:$K$149,0)),"")) | H34: =IF($A34="","",IFERROR(INDEX(計算用!$D$2:$D$149,MATCH(計算用!$U$3&4&"-"&$A34,計算用!$K$2:$K$149,0)),"")) | I34: =IF($A34="","",IFERROR(INDEX(計算用!$G$2:$G$149,MATCH(計算用!$U$3&4&"-"&$A34,計算用!$K$2:$K$149,0)),"")) | K34: =IF(30<=計算用!$U$10,30,"") | L34: =IF($K34="","",IFERROR(INDEX(計算用!$D$2:$D$149,MATCH("女"&1&"-"&$K34,計算用!$K$2:$K$149,0)),"")) | M34: =IF($K34="","",IFERROR(INDEX(計算用!$G$2:$G$149,MATCH("女"&1&"-"&$K34,計算用!$K$2:$K$149,0)),"")) | N34: =IF($K34="","",IFERROR(INDEX(計算用!$D$2:$D$149,MATCH("女"&2&"-"&$K34,計算用!$K$2:$K$149,0)),"")) | O34: =IF($K34="","",IFERROR(INDEX(計算用!$G$2:$G$149,MATCH("女"&2&"-"&$K34,計算用!$K$2:$K$149,0)),"")) | P34: =IF($K34="","",IFERROR(INDEX(計算用!$D$2:$D$149,MATCH("女"&3&"-"&$K34,計算用!$K$2:$K$149,0)),"")) | Q34: =IF($K34="","",IFERROR(INDEX(計算用!$G$2:$G$149,MATCH("女"&3&"-"&$K34,計算用!$K$2:$K$149,0)),"")) | R34: =IF($K34="","",IFERROR(INDEX(計算用!$D$2:$D$149,MATCH("女"&4&"-"&$K34,計算用!$K$2:$K$149,0)),"")) | S34: =IF($K34="","",IFERROR(INDEX(計算用!$G$2:$G$149,MATCH("女"&4&"-"&$K34,計算用!$K$2:$K$149,0)),""))
A35: =IF(31<=計算用!$U$9,31,"") | B35: =IF($A35="","",IFERROR(INDEX(計算用!$D$2:$D$149,MATCH(計算用!$U$3&1&"-"&$A35,計算用!$K$2:$K$149,0)),"")) | C35: =IF($A35="","",IFERROR(INDEX(計算用!$G$2:$G$149,MATCH(計算用!$U$3&1&"-"&$A35,計算用!$K$2:$K$149,0)),"")) | D35: =IF($A35="","",IFERROR(INDEX(計算用!$D$2:$D$149,MATCH(計算用!$U$3&2&"-"&$A35,計算用!$K$2:$K$149,0)),"")) | E35: =IF($A35="","",IFERROR(INDEX(計算用!$G$2:$G$149,MATCH(計算用!$U$3&2&"-"&$A35,計算用!$K$2:$K$149,0)),"")) | F35: =IF($A35="","",IFERROR(INDEX(計算用!$D$2:$D$149,MATCH(計算用!$U$3&3&"-"&$A35,計算用!$K$2:$K$149,0)),"")) | G35: =IF($A35="","",IFERROR(INDEX(計算用!$G$2:$G$149,MATCH(計算用!$U$3&3&"-"&$A35,計算用!$K$2:$K$149,0)),"")) | H35: =IF($A35="","",IFERROR(INDEX(計算用!$D$2:$D$149,MATCH(計算用!$U$3&4&"-"&$A35,計算用!$K$2:$K$149,0)),"")) | I35: =IF($A35="","",IFERROR(INDEX(計算用!$G$2:$G$149,MATCH(計算用!$U$3&4&"-"&$A35,計算用!$K$2:$K$149,0)),"")) | K35: =IF(31<=計算用!$U$10,31,"") | L35: =IF($K35="","",IFERROR(INDEX(計算用!$D$2:$D$149,MATCH("女"&1&"-"&$K35,計算用!$K$2:$K$149,0)),"")) | M35: =IF($K35="","",IFERROR(INDEX(計算用!$G$2:$G$149,MATCH("女"&1&"-"&$K35,計算用!$K$2:$K$149,0)),"")) | N35: =IF($K35="","",IFERROR(INDEX(計算用!$D$2:$D$149,MATCH("女"&2&"-"&$K35,計算用!$K$2:$K$149,0)),"")) | O35: =IF($K35="","",IFERROR(INDEX(計算用!$G$2:$G$149,MATCH("女"&2&"-"&$K35,計算用!$K$2:$K$149,0)),"")) | P35: =IF($K35="","",IFERROR(INDEX(計算用!$D$2:$D$149,MATCH("女"&3&"-"&$K35,計算用!$K$2:$K$149,0)),"")) | Q35: =IF($K35="","",IFERROR(INDEX(計算用!$G$2:$G$149,MATCH("女"&3&"-"&$K35,計算用!$K$2:$K$149,0)),"")) | R35: =IF($K35="","",IFERROR(INDEX(計算用!$D$2:$D$149,MATCH("女"&4&"-"&$K35,計算用!$K$2:$K$149,0)),"")) | S35: =IF($K35="","",IFERROR(INDEX(計算用!$G$2:$G$149,MATCH("女"&4&"-"&$K35,計算用!$K$2:$K$149,0)),""))
A36: =IF(32<=計算用!$U$9,32,"") | B36: =IF($A36="","",IFERROR(INDEX(計算用!$D$2:$D$149,MATCH(計算用!$U$3&1&"-"&$A36,計算用!$K$2:$K$149,0)),"")) | C36: =IF($A36="","",IFERROR(INDEX(計算用!$G$2:$G$149,MATCH(計算用!$U$3&1&"-"&$A36,計算用!$K$2:$K$149,0)),"")) | D36: =IF($A36="","",IFERROR(INDEX(計算用!$D$2:$D$149,MATCH(計算用!$U$3&2&"-"&$A36,計算用!$K$2:$K$149,0)),"")) | E36: =IF($A36="","",IFERROR(INDEX(計算用!$G$2:$G$149,MATCH(計算用!$U$3&2&"-"&$A36,計算用!$K$2:$K$149,0)),"")) | F36: =IF($A36="","",IFERROR(INDEX(計算用!$D$2:$D$149,MATCH(計算用!$U$3&3&"-"&$A36,計算用!$K$2:$K$149,0)),"")) | G36: =IF($A36="","",IFERROR(INDEX(計算用!$G$2:$G$149,MATCH(計算用!$U$3&3&"-"&$A36,計算用!$K$2:$K$149,0)),"")) | H36: =IF($A36="","",IFERROR(INDEX(計算用!$D$2:$D$149,MATCH(計算用!$U$3&4&"-"&$A36,計算用!$K$2:$K$149,0)),"")) | I36: =IF($A36="","",IFERROR(INDEX(計算用!$G$2:$G$149,MATCH(計算用!$U$3&4&"-"&$A36,計算用!$K$2:$K$149,0)),"")) | K36: =IF(32<=計算用!$U$10,32,"") | L36: =IF($K36="","",IFERROR(INDEX(計算用!$D$2:$D$149,MATCH("女"&1&"-"&$K36,計算用!$K$2:$K$149,0)),"")) | M36: =IF($K36="","",IFERROR(INDEX(計算用!$G$2:$G$149,MATCH("女"&1&"-"&$K36,計算用!$K$2:$K$149,0)),"")) | N36: =IF($K36="","",IFERROR(INDEX(計算用!$D$2:$D$149,MATCH("女"&2&"-"&$K36,計算用!$K$2:$K$149,0)),"")) | O36: =IF($K36="","",IFERROR(INDEX(計算用!$G$2:$G$149,MATCH("女"&2&"-"&$K36,計算用!$K$2:$K$149,0)),"")) | P36: =IF($K36="","",IFERROR(INDEX(計算用!$D$2:$D$149,MATCH("女"&3&"-"&$K36,計算用!$K$2:$K$149,0)),"")) | Q36: =IF($K36="","",IFERROR(INDEX(計算用!$G$2:$G$149,MATCH("女"&3&"-"&$K36,計算用!$K$2:$K$149,0)),"")) | R36: =IF($K36="","",IFERROR(INDEX(計算用!$D$2:$D$149,MATCH("女"&4&"-"&$K36,計算用!$K$2:$K$149,0)),"")) | S36: =IF($K36="","",IFERROR(INDEX(計算用!$G$2:$G$149,MATCH("女"&4&"-"&$K36,計算用!$K$2:$K$149,0)),""))
A37: =IF(33<=計算用!$U$9,33,"") | B37: =IF($A37="","",IFERROR(INDEX(計算用!$D$2:$D$149,MATCH(計算用!$U$3&1&"-"&$A37,計算用!$K$2:$K$149,0)),"")) | C37: =IF($A37="","",IFERROR(INDEX(計算用!$G$2:$G$149,MATCH(計算用!$U$3&1&"-"&$A37,計算用!$K$2:$K$149,0)),"")) | D37: =IF($A37="","",IFERROR(INDEX(計算用!$D$2:$D$149,MATCH(計算用!$U$3&2&"-"&$A37,計算用!$K$2:$K$149,0)),"")) | E37: =IF($A37="","",IFERROR(INDEX(計算用!$G$2:$G$149,MATCH(計算用!$U$3&2&"-"&$A37,計算用!$K$2:$K$149,0)),"")) | F37: =IF($A37="","",IFERROR(INDEX(計算用!$D$2:$D$149,MATCH(計算用!$U$3&3&"-"&$A37,計算用!$K$2:$K$149,0)),"")) | G37: =IF($A37="","",IFERROR(INDEX(計算用!$G$2:$G$149,MATCH(計算用!$U$3&3&"-"&$A37,計算用!$K$2:$K$149,0)),"")) | H37: =IF($A37="","",IFERROR(INDEX(計算用!$D$2:$D$149,MATCH(計算用!$U$3&4&"-"&$A37,計算用!$K$2:$K$149,0)),"")) | I37: =IF($A37="","",IFERROR(INDEX(計算用!$G$2:$G$149,MATCH(計算用!$U$3&4&"-"&$A37,計算用!$K$2:$K$149,0)),"")) | K37: =IF(33<=計算用!$U$10,33,"") | L37: =IF($K37="","",IFERROR(INDEX(計算用!$D$2:$D$149,MATCH("女"&1&"-"&$K37,計算用!$K$2:$K$149,0)),"")) | M37: =IF($K37="","",IFERROR(INDEX(計算用!$G$2:$G$149,MATCH("女"&1&"-"&$K37,計算用!$K$2:$K$149,0)),"")) | N37: =IF($K37="","",IFERROR(INDEX(計算用!$D$2:$D$149,MATCH("女"&2&"-"&$K37,計算用!$K$2:$K$149,0)),"")) | O37: =IF($K37="","",IFERROR(INDEX(計算用!$G$2:$G$149,MATCH("女"&2&"-"&$K37,計算用!$K$2:$K$149,0)),"")) | P37: =IF($K37="","",IFERROR(INDEX(計算用!$D$2:$D$149,MATCH("女"&3&"-"&$K37,計算用!$K$2:$K$149,0)),"")) | Q37: =IF($K37="","",IFERROR(INDEX(計算用!$G$2:$G$149,MATCH("女"&3&"-"&$K37,計算用!$K$2:$K$149,0)),"")) | R37: =IF($K37="","",IFERROR(INDEX(計算用!$D$2:$D$149,MATCH("女"&4&"-"&$K37,計算用!$K$2:$K$149,0)),"")) | S37: =IF($K37="","",IFERROR(INDEX(計算用!$G$2:$G$149,MATCH("女"&4&"-"&$K37,計算用!$K$2:$K$149,0)),""))
A38: =IF(34<=計算用!$U$9,34,"") | B38: =IF($A38="","",IFERROR(INDEX(計算用!$D$2:$D$149,MATCH(計算用!$U$3&1&"-"&$A38,計算用!$K$2:$K$149,0)),"")) | C38: =IF($A38="","",IFERROR(INDEX(計算用!$G$2:$G$149,MATCH(計算用!$U$3&1&"-"&$A38,計算用!$K$2:$K$149,0)),"")) | D38: =IF($A38="","",IFERROR(INDEX(計算用!$D$2:$D$149,MATCH(計算用!$U$3&2&"-"&$A38,計算用!$K$2:$K$149,0)),"")) | E38: =IF($A38="","",IFERROR(INDEX(計算用!$G$2:$G$149,MATCH(計算用!$U$3&2&"-"&$A38,計算用!$K$2:$K$149,0)),"")) | F38: =IF($A38="","",IFERROR(INDEX(計算用!$D$2:$D$149,MATCH(計算用!$U$3&3&"-"&$A38,計算用!$K$2:$K$149,0)),"")) | G38: =IF($A38="","",IFERROR(INDEX(計算用!$G$2:$G$149,MATCH(計算用!$U$3&3&"-"&$A38,計算用!$K$2:$K$149,0)),"")) | H38: =IF($A38="","",IFERROR(INDEX(計算用!$D$2:$D$149,MATCH(計算用!$U$3&4&"-"&$A38,計算用!$K$2:$K$149,0)),"")) | I38: =IF($A38="","",IFERROR(INDEX(計算用!$G$2:$G$149,MATCH(計算用!$U$3&4&"-"&$A38,計算用!$K$2:$K$149,0)),"")) | K38: =IF(34<=計算用!$U$10,34,"") | L38: =IF($K38="","",IFERROR(INDEX(計算用!$D$2:$D$149,MATCH("女"&1&"-"&$K38,計算用!$K$2:$K$149,0)),"")) | M38: =IF($K38="","",IFERROR(INDEX(計算用!$G$2:$G$149,MATCH("女"&1&"-"&$K38,計算用!$K$2:$K$149,0)),"")) | N38: =IF($K38="","",IFERROR(INDEX(計算用!$D$2:$D$149,MATCH("女"&2&"-"&$K38,計算用!$K$2:$K$149,0)),"")) | O38: =IF($K38="","",IFERROR(INDEX(計算用!$G$2:$G$149,MATCH("女"&2&"-"&$K38,計算用!$K$2:$K$149,0)),"")) | P38: =IF($K38="","",IFERROR(INDEX(計算用!$D$2:$D$149,MATCH("女"&3&"-"&$K38,計算用!$K$2:$K$149,0)),"")) | Q38: =IF($K38="","",IFERROR(INDEX(計算用!$G$2:$G$149,MATCH("女"&3&"-"&$K38,計算用!$K$2:$K$149,0)),"")) | R38: =IF($K38="","",IFERROR(INDEX(計算用!$D$2:$D$149,MATCH("女"&4&"-"&$K38,計算用!$K$2:$K$149,0)),"")) | S38: =IF($K38="","",IFERROR(INDEX(計算用!$G$2:$G$149,MATCH("女"&4&"-"&$K38,計算用!$K$2:$K$149,0)),""))
A39: =IF(35<=計算用!$U$9,35,"") | B39: =IF($A39="","",IFERROR(INDEX(計算用!$D$2:$D$149,MATCH(計算用!$U$3&1&"-"&$A39,計算用!$K$2:$K$149,0)),"")) | C39: =IF($A39="","",IFERROR(INDEX(計算用!$G$2:$G$149,MATCH(計算用!$U$3&1&"-"&$A39,計算用!$K$2:$K$149,0)),"")) | D39: =IF($A39="","",IFERROR(INDEX(計算用!$D$2:$D$149,MATCH(計算用!$U$3&2&"-"&$A39,計算用!$K$2:$K$149,0)),"")) | E39: =IF($A39="","",IFERROR(INDEX(計算用!$G$2:$G$149,MATCH(計算用!$U$3&2&"-"&$A39,計算用!$K$2:$K$149,0)),"")) | F39: =IF($A39="","",IFERROR(INDEX(計算用!$D$2:$D$149,MATCH(計算用!$U$3&3&"-"&$A39,計算用!$K$2:$K$149,0)),"")) | G39: =IF($A39="","",IFERROR(INDEX(計算用!$G$2:$G$149,MATCH(計算用!$U$3&3&"-"&$A39,計算用!$K$2:$K$149,0)),"")) | H39: =IF($A39="","",IFERROR(INDEX(計算用!$D$2:$D$149,MATCH(計算用!$U$3&4&"-"&$A39,計算用!$K$2:$K$149,0)),"")) | I39: =IF($A39="","",IFERROR(INDEX(計算用!$G$2:$G$149,MATCH(計算用!$U$3&4&"-"&$A39,計算用!$K$2:$K$149,0)),"")) | K39: =IF(35<=計算用!$U$10,35,"") | L39: =IF($K39="","",IFERROR(INDEX(計算用!$D$2:$D$149,MATCH("女"&1&"-"&$K39,計算用!$K$2:$K$149,0)),"")) | M39: =IF($K39="","",IFERROR(INDEX(計算用!$G$2:$G$149,MATCH("女"&1&"-"&$K39,計算用!$K$2:$K$149,0)),"")) | N39: =IF($K39="","",IFERROR(INDEX(計算用!$D$2:$D$149,MATCH("女"&2&"-"&$K39,計算用!$K$2:$K$149,0)),"")) | O39: =IF($K39="","",IFERROR(INDEX(計算用!$G$2:$G$149,MATCH("女"&2&"-"&$K39,計算用!$K$2:$K$149,0)),"")) | P39: =IF($K39="","",IFERROR(INDEX(計算用!$D$2:$D$149,MATCH("女"&3&"-"&$K39,計算用!$K$2:$K$149,0)),"")) | Q39: =IF($K39="","",IFERROR(INDEX(計算用!$G$2:$G$149,MATCH("女"&3&"-"&$K39,計算用!$K$2:$K$149,0)),"")) | R39: =IF($K39="","",IFERROR(INDEX(計算用!$D$2:$D$149,MATCH("女"&4&"-"&$K39,計算用!$K$2:$K$149,0)),"")) | S39: =IF($K39="","",IFERROR(INDEX(計算用!$G$2:$G$149,MATCH("女"&4&"-"&$K39,計算用!$K$2:$K$149,0)),""))
