Workbook

Sheet 使い方
B1: クラブ名簿作成ツール 使い方
B3: ■ 色のきまり
B4: 黄色いセル＝先生が入力する所です。それ以外のセルには数式が入っているので、保護しています（「校閲」→「シート保護の解除」で外せます。パスワードなし）。
B6: ■ 前年度（1〜3月）にすること
B7: ① 【設定】年度（新年度）、新年度の学年（6・5・4）、前年度の組・新年度の組、クラブの名前・定員・担当・活動場所を入力します。
B8: ・クラブを増やす：空いている行に書きこむ 減らす：行の中身を消す 名前を変える：書きかえる
B9: ② 【前年度名簿】アンケートをとる学年（3〜5年）全員の「学年・組・番号・名前」を貼り付けます。学年は数字で入れます。
B10: ・「定員」と「融通」（何人まで超えてよいか）、「上の学年から優先」（〇で有効）、希望調査用紙の注意書きも設定します。
B11: ・【希望調査用紙】を印刷して配ります。クラブの番号は設定シートの No. です（配ったあとは順番を変えないでください）。
B12: ③ 【希望入力】前年度の学年・組・番号と、第1〜第3希望を入れます。
B13: ・紙の場合：希望はクラブの「番号」を打つだけでかまいません。右側にクラブ名が出るので確認してください。
B14: ・Formsの場合：結果の表から「学年〜第3希望」の6列をコピーし、A列の2行目に「値の貼り付け」をします。
... B43: 本番で使うときは、【前年度名簿】【希望入力】【新年度名簿】のデータと、【振り分け】の「先生の決定」欄を消してから使ってください。

Sheet 設定
A1: 設定（黄色いセルを入力してください）
A3: 年度 | B3: 令和9年度 | E3: ← 名簿のタイトルに使う「新年度」
A4: 呼び名 | B4: クラブ
A6: 学年の設定 | E6: 前年度の組（アンケート時） | J6: 新年度の組 | O6: クラブの設定（上から順に「クラブ①、②…」のシートに入ります）
B7: 新年度 | C7: 前年度 | E7: 学年 | F7: 組 | G7: 名簿での表示 | H7: 色 | J7: 学年 | K7: 組 | L7: 名簿での表示 | M7: 色 | O7: No. | P7: クラブ名 | Q7: 定員 | R7: 融通 | S7: 担当 | T7: 活動場所
A8: 上の学年 | B8: 6 | C8: =IF(B8="","",B8-1) | E8: =$C$8 | F8: 松 | G8: =IF(F8="","",E8&F8) | H8: 緑 | J8: =$B$8 | K8: 松 | L8: =IF(K8="","",J8&K8) | M8: 緑 | O8: 1 | P8: 科学 | Q8: 35 | R8: 2 | S8: 3松 | T8: 理科室 | Y8: =IF(F8="","",E8&"-"&F8) | Z8: =IF(K8="","",J8&"-"&K8)
A9: 中の学年 | B9: 5 | C9: =IF(B9="","",B9-1) | E9: =$C$8 | F9: 竹 | G9: =IF(F9="","",E9&F9) | H9: 青 | J9: =$B$8 | K9: 竹 | L9: =IF(K9="","",J9&K9) | M9: 青 | O9: 2 | P9: 料理 | Q9: 35 | R9: 2 | S9: 5竹 | T9: 家庭科室 | Y9: =IF(F9="","",E9&"-"&F9) | Z9: =IF(K9="","",J9&"-"&K9)
A10: 下の学年 | B10: 4 | C10: =IF(B10="","",B10-1) | E10: =$C$8 | F10: 梅 | G10: =IF(F10="","",E10&F10) | H10: 赤 | J10: =$B$8 | K10: 梅 | L10: =IF(K10="","",J10&K10) | M10: 赤 | O10: 3 | P10: 手芸 | Q10: 25 | R10: 0 | S10: 4梅 | T10: 図工室 | Y10: =IF(F10="","",E10&"-"&F10) | Z10: =IF(K10="","",J10&"-"&K10)
E11: =$C$8 | F11: 月 | G11: =IF(F11="","",E11&F11) | H11: 黄 | J11: =$B$8 | K11: 月 | L11: =IF(K11="","",J11&K11) | M11: 黄 | O11: 4 | P11: イラスト | Q11: 35 | R11: 2 | S11: 6月 | T11: 多目的室 | Y11: =IF(F11="","",E11&"-"&F11) | Z11: =IF(K11="","",J11&"-"&K11)
A12: ※ 前年度の学年は自動で1つ下になります。 | E12: =$C$8 | G12: =IF(F12="","",E12&F12) | J12: =$B$8 | L12: =IF(K12="","",J12&K12) | O12: 5 | P12: 卓球 | Q12: 30 | R12: 2 | S12: 4松 | T12: 体育館ステージ | Y12: =IF(F12="","",E12&"-"&F12) | Z12: =IF(K12="","",J12&"-"&K12)
E13: =$C$8 | G13: =IF(F13="","",E13&F13) | J13: =$B$8 | L13: =IF(K13="","",J13&K13) | O13: 6 | P13: バドミントン | Q13: 30 | R13: 2 | S13: 6竹 | T13: 体育館 | Y13: =IF(F13="","",E13&"-"&F13) | Z13: =IF(K13="","",J13&"-"&K13)
A14: 上の学年から優先 | C14: 〇 | E14: =$C$8 | G14: =IF(F14="","",E14&F14) | J14: =$B$8 | L14: =IF(K14="","",J14&K14) | O14: 7 | P14: サッカー | Q14: 40 | R14: 3 | S14: 5松 | T14: 運動場 | Y14: =IF(F14="","",E14&"-"&F14) | Z14: =IF(K14="","",J14&"-"&K14)
A15: （6年→5年→4年） | E15: =$C$8 | G15: =IF(F15="","",E15&F15) | J15: =$B$8 | L15: =IF(K15="","",J15&K15) | O15: 8 | P15: バスケットボール | Q15: 35 | R15: 2 | S15: 6松 | T15: 体育館 | Y15: =IF(F15="","",E15&"-"&F15) | Z15: =IF(K15="","",J15&"-"&K15)
A16: ※ 〇を入れると、上の学年から順に「定員＋融通」の枠を埋めます。空欄なら全学年まとめて判定します。 | E16: =$C$9 | F16: 松 | G16: =IF(F16="","",E16&F16) | H16: 緑 | J16: =$B$9 | K16: 松 | L16: =IF(K16="","",J16&K16) | M16: 緑 | O16: 9 | P16: 将棋囲碁 | Q16: 25 | R16: 2 | S16: 3竹 | T16: 会議室 | Y16: =IF(F16="","",E16&"-"&F16) | Z16: =IF(K16="","",J16&"-"&K16)
E17: =$C$9 | F17: 竹 | G17: =IF(F17="","",E17&F17) | H17: 青 | J17: =$B$9 | K17: 竹 | L17: =IF(K17="","",J17&K17) | M17: 青 | O17: 10 | P17: パソコン | Q17: 40 | R17: 2 | S17: 5梅 | T17: パソコン室 | Y17: =IF(F17="","",E17&"-"&F17) | Z17: =IF(K17="","",J17&"-"&K17)
A18: 希望調査用紙の注意書き | E18: =$C$9 | F18: 梅 | G18: =IF(F18="","",E18&F18) | H18: 赤 | J18: =$B$9 | K18: 梅 | L18: =IF(K18="","",J18&K18) | M18: 赤 | O18: 11 | P18: 音楽 | Q18: 30 | R18: 2 | S18: 4月 | T18: 音楽室 | Y18: =IF(F18="","",E18&"-"&F18) | Z18: =IF(K18="","",J18&"-"&K18)
A19: 必ずしも第1希望が通るわけではありません。 | E19: =$C$9 | F19: 月 | G19: =IF(F19="","",E19&F19) | H19: 黄 | J19: =$B$9 | K19: 月 | L19: =IF(K19="","",J19&K19) | M19: 黄 | O19: 12 | P19: 室内ゲーム | Q19: 40 | R19: 2 | S19: 6梅 | T19: 学習室 | Y19: =IF(F19="","",E19&"-"&F19) | Z19: =IF(K19="","",J19&"-"&K19)
E20: =$C$9 | G20: =IF(F20="","",E20&F20) | J20: =$B$9 | L20: =IF(K20="","",J20&K20) | O20: 13 | Y20: =IF(F20="","",E20&"-"&F20) | Z20: =IF(K20="","",J20&"-"&K20)
E21: =$C$9 | G21: =IF(F21="","",E21&F21) | J21: =$B$9 | L21: =IF(K21="","",J21&K21) | O21: 14 | Y21: =IF(F21="","",E21&"-"&F21) | Z21: =IF(K21="","",J21&"-"&K21)
E22: =$C$9 | G22: =IF(F22="","",E22&F22) | J22: =$B$9 | L22: =IF(K22="","",J22&K22) | O22: 15 | Y22: =IF(F22="","",E22&"-"&F22) | Z22: =IF(K22="","",J22&"-"&K22)
E23: =$C$9 | G23: =IF(F23="","",E23&F23) | J23: =$B$9 | L23: =IF(K23="","",J23&K23) | O23: 16 | Y23: =IF(F23="","",E23&"-"&F23) | Z23: =IF(K23="","",J23&"-"&K23)
E24: =$C$10 | F24: 松 | G24: =IF(F24="","",E24&F24) | H24: 緑 | J24: =$B$10 | K24: 松 | L24: =IF(K24="","",J24&K24) | M24: 緑 | O24: 17 | Y24: =IF(F24="","",E24&"-"&F24) | Z24: =IF(K24="","",J24&"-"&K24)
E25: =$C$10 | F25: 竹 | G25: =IF(F25="","",E25&F25) | H25: 青 | J25: =$B$10 | K25: 竹 | L25: =IF(K25="","",J25&K25) | M25: 青 | O25: 18 | Y25: =IF(F25="","",E25&"-"&F25) | Z25: =IF(K25="","",J25&"-"&K25)
E26: =$C$10 | F26: 梅 | G26: =IF(F26="","",E26&F26) | H26: 赤 | J26: =$B$10 | K26: 梅 | L26: =IF(K26="","",J26&K26) | M26: 赤 | O26: 19 | Y26: =IF(F26="","",E26&"-"&F26) | Z26: =IF(K26="","",J26&"-"&K26)
E27: =$C$10 | F27: 月 | G27: =IF(F27="","",E27&F27) | H27: 黄 | J27: =$B$10 | K27: 月 | L27: =IF(K27="","",J27&K27) | M27: 黄 | O27: 20 | Y27: =IF(F27="","",E27&"-"&F27) | Z27: =IF(K27="","",J27&"-"&K27)
E28: =$C$10 | G28: =IF(F28="","",E28&F28) | J28: =$B$10 | L28: =IF(K28="","",J28&K28) | O28: =" 定員の合計："&SUM(Q8:Q27)&"人" | Y28: =IF(F28="","",E28&"-"&F28) | Z28: =IF(K28="","",J28&"-"&K28)
E29: =$C$10 | G29: =IF(F29="","",E29&F29) | J29: =$B$10 | L29: =IF(K29="","",J29&K29) | O29: ※「融通」は、定員を何人まで超えてもよいかです（空欄は0人）。「定員＋融通」までなら自動で決定になります。 | Y29: =IF(F29="","",E29&"-"&F29) | Z29: =IF(K29="","",J29&"-"&K29)
E30: =$C$10 | G30: =IF(F30="","",E30&F30) | J30: =$B$10 | L30: =IF(K30="","",J30&K30) | O30: ※ No. は希望調査用紙のクラブ番号です。用紙を配ったあとは、クラブの順番を入れかえないでください。 | Y30: =IF(F30="","",E30&"-"&F30) | Z30: =IF(K30="","",J30&"-"&K30)
E31: =$C$10 | G31: =IF(F31="","",E31&F31) | J31: =$B$10 | L31: =IF(K31="","",J31&K31) | Y31: =IF(F31="","",E31&"-"&F31) | Z31: =IF(K31="","",J31&"-"&K31)
E33: ※ 上から名簿の並び順です（学年ごとに8行）。「名簿での表示」は「5-1」などに書きかえてもかまいません。
E34: ※「色」はプルダウンで選びます。名簿の組の文字がその色になります（空欄なら黒）。

Sheet 希望調査用紙
B1: =設定!B3&" "&設定!B4&"希望調査" | J1: =ROUNDUP(COUNTIF(設定!$P$8:$P$27,"?*")/2,0)
B3: 年 組 番 名前（ ）
B5: =設定!B4&"一覧"
B6: =IF(1>$J$1,"",1) | C6: =IF(1>$J$1,""," "&INDEX(設定!$P$8:$P$27,1)) | F6: =IF(1+$J$1>COUNTIF(設定!$P$8:$P$27,"?*"),"",1+$J$1) | G6: =IF(1+$J$1>COUNTIF(設定!$P$8:$P$27,"?*"),""," "&INDEX(設定!$P$8:$P$27,1+$J$1))
B7: =IF(2>$J$1,"",2) | C7: =IF(2>$J$1,""," "&INDEX(設定!$P$8:$P$27,2)) | F7: =IF(2+$J$1>COUNTIF(設定!$P$8:$P$27,"?*"),"",2+$J$1) | G7: =IF(2+$J$1>COUNTIF(設定!$P$8:$P$27,"?*"),""," "&INDEX(設定!$P$8:$P$27,2+$J$1))
B8: =IF(3>$J$1,"",3) | C8: =IF(3>$J$1,""," "&INDEX(設定!$P$8:$P$27,3)) | F8: =IF(3+$J$1>COUNTIF(設定!$P$8:$P$27,"?*"),"",3+$J$1) | G8: =IF(3+$J$1>COUNTIF(設定!$P$8:$P$27,"?*"),""," "&INDEX(設定!$P$8:$P$27,3+$J$1))
B9: =IF(4>$J$1,"",4) | C9: =IF(4>$J$1,""," "&INDEX(設定!$P$8:$P$27,4)) | F9: =IF(4+$J$1>COUNTIF(設定!$P$8:$P$27,"?*"),"",4+$J$1) | G9: =IF(4+$J$1>COUNTIF(設定!$P$8:$P$27,"?*"),""," "&INDEX(設定!$P$8:$P$27,4+$J$1))
B10: =IF(5>$J$1,"",5) | C10: =IF(5>$J$1,""," "&INDEX(設定!$P$8:$P$27,5)) | F10: =IF(5+$J$1>COUNTIF(設定!$P$8:$P$27,"?*"),"",5+$J$1) | G10: =IF(5+$J$1>COUNTIF(設定!$P$8:$P$27,"?*"),""," "&INDEX(設定!$P$8:$P$27,5+$J$1))
B11: =IF(6>$J$1,"",6) | C11: =IF(6>$J$1,""," "&INDEX(設定!$P$8:$P$27,6)) | F11: =IF(6+$J$1>COUNTIF(設定!$P$8:$P$27,"?*"),"",6+$J$1) | G11: =IF(6+$J$1>COUNTIF(設定!$P$8:$P$27,"?*"),""," "&INDEX(設定!$P$8:$P$27,6+$J$1))
B12: =IF(7>$J$1,"",7) | C12: =IF(7>$J$1,""," "&INDEX(設定!$P$8:$P$27,7)) | F12: =IF(7+$J$1>COUNTIF(設定!$P$8:$P$27,"?*"),"",7+$J$1) | G12: =IF(7+$J$1>COUNTIF(設定!$P$8:$P$27,"?*"),""," "&INDEX(設定!$P$8:$P$27,7+$J$1))
B13: =IF(8>$J$1,"",8) | C13: =IF(8>$J$1,""," "&INDEX(設定!$P$8:$P$27,8)) | F13: =IF(8+$J$1>COUNTIF(設定!$P$8:$P$27,"?*"),"",8+$J$1) | G13: =IF(8+$J$1>COUNTIF(設定!$P$8:$P$27,"?*"),""," "&INDEX(設定!$P$8:$P$27,8+$J$1))
B14: =IF(9>$J$1,"",9) | C14: =IF(9>$J$1,""," "&INDEX(設定!$P$8:$P$27,9)) | F14: =IF(9+$J$1>COUNTIF(設定!$P$8:$P$27,"?*"),"",9+$J$1) | G14: =IF(9+$J$1>COUNTIF(設定!$P$8:$P$27,"?*"),""," "&INDEX(設定!$P$8:$P$27,9+$J$1))
B15: =IF(10>$J$1,"",10) | C15: =IF(10>$J$1,""," "&INDEX(設定!$P$8:$P$27,10)) | F15: =IF(10+$J$1>COUNTIF(設定!$P$8:$P$27,"?*"),"",10+$J$1) | G15: =IF(10+$J$1>COUNTIF(設定!$P$8:$P$27,"?*"),""," "&INDEX(設定!$P$8:$P$27,10+$J$1))
B17: 希望
C18: 番号 | D18: クラブ名
B19: 第1希望
B20: 第2希望
B21: 第3希望
B24: =IF(設定!A19="","","※ "&設定!A19)

Sheet 前年度名簿
A1: 学年 | B1: 組 | C1: 番号 | D1: 名前 | F1: キー | G1: 並び順 | H1: 新学年 | I1: 名前キー | J1: チェック（自動）
A2: 5 | B2: 松 | C2: 1 | D2: 石井 柚葉 | F2: =IF(D2="","",A2&"-"&B2&"-"&C2) | G2: =IF(D2="","",IFERROR(MATCH(A2&"-"&B2,設定!$Y$8:$Y$31,0),99)*1000+C2+ROW()/1000000) | H2: =IF(D2="","",A2+1) | I2: =IF(D2="","",H2&"|"&SUBSTITUTE(SUBSTITUTE(D2," ","")," ","")) | J2: =IF(D2="","",IF(ISERROR(MATCH(A2&"-"&B2,設定!$Y$8:$Y$31,0)),"設定にない学年・組",IF(COUNTIF($F$2:$F$451,F2)>1,"同じ学年・組・番号がいる",IF(COUNTIF($I$2:$I$451,I2)>1,"同姓同名あり",""))))
A3: 5 | B3: 松 | C3: 2 | D3: 金子 美月 | F3: =IF(D3="","",A3&"-"&B3&"-"&C3) | G3: =IF(D3="","",IFERROR(MATCH(A3&"-"&B3,設定!$Y$8:$Y$31,0),99)*1000+C3+ROW()/1000000) | H3: =IF(D3="","",A3+1) | I3: =IF(D3="","",H3&"|"&SUBSTITUTE(SUBSTITUTE(D3," ","")," ","")) | J3: =IF(D3="","",IF(ISERROR(MATCH(A3&"-"&B3,設定!$Y$8:$Y$31,0)),"設定にない学年・組",IF(COUNTIF($F$2:$F$451,F3)>1,"同じ学年・組・番号がいる",IF(COUNTIF($I$2:$I$451,I3)>1,"同姓同名あり",""))))
A4: 5 | B4: 松 | C4: 3 | D4: 石井 莉子 | F4: =IF(D4="","",A4&"-"&B4&"-"&C4) | G4: =IF(D4="","",IFERROR(MATCH(A4&"-"&B4,設定!$Y$8:$Y$31,0),99)*1000+C4+ROW()/1000000) | H4: =IF(D4="","",A4+1) | I4: =IF(D4="","",H4&"|"&SUBSTITUTE(SUBSTITUTE(D4," ","")," ","")) | J4: =IF(D4="","",IF(ISERROR(MATCH(A4&"-"&B4,設定!$Y$8:$Y$31,0)),"設定にない学年・組",IF(COUNTIF($F$2:$F$451,F4)>1,"同じ学年・組・番号がいる",IF(COUNTIF($I$2:$I$451,I4)>1,"同姓同名あり",""))))
A5: 5 | B5: 松 | C5: 4 | D5: 遠藤 優斗 | F5: =IF(D5="","",A5&"-"&B5&"-"&C5) | G5: =IF(D5="","",IFERROR(MATCH(A5&"-"&B5,設定!$Y$8:$Y$31,0),99)*1000+C5+ROW()/1000000) | H5: =IF(D5="","",A5+1) | I5: =IF(D5="","",H5&"|"&SUBSTITUTE(SUBSTITUTE(D5," ","")," ","")) | J5: =IF(D5="","",IF(ISERROR(MATCH(A5&"-"&B5,設定!$Y$8:$Y$31,0)),"設定にない学年・組",IF(COUNTIF($F$2:$F$451,F5)>1,"同じ学年・組・番号がいる",IF(COUNTIF($I$2:$I$451,I5)>1,"同姓同名あり",""))))
A6: 5 | B6: 松 | C6: 5 | D6: 山田 莉子 | F6: =IF(D6="","",A6&"-"&B6&"-"&C6) | G6: =IF(D6="","",IFERROR(MATCH(A6&"-"&B6,設定!$Y$8:$Y$31,0),99)*1000+C6+ROW()/1000000) | H6: =IF(D6="","",A6+1) | I6: =IF(D6="","",H6&"|"&SUBSTITUTE(SUBSTITUTE(D6," ","")," ","")) | J6: =IF(D6="","",IF(ISERROR(MATCH(A6&"-"&B6,設定!$Y$8:$Y$31,0)),"設定にない学年・組",IF(COUNTIF($F$2:$F$451,F6)>1,"同じ学年・組・番号がいる",IF(COUNTIF($I$2:$I$451,I6)>1,"同姓同名あり",""))))
A7: 5 | B7: 松 | C7: 6 | D7: 前田 大翔 | F7: =IF(D7="","",A7&"-"&B7&"-"&C7) | G7: =IF(D7="","",IFERROR(MATCH(A7&"-"&B7,設定!$Y$8:$Y$31,0),99)*1000+C7+ROW()/1000000) | H7: =IF(D7="","",A7+1) | I7: =IF(D7="","",H7&"|"&SUBSTITUTE(SUBSTITUTE(D7," ","")," ","")) | J7: =IF(D7="","",IF(ISERROR(MATCH(A7&"-"&B7,設定!$Y$8:$Y$31,0)),"設定にない学年・組",IF(COUNTIF($F$2:$F$451,F7)>1,"同じ学年・組・番号がいる",IF(COUNTIF($I$2:$I$451,I7)>1,"同姓同名あり",""))))
A8: 5 | B8: 松 | C8: 7 | D8: 坂本 結翔 | F8: =IF(D8="","",A8&"-"&B8&"-"&C8) | G8: =IF(D8="","",IFERROR(MATCH(A8&"-"&B8,設定!$Y$8:$Y$31,0),99)*1000+C8+ROW()/1000000) | H8: =IF(D8="","",A8+1) | I8: =IF(D8="","",H8&"|"&SUBSTITUTE(SUBSTITUTE(D8," ","")," ","")) | J8: =IF(D8="","",IF(ISERROR(MATCH(A8&"-"&B8,設定!$Y$8:$Y$31,0)),"設定にない学年・組",IF(COUNTIF($F$2:$F$451,F8)>1,"同じ学年・組・番号がいる",IF(COUNTIF($I$2:$I$451,I8)>1,"同姓同名あり",""))))
A9: 5 | B9: 松 | C9: 8 | D9: 山本 咲良 | F9: =IF(D9="","",A9&"-"&B9&"-"&C9) | G9: =IF(D9="","",IFERROR(MATCH(A9&"-"&B9,設定!$Y$8:$Y$31,0),99)*1000+C9+ROW()/1000000) | H9: =IF(D9="","",A9+1) | I9: =IF(D9="","",H9&"|"&SUBSTITUTE(SUBSTITUTE(D9," ","")," ","")) | J9: =IF(D9="","",IF(ISERROR(MATCH(A9&"-"&B9,設定!$Y$8:$Y$31,0)),"設定にない学年・組",IF(COUNTIF($F$2:$F$451,F9)>1,"同じ学年・組・番号がいる",IF(COUNTIF($I$2:$I$451,I9)>1,"同姓同名あり",""))))
A10: 5 | B10: 松 | C10: 9 | D10: 清水 律 | F10: =IF(D10="","",A10&"-"&B10&"-"&C10) | G10: =IF(D10="","",IFERROR(MATCH(A10&"-"&B10,設定!$Y$8:$Y$31,0),99)*1000+C10+ROW()/1000000) | H10: =IF(D10="","",A10+1) | I10: =IF(D10="","",H10&"|"&SUBSTITUTE(SUBSTITUTE(D10," ","")," ","")) | J10: =IF(D10="","",IF(ISERROR(MATCH(A10&"-"&B10,設定!$Y$8:$Y$31,0)),"設定にない学年・組",IF(COUNTIF($F$2:$F$451,F10)>1,"同じ学年・組・番号がいる",IF(COUNTIF($I$2:$I$451,I10)>1,"同姓同名あり",""))))
A11: 5 | B11: 松 | C11: 10 | D11: 渡辺 花音 | F11: =IF(D11="","",A11&"-"&B11&"-"&C11) | G11: =IF(D11="","",IFERROR(MATCH(A11&"-"&B11,設定!$Y$8:$Y$31,0),99)*1000+C11+ROW()/1000000) | H11: =IF(D11="","",A11+1) | I11: =IF(D11="","",H11&"|"&SUBSTITUTE(SUBSTITUTE(D11," ","")," ","")) | J11: =IF(D11="","",IF(ISERROR(MATCH(A11&"-"&B11,設定!$Y$8:$Y$31,0)),"設定にない学年・組",IF(COUNTIF($F$2:$F$451,F11)>1,"同じ学年・組・番号がいる",IF(COUNTIF($I$2:$I$451,I11)>1,"同姓同名あり",""))))
A12: 5 | B12: 松 | C12: 11 | D12: 岡本 大翔 | F12: =IF(D12="","",A12&"-"&B12&"-"&C12) | G12: =IF(D12="","",IFERROR(MATCH(A12&"-"&B12,設定!$Y$8:$Y$31,0),99)*1000+C12+ROW()/1000000) | H12: =IF(D12="","",A12+1) | I12: =IF(D12="","",H12&"|"&SUBSTITUTE(SUBSTITUTE(D12," ","")," ","")) | J12: =IF(D12="","",IF(ISERROR(MATCH(A12&"-"&B12,設定!$Y$8:$Y$31,0)),"設定にない学年・組",IF(COUNTIF($F$2:$F$451,F12)>1,"同じ学年・組・番号がいる",IF(COUNTIF($I$2:$I$451,I12)>1,"同姓同名あり",""))))
A13: 5 | B13: 松 | C13: 12 | D13: 高橋 真央 | F13: =IF(D13="","",A13&"-"&B13&"-"&C13) | G13: =IF(D13="","",IFERROR(MATCH(A13&"-"&B13,設定!$Y$8:$Y$31,0),99)*1000+C13+ROW()/1000000) | H13: =IF(D13="","",A13+1) | I13: =IF(D13="","",H13&"|"&SUBSTITUTE(SUBSTITUTE(D13," ","")," ","")) | J13: =IF(D13="","",IF(ISERROR(MATCH(A13&"-"&B13,設定!$Y$8:$Y$31,0)),"設定にない学年・組",IF(COUNTIF($F$2:$F$451,F13)>1,"同じ学年・組・番号がいる",IF(COUNTIF($I$2:$I$451,I13)>1,"同姓同名あり",""))))
... A361: 3 | B361: 月 | C361: 30 | D361: 池田 大翔 | F361: =IF(D361="","",A361&"-"&B361&"-"&C361) | G361: =IF(D361="","",IFERROR(MATCH(A361&"-"&B361,設定!$Y$8:$Y$31,0),99)*1000+C361+ROW()/1000000) | H361: =IF(D361="","",A361+1) | I361: =IF(D361="","",H361&"|"&SUBSTITUTE(SUBSTITUTE(D361," ","")," ","")) | J361: =IF(D361="","",IF(ISERROR(MATCH(A361&"-"&B361,設定!$Y$8:$Y$31,0)),"設定にない学年・組",IF(COUNTIF($F$2:$F$451,F361)>1,"同じ学年・組・番号がいる",IF(COUNTIF($I$2:$I$451,I361)>1,"同姓同名あり",""))))
F362: =IF(D362="","",A362&"-"&B362&"-"&C362) | G362: =IF(D362="","",IFERROR(MATCH(A362&"-"&B362,設定!$Y$8:$Y$31,0),99)*1000+C362+ROW()/1000000) | H362: =IF(D362="","",A362+1) | I362: =IF(D362="","",H362&"|"&SUBSTITUTE(SUBSTITUTE(D362," ","")," ","")) | J362: =IF(D362="","",IF(ISERROR(MATCH(A362&"-"&B362,設定!$Y$8:$Y$31,0)),"設定にない学年・組",IF(COUNTIF($F$2:$F$451,F362)>1,"同じ学年・組・番号がいる",IF(COUNTIF($I$2:$I$451,I362)>1,"同姓同名あり",""))))
F363: =IF(D363="","",A363&"-"&B363&"-"&C363) | G363: =IF(D363="","",IFERROR(MATCH(A363&"-"&B363,設定!$Y$8:$Y$31,0),99)*1000+C363+ROW()/1000000) | H363: =IF(D363="","",A363+1) | I363: =IF(D363="","",H363&"|"&SUBSTITUTE(SUBSTITUTE(D363," ","")," ","")) | J363: =IF(D363="","",IF(ISERROR(MATCH(A363&"-"&B363,設定!$Y$8:$Y$31,0)),"設定にない学年・組",IF(COUNTIF($F$2:$F$451,F363)>1,"同じ学年・組・番号がいる",IF(COUNTIF($I$2:$I$451,I363)>1,"同姓同名あり",""))))
F364: =IF(D364="","",A364&"-"&B364&"-"&C364) | G364: =IF(D364="","",IFERROR(MATCH(A364&"-"&B364,設定!$Y$8:$Y$31,0),99)*1000+C364+ROW()/1000000) | H364: =IF(D364="","",A364+1) | I364: =IF(D364="","",H364&"|"&SUBSTITUTE(SUBSTITUTE(D364," ","")," ","")) | J364: =IF(D364="","",IF(ISERROR(MATCH(A364&"-"&B364,設定!$Y$8:$Y$31,0)),"設定にない学年・組",IF(COUNTIF($F$2:$F$451,F364)>1,"同じ学年・組・番号がいる",IF(COUNTIF($I$2:$I$451,I364)>1,"同姓同名あり",""))))
F365: =IF(D365="","",A365&"-"&B365&"-"&C365) | G365: =IF(D365="","",IFERROR(MATCH(A365&"-"&B365,設定!$Y$8:$Y$31,0),99)*1000+C365+ROW()/1000000) | H365: =IF(D365="","",A365+1) | I365: =IF(D365="","",H365&"|"&SUBSTITUTE(SUBSTITUTE(D365," ","")," ","")) | J365: =IF(D365="","",IF(ISERROR(MATCH(A365&"-"&B365,設定!$Y$8:$Y$31,0)),"設定にない学年・組",IF(COUNTIF($F$2:$F$451,F365)>1,"同じ学年・組・番号がいる",IF(COUNTIF($I$2:$I$451,I365)>1,"同姓同名あり",""))))
F366: =IF(D366="","",A366&"-"&B366&"-"&C366) | G366: =IF(D366="","",IFERROR(MATCH(A366&"-"&B366,設定!$Y$8:$Y$31,0),99)*1000+C366+ROW()/1000000) | H366: =IF(D366="","",A366+1) | I366: =IF(D366="","",H366&"|"&SUBSTITUTE(SUBSTITUTE(D366," ","")," ","")) | J366: =IF(D366="","",IF(ISERROR(MATCH(A366&"-"&B366,設定!$Y$8:$Y$31,0)),"設定にない学年・組",IF(COUNTIF($F$2:$F$451,F366)>1,"同じ学年・組・番号がいる",IF(COUNTIF($I$2:$I$451,I366)>1,"同姓同名あり",""))))
F367: =IF(D367="","",A367&"-"&B367&"-"&C367) | G367: =IF(D367="","",IFERROR(MATCH(A367&"-"&B367,設定!$Y$8:$Y$31,0),99)*1000+C367+ROW()/1000000) | H367: =IF(D367="","",A367+1) | I367: =IF(D367="","",H367&"|"&SUBSTITUTE(SUBSTITUTE(D367," ","")," ","")) | J367: =IF(D367="","",IF(ISERROR(MATCH(A367&"-"&B367,設定!$Y$8:$Y$31,0)),"設定にない学年・組",IF(COUNTIF($F$2:$F$451,F367)>1,"同じ学年・組・番号がいる",IF(COUNTIF($I$2:$I$451,I367)>1,"同姓同名あり",""))))
F368: =IF(D368="","",A368&"-"&B368&"-"&C368) | G368: =IF(D368="","",IFERROR(MATCH(A368&"-"&B368,設定!$Y$8:$Y$31,0),99)*1000+C368+ROW()/1000000) | H368: =IF(D368="","",A368+1) | I368: =IF(D368="","",H368&"|"&SUBSTITUTE(SUBSTITUTE(D368," ","")," ","")) | J368: =IF(D368="","",IF(ISERROR(MATCH(A368&"-"&B368,設定!$Y$8:$Y$31,0)),"設定にない学年・組",IF(COUNTIF($F$2:$F$451,F368)>1,"同じ学年・組・番号がいる",IF(COUNTIF($I$2:$I$451,I368)>1,"同姓同名あり",""))))
F369: =IF(D369="","",A369&"-"&B369&"-"&C369) | G369: =IF(D369="","",IFERROR(MATCH(A369&"-"&B369,設定!$Y$8:$Y$31,0),99)*1000+C369+ROW()/1000000) | H369: =IF(D369="","",A369+1) | I369: =IF(D369="","",H369&"|"&SUBSTITUTE(SUBSTITUTE(D369," ","")," ","")) | J369: =IF(D369="","",IF(ISERROR(MATCH(A369&"-"&B369,設定!$Y$8:$Y$31,0)),"設定にない学年・組",IF(COUNTIF($F$2:$F$451,F369)>1,"同じ学年・組・番号がいる",IF(COUNTIF($I$2:$I$451,I369)>1,"同姓同名あり",""))))
F370: =IF(D370="","",A370&"-"&B370&"-"&C370) | G370: =IF(D370="","",IFERROR(MATCH(A370&"-"&B370,設定!$Y$8:$Y$31,0),99)*1000+C370+ROW()/1000000) | H370: =IF(D370="","",A370+1) | I370: =IF(D370="","",H370&"|"&SUBSTITUTE(SUBSTITUTE(D370," ","")," ","")) | J370: =IF(D370="","",IF(ISERROR(MATCH(A370&"-"&B370,設定!$Y$8:$Y$31,0)),"設定にない学年・組",IF(COUNTIF($F$2:$F$451,F370)>1,"同じ学年・組・番号がいる",IF(COUNTIF($I$2:$I$451,I370)>1,"同姓同名あり",""))))
F371: =IF(D371="","",A371&"-"&B371&"-"&C371) | G371: =IF(D371="","",IFERROR(MATCH(A371&"-"&B371,設定!$Y$8:$Y$31,0),99)*1000+C371+ROW()/1000000) | H371: =IF(D371="","",A371+1) | I371: =IF(D371="","",H371&"|"&SUBSTITUTE(SUBSTITUTE(D371," ","")," ","")) | J371: =IF(D371="","",IF(ISERROR(MATCH(A371&"-"&B371,設定!$Y$8:$Y$31,0)),"設定にない学年・組",IF(COUNTIF($F$2:$F$451,F371)>1,"同じ学年・組・番号がいる",IF(COUNTIF($I$2:$I$451,I371)>1,"同姓同名あり",""))))
F372: =IF(D372="","",A372&"-"&B372&"-"&C372) | G372: =IF(D372="","",IFERROR(MATCH(A372&"-"&B372,設定!$Y$8:$Y$31,0),99)*1000+C372+ROW()/1000000) | H372: =IF(D372="","",A372+1) | I372: =IF(D372="","",H372&"|"&SUBSTITUTE(SUBSTITUTE(D372," ","")," ","")) | J372: =IF(D372="","",IF(ISERROR(MATCH(A372&"-"&B372,設定!$Y$8:$Y$31,0)),"設定にない学年・組",IF(COUNTIF($F$2:$F$451,F372)>1,"同じ学年・組・番号がいる",IF(COUNTIF($I$2:$I$451,I372)>1,"同姓同名あり",""))))
F373: =IF(D373="","",A373&"-"&B373&"-"&C373) | G373: =IF(D373="","",IFERROR(MATCH(A373&"-"&B373,設定!$Y$8:$Y$31,0),99)*1000+C373+ROW()/1000000) | H373: =IF(D373="","",A373+1) | I373: =IF(D373="","",H373&"|"&SUBSTITUTE(SUBSTITUTE(D373," ","")," ","")) | J373: =IF(D373="","",IF(ISERROR(MATCH(A373&"-"&B373,設定!$Y$8:$Y$31,0)),"設定にない学年・組",IF(COUNTIF($F$2:$F$451,F373)>1,"同じ学年・組・番号がいる",IF(COUNTIF($I$2:$I$451,I373)>1,"同姓同名あり",""))))
... F451: =IF(D451="","",A451&"-"&B451&"-"&C451) | G451: =IF(D451="","",IFERROR(MATCH(A451&"-"&B451,設定!$Y$8:$Y$31,0),99)*1000+C451+ROW()/1000000) | H451: =IF(D451="","",A451+1) | I451: =IF(D451="","",H451&"|"&SUBSTITUTE(SUBSTITUTE(D451," ","")," ","")) | J451: =IF(D451="","",IF(ISERROR(MATCH(A451&"-"&B451,設定!$Y$8:$Y$31,0)),"設定にない学年・組",IF(COUNTIF($F$2:$F$451,F451)>1,"同じ学年・組・番号がいる",IF(COUNTIF($I$2:$I$451,I451)>1,"同姓同名あり",""))))

Sheet 希望入力
A1: 学年 | B1: 組 | C1: 番号 | D1: 第1希望 | E1: 第2希望 | F1: 第3希望 | G1: 名前（自動） | H1: 第1（クラブ名） | I1: 第2（クラブ名） | J1: 第3（クラブ名） | K1: チェック（自動） | L1: キー | M1: 採用
A2: 4 | B2: 松 | C2: 12 | D2: 1 | E2: 8 | F2: 7 | G2: =IF(L2="","",IFERROR(INDEX(前年度名簿!$D$2:$D$451,MATCH(L2,前年度名簿!$F$2:$F$451,0)),"")) | H2: =IF(D2="","",IF(ISERROR(VALUE(D2)),D2&"",IF(AND(VALUE(D2)>=1,VALUE(D2)<=20),IF(INDEX(設定!$P$8:$P$27,VALUE(D2))="","？",INDEX(設定!$P$8:$P$27,VALUE(D2))),"？"))) | I2: =IF(E2="","",IF(ISERROR(VALUE(E2)),E2&"",IF(AND(VALUE(E2)>=1,VALUE(E2)<=20),IF(INDEX(設定!$P$8:$P$27,VALUE(E2))="","？",INDEX(設定!$P$8:$P$27,VALUE(E2))),"？"))) | J2: =IF(F2="","",IF(ISERROR(VALUE(F2)),F2&"",IF(AND(VALUE(F2)>=1,VALUE(F2)<=20),IF(INDEX(設定!$P$8:$P$27,VALUE(F2))="","？",INDEX(設定!$P$8:$P$27,VALUE(F2))),"？"))) | K2: =IF(L2="","",IF(G2="","名簿にいない",IF(COUNTIF(L3:L$552,L2)>0,"2回提出（下の行を使います）",IF(OR(H2="？",I2="？",J2="？"),"クラブ番号がちがう",IF(OR(AND(H2<>"",H2<>"？",COUNTIF(設定!$P$8:$P$27,H2)=0),AND(I2<>"",I2<>"？",COUNTIF(設定!$P$8:$P$27,I2)=0),AND(J2<>"",J2<>"？",COUNTIF(設定!$P$8:$P$27,J2)=0)),"クラブ名がちがう",IF(H2="","第1希望がない",IF(OR(AND(H2<>"",H2=I2),AND(H2<>"",H2=J2),AND(I2<>"",I2=J2)),"同じクラブを重複して希望","OK"))))))) | L2: =IF(A2="","",A2&"-"&B2&"-"&C2) | M2: =IF(OR(L2="",G2=""),"",IF(COUNTIF(L3:L$552,L2)=0,L2,""))
A3: 5 | B3: 松 | C3: 26 | D3: 3 | E3: 8 | F3: 5 | G3: =IF(L3="","",IFERROR(INDEX(前年度名簿!$D$2:$D$451,MATCH(L3,前年度名簿!$F$2:$F$451,0)),"")) | H3: =IF(D3="","",IF(ISERROR(VALUE(D3)),D3&"",IF(AND(VALUE(D3)>=1,VALUE(D3)<=20),IF(INDEX(設定!$P$8:$P$27,VALUE(D3))="","？",INDEX(設定!$P$8:$P$27,VALUE(D3))),"？"))) | I3: =IF(E3="","",IF(ISERROR(VALUE(E3)),E3&"",IF(AND(VALUE(E3)>=1,VALUE(E3)<=20),IF(INDEX(設定!$P$8:$P$27,VALUE(E3))="","？",INDEX(設定!$P$8:$P$27,VALUE(E3))),"？"))) | J3: =IF(F3="","",IF(ISERROR(VALUE(F3)),F3&"",IF(AND(VALUE(F3)>=1,VALUE(F3)<=20),IF(INDEX(設定!$P$8:$P$27,VALUE(F3))="","？",INDEX(設定!$P$8:$P$27,VALUE(F3))),"？"))) | K3: =IF(L3="","",IF(G3="","名簿にいない",IF(COUNTIF(L4:L$552,L3)>0,"2回提出（下の行を使います）",IF(OR(H3="？",I3="？",J3="？"),"クラブ番号がちがう",IF(OR(AND(H3<>"",H3<>"？",COUNTIF(設定!$P$8:$P$27,H3)=0),AND(I3<>"",I3<>"？",COUNTIF(設定!$P$8:$P$27,I3)=0),AND(J3<>"",J3<>"？",COUNTIF(設定!$P$8:$P$27,J3)=0)),"クラブ名がちがう",IF(H3="","第1希望がない",IF(OR(AND(H3<>"",H3=I3),AND(H3<>"",H3=J3),AND(I3<>"",I3=J3)),"同じクラブを重複して希望","OK"))))))) | L3: =IF(A3="","",A3&"-"&B3&"-"&C3) | M3: =IF(OR(L3="",G3=""),"",IF(COUNTIF(L4:L$552,L3)=0,L3,""))
A4: 3 | B4: 梅 | C4: 21 | D4: 9 | E4: 2 | F4: 6 | G4: =IF(L4="","",IFERROR(INDEX(前年度名簿!$D$2:$D$451,MATCH(L4,前年度名簿!$F$2:$F$451,0)),"")) | H4: =IF(D4="","",IF(ISERROR(VALUE(D4)),D4&"",IF(AND(VALUE(D4)>=1,VALUE(D4)<=20),IF(INDEX(設定!$P$8:$P$27,VALUE(D4))="","？",INDEX(設定!$P$8:$P$27,VALUE(D4))),"？"))) | I4: =IF(E4="","",IF(ISERROR(VALUE(E4)),E4&"",IF(AND(VALUE(E4)>=1,VALUE(E4)<=20),IF(INDEX(設定!$P$8:$P$27,VALUE(E4))="","？",INDEX(設定!$P$8:$P$27,VALUE(E4))),"？"))) | J4: =IF(F4="","",IF(ISERROR(VALUE(F4)),F4&"",IF(AND(VALUE(F4)>=1,VALUE(F4)<=20),IF(INDEX(設定!$P$8:$P$27,VALUE(F4))="","？",INDEX(設定!$P$8:$P$27,VALUE(F4))),"？"))) | K4: =IF(L4="","",IF(G4="","名簿にいない",IF(COUNTIF(L5:L$552,L4)>0,"2回提出（下の行を使います）",IF(OR(H4="？",I4="？",J4="？"),"クラブ番号がちがう",IF(OR(AND(H4<>"",H4<>"？",COUNTIF(設定!$P$8:$P$27,H4)=0),AND(I4<>"",I4<>"？",COUNTIF(設定!$P$8:$P$27,I4)=0),AND(J4<>"",J4<>"？",COUNTIF(設定!$P$8:$P$27,J4)=0)),"クラブ名がちがう",IF(H4="","第1希望がない",IF(OR(AND(H4<>"",H4=I4),AND(H4<>"",H4=J4),AND(I4<>"",I4=J4)),"同じクラブを重複して希望","OK"))))))) | L4: =IF(A4="","",A4&"-"&B4&"-"&C4) | M4: =IF(OR(L4="",G4=""),"",IF(COUNTIF(L5:L$552,L4)=0,L4,""))
A5: 4 | B5: 竹 | C5: 10 | D5: 10 | E5: 5 | F5: 2 | G5: =IF(L5="","",IFERROR(INDEX(前年度名簿!$D$2:$D$451,MATCH(L5,前年度名簿!$F$2:$F$451,0)),"")) | H5: =IF(D5="","",IF(ISERROR(VALUE(D5)),D5&"",IF(AND(VALUE(D5)>=1,VALUE(D5)<=20),IF(INDEX(設定!$P$8:$P$27,VALUE(D5))="","？",INDEX(設定!$P$8:$P$27,VALUE(D5))),"？"))) | I5: =IF(E5="","",IF(ISERROR(VALUE(E5)),E5&"",IF(AND(VALUE(E5)>=1,VALUE(E5)<=20),IF(INDEX(設定!$P$8:$P$27,VALUE(E5))="","？",INDEX(設定!$P$8:$P$27,VALUE(E5))),"？"))) | J5: =IF(F5="","",IF(ISERROR(VALUE(F5)),F5&"",IF(AND(VALUE(F5)>=1,VALUE(F5)<=20),IF(INDEX(設定!$P$8:$P$27,VALUE(F5))="","？",INDEX(設定!$P$8:$P$27,VALUE(F5))),"？"))) | K5: =IF(L5="","",IF(G5="","名簿にいない",IF(COUNTIF(L6:L$552,L5)>0,"2回提出（下の行を使います）",IF(OR(H5="？",I5="？",J5="？"),"クラブ番号がちがう",IF(OR(AND(H5<>"",H5<>"？",COUNTIF(設定!$P$8:$P$27,H5)=0),AND(I5<>"",I5<>"？",COUNTIF(設定!$P$8:$P$27,I5)=0),AND(J5<>"",J5<>"？",COUNTIF(設定!$P$8:$P$27,J5)=0)),"クラブ名がちがう",IF(H5="","第1希望がない",IF(OR(AND(H5<>"",H5=I5),AND(H5<>"",H5=J5),AND(I5<>"",I5=J5)),"同じクラブを重複して希望","OK"))))))) | L5: =IF(A5="","",A5&"-"&B5&"-"&C5) | M5: =IF(OR(L5="",G5=""),"",IF(COUNTIF(L6:L$552,L5)=0,L5,""))
A6: 3 | B6: 梅 | C6: 18 | D6: 1 | E6: 6 | F6: 3 | G6: =IF(L6="","",IFERROR(INDEX(前年度名簿!$D$2:$D$451,MATCH(L6,前年度名簿!$F$2:$F$451,0)),"")) | H6: =IF(D6="","",IF(ISERROR(VALUE(D6)),D6&"",IF(AND(VALUE(D6)>=1,VALUE(D6)<=20),IF(INDEX(設定!$P$8:$P$27,VALUE(D6))="","？",INDEX(設定!$P$8:$P$27,VALUE(D6))),"？"))) | I6: =IF(E6="","",IF(ISERROR(VALUE(E6)),E6&"",IF(AND(VALUE(E6)>=1,VALUE(E6)<=20),IF(INDEX(設定!$P$8:$P$27,VALUE(E6))="","？",INDEX(設定!$P$8:$P$27,VALUE(E6))),"？"))) | J6: =IF(F6="","",IF(ISERROR(VALUE(F6)),F6&"",IF(AND(VALUE(F6)>=1,VALUE(F6)<=20),IF(INDEX(設定!$P$8:$P$27,VALUE(F6))="","？",INDEX(設定!$P$8:$P$27,VALUE(F6))),"？"))) | K6: =IF(L6="","",IF(G6="","名簿にいない",IF(COUNTIF(L7:L$552,L6)>0,"2回提出（下の行を使います）",IF(OR(H6="？",I6="？",J6="？"),"クラブ番号がちがう",IF(OR(AND(H6<>"",H6<>"？",COUNTIF(設定!$P$8:$P$27,H6)=0),AND(I6<>"",I6<>"？",COUNTIF(設定!$P$8:$P$27,I6)=0),AND(J6<>"",J6<>"？",COUNTIF(設定!$P$8:$P$27,J6)=0)),"クラブ名がちがう",IF(H6="","第1希望がない",IF(OR(AND(H6<>"",H6=I6),AND(H6<>"",H6=J6),AND(I6<>"",I6=J6)),"同じクラブを重複して希望","OK"))))))) | L6: =IF(A6="","",A6&"-"&B6&"-"&C6) | M6: =IF(OR(L6="",G6=""),"",IF(COUNTIF(L7:L$552,L6)=0,L6,""))
A7: 3 | B7: 梅 | C7: 15 | D7: 5 | E7: 2 | F7: 12 | G7: =IF(L7="","",IFERROR(INDEX(前年度名簿!$D$2:$D$451,MATCH(L7,前年度名簿!$F$2:$F$451,0)),"")) | H7: =IF(D7="","",IF(ISERROR(VALUE(D7)),D7&"",IF(AND(VALUE(D7)>=1,VALUE(D7)<=20),IF(INDEX(設定!$P$8:$P$27,VALUE(D7))="","？",INDEX(設定!$P$8:$P$27,VALUE(D7))),"？"))) | I7: =IF(E7="","",IF(ISERROR(VALUE(E7)),E7&"",IF(AND(VALUE(E7)>=1,VALUE(E7)<=20),IF(INDEX(設定!$P$8:$P$27,VALUE(E7))="","？",INDEX(設定!$P$8:$P$27,VALUE(E7))),"？"))) | J7: =IF(F7="","",IF(ISERROR(VALUE(F7)),F7&"",IF(AND(VALUE(F7)>=1,VALUE(F7)<=20),IF(INDEX(設定!$P$8:$P$27,VALUE(F7))="","？",INDEX(設定!$P$8:$P$27,VALUE(F7))),"？"))) | K7: =IF(L7="","",IF(G7="","名簿にいない",IF(COUNTIF(L8:L$552,L7)>0,"2回提出（下の行を使います）",IF(OR(H7="？",I7="？",J7="？"),"クラブ番号がちがう",IF(OR(AND(H7<>"",H7<>"？",COUNTIF(設定!$P$8:$P$27,H7)=0),AND(I7<>"",I7<>"？",COUNTIF(設定!$P$8:$P$27,I7)=0),AND(J7<>"",J7<>"？",COUNTIF(設定!$P$8:$P$27,J7)=0)),"クラブ名がちがう",IF(H7="","第1希望がない",IF(OR(AND(H7<>"",H7=I7),AND(H7<>"",H7=J7),AND(I7<>"",I7=J7)),"同じクラブを重複して希望","OK"))))))) | L7: =IF(A7="","",A7&"-"&B7&"-"&C7) | M7: =IF(OR(L7="",G7=""),"",IF(COUNTIF(L8:L$552,L7)=0,L7,""))
A8: 4 | B8: 梅 | C8: 26 | D8: 5 | E8: 12 | F8: 10 | G8: =IF(L8="","",IFERROR(INDEX(前年度名簿!$D$2:$D$451,MATCH(L8,前年度名簿!$F$2:$F$451,0)),"")) | H8: =IF(D8="","",IF(ISERROR(VALUE(D8)),D8&"",IF(AND(VALUE(D8)>=1,VALUE(D8)<=20),IF(INDEX(設定!$P$8:$P$27,VALUE(D8))="","？",INDEX(設定!$P$8:$P$27,VALUE(D8))),"？"))) | I8: =IF(E8="","",IF(ISERROR(VALUE(E8)),E8&"",IF(AND(VALUE(E8)>=1,VALUE(E8)<=20),IF(INDEX(設定!$P$8:$P$27,VALUE(E8))="","？",INDEX(設定!$P$8:$P$27,VALUE(E8))),"？"))) | J8: =IF(F8="","",IF(ISERROR(VALUE(F8)),F8&"",IF(AND(VALUE(F8)>=1,VALUE(F8)<=20),IF(INDEX(設定!$P$8:$P$27,VALUE(F8))="","？",INDEX(設定!$P$8:$P$27,VALUE(F8))),"？"))) | K8: =IF(L8="","",IF(G8="","名簿にいない",IF(COUNTIF(L9:L$552,L8)>0,"2回提出（下の行を使います）",IF(OR(H8="？",I8="？",J8="？"),"クラブ番号がちがう",IF(OR(AND(H8<>"",H8<>"？",COUNTIF(設定!$P$8:$P$27,H8)=0),AND(I8<>"",I8<>"？",COUNTIF(設定!$P$8:$P$27,I8)=0),AND(J8<>"",J8<>"？",COUNTIF(設定!$P$8:$P$27,J8)=0)),"クラブ名がちがう",IF(H8="","第1希望がない",IF(OR(AND(H8<>"",H8=I8),AND(H8<>"",H8=J8),AND(I8<>"",I8=J8)),"同じクラブを重複して希望","OK"))))))) | L8: =IF(A8="","",A8&"-"&B8&"-"&C8) | M8: =IF(OR(L8="",G8=""),"",IF(COUNTIF(L9:L$552,L8)=0,L8,""))
A9: 4 | B9: 松 | C9: 2 | D9: 10 | E9: 5 | F9: 9 | G9: =IF(L9="","",IFERROR(INDEX(前年度名簿!$D$2:$D$451,MATCH(L9,前年度名簿!$F$2:$F$451,0)),"")) | H9: =IF(D9="","",IF(ISERROR(VALUE(D9)),D9&"",IF(AND(VALUE(D9)>=1,VALUE(D9)<=20),IF(INDEX(設定!$P$8:$P$27,VALUE(D9))="","？",INDEX(設定!$P$8:$P$27,VALUE(D9))),"？"))) | I9: =IF(E9="","",IF(ISERROR(VALUE(E9)),E9&"",IF(AND(VALUE(E9)>=1,VALUE(E9)<=20),IF(INDEX(設定!$P$8:$P$27,VALUE(E9))="","？",INDEX(設定!$P$8:$P$27,VALUE(E9))),"？"))) | J9: =IF(F9="","",IF(ISERROR(VALUE(F9)),F9&"",IF(AND(VALUE(F9)>=1,VALUE(F9)<=20),IF(INDEX(設定!$P$8:$P$27,VALUE(F9))="","？",INDEX(設定!$P$8:$P$27,VALUE(F9))),"？"))) | K9: =IF(L9="","",IF(G9="","名簿にいない",IF(COUNTIF(L10:L$552,L9)>0,"2回提出（下の行を使います）",IF(OR(H9="？",I9="？",J9="？"),"クラブ番号がちがう",IF(OR(AND(H9<>"",H9<>"？",COUNTIF(設定!$P$8:$P$27,H9)=0),AND(I9<>"",I9<>"？",COUNTIF(設定!$P$8:$P$27,I9)=0),AND(J9<>"",J9<>"？",COUNTIF(設定!$P$8:$P$27,J9)=0)),"クラブ名がちがう",IF(H9="","第1希望がない",IF(OR(AND(H9<>"",H9=I9),AND(H9<>"",H9=J9),AND(I9<>"",I9=J9)),"同じクラブを重複して希望","OK"))))))) | L9: =IF(A9="","",A9&"-"&B9&"-"&C9) | M9: =IF(OR(L9="",G9=""),"",IF(COUNTIF(L10:L$552,L9)=0,L9,""))
A10: 4 | B10: 月 | C10: 7 | D10: 3 | E10: 5 | F10: 10 | G10: =IF(L10="","",IFERROR(INDEX(前年度名簿!$D$2:$D$451,MATCH(L10,前年度名簿!$F$2:$F$451,0)),"")) | H10: =IF(D10="","",IF(ISERROR(VALUE(D10)),D10&"",IF(AND(VALUE(D10)>=1,VALUE(D10)<=20),IF(INDEX(設定!$P$8:$P$27,VALUE(D10))="","？",INDEX(設定!$P$8:$P$27,VALUE(D10))),"？"))) | I10: =IF(E10="","",IF(ISERROR(VALUE(E10)),E10&"",IF(AND(VALUE(E10)>=1,VALUE(E10)<=20),IF(INDEX(設定!$P$8:$P$27,VALUE(E10))="","？",INDEX(設定!$P$8:$P$27,VALUE(E10))),"？"))) | J10: =IF(F10="","",IF(ISERROR(VALUE(F10)),F10&"",IF(AND(VALUE(F10)>=1,VALUE(F10)<=20),IF(INDEX(設定!$P$8:$P$27,VALUE(F10))="","？",INDEX(設定!$P$8:$P$27,VALUE(F10))),"？"))) | K10: =IF(L10="","",IF(G10="","名簿にいない",IF(COUNTIF(L11:L$552,L10)>0,"2回提出（下の行を使います）",IF(OR(H10="？",I10="？",J10="？"),"クラブ番号がちがう",IF(OR(AND(H10<>"",H10<>"？",COUNTIF(設定!$P$8:$P$27,H10)=0),AND(I10<>"",I10<>"？",COUNTIF(設定!$P$8:$P$27,I10)=0),AND(J10<>"",J10<>"？",COUNTIF(設定!$P$8:$P$27,J10)=0)),"クラブ名がちがう",IF(H10="","第1希望がない",IF(OR(AND(H10<>"",H10=I10),AND(H10<>"",H10=J10),AND(I10<>"",I10=J10)),"同じクラブを重複して希望","OK"))))))) | L10: =IF(A10="","",A10&"-"&B10&"-"&C10) | M10: =IF(OR(L10="",G10=""),"",IF(COUNTIF(L11:L$552,L10)=0,L10,""))
A11: 5 | B11: 梅 | C11: 12 | D11: 3 | E11: 8 | F11: 7 | G11: =IF(L11="","",IFERROR(INDEX(前年度名簿!$D$2:$D$451,MATCH(L11,前年度名簿!$F$2:$F$451,0)),"")) | H11: =IF(D11="","",IF(ISERROR(VALUE(D11)),D11&"",IF(AND(VALUE(D11)>=1,VALUE(D11)<=20),IF(INDEX(設定!$P$8:$P$27,VALUE(D11))="","？",INDEX(設定!$P$8:$P$27,VALUE(D11))),"？"))) | I11: =IF(E11="","",IF(ISERROR(VALUE(E11)),E11&"",IF(AND(VALUE(E11)>=1,VALUE(E11)<=20),IF(INDEX(設定!$P$8:$P$27,VALUE(E11))="","？",INDEX(設定!$P$8:$P$27,VALUE(E11))),"？"))) | J11: =IF(F11="","",IF(ISERROR(VALUE(F11)),F11&"",IF(AND(VALUE(F11)>=1,VALUE(F11)<=20),IF(INDEX(設定!$P$8:$P$27,VALUE(F11))="","？",INDEX(設定!$P$8:$P$27,VALUE(F11))),"？"))) | K11: =IF(L11="","",IF(G11="","名簿にいない",IF(COUNTIF(L12:L$552,L11)>0,"2回提出（下の行を使います）",IF(OR(H11="？",I11="？",J11="？"),"クラブ番号がちがう",IF(OR(AND(H11<>"",H11<>"？",COUNTIF(設定!$P$8:$P$27,H11)=0),AND(I11<>"",I11<>"？",COUNTIF(設定!$P$8:$P$27,I11)=0),AND(J11<>"",J11<>"？",COUNTIF(設定!$P$8:$P$27,J11)=0)),"クラブ名がちがう",IF(H11="","第1希望がない",IF(OR(AND(H11<>"",H11=I11),AND(H11<>"",H11=J11),AND(I11<>"",I11=J11)),"同じクラブを重複して希望","OK"))))))) | L11: =IF(A11="","",A11&"-"&B11&"-"&C11) | M11: =IF(OR(L11="",G11=""),"",IF(COUNTIF(L12:L$552,L11)=0,L11,""))
A12: 3 | B12: 松 | C12: 1 | D12: 2 | E12: 12 | F12: 9 | G12: =IF(L12="","",IFERROR(INDEX(前年度名簿!$D$2:$D$451,MATCH(L12,前年度名簿!$F$2:$F$451,0)),"")) | H12: =IF(D12="","",IF(ISERROR(VALUE(D12)),D12&"",IF(AND(VALUE(D12)>=1,VALUE(D12)<=20),IF(INDEX(設定!$P$8:$P$27,VALUE(D12))="","？",INDEX(設定!$P$8:$P$27,VALUE(D12))),"？"))) | I12: =IF(E12="","",IF(ISERROR(VALUE(E12)),E12&"",IF(AND(VALUE(E12)>=1,VALUE(E12)<=20),IF(INDEX(設定!$P$8:$P$27,VALUE(E12))="","？",INDEX(設定!$P$8:$P$27,VALUE(E12))),"？"))) | J12: =IF(F12="","",IF(ISERROR(VALUE(F12)),F12&"",IF(AND(VALUE(F12)>=1,VALUE(F12)<=20),IF(INDEX(設定!$P$8:$P$27,VALUE(F12))="","？",INDEX(設定!$P$8:$P$27,VALUE(F12))),"？"))) | K12: =IF(L12="","",IF(G12="","名簿にいない",IF(COUNTIF(L13:L$552,L12)>0,"2回提出（下の行を使います）",IF(OR(H12="？",I12="？",J12="？"),"クラブ番号がちがう",IF(OR(AND(H12<>"",H12<>"？",COUNTIF(設定!$P$8:$P$27,H12)=0),AND(I12<>"",I12<>"？",COUNTIF(設定!$P$8:$P$27,I12)=0),AND(J12<>"",J12<>"？",COUNTIF(設定!$P$8:$P$27,J12)=0)),"クラブ名がちがう",IF(H12="","第1希望がない",IF(OR(AND(H12<>"",H12=I12),AND(H12<>"",H12=J12),AND(I12<>"",I12=J12)),"同じクラブを重複して希望","OK"))))))) | L12: =IF(A12="","",A12&"-"&B12&"-"&C12) | M12: =IF(OR(L12="",G12=""),"",IF(COUNTIF(L13:L$552,L12)=0,L12,""))
A13: 3 | B13: 竹 | C13: 12 | D13: 3 | E13: 4 | F13: 2 | G13: =IF(L13="","",IFERROR(INDEX(前年度名簿!$D$2:$D$451,MATCH(L13,前年度名簿!$F$2:$F$451,0)),"")) | H13: =IF(D13="","",IF(ISERROR(VALUE(D13)),D13&"",IF(AND(VALUE(D13)>=1,VALUE(D13)<=20),IF(INDEX(設定!$P$8:$P$27,VALUE(D13))="","？",INDEX(設定!$P$8:$P$27,VALUE(D13))),"？"))) | I13: =IF(E13="","",IF(ISERROR(VALUE(E13)),E13&"",IF(AND(VALUE(E13)>=1,VALUE(E13)<=20),IF(INDEX(設定!$P$8:$P$27,VALUE(E13))="","？",INDEX(設定!$P$8:$P$27,VALUE(E13))),"？"))) | J13: =IF(F13="","",IF(ISERROR(VALUE(F13)),F13&"",IF(AND(VALUE(F13)>=1,VALUE(F13)<=20),IF(INDEX(設定!$P$8:$P$27,VALUE(F13))="","？",INDEX(設定!$P$8:$P$27,VALUE(F13))),"？"))) | K13: =IF(L13="","",IF(G13="","名簿にいない",IF(COUNTIF(L14:L$552,L13)>0,"2回提出（下の行を使います）",IF(OR(H13="？",I13="？",J13="？"),"クラブ番号がちがう",IF(OR(AND(H13<>"",H13<>"？",COUNTIF(設定!$P$8:$P$27,H13)=0),AND(I13<>"",I13<>"？",COUNTIF(設定!$P$8:$P$27,I13)=0),AND(J13<>"",J13<>"？",COUNTIF(設定!$P$8:$P$27,J13)=0)),"クラブ名がちがう",IF(H13="","第1希望がない",IF(OR(AND(H13<>"",H13=I13),AND(H13<>"",H13=J13),AND(I13<>"",I13=J13)),"同じクラブを重複して希望","OK"))))))) | L13: =IF(A13="","",A13&"-"&B13&"-"&C13) | M13: =IF(OR(L13="",G13=""),"",IF(COUNTIF(L14:L$552,L13)=0,L13,""))
... A41: 3 | B41: 月 | C41: 27 | D41: 10 | E41: 2 | F41: 11 | G41: =IF(L41="","",IFERROR(INDEX(前年度名簿!$D$2:$D$451,MATCH(L41,前年度名簿!$F$2:$F$451,0)),"")) | H41: =IF(D41="","",IF(ISERROR(VALUE(D41)),D41&"",IF(AND(VALUE(D41)>=1,VALUE(D41)<=20),IF(INDEX(設定!$P$8:$P$27,VALUE(D41))="","？",INDEX(設定!$P$8:$P$27,VALUE(D41))),"？"))) | I41: =IF(E41="","",IF(ISERROR(VALUE(E41)),E41&"",IF(AND(VALUE(E41)>=1,VALUE(E41)<=20),IF(INDEX(設定!$P$8:$P$27,VALUE(E41))="","？",INDEX(設定!$P$8:$P$27,VALUE(E41))),"？"))) | J41: =IF(F41="","",IF(ISERROR(VALUE(F41)),F41&"",IF(AND(VALUE(F41)>=1,VALUE(F41)<=20),IF(INDEX(設定!$P$8:$P$27,VALUE(F41))="","？",INDEX(設定!$P$8:$P$27,VALUE(F41))),"？"))) | K41: =IF(L41="","",IF(G41="","名簿にいない",IF(COUNTIF(L42:L$552,L41)>0,"2回提出（下の行を使います）",IF(OR(H41="？",I41="？",J41="？"),"クラブ番号がちがう",IF(OR(AND(H41<>"",H41<>"？",COUNTIF(設定!$P$8:$P$27,H41)=0),AND(I41<>"",I41<>"？",COUNTIF(設定!$P$8:$P$27,I41)=0),AND(J41<>"",J41<>"？",COUNTIF(設定!$P$8:$P$27,J41)=0)),"クラブ名がちがう",IF(H41="","第1希望がない",IF(OR(AND(H41<>"",H41=I41),AND(H41<>"",H41=J41),AND(I41<>"",I41=J41)),"同じクラブを重複して希望","OK"))))))) | L41: =IF(A41="","",A41&"-"&B41&"-"&C41) | M41: =IF(OR(L41="",G41=""),"",IF(COUNTIF(L42:L$552,L41)=0,L41,""))
A42: 4 | B42: 竹 | C42: 21 | D42: バドミントン | E42: イラスト | F42: 手芸 | G42: =IF(L42="","",IFERROR(INDEX(前年度名簿!$D$2:$D$451,MATCH(L42,前年度名簿!$F$2:$F$451,0)),"")) | H42: =IF(D42="","",IF(ISERROR(VALUE(D42)),D42&"",IF(AND(VALUE(D42)>=1,VALUE(D42)<=20),IF(INDEX(設定!$P$8:$P$27,VALUE(D42))="","？",INDEX(設定!$P$8:$P$27,VALUE(D42))),"？"))) | I42: =IF(E42="","",IF(ISERROR(VALUE(E42)),E42&"",IF(AND(VALUE(E42)>=1,VALUE(E42)<=20),IF(INDEX(設定!$P$8:$P$27,VALUE(E42))="","？",INDEX(設定!$P$8:$P$27,VALUE(E42))),"？"))) | J42: =IF(F42="","",IF(ISERROR(VALUE(F42)),F42&"",IF(AND(VALUE(F42)>=1,VALUE(F42)<=20),IF(INDEX(設定!$P$8:$P$27,VALUE(F42))="","？",INDEX(設定!$P$8:$P$27,VALUE(F42))),"？"))) | K42: =IF(L42="","",IF(G42="","名簿にいない",IF(COUNTIF(L43:L$552,L42)>0,"2回提出（下の行を使います）",IF(OR(H42="？",I42="？",J42="？"),"クラブ番号がちがう",IF(OR(AND(H42<>"",H42<>"？",COUNTIF(設定!$P$8:$P$27,H42)=0),AND(I42<>"",I42<>"？",COUNTIF(設定!$P$8:$P$27,I42)=0),AND(J42<>"",J42<>"？",COUNTIF(設定!$P$8:$P$27,J42)=0)),"クラブ名がちがう",IF(H42="","第1希望がない",IF(OR(AND(H42<>"",H42=I42),AND(H42<>"",H42=J42),AND(I42<>"",I42=J42)),"同じクラブを重複して希望","OK"))))))) | L42: =IF(A42="","",A42&"-"&B42&"-"&C42) | M42: =IF(OR(L42="",G42=""),"",IF(COUNTIF(L43:L$552,L42)=0,L42,""))
A43: 3 | B43: 松 | C43: 16 | D43: 室内ゲーム | E43: 手芸 | F43: 音楽 | G43: =IF(L43="","",IFERROR(INDEX(前年度名簿!$D$2:$D$451,MATCH(L43,前年度名簿!$F$2:$F$451,0)),"")) | H43: =IF(D43="","",IF(ISERROR(VALUE(D43)),D43&"",IF(AND(VALUE(D43)>=1,VALUE(D43)<=20),IF(INDEX(設定!$P$8:$P$27,VALUE(D43))="","？",INDEX(設定!$P$8:$P$27,VALUE(D43))),"？"))) | I43: =IF(E43="","",IF(ISERROR(VALUE(E43)),E43&"",IF(AND(VALUE(E43)>=1,VALUE(E43)<=20),IF(INDEX(設定!$P$8:$P$27,VALUE(E43))="","？",INDEX(設定!$P$8:$P$27,VALUE(E43))),"？"))) | J43: =IF(F43="","",IF(ISERROR(VALUE(F43)),F43&"",IF(AND(VALUE(F43)>=1,VALUE(F43)<=20),IF(INDEX(設定!$P$8:$P$27,VALUE(F43))="","？",INDEX(設定!$P$8:$P$27,VALUE(F43))),"？"))) | K43: =IF(L43="","",IF(G43="","名簿にいない",IF(COUNTIF(L44:L$552,L43)>0,"2回提出（下の行を使います）",IF(OR(H43="？",I43="？",J43="？"),"クラブ番号がちがう",IF(OR(AND(H43<>"",H43<>"？",COUNTIF(設定!$P$8:$P$27,H43)=0),AND(I43<>"",I43<>"？",COUNTIF(設定!$P$8:$P$27,I43)=0),AND(J43<>"",J43<>"？",COUNTIF(設定!$P$8:$P$27,J43)=0)),"クラブ名がちがう",IF(H43="","第1希望がない",IF(OR(AND(H43<>"",H43=I43),AND(H43<>"",H43=J43),AND(I43<>"",I43=J43)),"同じクラブを重複して希望","OK"))))))) | L43: =IF(A43="","",A43&"-"&B43&"-"&C43) | M43: =IF(OR(L43="",G43=""),"",IF(COUNTIF(L44:L$552,L43)=0,L43,""))
A44: 3 | B44: 松 | C44: 13 | D44: パソコン | E44: 手芸 | F44: 音楽 | G44: =IF(L44="","",IFERROR(INDEX(前年度名簿!$D$2:$D$451,MATCH(L44,前年度名簿!$F$2:$F$451,0)),"")) | H44: =IF(D44="","",IF(ISERROR(VALUE(D44)),D44&"",IF(AND(VALUE(D44)>=1,VALUE(D44)<=20),IF(INDEX(設定!$P$8:$P$27,VALUE(D44))="","？",INDEX(設定!$P$8:$P$27,VALUE(D44))),"？"))) | I44: =IF(E44="","",IF(ISERROR(VALUE(E44)),E44&"",IF(AND(VALUE(E44)>=1,VALUE(E44)<=20),IF(INDEX(設定!$P$8:$P$27,VALUE(E44))="","？",INDEX(設定!$P$8:$P$27,VALUE(E44))),"？"))) | J44: =IF(F44="","",IF(ISERROR(VALUE(F44)),F44&"",IF(AND(VALUE(F44)>=1,VALUE(F44)<=20),IF(INDEX(設定!$P$8:$P$27,VALUE(F44))="","？",INDEX(設定!$P$8:$P$27,VALUE(F44))),"？"))) | K44: =IF(L44="","",IF(G44="","名簿にいない",IF(COUNTIF(L45:L$552,L44)>0,"2回提出（下の行を使います）",IF(OR(H44="？",I44="？",J44="？"),"クラブ番号がちがう",IF(OR(AND(H44<>"",H44<>"？",COUNTIF(設定!$P$8:$P$27,H44)=0),AND(I44<>"",I44<>"？",COUNTIF(設定!$P$8:$P$27,I44)=0),AND(J44<>"",J44<>"？",COUNTIF(設定!$P$8:$P$27,J44)=0)),"クラブ名がちがう",IF(H44="","第1希望がない",IF(OR(AND(H44<>"",H44=I44),AND(H44<>"",H44=J44),AND(I44<>"",I44=J44)),"同じクラブを重複して希望","OK"))))))) | L44: =IF(A44="","",A44&"-"&B44&"-"&C44) | M44: =IF(OR(L44="",G44=""),"",IF(COUNTIF(L45:L$552,L44)=0,L44,""))
A45: 5 | B45: 松 | C45: 5 | D45: 3 | E45: 4 | F45: 5 | G45: =IF(L45="","",IFERROR(INDEX(前年度名簿!$D$2:$D$451,MATCH(L45,前年度名簿!$F$2:$F$451,0)),"")) | H45: =IF(D45="","",IF(ISERROR(VALUE(D45)),D45&"",IF(AND(VALUE(D45)>=1,VALUE(D45)<=20),IF(INDEX(設定!$P$8:$P$27,VALUE(D45))="","？",INDEX(設定!$P$8:$P$27,VALUE(D45))),"？"))) | I45: =IF(E45="","",IF(ISERROR(VALUE(E45)),E45&"",IF(AND(VALUE(E45)>=1,VALUE(E45)<=20),IF(INDEX(設定!$P$8:$P$27,VALUE(E45))="","？",INDEX(設定!$P$8:$P$27,VALUE(E45))),"？"))) | J45: =IF(F45="","",IF(ISERROR(VALUE(F45)),F45&"",IF(AND(VALUE(F45)>=1,VALUE(F45)<=20),IF(INDEX(設定!$P$8:$P$27,VALUE(F45))="","？",INDEX(設定!$P$8:$P$27,VALUE(F45))),"？"))) | K45: =IF(L45="","",IF(G45="","名簿にいない",IF(COUNTIF(L46:L$552,L45)>0,"2回提出（下の行を使います）",IF(OR(H45="？",I45="？",J45="？"),"クラブ番号がちがう",IF(OR(AND(H45<>"",H45<>"？",COUNTIF(設定!$P$8:$P$27,H45)=0),AND(I45<>"",I45<>"？",COUNTIF(設定!$P$8:$P$27,I45)=0),AND(J45<>"",J45<>"？",COUNTIF(設定!$P$8:$P$27,J45)=0)),"クラブ名がちがう",IF(H45="","第1希望がない",IF(OR(AND(H45<>"",H45=I45),AND(H45<>"",H45=J45),AND(I45<>"",I45=J45)),"同じクラブを重複して希望","OK"))))))) | L45: =IF(A45="","",A45&"-"&B45&"-"&C45) | M45: =IF(OR(L45="",G45=""),"",IF(COUNTIF(L46:L$552,L45)=0,L45,""))
A46: 5 | B46: 竹 | C46: 19 | D46: 2 | E46: 5 | F46: 11 | G46: =IF(L46="","",IFERROR(INDEX(前年度名簿!$D$2:$D$451,MATCH(L46,前年度名簿!$F$2:$F$451,0)),"")) | H46: =IF(D46="","",IF(ISERROR(VALUE(D46)),D46&"",IF(AND(VALUE(D46)>=1,VALUE(D46)<=20),IF(INDEX(設定!$P$8:$P$27,VALUE(D46))="","？",INDEX(設定!$P$8:$P$27,VALUE(D46))),"？"))) | I46: =IF(E46="","",IF(ISERROR(VALUE(E46)),E46&"",IF(AND(VALUE(E46)>=1,VALUE(E46)<=20),IF(INDEX(設定!$P$8:$P$27,VALUE(E46))="","？",INDEX(設定!$P$8:$P$27,VALUE(E46))),"？"))) | J46: =IF(F46="","",IF(ISERROR(VALUE(F46)),F46&"",IF(AND(VALUE(F46)>=1,VALUE(F46)<=20),IF(INDEX(設定!$P$8:$P$27,VALUE(F46))="","？",INDEX(設定!$P$8:$P$27,VALUE(F46))),"？"))) | K46: =IF(L46="","",IF(G46="","名簿にいない",IF(COUNTIF(L47:L$552,L46)>0,"2回提出（下の行を使います）",IF(OR(H46="？",I46="？",J46="？"),"クラブ番号がちがう",IF(OR(AND(H46<>"",H46<>"？",COUNTIF(設定!$P$8:$P$27,H46)=0),AND(I46<>"",I46<>"？",COUNTIF(設定!$P$8:$P$27,I46)=0),AND(J46<>"",J46<>"？",COUNTIF(設定!$P$8:$P$27,J46)=0)),"クラブ名がちがう",IF(H46="","第1希望がない",IF(OR(AND(H46<>"",H46=I46),AND(H46<>"",H46=J46),AND(I46<>"",I46=J46)),"同じクラブを重複して希望","OK"))))))) | L46: =IF(A46="","",A46&"-"&B46&"-"&C46) | M46: =IF(OR(L46="",G46=""),"",IF(COUNTIF(L47:L$552,L46)=0,L46,""))
A47: 3 | B47: 松 | C47: 26 | D47: 7 | E47: 1 | F47: 3 | G47: =IF(L47="","",IFERROR(INDEX(前年度名簿!$D$2:$D$451,MATCH(L47,前年度名簿!$F$2:$F$451,0)),"")) | H47: =IF(D47="","",IF(ISERROR(VALUE(D47)),D47&"",IF(AND(VALUE(D47)>=1,VALUE(D47)<=20),IF(INDEX(設定!$P$8:$P$27,VALUE(D47))="","？",INDEX(設定!$P$8:$P$27,VALUE(D47))),"？"))) | I47: =IF(E47="","",IF(ISERROR(VALUE(E47)),E47&"",IF(AND(VALUE(E47)>=1,VALUE(E47)<=20),IF(INDEX(設定!$P$8:$P$27,VALUE(E47))="","？",INDEX(設定!$P$8:$P$27,VALUE(E47))),"？"))) | J47: =IF(F47="","",IF(ISERROR(VALUE(F47)),F47&"",IF(AND(VALUE(F47)>=1,VALUE(F47)<=20),IF(INDEX(設定!$P$8:$P$27,VALUE(F47))="","？",INDEX(設定!$P$8:$P$27,VALUE(F47))),"？"))) | K47: =IF(L47="","",IF(G47="","名簿にいない",IF(COUNTIF(L48:L$552,L47)>0,"2回提出（下の行を使います）",IF(OR(H47="？",I47="？",J47="？"),"クラブ番号がちがう",IF(OR(AND(H47<>"",H47<>"？",COUNTIF(設定!$P$8:$P$27,H47)=0),AND(I47<>"",I47<>"？",COUNTIF(設定!$P$8:$P$27,I47)=0),AND(J47<>"",J47<>"？",COUNTIF(設定!$P$8:$P$27,J47)=0)),"クラブ名がちがう",IF(H47="","第1希望がない",IF(OR(AND(H47<>"",H47=I47),AND(H47<>"",H47=J47),AND(I47<>"",I47=J47)),"同じクラブを重複して希望","OK"))))))) | L47: =IF(A47="","",A47&"-"&B47&"-"&C47) | M47: =IF(OR(L47="",G47=""),"",IF(COUNTIF(L48:L$552,L47)=0,L47,""))
A48: 5 | B48: 梅 | C48: 9 | D48: 3 | E48: 10 | F48: 6 | G48: =IF(L48="","",IFERROR(INDEX(前年度名簿!$D$2:$D$451,MATCH(L48,前年度名簿!$F$2:$F$451,0)),"")) | H48: =IF(D48="","",IF(ISERROR(VALUE(D48)),D48&"",IF(AND(VALUE(D48)>=1,VALUE(D48)<=20),IF(INDEX(設定!$P$8:$P$27,VALUE(D48))="","？",INDEX(設定!$P$8:$P$27,VALUE(D48))),"？"))) | I48: =IF(E48="","",IF(ISERROR(VALUE(E48)),E48&"",IF(AND(VALUE(E48)>=1,VALUE(E48)<=20),IF(INDEX(設定!$P$8:$P$27,VALUE(E48))="","？",INDEX(設定!$P$8:$P$27,VALUE(E48))),"？"))) | J48: =IF(F48="","",IF(ISERROR(VALUE(F48)),F48&"",IF(AND(VALUE(F48)>=1,VALUE(F48)<=20),IF(INDEX(設定!$P$8:$P$27,VALUE(F48))="","？",INDEX(設定!$P$8:$P$27,VALUE(F48))),"？"))) | K48: =IF(L48="","",IF(G48="","名簿にいない",IF(COUNTIF(L49:L$552,L48)>0,"2回提出（下の行を使います）",IF(OR(H48="？",I48="？",J48="？"),"クラブ番号がちがう",IF(OR(AND(H48<>"",H48<>"？",COUNTIF(設定!$P$8:$P$27,H48)=0),AND(I48<>"",I48<>"？",COUNTIF(設定!$P$8:$P$27,I48)=0),AND(J48<>"",J48<>"？",COUNTIF(設定!$P$8:$P$27,J48)=0)),"クラブ名がちがう",IF(H48="","第1希望がない",IF(OR(AND(H48<>"",H48=I48),AND(H48<>"",H48=J48),AND(I48<>"",I48=J48)),"同じクラブを重複して希望","OK"))))))) | L48: =IF(A48="","",A48&"-"&B48&"-"&C48) | M48: =IF(OR(L48="",G48=""),"",IF(COUNTIF(L49:L$552,L48)=0,L48,""))
A49: 4 | B49: 月 | C49: 21 | D49: 10 | E49: 12 | F49: 9 | G49: =IF(L49="","",IFERROR(INDEX(前年度名簿!$D$2:$D$451,MATCH(L49,前年度名簿!$F$2:$F$451,0)),"")) | H49: =IF(D49="","",IF(ISERROR(VALUE(D49)),D49&"",IF(AND(VALUE(D49)>=1,VALUE(D49)<=20),IF(INDEX(設定!$P$8:$P$27,VALUE(D49))="","？",INDEX(設定!$P$8:$P$27,VALUE(D49))),"？"))) | I49: =IF(E49="","",IF(ISERROR(VALUE(E49)),E49&"",IF(AND(VALUE(E49)>=1,VALUE(E49)<=20),IF(INDEX(設定!$P$8:$P$27,VALUE(E49))="","？",INDEX(設定!$P$8:$P$27,VALUE(E49))),"？"))) | J49: =IF(F49="","",IF(ISERROR(VALUE(F49)),F49&"",IF(AND(VALUE(F49)>=1,VALUE(F49)<=20),IF(INDEX(設定!$P$8:$P$27,VALUE(F49))="","？",INDEX(設定!$P$8:$P$27,VALUE(F49))),"？"))) | K49: =IF(L49="","",IF(G49="","名簿にいない",IF(COUNTIF(L50:L$552,L49)>0,"2回提出（下の行を使います）",IF(OR(H49="？",I49="？",J49="？"),"クラブ番号がちがう",IF(OR(AND(H49<>"",H49<>"？",COUNTIF(設定!$P$8:$P$27,H49)=0),AND(I49<>"",I49<>"？",COUNTIF(設定!$P$8:$P$27,I49)=0),AND(J49<>"",J49<>"？",COUNTIF(設定!$P$8:$P$27,J49)=0)),"クラブ名がちがう",IF(H49="","第1希望がない",IF(OR(AND(H49<>"",H49=I49),AND(H49<>"",H49=J49),AND(I49<>"",I49=J49)),"同じクラブを重複して希望","OK"))))))) | L49: =IF(A49="","",A49&"-"&B49&"-"&C49) | M49: =IF(OR(L49="",G49=""),"",IF(COUNTIF(L50:L$552,L49)=0,L49,""))
A50: 3 | B50: 松 | C50: 30 | D50: 2 | E50: 3 | F50: 8 | G50: =IF(L50="","",IFERROR(INDEX(前年度名簿!$D$2:$D$451,MATCH(L50,前年度名簿!$F$2:$F$451,0)),"")) | H50: =IF(D50="","",IF(ISERROR(VALUE(D50)),D50&"",IF(AND(VALUE(D50)>=1,VALUE(D50)<=20),IF(INDEX(設定!$P$8:$P$27,VALUE(D50))="","？",INDEX(設定!$P$8:$P$27,VALUE(D50))),"？"))) | I50: =IF(E50="","",IF(ISERROR(VALUE(E50)),E50&"",IF(AND(VALUE(E50)>=1,VALUE(E50)<=20),IF(INDEX(設定!$P$8:$P$27,VALUE(E50))="","？",INDEX(設定!$P$8:$P$27,VALUE(E50))),"？"))) | J50: =IF(F50="","",IF(ISERROR(VALUE(F50)),F50&"",IF(AND(VALUE(F50)>=1,VALUE(F50)<=20),IF(INDEX(設定!$P$8:$P$27,VALUE(F50))="","？",INDEX(設定!$P$8:$P$27,VALUE(F50))),"？"))) | K50: =IF(L50="","",IF(G50="","名簿にいない",IF(COUNTIF(L51:L$552,L50)>0,"2回提出（下の行を使います）",IF(OR(H50="？",I50="？",J50="？"),"クラブ番号がちがう",IF(OR(AND(H50<>"",H50<>"？",COUNTIF(設定!$P$8:$P$27,H50)=0),AND(I50<>"",I50<>"？",COUNTIF(設定!$P$8:$P$27,I50)=0),AND(J50<>"",J50<>"？",COUNTIF(設定!$P$8:$P$27,J50)=0)),"クラブ名がちがう",IF(H50="","第1希望がない",IF(OR(AND(H50<>"",H50=I50),AND(H50<>"",H50=J50),AND(I50<>"",I50=J50)),"同じクラブを重複して希望","OK"))))))) | L50: =IF(A50="","",A50&"-"&B50&"-"&C50) | M50: =IF(OR(L50="",G50=""),"",IF(COUNTIF(L51:L$552,L50)=0,L50,""))
A51: 4 | B51: 月 | C51: 27 | D51: 3 | E51: 4 | F51: 2 | G51: =IF(L51="","",IFERROR(INDEX(前年度名簿!$D$2:$D$451,MATCH(L51,前年度名簿!$F$2:$F$451,0)),"")) | H51: =IF(D51="","",IF(ISERROR(VALUE(D51)),D51&"",IF(AND(VALUE(D51)>=1,VALUE(D51)<=20),IF(INDEX(設定!$P$8:$P$27,VALUE(D51))="","？",INDEX(設定!$P$8:$P$27,VALUE(D51))),"？"))) | I51: =IF(E51="","",IF(ISERROR(VALUE(E51)),E51&"",IF(AND(VALUE(E51)>=1,VALUE(E51)<=20),IF(INDEX(設定!$P$8:$P$27,VALUE(E51))="","？",INDEX(設定!$P$8:$P$27,VALUE(E51))),"？"))) | J51: =IF(F51="","",IF(ISERROR(VALUE(F51)),F51&"",IF(AND(VALUE(F51)>=1,VALUE(F51)<=20),IF(INDEX(設定!$P$8:$P$27,VALUE(F51))="","？",INDEX(設定!$P$8:$P$27,VALUE(F51))),"？"))) | K51: =IF(L51="","",IF(G51="","名簿にいない",IF(COUNTIF(L52:L$552,L51)>0,"2回提出（下の行を使います）",IF(OR(H51="？",I51="？",J51="？"),"クラブ番号がちがう",IF(OR(AND(H51<>"",H51<>"？",COUNTIF(設定!$P$8:$P$27,H51)=0),AND(I51<>"",I51<>"？",COUNTIF(設定!$P$8:$P$27,I51)=0),AND(J51<>"",J51<>"？",COUNTIF(設定!$P$8:$P$27,J51)=0)),"クラブ名がちがう",IF(H51="","第1希望がない",IF(OR(AND(H51<>"",H51=I51),AND(H51<>"",H51=J51),AND(I51<>"",I51=J51)),"同じクラブを重複して希望","OK"))))))) | L51: =IF(A51="","",A51&"-"&B51&"-"&C51) | M51: =IF(OR(L51="",G51=""),"",IF(COUNTIF(L52:L$552,L51)=0,L51,""))
A52: 3 | B52: 月 | C52: 25 | D52: 9 | E52: 3 | F52: 6 | G52: =IF(L52="","",IFERROR(INDEX(前年度名簿!$D$2:$D$451,MATCH(L52,前年度名簿!$F$2:$F$451,0)),"")) | H52: =IF(D52="","",IF(ISERROR(VALUE(D52)),D52&"",IF(AND(VALUE(D52)>=1,VALUE(D52)<=20),IF(INDEX(設定!$P$8:$P$27,VALUE(D52))="","？",INDEX(設定!$P$8:$P$27,VALUE(D52))),"？"))) | I52: =IF(E52="","",IF(ISERROR(VALUE(E52)),E52&"",IF(AND(VALUE(E52)>=1,VALUE(E52)<=20),IF(INDEX(設定!$P$8:$P$27,VALUE(E52))="","？",INDEX(設定!$P$8:$P$27,VALUE(E52))),"？"))) | J52: =IF(F52="","",IF(ISERROR(VALUE(F52)),F52&"",IF(AND(VALUE(F52)>=1,VALUE(F52)<=20),IF(INDEX(設定!$P$8:$P$27,VALUE(F52))="","？",INDEX(設定!$P$8:$P$27,VALUE(F52))),"？"))) | K52: =IF(L52="","",IF(G52="","名簿にいない",IF(COUNTIF(L53:L$552,L52)>0,"2回提出（下の行を使います）",IF(OR(H52="？",I52="？",J52="？"),"クラブ番号がちがう",IF(OR(AND(H52<>"",H52<>"？",COUNTIF(設定!$P$8:$P$27,H52)=0),AND(I52<>"",I52<>"？",COUNTIF(設定!$P$8:$P$27,I52)=0),AND(J52<>"",J52<>"？",COUNTIF(設定!$P$8:$P$27,J52)=0)),"クラブ名がちがう",IF(H52="","第1希望がない",IF(OR(AND(H52<>"",H52=I52),AND(H52<>"",H52=J52),AND(I52<>"",I52=J52)),"同じクラブを重複して希望","OK"))))))) | L52: =IF(A52="","",A52&"-"&B52&"-"&C52) | M52: =IF(OR(L52="",G52=""),"",IF(COUNTIF(L53:L$552,L52)=0,L52,""))
A53: 3 | B53: 月 | C53: 28 | D53: 11 | E53: 6 | F53: 7 | G53: =IF(L53="","",IFERROR(INDEX(前年度名簿!$D$2:$D$451,MATCH(L53,前年度名簿!$F$2:$F$451,0)),"")) | H53: =IF(D53="","",IF(ISERROR(VALUE(D53)),D53&"",IF(AND(VALUE(D53)>=1,VALUE(D53)<=20),IF(INDEX(設定!$P$8:$P$27,VALUE(D53))="","？",INDEX(設定!$P$8:$P$27,VALUE(D53))),"？"))) | I53: =IF(E53="","",IF(ISERROR(VALUE(E53)),E53&"",IF(AND(VALUE(E53)>=1,VALUE(E53)<=20),IF(INDEX(設定!$P$8:$P$27,VALUE(E53))="","？",INDEX(設定!$P$8:$P$27,VALUE(E53))),"？"))) | J53: =IF(F53="","",IF(ISERROR(VALUE(F53)),F53&"",IF(AND(VALUE(F53)>=1,VALUE(F53)<=20),IF(INDEX(設定!$P$8:$P$27,VALUE(F53))="","？",INDEX(設定!$P$8:$P$27,VALUE(F53))),"？"))) | K53: =IF(L53="","",IF(G53="","名簿にいない",IF(COUNTIF(L54:L$552,L53)>0,"2回提出（下の行を使います）",IF(OR(H53="？",I53="？",J53="？"),"クラブ番号がちがう",IF(OR(AND(H53<>"",H53<>"？",COUNTIF(設定!$P$8:$P$27,H53)=0),AND(I53<>"",I53<>"？",COUNTIF(設定!$P$8:$P$27,I53)=0),AND(J53<>"",J53<>"？",COUNTIF(設定!$P$8:$P$27,J53)=0)),"クラブ名がちがう",IF(H53="","第1希望がない",IF(OR(AND(H53<>"",H53=I53),AND(H53<>"",H53=J53),AND(I53<>"",I53=J53)),"同じクラブを重複して希望","OK"))))))) | L53: =IF(A53="","",A53&"-"&B53&"-"&C53) | M53: =IF(OR(L53="",G53=""),"",IF(COUNTIF(L54:L$552,L53)=0,L53,""))
A54: 4 | B54: 竹 | C54: 22 | D54: 7 | E54: 8 | F54: 4 | G54: =IF(L54="","",IFERROR(INDEX(前年度名簿!$D$2:$D$451,MATCH(L54,前年度名簿!$F$2:$F$451,0)),"")) | H54: =IF(D54="","",IF(ISERROR(VALUE(D54)),D54&"",IF(AND(VALUE(D54)>=1,VALUE(D54)<=20),IF(INDEX(設定!$P$8:$P$27,VALUE(D54))="","？",INDEX(設定!$P$8:$P$27,VALUE(D54))),"？"))) | I54: =IF(E54="","",IF(ISERROR(VALUE(E54)),E54&"",IF(AND(VALUE(E54)>=1,VALUE(E54)<=20),IF(INDEX(設定!$P$8:$P$27,VALUE(E54))="","？",INDEX(設定!$P$8:$P$27,VALUE(E54))),"？"))) | J54: =IF(F54="","",IF(ISERROR(VALUE(F54)),F54&"",IF(AND(VALUE(F54)>=1,VALUE(F54)<=20),IF(INDEX(設定!$P$8:$P$27,VALUE(F54))="","？",INDEX(設定!$P$8:$P$27,VALUE(F54))),"？"))) | K54: =IF(L54="","",IF(G54="","名簿にいない",IF(COUNTIF(L55:L$552,L54)>0,"2回提出（下の行を使います）",IF(OR(H54="？",I54="？",J54="？"),"クラブ番号がちがう",IF(OR(AND(H54<>"",H54<>"？",COUNTIF(設定!$P$8:$P$27,H54)=0),AND(I54<>"",I54<>"？",COUNTIF(設定!$P$8:$P$27,I54)=0),AND(J54<>"",J54<>"？",COUNTIF(設定!$P$8:$P$27,J54)=0)),"クラブ名がちがう",IF(H54="","第1希望がない",IF(OR(AND(H54<>"",H54=I54),AND(H54<>"",H54=J54),AND(I54<>"",I54=J54)),"同じクラブを重複して希望","OK"))))))) | L54: =IF(A54="","",A54&"-"&B54&"-"&C54) | M54: =IF(OR(L54="",G54=""),"",IF(COUNTIF(L55:L$552,L54)=0,L54,""))
A55: 3 | B55: 梅 | C55: 2 | D55: 7 | E55: 8 | F55: 9 | G55: =IF(L55="","",IFERROR(INDEX(前年度名簿!$D$2:$D$451,MATCH(L55,前年度名簿!$F$2:$F$451,0)),"")) | H55: =IF(D55="","",IF(ISERROR(VALUE(D55)),D55&"",IF(AND(VALUE(D55)>=1,VALUE(D55)<=20),IF(INDEX(設定!$P$8:$P$27,VALUE(D55))="","？",INDEX(設定!$P$8:$P$27,VALUE(D55))),"？"))) | I55: =IF(E55="","",IF(ISERROR(VALUE(E55)),E55&"",IF(AND(VALUE(E55)>=1,VALUE(E55)<=20),IF(INDEX(設定!$P$8:$P$27,VALUE(E55))="","？",INDEX(設定!$P$8:$P$27,VALUE(E55))),"？"))) | J55: =IF(F55="","",IF(ISERROR(VALUE(F55)),F55&"",IF(AND(VALUE(F55)>=1,VALUE(F55)<=20),IF(INDEX(設定!$P$8:$P$27,VALUE(F55))="","？",INDEX(設定!$P$8:$P$27,VALUE(F55))),"？"))) | K55: =IF(L55="","",IF(G55="","名簿にいない",IF(COUNTIF(L56:L$552,L55)>0,"2回提出（下の行を使います）",IF(OR(H55="？",I55="？",J55="？"),"クラブ番号がちがう",IF(OR(AND(H55<>"",H55<>"？",COUNTIF(設定!$P$8:$P$27,H55)=0),AND(I55<>"",I55<>"？",COUNTIF(設定!$P$8:$P$27,I55)=0),AND(J55<>"",J55<>"？",COUNTIF(設定!$P$8:$P$27,J55)=0)),"クラブ名がちがう",IF(H55="","第1希望がない",IF(OR(AND(H55<>"",H55=I55),AND(H55<>"",H55=J55),AND(I55<>"",I55=J55)),"同じクラブを重複して希望","OK"))))))) | L55: =IF(A55="","",A55&"-"&B55&"-"&C55) | M55: =IF(OR(L55="",G55=""),"",IF(COUNTIF(L56:L$552,L55)=0,L55,""))
A56: 3 | B56: 竹 | C56: 10 | D56: 4 | E56: 10 | F56: 6 | G56: =IF(L56="","",IFERROR(INDEX(前年度名簿!$D$2:$D$451,MATCH(L56,前年度名簿!$F$2:$F$451,0)),"")) | H56: =IF(D56="","",IF(ISERROR(VALUE(D56)),D56&"",IF(AND(VALUE(D56)>=1,VALUE(D56)<=20),IF(INDEX(設定!$P$8:$P$27,VALUE(D56))="","？",INDEX(設定!$P$8:$P$27,VALUE(D56))),"？"))) | I56: =IF(E56="","",IF(ISERROR(VALUE(E56)),E56&"",IF(AND(VALUE(E56)>=1,VALUE(E56)<=20),IF(INDEX(設定!$P$8:$P$27,VALUE(E56))="","？",INDEX(設定!$P$8:$P$27,VALUE(E56))),"？"))) | J56: =IF(F56="","",IF(ISERROR(VALUE(F56)),F56&"",IF(AND(VALUE(F56)>=1,VALUE(F56)<=20),IF(INDEX(設定!$P$8:$P$27,VALUE(F56))="","？",INDEX(設定!$P$8:$P$27,VALUE(F56))),"？"))) | K56: =IF(L56="","",IF(G56="","名簿にいない",IF(COUNTIF(L57:L$552,L56)>0,"2回提出（下の行を使います）",IF(OR(H56="？",I56="？",J56="？"),"クラブ番号がちがう",IF(OR(AND(H56<>"",H56<>"？",COUNTIF(設定!$P$8:$P$27,H56)=0),AND(I56<>"",I56<>"？",COUNTIF(設定!$P$8:$P$27,I56)=0),AND(J56<>"",J56<>"？",COUNTIF(設定!$P$8:$P$27,J56)=0)),"クラブ名がちがう",IF(H56="","第1希望がない",IF(OR(AND(H56<>"",H56=I56),AND(H56<>"",H56=J56),AND(I56<>"",I56=J56)),"同じクラブを重複して希望","OK"))))))) | L56: =IF(A56="","",A56&"-"&B56&"-"&C56) | M56: =IF(OR(L56="",G56=""),"",IF(COUNTIF(L57:L$552,L56)=0,L56,""))
... A359: 5 | B359: 松 | C359: 9 | D359: 4 | E359: 12 | F359: 6 | G359: =IF(L359="","",IFERROR(INDEX(前年度名簿!$D$2:$D$451,MATCH(L359,前年度名簿!$F$2:$F$451,0)),"")) | H359: =IF(D359="","",IF(ISERROR(VALUE(D359)),D359&"",IF(AND(VALUE(D359)>=1,VALUE(D359)<=20),IF(INDEX(設定!$P$8:$P$27,VALUE(D359))="","？",INDEX(設定!$P$8:$P$27,VALUE(D359))),"？"))) | I359: =IF(E359="","",IF(ISERROR(VALUE(E359)),E359&"",IF(AND(VALUE(E359)>=1,VALUE(E359)<=20),IF(INDEX(設定!$P$8:$P$27,VALUE(E359))="","？",INDEX(設定!$P$8:$P$27,VALUE(E359))),"？"))) | J359: =IF(F359="","",IF(ISERROR(VALUE(F359)),F359&"",IF(AND(VALUE(F359)>=1,VALUE(F359)<=20),IF(INDEX(設定!$P$8:$P$27,VALUE(F359))="","？",INDEX(設定!$P$8:$P$27,VALUE(F359))),"？"))) | K359: =IF(L359="","",IF(G359="","名簿にいない",IF(COUNTIF(L360:L$552,L359)>0,"2回提出（下の行を使います）",IF(OR(H359="？",I359="？",J359="？"),"クラブ番号がちがう",IF(OR(AND(H359<>"",H359<>"？",COUNTIF(設定!$P$8:$P$27,H359)=0),AND(I359<>"",I359<>"？",COUNTIF(設定!$P$8:$P$27,I359)=0),AND(J359<>"",J359<>"？",COUNTIF(設定!$P$8:$P$27,J359)=0)),"クラブ名がちがう",IF(H359="","第1希望がない",IF(OR(AND(H359<>"",H359=I359),AND(H359<>"",H359=J359),AND(I359<>"",I359=J359)),"同じクラブを重複して希望","OK"))))))) | L359: =IF(A359="","",A359&"-"&B359&"-"&C359) | M359: =IF(OR(L359="",G359=""),"",IF(COUNTIF(L360:L$552,L359)=0,L359,""))
G360: =IF(L360="","",IFERROR(INDEX(前年度名簿!$D$2:$D$451,MATCH(L360,前年度名簿!$F$2:$F$451,0)),"")) | H360: =IF(D360="","",IF(ISERROR(VALUE(D360)),D360&"",IF(AND(VALUE(D360)>=1,VALUE(D360)<=20),IF(INDEX(設定!$P$8:$P$27,VALUE(D360))="","？",INDEX(設定!$P$8:$P$27,VALUE(D360))),"？"))) | I360: =IF(E360="","",IF(ISERROR(VALUE(E360)),E360&"",IF(AND(VALUE(E360)>=1,VALUE(E360)<=20),IF(INDEX(設定!$P$8:$P$27,VALUE(E360))="","？",INDEX(設定!$P$8:$P$27,VALUE(E360))),"？"))) | J360: =IF(F360="","",IF(ISERROR(VALUE(F360)),F360&"",IF(AND(VALUE(F360)>=1,VALUE(F360)<=20),IF(INDEX(設定!$P$8:$P$27,VALUE(F360))="","？",INDEX(設定!$P$8:$P$27,VALUE(F360))),"？"))) | K360: =IF(L360="","",IF(G360="","名簿にいない",IF(COUNTIF(L361:L$552,L360)>0,"2回提出（下の行を使います）",IF(OR(H360="？",I360="？",J360="？"),"クラブ番号がちがう",IF(OR(AND(H360<>"",H360<>"？",COUNTIF(設定!$P$8:$P$27,H360)=0),AND(I360<>"",I360<>"？",COUNTIF(設定!$P$8:$P$27,I360)=0),AND(J360<>"",J360<>"？",COUNTIF(設定!$P$8:$P$27,J360)=0)),"クラブ名がちがう",IF(H360="","第1希望がない",IF(OR(AND(H360<>"",H360=I360),AND(H360<>"",H360=J360),AND(I360<>"",I360=J360)),"同じクラブを重複して希望","OK"))))))) | L360: =IF(A360="","",A360&"-"&B360&"-"&C360) | M360: =IF(OR(L360="",G360=""),"",IF(COUNTIF(L361:L$552,L360)=0,L360,""))
G361: =IF(L361="","",IFERROR(INDEX(前年度名簿!$D$2:$D$451,MATCH(L361,前年度名簿!$F$2:$F$451,0)),"")) | H361: =IF(D361="","",IF(ISERROR(VALUE(D361)),D361&"",IF(AND(VALUE(D361)>=1,VALUE(D361)<=20),IF(INDEX(設定!$P$8:$P$27,VALUE(D361))="","？",INDEX(設定!$P$8:$P$27,VALUE(D361))),"？"))) | I361: =IF(E361="","",IF(ISERROR(VALUE(E361)),E361&"",IF(AND(VALUE(E361)>=1,VALUE(E361)<=20),IF(INDEX(設定!$P$8:$P$27,VALUE(E361))="","？",INDEX(設定!$P$8:$P$27,VALUE(E361))),"？"))) | J361: =IF(F361="","",IF(ISERROR(VALUE(F361)),F361&"",IF(AND(VALUE(F361)>=1,VALUE(F361)<=20),IF(INDEX(設定!$P$8:$P$27,VALUE(F361))="","？",INDEX(設定!$P$8:$P$27,VALUE(F361))),"？"))) | K361: =IF(L361="","",IF(G361="","名簿にいない",IF(COUNTIF(L362:L$552,L361)>0,"2回提出（下の行を使います）",IF(OR(H361="？",I361="？",J361="？"),"クラブ番号がちがう",IF(OR(AND(H361<>"",H361<>"？",COUNTIF(設定!$P$8:$P$27,H361)=0),AND(I361<>"",I361<>"？",COUNTIF(設定!$P$8:$P$27,I361)=0),AND(J361<>"",J361<>"？",COUNTIF(設定!$P$8:$P$27,J361)=0)),"クラブ名がちがう",IF(H361="","第1希望がない",IF(OR(AND(H361<>"",H361=I361),AND(H361<>"",H361=J361),AND(I361<>"",I361=J361)),"同じクラブを重複して希望","OK"))))))) | L361: =IF(A361="","",A361&"-"&B361&"-"&C361) | M361: =IF(OR(L361="",G361=""),"",IF(COUNTIF(L362:L$552,L361)=0,L361,""))
G362: =IF(L362="","",IFERROR(INDEX(前年度名簿!$D$2:$D$451,MATCH(L362,前年度名簿!$F$2:$F$451,0)),"")) | H362: =IF(D362="","",IF(ISERROR(VALUE(D362)),D362&"",IF(AND(VALUE(D362)>=1,VALUE(D362)<=20),IF(INDEX(設定!$P$8:$P$27,VALUE(D362))="","？",INDEX(設定!$P$8:$P$27,VALUE(D362))),"？"))) | I362: =IF(E362="","",IF(ISERROR(VALUE(E362)),E362&"",IF(AND(VALUE(E362)>=1,VALUE(E362)<=20),IF(INDEX(設定!$P$8:$P$27,VALUE(E362))="","？",INDEX(設定!$P$8:$P$27,VALUE(E362))),"？"))) | J362: =IF(F362="","",IF(ISERROR(VALUE(F362)),F362&"",IF(AND(VALUE(F362)>=1,VALUE(F362)<=20),IF(INDEX(設定!$P$8:$P$27,VALUE(F362))="","？",INDEX(設定!$P$8:$P$27,VALUE(F362))),"？"))) | K362: =IF(L362="","",IF(G362="","名簿にいない",IF(COUNTIF(L363:L$552,L362)>0,"2回提出（下の行を使います）",IF(OR(H362="？",I362="？",J362="？"),"クラブ番号がちがう",IF(OR(AND(H362<>"",H362<>"？",COUNTIF(設定!$P$8:$P$27,H362)=0),AND(I362<>"",I362<>"？",COUNTIF(設定!$P$8:$P$27,I362)=0),AND(J362<>"",J362<>"？",COUNTIF(設定!$P$8:$P$27,J362)=0)),"クラブ名がちがう",IF(H362="","第1希望がない",IF(OR(AND(H362<>"",H362=I362),AND(H362<>"",H362=J362),AND(I362<>"",I362=J362)),"同じクラブを重複して希望","OK"))))))) | L362: =IF(A362="","",A362&"-"&B362&"-"&C362) | M362: =IF(OR(L362="",G362=""),"",IF(COUNTIF(L363:L$552,L362)=0,L362,""))
G363: =IF(L363="","",IFERROR(INDEX(前年度名簿!$D$2:$D$451,MATCH(L363,前年度名簿!$F$2:$F$451,0)),"")) | H363: =IF(D363="","",IF(ISERROR(VALUE(D363)),D363&"",IF(AND(VALUE(D363)>=1,VALUE(D363)<=20),IF(INDEX(設定!$P$8:$P$27,VALUE(D363))="","？",INDEX(設定!$P$8:$P$27,VALUE(D363))),"？"))) | I363: =IF(E363="","",IF(ISERROR(VALUE(E363)),E363&"",IF(AND(VALUE(E363)>=1,VALUE(E363)<=20),IF(INDEX(設定!$P$8:$P$27,VALUE(E363))="","？",INDEX(設定!$P$8:$P$27,VALUE(E363))),"？"))) | J363: =IF(F363="","",IF(ISERROR(VALUE(F363)),F363&"",IF(AND(VALUE(F363)>=1,VALUE(F363)<=20),IF(INDEX(設定!$P$8:$P$27,VALUE(F363))="","？",INDEX(設定!$P$8:$P$27,VALUE(F363))),"？"))) | K363: =IF(L363="","",IF(G363="","名簿にいない",IF(COUNTIF(L364:L$552,L363)>0,"2回提出（下の行を使います）",IF(OR(H363="？",I363="？",J363="？"),"クラブ番号がちがう",IF(OR(AND(H363<>"",H363<>"？",COUNTIF(設定!$P$8:$P$27,H363)=0),AND(I363<>"",I363<>"？",COUNTIF(設定!$P$8:$P$27,I363)=0),AND(J363<>"",J363<>"？",COUNTIF(設定!$P$8:$P$27,J363)=0)),"クラブ名がちがう",IF(H363="","第1希望がない",IF(OR(AND(H363<>"",H363=I363),AND(H363<>"",H363=J363),AND(I363<>"",I363=J363)),"同じクラブを重複して希望","OK"))))))) | L363: =IF(A363="","",A363&"-"&B363&"-"&C363) | M363: =IF(OR(L363="",G363=""),"",IF(COUNTIF(L364:L$552,L363)=0,L363,""))
G364: =IF(L364="","",IFERROR(INDEX(前年度名簿!$D$2:$D$451,MATCH(L364,前年度名簿!$F$2:$F$451,0)),"")) | H364: =IF(D364="","",IF(ISERROR(VALUE(D364)),D364&"",IF(AND(VALUE(D364)>=1,VALUE(D364)<=20),IF(INDEX(設定!$P$8:$P$27,VALUE(D364))="","？",INDEX(設定!$P$8:$P$27,VALUE(D364))),"？"))) | I364: =IF(E364="","",IF(ISERROR(VALUE(E364)),E364&"",IF(AND(VALUE(E364)>=1,VALUE(E364)<=20),IF(INDEX(設定!$P$8:$P$27,VALUE(E364))="","？",INDEX(設定!$P$8:$P$27,VALUE(E364))),"？"))) | J364: =IF(F364="","",IF(ISERROR(VALUE(F364)),F364&"",IF(AND(VALUE(F364)>=1,VALUE(F364)<=20),IF(INDEX(設定!$P$8:$P$27,VALUE(F364))="","？",INDEX(設定!$P$8:$P$27,VALUE(F364))),"？"))) | K364: =IF(L364="","",IF(G364="","名簿にいない",IF(COUNTIF(L365:L$552,L364)>0,"2回提出（下の行を使います）",IF(OR(H364="？",I364="？",J364="？"),"クラブ番号がちがう",IF(OR(AND(H364<>"",H364<>"？",COUNTIF(設定!$P$8:$P$27,H364)=0),AND(I364<>"",I364<>"？",COUNTIF(設定!$P$8:$P$27,I364)=0),AND(J364<>"",J364<>"？",COUNTIF(設定!$P$8:$P$27,J364)=0)),"クラブ名がちがう",IF(H364="","第1希望がない",IF(OR(AND(H364<>"",H364=I364),AND(H364<>"",H364=J364),AND(I364<>"",I364=J364)),"同じクラブを重複して希望","OK"))))))) | L364: =IF(A364="","",A364&"-"&B364&"-"&C364) | M364: =IF(OR(L364="",G364=""),"",IF(COUNTIF(L365:L$552,L364)=0,L364,""))
