Workbook
Name 自動案Aの表: '自動案A'!$C$6:$H$29
Name 自動案Bの表: '自動案B'!$C$6:$H$29
Name 決定の表: '調整・決定'!$C$6:$H$29

Sheet ホーム
A1: 面談日程ツール | K1: Ver.2.5
A2: ×のついた予定表から、個人面談の日程を組むツールです（マクロなし）。黄色のマスが入力する場所です。
B4: いまの状況
B5: 名簿の人数 | D5: ×入力済み | F5: 未入力 | H5: 未提出 | J5: 決定済み | L5: 未決定
B6: =COUNTIF('名簿'!$B$5:$B$49,"?*") | D6: =COUNTIF('名簿'!$Q$5:$Q$49,"入力済み")+COUNTIF('名簿'!$Q$5:$Q$49,"×なし") | F6: =COUNTIF('名簿'!$Q$5:$Q$49,"未入力") | H6: =COUNTIF('名簿'!$Q$5:$Q$49,"未提出") | J6: =SUMPRODUCT(('名簿'!$U$5:$U$49<>"")*1) | L6: =COUNTIF('名簿'!$W$5:$W$49,"未決定")
B8: 使う順番
B9: 1 | C9: 日付と時間枠を決める | K9: =HYPERLINK("#'設定'!A1","開く ▶")
C10: 面談する日付、時間帯（2つまで）、1枠の長さ。出張などで組まない日・時間もここで止めます。
B12: 2 | C12: 名簿を貼り付ける | K12: =HYPERLINK("#'名簿'!A1","開く ▶")
C13: 番号と名前を貼り付けます。兄弟・希望の時間・後ろを空けるもここで選びます。
B15: 3 | C15: ×を入力する | K15: =HYPERLINK("#'×入力'!A1","開く ▶")
C16: 予定表と同じ形の表に「×」。日付の上・時刻の左の欄で、1日全部・その時間全部も一度に×にできます。
B18: 4 | C18: 自動案を見る（A：詰める／B：散らす） | K18: =HYPERLINK("#'自動案A'!A1","案A ▶") | L18: =HYPERLINK("#'自動案B'!A1","案B ▶")
C19: 集まった分で作るときは、自動案Aのシートの右上を「自動案を出す」に。入れられる枠が少ない家庭から順に組んだ案が2つ出ます。よいほうを調整・決定に貼り付けます。
B21: 5 | C21: 調整して決定する | K21: =HYPERLINK("#'調整・決定'!A1","開く ▶")
C22: プルダウンで手直しして日程を決めます。児童を選ぶと、入れられる枠に色がつきます。
B24: 6 | C24: 印刷して兄弟を確認する | K24: =HYPERLINK("#'兄弟確認用'!A1","開く ▶")
C25: 決めた日程を予定表の形で印刷。兄弟がいる子は色付きで、兄弟のクラスも出ます。
B27: 7 | C27: お手紙を印刷する | K27: =HYPERLINK("#'お手紙（夏）'!A1","夏 ▶") | L27: =HYPERLINK("#'お手紙（秋）'!A1","秋 ▶")
C28: 保護者へのお知らせ（夏用・秋用）。宛名・日付・学校名・担任名・本文は設定で決めます。6年は「進路面談」になります。
B32: くわしい使い方
B33: 1. 「設定」シート
B34: ・面談の日付（上から順に、最大6日）、時間帯（午前と午後に分けるときは2つ）と1枠の長さを入れます（1日最大24枠）。
B35: ・空けたい日や休憩の時刻には「〇」を選びます。自動案では、ほかに入る枠がないときだけ使われます。
B36: ・出張や会議などで面談を組まない日・時間・枠は、右の「先生の都合で使えない枠」で「×」を選びます。止めた枠は、×入力・自動案・調整・決定で灰色になり、使われません。
B37: 2. 「名簿」シート
B38: ・Excelの名簿から「出席番号」と「名前」をコピーして、「番号」の列のいちばん上のマスに貼り付けます（最大40人）。
B39: ・他のクラスに兄弟がいる家庭は、「兄弟」の列で「〇」を選び、「兄弟メモ」に兄弟のクラスなどをメモします。
B40: ・「希望」：早い時刻／遅い時刻／早い日／遅い日 から選べます。自動案で、×のない枠の中からできるだけ希望に合う枠を選びます（希望なので、合わないこともあります）。
B41: ・「後ろを空ける」：話が長引きそうな家庭は、同じ日のすぐ次の枠を空けます。「必ず空けたい」「出来れば空けたい」から選びます（出来れば空けたいは、空けられないときは詰めて入れます）。日の最後の枠なら空ける必要はありません。
B42: ・名簿の行は並べ替えないでください（×入力の内容とずれてしまいます）。絞り込み（フィルター）は使えます。
B43: ・自動案や調整・決定には名前だけが出ます。同じ名前の児童がいるときだけ、「番号 名前」で区別して表示します。
... B73: ※ 「calcA」「calcB」「calcC」は計算用の隠しシートです。さわらないでください。

Sheet 設定
A1: 設定 | E1: =HYPERLINK("#'ホーム'!A1","ホーム") | F1: =HYPERLINK("#'設定'!A1","① 設定") | H1: =HYPERLINK("#'名簿'!A1","② 名簿") | I1: =HYPERLINK("#'×入力'!A1","③ ×入力") | K1: =HYPERLINK("#'自動案A'!A1","④ 自動案A") | M1: =HYPERLINK("#'自動案B'!A1","④ 自動案B") | N1: =HYPERLINK("#'調整・決定'!A1","⑤ 調整・決定") | O1: =HYPERLINK("#'兄弟確認用'!A1","⑥ 兄弟確認") | P1: =HYPERLINK("#'お手紙（夏）'!A1","⑦ お手紙 夏") | Q1: =HYPERLINK("#'お手紙（秋）'!A1","⑧ お手紙 秋")
A2: 面談の日付と時間枠を決めます。黄色のマスを入力してください。
A3: 時間帯1 | B3: 0.5625 | C3: 〜 | D3: 0.64583333 | E3: =IF(OR(NOT(ISNUMBER(B3)),NOT(ISNUMBER(D3))),"← 始まりと終わりの時刻を入れてください",IF(D3<B3,"← 終わりは始まりより後の時刻にしてください",""))
A4: 時間帯2（なければ空欄） | C4: 〜 | E4: =IF(AND(B4="",D4=""),"",IF(OR(NOT(ISNUMBER(B4)),NOT(ISNUMBER(D4))),"← 始まりと終わりの両方を入れてください",IF(D4<B4,"← 終わりは始まりより後の時刻にしてください",IF(AND(ISNUMBER(D3),B4<=D3),"← 時間帯1より後の時刻にしてください",""))))
A5: 1枠の長さ（分） | B5: 15 | E5: =IF(AND(ISNUMBER(B5),B5>0),"","← 5〜120の数字を入れてください")
A6: 1日の枠の数 | B6: =MIN(24,calcA!$A$3+calcA!$A$4) | D6: （最大24枠） | E6: =IF(calcA!$A$3+calcA!$A$4>24,"← 枠が24をこえています。こえた分は使いません","")
K7: 先生の都合で使えない枠（出張・会議など）
A8: 自動案の詰め方 | B8: 早い時間から（各日の最後を空ける） | K8: 「×」を選んだ日・時間・枠は、自動案にも調整・決定にも使いません。
K9: この日は組まない ▶
B10: 日付 | C10: 曜日 | D10: なるべく空ける | E10: 表示 | G10: 時刻 | H10: 休憩（なるべく空ける） | I10: 表示 | K10: この時間は 組まない ▼ | M10: ='設定'!$E$11 | N10: ='設定'!$E$12 | O10: ='設定'!$E$13 | P10: ='設定'!$E$14 | Q10: ='設定'!$E$15 | R10: ='設定'!$E$16
A11: 1日目 | B11: 46350 | C11: =IF(B11="","",CHOOSE(WEEKDAY(B11),"日","月","火","水","木","金","土")) | E11: =IF(B11="","",MONTH(B11)&"月"&DAY(B11)&"日（"&C11&"）") | F11: 1 | G11: =IF(F11<=MIN(calcA!$A$3,24),$B$3+(F11-1)*$B$5/1440,IF(F11<=$B$6,$B$4+(F11-calcA!$A$3-1)*$B$5/1440,"")) | I11: =IF(G11="","",TEXT(G11,"h:mm")&"〜") | L11: =$I$11
A12: 2日目 | B12: 46351 | C12: =IF(B12="","",CHOOSE(WEEKDAY(B12),"日","月","火","水","木","金","土")) | E12: =IF(B12="","",MONTH(B12)&"月"&DAY(B12)&"日（"&C12&"）") | F12: 2 | G12: =IF(F12<=MIN(calcA!$A$3,24),$B$3+(F12-1)*$B$5/1440,IF(F12<=$B$6,$B$4+(F12-calcA!$A$3-1)*$B$5/1440,"")) | I12: =IF(G12="","",TEXT(G12,"h:mm")&"〜") | L12: =$I$12
A13: 3日目 | B13: 46352 | C13: =IF(B13="","",CHOOSE(WEEKDAY(B13),"日","月","火","水","木","金","土")) | E13: =IF(B13="","",MONTH(B13)&"月"&DAY(B13)&"日（"&C13&"）") | F13: 3 | G13: =IF(F13<=MIN(calcA!$A$3,24),$B$3+(F13-1)*$B$5/1440,IF(F13<=$B$6,$B$4+(F13-calcA!$A$3-1)*$B$5/1440,"")) | I13: =IF(G13="","",TEXT(G13,"h:mm")&"〜") | L13: =$I$13
A14: 4日目 | B14: 46353 | C14: =IF(B14="","",CHOOSE(WEEKDAY(B14),"日","月","火","水","木","金","土")) | E14: =IF(B14="","",MONTH(B14)&"月"&DAY(B14)&"日（"&C14&"）") | F14: 4 | G14: =IF(F14<=MIN(calcA!$A$3,24),$B$3+(F14-1)*$B$5/1440,IF(F14<=$B$6,$B$4+(F14-calcA!$A$3-1)*$B$5/1440,"")) | I14: =IF(G14="","",TEXT(G14,"h:mm")&"〜") | L14: =$I$14
A15: 5日目 | B15: 46356 | C15: =IF(B15="","",CHOOSE(WEEKDAY(B15),"日","月","火","水","木","金","土")) | E15: =IF(B15="","",MONTH(B15)&"月"&DAY(B15)&"日（"&C15&"）") | F15: 5 | G15: =IF(F15<=MIN(calcA!$A$3,24),$B$3+(F15-1)*$B$5/1440,IF(F15<=$B$6,$B$4+(F15-calcA!$A$3-1)*$B$5/1440,"")) | I15: =IF(G15="","",TEXT(G15,"h:mm")&"〜") | L15: =$I$15
A16: 6日目 | C16: =IF(B16="","",CHOOSE(WEEKDAY(B16),"日","月","火","水","木","金","土")) | E16: =IF(B16="","",MONTH(B16)&"月"&DAY(B16)&"日（"&C16&"）") | F16: 6 | G16: =IF(F16<=MIN(calcA!$A$3,24),$B$3+(F16-1)*$B$5/1440,IF(F16<=$B$6,$B$4+(F16-calcA!$A$3-1)*$B$5/1440,"")) | I16: =IF(G16="","",TEXT(G16,"h:mm")&"〜") | L16: =$I$16
F17: 7 | G17: =IF(F17<=MIN(calcA!$A$3,24),$B$3+(F17-1)*$B$5/1440,IF(F17<=$B$6,$B$4+(F17-calcA!$A$3-1)*$B$5/1440,"")) | I17: =IF(G17="","",TEXT(G17,"h:mm")&"〜") | L17: =$I$17 | P17: ×
F18: 8 | G18: =IF(F18<=MIN(calcA!$A$3,24),$B$3+(F18-1)*$B$5/1440,IF(F18<=$B$6,$B$4+(F18-calcA!$A$3-1)*$B$5/1440,"")) | I18: =IF(G18="","",TEXT(G18,"h:mm")&"〜") | L18: =$I$18 | P18: ×
F19: 9 | G19: =IF(F19<=MIN(calcA!$A$3,24),$B$3+(F19-1)*$B$5/1440,IF(F19<=$B$6,$B$4+(F19-calcA!$A$3-1)*$B$5/1440,"")) | I19: =IF(G19="","",TEXT(G19,"h:mm")&"〜") | L19: =$I$19 | P19: ×
F20: 10 | G20: =IF(F20<=MIN(calcA!$A$3,24),$B$3+(F20-1)*$B$5/1440,IF(F20<=$B$6,$B$4+(F20-calcA!$A$3-1)*$B$5/1440,"")) | I20: =IF(G20="","",TEXT(G20,"h:mm")&"〜") | L20: =$I$20
F21: 11 | G21: =IF(F21<=MIN(calcA!$A$3,24),$B$3+(F21-1)*$B$5/1440,IF(F21<=$B$6,$B$4+(F21-calcA!$A$3-1)*$B$5/1440,"")) | I21: =IF(G21="","",TEXT(G21,"h:mm")&"〜") | L21: =$I$21
A22: ※ 日付は上から詰めて入れてください。曜日・表示・時刻は自動で出ます。午前と午後に分けるときは、時間帯2も入れます（昼休みは表に出ません）。 | F22: 12 | G22: =IF(F22<=MIN(calcA!$A$3,24),$B$3+(F22-1)*$B$5/1440,IF(F22<=$B$6,$B$4+(F22-calcA!$A$3-1)*$B$5/1440,"")) | I22: =IF(G22="","",TEXT(G22,"h:mm")&"〜") | L22: =$I$22
F23: 13 | G23: =IF(F23<=MIN(calcA!$A$3,24),$B$3+(F23-1)*$B$5/1440,IF(F23<=$B$6,$B$4+(F23-calcA!$A$3-1)*$B$5/1440,"")) | I23: =IF(G23="","",TEXT(G23,"h:mm")&"〜") | L23: =$I$23
F24: 14 | G24: =IF(F24<=MIN(calcA!$A$3,24),$B$3+(F24-1)*$B$5/1440,IF(F24<=$B$6,$B$4+(F24-calcA!$A$3-1)*$B$5/1440,"")) | I24: =IF(G24="","",TEXT(G24,"h:mm")&"〜") | L24: =$I$24
A25: ※「なるべく空ける」「休憩」は、ほかに入る枠がないときだけ使います。必ず使わない枠は、右の「先生の都合で使えない枠」で止めてください。 | F25: 15 | G25: =IF(F25<=MIN(calcA!$A$3,24),$B$3+(F25-1)*$B$5/1440,IF(F25<=$B$6,$B$4+(F25-calcA!$A$3-1)*$B$5/1440,"")) | I25: =IF(G25="","",TEXT(G25,"h:mm")&"〜") | L25: =$I$25
F26: 16 | G26: =IF(F26<=MIN(calcA!$A$3,24),$B$3+(F26-1)*$B$5/1440,IF(F26<=$B$6,$B$4+(F26-calcA!$A$3-1)*$B$5/1440,"")) | I26: =IF(G26="","",TEXT(G26,"h:mm")&"〜") | L26: =$I$26
F27: 17 | G27: =IF(F27<=MIN(calcA!$A$3,24),$B$3+(F27-1)*$B$5/1440,IF(F27<=$B$6,$B$4+(F27-calcA!$A$3-1)*$B$5/1440,"")) | I27: =IF(G27="","",TEXT(G27,"h:mm")&"〜") | L27: =$I$27
F28: 18 | G28: =IF(F28<=MIN(calcA!$A$3,24),$B$3+(F28-1)*$B$5/1440,IF(F28<=$B$6,$B$4+(F28-calcA!$A$3-1)*$B$5/1440,"")) | I28: =IF(G28="","",TEXT(G28,"h:mm")&"〜") | L28: =$I$28
F29: 19 | G29: =IF(F29<=MIN(calcA!$A$3,24),$B$3+(F29-1)*$B$5/1440,IF(F29<=$B$6,$B$4+(F29-calcA!$A$3-1)*$B$5/1440,"")) | I29: =IF(G29="","",TEXT(G29,"h:mm")&"〜") | L29: =$I$29
A30: お手紙（お知らせ） | B30: 「お手紙（夏）」「お手紙（秋）」シートに出ます。 | F30: 20 | G30: =IF(F30<=MIN(calcA!$A$3,24),$B$3+(F30-1)*$B$5/1440,IF(F30<=$B$6,$B$4+(F30-calcA!$A$3-1)*$B$5/1440,"")) | I30: =IF(G30="","",TEXT(G30,"h:mm")&"〜") | L30: =$I$30
A31: 学年 | B31: 6 | C31: =IF(B36="学年に合わせる（6年は進路面談）","→ "&IF(OR(IF(RIGHT(B31,1)="年",LEFT(B31,LEN(B31)-1),B31)&""="6",IF(RIGHT(B31,1)="年",LEFT(B31,LEN(B31)-1),B31)&""="６"),"進路面談","個人面談")&"のお知らせになります","") | F31: 21 | G31: =IF(F31<=MIN(calcA!$A$3,24),$B$3+(F31-1)*$B$5/1440,IF(F31<=$B$6,$B$4+(F31-calcA!$A$3-1)*$B$5/1440,"")) | I31: =IF(G31="","",TEXT(G31,"h:mm")&"〜") | L31: =$I$31
A32: 組 | B32: 1 | C32: ← 数字だけ（例：1）。「組」は自動 | F32: 22 | G32: =IF(F32<=MIN(calcA!$A$3,24),$B$3+(F32-1)*$B$5/1440,IF(F32<=$B$6,$B$4+(F32-calcA!$A$3-1)*$B$5/1440,"")) | I32: =IF(G32="","",TEXT(G32,"h:mm")&"〜") | L32: =$I$32
A33: 担任名 | F33: 23 | G33: =IF(F33<=MIN(calcA!$A$3,24),$B$3+(F33-1)*$B$5/1440,IF(F33<=$B$6,$B$4+(F33-calcA!$A$3-1)*$B$5/1440,"")) | I33: =IF(G33="","",TEXT(G33,"h:mm")&"〜") | L33: =$I$33
A34: 学校名 | F34: 24 | G34: =IF(F34<=MIN(calcA!$A$3,24),$B$3+(F34-1)*$B$5/1440,IF(F34<=$B$6,$B$4+(F34-calcA!$A$3-1)*$B$5/1440,"")) | I34: =IF(G34="","",TEXT(G34,"h:mm")&"〜") | L34: =$I$34
A35: お手紙の日付 | B35: 46325
A36: 面談の種類 | B36: 学年に合わせる（6年は進路面談）
A37: 秋の本文 | B37: 【面談】の希望調査へのご協力ありがとうございました。下記の日程で予定を組ませていただきました。短い時間ですが、有意義な話し合いとし、日々の学級生活に生かしたいと思います。どうぞ、よろしくお願いいたします。
A40: 秋の注意（表の下・3行） | B40: 〇来校の際には、名札・上履きをお持ちください。
A43: 夏の本文 | B43: 下記の日程で予定を組ませていただきました。どうぞ、よろしくお願いいたします。
A45: 夏の注意（表の上・3行） | B45: 〇来校の際には、名札・上履きをお持ちください。
...

Sheet 名簿
A1: 名簿・結果 | D1: =HYPERLINK("#'ホーム'!A1","ホーム") | F1: ▲ 上の「＋」で 兄弟の列を開く | P1: =HYPERLINK("#'設定'!A1","① 設定") | Q1: =HYPERLINK("#'名簿'!A1","② 名簿") | S1: =HYPERLINK("#'×入力'!A1","③ ×入力") | U1: =HYPERLINK("#'自動案A'!A1","④ 自動案A") | X1: =HYPERLINK("#'自動案B'!A1","④ 自動案B") | Y1: =HYPERLINK("#'調整・決定'!A1","⑤ 調整・決定") | Z1: =HYPERLINK("#'兄弟確認用'!A1","⑥ 兄弟確認") | AB1: =HYPERLINK("#'お手紙（夏）'!A1","⑦ お手紙 夏") | AD1: =HYPERLINK("#'お手紙（秋）'!A1","⑧ お手紙 秋")
A2: 黄色の列（番号〜兄弟③との順番）を入力します。Excelの名簿から番号と名前を「番号」の列のいちばん上に貼り付けてください（最大40人）。行の並べ替えはしないでください。
A3: 兄弟クラス：書き方は自由です（例：2年1組、2-1、兄 5年 など）。10字くらいまでが見やすいです。灰色の欄は、兄弟が〇の子だけ入力します。 | P3: ◀ 兄弟①〜③の列（兄弟の担任から聞いた面談の日時と順番）は、左上の「＋」で開き、「−」でたためます。
A4: 番号 | B4: 名前 | C4: 希望 | D4: 後ろを空ける | E4: 兄弟 | F4: 兄弟クラス 日時は上の＋を押す | G4: 兄弟① 日付 | H4: 兄弟① 時刻 | I4: 兄弟① との順番 | J4: 兄弟② 日付 | K4: 兄弟② 時刻 | L4: 兄弟② との順番 | M4: 兄弟③ 日付 | N4: 兄弟③ 時刻 | O4: 兄弟③ との順番 | P4: 表示名 | Q4: 状況 | R4: ×の数 | S4: 入れられる空き枠 | T4: 決める順 | U4: 日付 | V4: 時刻 | W4: 注意 | X4: 自動案A（詰める） | Y4: 自動案B（散らす）
A5: 1 | B5: 佐藤 はると | P5: =IF(B5="","",IF(COUNTIF($B$5:$B$49,B5)>1,IF(A5="","",A5&" ")&B5,B5)) | Q5: =IF(B5="","",IF('×入力'!F5="未提出","未提出",IF(R5>0,"入力済み",IF('×入力'!F5="×なし（どこでもOK）","×なし","未入力")))) | R5: =IF(B5="","",'calcA'!IN10) | S5: =IF(OR(Q5="入力済み",Q5="×なし"),'calcA'!IM10,"") | T5: =IF('calcA'!C10=1,COUNTIFS('calcA'!$C$10:$C$54,1,'calcA'!$IM$10:$IM$54,"<"&'calcA'!IM10)+1,"") | U5: =IF('calcA'!IO10=0,"",INDEX('設定'!$E$11:$E$16,INDEX('calcA'!$D$2:$EQ$2,'calcA'!IO10))) | V5: =IF('calcA'!IO10=0,"",INDEX('設定'!$I$11:$I$34,INDEX('calcA'!$D$3:$EQ$3,'calcA'!IO10))) | W5: =IF(P5="","",IF('calcA'!JG10=1,"兄弟の日付・時刻が表にありません",IF(COUNTIF('調整・決定'!$C$6:$H$29,P5)>1,"2か所以上に入っています",IF('calcA'!IO10>0,IF(INDEX('calcA'!$D$4:$EQ$4,'calcA'!IO10)=0,"使えない枠に入っています",IF(INDEX('calcA'!$D$10:$EQ$10,'calcA'!IO10)=1,"×の枠に入っています",IF('calcA'!IV10=0,"（出来れば）兄弟の前後ではありません",IF(AND(RIGHT(D5,4)="空けたい",INDEX('calcA'!$D$106:$EQ$106,'calcA'!IO10)=1,INDEX('calcA'!$D$109:$EQ$109,'calcA'!IO10+1)=1),IF(D5="必ず空けたい","後ろの枠が空いていません","（出来れば）後ろが空いていません"),IF(AND(D5="空けない",INDEX('calcA'!$D$106:$EQ$106,'calcA'!IO10)=1,INDEX('calcA'!$D$109:$EQ$109,'calcA'!IO10+1)=0),"（出来れば）すぐ後が空いています",""))))),IF(OR(Q5="入力済み",Q5="×なし"),"未決定",""))))) | X5: =IF('calcA'!IK10=0,IF('calcA'!IL10=1,"入る枠がありません",""),INDEX('calcA'!$D$8:$EQ$8,'calcA'!IK10)) | Y5: =IF('calcA'!IR10=0,IF('calcA'!IS10=1,"入る枠がありません",""),INDEX('calcA'!$D$8:$EQ$8,'calcA'!IR10)) | Z5: =HYPERLINK("#'×入力'!B5","×入力へ")
A6: 2 | B6: 鈴木 ゆい | C6: 遅い時刻 | P6: =IF(B6="","",IF(COUNTIF($B$5:$B$49,B6)>1,IF(A6="","",A6&" ")&B6,B6)) | Q6: =IF(B6="","",IF('×入力'!F33="未提出","未提出",IF(R6>0,"入力済み",IF('×入力'!F33="×なし（どこでもOK）","×なし","未入力")))) | R6: =IF(B6="","",'calcA'!IN11) | S6: =IF(OR(Q6="入力済み",Q6="×なし"),'calcA'!IM11,"") | T6: =IF('calcA'!C11=1,COUNTIFS('calcA'!$C$10:$C$54,1,'calcA'!$IM$10:$IM$54,"<"&'calcA'!IM11)+1,"") | U6: =IF('calcA'!IO11=0,"",INDEX('設定'!$E$11:$E$16,INDEX('calcA'!$D$2:$EQ$2,'calcA'!IO11))) | V6: =IF('calcA'!IO11=0,"",INDEX('設定'!$I$11:$I$34,INDEX('calcA'!$D$3:$EQ$3,'calcA'!IO11))) | W6: =IF(P6="","",IF('calcA'!JG11=1,"兄弟の日付・時刻が表にありません",IF(COUNTIF('調整・決定'!$C$6:$H$29,P6)>1,"2か所以上に入っています",IF('calcA'!IO11>0,IF(INDEX('calcA'!$D$4:$EQ$4,'calcA'!IO11)=0,"使えない枠に入っています",IF(INDEX('calcA'!$D$11:$EQ$11,'calcA'!IO11)=1,"×の枠に入っています",IF('calcA'!IV11=0,"（出来れば）兄弟の前後ではありません",IF(AND(RIGHT(D6,4)="空けたい",INDEX('calcA'!$D$106:$EQ$106,'calcA'!IO11)=1,INDEX('calcA'!$D$109:$EQ$109,'calcA'!IO11+1)=1),IF(D6="必ず空けたい","後ろの枠が空いていません","（出来れば）後ろが空いていません"),IF(AND(D6="空けない",INDEX('calcA'!$D$106:$EQ$106,'calcA'!IO11)=1,INDEX('calcA'!$D$109:$EQ$109,'calcA'!IO11+1)=0),"（出来れば）すぐ後が空いています",""))))),IF(OR(Q6="入力済み",Q6="×なし"),"未決定",""))))) | X6: =IF('calcA'!IK11=0,IF('calcA'!IL11=1,"入る枠がありません",""),INDEX('calcA'!$D$8:$EQ$8,'calcA'!IK11)) | Y6: =IF('calcA'!IR11=0,IF('calcA'!IS11=1,"入る枠がありません",""),INDEX('calcA'!$D$8:$EQ$8,'calcA'!IR11)) | Z6: =HYPERLINK("#'×入力'!B33","×入力へ")
A7: 3 | B7: 高橋 そうた | P7: =IF(B7="","",IF(COUNTIF($B$5:$B$49,B7)>1,IF(A7="","",A7&" ")&B7,B7)) | Q7: =IF(B7="","",IF('×入力'!F61="未提出","未提出",IF(R7>0,"入力済み",IF('×入力'!F61="×なし（どこでもOK）","×なし","未入力")))) | R7: =IF(B7="","",'calcA'!IN12) | S7: =IF(OR(Q7="入力済み",Q7="×なし"),'calcA'!IM12,"") | T7: =IF('calcA'!C12=1,COUNTIFS('calcA'!$C$10:$C$54,1,'calcA'!$IM$10:$IM$54,"<"&'calcA'!IM12)+1,"") | U7: =IF('calcA'!IO12=0,"",INDEX('設定'!$E$11:$E$16,INDEX('calcA'!$D$2:$EQ$2,'calcA'!IO12))) | V7: =IF('calcA'!IO12=0,"",INDEX('設定'!$I$11:$I$34,INDEX('calcA'!$D$3:$EQ$3,'calcA'!IO12))) | W7: =IF(P7="","",IF('calcA'!JG12=1,"兄弟の日付・時刻が表にありません",IF(COUNTIF('調整・決定'!$C$6:$H$29,P7)>1,"2か所以上に入っています",IF('calcA'!IO12>0,IF(INDEX('calcA'!$D$4:$EQ$4,'calcA'!IO12)=0,"使えない枠に入っています",IF(INDEX('calcA'!$D$12:$EQ$12,'calcA'!IO12)=1,"×の枠に入っています",IF('calcA'!IV12=0,"（出来れば）兄弟の前後ではありません",IF(AND(RIGHT(D7,4)="空けたい",INDEX('calcA'!$D$106:$EQ$106,'calcA'!IO12)=1,INDEX('calcA'!$D$109:$EQ$109,'calcA'!IO12+1)=1),IF(D7="必ず空けたい","後ろの枠が空いていません","（出来れば）後ろが空いていません"),IF(AND(D7="空けない",INDEX('calcA'!$D$106:$EQ$106,'calcA'!IO12)=1,INDEX('calcA'!$D$109:$EQ$109,'calcA'!IO12+1)=0),"（出来れば）すぐ後が空いています",""))))),IF(OR(Q7="入力済み",Q7="×なし"),"未決定",""))))) | X7: =IF('calcA'!IK12=0,IF('calcA'!IL12=1,"入る枠がありません",""),INDEX('calcA'!$D$8:$EQ$8,'calcA'!IK12)) | Y7: =IF('calcA'!IR12=0,IF('calcA'!IS12=1,"入る枠がありません",""),INDEX('calcA'!$D$8:$EQ$8,'calcA'!IR12)) | Z7: =HYPERLINK("#'×入力'!B61","×入力へ")
A8: 4 | B8: 田中 めい | E8: 〇 | F8: 2年1組 | P8: =IF(B8="","",IF(COUNTIF($B$5:$B$49,B8)>1,IF(A8="","",A8&" ")&B8,B8)) | Q8: =IF(B8="","",IF('×入力'!F89="未提出","未提出",IF(R8>0,"入力済み",IF('×入力'!F89="×なし（どこでもOK）","×なし","未入力")))) | R8: =IF(B8="","",'calcA'!IN13) | S8: =IF(OR(Q8="入力済み",Q8="×なし"),'calcA'!IM13,"") | T8: =IF('calcA'!C13=1,COUNTIFS('calcA'!$C$10:$C$54,1,'calcA'!$IM$10:$IM$54,"<"&'calcA'!IM13)+1,"") | U8: =IF('calcA'!IO13=0,"",INDEX('設定'!$E$11:$E$16,INDEX('calcA'!$D$2:$EQ$2,'calcA'!IO13))) | V8: =IF('calcA'!IO13=0,"",INDEX('設定'!$I$11:$I$34,INDEX('calcA'!$D$3:$EQ$3,'calcA'!IO13))) | W8: =IF(P8="","",IF('calcA'!JG13=1,"兄弟の日付・時刻が表にありません",IF(COUNTIF('調整・決定'!$C$6:$H$29,P8)>1,"2か所以上に入っています",IF('calcA'!IO13>0,IF(INDEX('calcA'!$D$4:$EQ$4,'calcA'!IO13)=0,"使えない枠に入っています",IF(INDEX('calcA'!$D$13:$EQ$13,'calcA'!IO13)=1,"×の枠に入っています",IF('calcA'!IV13=0,"（出来れば）兄弟の前後ではありません",IF(AND(RIGHT(D8,4)="空けたい",INDEX('calcA'!$D$106:$EQ$106,'calcA'!IO13)=1,INDEX('calcA'!$D$109:$EQ$109,'calcA'!IO13+1)=1),IF(D8="必ず空けたい","後ろの枠が空いていません","（出来れば）後ろが空いていません"),IF(AND(D8="空けない",INDEX('calcA'!$D$106:$EQ$106,'calcA'!IO13)=1,INDEX('calcA'!$D$109:$EQ$109,'calcA'!IO13+1)=0),"（出来れば）すぐ後が空いています",""))))),IF(OR(Q8="入力済み",Q8="×なし"),"未決定",""))))) | X8: =IF('calcA'!IK13=0,IF('calcA'!IL13=1,"入る枠がありません",""),INDEX('calcA'!$D$8:$EQ$8,'calcA'!IK13)) | Y8: =IF('calcA'!IR13=0,IF('calcA'!IS13=1,"入る枠がありません",""),INDEX('calcA'!$D$8:$EQ$8,'calcA'!IR13)) | Z8: =HYPERLINK("#'×入力'!B89","×入力へ")
A9: 5 | B9: 伊藤 ひなた | P9: =IF(B9="","",IF(COUNTIF($B$5:$B$49,B9)>1,IF(A9="","",A9&" ")&B9,B9)) | Q9: =IF(B9="","",IF('×入力'!F117="未提出","未提出",IF(R9>0,"入力済み",IF('×入力'!F117="×なし（どこでもOK）","×なし","未入力")))) | R9: =IF(B9="","",'calcA'!IN14) | S9: =IF(OR(Q9="入力済み",Q9="×なし"),'calcA'!IM14,"") | T9: =IF('calcA'!C14=1,COUNTIFS('calcA'!$C$10:$C$54,1,'calcA'!$IM$10:$IM$54,"<"&'calcA'!IM14)+1,"") | U9: =IF('calcA'!IO14=0,"",INDEX('設定'!$E$11:$E$16,INDEX('calcA'!$D$2:$EQ$2,'calcA'!IO14))) | V9: =IF('calcA'!IO14=0,"",INDEX('設定'!$I$11:$I$34,INDEX('calcA'!$D$3:$EQ$3,'calcA'!IO14))) | W9: =IF(P9="","",IF('calcA'!JG14=1,"兄弟の日付・時刻が表にありません",IF(COUNTIF('調整・決定'!$C$6:$H$29,P9)>1,"2か所以上に入っています",IF('calcA'!IO14>0,IF(INDEX('calcA'!$D$4:$EQ$4,'calcA'!IO14)=0,"使えない枠に入っています",IF(INDEX('calcA'!$D$14:$EQ$14,'calcA'!IO14)=1,"×の枠に入っています",IF('calcA'!IV14=0,"（出来れば）兄弟の前後ではありません",IF(AND(RIGHT(D9,4)="空けたい",INDEX('calcA'!$D$106:$EQ$106,'calcA'!IO14)=1,INDEX('calcA'!$D$109:$EQ$109,'calcA'!IO14+1)=1),IF(D9="必ず空けたい","後ろの枠が空いていません","（出来れば）後ろが空いていません"),IF(AND(D9="空けない",INDEX('calcA'!$D$106:$EQ$106,'calcA'!IO14)=1,INDEX('calcA'!$D$109:$EQ$109,'calcA'!IO14+1)=0),"（出来れば）すぐ後が空いています",""))))),IF(OR(Q9="入力済み",Q9="×なし"),"未決定",""))))) | X9: =IF('calcA'!IK14=0,IF('calcA'!IL14=1,"入る枠がありません",""),INDEX('calcA'!$D$8:$EQ$8,'calcA'!IK14)) | Y9: =IF('calcA'!IR14=0,IF('calcA'!IS14=1,"入る枠がありません",""),INDEX('calcA'!$D$8:$EQ$8,'calcA'!IR14)) | Z9: =HYPERLINK("#'×入力'!B117","×入力へ")
A10: 6 | B10: 渡辺 さくら | D10: 必ず空けたい | P10: =IF(B10="","",IF(COUNTIF($B$5:$B$49,B10)>1,IF(A10="","",A10&" ")&B10,B10)) | Q10: =IF(B10="","",IF('×入力'!F145="未提出","未提出",IF(R10>0,"入力済み",IF('×入力'!F145="×なし（どこでもOK）","×なし","未入力")))) | R10: =IF(B10="","",'calcA'!IN15) | S10: =IF(OR(Q10="入力済み",Q10="×なし"),'calcA'!IM15,"") | T10: =IF('calcA'!C15=1,COUNTIFS('calcA'!$C$10:$C$54,1,'calcA'!$IM$10:$IM$54,"<"&'calcA'!IM15)+1,"") | U10: =IF('calcA'!IO15=0,"",INDEX('設定'!$E$11:$E$16,INDEX('calcA'!$D$2:$EQ$2,'calcA'!IO15))) | V10: =IF('calcA'!IO15=0,"",INDEX('設定'!$I$11:$I$34,INDEX('calcA'!$D$3:$EQ$3,'calcA'!IO15))) | W10: =IF(P10="","",IF('calcA'!JG15=1,"兄弟の日付・時刻が表にありません",IF(COUNTIF('調整・決定'!$C$6:$H$29,P10)>1,"2か所以上に入っています",IF('calcA'!IO15>0,IF(INDEX('calcA'!$D$4:$EQ$4,'calcA'!IO15)=0,"使えない枠に入っています",IF(INDEX('calcA'!$D$15:$EQ$15,'calcA'!IO15)=1,"×の枠に入っています",IF('calcA'!IV15=0,"（出来れば）兄弟の前後ではありません",IF(AND(RIGHT(D10,4)="空けたい",INDEX('calcA'!$D$106:$EQ$106,'calcA'!IO15)=1,INDEX('calcA'!$D$109:$EQ$109,'calcA'!IO15+1)=1),IF(D10="必ず空けたい","後ろの枠が空いていません","（出来れば）後ろが空いていません"),IF(AND(D10="空けない",INDEX('calcA'!$D$106:$EQ$106,'calcA'!IO15)=1,INDEX('calcA'!$D$109:$EQ$109,'calcA'!IO15+1)=0),"（出来れば）すぐ後が空いています",""))))),IF(OR(Q10="入力済み",Q10="×なし"),"未決定",""))))) | X10: =IF('calcA'!IK15=0,IF('calcA'!IL15=1,"入る枠がありません",""),INDEX('calcA'!$D$8:$EQ$8,'calcA'!IK15)) | Y10: =IF('calcA'!IR15=0,IF('calcA'!IS15=1,"入る枠がありません",""),INDEX('calcA'!$D$8:$EQ$8,'calcA'!IR15)) | Z10: =HYPERLINK("#'×入力'!B145","×入力へ")
A11: 7 | B11: 山本 りく | P11: =IF(B11="","",IF(COUNTIF($B$5:$B$49,B11)>1,IF(A11="","",A11&" ")&B11,B11)) | Q11: =IF(B11="","",IF('×入力'!F173="未提出","未提出",IF(R11>0,"入力済み",IF('×入力'!F173="×なし（どこでもOK）","×なし","未入力")))) | R11: =IF(B11="","",'calcA'!IN16) | S11: =IF(OR(Q11="入力済み",Q11="×なし"),'calcA'!IM16,"") | T11: =IF('calcA'!C16=1,COUNTIFS('calcA'!$C$10:$C$54,1,'calcA'!$IM$10:$IM$54,"<"&'calcA'!IM16)+1,"") | U11: =IF('calcA'!IO16=0,"",INDEX('設定'!$E$11:$E$16,INDEX('calcA'!$D$2:$EQ$2,'calcA'!IO16))) | V11: =IF('calcA'!IO16=0,"",INDEX('設定'!$I$11:$I$34,INDEX('calcA'!$D$3:$EQ$3,'calcA'!IO16))) | W11: =IF(P11="","",IF('calcA'!JG16=1,"兄弟の日付・時刻が表にありません",IF(COUNTIF('調整・決定'!$C$6:$H$29,P11)>1,"2か所以上に入っています",IF('calcA'!IO16>0,IF(INDEX('calcA'!$D$4:$EQ$4,'calcA'!IO16)=0,"使えない枠に入っています",IF(INDEX('calcA'!$D$16:$EQ$16,'calcA'!IO16)=1,"×の枠に入っています",IF('calcA'!IV16=0,"（出来れば）兄弟の前後ではありません",IF(AND(RIGHT(D11,4)="空けたい",INDEX('calcA'!$D$106:$EQ$106,'calcA'!IO16)=1,INDEX('calcA'!$D$109:$EQ$109,'calcA'!IO16+1)=1),IF(D11="必ず空けたい","後ろの枠が空いていません","（出来れば）後ろが空いていません"),IF(AND(D11="空けない",INDEX('calcA'!$D$106:$EQ$106,'calcA'!IO16)=1,INDEX('calcA'!$D$109:$EQ$109,'calcA'!IO16+1)=0),"（出来れば）すぐ後が空いています",""))))),IF(OR(Q11="入力済み",Q11="×なし"),"未決定",""))))) | X11: =IF('calcA'!IK16=0,IF('calcA'!IL16=1,"入る枠がありません",""),INDEX('calcA'!$D$8:$EQ$8,'calcA'!IK16)) | Y11: =IF('calcA'!IR16=0,IF('calcA'!IS16=1,"入る枠がありません",""),INDEX('calcA'!$D$8:$EQ$8,'calcA'!IR16)) | Z11: =HYPERLINK("#'×入力'!B173","×入力へ")
A12: 8 | B12: 中村 あおい | C12: 早い時刻 | P12: =IF(B12="","",IF(COUNTIF($B$5:$B$49,B12)>1,IF(A12="","",A12&" ")&B12,B12)) | Q12: =IF(B12="","",IF('×入力'!F201="未提出","未提出",IF(R12>0,"入力済み",IF('×入力'!F201="×なし（どこでもOK）","×なし","未入力")))) | R12: =IF(B12="","",'calcA'!IN17) | S12: =IF(OR(Q12="入力済み",Q12="×なし"),'calcA'!IM17,"") | T12: =IF('calcA'!C17=1,COUNTIFS('calcA'!$C$10:$C$54,1,'calcA'!$IM$10:$IM$54,"<"&'calcA'!IM17)+1,"") | U12: =IF('calcA'!IO17=0,"",INDEX('設定'!$E$11:$E$16,INDEX('calcA'!$D$2:$EQ$2,'calcA'!IO17))) | V12: =IF('calcA'!IO17=0,"",INDEX('設定'!$I$11:$I$34,INDEX('calcA'!$D$3:$EQ$3,'calcA'!IO17))) | W12: =IF(P12="","",IF('calcA'!JG17=1,"兄弟の日付・時刻が表にありません",IF(COUNTIF('調整・決定'!$C$6:$H$29,P12)>1,"2か所以上に入っています",IF('calcA'!IO17>0,IF(INDEX('calcA'!$D$4:$EQ$4,'calcA'!IO17)=0,"使えない枠に入っています",IF(INDEX('calcA'!$D$17:$EQ$17,'calcA'!IO17)=1,"×の枠に入っています",IF('calcA'!IV17=0,"（出来れば）兄弟の前後ではありません",IF(AND(RIGHT(D12,4)="空けたい",INDEX('calcA'!$D$106:$EQ$106,'calcA'!IO17)=1,INDEX('calcA'!$D$109:$EQ$109,'calcA'!IO17+1)=1),IF(D12="必ず空けたい","後ろの枠が空いていません","（出来れば）後ろが空いていません"),IF(AND(D12="空けない",INDEX('calcA'!$D$106:$EQ$106,'calcA'!IO17)=1,INDEX('calcA'!$D$109:$EQ$109,'calcA'!IO17+1)=0),"（出来れば）すぐ後が空いています",""))))),IF(OR(Q12="入力済み",Q12="×なし"),"未決定",""))))) | X12: =IF('calcA'!IK17=0,IF('calcA'!IL17=1,"入る枠がありません",""),INDEX('calcA'!$D$8:$EQ$8,'calcA'!IK17)) | Y12: =IF('calcA'!IR17=0,IF('calcA'!IS17=1,"入る枠がありません",""),INDEX('calcA'!$D$8:$EQ$8,'calcA'!IR17)) | Z12: =HYPERLINK("#'×入力'!B201","×入力へ")
A13: 9 | B13: 小林 ゆうと | P13: =IF(B13="","",IF(COUNTIF($B$5:$B$49,B13)>1,IF(A13="","",A13&" ")&B13,B13)) | Q13: =IF(B13="","",IF('×入力'!F229="未提出","未提出",IF(R13>0,"入力済み",IF('×入力'!F229="×なし（どこでもOK）","×なし","未入力")))) | R13: =IF(B13="","",'calcA'!IN18) | S13: =IF(OR(Q13="入力済み",Q13="×なし"),'calcA'!IM18,"") | T13: =IF('calcA'!C18=1,COUNTIFS('calcA'!$C$10:$C$54,1,'calcA'!$IM$10:$IM$54,"<"&'calcA'!IM18)+1,"") | U13: =IF('calcA'!IO18=0,"",INDEX('設定'!$E$11:$E$16,INDEX('calcA'!$D$2:$EQ$2,'calcA'!IO18))) | V13: =IF('calcA'!IO18=0,"",INDEX('設定'!$I$11:$I$34,INDEX('calcA'!$D$3:$EQ$3,'calcA'!IO18))) | W13: =IF(P13="","",IF('calcA'!JG18=1,"兄弟の日付・時刻が表にありません",IF(COUNTIF('調整・決定'!$C$6:$H$29,P13)>1,"2か所以上に入っています",IF('calcA'!IO18>0,IF(INDEX('calcA'!$D$4:$EQ$4,'calcA'!IO18)=0,"使えない枠に入っています",IF(INDEX('calcA'!$D$18:$EQ$18,'calcA'!IO18)=1,"×の枠に入っています",IF('calcA'!IV18=0,"（出来れば）兄弟の前後ではありません",IF(AND(RIGHT(D13,4)="空けたい",INDEX('calcA'!$D$106:$EQ$106,'calcA'!IO18)=1,INDEX('calcA'!$D$109:$EQ$109,'calcA'!IO18+1)=1),IF(D13="必ず空けたい","後ろの枠が空いていません","（出来れば）後ろが空いていません"),IF(AND(D13="空けない",INDEX('calcA'!$D$106:$EQ$106,'calcA'!IO18)=1,INDEX('calcA'!$D$109:$EQ$109,'calcA'!IO18+1)=0),"（出来れば）すぐ後が空いています",""))))),IF(OR(Q13="入力済み",Q13="×なし"),"未決定",""))))) | X13: =IF('calcA'!IK18=0,IF('calcA'!IL18=1,"入る枠がありません",""),INDEX('calcA'!$D$8:$EQ$8,'calcA'!IK18)) | Y13: =IF('calcA'!IR18=0,IF('calcA'!IS18=1,"入る枠がありません",""),INDEX('calcA'!$D$8:$EQ$8,'calcA'!IR18)) | Z13: =HYPERLINK("#'×入力'!B229","×入力へ")
A14: 10 | B14: 加藤 ひまり | P14: =IF(B14="","",IF(COUNTIF($B$5:$B$49,B14)>1,IF(A14="","",A14&" ")&B14,B14)) | Q14: =IF(B14="","",IF('×入力'!F257="未提出","未提出",IF(R14>0,"入力済み",IF('×入力'!F257="×なし（どこでもOK）","×なし","未入力")))) | R14: =IF(B14="","",'calcA'!IN19) | S14: =IF(OR(Q14="入力済み",Q14="×なし"),'calcA'!IM19,"") | T14: =IF('calcA'!C19=1,COUNTIFS('calcA'!$C$10:$C$54,1,'calcA'!$IM$10:$IM$54,"<"&'calcA'!IM19)+1,"") | U14: =IF('calcA'!IO19=0,"",INDEX('設定'!$E$11:$E$16,INDEX('calcA'!$D$2:$EQ$2,'calcA'!IO19))) | V14: =IF('calcA'!IO19=0,"",INDEX('設定'!$I$11:$I$34,INDEX('calcA'!$D$3:$EQ$3,'calcA'!IO19))) | W14: =IF(P14="","",IF('calcA'!JG19=1,"兄弟の日付・時刻が表にありません",IF(COUNTIF('調整・決定'!$C$6:$H$29,P14)>1,"2か所以上に入っています",IF('calcA'!IO19>0,IF(INDEX('calcA'!$D$4:$EQ$4,'calcA'!IO19)=0,"使えない枠に入っています",IF(INDEX('calcA'!$D$19:$EQ$19,'calcA'!IO19)=1,"×の枠に入っています",IF('calcA'!IV19=0,"（出来れば）兄弟の前後ではありません",IF(AND(RIGHT(D14,4)="空けたい",INDEX('calcA'!$D$106:$EQ$106,'calcA'!IO19)=1,INDEX('calcA'!$D$109:$EQ$109,'calcA'!IO19+1)=1),IF(D14="必ず空けたい","後ろの枠が空いていません","（出来れば）後ろが空いていません"),IF(AND(D14="空けない",INDEX('calcA'!$D$106:$EQ$106,'calcA'!IO19)=1,INDEX('calcA'!$D$109:$EQ$109,'calcA'!IO19+1)=0),"（出来れば）すぐ後が空いています",""))))),IF(OR(Q14="入力済み",Q14="×なし"),"未決定",""))))) | X14: =IF('calcA'!IK19=0,IF('calcA'!IL19=1,"入る枠がありません",""),INDEX('calcA'!$D$8:$EQ$8,'calcA'!IK19)) | Y14: =IF('calcA'!IR19=0,IF('calcA'!IS19=1,"入る枠がありません",""),INDEX('calcA'!$D$8:$EQ$8,'calcA'!IR19)) | Z14: =HYPERLINK("#'×入力'!B257","×入力へ")
A15: 11 | B15: 吉田 いつき | E15: 〇 | F15: 5年3組 | G15: 11月26日（木） | H15: 15:00〜 | I15: 兄弟①の前 | P15: =IF(B15="","",IF(COUNTIF($B$5:$B$49,B15)>1,IF(A15="","",A15&" ")&B15,B15)) | Q15: =IF(B15="","",IF('×入力'!F285="未提出","未提出",IF(R15>0,"入力済み",IF('×入力'!F285="×なし（どこでもOK）","×なし","未入力")))) | R15: =IF(B15="","",'calcA'!IN20) | S15: =IF(OR(Q15="入力済み",Q15="×なし"),'calcA'!IM20,"") | T15: =IF('calcA'!C20=1,COUNTIFS('calcA'!$C$10:$C$54,1,'calcA'!$IM$10:$IM$54,"<"&'calcA'!IM20)+1,"") | U15: =IF('calcA'!IO20=0,"",INDEX('設定'!$E$11:$E$16,INDEX('calcA'!$D$2:$EQ$2,'calcA'!IO20))) | V15: =IF('calcA'!IO20=0,"",INDEX('設定'!$I$11:$I$34,INDEX('calcA'!$D$3:$EQ$3,'calcA'!IO20))) | W15: =IF(P15="","",IF('calcA'!JG20=1,"兄弟の日付・時刻が表にありません",IF(COUNTIF('調整・決定'!$C$6:$H$29,P15)>1,"2か所以上に入っています",IF('calcA'!IO20>0,IF(INDEX('calcA'!$D$4:$EQ$4,'calcA'!IO20)=0,"使えない枠に入っています",IF(INDEX('calcA'!$D$20:$EQ$20,'calcA'!IO20)=1,"×の枠に入っています",IF('calcA'!IV20=0,"（出来れば）兄弟の前後ではありません",IF(AND(RIGHT(D15,4)="空けたい",INDEX('calcA'!$D$106:$EQ$106,'calcA'!IO20)=1,INDEX('calcA'!$D$109:$EQ$109,'calcA'!IO20+1)=1),IF(D15="必ず空けたい","後ろの枠が空いていません","（出来れば）後ろが空いていません"),IF(AND(D15="空けない",INDEX('calcA'!$D$106:$EQ$106,'calcA'!IO20)=1,INDEX('calcA'!$D$109:$EQ$109,'calcA'!IO20+1)=0),"（出来れば）すぐ後が空いています",""))))),IF(OR(Q15="入力済み",Q15="×なし"),"未決定",""))))) | X15: =IF('calcA'!IK20=0,IF('calcA'!IL20=1,"入る枠がありません",""),INDEX('calcA'!$D$8:$EQ$8,'calcA'!IK20)) | Y15: =IF('calcA'!IR20=0,IF('calcA'!IS20=1,"入る枠がありません",""),INDEX('calcA'!$D$8:$EQ$8,'calcA'!IR20)) | Z15: =HYPERLINK("#'×入力'!B285","×入力へ")
A16: 12 | B16: 山田 りん | P16: =IF(B16="","",IF(COUNTIF($B$5:$B$49,B16)>1,IF(A16="","",A16&" ")&B16,B16)) | Q16: =IF(B16="","",IF('×入力'!F313="未提出","未提出",IF(R16>0,"入力済み",IF('×入力'!F313="×なし（どこでもOK）","×なし","未入力")))) | R16: =IF(B16="","",'calcA'!IN21) | S16: =IF(OR(Q16="入力済み",Q16="×なし"),'calcA'!IM21,"") | T16: =IF('calcA'!C21=1,COUNTIFS('calcA'!$C$10:$C$54,1,'calcA'!$IM$10:$IM$54,"<"&'calcA'!IM21)+1,"") | U16: =IF('calcA'!IO21=0,"",INDEX('設定'!$E$11:$E$16,INDEX('calcA'!$D$2:$EQ$2,'calcA'!IO21))) | V16: =IF('calcA'!IO21=0,"",INDEX('設定'!$I$11:$I$34,INDEX('calcA'!$D$3:$EQ$3,'calcA'!IO21))) | W16: =IF(P16="","",IF('calcA'!JG21=1,"兄弟の日付・時刻が表にありません",IF(COUNTIF('調整・決定'!$C$6:$H$29,P16)>1,"2か所以上に入っています",IF('calcA'!IO21>0,IF(INDEX('calcA'!$D$4:$EQ$4,'calcA'!IO21)=0,"使えない枠に入っています",IF(INDEX('calcA'!$D$21:$EQ$21,'calcA'!IO21)=1,"×の枠に入っています",IF('calcA'!IV21=0,"（出来れば）兄弟の前後ではありません",IF(AND(RIGHT(D16,4)="空けたい",INDEX('calcA'!$D$106:$EQ$106,'calcA'!IO21)=1,INDEX('calcA'!$D$109:$EQ$109,'calcA'!IO21+1)=1),IF(D16="必ず空けたい","後ろの枠が空いていません","（出来れば）後ろが空いていません"),IF(AND(D16="空けない",INDEX('calcA'!$D$106:$EQ$106,'calcA'!IO21)=1,INDEX('calcA'!$D$109:$EQ$109,'calcA'!IO21+1)=0),"（出来れば）すぐ後が空いています",""))))),IF(OR(Q16="入力済み",Q16="×なし"),"未決定",""))))) | X16: =IF('calcA'!IK21=0,IF('calcA'!IL21=1,"入る枠がありません",""),INDEX('calcA'!$D$8:$EQ$8,'calcA'!IK21)) | Y16: =IF('calcA'!IR21=0,IF('calcA'!IS21=1,"入る枠がありません",""),INDEX('calcA'!$D$8:$EQ$8,'calcA'!IR21)) | Z16: =HYPERLINK("#'×入力'!B313","×入力へ")
A17: 13 | B17: 佐々木 そら | P17: =IF(B17="","",IF(COUNTIF($B$5:$B$49,B17)>1,IF(A17="","",A17&" ")&B17,B17)) | Q17: =IF(B17="","",IF('×入力'!F341="未提出","未提出",IF(R17>0,"入力済み",IF('×入力'!F341="×なし（どこでもOK）","×なし","未入力")))) | R17: =IF(B17="","",'calcA'!IN22) | S17: =IF(OR(Q17="入力済み",Q17="×なし"),'calcA'!IM22,"") | T17: =IF('calcA'!C22=1,COUNTIFS('calcA'!$C$10:$C$54,1,'calcA'!$IM$10:$IM$54,"<"&'calcA'!IM22)+1,"") | U17: =IF('calcA'!IO22=0,"",INDEX('設定'!$E$11:$E$16,INDEX('calcA'!$D$2:$EQ$2,'calcA'!IO22))) | V17: =IF('calcA'!IO22=0,"",INDEX('設定'!$I$11:$I$34,INDEX('calcA'!$D$3:$EQ$3,'calcA'!IO22))) | W17: =IF(P17="","",IF('calcA'!JG22=1,"兄弟の日付・時刻が表にありません",IF(COUNTIF('調整・決定'!$C$6:$H$29,P17)>1,"2か所以上に入っています",IF('calcA'!IO22>0,IF(INDEX('calcA'!$D$4:$EQ$4,'calcA'!IO22)=0,"使えない枠に入っています",IF(INDEX('calcA'!$D$22:$EQ$22,'calcA'!IO22)=1,"×の枠に入っています",IF('calcA'!IV22=0,"（出来れば）兄弟の前後ではありません",IF(AND(RIGHT(D17,4)="空けたい",INDEX('calcA'!$D$106:$EQ$106,'calcA'!IO22)=1,INDEX('calcA'!$D$109:$EQ$109,'calcA'!IO22+1)=1),IF(D17="必ず空けたい","後ろの枠が空いていません","（出来れば）後ろが空いていません"),IF(AND(D17="空けない",INDEX('calcA'!$D$106:$EQ$106,'calcA'!IO22)=1,INDEX('calcA'!$D$109:$EQ$109,'calcA'!IO22+1)=0),"（出来れば）すぐ後が空いています",""))))),IF(OR(Q17="入力済み",Q17="×なし"),"未決定",""))))) | X17: =IF('calcA'!IK22=0,IF('calcA'!IL22=1,"入る枠がありません",""),INDEX('calcA'!$D$8:$EQ$8,'calcA'!IK22)) | Y17: =IF('calcA'!IR22=0,IF('calcA'!IS22=1,"入る枠がありません",""),INDEX('calcA'!$D$8:$EQ$8,'calcA'!IR22)) | Z17: =HYPERLINK("#'×入力'!B341","×入力へ")
A18: 14 | B18: 山口 ゆな | D18: 出来れば空けたい | P18: =IF(B18="","",IF(COUNTIF($B$5:$B$49,B18)>1,IF(A18="","",A18&" ")&B18,B18)) | Q18: =IF(B18="","",IF('×入力'!F369="未提出","未提出",IF(R18>0,"入力済み",IF('×入力'!F369="×なし（どこでもOK）","×なし","未入力")))) | R18: =IF(B18="","",'calcA'!IN23) | S18: =IF(OR(Q18="入力済み",Q18="×なし"),'calcA'!IM23,"") | T18: =IF('calcA'!C23=1,COUNTIFS('calcA'!$C$10:$C$54,1,'calcA'!$IM$10:$IM$54,"<"&'calcA'!IM23)+1,"") | U18: =IF('calcA'!IO23=0,"",INDEX('設定'!$E$11:$E$16,INDEX('calcA'!$D$2:$EQ$2,'calcA'!IO23))) | V18: =IF('calcA'!IO23=0,"",INDEX('設定'!$I$11:$I$34,INDEX('calcA'!$D$3:$EQ$3,'calcA'!IO23))) | W18: =IF(P18="","",IF('calcA'!JG23=1,"兄弟の日付・時刻が表にありません",IF(COUNTIF('調整・決定'!$C$6:$H$29,P18)>1,"2か所以上に入っています",IF('calcA'!IO23>0,IF(INDEX('calcA'!$D$4:$EQ$4,'calcA'!IO23)=0,"使えない枠に入っています",IF(INDEX('calcA'!$D$23:$EQ$23,'calcA'!IO23)=1,"×の枠に入っています",IF('calcA'!IV23=0,"（出来れば）兄弟の前後ではありません",IF(AND(RIGHT(D18,4)="空けたい",INDEX('calcA'!$D$106:$EQ$106,'calcA'!IO23)=1,INDEX('calcA'!$D$109:$EQ$109,'calcA'!IO23+1)=1),IF(D18="必ず空けたい","後ろの枠が空いていません","（出来れば）後ろが空いていません"),IF(AND(D18="空けない",INDEX('calcA'!$D$106:$EQ$106,'calcA'!IO23)=1,INDEX('calcA'!$D$109:$EQ$109,'calcA'!IO23+1)=0),"（出来れば）すぐ後が空いています",""))))),IF(OR(Q18="入力済み",Q18="×なし"),"未決定",""))))) | X18: =IF('calcA'!IK23=0,IF('calcA'!IL23=1,"入る枠がありません",""),INDEX('calcA'!$D$8:$EQ$8,'calcA'!IK23)) | Y18: =IF('calcA'!IR23=0,IF('calcA'!IS23=1,"入る枠がありません",""),INDEX('calcA'!$D$8:$EQ$8,'calcA'!IR23)) | Z18: =HYPERLINK("#'×入力'!B369","×入力へ")
A19: 15 | B19: 松本 たいが | C19: 早い日 | P19: =IF(B19="","",IF(COUNTIF($B$5:$B$49,B19)>1,IF(A19="","",A19&" ")&B19,B19)) | Q19: =IF(B19="","",IF('×入力'!F397="未提出","未提出",IF(R19>0,"入力済み",IF('×入力'!F397="×なし（どこでもOK）","×なし","未入力")))) | R19: =IF(B19="","",'calcA'!IN24) | S19: =IF(OR(Q19="入力済み",Q19="×なし"),'calcA'!IM24,"") | T19: =IF('calcA'!C24=1,COUNTIFS('calcA'!$C$10:$C$54,1,'calcA'!$IM$10:$IM$54,"<"&'calcA'!IM24)+1,"") | U19: =IF('calcA'!IO24=0,"",INDEX('設定'!$E$11:$E$16,INDEX('calcA'!$D$2:$EQ$2,'calcA'!IO24))) | V19: =IF('calcA'!IO24=0,"",INDEX('設定'!$I$11:$I$34,INDEX('calcA'!$D$3:$EQ$3,'calcA'!IO24))) | W19: =IF(P19="","",IF('calcA'!JG24=1,"兄弟の日付・時刻が表にありません",IF(COUNTIF('調整・決定'!$C$6:$H$29,P19)>1,"2か所以上に入っています",IF('calcA'!IO24>0,IF(INDEX('calcA'!$D$4:$EQ$4,'calcA'!IO24)=0,"使えない枠に入っています",IF(INDEX('calcA'!$D$24:$EQ$24,'calcA'!IO24)=1,"×の枠に入っています",IF('calcA'!IV24=0,"（出来れば）兄弟の前後ではありません",IF(AND(RIGHT(D19,4)="空けたい",INDEX('calcA'!$D$106:$EQ$106,'calcA'!IO24)=1,INDEX('calcA'!$D$109:$EQ$109,'calcA'!IO24+1)=1),IF(D19="必ず空けたい","後ろの枠が空いていません","（出来れば）後ろが空いていません"),IF(AND(D19="空けない",INDEX('calcA'!$D$106:$EQ$106,'calcA'!IO24)=1,INDEX('calcA'!$D$109:$EQ$109,'calcA'!IO24+1)=0),"（出来れば）すぐ後が空いています",""))))),IF(OR(Q19="入力済み",Q19="×なし"),"未決定",""))))) | X19: =IF('calcA'!IK24=0,IF('calcA'!IL24=1,"入る枠がありません",""),INDEX('calcA'!$D$8:$EQ$8,'calcA'!IK24)) | Y19: =IF('calcA'!IR24=0,IF('calcA'!IS24=1,"入る枠がありません",""),INDEX('calcA'!$D$8:$EQ$8,'calcA'!IR24)) | Z19: =HYPERLINK("#'×入力'!B397","×入力へ")
A20: 16 | B20: 井上 こはる | P20: =IF(B20="","",IF(COUNTIF($B$5:$B$49,B20)>1,IF(A20="","",A20&" ")&B20,B20)) | Q20: =IF(B20="","",IF('×入力'!F425="未提出","未提出",IF(R20>0,"入力済み",IF('×入力'!F425="×なし（どこでもOK）","×なし","未入力")))) | R20: =IF(B20="","",'calcA'!IN25) | S20: =IF(OR(Q20="入力済み",Q20="×なし"),'calcA'!IM25,"") | T20: =IF('calcA'!C25=1,COUNTIFS('calcA'!$C$10:$C$54,1,'calcA'!$IM$10:$IM$54,"<"&'calcA'!IM25)+1,"") | U20: =IF('calcA'!IO25=0,"",INDEX('設定'!$E$11:$E$16,INDEX('calcA'!$D$2:$EQ$2,'calcA'!IO25))) | V20: =IF('calcA'!IO25=0,"",INDEX('設定'!$I$11:$I$34,INDEX('calcA'!$D$3:$EQ$3,'calcA'!IO25))) | W20: =IF(P20="","",IF('calcA'!JG25=1,"兄弟の日付・時刻が表にありません",IF(COUNTIF('調整・決定'!$C$6:$H$29,P20)>1,"2か所以上に入っています",IF('calcA'!IO25>0,IF(INDEX('calcA'!$D$4:$EQ$4,'calcA'!IO25)=0,"使えない枠に入っています",IF(INDEX('calcA'!$D$25:$EQ$25,'calcA'!IO25)=1,"×の枠に入っています",IF('calcA'!IV25=0,"（出来れば）兄弟の前後ではありません",IF(AND(RIGHT(D20,4)="空けたい",INDEX('calcA'!$D$106:$EQ$106,'calcA'!IO25)=1,INDEX('calcA'!$D$109:$EQ$109,'calcA'!IO25+1)=1),IF(D20="必ず空けたい","後ろの枠が空いていません","（出来れば）後ろが空いていません"),IF(AND(D20="空けない",INDEX('calcA'!$D$106:$EQ$106,'calcA'!IO25)=1,INDEX('calcA'!$D$109:$EQ$109,'calcA'!IO25+1)=0),"（出来れば）すぐ後が空いています",""))))),IF(OR(Q20="入力済み",Q20="×なし"),"未決定",""))))) | X20: =IF('calcA'!IK25=0,IF('calcA'!IL25=1,"入る枠がありません",""),INDEX('calcA'!$D$8:$EQ$8,'calcA'!IK25)) | Y20: =IF('calcA'!IR25=0,IF('calcA'!IS25=1,"入る枠がありません",""),INDEX('calcA'!$D$8:$EQ$8,'calcA'!IR25)) | Z20: =HYPERLINK("#'×入力'!B425","×入力へ")
A21: 17 | B21: 木村 れん | P21: =IF(B21="","",IF(COUNTIF($B$5:$B$49,B21)>1,IF(A21="","",A21&" ")&B21,B21)) | Q21: =IF(B21="","",IF('×入力'!F453="未提出","未提出",IF(R21>0,"入力済み",IF('×入力'!F453="×なし（どこでもOK）","×なし","未入力")))) | R21: =IF(B21="","",'calcA'!IN26) | S21: =IF(OR(Q21="入力済み",Q21="×なし"),'calcA'!IM26,"") | T21: =IF('calcA'!C26=1,COUNTIFS('calcA'!$C$10:$C$54,1,'calcA'!$IM$10:$IM$54,"<"&'calcA'!IM26)+1,"") | U21: =IF('calcA'!IO26=0,"",INDEX('設定'!$E$11:$E$16,INDEX('calcA'!$D$2:$EQ$2,'calcA'!IO26))) | V21: =IF('calcA'!IO26=0,"",INDEX('設定'!$I$11:$I$34,INDEX('calcA'!$D$3:$EQ$3,'calcA'!IO26))) | W21: =IF(P21="","",IF('calcA'!JG26=1,"兄弟の日付・時刻が表にありません",IF(COUNTIF('調整・決定'!$C$6:$H$29,P21)>1,"2か所以上に入っています",IF('calcA'!IO26>0,IF(INDEX('calcA'!$D$4:$EQ$4,'calcA'!IO26)=0,"使えない枠に入っています",IF(INDEX('calcA'!$D$26:$EQ$26,'calcA'!IO26)=1,"×の枠に入っています",IF('calcA'!IV26=0,"（出来れば）兄弟の前後ではありません",IF(AND(RIGHT(D21,4)="空けたい",INDEX('calcA'!$D$106:$EQ$106,'calcA'!IO26)=1,INDEX('calcA'!$D$109:$EQ$109,'calcA'!IO26+1)=1),IF(D21="必ず空けたい","後ろの枠が空いていません","（出来れば）後ろが空いていません"),IF(AND(D21="空けない",INDEX('calcA'!$D$106:$EQ$106,'calcA'!IO26)=1,INDEX('calcA'!$D$109:$EQ$109,'calcA'!IO26+1)=0),"（出来れば）すぐ後が空いています",""))))),IF(OR(Q21="入力済み",Q21="×なし"),"未決定",""))))) | X21: =IF('calcA'!IK26=0,IF('calcA'!IL26=1,"入る枠がありません",""),INDEX('calcA'!$D$8:$EQ$8,'calcA'!IK26)) | Y21: =IF('calcA'!IR26=0,IF('calcA'!IS26=1,"入る枠がありません",""),INDEX('calcA'!$D$8:$EQ$8,'calcA'!IR26)) | Z21: =HYPERLINK("#'×入力'!B453","×入力へ")
A22: 18 | B22: 林 みお | P22: =IF(B22="","",IF(COUNTIF($B$5:$B$49,B22)>1,IF(A22="","",A22&" ")&B22,B22)) | Q22: =IF(B22="","",IF('×入力'!F481="未提出","未提出",IF(R22>0,"入力済み",IF('×入力'!F481="×なし（どこでもOK）","×なし","未入力")))) | R22: =IF(B22="","",'calcA'!IN27) | S22: =IF(OR(Q22="入力済み",Q22="×なし"),'calcA'!IM27,"") | T22: =IF('calcA'!C27=1,COUNTIFS('calcA'!$C$10:$C$54,1,'calcA'!$IM$10:$IM$54,"<"&'calcA'!IM27)+1,"") | U22: =IF('calcA'!IO27=0,"",INDEX('設定'!$E$11:$E$16,INDEX('calcA'!$D$2:$EQ$2,'calcA'!IO27))) | V22: =IF('calcA'!IO27=0,"",INDEX('設定'!$I$11:$I$34,INDEX('calcA'!$D$3:$EQ$3,'calcA'!IO27))) | W22: =IF(P22="","",IF('calcA'!JG27=1,"兄弟の日付・時刻が表にありません",IF(COUNTIF('調整・決定'!$C$6:$H$29,P22)>1,"2か所以上に入っています",IF('calcA'!IO27>0,IF(INDEX('calcA'!$D$4:$EQ$4,'calcA'!IO27)=0,"使えない枠に入っています",IF(INDEX('calcA'!$D$27:$EQ$27,'calcA'!IO27)=1,"×の枠に入っています",IF('calcA'!IV27=0,"（出来れば）兄弟の前後ではありません",IF(AND(RIGHT(D22,4)="空けたい",INDEX('calcA'!$D$106:$EQ$106,'calcA'!IO27)=1,INDEX('calcA'!$D$109:$EQ$109,'calcA'!IO27+1)=1),IF(D22="必ず空けたい","後ろの枠が空いていません","（出来れば）後ろが空いていません"),IF(AND(D22="空けない",INDEX('calcA'!$D$106:$EQ$106,'calcA'!IO27)=1,INDEX('calcA'!$D$109:$EQ$109,'calcA'!IO27+1)=0),"（出来れば）すぐ後が空いています",""))))),IF(OR(Q22="入力済み",Q22="×なし"),"未決定",""))))) | X22: =IF('calcA'!IK27=0,IF('calcA'!IL27=1,"入る枠がありません",""),INDEX('calcA'!$D$8:$EQ$8,'calcA'!IK27)) | Y22: =IF('calcA'!IR27=0,IF('calcA'!IS27=1,"入る枠がありません",""),INDEX('calcA'!$D$8:$EQ$8,'calcA'!IR27)) | Z22: =HYPERLINK("#'×入力'!B481","×入力へ")
A23: 19 | B23: 斎藤 かいと | E23: 〇 | F23: 1年2組・4年1組 | G23: 11月25日（水） | H23: 14:00〜 | I23: どちらでも | J23: 11月25日（水） | K23: 14:30〜 | L23: 兄弟②の前 | P23: =IF(B23="","",IF(COUNTIF($B$5:$B$49,B23)>1,IF(A23="","",A23&" ")&B23,B23)) | Q23: =IF(B23="","",IF('×入力'!F509="未提出","未提出",IF(R23>0,"入力済み",IF('×入力'!F509="×なし（どこでもOK）","×なし","未入力")))) | R23: =IF(B23="","",'calcA'!IN28) | S23: =IF(OR(Q23="入力済み",Q23="×なし"),'calcA'!IM28,"") | T23: =IF('calcA'!C28=1,COUNTIFS('calcA'!$C$10:$C$54,1,'calcA'!$IM$10:$IM$54,"<"&'calcA'!IM28)+1,"") | U23: =IF('calcA'!IO28=0,"",INDEX('設定'!$E$11:$E$16,INDEX('calcA'!$D$2:$EQ$2,'calcA'!IO28))) | V23: =IF('calcA'!IO28=0,"",INDEX('設定'!$I$11:$I$34,INDEX('calcA'!$D$3:$EQ$3,'calcA'!IO28))) | W23: =IF(P23="","",IF('calcA'!JG28=1,"兄弟の日付・時刻が表にありません",IF(COUNTIF('調整・決定'!$C$6:$H$29,P23)>1,"2か所以上に入っています",IF('calcA'!IO28>0,IF(INDEX('calcA'!$D$4:$EQ$4,'calcA'!IO28)=0,"使えない枠に入っています",IF(INDEX('calcA'!$D$28:$EQ$28,'calcA'!IO28)=1,"×の枠に入っています",IF('calcA'!IV28=0,"（出来れば）兄弟の前後ではありません",IF(AND(RIGHT(D23,4)="空けたい",INDEX('calcA'!$D$106:$EQ$106,'calcA'!IO28)=1,INDEX('calcA'!$D$109:$EQ$109,'calcA'!IO28+1)=1),IF(D23="必ず空けたい","後ろの枠が空いていません","（出来れば）後ろが空いていません"),IF(AND(D23="空けない",INDEX('calcA'!$D$106:$EQ$106,'calcA'!IO28)=1,INDEX('calcA'!$D$109:$EQ$109,'calcA'!IO28+1)=0),"（出来れば）すぐ後が空いています",""))))),IF(OR(Q23="入力済み",Q23="×なし"),"未決定",""))))) | X23: =IF('calcA'!IK28=0,IF('calcA'!IL28=1,"入る枠がありません",""),INDEX('calcA'!$D$8:$EQ$8,'calcA'!IK28)) | Y23: =IF('calcA'!IR28=0,IF('calcA'!IS28=1,"入る枠がありません",""),INDEX('calcA'!$D$8:$EQ$8,'calcA'!IR28)) | Z23: =HYPERLINK("#'×入力'!B509","×入力へ")
A24: 20 | B24: 清水 えま | P24: =IF(B24="","",IF(COUNTIF($B$5:$B$49,B24)>1,IF(A24="","",A24&" ")&B24,B24)) | Q24: =IF(B24="","",IF('×入力'!F537="未提出","未提出",IF(R24>0,"入力済み",IF('×入力'!F537="×なし（どこでもOK）","×なし","未入力")))) | R24: =IF(B24="","",'calcA'!IN29) | S24: =IF(OR(Q24="入力済み",Q24="×なし"),'calcA'!IM29,"") | T24: =IF('calcA'!C29=1,COUNTIFS('calcA'!$C$10:$C$54,1,'calcA'!$IM$10:$IM$54,"<"&'calcA'!IM29)+1,"") | U24: =IF('calcA'!IO29=0,"",INDEX('設定'!$E$11:$E$16,INDEX('calcA'!$D$2:$EQ$2,'calcA'!IO29))) | V24: =IF('calcA'!IO29=0,"",INDEX('設定'!$I$11:$I$34,INDEX('calcA'!$D$3:$EQ$3,'calcA'!IO29))) | W24: =IF(P24="","",IF('calcA'!JG29=1,"兄弟の日付・時刻が表にありません",IF(COUNTIF('調整・決定'!$C$6:$H$29,P24)>1,"2か所以上に入っています",IF('calcA'!IO29>0,IF(INDEX('calcA'!$D$4:$EQ$4,'calcA'!IO29)=0,"使えない枠に入っています",IF(INDEX('calcA'!$D$29:$EQ$29,'calcA'!IO29)=1,"×の枠に入っています",IF('calcA'!IV29=0,"（出来れば）兄弟の前後ではありません",IF(AND(RIGHT(D24,4)="空けたい",INDEX('calcA'!$D$106:$EQ$106,'calcA'!IO29)=1,INDEX('calcA'!$D$109:$EQ$109,'calcA'!IO29+1)=1),IF(D24="必ず空けたい","後ろの枠が空いていません","（出来れば）後ろが空いていません"),IF(AND(D24="空けない",INDEX('calcA'!$D$106:$EQ$106,'calcA'!IO29)=1,INDEX('calcA'!$D$109:$EQ$109,'calcA'!IO29+1)=0),"（出来れば）すぐ後が空いています",""))))),IF(OR(Q24="入力済み",Q24="×なし"),"未決定",""))))) | X24: =IF('calcA'!IK29=0,IF('calcA'!IL29=1,"入る枠がありません",""),INDEX('calcA'!$D$8:$EQ$8,'calcA'!IK29)) | Y24: =IF('calcA'!IR29=0,IF('calcA'!IS29=1,"入る枠がありません",""),INDEX('calcA'!$D$8:$EQ$8,'calcA'!IR29)) | Z24: =HYPERLINK("#'×入力'!B537","×入力へ")
A25: 21 | B25: 山崎 はやと | D25: 必ず空けたい | P25: =IF(B25="","",IF(COUNTIF($B$5:$B$49,B25)>1,IF(A25="","",A25&" ")&B25,B25)) | Q25: =IF(B25="","",IF('×入力'!F565="未提出","未提出",IF(R25>0,"入力済み",IF('×入力'!F565="×なし（どこでもOK）","×なし","未入力")))) | R25: =IF(B25="","",'calcA'!IN30) | S25: =IF(OR(Q25="入力済み",Q25="×なし"),'calcA'!IM30,"") | T25: =IF('calcA'!C30=1,COUNTIFS('calcA'!$C$10:$C$54,1,'calcA'!$IM$10:$IM$54,"<"&'calcA'!IM30)+1,"") | U25: =IF('calcA'!IO30=0,"",INDEX('設定'!$E$11:$E$16,INDEX('calcA'!$D$2:$EQ$2,'calcA'!IO30))) | V25: =IF('calcA'!IO30=0,"",INDEX('設定'!$I$11:$I$34,INDEX('calcA'!$D$3:$EQ$3,'calcA'!IO30))) | W25: =IF(P25="","",IF('calcA'!JG30=1,"兄弟の日付・時刻が表にありません",IF(COUNTIF('調整・決定'!$C$6:$H$29,P25)>1,"2か所以上に入っています",IF('calcA'!IO30>0,IF(INDEX('calcA'!$D$4:$EQ$4,'calcA'!IO30)=0,"使えない枠に入っています",IF(INDEX('calcA'!$D$30:$EQ$30,'calcA'!IO30)=1,"×の枠に入っています",IF('calcA'!IV30=0,"（出来れば）兄弟の前後ではありません",IF(AND(RIGHT(D25,4)="空けたい",INDEX('calcA'!$D$106:$EQ$106,'calcA'!IO30)=1,INDEX('calcA'!$D$109:$EQ$109,'calcA'!IO30+1)=1),IF(D25="必ず空けたい","後ろの枠が空いていません","（出来れば）後ろが空いていません"),IF(AND(D25="空けない",INDEX('calcA'!$D$106:$EQ$106,'calcA'!IO30)=1,INDEX('calcA'!$D$109:$EQ$109,'calcA'!IO30+1)=0),"（出来れば）すぐ後が空いています",""))))),IF(OR(Q25="入力済み",Q25="×なし"),"未決定",""))))) | X25: =IF('calcA'!IK30=0,IF('calcA'!IL30=1,"入る枠がありません",""),INDEX('calcA'!$D$8:$EQ$8,'calcA'!IK30)) | Y25: =IF('calcA'!IR30=0,IF('calcA'!IS30=1,"入る枠がありません",""),INDEX('calcA'!$D$8:$EQ$8,'calcA'!IR30)) | Z25: =HYPERLINK("#'×入力'!B565","×入力へ")
A26: 22 | B26: 森 つむぎ | P26: =IF(B26="","",IF(COUNTIF($B$5:$B$49,B26)>1,IF(A26="","",A26&" ")&B26,B26)) | Q26: =IF(B26="","",IF('×入力'!F593="未提出","未提出",IF(R26>0,"入力済み",IF('×入力'!F593="×なし（どこでもOK）","×なし","未入力")))) | R26: =IF(B26="","",'calcA'!IN31) | S26: =IF(OR(Q26="入力済み",Q26="×なし"),'calcA'!IM31,"") | T26: =IF('calcA'!C31=1,COUNTIFS('calcA'!$C$10:$C$54,1,'calcA'!$IM$10:$IM$54,"<"&'calcA'!IM31)+1,"") | U26: =IF('calcA'!IO31=0,"",INDEX('設定'!$E$11:$E$16,INDEX('calcA'!$D$2:$EQ$2,'calcA'!IO31))) | V26: =IF('calcA'!IO31=0,"",INDEX('設定'!$I$11:$I$34,INDEX('calcA'!$D$3:$EQ$3,'calcA'!IO31))) | W26: =IF(P26="","",IF('calcA'!JG31=1,"兄弟の日付・時刻が表にありません",IF(COUNTIF('調整・決定'!$C$6:$H$29,P26)>1,"2か所以上に入っています",IF('calcA'!IO31>0,IF(INDEX('calcA'!$D$4:$EQ$4,'calcA'!IO31)=0,"使えない枠に入っています",IF(INDEX('calcA'!$D$31:$EQ$31,'calcA'!IO31)=1,"×の枠に入っています",IF('calcA'!IV31=0,"（出来れば）兄弟の前後ではありません",IF(AND(RIGHT(D26,4)="空けたい",INDEX('calcA'!$D$106:$EQ$106,'calcA'!IO31)=1,INDEX('calcA'!$D$109:$EQ$109,'calcA'!IO31+1)=1),IF(D26="必ず空けたい","後ろの枠が空いていません","（出来れば）後ろが空いていません"),IF(AND(D26="空けない",INDEX('calcA'!$D$106:$EQ$106,'calcA'!IO31)=1,INDEX('calcA'!$D$109:$EQ$109,'calcA'!IO31+1)=0),"（出来れば）すぐ後が空いています",""))))),IF(OR(Q26="入力済み",Q26="×なし"),"未決定",""))))) | X26: =IF('calcA'!IK31=0,IF('calcA'!IL31=1,"入る枠がありません",""),INDEX('calcA'!$D$8:$EQ$8,'calcA'!IK31)) | Y26: =IF('calcA'!IR31=0,IF('calcA'!IS31=1,"入る枠がありません",""),INDEX('calcA'!$D$8:$EQ$8,'calcA'!IR31)) | Z26: =HYPERLINK("#'×入力'!B593","×入力へ")
A27: 23 | B27: 池田 あさひ | C27: 遅い日 | P27: =IF(B27="","",IF(COUNTIF($B$5:$B$49,B27)>1,IF(A27="","",A27&" ")&B27,B27)) | Q27: =IF(B27="","",IF('×入力'!F621="未提出","未提出",IF(R27>0,"入力済み",IF('×入力'!F621="×なし（どこでもOK）","×なし","未入力")))) | R27: =IF(B27="","",'calcA'!IN32) | S27: =IF(OR(Q27="入力済み",Q27="×なし"),'calcA'!IM32,"") | T27: =IF('calcA'!C32=1,COUNTIFS('calcA'!$C$10:$C$54,1,'calcA'!$IM$10:$IM$54,"<"&'calcA'!IM32)+1,"") | U27: =IF('calcA'!IO32=0,"",INDEX('設定'!$E$11:$E$16,INDEX('calcA'!$D$2:$EQ$2,'calcA'!IO32))) | V27: =IF('calcA'!IO32=0,"",INDEX('設定'!$I$11:$I$34,INDEX('calcA'!$D$3:$EQ$3,'calcA'!IO32))) | W27: =IF(P27="","",IF('calcA'!JG32=1,"兄弟の日付・時刻が表にありません",IF(COUNTIF('調整・決定'!$C$6:$H$29,P27)>1,"2か所以上に入っています",IF('calcA'!IO32>0,IF(INDEX('calcA'!$D$4:$EQ$4,'calcA'!IO32)=0,"使えない枠に入っています",IF(INDEX('calcA'!$D$32:$EQ$32,'calcA'!IO32)=1,"×の枠に入っています",IF('calcA'!IV32=0,"（出来れば）兄弟の前後ではありません",IF(AND(RIGHT(D27,4)="空けたい",INDEX('calcA'!$D$106:$EQ$106,'calcA'!IO32)=1,INDEX('calcA'!$D$109:$EQ$109,'calcA'!IO32+1)=1),IF(D27="必ず空けたい","後ろの枠が空いていません","（出来れば）後ろが空いていません"),IF(AND(D27="空けない",INDEX('calcA'!$D$106:$EQ$106,'calcA'!IO32)=1,INDEX('calcA'!$D$109:$EQ$109,'calcA'!IO32+1)=0),"（出来れば）すぐ後が空いています",""))))),IF(OR(Q27="入力済み",Q27="×なし"),"未決定",""))))) | X27: =IF('calcA'!IK32=0,IF('calcA'!IL32=1,"入る枠がありません",""),INDEX('calcA'!$D$8:$EQ$8,'calcA'!IK32)) | Y27: =IF('calcA'!IR32=0,IF('calcA'!IS32=1,"入る枠がありません",""),INDEX('calcA'!$D$8:$EQ$8,'calcA'!IR32)) | Z27: =HYPERLINK("#'×入力'!B621","×入力へ")
A28: 24 | B28: 橋本 ここな | P28: =IF(B28="","",IF(COUNTIF($B$5:$B$49,B28)>1,IF(A28="","",A28&" ")&B28,B28)) | Q28: =IF(B28="","",IF('×入力'!F649="未提出","未提出",IF(R28>0,"入力済み",IF('×入力'!F649="×なし（どこでもOK）","×なし","未入力")))) | R28: =IF(B28="","",'calcA'!IN33) | S28: =IF(OR(Q28="入力済み",Q28="×なし"),'calcA'!IM33,"") | T28: =IF('calcA'!C33=1,COUNTIFS('calcA'!$C$10:$C$54,1,'calcA'!$IM$10:$IM$54,"<"&'calcA'!IM33)+1,"") | U28: =IF('calcA'!IO33=0,"",INDEX('設定'!$E$11:$E$16,INDEX('calcA'!$D$2:$EQ$2,'calcA'!IO33))) | V28: =IF('calcA'!IO33=0,"",INDEX('設定'!$I$11:$I$34,INDEX('calcA'!$D$3:$EQ$3,'calcA'!IO33))) | W28: =IF(P28="","",IF('calcA'!JG33=1,"兄弟の日付・時刻が表にありません",IF(COUNTIF('調整・決定'!$C$6:$H$29,P28)>1,"2か所以上に入っています",IF('calcA'!IO33>0,IF(INDEX('calcA'!$D$4:$EQ$4,'calcA'!IO33)=0,"使えない枠に入っています",IF(INDEX('calcA'!$D$33:$EQ$33,'calcA'!IO33)=1,"×の枠に入っています",IF('calcA'!IV33=0,"（出来れば）兄弟の前後ではありません",IF(AND(RIGHT(D28,4)="空けたい",INDEX('calcA'!$D$106:$EQ$106,'calcA'!IO33)=1,INDEX('calcA'!$D$109:$EQ$109,'calcA'!IO33+1)=1),IF(D28="必ず空けたい","後ろの枠が空いていません","（出来れば）後ろが空いていません"),IF(AND(D28="空けない",INDEX('calcA'!$D$106:$EQ$106,'calcA'!IO33)=1,INDEX('calcA'!$D$109:$EQ$109,'calcA'!IO33+1)=0),"（出来れば）すぐ後が空いています",""))))),IF(OR(Q28="入力済み",Q28="×なし"),"未決定",""))))) | X28: =IF('calcA'!IK33=0,IF('calcA'!IL33=1,"入る枠がありません",""),INDEX('calcA'!$D$8:$EQ$8,'calcA'!IK33)) | Y28: =IF('calcA'!IR33=0,IF('calcA'!IS33=1,"入る枠がありません",""),INDEX('calcA'!$D$8:$EQ$8,'calcA'!IR33)) | Z28: =HYPERLINK("#'×入力'!B649","×入力へ")
A29: 25 | B29: 阿部 ゆうま | D29: 空けない | P29: =IF(B29="","",IF(COUNTIF($B$5:$B$49,B29)>1,IF(A29="","",A29&" ")&B29,B29)) | Q29: =IF(B29="","",IF('×入力'!F677="未提出","未提出",IF(R29>0,"入力済み",IF('×入力'!F677="×なし（どこでもOK）","×なし","未入力")))) | R29: =IF(B29="","",'calcA'!IN34) | S29: =IF(OR(Q29="入力済み",Q29="×なし"),'calcA'!IM34,"") | T29: =IF('calcA'!C34=1,COUNTIFS('calcA'!$C$10:$C$54,1,'calcA'!$IM$10:$IM$54,"<"&'calcA'!IM34)+1,"") | U29: =IF('calcA'!IO34=0,"",INDEX('設定'!$E$11:$E$16,INDEX('calcA'!$D$2:$EQ$2,'calcA'!IO34))) | V29: =IF('calcA'!IO34=0,"",INDEX('設定'!$I$11:$I$34,INDEX('calcA'!$D$3:$EQ$3,'calcA'!IO34))) | W29: =IF(P29="","",IF('calcA'!JG34=1,"兄弟の日付・時刻が表にありません",IF(COUNTIF('調整・決定'!$C$6:$H$29,P29)>1,"2か所以上に入っています",IF('calcA'!IO34>0,IF(INDEX('calcA'!$D$4:$EQ$4,'calcA'!IO34)=0,"使えない枠に入っています",IF(INDEX('calcA'!$D$34:$EQ$34,'calcA'!IO34)=1,"×の枠に入っています",IF('calcA'!IV34=0,"（出来れば）兄弟の前後ではありません",IF(AND(RIGHT(D29,4)="空けたい",INDEX('calcA'!$D$106:$EQ$106,'calcA'!IO34)=1,INDEX('calcA'!$D$109:$EQ$109,'calcA'!IO34+1)=1),IF(D29="必ず空けたい","後ろの枠が空いていません","（出来れば）後ろが空いていません"),IF(AND(D29="空けない",INDEX('calcA'!$D$106:$EQ$106,'calcA'!IO34)=1,INDEX('calcA'!$D$109:$EQ$109,'calcA'!IO34+1)=0),"（出来れば）すぐ後が空いています",""))))),IF(OR(Q29="入力済み",Q29="×なし"),"未決定",""))))) | X29: =IF('calcA'!IK34=0,IF('calcA'!IL34=1,"入る枠がありません",""),INDEX('calcA'!$D$8:$EQ$8,'calcA'!IK34)) | Y29: =IF('calcA'!IR34=0,IF('calcA'!IS34=1,"入る枠がありません",""),INDEX('calcA'!$D$8:$EQ$8,'calcA'!IR34)) | Z29: =HYPERLINK("#'×入力'!B677","×入力へ")
A30: 26 | B30: 石川 ほのか | P30: =IF(B30="","",IF(COUNTIF($B$5:$B$49,B30)>1,IF(A30="","",A30&" ")&B30,B30)) | Q30: =IF(B30="","",IF('×入力'!F705="未提出","未提出",IF(R30>0,"入力済み",IF('×入力'!F705="×なし（どこでもOK）","×なし","未入力")))) | R30: =IF(B30="","",'calcA'!IN35) | S30: =IF(OR(Q30="入力済み",Q30="×なし"),'calcA'!IM35,"") | T30: =IF('calcA'!C35=1,COUNTIFS('calcA'!$C$10:$C$54,1,'calcA'!$IM$10:$IM$54,"<"&'calcA'!IM35)+1,"") | U30: =IF('calcA'!IO35=0,"",INDEX('設定'!$E$11:$E$16,INDEX('calcA'!$D$2:$EQ$2,'calcA'!IO35))) | V30: =IF('calcA'!IO35=0,"",INDEX('設定'!$I$11:$I$34,INDEX('calcA'!$D$3:$EQ$3,'calcA'!IO35))) | W30: =IF(P30="","",IF('calcA'!JG35=1,"兄弟の日付・時刻が表にありません",IF(COUNTIF('調整・決定'!$C$6:$H$29,P30)>1,"2か所以上に入っています",IF('calcA'!IO35>0,IF(INDEX('calcA'!$D$4:$EQ$4,'calcA'!IO35)=0,"使えない枠に入っています",IF(INDEX('calcA'!$D$35:$EQ$35,'calcA'!IO35)=1,"×の枠に入っています",IF('calcA'!IV35=0,"（出来れば）兄弟の前後ではありません",IF(AND(RIGHT(D30,4)="空けたい",INDEX('calcA'!$D$106:$EQ$106,'calcA'!IO35)=1,INDEX('calcA'!$D$109:$EQ$109,'calcA'!IO35+1)=1),IF(D30="必ず空けたい","後ろの枠が空いていません","（出来れば）後ろが空いていません"),IF(AND(D30="空けない",INDEX('calcA'!$D$106:$EQ$106,'calcA'!IO35)=1,INDEX('calcA'!$D$109:$EQ$109,'calcA'!IO35+1)=0),"（出来れば）すぐ後が空いています",""))))),IF(OR(Q30="入力済み",Q30="×なし"),"未決定",""))))) | X30: =IF('calcA'!IK35=0,IF('calcA'!IL35=1,"入る枠がありません",""),INDEX('calcA'!$D$8:$EQ$8,'calcA'!IK35)) | Y30: =IF('calcA'!IR35=0,IF('calcA'!IS35=1,"入る枠がありません",""),INDEX('calcA'!$D$8:$EQ$8,'calcA'!IR35)) | Z30: =HYPERLINK("#'×入力'!B705","×入力へ")
A31: 27 | B31: 山下 しょう | E31: 〇 | F31: 3年1組 | P31: =IF(B31="","",IF(COUNTIF($B$5:$B$49,B31)>1,IF(A31="","",A31&" ")&B31,B31)) | Q31: =IF(B31="","",IF('×入力'!F733="未提出","未提出",IF(R31>0,"入力済み",IF('×入力'!F733="×なし（どこでもOK）","×なし","未入力")))) | R31: =IF(B31="","",'calcA'!IN36) | S31: =IF(OR(Q31="入力済み",Q31="×なし"),'calcA'!IM36,"") | T31: =IF('calcA'!C36=1,COUNTIFS('calcA'!$C$10:$C$54,1,'calcA'!$IM$10:$IM$54,"<"&'calcA'!IM36)+1,"") | U31: =IF('calcA'!IO36=0,"",INDEX('設定'!$E$11:$E$16,INDEX('calcA'!$D$2:$EQ$2,'calcA'!IO36))) | V31: =IF('calcA'!IO36=0,"",INDEX('設定'!$I$11:$I$34,INDEX('calcA'!$D$3:$EQ$3,'calcA'!IO36))) | W31: =IF(P31="","",IF('calcA'!JG36=1,"兄弟の日付・時刻が表にありません",IF(COUNTIF('調整・決定'!$C$6:$H$29,P31)>1,"2か所以上に入っています",IF('calcA'!IO36>0,IF(INDEX('calcA'!$D$4:$EQ$4,'calcA'!IO36)=0,"使えない枠に入っています",IF(INDEX('calcA'!$D$36:$EQ$36,'calcA'!IO36)=1,"×の枠に入っています",IF('calcA'!IV36=0,"（出来れば）兄弟の前後ではありません",IF(AND(RIGHT(D31,4)="空けたい",INDEX('calcA'!$D$106:$EQ$106,'calcA'!IO36)=1,INDEX('calcA'!$D$109:$EQ$109,'calcA'!IO36+1)=1),IF(D31="必ず空けたい","後ろの枠が空いていません","（出来れば）後ろが空いていません"),IF(AND(D31="空けない",INDEX('calcA'!$D$106:$EQ$106,'calcA'!IO36)=1,INDEX('calcA'!$D$109:$EQ$109,'calcA'!IO36+1)=0),"（出来れば）すぐ後が空いています",""))))),IF(OR(Q31="入力済み",Q31="×なし"),"未決定",""))))) | X31: =IF('calcA'!IK36=0,IF('calcA'!IL36=1,"入る枠がありません",""),INDEX('calcA'!$D$8:$EQ$8,'calcA'!IK36)) | Y31: =IF('calcA'!IR36=0,IF('calcA'!IS36=1,"入る枠がありません",""),INDEX('calcA'!$D$8:$EQ$8,'calcA'!IR36)) | Z31: =HYPERLINK("#'×入力'!B733","×入力へ")
A32: 28 | B32: 中島 あかり | P32: =IF(B32="","",IF(COUNTIF($B$5:$B$49,B32)>1,IF(A32="","",A32&" ")&B32,B32)) | Q32: =IF(B32="","",IF('×入力'!F761="未提出","未提出",IF(R32>0,"入力済み",IF('×入力'!F761="×なし（どこでもOK）","×なし","未入力")))) | R32: =IF(B32="","",'calcA'!IN37) | S32: =IF(OR(Q32="入力済み",Q32="×なし"),'calcA'!IM37,"") | T32: =IF('calcA'!C37=1,COUNTIFS('calcA'!$C$10:$C$54,1,'calcA'!$IM$10:$IM$54,"<"&'calcA'!IM37)+1,"") | U32: =IF('calcA'!IO37=0,"",INDEX('設定'!$E$11:$E$16,INDEX('calcA'!$D$2:$EQ$2,'calcA'!IO37))) | V32: =IF('calcA'!IO37=0,"",INDEX('設定'!$I$11:$I$34,INDEX('calcA'!$D$3:$EQ$3,'calcA'!IO37))) | W32: =IF(P32="","",IF('calcA'!JG37=1,"兄弟の日付・時刻が表にありません",IF(COUNTIF('調整・決定'!$C$6:$H$29,P32)>1,"2か所以上に入っています",IF('calcA'!IO37>0,IF(INDEX('calcA'!$D$4:$EQ$4,'calcA'!IO37)=0,"使えない枠に入っています",IF(INDEX('calcA'!$D$37:$EQ$37,'calcA'!IO37)=1,"×の枠に入っています",IF('calcA'!IV37=0,"（出来れば）兄弟の前後ではありません",IF(AND(RIGHT(D32,4)="空けたい",INDEX('calcA'!$D$106:$EQ$106,'calcA'!IO37)=1,INDEX('calcA'!$D$109:$EQ$109,'calcA'!IO37+1)=1),IF(D32="必ず空けたい","後ろの枠が空いていません","（出来れば）後ろが空いていません"),IF(AND(D32="空けない",INDEX('calcA'!$D$106:$EQ$106,'calcA'!IO37)=1,INDEX('calcA'!$D$109:$EQ$109,'calcA'!IO37+1)=0),"（出来れば）すぐ後が空いています",""))))),IF(OR(Q32="入力済み",Q32="×なし"),"未決定",""))))) | X32: =IF('calcA'!IK37=0,IF('calcA'!IL37=1,"入る枠がありません",""),INDEX('calcA'!$D$8:$EQ$8,'calcA'!IK37)) | Y32: =IF('calcA'!IR37=0,IF('calcA'!IS37=1,"入る枠がありません",""),INDEX('calcA'!$D$8:$EQ$8,'calcA'!IR37)) | Z32: =HYPERLINK("#'×入力'!B761","×入力へ")
A33: 29 | B33: 石井 けんと | P33: =IF(B33="","",IF(COUNTIF($B$5:$B$49,B33)>1,IF(A33="","",A33&" ")&B33,B33)) | Q33: =IF(B33="","",IF('×入力'!F789="未提出","未提出",IF(R33>0,"入力済み",IF('×入力'!F789="×なし（どこでもOK）","×なし","未入力")))) | R33: =IF(B33="","",'calcA'!IN38) | S33: =IF(OR(Q33="入力済み",Q33="×なし"),'calcA'!IM38,"") | T33: =IF('calcA'!C38=1,COUNTIFS('calcA'!$C$10:$C$54,1,'calcA'!$IM$10:$IM$54,"<"&'calcA'!IM38)+1,"") | U33: =IF('calcA'!IO38=0,"",INDEX('設定'!$E$11:$E$16,INDEX('calcA'!$D$2:$EQ$2,'calcA'!IO38))) | V33: =IF('calcA'!IO38=0,"",INDEX('設定'!$I$11:$I$34,INDEX('calcA'!$D$3:$EQ$3,'calcA'!IO38))) | W33: =IF(P33="","",IF('calcA'!JG38=1,"兄弟の日付・時刻が表にありません",IF(COUNTIF('調整・決定'!$C$6:$H$29,P33)>1,"2か所以上に入っています",IF('calcA'!IO38>0,IF(INDEX('calcA'!$D$4:$EQ$4,'calcA'!IO38)=0,"使えない枠に入っています",IF(INDEX('calcA'!$D$38:$EQ$38,'calcA'!IO38)=1,"×の枠に入っています",IF('calcA'!IV38=0,"（出来れば）兄弟の前後ではありません",IF(AND(RIGHT(D33,4)="空けたい",INDEX('calcA'!$D$106:$EQ$106,'calcA'!IO38)=1,INDEX('calcA'!$D$109:$EQ$109,'calcA'!IO38+1)=1),IF(D33="必ず空けたい","後ろの枠が空いていません","（出来れば）後ろが空いていません"),IF(AND(D33="空けない",INDEX('calcA'!$D$106:$EQ$106,'calcA'!IO38)=1,INDEX('calcA'!$D$109:$EQ$109,'calcA'!IO38+1)=0),"（出来れば）すぐ後が空いています",""))))),IF(OR(Q33="入力済み",Q33="×なし"),"未決定",""))))) | X33: =IF('calcA'!IK38=0,IF('calcA'!IL38=1,"入る枠がありません",""),INDEX('calcA'!$D$8:$EQ$8,'calcA'!IK38)) | Y33: =IF('calcA'!IR38=0,IF('calcA'!IS38=1,"入る枠がありません",""),INDEX('calcA'!$D$8:$EQ$8,'calcA'!IR38)) | Z33: =HYPERLINK("#'×入力'!B789","×入力へ")
A34: 30 | B34: 小川 ゆず | C34: 遅い時刻 | P34: =IF(B34="","",IF(COUNTIF($B$5:$B$49,B34)>1,IF(A34="","",A34&" ")&B34,B34)) | Q34: =IF(B34="","",IF('×入力'!F817="未提出","未提出",IF(R34>0,"入力済み",IF('×入力'!F817="×なし（どこでもOK）","×なし","未入力")))) | R34: =IF(B34="","",'calcA'!IN39) | S34: =IF(OR(Q34="入力済み",Q34="×なし"),'calcA'!IM39,"") | T34: =IF('calcA'!C39=1,COUNTIFS('calcA'!$C$10:$C$54,1,'calcA'!$IM$10:$IM$54,"<"&'calcA'!IM39)+1,"") | U34: =IF('calcA'!IO39=0,"",INDEX('設定'!$E$11:$E$16,INDEX('calcA'!$D$2:$EQ$2,'calcA'!IO39))) | V34: =IF('calcA'!IO39=0,"",INDEX('設定'!$I$11:$I$34,INDEX('calcA'!$D$3:$EQ$3,'calcA'!IO39))) | W34: =IF(P34="","",IF('calcA'!JG39=1,"兄弟の日付・時刻が表にありません",IF(COUNTIF('調整・決定'!$C$6:$H$29,P34)>1,"2か所以上に入っています",IF('calcA'!IO39>0,IF(INDEX('calcA'!$D$4:$EQ$4,'calcA'!IO39)=0,"使えない枠に入っています",IF(INDEX('calcA'!$D$39:$EQ$39,'calcA'!IO39)=1,"×の枠に入っています",IF('calcA'!IV39=0,"（出来れば）兄弟の前後ではありません",IF(AND(RIGHT(D34,4)="空けたい",INDEX('calcA'!$D$106:$EQ$106,'calcA'!IO39)=1,INDEX('calcA'!$D$109:$EQ$109,'calcA'!IO39+1)=1),IF(D34="必ず空けたい","後ろの枠が空いていません","（出来れば）後ろが空いていません"),IF(AND(D34="空けない",INDEX('calcA'!$D$106:$EQ$106,'calcA'!IO39)=1,INDEX('calcA'!$D$109:$EQ$109,'calcA'!IO39+1)=0),"（出来れば）すぐ後が空いています",""))))),IF(OR(Q34="入力済み",Q34="×なし"),"未決定",""))))) | X34: =IF('calcA'!IK39=0,IF('calcA'!IL39=1,"入る枠がありません",""),INDEX('calcA'!$D$8:$EQ$8,'calcA'!IK39)) | Y34: =IF('calcA'!IR39=0,IF('calcA'!IS39=1,"入る枠がありません",""),INDEX('calcA'!$D$8:$EQ$8,'calcA'!IR39)) | Z34: =HYPERLINK("#'×入力'!B817","×入力へ")
A35: 31 | B35: 前田 だいち | P35: =IF(B35="","",IF(COUNTIF($B$5:$B$49,B35)>1,IF(A35="","",A35&" ")&B35,B35)) | Q35: =IF(B35="","",IF('×入力'!F845="未提出","未提出",IF(R35>0,"入力済み",IF('×入力'!F845="×なし（どこでもOK）","×なし","未入力")))) | R35: =IF(B35="","",'calcA'!IN40) | S35: =IF(OR(Q35="入力済み",Q35="×なし"),'calcA'!IM40,"") | T35: =IF('calcA'!C40=1,COUNTIFS('calcA'!$C$10:$C$54,1,'calcA'!$IM$10:$IM$54,"<"&'calcA'!IM40)+1,"") | U35: =IF('calcA'!IO40=0,"",INDEX('設定'!$E$11:$E$16,INDEX('calcA'!$D$2:$EQ$2,'calcA'!IO40))) | V35: =IF('calcA'!IO40=0,"",INDEX('設定'!$I$11:$I$34,INDEX('calcA'!$D$3:$EQ$3,'calcA'!IO40))) | W35: =IF(P35="","",IF('calcA'!JG40=1,"兄弟の日付・時刻が表にありません",IF(COUNTIF('調整・決定'!$C$6:$H$29,P35)>1,"2か所以上に入っています",IF('calcA'!IO40>0,IF(INDEX('calcA'!$D$4:$EQ$4,'calcA'!IO40)=0,"使えない枠に入っています",IF(INDEX('calcA'!$D$40:$EQ$40,'calcA'!IO40)=1,"×の枠に入っています",IF('calcA'!IV40=0,"（出来れば）兄弟の前後ではありません",IF(AND(RIGHT(D35,4)="空けたい",INDEX('calcA'!$D$106:$EQ$106,'calcA'!IO40)=1,INDEX('calcA'!$D$109:$EQ$109,'calcA'!IO40+1)=1),IF(D35="必ず空けたい","後ろの枠が空いていません","（出来れば）後ろが空いていません"),IF(AND(D35="空けない",INDEX('calcA'!$D$106:$EQ$106,'calcA'!IO40)=1,INDEX('calcA'!$D$109:$EQ$109,'calcA'!IO40+1)=0),"（出来れば）すぐ後が空いています",""))))),IF(OR(Q35="入力済み",Q35="×なし"),"未決定",""))))) | X35: =IF('calcA'!IK40=0,IF('calcA'!IL40=1,"入る枠がありません",""),INDEX('calcA'!$D$8:$EQ$8,'calcA'!IK40)) | Y35: =IF('calcA'!IR40=0,IF('calcA'!IS40=1,"入る枠がありません",""),INDEX('calcA'!$D$8:$EQ$8,'calcA'!IR40)) | Z35: =HYPERLINK("#'×入力'!B845","×入力へ")
A36: 32 | B36: 岡田 みゆ | P36: =IF(B36="","",IF(COUNTIF($B$5:$B$49,B36)>1,IF(A36="","",A36&" ")&B36,B36)) | Q36: =IF(B36="","",IF('×入力'!F873="未提出","未提出",IF(R36>0,"入力済み",IF('×入力'!F873="×なし（どこでもOK）","×なし","未入力")))) | R36: =IF(B36="","",'calcA'!IN41) | S36: =IF(OR(Q36="入力済み",Q36="×なし"),'calcA'!IM41,"") | T36: =IF('calcA'!C41=1,COUNTIFS('calcA'!$C$10:$C$54,1,'calcA'!$IM$10:$IM$54,"<"&'calcA'!IM41)+1,"") | U36: =IF('calcA'!IO41=0,"",INDEX('設定'!$E$11:$E$16,INDEX('calcA'!$D$2:$EQ$2,'calcA'!IO41))) | V36: =IF('calcA'!IO41=0,"",INDEX('設定'!$I$11:$I$34,INDEX('calcA'!$D$3:$EQ$3,'calcA'!IO41))) | W36: =IF(P36="","",IF('calcA'!JG41=1,"兄弟の日付・時刻が表にありません",IF(COUNTIF('調整・決定'!$C$6:$H$29,P36)>1,"2か所以上に入っています",IF('calcA'!IO41>0,IF(INDEX('calcA'!$D$4:$EQ$4,'calcA'!IO41)=0,"使えない枠に入っています",IF(INDEX('calcA'!$D$41:$EQ$41,'calcA'!IO41)=1,"×の枠に入っています",IF('calcA'!IV41=0,"（出来れば）兄弟の前後ではありません",IF(AND(RIGHT(D36,4)="空けたい",INDEX('calcA'!$D$106:$EQ$106,'calcA'!IO41)=1,INDEX('calcA'!$D$109:$EQ$109,'calcA'!IO41+1)=1),IF(D36="必ず空けたい","後ろの枠が空いていません","（出来れば）後ろが空いていません"),IF(AND(D36="空けない",INDEX('calcA'!$D$106:$EQ$106,'calcA'!IO41)=1,INDEX('calcA'!$D$109:$EQ$109,'calcA'!IO41+1)=0),"（出来れば）すぐ後が空いています",""))))),IF(OR(Q36="入力済み",Q36="×なし"),"未決定",""))))) | X36: =IF('calcA'!IK41=0,IF('calcA'!IL41=1,"入る枠がありません",""),INDEX('calcA'!$D$8:$EQ$8,'calcA'!IK41)) | Y36: =IF('calcA'!IR41=0,IF('calcA'!IS41=1,"入る枠がありません",""),INDEX('calcA'!$D$8:$EQ$8,'calcA'!IR41)) | Z36: =HYPERLINK("#'×入力'!B873","×入力へ")
A37: 33 | B37: 長谷川 こうき | C37: 早い時刻 | P37: =IF(B37="","",IF(COUNTIF($B$5:$B$49,B37)>1,IF(A37="","",A37&" ")&B37,B37)) | Q37: =IF(B37="","",IF('×入力'!F901="未提出","未提出",IF(R37>0,"入力済み",IF('×入力'!F901="×なし（どこでもOK）","×なし","未入力")))) | R37: =IF(B37="","",'calcA'!IN42) | S37: =IF(OR(Q37="入力済み",Q37="×なし"),'calcA'!IM42,"") | T37: =IF('calcA'!C42=1,COUNTIFS('calcA'!$C$10:$C$54,1,'calcA'!$IM$10:$IM$54,"<"&'calcA'!IM42)+1,"") | U37: =IF('calcA'!IO42=0,"",INDEX('設定'!$E$11:$E$16,INDEX('calcA'!$D$2:$EQ$2,'calcA'!IO42))) | V37: =IF('calcA'!IO42=0,"",INDEX('設定'!$I$11:$I$34,INDEX('calcA'!$D$3:$EQ$3,'calcA'!IO42))) | W37: =IF(P37="","",IF('calcA'!JG42=1,"兄弟の日付・時刻が表にありません",IF(COUNTIF('調整・決定'!$C$6:$H$29,P37)>1,"2か所以上に入っています",IF('calcA'!IO42>0,IF(INDEX('calcA'!$D$4:$EQ$4,'calcA'!IO42)=0,"使えない枠に入っています",IF(INDEX('calcA'!$D$42:$EQ$42,'calcA'!IO42)=1,"×の枠に入っています",IF('calcA'!IV42=0,"（出来れば）兄弟の前後ではありません",IF(AND(RIGHT(D37,4)="空けたい",INDEX('calcA'!$D$106:$EQ$106,'calcA'!IO42)=1,INDEX('calcA'!$D$109:$EQ$109,'calcA'!IO42+1)=1),IF(D37="必ず空けたい","後ろの枠が空いていません","（出来れば）後ろが空いていません"),IF(AND(D37="空けない",INDEX('calcA'!$D$106:$EQ$106,'calcA'!IO42)=1,INDEX('calcA'!$D$109:$EQ$109,'calcA'!IO42+1)=0),"（出来れば）すぐ後が空いています",""))))),IF(OR(Q37="入力済み",Q37="×なし"),"未決定",""))))) | X37: =IF('calcA'!IK42=0,IF('calcA'!IL42=1,"入る枠がありません",""),INDEX('calcA'!$D$8:$EQ$8,'calcA'!IK42)) | Y37: =IF('calcA'!IR42=0,IF('calcA'!IS42=1,"入る枠がありません",""),INDEX('calcA'!$D$8:$EQ$8,'calcA'!IR42)) | Z37: =HYPERLINK("#'×入力'!B901","×入力へ")
