Workbook
Name 自動案の表: '自動案'!$C$6:$L$29
Name 決定の表: '調整・決定'!$C$6:$L$29

Sheet ホーム
A1: 面談日程ツール
A2: ×のついた予定表から、個人面談の日程を組むツールです（マクロなし）。黄色のマスが入力する場所です。
B4: いまの状況
B5: 名簿の人数 | D5: ×入力済み | F5: 未入力 | H5: 未提出 | J5: 決定済み | L5: 未決定
B6: =COUNTIF('名簿'!$B$5:$B$49,"?*") | D6: =COUNTIF('名簿'!$H$5:$H$49,"入力済み")+COUNTIF('名簿'!$H$5:$H$49,"×なし") | F6: =COUNTIF('名簿'!$H$5:$H$49,"未入力") | H6: =COUNTIF('名簿'!$H$5:$H$49,"未提出") | J6: =SUMPRODUCT(('名簿'!$L$5:$L$49<>"")*1) | L6: =COUNTIF('名簿'!$N$5:$N$49,"未決定")
B8: 使う順番
B9: 1 | C9: 日付と時間枠を決める | K9: =HYPERLINK("#'設定'!A1","開く ▶")
C10: 面談する日付、時間帯（2つまで）、1枠の長さ。出張などで組まない日・時間もここで止めます。
B12: 2 | C12: 名簿を貼り付ける | K12: =HYPERLINK("#'名簿'!A1","開く ▶")
C13: 番号と名前を貼り付けます。兄弟・希望の時間・後ろを空けるもここで選びます。
B15: 3 | C15: ×を入力する | K15: =HYPERLINK("#'×入力'!A1","開く ▶")
C16: 予定表と同じ形の表に「×」。日付の上・時刻の左の欄で、1日全部・その時間全部も一度に×にできます。
B18: 4 | C18: 自動案を見る | K18: =HYPERLINK("#'自動案'!A1","開く ▶")
C19: 入れられる枠が少ない家庭から順に自動で組んだ案。よければ調整・決定に貼り付けます。
B21: 5 | C21: 調整して決定する | K21: =HYPERLINK("#'調整・決定'!A1","開く ▶")
C22: プルダウンで手直しして日程を決めます。児童を選ぶと、入れられる枠に色がつきます。
B26: くわしい使い方
B27: 1. 「設定」シート
B28: ・面談の日付（上から順に、最大10日）、時間帯（午前と午後に分けるときは2つ）と1枠の長さを入れます（1日最大24枠）。
B29: ・空けたい日や休憩の時刻には「〇」を選びます。自動案では、ほかに入る枠がないときだけ使われます。
B30: ・出張や会議などで面談を組まない日・時間・枠は、右の「先生の都合で使えない枠」で「×」を選びます。止めた枠は、×入力・自動案・調整・決定で灰色になり、使われません。
B31: 2. 「名簿」シート
B32: ・Excelの名簿から「出席番号」と「名前」をコピーして、「番号」の列のいちばん上のマスに貼り付けます（最大45人）。
B33: ・他のクラスに兄弟がいる家庭は、「兄弟」の列で「〇」を選び、「兄弟メモ」に兄弟のクラスなどをメモします。
B34: ・「希望」：早い時刻／遅い時刻／早い日／遅い日 から選べます。自動案で、×のない枠の中からできるだけ希望に合う枠を選びます（希望なので、合わないこともあります）。
B35: ・「後ろを空ける」：話が長引きそうな家庭は、同じ日のすぐ次の枠を空けます。「必ず空けたい」「出来れば空けたい」から選びます（出来れば空けたいは、空けられないときは詰めて入れます）。日の最後の枠なら空ける必要はありません。
B36: ・名簿の行は並べ替えないでください（×入力の内容とずれてしまいます）。絞り込み（フィルター）は使えます。
B37: 3. 「×入力」シート
... B58: ※ 「計算A」「計算B」は計算用の隠しシートです。さわらないでください。

Sheet 設定
A1: 設定 | D1: =HYPERLINK("#'ホーム'!A1","ホーム") | E1: =HYPERLINK("#'設定'!A1","① 設定") | F1: =HYPERLINK("#'名簿'!A1","② 名簿") | H1: =HYPERLINK("#'×入力'!A1","③ ×入力") | I1: =HYPERLINK("#'自動案'!A1","④ 自動案") | K1: =HYPERLINK("#'調整・決定'!A1","⑤ 調整・決定")
A2: 面談の日付と時間枠を決めます。黄色のマスを入力してください。
A3: 時間帯1 | B3: 0.5625 | C3: 〜 | D3: 0.64583333 | E3: =IF(OR(NOT(ISNUMBER(B3)),NOT(ISNUMBER(D3))),"← 始まりと終わりの時刻を入れてください",IF(D3<B3,"← 終わりは始まりより後の時刻にしてください",""))
A4: 時間帯2（なければ空欄） | C4: 〜 | E4: =IF(AND(B4="",D4=""),"",IF(OR(NOT(ISNUMBER(B4)),NOT(ISNUMBER(D4))),"← 始まりと終わりの両方を入れてください",IF(D4<B4,"← 終わりは始まりより後の時刻にしてください",IF(AND(ISNUMBER(D3),B4<=D3),"← 時間帯1より後の時刻にしてください",""))))
A5: 1枠の長さ（分） | B5: 15 | E5: =IF(AND(ISNUMBER(B5),B5>0),"","← 5〜120の数字を入れてください")
A6: 1日の枠の数 | B6: =MIN(24,'計算A'!$A$3+'計算A'!$A$4) | D6: （最大24枠） | E6: =IF('計算A'!$A$3+'計算A'!$A$4>24,"← 枠が24をこえています。こえた分は使いません","")
K7: 先生の都合で使えない枠（出張・会議など）
A8: 自動案の詰め方 | B8: 早い時間から（各日の最後を空ける） | K8: 「×」を選んだ日・時間・枠は、自動案にも調整・決定にも使いません。
K9: この日は組まない ▶
B10: 日付 | C10: 曜日 | D10: なるべく空ける | E10: 表示 | G10: 時刻 | H10: 休憩（なるべく空ける） | I10: 表示 | K10: この時間は 組まない ▼ | M10: ='設定'!$E$11 | N10: ='設定'!$E$12 | O10: ='設定'!$E$13 | P10: ='設定'!$E$14 | Q10: ='設定'!$E$15 | R10: ='設定'!$E$16 | S10: ='設定'!$E$17 | T10: ='設定'!$E$18 | U10: ='設定'!$E$19 | V10: ='設定'!$E$20
A11: 1日目 | B11: 46350 | C11: =IF(B11="","",CHOOSE(WEEKDAY(B11),"日","月","火","水","木","金","土")) | E11: =IF(B11="","",MONTH(B11)&"月"&DAY(B11)&"日（"&C11&"）") | F11: 1 | G11: =IF(F11<=MIN('計算A'!$A$3,24),$B$3+(F11-1)*$B$5/1440,IF(F11<=$B$6,$B$4+(F11-'計算A'!$A$3-1)*$B$5/1440,"")) | I11: =IF(G11="","",TEXT(G11,"h:mm")&"〜") | L11: =$I$11
A12: 2日目 | B12: 46351 | C12: =IF(B12="","",CHOOSE(WEEKDAY(B12),"日","月","火","水","木","金","土")) | E12: =IF(B12="","",MONTH(B12)&"月"&DAY(B12)&"日（"&C12&"）") | F12: 2 | G12: =IF(F12<=MIN('計算A'!$A$3,24),$B$3+(F12-1)*$B$5/1440,IF(F12<=$B$6,$B$4+(F12-'計算A'!$A$3-1)*$B$5/1440,"")) | I12: =IF(G12="","",TEXT(G12,"h:mm")&"〜") | L12: =$I$12
A13: 3日目 | B13: 46352 | C13: =IF(B13="","",CHOOSE(WEEKDAY(B13),"日","月","火","水","木","金","土")) | E13: =IF(B13="","",MONTH(B13)&"月"&DAY(B13)&"日（"&C13&"）") | F13: 3 | G13: =IF(F13<=MIN('計算A'!$A$3,24),$B$3+(F13-1)*$B$5/1440,IF(F13<=$B$6,$B$4+(F13-'計算A'!$A$3-1)*$B$5/1440,"")) | I13: =IF(G13="","",TEXT(G13,"h:mm")&"〜") | L13: =$I$13
A14: 4日目 | B14: 46353 | C14: =IF(B14="","",CHOOSE(WEEKDAY(B14),"日","月","火","水","木","金","土")) | E14: =IF(B14="","",MONTH(B14)&"月"&DAY(B14)&"日（"&C14&"）") | F14: 4 | G14: =IF(F14<=MIN('計算A'!$A$3,24),$B$3+(F14-1)*$B$5/1440,IF(F14<=$B$6,$B$4+(F14-'計算A'!$A$3-1)*$B$5/1440,"")) | I14: =IF(G14="","",TEXT(G14,"h:mm")&"〜") | L14: =$I$14
A15: 5日目 | B15: 46356 | C15: =IF(B15="","",CHOOSE(WEEKDAY(B15),"日","月","火","水","木","金","土")) | E15: =IF(B15="","",MONTH(B15)&"月"&DAY(B15)&"日（"&C15&"）") | F15: 5 | G15: =IF(F15<=MIN('計算A'!$A$3,24),$B$3+(F15-1)*$B$5/1440,IF(F15<=$B$6,$B$4+(F15-'計算A'!$A$3-1)*$B$5/1440,"")) | I15: =IF(G15="","",TEXT(G15,"h:mm")&"〜") | L15: =$I$15
A16: 6日目 | C16: =IF(B16="","",CHOOSE(WEEKDAY(B16),"日","月","火","水","木","金","土")) | E16: =IF(B16="","",MONTH(B16)&"月"&DAY(B16)&"日（"&C16&"）") | F16: 6 | G16: =IF(F16<=MIN('計算A'!$A$3,24),$B$3+(F16-1)*$B$5/1440,IF(F16<=$B$6,$B$4+(F16-'計算A'!$A$3-1)*$B$5/1440,"")) | I16: =IF(G16="","",TEXT(G16,"h:mm")&"〜") | L16: =$I$16
A17: 7日目 | C17: =IF(B17="","",CHOOSE(WEEKDAY(B17),"日","月","火","水","木","金","土")) | E17: =IF(B17="","",MONTH(B17)&"月"&DAY(B17)&"日（"&C17&"）") | F17: 7 | G17: =IF(F17<=MIN('計算A'!$A$3,24),$B$3+(F17-1)*$B$5/1440,IF(F17<=$B$6,$B$4+(F17-'計算A'!$A$3-1)*$B$5/1440,"")) | I17: =IF(G17="","",TEXT(G17,"h:mm")&"〜") | L17: =$I$17
A18: 8日目 | C18: =IF(B18="","",CHOOSE(WEEKDAY(B18),"日","月","火","水","木","金","土")) | E18: =IF(B18="","",MONTH(B18)&"月"&DAY(B18)&"日（"&C18&"）") | F18: 8 | G18: =IF(F18<=MIN('計算A'!$A$3,24),$B$3+(F18-1)*$B$5/1440,IF(F18<=$B$6,$B$4+(F18-'計算A'!$A$3-1)*$B$5/1440,"")) | I18: =IF(G18="","",TEXT(G18,"h:mm")&"〜") | L18: =$I$18
A19: 9日目 | C19: =IF(B19="","",CHOOSE(WEEKDAY(B19),"日","月","火","水","木","金","土")) | E19: =IF(B19="","",MONTH(B19)&"月"&DAY(B19)&"日（"&C19&"）") | F19: 9 | G19: =IF(F19<=MIN('計算A'!$A$3,24),$B$3+(F19-1)*$B$5/1440,IF(F19<=$B$6,$B$4+(F19-'計算A'!$A$3-1)*$B$5/1440,"")) | I19: =IF(G19="","",TEXT(G19,"h:mm")&"〜") | L19: =$I$19
A20: 10日目 | C20: =IF(B20="","",CHOOSE(WEEKDAY(B20),"日","月","火","水","木","金","土")) | E20: =IF(B20="","",MONTH(B20)&"月"&DAY(B20)&"日（"&C20&"）") | F20: 10 | G20: =IF(F20<=MIN('計算A'!$A$3,24),$B$3+(F20-1)*$B$5/1440,IF(F20<=$B$6,$B$4+(F20-'計算A'!$A$3-1)*$B$5/1440,"")) | I20: =IF(G20="","",TEXT(G20,"h:mm")&"〜") | L20: =$I$20
F21: 11 | G21: =IF(F21<=MIN('計算A'!$A$3,24),$B$3+(F21-1)*$B$5/1440,IF(F21<=$B$6,$B$4+(F21-'計算A'!$A$3-1)*$B$5/1440,"")) | I21: =IF(G21="","",TEXT(G21,"h:mm")&"〜") | L21: =$I$21
A22: ※ 日付は上から詰めて入れてください。曜日・表示・時刻は自動で出ます。午前と午後に分けるときは、時間帯2も入れます（昼休みは表に出ません）。 | F22: 12 | G22: =IF(F22<=MIN('計算A'!$A$3,24),$B$3+(F22-1)*$B$5/1440,IF(F22<=$B$6,$B$4+(F22-'計算A'!$A$3-1)*$B$5/1440,"")) | I22: =IF(G22="","",TEXT(G22,"h:mm")&"〜") | L22: =$I$22
F23: 13 | G23: =IF(F23<=MIN('計算A'!$A$3,24),$B$3+(F23-1)*$B$5/1440,IF(F23<=$B$6,$B$4+(F23-'計算A'!$A$3-1)*$B$5/1440,"")) | I23: =IF(G23="","",TEXT(G23,"h:mm")&"〜") | L23: =$I$23
F24: 14 | G24: =IF(F24<=MIN('計算A'!$A$3,24),$B$3+(F24-1)*$B$5/1440,IF(F24<=$B$6,$B$4+(F24-'計算A'!$A$3-1)*$B$5/1440,"")) | I24: =IF(G24="","",TEXT(G24,"h:mm")&"〜") | L24: =$I$24
A25: ※「なるべく空ける」「休憩」は、ほかに入る枠がないときだけ使います。必ず使わない枠は、右の「先生の都合で使えない枠」で止めてください。 | F25: 15 | G25: =IF(F25<=MIN('計算A'!$A$3,24),$B$3+(F25-1)*$B$5/1440,IF(F25<=$B$6,$B$4+(F25-'計算A'!$A$3-1)*$B$5/1440,"")) | I25: =IF(G25="","",TEXT(G25,"h:mm")&"〜") | L25: =$I$25
F26: 16 | G26: =IF(F26<=MIN('計算A'!$A$3,24),$B$3+(F26-1)*$B$5/1440,IF(F26<=$B$6,$B$4+(F26-'計算A'!$A$3-1)*$B$5/1440,"")) | I26: =IF(G26="","",TEXT(G26,"h:mm")&"〜") | L26: =$I$26
F27: 17 | G27: =IF(F27<=MIN('計算A'!$A$3,24),$B$3+(F27-1)*$B$5/1440,IF(F27<=$B$6,$B$4+(F27-'計算A'!$A$3-1)*$B$5/1440,"")) | I27: =IF(G27="","",TEXT(G27,"h:mm")&"〜") | L27: =$I$27
F28: 18 | G28: =IF(F28<=MIN('計算A'!$A$3,24),$B$3+(F28-1)*$B$5/1440,IF(F28<=$B$6,$B$4+(F28-'計算A'!$A$3-1)*$B$5/1440,"")) | I28: =IF(G28="","",TEXT(G28,"h:mm")&"〜") | L28: =$I$28
F29: 19 | G29: =IF(F29<=MIN('計算A'!$A$3,24),$B$3+(F29-1)*$B$5/1440,IF(F29<=$B$6,$B$4+(F29-'計算A'!$A$3-1)*$B$5/1440,"")) | I29: =IF(G29="","",TEXT(G29,"h:mm")&"〜") | L29: =$I$29
F30: 20 | G30: =IF(F30<=MIN('計算A'!$A$3,24),$B$3+(F30-1)*$B$5/1440,IF(F30<=$B$6,$B$4+(F30-'計算A'!$A$3-1)*$B$5/1440,"")) | I30: =IF(G30="","",TEXT(G30,"h:mm")&"〜") | L30: =$I$30
F31: 21 | G31: =IF(F31<=MIN('計算A'!$A$3,24),$B$3+(F31-1)*$B$5/1440,IF(F31<=$B$6,$B$4+(F31-'計算A'!$A$3-1)*$B$5/1440,"")) | I31: =IF(G31="","",TEXT(G31,"h:mm")&"〜") | L31: =$I$31
F32: 22 | G32: =IF(F32<=MIN('計算A'!$A$3,24),$B$3+(F32-1)*$B$5/1440,IF(F32<=$B$6,$B$4+(F32-'計算A'!$A$3-1)*$B$5/1440,"")) | I32: =IF(G32="","",TEXT(G32,"h:mm")&"〜") | L32: =$I$32
F33: 23 | G33: =IF(F33<=MIN('計算A'!$A$3,24),$B$3+(F33-1)*$B$5/1440,IF(F33<=$B$6,$B$4+(F33-'計算A'!$A$3-1)*$B$5/1440,"")) | I33: =IF(G33="","",TEXT(G33,"h:mm")&"〜") | L33: =$I$33
F34: 24 | G34: =IF(F34<=MIN('計算A'!$A$3,24),$B$3+(F34-1)*$B$5/1440,IF(F34<=$B$6,$B$4+(F34-'計算A'!$A$3-1)*$B$5/1440,"")) | I34: =IF(G34="","",TEXT(G34,"h:mm")&"〜") | L34: =$I$34

Sheet 名簿
A1: 名簿・結果 | E1: =HYPERLINK("#'ホーム'!A1","ホーム") | G1: =HYPERLINK("#'設定'!A1","① 設定") | H1: =HYPERLINK("#'名簿'!A1","② 名簿") | J1: =HYPERLINK("#'×入力'!A1","③ ×入力") | L1: =HYPERLINK("#'自動案'!A1","④ 自動案") | N1: =HYPERLINK("#'調整・決定'!A1","⑤ 調整・決定")
A2: 黄色の列（番号〜後ろを空ける）を入力します。Excelの名簿から番号と名前を「番号」の列のいちばん上に貼り付けてください（最大45人）。行の並べ替えはしないでください。
A3: 希望：早い時刻／遅い時刻／早い日／遅い日。後ろを空ける：必ず空けたい／出来れば空けたい（同じ日のすぐ次の枠を空けます）。
A4: 番号 | B4: 名前 | C4: 兄弟 | D4: 兄弟メモ | E4: 希望 | F4: 後ろを空ける | G4: 表示名 | H4: 状況 | I4: ×の数 | J4: 入れられる空き枠 | K4: 決める順 | L4: 日付 | M4: 時刻 | N4: 注意 | O4: 自動案
G5: =IF(B5="","",IF(A5="","",A5&" ")&B5) | H5: =IF(B5="","",IF('×入力'!F5="未提出","未提出",IF(I5>0,"入力済み",IF('×入力'!F5="×なし（どこでもOK）","×なし","未入力")))) | I5: =IF(B5="","",'計算A'!IN10) | J5: =IF(OR(H5="入力済み",H5="×なし"),'計算A'!IM10,"") | K5: =IF('計算A'!C10=1,COUNTIFS('計算A'!$C$10:$C$54,1,'計算A'!$IM$10:$IM$54,"<"&'計算A'!IM10)+1,"") | L5: =IF('計算A'!IO10=0,"",INDEX('設定'!$E$11:$E$20,INDEX('計算A'!$D$2:$II$2,'計算A'!IO10))) | M5: =IF('計算A'!IO10=0,"",INDEX('設定'!$I$11:$I$34,INDEX('計算A'!$D$3:$II$3,'計算A'!IO10))) | N5: =IF(G5="","",IF(COUNTIF('調整・決定'!$C$6:$L$29,G5)>1,"2か所以上に入っています",IF('計算A'!IO10>0,IF(INDEX('計算A'!$D$4:$II$4,'計算A'!IO10)=0,"使えない枠に入っています",IF(INDEX('計算A'!$D$10:$II$10,'計算A'!IO10)=1,"×の枠に入っています",IF(AND(F5<>"",INDEX('計算A'!$D$106:$II$106,'計算A'!IO10)=1,INDEX('計算A'!$D$109:$II$109,'計算A'!IO10+1)=1),IF(F5="必ず空けたい","後ろの枠が空いていません","（出来れば）後ろが空いていません"),""))),IF(OR(H5="入力済み",H5="×なし"),"未決定","")))) | O5: =IF('計算A'!IK10=0,IF('計算A'!IL10=1,"入る枠がありません",""),INDEX('計算A'!$D$8:$II$8,'計算A'!IK10)) | P5: =HYPERLINK("#'×入力'!B5","×入力へ")
G6: =IF(B6="","",IF(A6="","",A6&" ")&B6) | H6: =IF(B6="","",IF('×入力'!F33="未提出","未提出",IF(I6>0,"入力済み",IF('×入力'!F33="×なし（どこでもOK）","×なし","未入力")))) | I6: =IF(B6="","",'計算A'!IN11) | J6: =IF(OR(H6="入力済み",H6="×なし"),'計算A'!IM11,"") | K6: =IF('計算A'!C11=1,COUNTIFS('計算A'!$C$10:$C$54,1,'計算A'!$IM$10:$IM$54,"<"&'計算A'!IM11)+1,"") | L6: =IF('計算A'!IO11=0,"",INDEX('設定'!$E$11:$E$20,INDEX('計算A'!$D$2:$II$2,'計算A'!IO11))) | M6: =IF('計算A'!IO11=0,"",INDEX('設定'!$I$11:$I$34,INDEX('計算A'!$D$3:$II$3,'計算A'!IO11))) | N6: =IF(G6="","",IF(COUNTIF('調整・決定'!$C$6:$L$29,G6)>1,"2か所以上に入っています",IF('計算A'!IO11>0,IF(INDEX('計算A'!$D$4:$II$4,'計算A'!IO11)=0,"使えない枠に入っています",IF(INDEX('計算A'!$D$11:$II$11,'計算A'!IO11)=1,"×の枠に入っています",IF(AND(F6<>"",INDEX('計算A'!$D$106:$II$106,'計算A'!IO11)=1,INDEX('計算A'!$D$109:$II$109,'計算A'!IO11+1)=1),IF(F6="必ず空けたい","後ろの枠が空いていません","（出来れば）後ろが空いていません"),""))),IF(OR(H6="入力済み",H6="×なし"),"未決定","")))) | O6: =IF('計算A'!IK11=0,IF('計算A'!IL11=1,"入る枠がありません",""),INDEX('計算A'!$D$8:$II$8,'計算A'!IK11)) | P6: =HYPERLINK("#'×入力'!B33","×入力へ")
G7: =IF(B7="","",IF(A7="","",A7&" ")&B7) | H7: =IF(B7="","",IF('×入力'!F61="未提出","未提出",IF(I7>0,"入力済み",IF('×入力'!F61="×なし（どこでもOK）","×なし","未入力")))) | I7: =IF(B7="","",'計算A'!IN12) | J7: =IF(OR(H7="入力済み",H7="×なし"),'計算A'!IM12,"") | K7: =IF('計算A'!C12=1,COUNTIFS('計算A'!$C$10:$C$54,1,'計算A'!$IM$10:$IM$54,"<"&'計算A'!IM12)+1,"") | L7: =IF('計算A'!IO12=0,"",INDEX('設定'!$E$11:$E$20,INDEX('計算A'!$D$2:$II$2,'計算A'!IO12))) | M7: =IF('計算A'!IO12=0,"",INDEX('設定'!$I$11:$I$34,INDEX('計算A'!$D$3:$II$3,'計算A'!IO12))) | N7: =IF(G7="","",IF(COUNTIF('調整・決定'!$C$6:$L$29,G7)>1,"2か所以上に入っています",IF('計算A'!IO12>0,IF(INDEX('計算A'!$D$4:$II$4,'計算A'!IO12)=0,"使えない枠に入っています",IF(INDEX('計算A'!$D$12:$II$12,'計算A'!IO12)=1,"×の枠に入っています",IF(AND(F7<>"",INDEX('計算A'!$D$106:$II$106,'計算A'!IO12)=1,INDEX('計算A'!$D$109:$II$109,'計算A'!IO12+1)=1),IF(F7="必ず空けたい","後ろの枠が空いていません","（出来れば）後ろが空いていません"),""))),IF(OR(H7="入力済み",H7="×なし"),"未決定","")))) | O7: =IF('計算A'!IK12=0,IF('計算A'!IL12=1,"入る枠がありません",""),INDEX('計算A'!$D$8:$II$8,'計算A'!IK12)) | P7: =HYPERLINK("#'×入力'!B61","×入力へ")
G8: =IF(B8="","",IF(A8="","",A8&" ")&B8) | H8: =IF(B8="","",IF('×入力'!F89="未提出","未提出",IF(I8>0,"入力済み",IF('×入力'!F89="×なし（どこでもOK）","×なし","未入力")))) | I8: =IF(B8="","",'計算A'!IN13) | J8: =IF(OR(H8="入力済み",H8="×なし"),'計算A'!IM13,"") | K8: =IF('計算A'!C13=1,COUNTIFS('計算A'!$C$10:$C$54,1,'計算A'!$IM$10:$IM$54,"<"&'計算A'!IM13)+1,"") | L8: =IF('計算A'!IO13=0,"",INDEX('設定'!$E$11:$E$20,INDEX('計算A'!$D$2:$II$2,'計算A'!IO13))) | M8: =IF('計算A'!IO13=0,"",INDEX('設定'!$I$11:$I$34,INDEX('計算A'!$D$3:$II$3,'計算A'!IO13))) | N8: =IF(G8="","",IF(COUNTIF('調整・決定'!$C$6:$L$29,G8)>1,"2か所以上に入っています",IF('計算A'!IO13>0,IF(INDEX('計算A'!$D$4:$II$4,'計算A'!IO13)=0,"使えない枠に入っています",IF(INDEX('計算A'!$D$13:$II$13,'計算A'!IO13)=1,"×の枠に入っています",IF(AND(F8<>"",INDEX('計算A'!$D$106:$II$106,'計算A'!IO13)=1,INDEX('計算A'!$D$109:$II$109,'計算A'!IO13+1)=1),IF(F8="必ず空けたい","後ろの枠が空いていません","（出来れば）後ろが空いていません"),""))),IF(OR(H8="入力済み",H8="×なし"),"未決定","")))) | O8: =IF('計算A'!IK13=0,IF('計算A'!IL13=1,"入る枠がありません",""),INDEX('計算A'!$D$8:$II$8,'計算A'!IK13)) | P8: =HYPERLINK("#'×入力'!B89","×入力へ")
G9: =IF(B9="","",IF(A9="","",A9&" ")&B9) | H9: =IF(B9="","",IF('×入力'!F117="未提出","未提出",IF(I9>0,"入力済み",IF('×入力'!F117="×なし（どこでもOK）","×なし","未入力")))) | I9: =IF(B9="","",'計算A'!IN14) | J9: =IF(OR(H9="入力済み",H9="×なし"),'計算A'!IM14,"") | K9: =IF('計算A'!C14=1,COUNTIFS('計算A'!$C$10:$C$54,1,'計算A'!$IM$10:$IM$54,"<"&'計算A'!IM14)+1,"") | L9: =IF('計算A'!IO14=0,"",INDEX('設定'!$E$11:$E$20,INDEX('計算A'!$D$2:$II$2,'計算A'!IO14))) | M9: =IF('計算A'!IO14=0,"",INDEX('設定'!$I$11:$I$34,INDEX('計算A'!$D$3:$II$3,'計算A'!IO14))) | N9: =IF(G9="","",IF(COUNTIF('調整・決定'!$C$6:$L$29,G9)>1,"2か所以上に入っています",IF('計算A'!IO14>0,IF(INDEX('計算A'!$D$4:$II$4,'計算A'!IO14)=0,"使えない枠に入っています",IF(INDEX('計算A'!$D$14:$II$14,'計算A'!IO14)=1,"×の枠に入っています",IF(AND(F9<>"",INDEX('計算A'!$D$106:$II$106,'計算A'!IO14)=1,INDEX('計算A'!$D$109:$II$109,'計算A'!IO14+1)=1),IF(F9="必ず空けたい","後ろの枠が空いていません","（出来れば）後ろが空いていません"),""))),IF(OR(H9="入力済み",H9="×なし"),"未決定","")))) | O9: =IF('計算A'!IK14=0,IF('計算A'!IL14=1,"入る枠がありません",""),INDEX('計算A'!$D$8:$II$8,'計算A'!IK14)) | P9: =HYPERLINK("#'×入力'!B117","×入力へ")
G10: =IF(B10="","",IF(A10="","",A10&" ")&B10) | H10: =IF(B10="","",IF('×入力'!F145="未提出","未提出",IF(I10>0,"入力済み",IF('×入力'!F145="×なし（どこでもOK）","×なし","未入力")))) | I10: =IF(B10="","",'計算A'!IN15) | J10: =IF(OR(H10="入力済み",H10="×なし"),'計算A'!IM15,"") | K10: =IF('計算A'!C15=1,COUNTIFS('計算A'!$C$10:$C$54,1,'計算A'!$IM$10:$IM$54,"<"&'計算A'!IM15)+1,"") | L10: =IF('計算A'!IO15=0,"",INDEX('設定'!$E$11:$E$20,INDEX('計算A'!$D$2:$II$2,'計算A'!IO15))) | M10: =IF('計算A'!IO15=0,"",INDEX('設定'!$I$11:$I$34,INDEX('計算A'!$D$3:$II$3,'計算A'!IO15))) | N10: =IF(G10="","",IF(COUNTIF('調整・決定'!$C$6:$L$29,G10)>1,"2か所以上に入っています",IF('計算A'!IO15>0,IF(INDEX('計算A'!$D$4:$II$4,'計算A'!IO15)=0,"使えない枠に入っています",IF(INDEX('計算A'!$D$15:$II$15,'計算A'!IO15)=1,"×の枠に入っています",IF(AND(F10<>"",INDEX('計算A'!$D$106:$II$106,'計算A'!IO15)=1,INDEX('計算A'!$D$109:$II$109,'計算A'!IO15+1)=1),IF(F10="必ず空けたい","後ろの枠が空いていません","（出来れば）後ろが空いていません"),""))),IF(OR(H10="入力済み",H10="×なし"),"未決定","")))) | O10: =IF('計算A'!IK15=0,IF('計算A'!IL15=1,"入る枠がありません",""),INDEX('計算A'!$D$8:$II$8,'計算A'!IK15)) | P10: =HYPERLINK("#'×入力'!B145","×入力へ")
G11: =IF(B11="","",IF(A11="","",A11&" ")&B11) | H11: =IF(B11="","",IF('×入力'!F173="未提出","未提出",IF(I11>0,"入力済み",IF('×入力'!F173="×なし（どこでもOK）","×なし","未入力")))) | I11: =IF(B11="","",'計算A'!IN16) | J11: =IF(OR(H11="入力済み",H11="×なし"),'計算A'!IM16,"") | K11: =IF('計算A'!C16=1,COUNTIFS('計算A'!$C$10:$C$54,1,'計算A'!$IM$10:$IM$54,"<"&'計算A'!IM16)+1,"") | L11: =IF('計算A'!IO16=0,"",INDEX('設定'!$E$11:$E$20,INDEX('計算A'!$D$2:$II$2,'計算A'!IO16))) | M11: =IF('計算A'!IO16=0,"",INDEX('設定'!$I$11:$I$34,INDEX('計算A'!$D$3:$II$3,'計算A'!IO16))) | N11: =IF(G11="","",IF(COUNTIF('調整・決定'!$C$6:$L$29,G11)>1,"2か所以上に入っています",IF('計算A'!IO16>0,IF(INDEX('計算A'!$D$4:$II$4,'計算A'!IO16)=0,"使えない枠に入っています",IF(INDEX('計算A'!$D$16:$II$16,'計算A'!IO16)=1,"×の枠に入っています",IF(AND(F11<>"",INDEX('計算A'!$D$106:$II$106,'計算A'!IO16)=1,INDEX('計算A'!$D$109:$II$109,'計算A'!IO16+1)=1),IF(F11="必ず空けたい","後ろの枠が空いていません","（出来れば）後ろが空いていません"),""))),IF(OR(H11="入力済み",H11="×なし"),"未決定","")))) | O11: =IF('計算A'!IK16=0,IF('計算A'!IL16=1,"入る枠がありません",""),INDEX('計算A'!$D$8:$II$8,'計算A'!IK16)) | P11: =HYPERLINK("#'×入力'!B173","×入力へ")
G12: =IF(B12="","",IF(A12="","",A12&" ")&B12) | H12: =IF(B12="","",IF('×入力'!F201="未提出","未提出",IF(I12>0,"入力済み",IF('×入力'!F201="×なし（どこでもOK）","×なし","未入力")))) | I12: =IF(B12="","",'計算A'!IN17) | J12: =IF(OR(H12="入力済み",H12="×なし"),'計算A'!IM17,"") | K12: =IF('計算A'!C17=1,COUNTIFS('計算A'!$C$10:$C$54,1,'計算A'!$IM$10:$IM$54,"<"&'計算A'!IM17)+1,"") | L12: =IF('計算A'!IO17=0,"",INDEX('設定'!$E$11:$E$20,INDEX('計算A'!$D$2:$II$2,'計算A'!IO17))) | M12: =IF('計算A'!IO17=0,"",INDEX('設定'!$I$11:$I$34,INDEX('計算A'!$D$3:$II$3,'計算A'!IO17))) | N12: =IF(G12="","",IF(COUNTIF('調整・決定'!$C$6:$L$29,G12)>1,"2か所以上に入っています",IF('計算A'!IO17>0,IF(INDEX('計算A'!$D$4:$II$4,'計算A'!IO17)=0,"使えない枠に入っています",IF(INDEX('計算A'!$D$17:$II$17,'計算A'!IO17)=1,"×の枠に入っています",IF(AND(F12<>"",INDEX('計算A'!$D$106:$II$106,'計算A'!IO17)=1,INDEX('計算A'!$D$109:$II$109,'計算A'!IO17+1)=1),IF(F12="必ず空けたい","後ろの枠が空いていません","（出来れば）後ろが空いていません"),""))),IF(OR(H12="入力済み",H12="×なし"),"未決定","")))) | O12: =IF('計算A'!IK17=0,IF('計算A'!IL17=1,"入る枠がありません",""),INDEX('計算A'!$D$8:$II$8,'計算A'!IK17)) | P12: =HYPERLINK("#'×入力'!B201","×入力へ")
G13: =IF(B13="","",IF(A13="","",A13&" ")&B13) | H13: =IF(B13="","",IF('×入力'!F229="未提出","未提出",IF(I13>0,"入力済み",IF('×入力'!F229="×なし（どこでもOK）","×なし","未入力")))) | I13: =IF(B13="","",'計算A'!IN18) | J13: =IF(OR(H13="入力済み",H13="×なし"),'計算A'!IM18,"") | K13: =IF('計算A'!C18=1,COUNTIFS('計算A'!$C$10:$C$54,1,'計算A'!$IM$10:$IM$54,"<"&'計算A'!IM18)+1,"") | L13: =IF('計算A'!IO18=0,"",INDEX('設定'!$E$11:$E$20,INDEX('計算A'!$D$2:$II$2,'計算A'!IO18))) | M13: =IF('計算A'!IO18=0,"",INDEX('設定'!$I$11:$I$34,INDEX('計算A'!$D$3:$II$3,'計算A'!IO18))) | N13: =IF(G13="","",IF(COUNTIF('調整・決定'!$C$6:$L$29,G13)>1,"2か所以上に入っています",IF('計算A'!IO18>0,IF(INDEX('計算A'!$D$4:$II$4,'計算A'!IO18)=0,"使えない枠に入っています",IF(INDEX('計算A'!$D$18:$II$18,'計算A'!IO18)=1,"×の枠に入っています",IF(AND(F13<>"",INDEX('計算A'!$D$106:$II$106,'計算A'!IO18)=1,INDEX('計算A'!$D$109:$II$109,'計算A'!IO18+1)=1),IF(F13="必ず空けたい","後ろの枠が空いていません","（出来れば）後ろが空いていません"),""))),IF(OR(H13="入力済み",H13="×なし"),"未決定","")))) | O13: =IF('計算A'!IK18=0,IF('計算A'!IL18=1,"入る枠がありません",""),INDEX('計算A'!$D$8:$II$8,'計算A'!IK18)) | P13: =HYPERLINK("#'×入力'!B229","×入力へ")
G14: =IF(B14="","",IF(A14="","",A14&" ")&B14) | H14: =IF(B14="","",IF('×入力'!F257="未提出","未提出",IF(I14>0,"入力済み",IF('×入力'!F257="×なし（どこでもOK）","×なし","未入力")))) | I14: =IF(B14="","",'計算A'!IN19) | J14: =IF(OR(H14="入力済み",H14="×なし"),'計算A'!IM19,"") | K14: =IF('計算A'!C19=1,COUNTIFS('計算A'!$C$10:$C$54,1,'計算A'!$IM$10:$IM$54,"<"&'計算A'!IM19)+1,"") | L14: =IF('計算A'!IO19=0,"",INDEX('設定'!$E$11:$E$20,INDEX('計算A'!$D$2:$II$2,'計算A'!IO19))) | M14: =IF('計算A'!IO19=0,"",INDEX('設定'!$I$11:$I$34,INDEX('計算A'!$D$3:$II$3,'計算A'!IO19))) | N14: =IF(G14="","",IF(COUNTIF('調整・決定'!$C$6:$L$29,G14)>1,"2か所以上に入っています",IF('計算A'!IO19>0,IF(INDEX('計算A'!$D$4:$II$4,'計算A'!IO19)=0,"使えない枠に入っています",IF(INDEX('計算A'!$D$19:$II$19,'計算A'!IO19)=1,"×の枠に入っています",IF(AND(F14<>"",INDEX('計算A'!$D$106:$II$106,'計算A'!IO19)=1,INDEX('計算A'!$D$109:$II$109,'計算A'!IO19+1)=1),IF(F14="必ず空けたい","後ろの枠が空いていません","（出来れば）後ろが空いていません"),""))),IF(OR(H14="入力済み",H14="×なし"),"未決定","")))) | O14: =IF('計算A'!IK19=0,IF('計算A'!IL19=1,"入る枠がありません",""),INDEX('計算A'!$D$8:$II$8,'計算A'!IK19)) | P14: =HYPERLINK("#'×入力'!B257","×入力へ")
G15: =IF(B15="","",IF(A15="","",A15&" ")&B15) | H15: =IF(B15="","",IF('×入力'!F285="未提出","未提出",IF(I15>0,"入力済み",IF('×入力'!F285="×なし（どこでもOK）","×なし","未入力")))) | I15: =IF(B15="","",'計算A'!IN20) | J15: =IF(OR(H15="入力済み",H15="×なし"),'計算A'!IM20,"") | K15: =IF('計算A'!C20=1,COUNTIFS('計算A'!$C$10:$C$54,1,'計算A'!$IM$10:$IM$54,"<"&'計算A'!IM20)+1,"") | L15: =IF('計算A'!IO20=0,"",INDEX('設定'!$E$11:$E$20,INDEX('計算A'!$D$2:$II$2,'計算A'!IO20))) | M15: =IF('計算A'!IO20=0,"",INDEX('設定'!$I$11:$I$34,INDEX('計算A'!$D$3:$II$3,'計算A'!IO20))) | N15: =IF(G15="","",IF(COUNTIF('調整・決定'!$C$6:$L$29,G15)>1,"2か所以上に入っています",IF('計算A'!IO20>0,IF(INDEX('計算A'!$D$4:$II$4,'計算A'!IO20)=0,"使えない枠に入っています",IF(INDEX('計算A'!$D$20:$II$20,'計算A'!IO20)=1,"×の枠に入っています",IF(AND(F15<>"",INDEX('計算A'!$D$106:$II$106,'計算A'!IO20)=1,INDEX('計算A'!$D$109:$II$109,'計算A'!IO20+1)=1),IF(F15="必ず空けたい","後ろの枠が空いていません","（出来れば）後ろが空いていません"),""))),IF(OR(H15="入力済み",H15="×なし"),"未決定","")))) | O15: =IF('計算A'!IK20=0,IF('計算A'!IL20=1,"入る枠がありません",""),INDEX('計算A'!$D$8:$II$8,'計算A'!IK20)) | P15: =HYPERLINK("#'×入力'!B285","×入力へ")
G16: =IF(B16="","",IF(A16="","",A16&" ")&B16) | H16: =IF(B16="","",IF('×入力'!F313="未提出","未提出",IF(I16>0,"入力済み",IF('×入力'!F313="×なし（どこでもOK）","×なし","未入力")))) | I16: =IF(B16="","",'計算A'!IN21) | J16: =IF(OR(H16="入力済み",H16="×なし"),'計算A'!IM21,"") | K16: =IF('計算A'!C21=1,COUNTIFS('計算A'!$C$10:$C$54,1,'計算A'!$IM$10:$IM$54,"<"&'計算A'!IM21)+1,"") | L16: =IF('計算A'!IO21=0,"",INDEX('設定'!$E$11:$E$20,INDEX('計算A'!$D$2:$II$2,'計算A'!IO21))) | M16: =IF('計算A'!IO21=0,"",INDEX('設定'!$I$11:$I$34,INDEX('計算A'!$D$3:$II$3,'計算A'!IO21))) | N16: =IF(G16="","",IF(COUNTIF('調整・決定'!$C$6:$L$29,G16)>1,"2か所以上に入っています",IF('計算A'!IO21>0,IF(INDEX('計算A'!$D$4:$II$4,'計算A'!IO21)=0,"使えない枠に入っています",IF(INDEX('計算A'!$D$21:$II$21,'計算A'!IO21)=1,"×の枠に入っています",IF(AND(F16<>"",INDEX('計算A'!$D$106:$II$106,'計算A'!IO21)=1,INDEX('計算A'!$D$109:$II$109,'計算A'!IO21+1)=1),IF(F16="必ず空けたい","後ろの枠が空いていません","（出来れば）後ろが空いていません"),""))),IF(OR(H16="入力済み",H16="×なし"),"未決定","")))) | O16: =IF('計算A'!IK21=0,IF('計算A'!IL21=1,"入る枠がありません",""),INDEX('計算A'!$D$8:$II$8,'計算A'!IK21)) | P16: =HYPERLINK("#'×入力'!B313","×入力へ")
G17: =IF(B17="","",IF(A17="","",A17&" ")&B17) | H17: =IF(B17="","",IF('×入力'!F341="未提出","未提出",IF(I17>0,"入力済み",IF('×入力'!F341="×なし（どこでもOK）","×なし","未入力")))) | I17: =IF(B17="","",'計算A'!IN22) | J17: =IF(OR(H17="入力済み",H17="×なし"),'計算A'!IM22,"") | K17: =IF('計算A'!C22=1,COUNTIFS('計算A'!$C$10:$C$54,1,'計算A'!$IM$10:$IM$54,"<"&'計算A'!IM22)+1,"") | L17: =IF('計算A'!IO22=0,"",INDEX('設定'!$E$11:$E$20,INDEX('計算A'!$D$2:$II$2,'計算A'!IO22))) | M17: =IF('計算A'!IO22=0,"",INDEX('設定'!$I$11:$I$34,INDEX('計算A'!$D$3:$II$3,'計算A'!IO22))) | N17: =IF(G17="","",IF(COUNTIF('調整・決定'!$C$6:$L$29,G17)>1,"2か所以上に入っています",IF('計算A'!IO22>0,IF(INDEX('計算A'!$D$4:$II$4,'計算A'!IO22)=0,"使えない枠に入っています",IF(INDEX('計算A'!$D$22:$II$22,'計算A'!IO22)=1,"×の枠に入っています",IF(AND(F17<>"",INDEX('計算A'!$D$106:$II$106,'計算A'!IO22)=1,INDEX('計算A'!$D$109:$II$109,'計算A'!IO22+1)=1),IF(F17="必ず空けたい","後ろの枠が空いていません","（出来れば）後ろが空いていません"),""))),IF(OR(H17="入力済み",H17="×なし"),"未決定","")))) | O17: =IF('計算A'!IK22=0,IF('計算A'!IL22=1,"入る枠がありません",""),INDEX('計算A'!$D$8:$II$8,'計算A'!IK22)) | P17: =HYPERLINK("#'×入力'!B341","×入力へ")
G18: =IF(B18="","",IF(A18="","",A18&" ")&B18) | H18: =IF(B18="","",IF('×入力'!F369="未提出","未提出",IF(I18>0,"入力済み",IF('×入力'!F369="×なし（どこでもOK）","×なし","未入力")))) | I18: =IF(B18="","",'計算A'!IN23) | J18: =IF(OR(H18="入力済み",H18="×なし"),'計算A'!IM23,"") | K18: =IF('計算A'!C23=1,COUNTIFS('計算A'!$C$10:$C$54,1,'計算A'!$IM$10:$IM$54,"<"&'計算A'!IM23)+1,"") | L18: =IF('計算A'!IO23=0,"",INDEX('設定'!$E$11:$E$20,INDEX('計算A'!$D$2:$II$2,'計算A'!IO23))) | M18: =IF('計算A'!IO23=0,"",INDEX('設定'!$I$11:$I$34,INDEX('計算A'!$D$3:$II$3,'計算A'!IO23))) | N18: =IF(G18="","",IF(COUNTIF('調整・決定'!$C$6:$L$29,G18)>1,"2か所以上に入っています",IF('計算A'!IO23>0,IF(INDEX('計算A'!$D$4:$II$4,'計算A'!IO23)=0,"使えない枠に入っています",IF(INDEX('計算A'!$D$23:$II$23,'計算A'!IO23)=1,"×の枠に入っています",IF(AND(F18<>"",INDEX('計算A'!$D$106:$II$106,'計算A'!IO23)=1,INDEX('計算A'!$D$109:$II$109,'計算A'!IO23+1)=1),IF(F18="必ず空けたい","後ろの枠が空いていません","（出来れば）後ろが空いていません"),""))),IF(OR(H18="入力済み",H18="×なし"),"未決定","")))) | O18: =IF('計算A'!IK23=0,IF('計算A'!IL23=1,"入る枠がありません",""),INDEX('計算A'!$D$8:$II$8,'計算A'!IK23)) | P18: =HYPERLINK("#'×入力'!B369","×入力へ")
G19: =IF(B19="","",IF(A19="","",A19&" ")&B19) | H19: =IF(B19="","",IF('×入力'!F397="未提出","未提出",IF(I19>0,"入力済み",IF('×入力'!F397="×なし（どこでもOK）","×なし","未入力")))) | I19: =IF(B19="","",'計算A'!IN24) | J19: =IF(OR(H19="入力済み",H19="×なし"),'計算A'!IM24,"") | K19: =IF('計算A'!C24=1,COUNTIFS('計算A'!$C$10:$C$54,1,'計算A'!$IM$10:$IM$54,"<"&'計算A'!IM24)+1,"") | L19: =IF('計算A'!IO24=0,"",INDEX('設定'!$E$11:$E$20,INDEX('計算A'!$D$2:$II$2,'計算A'!IO24))) | M19: =IF('計算A'!IO24=0,"",INDEX('設定'!$I$11:$I$34,INDEX('計算A'!$D$3:$II$3,'計算A'!IO24))) | N19: =IF(G19="","",IF(COUNTIF('調整・決定'!$C$6:$L$29,G19)>1,"2か所以上に入っています",IF('計算A'!IO24>0,IF(INDEX('計算A'!$D$4:$II$4,'計算A'!IO24)=0,"使えない枠に入っています",IF(INDEX('計算A'!$D$24:$II$24,'計算A'!IO24)=1,"×の枠に入っています",IF(AND(F19<>"",INDEX('計算A'!$D$106:$II$106,'計算A'!IO24)=1,INDEX('計算A'!$D$109:$II$109,'計算A'!IO24+1)=1),IF(F19="必ず空けたい","後ろの枠が空いていません","（出来れば）後ろが空いていません"),""))),IF(OR(H19="入力済み",H19="×なし"),"未決定","")))) | O19: =IF('計算A'!IK24=0,IF('計算A'!IL24=1,"入る枠がありません",""),INDEX('計算A'!$D$8:$II$8,'計算A'!IK24)) | P19: =HYPERLINK("#'×入力'!B397","×入力へ")
G20: =IF(B20="","",IF(A20="","",A20&" ")&B20) | H20: =IF(B20="","",IF('×入力'!F425="未提出","未提出",IF(I20>0,"入力済み",IF('×入力'!F425="×なし（どこでもOK）","×なし","未入力")))) | I20: =IF(B20="","",'計算A'!IN25) | J20: =IF(OR(H20="入力済み",H20="×なし"),'計算A'!IM25,"") | K20: =IF('計算A'!C25=1,COUNTIFS('計算A'!$C$10:$C$54,1,'計算A'!$IM$10:$IM$54,"<"&'計算A'!IM25)+1,"") | L20: =IF('計算A'!IO25=0,"",INDEX('設定'!$E$11:$E$20,INDEX('計算A'!$D$2:$II$2,'計算A'!IO25))) | M20: =IF('計算A'!IO25=0,"",INDEX('設定'!$I$11:$I$34,INDEX('計算A'!$D$3:$II$3,'計算A'!IO25))) | N20: =IF(G20="","",IF(COUNTIF('調整・決定'!$C$6:$L$29,G20)>1,"2か所以上に入っています",IF('計算A'!IO25>0,IF(INDEX('計算A'!$D$4:$II$4,'計算A'!IO25)=0,"使えない枠に入っています",IF(INDEX('計算A'!$D$25:$II$25,'計算A'!IO25)=1,"×の枠に入っています",IF(AND(F20<>"",INDEX('計算A'!$D$106:$II$106,'計算A'!IO25)=1,INDEX('計算A'!$D$109:$II$109,'計算A'!IO25+1)=1),IF(F20="必ず空けたい","後ろの枠が空いていません","（出来れば）後ろが空いていません"),""))),IF(OR(H20="入力済み",H20="×なし"),"未決定","")))) | O20: =IF('計算A'!IK25=0,IF('計算A'!IL25=1,"入る枠がありません",""),INDEX('計算A'!$D$8:$II$8,'計算A'!IK25)) | P20: =HYPERLINK("#'×入力'!B425","×入力へ")
G21: =IF(B21="","",IF(A21="","",A21&" ")&B21) | H21: =IF(B21="","",IF('×入力'!F453="未提出","未提出",IF(I21>0,"入力済み",IF('×入力'!F453="×なし（どこでもOK）","×なし","未入力")))) | I21: =IF(B21="","",'計算A'!IN26) | J21: =IF(OR(H21="入力済み",H21="×なし"),'計算A'!IM26,"") | K21: =IF('計算A'!C26=1,COUNTIFS('計算A'!$C$10:$C$54,1,'計算A'!$IM$10:$IM$54,"<"&'計算A'!IM26)+1,"") | L21: =IF('計算A'!IO26=0,"",INDEX('設定'!$E$11:$E$20,INDEX('計算A'!$D$2:$II$2,'計算A'!IO26))) | M21: =IF('計算A'!IO26=0,"",INDEX('設定'!$I$11:$I$34,INDEX('計算A'!$D$3:$II$3,'計算A'!IO26))) | N21: =IF(G21="","",IF(COUNTIF('調整・決定'!$C$6:$L$29,G21)>1,"2か所以上に入っています",IF('計算A'!IO26>0,IF(INDEX('計算A'!$D$4:$II$4,'計算A'!IO26)=0,"使えない枠に入っています",IF(INDEX('計算A'!$D$26:$II$26,'計算A'!IO26)=1,"×の枠に入っています",IF(AND(F21<>"",INDEX('計算A'!$D$106:$II$106,'計算A'!IO26)=1,INDEX('計算A'!$D$109:$II$109,'計算A'!IO26+1)=1),IF(F21="必ず空けたい","後ろの枠が空いていません","（出来れば）後ろが空いていません"),""))),IF(OR(H21="入力済み",H21="×なし"),"未決定","")))) | O21: =IF('計算A'!IK26=0,IF('計算A'!IL26=1,"入る枠がありません",""),INDEX('計算A'!$D$8:$II$8,'計算A'!IK26)) | P21: =HYPERLINK("#'×入力'!B453","×入力へ")
G22: =IF(B22="","",IF(A22="","",A22&" ")&B22) | H22: =IF(B22="","",IF('×入力'!F481="未提出","未提出",IF(I22>0,"入力済み",IF('×入力'!F481="×なし（どこでもOK）","×なし","未入力")))) | I22: =IF(B22="","",'計算A'!IN27) | J22: =IF(OR(H22="入力済み",H22="×なし"),'計算A'!IM27,"") | K22: =IF('計算A'!C27=1,COUNTIFS('計算A'!$C$10:$C$54,1,'計算A'!$IM$10:$IM$54,"<"&'計算A'!IM27)+1,"") | L22: =IF('計算A'!IO27=0,"",INDEX('設定'!$E$11:$E$20,INDEX('計算A'!$D$2:$II$2,'計算A'!IO27))) | M22: =IF('計算A'!IO27=0,"",INDEX('設定'!$I$11:$I$34,INDEX('計算A'!$D$3:$II$3,'計算A'!IO27))) | N22: =IF(G22="","",IF(COUNTIF('調整・決定'!$C$6:$L$29,G22)>1,"2か所以上に入っています",IF('計算A'!IO27>0,IF(INDEX('計算A'!$D$4:$II$4,'計算A'!IO27)=0,"使えない枠に入っています",IF(INDEX('計算A'!$D$27:$II$27,'計算A'!IO27)=1,"×の枠に入っています",IF(AND(F22<>"",INDEX('計算A'!$D$106:$II$106,'計算A'!IO27)=1,INDEX('計算A'!$D$109:$II$109,'計算A'!IO27+1)=1),IF(F22="必ず空けたい","後ろの枠が空いていません","（出来れば）後ろが空いていません"),""))),IF(OR(H22="入力済み",H22="×なし"),"未決定","")))) | O22: =IF('計算A'!IK27=0,IF('計算A'!IL27=1,"入る枠がありません",""),INDEX('計算A'!$D$8:$II$8,'計算A'!IK27)) | P22: =HYPERLINK("#'×入力'!B481","×入力へ")
G23: =IF(B23="","",IF(A23="","",A23&" ")&B23) | H23: =IF(B23="","",IF('×入力'!F509="未提出","未提出",IF(I23>0,"入力済み",IF('×入力'!F509="×なし（どこでもOK）","×なし","未入力")))) | I23: =IF(B23="","",'計算A'!IN28) | J23: =IF(OR(H23="入力済み",H23="×なし"),'計算A'!IM28,"") | K23: =IF('計算A'!C28=1,COUNTIFS('計算A'!$C$10:$C$54,1,'計算A'!$IM$10:$IM$54,"<"&'計算A'!IM28)+1,"") | L23: =IF('計算A'!IO28=0,"",INDEX('設定'!$E$11:$E$20,INDEX('計算A'!$D$2:$II$2,'計算A'!IO28))) | M23: =IF('計算A'!IO28=0,"",INDEX('設定'!$I$11:$I$34,INDEX('計算A'!$D$3:$II$3,'計算A'!IO28))) | N23: =IF(G23="","",IF(COUNTIF('調整・決定'!$C$6:$L$29,G23)>1,"2か所以上に入っています",IF('計算A'!IO28>0,IF(INDEX('計算A'!$D$4:$II$4,'計算A'!IO28)=0,"使えない枠に入っています",IF(INDEX('計算A'!$D$28:$II$28,'計算A'!IO28)=1,"×の枠に入っています",IF(AND(F23<>"",INDEX('計算A'!$D$106:$II$106,'計算A'!IO28)=1,INDEX('計算A'!$D$109:$II$109,'計算A'!IO28+1)=1),IF(F23="必ず空けたい","後ろの枠が空いていません","（出来れば）後ろが空いていません"),""))),IF(OR(H23="入力済み",H23="×なし"),"未決定","")))) | O23: =IF('計算A'!IK28=0,IF('計算A'!IL28=1,"入る枠がありません",""),INDEX('計算A'!$D$8:$II$8,'計算A'!IK28)) | P23: =HYPERLINK("#'×入力'!B509","×入力へ")
G24: =IF(B24="","",IF(A24="","",A24&" ")&B24) | H24: =IF(B24="","",IF('×入力'!F537="未提出","未提出",IF(I24>0,"入力済み",IF('×入力'!F537="×なし（どこでもOK）","×なし","未入力")))) | I24: =IF(B24="","",'計算A'!IN29) | J24: =IF(OR(H24="入力済み",H24="×なし"),'計算A'!IM29,"") | K24: =IF('計算A'!C29=1,COUNTIFS('計算A'!$C$10:$C$54,1,'計算A'!$IM$10:$IM$54,"<"&'計算A'!IM29)+1,"") | L24: =IF('計算A'!IO29=0,"",INDEX('設定'!$E$11:$E$20,INDEX('計算A'!$D$2:$II$2,'計算A'!IO29))) | M24: =IF('計算A'!IO29=0,"",INDEX('設定'!$I$11:$I$34,INDEX('計算A'!$D$3:$II$3,'計算A'!IO29))) | N24: =IF(G24="","",IF(COUNTIF('調整・決定'!$C$6:$L$29,G24)>1,"2か所以上に入っています",IF('計算A'!IO29>0,IF(INDEX('計算A'!$D$4:$II$4,'計算A'!IO29)=0,"使えない枠に入っています",IF(INDEX('計算A'!$D$29:$II$29,'計算A'!IO29)=1,"×の枠に入っています",IF(AND(F24<>"",INDEX('計算A'!$D$106:$II$106,'計算A'!IO29)=1,INDEX('計算A'!$D$109:$II$109,'計算A'!IO29+1)=1),IF(F24="必ず空けたい","後ろの枠が空いていません","（出来れば）後ろが空いていません"),""))),IF(OR(H24="入力済み",H24="×なし"),"未決定","")))) | O24: =IF('計算A'!IK29=0,IF('計算A'!IL29=1,"入る枠がありません",""),INDEX('計算A'!$D$8:$II$8,'計算A'!IK29)) | P24: =HYPERLINK("#'×入力'!B537","×入力へ")
G25: =IF(B25="","",IF(A25="","",A25&" ")&B25) | H25: =IF(B25="","",IF('×入力'!F565="未提出","未提出",IF(I25>0,"入力済み",IF('×入力'!F565="×なし（どこでもOK）","×なし","未入力")))) | I25: =IF(B25="","",'計算A'!IN30) | J25: =IF(OR(H25="入力済み",H25="×なし"),'計算A'!IM30,"") | K25: =IF('計算A'!C30=1,COUNTIFS('計算A'!$C$10:$C$54,1,'計算A'!$IM$10:$IM$54,"<"&'計算A'!IM30)+1,"") | L25: =IF('計算A'!IO30=0,"",INDEX('設定'!$E$11:$E$20,INDEX('計算A'!$D$2:$II$2,'計算A'!IO30))) | M25: =IF('計算A'!IO30=0,"",INDEX('設定'!$I$11:$I$34,INDEX('計算A'!$D$3:$II$3,'計算A'!IO30))) | N25: =IF(G25="","",IF(COUNTIF('調整・決定'!$C$6:$L$29,G25)>1,"2か所以上に入っています",IF('計算A'!IO30>0,IF(INDEX('計算A'!$D$4:$II$4,'計算A'!IO30)=0,"使えない枠に入っています",IF(INDEX('計算A'!$D$30:$II$30,'計算A'!IO30)=1,"×の枠に入っています",IF(AND(F25<>"",INDEX('計算A'!$D$106:$II$106,'計算A'!IO30)=1,INDEX('計算A'!$D$109:$II$109,'計算A'!IO30+1)=1),IF(F25="必ず空けたい","後ろの枠が空いていません","（出来れば）後ろが空いていません"),""))),IF(OR(H25="入力済み",H25="×なし"),"未決定","")))) | O25: =IF('計算A'!IK30=0,IF('計算A'!IL30=1,"入る枠がありません",""),INDEX('計算A'!$D$8:$II$8,'計算A'!IK30)) | P25: =HYPERLINK("#'×入力'!B565","×入力へ")
G26: =IF(B26="","",IF(A26="","",A26&" ")&B26) | H26: =IF(B26="","",IF('×入力'!F593="未提出","未提出",IF(I26>0,"入力済み",IF('×入力'!F593="×なし（どこでもOK）","×なし","未入力")))) | I26: =IF(B26="","",'計算A'!IN31) | J26: =IF(OR(H26="入力済み",H26="×なし"),'計算A'!IM31,"") | K26: =IF('計算A'!C31=1,COUNTIFS('計算A'!$C$10:$C$54,1,'計算A'!$IM$10:$IM$54,"<"&'計算A'!IM31)+1,"") | L26: =IF('計算A'!IO31=0,"",INDEX('設定'!$E$11:$E$20,INDEX('計算A'!$D$2:$II$2,'計算A'!IO31))) | M26: =IF('計算A'!IO31=0,"",INDEX('設定'!$I$11:$I$34,INDEX('計算A'!$D$3:$II$3,'計算A'!IO31))) | N26: =IF(G26="","",IF(COUNTIF('調整・決定'!$C$6:$L$29,G26)>1,"2か所以上に入っています",IF('計算A'!IO31>0,IF(INDEX('計算A'!$D$4:$II$4,'計算A'!IO31)=0,"使えない枠に入っています",IF(INDEX('計算A'!$D$31:$II$31,'計算A'!IO31)=1,"×の枠に入っています",IF(AND(F26<>"",INDEX('計算A'!$D$106:$II$106,'計算A'!IO31)=1,INDEX('計算A'!$D$109:$II$109,'計算A'!IO31+1)=1),IF(F26="必ず空けたい","後ろの枠が空いていません","（出来れば）後ろが空いていません"),""))),IF(OR(H26="入力済み",H26="×なし"),"未決定","")))) | O26: =IF('計算A'!IK31=0,IF('計算A'!IL31=1,"入る枠がありません",""),INDEX('計算A'!$D$8:$II$8,'計算A'!IK31)) | P26: =HYPERLINK("#'×入力'!B593","×入力へ")
G27: =IF(B27="","",IF(A27="","",A27&" ")&B27) | H27: =IF(B27="","",IF('×入力'!F621="未提出","未提出",IF(I27>0,"入力済み",IF('×入力'!F621="×なし（どこでもOK）","×なし","未入力")))) | I27: =IF(B27="","",'計算A'!IN32) | J27: =IF(OR(H27="入力済み",H27="×なし"),'計算A'!IM32,"") | K27: =IF('計算A'!C32=1,COUNTIFS('計算A'!$C$10:$C$54,1,'計算A'!$IM$10:$IM$54,"<"&'計算A'!IM32)+1,"") | L27: =IF('計算A'!IO32=0,"",INDEX('設定'!$E$11:$E$20,INDEX('計算A'!$D$2:$II$2,'計算A'!IO32))) | M27: =IF('計算A'!IO32=0,"",INDEX('設定'!$I$11:$I$34,INDEX('計算A'!$D$3:$II$3,'計算A'!IO32))) | N27: =IF(G27="","",IF(COUNTIF('調整・決定'!$C$6:$L$29,G27)>1,"2か所以上に入っています",IF('計算A'!IO32>0,IF(INDEX('計算A'!$D$4:$II$4,'計算A'!IO32)=0,"使えない枠に入っています",IF(INDEX('計算A'!$D$32:$II$32,'計算A'!IO32)=1,"×の枠に入っています",IF(AND(F27<>"",INDEX('計算A'!$D$106:$II$106,'計算A'!IO32)=1,INDEX('計算A'!$D$109:$II$109,'計算A'!IO32+1)=1),IF(F27="必ず空けたい","後ろの枠が空いていません","（出来れば）後ろが空いていません"),""))),IF(OR(H27="入力済み",H27="×なし"),"未決定","")))) | O27: =IF('計算A'!IK32=0,IF('計算A'!IL32=1,"入る枠がありません",""),INDEX('計算A'!$D$8:$II$8,'計算A'!IK32)) | P27: =HYPERLINK("#'×入力'!B621","×入力へ")
G28: =IF(B28="","",IF(A28="","",A28&" ")&B28) | H28: =IF(B28="","",IF('×入力'!F649="未提出","未提出",IF(I28>0,"入力済み",IF('×入力'!F649="×なし（どこでもOK）","×なし","未入力")))) | I28: =IF(B28="","",'計算A'!IN33) | J28: =IF(OR(H28="入力済み",H28="×なし"),'計算A'!IM33,"") | K28: =IF('計算A'!C33=1,COUNTIFS('計算A'!$C$10:$C$54,1,'計算A'!$IM$10:$IM$54,"<"&'計算A'!IM33)+1,"") | L28: =IF('計算A'!IO33=0,"",INDEX('設定'!$E$11:$E$20,INDEX('計算A'!$D$2:$II$2,'計算A'!IO33))) | M28: =IF('計算A'!IO33=0,"",INDEX('設定'!$I$11:$I$34,INDEX('計算A'!$D$3:$II$3,'計算A'!IO33))) | N28: =IF(G28="","",IF(COUNTIF('調整・決定'!$C$6:$L$29,G28)>1,"2か所以上に入っています",IF('計算A'!IO33>0,IF(INDEX('計算A'!$D$4:$II$4,'計算A'!IO33)=0,"使えない枠に入っています",IF(INDEX('計算A'!$D$33:$II$33,'計算A'!IO33)=1,"×の枠に入っています",IF(AND(F28<>"",INDEX('計算A'!$D$106:$II$106,'計算A'!IO33)=1,INDEX('計算A'!$D$109:$II$109,'計算A'!IO33+1)=1),IF(F28="必ず空けたい","後ろの枠が空いていません","（出来れば）後ろが空いていません"),""))),IF(OR(H28="入力済み",H28="×なし"),"未決定","")))) | O28: =IF('計算A'!IK33=0,IF('計算A'!IL33=1,"入る枠がありません",""),INDEX('計算A'!$D$8:$II$8,'計算A'!IK33)) | P28: =HYPERLINK("#'×入力'!B649","×入力へ")
G29: =IF(B29="","",IF(A29="","",A29&" ")&B29) | H29: =IF(B29="","",IF('×入力'!F677="未提出","未提出",IF(I29>0,"入力済み",IF('×入力'!F677="×なし（どこでもOK）","×なし","未入力")))) | I29: =IF(B29="","",'計算A'!IN34) | J29: =IF(OR(H29="入力済み",H29="×なし"),'計算A'!IM34,"") | K29: =IF('計算A'!C34=1,COUNTIFS('計算A'!$C$10:$C$54,1,'計算A'!$IM$10:$IM$54,"<"&'計算A'!IM34)+1,"") | L29: =IF('計算A'!IO34=0,"",INDEX('設定'!$E$11:$E$20,INDEX('計算A'!$D$2:$II$2,'計算A'!IO34))) | M29: =IF('計算A'!IO34=0,"",INDEX('設定'!$I$11:$I$34,INDEX('計算A'!$D$3:$II$3,'計算A'!IO34))) | N29: =IF(G29="","",IF(COUNTIF('調整・決定'!$C$6:$L$29,G29)>1,"2か所以上に入っています",IF('計算A'!IO34>0,IF(INDEX('計算A'!$D$4:$II$4,'計算A'!IO34)=0,"使えない枠に入っています",IF(INDEX('計算A'!$D$34:$II$34,'計算A'!IO34)=1,"×の枠に入っています",IF(AND(F29<>"",INDEX('計算A'!$D$106:$II$106,'計算A'!IO34)=1,INDEX('計算A'!$D$109:$II$109,'計算A'!IO34+1)=1),IF(F29="必ず空けたい","後ろの枠が空いていません","（出来れば）後ろが空いていません"),""))),IF(OR(H29="入力済み",H29="×なし"),"未決定","")))) | O29: =IF('計算A'!IK34=0,IF('計算A'!IL34=1,"入る枠がありません",""),INDEX('計算A'!$D$8:$II$8,'計算A'!IK34)) | P29: =HYPERLINK("#'×入力'!B677","×入力へ")
G30: =IF(B30="","",IF(A30="","",A30&" ")&B30) | H30: =IF(B30="","",IF('×入力'!F705="未提出","未提出",IF(I30>0,"入力済み",IF('×入力'!F705="×なし（どこでもOK）","×なし","未入力")))) | I30: =IF(B30="","",'計算A'!IN35) | J30: =IF(OR(H30="入力済み",H30="×なし"),'計算A'!IM35,"") | K30: =IF('計算A'!C35=1,COUNTIFS('計算A'!$C$10:$C$54,1,'計算A'!$IM$10:$IM$54,"<"&'計算A'!IM35)+1,"") | L30: =IF('計算A'!IO35=0,"",INDEX('設定'!$E$11:$E$20,INDEX('計算A'!$D$2:$II$2,'計算A'!IO35))) | M30: =IF('計算A'!IO35=0,"",INDEX('設定'!$I$11:$I$34,INDEX('計算A'!$D$3:$II$3,'計算A'!IO35))) | N30: =IF(G30="","",IF(COUNTIF('調整・決定'!$C$6:$L$29,G30)>1,"2か所以上に入っています",IF('計算A'!IO35>0,IF(INDEX('計算A'!$D$4:$II$4,'計算A'!IO35)=0,"使えない枠に入っています",IF(INDEX('計算A'!$D$35:$II$35,'計算A'!IO35)=1,"×の枠に入っています",IF(AND(F30<>"",INDEX('計算A'!$D$106:$II$106,'計算A'!IO35)=1,INDEX('計算A'!$D$109:$II$109,'計算A'!IO35+1)=1),IF(F30="必ず空けたい","後ろの枠が空いていません","（出来れば）後ろが空いていません"),""))),IF(OR(H30="入力済み",H30="×なし"),"未決定","")))) | O30: =IF('計算A'!IK35=0,IF('計算A'!IL35=1,"入る枠がありません",""),INDEX('計算A'!$D$8:$II$8,'計算A'!IK35)) | P30: =HYPERLINK("#'×入力'!B705","×入力へ")
G31: =IF(B31="","",IF(A31="","",A31&" ")&B31) | H31: =IF(B31="","",IF('×入力'!F733="未提出","未提出",IF(I31>0,"入力済み",IF('×入力'!F733="×なし（どこでもOK）","×なし","未入力")))) | I31: =IF(B31="","",'計算A'!IN36) | J31: =IF(OR(H31="入力済み",H31="×なし"),'計算A'!IM36,"") | K31: =IF('計算A'!C36=1,COUNTIFS('計算A'!$C$10:$C$54,1,'計算A'!$IM$10:$IM$54,"<"&'計算A'!IM36)+1,"") | L31: =IF('計算A'!IO36=0,"",INDEX('設定'!$E$11:$E$20,INDEX('計算A'!$D$2:$II$2,'計算A'!IO36))) | M31: =IF('計算A'!IO36=0,"",INDEX('設定'!$I$11:$I$34,INDEX('計算A'!$D$3:$II$3,'計算A'!IO36))) | N31: =IF(G31="","",IF(COUNTIF('調整・決定'!$C$6:$L$29,G31)>1,"2か所以上に入っています",IF('計算A'!IO36>0,IF(INDEX('計算A'!$D$4:$II$4,'計算A'!IO36)=0,"使えない枠に入っています",IF(INDEX('計算A'!$D$36:$II$36,'計算A'!IO36)=1,"×の枠に入っています",IF(AND(F31<>"",INDEX('計算A'!$D$106:$II$106,'計算A'!IO36)=1,INDEX('計算A'!$D$109:$II$109,'計算A'!IO36+1)=1),IF(F31="必ず空けたい","後ろの枠が空いていません","（出来れば）後ろが空いていません"),""))),IF(OR(H31="入力済み",H31="×なし"),"未決定","")))) | O31: =IF('計算A'!IK36=0,IF('計算A'!IL36=1,"入る枠がありません",""),INDEX('計算A'!$D$8:$II$8,'計算A'!IK36)) | P31: =HYPERLINK("#'×入力'!B733","×入力へ")
G32: =IF(B32="","",IF(A32="","",A32&" ")&B32) | H32: =IF(B32="","",IF('×入力'!F761="未提出","未提出",IF(I32>0,"入力済み",IF('×入力'!F761="×なし（どこでもOK）","×なし","未入力")))) | I32: =IF(B32="","",'計算A'!IN37) | J32: =IF(OR(H32="入力済み",H32="×なし"),'計算A'!IM37,"") | K32: =IF('計算A'!C37=1,COUNTIFS('計算A'!$C$10:$C$54,1,'計算A'!$IM$10:$IM$54,"<"&'計算A'!IM37)+1,"") | L32: =IF('計算A'!IO37=0,"",INDEX('設定'!$E$11:$E$20,INDEX('計算A'!$D$2:$II$2,'計算A'!IO37))) | M32: =IF('計算A'!IO37=0,"",INDEX('設定'!$I$11:$I$34,INDEX('計算A'!$D$3:$II$3,'計算A'!IO37))) | N32: =IF(G32="","",IF(COUNTIF('調整・決定'!$C$6:$L$29,G32)>1,"2か所以上に入っています",IF('計算A'!IO37>0,IF(INDEX('計算A'!$D$4:$II$4,'計算A'!IO37)=0,"使えない枠に入っています",IF(INDEX('計算A'!$D$37:$II$37,'計算A'!IO37)=1,"×の枠に入っています",IF(AND(F32<>"",INDEX('計算A'!$D$106:$II$106,'計算A'!IO37)=1,INDEX('計算A'!$D$109:$II$109,'計算A'!IO37+1)=1),IF(F32="必ず空けたい","後ろの枠が空いていません","（出来れば）後ろが空いていません"),""))),IF(OR(H32="入力済み",H32="×なし"),"未決定","")))) | O32: =IF('計算A'!IK37=0,IF('計算A'!IL37=1,"入る枠がありません",""),INDEX('計算A'!$D$8:$II$8,'計算A'!IK37)) | P32: =HYPERLINK("#'×入力'!B761","×入力へ")
G33: =IF(B33="","",IF(A33="","",A33&" ")&B33) | H33: =IF(B33="","",IF('×入力'!F789="未提出","未提出",IF(I33>0,"入力済み",IF('×入力'!F789="×なし（どこでもOK）","×なし","未入力")))) | I33: =IF(B33="","",'計算A'!IN38) | J33: =IF(OR(H33="入力済み",H33="×なし"),'計算A'!IM38,"") | K33: =IF('計算A'!C38=1,COUNTIFS('計算A'!$C$10:$C$54,1,'計算A'!$IM$10:$IM$54,"<"&'計算A'!IM38)+1,"") | L33: =IF('計算A'!IO38=0,"",INDEX('設定'!$E$11:$E$20,INDEX('計算A'!$D$2:$II$2,'計算A'!IO38))) | M33: =IF('計算A'!IO38=0,"",INDEX('設定'!$I$11:$I$34,INDEX('計算A'!$D$3:$II$3,'計算A'!IO38))) | N33: =IF(G33="","",IF(COUNTIF('調整・決定'!$C$6:$L$29,G33)>1,"2か所以上に入っています",IF('計算A'!IO38>0,IF(INDEX('計算A'!$D$4:$II$4,'計算A'!IO38)=0,"使えない枠に入っています",IF(INDEX('計算A'!$D$38:$II$38,'計算A'!IO38)=1,"×の枠に入っています",IF(AND(F33<>"",INDEX('計算A'!$D$106:$II$106,'計算A'!IO38)=1,INDEX('計算A'!$D$109:$II$109,'計算A'!IO38+1)=1),IF(F33="必ず空けたい","後ろの枠が空いていません","（出来れば）後ろが空いていません"),""))),IF(OR(H33="入力済み",H33="×なし"),"未決定","")))) | O33: =IF('計算A'!IK38=0,IF('計算A'!IL38=1,"入る枠がありません",""),INDEX('計算A'!$D$8:$II$8,'計算A'!IK38)) | P33: =HYPERLINK("#'×入力'!B789","×入力へ")
G34: =IF(B34="","",IF(A34="","",A34&" ")&B34) | H34: =IF(B34="","",IF('×入力'!F817="未提出","未提出",IF(I34>0,"入力済み",IF('×入力'!F817="×なし（どこでもOK）","×なし","未入力")))) | I34: =IF(B34="","",'計算A'!IN39) | J34: =IF(OR(H34="入力済み",H34="×なし"),'計算A'!IM39,"") | K34: =IF('計算A'!C39=1,COUNTIFS('計算A'!$C$10:$C$54,1,'計算A'!$IM$10:$IM$54,"<"&'計算A'!IM39)+1,"") | L34: =IF('計算A'!IO39=0,"",INDEX('設定'!$E$11:$E$20,INDEX('計算A'!$D$2:$II$2,'計算A'!IO39))) | M34: =IF('計算A'!IO39=0,"",INDEX('設定'!$I$11:$I$34,INDEX('計算A'!$D$3:$II$3,'計算A'!IO39))) | N34: =IF(G34="","",IF(COUNTIF('調整・決定'!$C$6:$L$29,G34)>1,"2か所以上に入っています",IF('計算A'!IO39>0,IF(INDEX('計算A'!$D$4:$II$4,'計算A'!IO39)=0,"使えない枠に入っています",IF(INDEX('計算A'!$D$39:$II$39,'計算A'!IO39)=1,"×の枠に入っています",IF(AND(F34<>"",INDEX('計算A'!$D$106:$II$106,'計算A'!IO39)=1,INDEX('計算A'!$D$109:$II$109,'計算A'!IO39+1)=1),IF(F34="必ず空けたい","後ろの枠が空いていません","（出来れば）後ろが空いていません"),""))),IF(OR(H34="入力済み",H34="×なし"),"未決定","")))) | O34: =IF('計算A'!IK39=0,IF('計算A'!IL39=1,"入る枠がありません",""),INDEX('計算A'!$D$8:$II$8,'計算A'!IK39)) | P34: =HYPERLINK("#'×入力'!B817","×入力へ")
G35: =IF(B35="","",IF(A35="","",A35&" ")&B35) | H35: =IF(B35="","",IF('×入力'!F845="未提出","未提出",IF(I35>0,"入力済み",IF('×入力'!F845="×なし（どこでもOK）","×なし","未入力")))) | I35: =IF(B35="","",'計算A'!IN40) | J35: =IF(OR(H35="入力済み",H35="×なし"),'計算A'!IM40,"") | K35: =IF('計算A'!C40=1,COUNTIFS('計算A'!$C$10:$C$54,1,'計算A'!$IM$10:$IM$54,"<"&'計算A'!IM40)+1,"") | L35: =IF('計算A'!IO40=0,"",INDEX('設定'!$E$11:$E$20,INDEX('計算A'!$D$2:$II$2,'計算A'!IO40))) | M35: =IF('計算A'!IO40=0,"",INDEX('設定'!$I$11:$I$34,INDEX('計算A'!$D$3:$II$3,'計算A'!IO40))) | N35: =IF(G35="","",IF(COUNTIF('調整・決定'!$C$6:$L$29,G35)>1,"2か所以上に入っています",IF('計算A'!IO40>0,IF(INDEX('計算A'!$D$4:$II$4,'計算A'!IO40)=0,"使えない枠に入っています",IF(INDEX('計算A'!$D$40:$II$40,'計算A'!IO40)=1,"×の枠に入っています",IF(AND(F35<>"",INDEX('計算A'!$D$106:$II$106,'計算A'!IO40)=1,INDEX('計算A'!$D$109:$II$109,'計算A'!IO40+1)=1),IF(F35="必ず空けたい","後ろの枠が空いていません","（出来れば）後ろが空いていません"),""))),IF(OR(H35="入力済み",H35="×なし"),"未決定","")))) | O35: =IF('計算A'!IK40=0,IF('計算A'!IL40=1,"入る枠がありません",""),INDEX('計算A'!$D$8:$II$8,'計算A'!IK40)) | P35: =HYPERLINK("#'×入力'!B845","×入力へ")
G36: =IF(B36="","",IF(A36="","",A36&" ")&B36) | H36: =IF(B36="","",IF('×入力'!F873="未提出","未提出",IF(I36>0,"入力済み",IF('×入力'!F873="×なし（どこでもOK）","×なし","未入力")))) | I36: =IF(B36="","",'計算A'!IN41) | J36: =IF(OR(H36="入力済み",H36="×なし"),'計算A'!IM41,"") | K36: =IF('計算A'!C41=1,COUNTIFS('計算A'!$C$10:$C$54,1,'計算A'!$IM$10:$IM$54,"<"&'計算A'!IM41)+1,"") | L36: =IF('計算A'!IO41=0,"",INDEX('設定'!$E$11:$E$20,INDEX('計算A'!$D$2:$II$2,'計算A'!IO41))) | M36: =IF('計算A'!IO41=0,"",INDEX('設定'!$I$11:$I$34,INDEX('計算A'!$D$3:$II$3,'計算A'!IO41))) | N36: =IF(G36="","",IF(COUNTIF('調整・決定'!$C$6:$L$29,G36)>1,"2か所以上に入っています",IF('計算A'!IO41>0,IF(INDEX('計算A'!$D$4:$II$4,'計算A'!IO41)=0,"使えない枠に入っています",IF(INDEX('計算A'!$D$41:$II$41,'計算A'!IO41)=1,"×の枠に入っています",IF(AND(F36<>"",INDEX('計算A'!$D$106:$II$106,'計算A'!IO41)=1,INDEX('計算A'!$D$109:$II$109,'計算A'!IO41+1)=1),IF(F36="必ず空けたい","後ろの枠が空いていません","（出来れば）後ろが空いていません"),""))),IF(OR(H36="入力済み",H36="×なし"),"未決定","")))) | O36: =IF('計算A'!IK41=0,IF('計算A'!IL41=1,"入る枠がありません",""),INDEX('計算A'!$D$8:$II$8,'計算A'!IK41)) | P36: =HYPERLINK("#'×入力'!B873","×入力へ")
G37: =IF(B37="","",IF(A37="","",A37&" ")&B37) | H37: =IF(B37="","",IF('×入力'!F901="未提出","未提出",IF(I37>0,"入力済み",IF('×入力'!F901="×なし（どこでもOK）","×なし","未入力")))) | I37: =IF(B37="","",'計算A'!IN42) | J37: =IF(OR(H37="入力済み",H37="×なし"),'計算A'!IM42,"") | K37: =IF('計算A'!C42=1,COUNTIFS('計算A'!$C$10:$C$54,1,'計算A'!$IM$10:$IM$54,"<"&'計算A'!IM42)+1,"") | L37: =IF('計算A'!IO42=0,"",INDEX('設定'!$E$11:$E$20,INDEX('計算A'!$D$2:$II$2,'計算A'!IO42))) | M37: =IF('計算A'!IO42=0,"",INDEX('設定'!$I$11:$I$34,INDEX('計算A'!$D$3:$II$3,'計算A'!IO42))) | N37: =IF(G37="","",IF(COUNTIF('調整・決定'!$C$6:$L$29,G37)>1,"2か所以上に入っています",IF('計算A'!IO42>0,IF(INDEX('計算A'!$D$4:$II$4,'計算A'!IO42)=0,"使えない枠に入っています",IF(INDEX('計算A'!$D$42:$II$42,'計算A'!IO42)=1,"×の枠に入っています",IF(AND(F37<>"",INDEX('計算A'!$D$106:$II$106,'計算A'!IO42)=1,INDEX('計算A'!$D$109:$II$109,'計算A'!IO42+1)=1),IF(F37="必ず空けたい","後ろの枠が空いていません","（出来れば）後ろが空いていません"),""))),IF(OR(H37="入力済み",H37="×なし"),"未決定","")))) | O37: =IF('計算A'!IK42=0,IF('計算A'!IL42=1,"入る枠がありません",""),INDEX('計算A'!$D$8:$II$8,'計算A'!IK42)) | P37: =HYPERLINK("#'×入力'!B901","×入力へ")
G38: =IF(B38="","",IF(A38="","",A38&" ")&B38) | H38: =IF(B38="","",IF('×入力'!F929="未提出","未提出",IF(I38>0,"入力済み",IF('×入力'!F929="×なし（どこでもOK）","×なし","未入力")))) | I38: =IF(B38="","",'計算A'!IN43) | J38: =IF(OR(H38="入力済み",H38="×なし"),'計算A'!IM43,"") | K38: =IF('計算A'!C43=1,COUNTIFS('計算A'!$C$10:$C$54,1,'計算A'!$IM$10:$IM$54,"<"&'計算A'!IM43)+1,"") | L38: =IF('計算A'!IO43=0,"",INDEX('設定'!$E$11:$E$20,INDEX('計算A'!$D$2:$II$2,'計算A'!IO43))) | M38: =IF('計算A'!IO43=0,"",INDEX('設定'!$I$11:$I$34,INDEX('計算A'!$D$3:$II$3,'計算A'!IO43))) | N38: =IF(G38="","",IF(COUNTIF('調整・決定'!$C$6:$L$29,G38)>1,"2か所以上に入っています",IF('計算A'!IO43>0,IF(INDEX('計算A'!$D$4:$II$4,'計算A'!IO43)=0,"使えない枠に入っています",IF(INDEX('計算A'!$D$43:$II$43,'計算A'!IO43)=1,"×の枠に入っています",IF(AND(F38<>"",INDEX('計算A'!$D$106:$II$106,'計算A'!IO43)=1,INDEX('計算A'!$D$109:$II$109,'計算A'!IO43+1)=1),IF(F38="必ず空けたい","後ろの枠が空いていません","（出来れば）後ろが空いていません"),""))),IF(OR(H38="入力済み",H38="×なし"),"未決定","")))) | O38: =IF('計算A'!IK43=0,IF('計算A'!IL43=1,"入る枠がありません",""),INDEX('計算A'!$D$8:$II$8,'計算A'!IK43)) | P38: =HYPERLINK("#'×入力'!B929","×入力へ")
G39: =IF(B39="","",IF(A39="","",A39&" ")&B39) | H39: =IF(B39="","",IF('×入力'!F957="未提出","未提出",IF(I39>0,"入力済み",IF('×入力'!F957="×なし（どこでもOK）","×なし","未入力")))) | I39: =IF(B39="","",'計算A'!IN44) | J39: =IF(OR(H39="入力済み",H39="×なし"),'計算A'!IM44,"") | K39: =IF('計算A'!C44=1,COUNTIFS('計算A'!$C$10:$C$54,1,'計算A'!$IM$10:$IM$54,"<"&'計算A'!IM44)+1,"") | L39: =IF('計算A'!IO44=0,"",INDEX('設定'!$E$11:$E$20,INDEX('計算A'!$D$2:$II$2,'計算A'!IO44))) | M39: =IF('計算A'!IO44=0,"",INDEX('設定'!$I$11:$I$34,INDEX('計算A'!$D$3:$II$3,'計算A'!IO44))) | N39: =IF(G39="","",IF(COUNTIF('調整・決定'!$C$6:$L$29,G39)>1,"2か所以上に入っています",IF('計算A'!IO44>0,IF(INDEX('計算A'!$D$4:$II$4,'計算A'!IO44)=0,"使えない枠に入っています",IF(INDEX('計算A'!$D$44:$II$44,'計算A'!IO44)=1,"×の枠に入っています",IF(AND(F39<>"",INDEX('計算A'!$D$106:$II$106,'計算A'!IO44)=1,INDEX('計算A'!$D$109:$II$109,'計算A'!IO44+1)=1),IF(F39="必ず空けたい","後ろの枠が空いていません","（出来れば）後ろが空いていません"),""))),IF(OR(H39="入力済み",H39="×なし"),"未決定","")))) | O39: =IF('計算A'!IK44=0,IF('計算A'!IL44=1,"入る枠がありません",""),INDEX('計算A'!$D$8:$II$8,'計算A'!IK44)) | P39: =HYPERLINK("#'×入力'!B957","×入力へ")
G40: =IF(B40="","",IF(A40="","",A40&" ")&B40) | H40: =IF(B40="","",IF('×入力'!F985="未提出","未提出",IF(I40>0,"入力済み",IF('×入力'!F985="×なし（どこでもOK）","×なし","未入力")))) | I40: =IF(B40="","",'計算A'!IN45) | J40: =IF(OR(H40="入力済み",H40="×なし"),'計算A'!IM45,"") | K40: =IF('計算A'!C45=1,COUNTIFS('計算A'!$C$10:$C$54,1,'計算A'!$IM$10:$IM$54,"<"&'計算A'!IM45)+1,"") | L40: =IF('計算A'!IO45=0,"",INDEX('設定'!$E$11:$E$20,INDEX('計算A'!$D$2:$II$2,'計算A'!IO45))) | M40: =IF('計算A'!IO45=0,"",INDEX('設定'!$I$11:$I$34,INDEX('計算A'!$D$3:$II$3,'計算A'!IO45))) | N40: =IF(G40="","",IF(COUNTIF('調整・決定'!$C$6:$L$29,G40)>1,"2か所以上に入っています",IF('計算A'!IO45>0,IF(INDEX('計算A'!$D$4:$II$4,'計算A'!IO45)=0,"使えない枠に入っています",IF(INDEX('計算A'!$D$45:$II$45,'計算A'!IO45)=1,"×の枠に入っています",IF(AND(F40<>"",INDEX('計算A'!$D$106:$II$106,'計算A'!IO45)=1,INDEX('計算A'!$D$109:$II$109,'計算A'!IO45+1)=1),IF(F40="必ず空けたい","後ろの枠が空いていません","（出来れば）後ろが空いていません"),""))),IF(OR(H40="入力済み",H40="×なし"),"未決定","")))) | O40: =IF('計算A'!IK45=0,IF('計算A'!IL45=1,"入る枠がありません",""),INDEX('計算A'!$D$8:$II$8,'計算A'!IK45)) | P40: =HYPERLINK("#'×入力'!B985","×入力へ")
...

Sheet ×入力
B1: ×入力 | F1: =HYPERLINK("#'ホーム'!A1","ホーム") | G1: =HYPERLINK("#'設定'!A1","① 設定") | H1: =HYPERLINK("#'名簿'!A1","② 名簿") | I1: =HYPERLINK("#'×入力'!A1","③ ×入力") | J1: =HYPERLINK("#'自動案'!A1","④ 自動案") | K1: =HYPERLINK("#'調整・決定'!A1","⑤ 調整・決定")
B2: 都合の悪い枠に「×」。日付の上の欄で「×」→その日全部、時刻の左の欄で「×」→その時間全部が×になります。消すときは Delete。
B3: ×が1つもない家庭は「提出状況」で「×なし（どこでもOK）」、出していない家庭は「未提出」を選びます。右上の「次の人へ ▼」で次の児童に移れます。
B5: =IF('名簿'!B5="","（名簿 1行目：なし）",'名簿'!G5) | E5: 提出状況 ▶ | H5: 状況： | I5: ='名簿'!H5 | J5: ×の数： | K5: ='名簿'!I5 | L5: =HYPERLINK("#'×入力'!B33","次の人へ ▼")
A6: この日全部 ▶
A7: この時間 全部 ▼ | C7: ='設定'!$E$11 | D7: ='設定'!$E$12 | E7: ='設定'!$E$13 | F7: ='設定'!$E$14 | G7: ='設定'!$E$15 | H7: ='設定'!$E$16 | I7: ='設定'!$E$17 | J7: ='設定'!$E$18 | K7: ='設定'!$E$19 | L7: ='設定'!$E$20
B8: ='設定'!$I$11
B9: ='設定'!$I$12
B10: ='設定'!$I$13
B11: ='設定'!$I$14
B12: ='設定'!$I$15
B13: ='設定'!$I$16
B14: ='設定'!$I$17
B15: ='設定'!$I$18
B16: ='設定'!$I$19
B17: ='設定'!$I$20
B18: ='設定'!$I$21
B19: ='設定'!$I$22
B20: ='設定'!$I$23
B21: ='設定'!$I$24
B22: ='設定'!$I$25
B23: ='設定'!$I$26
B24: ='設定'!$I$27
B25: ='設定'!$I$28
B26: ='設定'!$I$29
B27: ='設定'!$I$30
B28: ='設定'!$I$31
B29: ='設定'!$I$32
B30: ='設定'!$I$33
B31: ='設定'!$I$34
B33: =IF('名簿'!B6="","（名簿 2行目：なし）",'名簿'!G6) | E33: 提出状況 ▶ | H33: 状況： | I33: ='名簿'!H6 | J33: ×の数： | K33: ='名簿'!I6 | L33: =HYPERLINK("#'×入力'!B61","次の人へ ▼")
A34: この日全部 ▶
A35: この時間 全部 ▼ | C35: ='設定'!$E$11 | D35: ='設定'!$E$12 | E35: ='設定'!$E$13 | F35: ='設定'!$E$14 | G35: ='設定'!$E$15 | H35: ='設定'!$E$16 | I35: ='設定'!$E$17 | J35: ='設定'!$E$18 | K35: ='設定'!$E$19 | L35: ='設定'!$E$20
B36: ='設定'!$I$11
B37: ='設定'!$I$12
B38: ='設定'!$I$13
B39: ='設定'!$I$14
B40: ='設定'!$I$15
B41: ='設定'!$I$16
B42: ='設定'!$I$17
...

Sheet 自動案
B1: 自動案 | F1: =HYPERLINK("#'ホーム'!A1","ホーム") | G1: =HYPERLINK("#'設定'!A1","① 設定") | H1: =HYPERLINK("#'名簿'!A1","② 名簿") | I1: =HYPERLINK("#'×入力'!A1","③ ×入力") | J1: =HYPERLINK("#'自動案'!A1","④ 自動案") | K1: =HYPERLINK("#'調整・決定'!A1","⑤ 調整・決定")
B2: 入れられる枠が少ない家庭から順に、自動で組んだ案です。緑が新しく入った人。よければ表をコピーし（名前ボックスで「自動案の表」を選ぶと全体を選べます）、「調整・決定」の表の左上に［値の貼り付け］をします。
C3: 新しく入った人 | D3: 後ろを空ける枠 | E3: なるべく空ける日・休憩 | F3: 先生の都合で使えない
C5: ='設定'!$E$11 | D5: ='設定'!$E$12 | E5: ='設定'!$E$13 | F5: ='設定'!$E$14 | G5: ='設定'!$E$15 | H5: ='設定'!$E$16 | I5: ='設定'!$E$17 | J5: ='設定'!$E$18 | K5: ='設定'!$E$19 | L5: ='設定'!$E$20 | N5: 決定済み（調整・決定シート） | O5: =SUMPRODUCT(('調整・決定'!$C$6:$L$29<>"")*1)&" 人"
B6: ='設定'!$I$11 | C6: =IF('計算A'!D$4=0,"",IF('調整・決定'!C6<>"",'調整・決定'!C6,IFERROR(INDEX('名簿'!$G$5:$G$49,INDEX('計算B'!$B$3:$B$47,MATCH(1,'計算B'!$C$3:$C$47,0))),""))) | D6: =IF('計算A'!AB$4=0,"",IF('調整・決定'!D6<>"",'調整・決定'!D6,IFERROR(INDEX('名簿'!$G$5:$G$49,INDEX('計算B'!$B$3:$B$47,MATCH(25,'計算B'!$C$3:$C$47,0))),""))) | E6: =IF('計算A'!AZ$4=0,"",IF('調整・決定'!E6<>"",'調整・決定'!E6,IFERROR(INDEX('名簿'!$G$5:$G$49,INDEX('計算B'!$B$3:$B$47,MATCH(49,'計算B'!$C$3:$C$47,0))),""))) | F6: =IF('計算A'!BX$4=0,"",IF('調整・決定'!F6<>"",'調整・決定'!F6,IFERROR(INDEX('名簿'!$G$5:$G$49,INDEX('計算B'!$B$3:$B$47,MATCH(73,'計算B'!$C$3:$C$47,0))),""))) | G6: =IF('計算A'!CV$4=0,"",IF('調整・決定'!G6<>"",'調整・決定'!G6,IFERROR(INDEX('名簿'!$G$5:$G$49,INDEX('計算B'!$B$3:$B$47,MATCH(97,'計算B'!$C$3:$C$47,0))),""))) | H6: =IF('計算A'!DT$4=0,"",IF('調整・決定'!H6<>"",'調整・決定'!H6,IFERROR(INDEX('名簿'!$G$5:$G$49,INDEX('計算B'!$B$3:$B$47,MATCH(121,'計算B'!$C$3:$C$47,0))),""))) | I6: =IF('計算A'!ER$4=0,"",IF('調整・決定'!I6<>"",'調整・決定'!I6,IFERROR(INDEX('名簿'!$G$5:$G$49,INDEX('計算B'!$B$3:$B$47,MATCH(145,'計算B'!$C$3:$C$47,0))),""))) | J6: =IF('計算A'!FP$4=0,"",IF('調整・決定'!J6<>"",'調整・決定'!J6,IFERROR(INDEX('名簿'!$G$5:$G$49,INDEX('計算B'!$B$3:$B$47,MATCH(169,'計算B'!$C$3:$C$47,0))),""))) | K6: =IF('計算A'!GN$4=0,"",IF('調整・決定'!K6<>"",'調整・決定'!K6,IFERROR(INDEX('名簿'!$G$5:$G$49,INDEX('計算B'!$B$3:$B$47,MATCH(193,'計算B'!$C$3:$C$47,0))),""))) | L6: =IF('計算A'!HL$4=0,"",IF('調整・決定'!L6<>"",'調整・決定'!L6,IFERROR(INDEX('名簿'!$G$5:$G$49,INDEX('計算B'!$B$3:$B$47,MATCH(217,'計算B'!$C$3:$C$47,0))),""))) | N6: 自動で新しく入った | O6: =SUMPRODUCT(('計算B'!$B$3:$B$47>0)*('計算B'!$C$3:$C$47>0))&" 人"
B7: ='設定'!$I$12 | C7: =IF('計算A'!E$4=0,"",IF('調整・決定'!C7<>"",'調整・決定'!C7,IFERROR(INDEX('名簿'!$G$5:$G$49,INDEX('計算B'!$B$3:$B$47,MATCH(2,'計算B'!$C$3:$C$47,0))),""))) | D7: =IF('計算A'!AC$4=0,"",IF('調整・決定'!D7<>"",'調整・決定'!D7,IFERROR(INDEX('名簿'!$G$5:$G$49,INDEX('計算B'!$B$3:$B$47,MATCH(26,'計算B'!$C$3:$C$47,0))),""))) | E7: =IF('計算A'!BA$4=0,"",IF('調整・決定'!E7<>"",'調整・決定'!E7,IFERROR(INDEX('名簿'!$G$5:$G$49,INDEX('計算B'!$B$3:$B$47,MATCH(50,'計算B'!$C$3:$C$47,0))),""))) | F7: =IF('計算A'!BY$4=0,"",IF('調整・決定'!F7<>"",'調整・決定'!F7,IFERROR(INDEX('名簿'!$G$5:$G$49,INDEX('計算B'!$B$3:$B$47,MATCH(74,'計算B'!$C$3:$C$47,0))),""))) | G7: =IF('計算A'!CW$4=0,"",IF('調整・決定'!G7<>"",'調整・決定'!G7,IFERROR(INDEX('名簿'!$G$5:$G$49,INDEX('計算B'!$B$3:$B$47,MATCH(98,'計算B'!$C$3:$C$47,0))),""))) | H7: =IF('計算A'!DU$4=0,"",IF('調整・決定'!H7<>"",'調整・決定'!H7,IFERROR(INDEX('名簿'!$G$5:$G$49,INDEX('計算B'!$B$3:$B$47,MATCH(122,'計算B'!$C$3:$C$47,0))),""))) | I7: =IF('計算A'!ES$4=0,"",IF('調整・決定'!I7<>"",'調整・決定'!I7,IFERROR(INDEX('名簿'!$G$5:$G$49,INDEX('計算B'!$B$3:$B$47,MATCH(146,'計算B'!$C$3:$C$47,0))),""))) | J7: =IF('計算A'!FQ$4=0,"",IF('調整・決定'!J7<>"",'調整・決定'!J7,IFERROR(INDEX('名簿'!$G$5:$G$49,INDEX('計算B'!$B$3:$B$47,MATCH(170,'計算B'!$C$3:$C$47,0))),""))) | K7: =IF('計算A'!GO$4=0,"",IF('調整・決定'!K7<>"",'調整・決定'!K7,IFERROR(INDEX('名簿'!$G$5:$G$49,INDEX('計算B'!$B$3:$B$47,MATCH(194,'計算B'!$C$3:$C$47,0))),""))) | L7: =IF('計算A'!HM$4=0,"",IF('調整・決定'!L7<>"",'調整・決定'!L7,IFERROR(INDEX('名簿'!$G$5:$G$49,INDEX('計算B'!$B$3:$B$47,MATCH(218,'計算B'!$C$3:$C$47,0))),"")))
B8: ='設定'!$I$13 | C8: =IF('計算A'!F$4=0,"",IF('調整・決定'!C8<>"",'調整・決定'!C8,IFERROR(INDEX('名簿'!$G$5:$G$49,INDEX('計算B'!$B$3:$B$47,MATCH(3,'計算B'!$C$3:$C$47,0))),""))) | D8: =IF('計算A'!AD$4=0,"",IF('調整・決定'!D8<>"",'調整・決定'!D8,IFERROR(INDEX('名簿'!$G$5:$G$49,INDEX('計算B'!$B$3:$B$47,MATCH(27,'計算B'!$C$3:$C$47,0))),""))) | E8: =IF('計算A'!BB$4=0,"",IF('調整・決定'!E8<>"",'調整・決定'!E8,IFERROR(INDEX('名簿'!$G$5:$G$49,INDEX('計算B'!$B$3:$B$47,MATCH(51,'計算B'!$C$3:$C$47,0))),""))) | F8: =IF('計算A'!BZ$4=0,"",IF('調整・決定'!F8<>"",'調整・決定'!F8,IFERROR(INDEX('名簿'!$G$5:$G$49,INDEX('計算B'!$B$3:$B$47,MATCH(75,'計算B'!$C$3:$C$47,0))),""))) | G8: =IF('計算A'!CX$4=0,"",IF('調整・決定'!G8<>"",'調整・決定'!G8,IFERROR(INDEX('名簿'!$G$5:$G$49,INDEX('計算B'!$B$3:$B$47,MATCH(99,'計算B'!$C$3:$C$47,0))),""))) | H8: =IF('計算A'!DV$4=0,"",IF('調整・決定'!H8<>"",'調整・決定'!H8,IFERROR(INDEX('名簿'!$G$5:$G$49,INDEX('計算B'!$B$3:$B$47,MATCH(123,'計算B'!$C$3:$C$47,0))),""))) | I8: =IF('計算A'!ET$4=0,"",IF('調整・決定'!I8<>"",'調整・決定'!I8,IFERROR(INDEX('名簿'!$G$5:$G$49,INDEX('計算B'!$B$3:$B$47,MATCH(147,'計算B'!$C$3:$C$47,0))),""))) | J8: =IF('計算A'!FR$4=0,"",IF('調整・決定'!J8<>"",'調整・決定'!J8,IFERROR(INDEX('名簿'!$G$5:$G$49,INDEX('計算B'!$B$3:$B$47,MATCH(171,'計算B'!$C$3:$C$47,0))),""))) | K8: =IF('計算A'!GP$4=0,"",IF('調整・決定'!K8<>"",'調整・決定'!K8,IFERROR(INDEX('名簿'!$G$5:$G$49,INDEX('計算B'!$B$3:$B$47,MATCH(195,'計算B'!$C$3:$C$47,0))),""))) | L8: =IF('計算A'!HN$4=0,"",IF('調整・決定'!L8<>"",'調整・決定'!L8,IFERROR(INDEX('名簿'!$G$5:$G$49,INDEX('計算B'!$B$3:$B$47,MATCH(219,'計算B'!$C$3:$C$47,0))),""))) | N8: 入る枠がない（×・必ず空けたい） | O8: {=_xlfn.TEXTJOIN("、",TRUE,IF('計算A'!$IL$10:$IL$54=1,'計算A'!$B$10:$B$54,""))}
B9: ='設定'!$I$14 | C9: =IF('計算A'!G$4=0,"",IF('調整・決定'!C9<>"",'調整・決定'!C9,IFERROR(INDEX('名簿'!$G$5:$G$49,INDEX('計算B'!$B$3:$B$47,MATCH(4,'計算B'!$C$3:$C$47,0))),""))) | D9: =IF('計算A'!AE$4=0,"",IF('調整・決定'!D9<>"",'調整・決定'!D9,IFERROR(INDEX('名簿'!$G$5:$G$49,INDEX('計算B'!$B$3:$B$47,MATCH(28,'計算B'!$C$3:$C$47,0))),""))) | E9: =IF('計算A'!BC$4=0,"",IF('調整・決定'!E9<>"",'調整・決定'!E9,IFERROR(INDEX('名簿'!$G$5:$G$49,INDEX('計算B'!$B$3:$B$47,MATCH(52,'計算B'!$C$3:$C$47,0))),""))) | F9: =IF('計算A'!CA$4=0,"",IF('調整・決定'!F9<>"",'調整・決定'!F9,IFERROR(INDEX('名簿'!$G$5:$G$49,INDEX('計算B'!$B$3:$B$47,MATCH(76,'計算B'!$C$3:$C$47,0))),""))) | G9: =IF('計算A'!CY$4=0,"",IF('調整・決定'!G9<>"",'調整・決定'!G9,IFERROR(INDEX('名簿'!$G$5:$G$49,INDEX('計算B'!$B$3:$B$47,MATCH(100,'計算B'!$C$3:$C$47,0))),""))) | H9: =IF('計算A'!DW$4=0,"",IF('調整・決定'!H9<>"",'調整・決定'!H9,IFERROR(INDEX('名簿'!$G$5:$G$49,INDEX('計算B'!$B$3:$B$47,MATCH(124,'計算B'!$C$3:$C$47,0))),""))) | I9: =IF('計算A'!EU$4=0,"",IF('調整・決定'!I9<>"",'調整・決定'!I9,IFERROR(INDEX('名簿'!$G$5:$G$49,INDEX('計算B'!$B$3:$B$47,MATCH(148,'計算B'!$C$3:$C$47,0))),""))) | J9: =IF('計算A'!FS$4=0,"",IF('調整・決定'!J9<>"",'調整・決定'!J9,IFERROR(INDEX('名簿'!$G$5:$G$49,INDEX('計算B'!$B$3:$B$47,MATCH(172,'計算B'!$C$3:$C$47,0))),""))) | K9: =IF('計算A'!GQ$4=0,"",IF('調整・決定'!K9<>"",'調整・決定'!K9,IFERROR(INDEX('名簿'!$G$5:$G$49,INDEX('計算B'!$B$3:$B$47,MATCH(196,'計算B'!$C$3:$C$47,0))),""))) | L9: =IF('計算A'!HO$4=0,"",IF('調整・決定'!L9<>"",'調整・決定'!L9,IFERROR(INDEX('名簿'!$G$5:$G$49,INDEX('計算B'!$B$3:$B$47,MATCH(220,'計算B'!$C$3:$C$47,0))),"")))
B10: ='設定'!$I$15 | C10: =IF('計算A'!H$4=0,"",IF('調整・決定'!C10<>"",'調整・決定'!C10,IFERROR(INDEX('名簿'!$G$5:$G$49,INDEX('計算B'!$B$3:$B$47,MATCH(5,'計算B'!$C$3:$C$47,0))),""))) | D10: =IF('計算A'!AF$4=0,"",IF('調整・決定'!D10<>"",'調整・決定'!D10,IFERROR(INDEX('名簿'!$G$5:$G$49,INDEX('計算B'!$B$3:$B$47,MATCH(29,'計算B'!$C$3:$C$47,0))),""))) | E10: =IF('計算A'!BD$4=0,"",IF('調整・決定'!E10<>"",'調整・決定'!E10,IFERROR(INDEX('名簿'!$G$5:$G$49,INDEX('計算B'!$B$3:$B$47,MATCH(53,'計算B'!$C$3:$C$47,0))),""))) | F10: =IF('計算A'!CB$4=0,"",IF('調整・決定'!F10<>"",'調整・決定'!F10,IFERROR(INDEX('名簿'!$G$5:$G$49,INDEX('計算B'!$B$3:$B$47,MATCH(77,'計算B'!$C$3:$C$47,0))),""))) | G10: =IF('計算A'!CZ$4=0,"",IF('調整・決定'!G10<>"",'調整・決定'!G10,IFERROR(INDEX('名簿'!$G$5:$G$49,INDEX('計算B'!$B$3:$B$47,MATCH(101,'計算B'!$C$3:$C$47,0))),""))) | H10: =IF('計算A'!DX$4=0,"",IF('調整・決定'!H10<>"",'調整・決定'!H10,IFERROR(INDEX('名簿'!$G$5:$G$49,INDEX('計算B'!$B$3:$B$47,MATCH(125,'計算B'!$C$3:$C$47,0))),""))) | I10: =IF('計算A'!EV$4=0,"",IF('調整・決定'!I10<>"",'調整・決定'!I10,IFERROR(INDEX('名簿'!$G$5:$G$49,INDEX('計算B'!$B$3:$B$47,MATCH(149,'計算B'!$C$3:$C$47,0))),""))) | J10: =IF('計算A'!FT$4=0,"",IF('調整・決定'!J10<>"",'調整・決定'!J10,IFERROR(INDEX('名簿'!$G$5:$G$49,INDEX('計算B'!$B$3:$B$47,MATCH(173,'計算B'!$C$3:$C$47,0))),""))) | K10: =IF('計算A'!GR$4=0,"",IF('調整・決定'!K10<>"",'調整・決定'!K10,IFERROR(INDEX('名簿'!$G$5:$G$49,INDEX('計算B'!$B$3:$B$47,MATCH(197,'計算B'!$C$3:$C$47,0))),""))) | L10: =IF('計算A'!HP$4=0,"",IF('調整・決定'!L10<>"",'調整・決定'!L10,IFERROR(INDEX('名簿'!$G$5:$G$49,INDEX('計算B'!$B$3:$B$47,MATCH(221,'計算B'!$C$3:$C$47,0))),""))) | N10: 未入力・未提出で外した | O10: {=_xlfn.TEXTJOIN("、",TRUE,IF((('名簿'!$H$5:$H$49="未入力")+('名簿'!$H$5:$H$49="未提出"))*('計算A'!$IO$10:$IO$54=0),'名簿'!$G$5:$G$49,""))}
B11: ='設定'!$I$16 | C11: =IF('計算A'!I$4=0,"",IF('調整・決定'!C11<>"",'調整・決定'!C11,IFERROR(INDEX('名簿'!$G$5:$G$49,INDEX('計算B'!$B$3:$B$47,MATCH(6,'計算B'!$C$3:$C$47,0))),""))) | D11: =IF('計算A'!AG$4=0,"",IF('調整・決定'!D11<>"",'調整・決定'!D11,IFERROR(INDEX('名簿'!$G$5:$G$49,INDEX('計算B'!$B$3:$B$47,MATCH(30,'計算B'!$C$3:$C$47,0))),""))) | E11: =IF('計算A'!BE$4=0,"",IF('調整・決定'!E11<>"",'調整・決定'!E11,IFERROR(INDEX('名簿'!$G$5:$G$49,INDEX('計算B'!$B$3:$B$47,MATCH(54,'計算B'!$C$3:$C$47,0))),""))) | F11: =IF('計算A'!CC$4=0,"",IF('調整・決定'!F11<>"",'調整・決定'!F11,IFERROR(INDEX('名簿'!$G$5:$G$49,INDEX('計算B'!$B$3:$B$47,MATCH(78,'計算B'!$C$3:$C$47,0))),""))) | G11: =IF('計算A'!DA$4=0,"",IF('調整・決定'!G11<>"",'調整・決定'!G11,IFERROR(INDEX('名簿'!$G$5:$G$49,INDEX('計算B'!$B$3:$B$47,MATCH(102,'計算B'!$C$3:$C$47,0))),""))) | H11: =IF('計算A'!DY$4=0,"",IF('調整・決定'!H11<>"",'調整・決定'!H11,IFERROR(INDEX('名簿'!$G$5:$G$49,INDEX('計算B'!$B$3:$B$47,MATCH(126,'計算B'!$C$3:$C$47,0))),""))) | I11: =IF('計算A'!EW$4=0,"",IF('調整・決定'!I11<>"",'調整・決定'!I11,IFERROR(INDEX('名簿'!$G$5:$G$49,INDEX('計算B'!$B$3:$B$47,MATCH(150,'計算B'!$C$3:$C$47,0))),""))) | J11: =IF('計算A'!FU$4=0,"",IF('調整・決定'!J11<>"",'調整・決定'!J11,IFERROR(INDEX('名簿'!$G$5:$G$49,INDEX('計算B'!$B$3:$B$47,MATCH(174,'計算B'!$C$3:$C$47,0))),""))) | K11: =IF('計算A'!GS$4=0,"",IF('調整・決定'!K11<>"",'調整・決定'!K11,IFERROR(INDEX('名簿'!$G$5:$G$49,INDEX('計算B'!$B$3:$B$47,MATCH(198,'計算B'!$C$3:$C$47,0))),""))) | L11: =IF('計算A'!HQ$4=0,"",IF('調整・決定'!L11<>"",'調整・決定'!L11,IFERROR(INDEX('名簿'!$G$5:$G$49,INDEX('計算B'!$B$3:$B$47,MATCH(222,'計算B'!$C$3:$C$47,0))),"")))
B12: ='設定'!$I$17 | C12: =IF('計算A'!J$4=0,"",IF('調整・決定'!C12<>"",'調整・決定'!C12,IFERROR(INDEX('名簿'!$G$5:$G$49,INDEX('計算B'!$B$3:$B$47,MATCH(7,'計算B'!$C$3:$C$47,0))),""))) | D12: =IF('計算A'!AH$4=0,"",IF('調整・決定'!D12<>"",'調整・決定'!D12,IFERROR(INDEX('名簿'!$G$5:$G$49,INDEX('計算B'!$B$3:$B$47,MATCH(31,'計算B'!$C$3:$C$47,0))),""))) | E12: =IF('計算A'!BF$4=0,"",IF('調整・決定'!E12<>"",'調整・決定'!E12,IFERROR(INDEX('名簿'!$G$5:$G$49,INDEX('計算B'!$B$3:$B$47,MATCH(55,'計算B'!$C$3:$C$47,0))),""))) | F12: =IF('計算A'!CD$4=0,"",IF('調整・決定'!F12<>"",'調整・決定'!F12,IFERROR(INDEX('名簿'!$G$5:$G$49,INDEX('計算B'!$B$3:$B$47,MATCH(79,'計算B'!$C$3:$C$47,0))),""))) | G12: =IF('計算A'!DB$4=0,"",IF('調整・決定'!G12<>"",'調整・決定'!G12,IFERROR(INDEX('名簿'!$G$5:$G$49,INDEX('計算B'!$B$3:$B$47,MATCH(103,'計算B'!$C$3:$C$47,0))),""))) | H12: =IF('計算A'!DZ$4=0,"",IF('調整・決定'!H12<>"",'調整・決定'!H12,IFERROR(INDEX('名簿'!$G$5:$G$49,INDEX('計算B'!$B$3:$B$47,MATCH(127,'計算B'!$C$3:$C$47,0))),""))) | I12: =IF('計算A'!EX$4=0,"",IF('調整・決定'!I12<>"",'調整・決定'!I12,IFERROR(INDEX('名簿'!$G$5:$G$49,INDEX('計算B'!$B$3:$B$47,MATCH(151,'計算B'!$C$3:$C$47,0))),""))) | J12: =IF('計算A'!FV$4=0,"",IF('調整・決定'!J12<>"",'調整・決定'!J12,IFERROR(INDEX('名簿'!$G$5:$G$49,INDEX('計算B'!$B$3:$B$47,MATCH(175,'計算B'!$C$3:$C$47,0))),""))) | K12: =IF('計算A'!GT$4=0,"",IF('調整・決定'!K12<>"",'調整・決定'!K12,IFERROR(INDEX('名簿'!$G$5:$G$49,INDEX('計算B'!$B$3:$B$47,MATCH(199,'計算B'!$C$3:$C$47,0))),""))) | L12: =IF('計算A'!HR$4=0,"",IF('調整・決定'!L12<>"",'調整・決定'!L12,IFERROR(INDEX('名簿'!$G$5:$G$49,INDEX('計算B'!$B$3:$B$47,MATCH(223,'計算B'!$C$3:$C$47,0))),""))) | N12: なるべく空けたい枠を使った | O12: =SUM('計算B'!$D$3:$D$47)&" 枠"
