Workbook
Name 自動案Aの表: '自動案A'!$C$6:$H$29
Name 自動案Bの表: '自動案B'!$C$6:$H$29
Name 決定の表: '調整・決定'!$C$6:$H$29

Sheet ホーム
A1: 面談日程ツール | K1: Ver.2.3
A2: ×のついた予定表から、個人面談の日程を組むツールです（マクロなし）。黄色のマスが入力する場所です。
B4: いまの状況
B5: 名簿の人数 | D5: ×入力済み | F5: 未入力 | H5: 未提出 | J5: 決定済み | L5: 未決定
B6: =COUNTIF('名簿'!$B$5:$B$49,"?*") | D6: =COUNTIF('名簿'!$Q$5:$Q$49,"入力済み")+COUNTIF('名簿'!$Q$5:$Q$49,"×なし") | F6: =COUNTIF('名簿'!$Q$5:$Q$49,"未入力") | H6: =COUNTIF('名簿'!$Q$5:$Q$49,"未提出") | J6: =SUMPRODUCT(('名簿'!$U$5:$U$49<>"")*1) | L6: =COUNTIF('名簿'!$W$5:$W$49,"未決定")
B8: 使う順番
B9: 1 | C9: 日付と時間枠を決める | K9: =HYPERLINK("#'設定'!A1","開く ▶")
C10: 面談する日付、時間帯（2つまで）、1枠の長さ。出張などで組まない日・時間もここで止めます。
B12: 2 | C12: 名簿を貼り付ける | K12: =HYPERLINK("#'名簿'!A1","開く ▶")
C13: 番号と名前を貼り付けます。兄弟・希望の時間・後ろを空けるもここで選びます。
B15: 3 | C15: ×を入力する | K15: =HYPERLINK("#'×入力'!A1","開く ▶")
C16: 予定表と同じ形の表に「×」。日付の上・時刻の左の欄で、1日全部・その時間全部も一度に×にできます。
B18: 4 | C18: 自動案を見る（A：詰める／B：散らす） | K18: =HYPERLINK("#'自動案A'!A1","案A ▶") | L18: =HYPERLINK("#'自動案B'!A1","案B ▶")
C19: 集まった分で作るときは、自動案Aのシートの右上を「自動案を出す」に。入れられる枠が少ない家庭から順に組んだ案が2つ出ます。よいほうを調整・決定に貼り付けます。
B21: 5 | C21: 調整して決定する | K21: =HYPERLINK("#'調整・決定'!A1","開く ▶")
C22: プルダウンで手直しして日程を決めます。児童を選ぶと、入れられる枠に色がつきます。
B24: 6 | C24: 印刷して兄弟を確認する | K24: =HYPERLINK("#'兄弟確認用'!A1","開く ▶")
C25: 決めた日程を予定表の形で印刷。兄弟がいる子は色付きで、兄弟のクラスも出ます。
B27: 7 | C27: お手紙を印刷する | K27: =HYPERLINK("#'お手紙（夏）'!A1","夏 ▶") | L27: =HYPERLINK("#'お手紙（秋）'!A1","秋 ▶")
C28: 保護者へのお知らせ（夏用・秋用）。宛名・日付・学校名・担任名・本文は設定で決めます。6年は「進路面談」になります。
B32: くわしい使い方
B33: 1. 「設定」シート
B34: ・面談の日付（上から順に、最大6日）、時間帯（午前と午後に分けるときは2つ）と1枠の長さを入れます（1日最大24枠）。
B35: ・空けたい日や休憩の時刻には「〇」を選びます。自動案では、ほかに入る枠がないときだけ使われます。
B36: ・出張や会議などで面談を組まない日・時間・枠は、右の「先生の都合で使えない枠」で「×」を選びます。止めた枠は、×入力・自動案・調整・決定で灰色になり、使われません。
B37: 2. 「名簿」シート
B38: ・Excelの名簿から「出席番号」と「名前」をコピーして、「番号」の列のいちばん上のマスに貼り付けます（最大45人）。
B39: ・他のクラスに兄弟がいる家庭は、「兄弟」の列で「〇」を選び、「兄弟メモ」に兄弟のクラスなどをメモします。
B40: ・「希望」：早い時刻／遅い時刻／早い日／遅い日 から選べます。自動案で、×のない枠の中からできるだけ希望に合う枠を選びます（希望なので、合わないこともあります）。
B41: ・「後ろを空ける」：話が長引きそうな家庭は、同じ日のすぐ次の枠を空けます。「必ず空けたい」「出来れば空けたい」から選びます（出来れば空けたいは、空けられないときは詰めて入れます）。日の最後の枠なら空ける必要はありません。
B42: ・名簿の行は並べ替えないでください（×入力の内容とずれてしまいます）。絞り込み（フィルター）は使えます。
B43: ・自動案や調整・決定には名前だけが出ます。同じ名前の児童がいるときだけ、「番号 名前」で区別して表示します。
... B73: ※ 「計算A」「計算B」「計算C」は計算用の隠しシートです。さわらないでください。

Sheet 設定
A1: 設定 | E1: =HYPERLINK("#'ホーム'!A1","ホーム") | F1: =HYPERLINK("#'設定'!A1","① 設定") | H1: =HYPERLINK("#'名簿'!A1","② 名簿") | I1: =HYPERLINK("#'×入力'!A1","③ ×入力") | K1: =HYPERLINK("#'自動案A'!A1","④ 自動案A") | M1: =HYPERLINK("#'自動案B'!A1","④ 自動案B") | N1: =HYPERLINK("#'調整・決定'!A1","⑤ 調整・決定") | O1: =HYPERLINK("#'兄弟確認用'!A1","⑥ 兄弟確認") | P1: =HYPERLINK("#'お手紙（夏）'!A1","⑦ お手紙 夏") | Q1: =HYPERLINK("#'お手紙（秋）'!A1","⑧ お手紙 秋")
A2: 面談の日付と時間枠を決めます。黄色のマスを入力してください。
A3: 時間帯1 | B3: 0.5625 | C3: 〜 | D3: 0.64583333 | E3: =IF(OR(NOT(ISNUMBER(B3)),NOT(ISNUMBER(D3))),"← 始まりと終わりの時刻を入れてください",IF(D3<B3,"← 終わりは始まりより後の時刻にしてください",""))
A4: 時間帯2（なければ空欄） | C4: 〜 | E4: =IF(AND(B4="",D4=""),"",IF(OR(NOT(ISNUMBER(B4)),NOT(ISNUMBER(D4))),"← 始まりと終わりの両方を入れてください",IF(D4<B4,"← 終わりは始まりより後の時刻にしてください",IF(AND(ISNUMBER(D3),B4<=D3),"← 時間帯1より後の時刻にしてください",""))))
A5: 1枠の長さ（分） | B5: 15 | E5: =IF(AND(ISNUMBER(B5),B5>0),"","← 5〜120の数字を入れてください")
A6: 1日の枠の数 | B6: =MIN(24,'計算A'!$A$3+'計算A'!$A$4) | D6: （最大24枠） | E6: =IF('計算A'!$A$3+'計算A'!$A$4>24,"← 枠が24をこえています。こえた分は使いません","")
K7: 先生の都合で使えない枠（出張・会議など）
A8: 自動案の詰め方 | B8: 早い時間から（各日の最後を空ける） | K8: 「×」を選んだ日・時間・枠は、自動案にも調整・決定にも使いません。
K9: この日は組まない ▶
B10: 日付 | C10: 曜日 | D10: なるべく空ける | E10: 表示 | G10: 時刻 | H10: 休憩（なるべく空ける） | I10: 表示 | K10: この時間は 組まない ▼ | M10: ='設定'!$E$11 | N10: ='設定'!$E$12 | O10: ='設定'!$E$13 | P10: ='設定'!$E$14 | Q10: ='設定'!$E$15 | R10: ='設定'!$E$16
A11: 1日目 | B11: 46350 | C11: =IF(B11="","",CHOOSE(WEEKDAY(B11),"日","月","火","水","木","金","土")) | E11: =IF(B11="","",MONTH(B11)&"月"&DAY(B11)&"日（"&C11&"）") | F11: 1 | G11: =IF(F11<=MIN('計算A'!$A$3,24),$B$3+(F11-1)*$B$5/1440,IF(F11<=$B$6,$B$4+(F11-'計算A'!$A$3-1)*$B$5/1440,"")) | I11: =IF(G11="","",TEXT(G11,"h:mm")&"〜") | L11: =$I$11
A12: 2日目 | B12: 46351 | C12: =IF(B12="","",CHOOSE(WEEKDAY(B12),"日","月","火","水","木","金","土")) | E12: =IF(B12="","",MONTH(B12)&"月"&DAY(B12)&"日（"&C12&"）") | F12: 2 | G12: =IF(F12<=MIN('計算A'!$A$3,24),$B$3+(F12-1)*$B$5/1440,IF(F12<=$B$6,$B$4+(F12-'計算A'!$A$3-1)*$B$5/1440,"")) | I12: =IF(G12="","",TEXT(G12,"h:mm")&"〜") | L12: =$I$12
A13: 3日目 | B13: 46352 | C13: =IF(B13="","",CHOOSE(WEEKDAY(B13),"日","月","火","水","木","金","土")) | E13: =IF(B13="","",MONTH(B13)&"月"&DAY(B13)&"日（"&C13&"）") | F13: 3 | G13: =IF(F13<=MIN('計算A'!$A$3,24),$B$3+(F13-1)*$B$5/1440,IF(F13<=$B$6,$B$4+(F13-'計算A'!$A$3-1)*$B$5/1440,"")) | I13: =IF(G13="","",TEXT(G13,"h:mm")&"〜") | L13: =$I$13
A14: 4日目 | B14: 46353 | C14: =IF(B14="","",CHOOSE(WEEKDAY(B14),"日","月","火","水","木","金","土")) | E14: =IF(B14="","",MONTH(B14)&"月"&DAY(B14)&"日（"&C14&"）") | F14: 4 | G14: =IF(F14<=MIN('計算A'!$A$3,24),$B$3+(F14-1)*$B$5/1440,IF(F14<=$B$6,$B$4+(F14-'計算A'!$A$3-1)*$B$5/1440,"")) | I14: =IF(G14="","",TEXT(G14,"h:mm")&"〜") | L14: =$I$14
A15: 5日目 | B15: 46356 | C15: =IF(B15="","",CHOOSE(WEEKDAY(B15),"日","月","火","水","木","金","土")) | E15: =IF(B15="","",MONTH(B15)&"月"&DAY(B15)&"日（"&C15&"）") | F15: 5 | G15: =IF(F15<=MIN('計算A'!$A$3,24),$B$3+(F15-1)*$B$5/1440,IF(F15<=$B$6,$B$4+(F15-'計算A'!$A$3-1)*$B$5/1440,"")) | I15: =IF(G15="","",TEXT(G15,"h:mm")&"〜") | L15: =$I$15
A16: 6日目 | C16: =IF(B16="","",CHOOSE(WEEKDAY(B16),"日","月","火","水","木","金","土")) | E16: =IF(B16="","",MONTH(B16)&"月"&DAY(B16)&"日（"&C16&"）") | F16: 6 | G16: =IF(F16<=MIN('計算A'!$A$3,24),$B$3+(F16-1)*$B$5/1440,IF(F16<=$B$6,$B$4+(F16-'計算A'!$A$3-1)*$B$5/1440,"")) | I16: =IF(G16="","",TEXT(G16,"h:mm")&"〜") | L16: =$I$16
F17: 7 | G17: =IF(F17<=MIN('計算A'!$A$3,24),$B$3+(F17-1)*$B$5/1440,IF(F17<=$B$6,$B$4+(F17-'計算A'!$A$3-1)*$B$5/1440,"")) | I17: =IF(G17="","",TEXT(G17,"h:mm")&"〜") | L17: =$I$17
F18: 8 | G18: =IF(F18<=MIN('計算A'!$A$3,24),$B$3+(F18-1)*$B$5/1440,IF(F18<=$B$6,$B$4+(F18-'計算A'!$A$3-1)*$B$5/1440,"")) | I18: =IF(G18="","",TEXT(G18,"h:mm")&"〜") | L18: =$I$18
F19: 9 | G19: =IF(F19<=MIN('計算A'!$A$3,24),$B$3+(F19-1)*$B$5/1440,IF(F19<=$B$6,$B$4+(F19-'計算A'!$A$3-1)*$B$5/1440,"")) | I19: =IF(G19="","",TEXT(G19,"h:mm")&"〜") | L19: =$I$19
F20: 10 | G20: =IF(F20<=MIN('計算A'!$A$3,24),$B$3+(F20-1)*$B$5/1440,IF(F20<=$B$6,$B$4+(F20-'計算A'!$A$3-1)*$B$5/1440,"")) | I20: =IF(G20="","",TEXT(G20,"h:mm")&"〜") | L20: =$I$20
F21: 11 | G21: =IF(F21<=MIN('計算A'!$A$3,24),$B$3+(F21-1)*$B$5/1440,IF(F21<=$B$6,$B$4+(F21-'計算A'!$A$3-1)*$B$5/1440,"")) | I21: =IF(G21="","",TEXT(G21,"h:mm")&"〜") | L21: =$I$21
A22: ※ 日付は上から詰めて入れてください。曜日・表示・時刻は自動で出ます。午前と午後に分けるときは、時間帯2も入れます（昼休みは表に出ません）。 | F22: 12 | G22: =IF(F22<=MIN('計算A'!$A$3,24),$B$3+(F22-1)*$B$5/1440,IF(F22<=$B$6,$B$4+(F22-'計算A'!$A$3-1)*$B$5/1440,"")) | I22: =IF(G22="","",TEXT(G22,"h:mm")&"〜") | L22: =$I$22
F23: 13 | G23: =IF(F23<=MIN('計算A'!$A$3,24),$B$3+(F23-1)*$B$5/1440,IF(F23<=$B$6,$B$4+(F23-'計算A'!$A$3-1)*$B$5/1440,"")) | I23: =IF(G23="","",TEXT(G23,"h:mm")&"〜") | L23: =$I$23
F24: 14 | G24: =IF(F24<=MIN('計算A'!$A$3,24),$B$3+(F24-1)*$B$5/1440,IF(F24<=$B$6,$B$4+(F24-'計算A'!$A$3-1)*$B$5/1440,"")) | I24: =IF(G24="","",TEXT(G24,"h:mm")&"〜") | L24: =$I$24
A25: ※「なるべく空ける」「休憩」は、ほかに入る枠がないときだけ使います。必ず使わない枠は、右の「先生の都合で使えない枠」で止めてください。 | F25: 15 | G25: =IF(F25<=MIN('計算A'!$A$3,24),$B$3+(F25-1)*$B$5/1440,IF(F25<=$B$6,$B$4+(F25-'計算A'!$A$3-1)*$B$5/1440,"")) | I25: =IF(G25="","",TEXT(G25,"h:mm")&"〜") | L25: =$I$25
F26: 16 | G26: =IF(F26<=MIN('計算A'!$A$3,24),$B$3+(F26-1)*$B$5/1440,IF(F26<=$B$6,$B$4+(F26-'計算A'!$A$3-1)*$B$5/1440,"")) | I26: =IF(G26="","",TEXT(G26,"h:mm")&"〜") | L26: =$I$26
F27: 17 | G27: =IF(F27<=MIN('計算A'!$A$3,24),$B$3+(F27-1)*$B$5/1440,IF(F27<=$B$6,$B$4+(F27-'計算A'!$A$3-1)*$B$5/1440,"")) | I27: =IF(G27="","",TEXT(G27,"h:mm")&"〜") | L27: =$I$27
F28: 18 | G28: =IF(F28<=MIN('計算A'!$A$3,24),$B$3+(F28-1)*$B$5/1440,IF(F28<=$B$6,$B$4+(F28-'計算A'!$A$3-1)*$B$5/1440,"")) | I28: =IF(G28="","",TEXT(G28,"h:mm")&"〜") | L28: =$I$28
F29: 19 | G29: =IF(F29<=MIN('計算A'!$A$3,24),$B$3+(F29-1)*$B$5/1440,IF(F29<=$B$6,$B$4+(F29-'計算A'!$A$3-1)*$B$5/1440,"")) | I29: =IF(G29="","",TEXT(G29,"h:mm")&"〜") | L29: =$I$29
A30: お手紙（お知らせ） | B30: 「お手紙（夏）」「お手紙（秋）」シートに出ます。 | F30: 20 | G30: =IF(F30<=MIN('計算A'!$A$3,24),$B$3+(F30-1)*$B$5/1440,IF(F30<=$B$6,$B$4+(F30-'計算A'!$A$3-1)*$B$5/1440,"")) | I30: =IF(G30="","",TEXT(G30,"h:mm")&"〜") | L30: =$I$30
A31: 学年 | B31: 6 | C31: =IF(B36="学年に合わせる（6年は進路面談）","→ "&IF(B31=6,"進路面談","個人面談")&"のお知らせになります","") | F31: 21 | G31: =IF(F31<=MIN('計算A'!$A$3,24),$B$3+(F31-1)*$B$5/1440,IF(F31<=$B$6,$B$4+(F31-'計算A'!$A$3-1)*$B$5/1440,"")) | I31: =IF(G31="","",TEXT(G31,"h:mm")&"〜") | L31: =$I$31
A32: 組 | B32: 1 | C32: ← 数字だけ（例：1）。「組」は自動 | F32: 22 | G32: =IF(F32<=MIN('計算A'!$A$3,24),$B$3+(F32-1)*$B$5/1440,IF(F32<=$B$6,$B$4+(F32-'計算A'!$A$3-1)*$B$5/1440,"")) | I32: =IF(G32="","",TEXT(G32,"h:mm")&"〜") | L32: =$I$32
A33: 担任名 | F33: 23 | G33: =IF(F33<=MIN('計算A'!$A$3,24),$B$3+(F33-1)*$B$5/1440,IF(F33<=$B$6,$B$4+(F33-'計算A'!$A$3-1)*$B$5/1440,"")) | I33: =IF(G33="","",TEXT(G33,"h:mm")&"〜") | L33: =$I$33
A34: 学校名 | F34: 24 | G34: =IF(F34<=MIN('計算A'!$A$3,24),$B$3+(F34-1)*$B$5/1440,IF(F34<=$B$6,$B$4+(F34-'計算A'!$A$3-1)*$B$5/1440,"")) | I34: =IF(G34="","",TEXT(G34,"h:mm")&"〜") | L34: =$I$34
A35: お手紙の日付 | B35: 46325
A36: 面談の種類 | B36: 学年に合わせる（6年は進路面談）
A37: 秋の本文 | B37: 【面談】の希望調査へのご協力ありがとうございました。下記の日程で予定を組ませていただきました。短い時間ですが、有意義な話し合いとし、日々の学級生活に生かしたいと思います。どうぞ、よろしくお願いいたします。
A40: 秋の注意（表の下・3行） | B40: 〇来校の際には、名札・上履きをお持ちください。
A43: 夏の本文 | B43: 下記の日程で予定を組ませていただきました。どうぞ、よろしくお願いいたします。
A45: 夏の注意（表の上・3行） | B45: 〇来校の際には、名札・上履きをお持ちください。
...

Sheet 名簿
A1: 名簿・結果 | D1: =HYPERLINK("#'ホーム'!A1","ホーム") | F1: ▲ 上の「＋」で 兄弟の列を開く | P1: =HYPERLINK("#'設定'!A1","① 設定") | Q1: =HYPERLINK("#'名簿'!A1","② 名簿") | S1: =HYPERLINK("#'×入力'!A1","③ ×入力") | U1: =HYPERLINK("#'自動案A'!A1","④ 自動案A") | X1: =HYPERLINK("#'自動案B'!A1","④ 自動案B") | Y1: =HYPERLINK("#'調整・決定'!A1","⑤ 調整・決定") | Z1: =HYPERLINK("#'兄弟確認用'!A1","⑥ 兄弟確認") | AB1: =HYPERLINK("#'お手紙（夏）'!A1","⑦ お手紙 夏") | AD1: =HYPERLINK("#'お手紙（秋）'!A1","⑧ お手紙 秋")
A2: 黄色の列（番号〜兄弟③との順番）を入力します。Excelの名簿から番号と名前を「番号」の列のいちばん上に貼り付けてください（最大45人）。行の並べ替えはしないでください。
A3: 兄弟クラス：書き方は自由です（例：2年1組、2-1、兄 5年 など）。10字くらいまでが見やすいです。灰色の欄は、兄弟が〇の子だけ入力します。 | P3: ◀ 兄弟①〜③の列（兄弟の担任から聞いた面談の日時と順番）は、左上の「＋」で開き、「−」でたためます。
A4: 番号 | B4: 名前 | C4: 希望 | D4: 後ろを空ける | E4: 兄弟 | F4: 兄弟クラス 日時は上の＋を押す | G4: 兄弟① 日付 | H4: 兄弟① 時刻 | I4: 兄弟① との順番 | J4: 兄弟② 日付 | K4: 兄弟② 時刻 | L4: 兄弟② との順番 | M4: 兄弟③ 日付 | N4: 兄弟③ 時刻 | O4: 兄弟③ との順番 | P4: 表示名 | Q4: 状況 | R4: ×の数 | S4: 入れられる空き枠 | T4: 決める順 | U4: 日付 | V4: 時刻 | W4: 注意 | X4: 自動案A（詰める） | Y4: 自動案B（散らす）
P5: =IF(B5="","",IF(COUNTIF($B$5:$B$49,B5)>1,IF(A5="","",A5&" ")&B5,B5)) | Q5: =IF(B5="","",IF('×入力'!F5="未提出","未提出",IF(R5>0,"入力済み",IF('×入力'!F5="×なし（どこでもOK）","×なし","未入力")))) | R5: =IF(B5="","",'計算A'!IN10) | S5: =IF(OR(Q5="入力済み",Q5="×なし"),'計算A'!IM10,"") | T5: =IF('計算A'!C10=1,COUNTIFS('計算A'!$C$10:$C$54,1,'計算A'!$IM$10:$IM$54,"<"&'計算A'!IM10)+1,"") | U5: =IF('計算A'!IO10=0,"",INDEX('設定'!$E$11:$E$16,INDEX('計算A'!$D$2:$EQ$2,'計算A'!IO10))) | V5: =IF('計算A'!IO10=0,"",INDEX('設定'!$I$11:$I$34,INDEX('計算A'!$D$3:$EQ$3,'計算A'!IO10))) | W5: =IF(P5="","",IF('計算A'!JG10=1,"兄弟の日付・時刻が表にありません",IF(COUNTIF('調整・決定'!$C$6:$H$29,P5)>1,"2か所以上に入っています",IF('計算A'!IO10>0,IF(INDEX('計算A'!$D$4:$EQ$4,'計算A'!IO10)=0,"使えない枠に入っています",IF(INDEX('計算A'!$D$10:$EQ$10,'計算A'!IO10)=1,"×の枠に入っています",IF('計算A'!IV10=0,"（出来れば）兄弟の前後ではありません",IF(AND(RIGHT(D5,4)="空けたい",INDEX('計算A'!$D$106:$EQ$106,'計算A'!IO10)=1,INDEX('計算A'!$D$109:$EQ$109,'計算A'!IO10+1)=1),IF(D5="必ず空けたい","後ろの枠が空いていません","（出来れば）後ろが空いていません"),IF(AND(D5="空けない",INDEX('計算A'!$D$106:$EQ$106,'計算A'!IO10)=1,INDEX('計算A'!$D$109:$EQ$109,'計算A'!IO10+1)=0),"（出来れば）すぐ後が空いています",""))))),IF(OR(Q5="入力済み",Q5="×なし"),"未決定",""))))) | X5: =IF('計算A'!IK10=0,IF('計算A'!IL10=1,"入る枠がありません",""),INDEX('計算A'!$D$8:$EQ$8,'計算A'!IK10)) | Y5: =IF('計算A'!IR10=0,IF('計算A'!IS10=1,"入る枠がありません",""),INDEX('計算A'!$D$8:$EQ$8,'計算A'!IR10)) | Z5: =HYPERLINK("#'×入力'!B5","×入力へ")
P6: =IF(B6="","",IF(COUNTIF($B$5:$B$49,B6)>1,IF(A6="","",A6&" ")&B6,B6)) | Q6: =IF(B6="","",IF('×入力'!F33="未提出","未提出",IF(R6>0,"入力済み",IF('×入力'!F33="×なし（どこでもOK）","×なし","未入力")))) | R6: =IF(B6="","",'計算A'!IN11) | S6: =IF(OR(Q6="入力済み",Q6="×なし"),'計算A'!IM11,"") | T6: =IF('計算A'!C11=1,COUNTIFS('計算A'!$C$10:$C$54,1,'計算A'!$IM$10:$IM$54,"<"&'計算A'!IM11)+1,"") | U6: =IF('計算A'!IO11=0,"",INDEX('設定'!$E$11:$E$16,INDEX('計算A'!$D$2:$EQ$2,'計算A'!IO11))) | V6: =IF('計算A'!IO11=0,"",INDEX('設定'!$I$11:$I$34,INDEX('計算A'!$D$3:$EQ$3,'計算A'!IO11))) | W6: =IF(P6="","",IF('計算A'!JG11=1,"兄弟の日付・時刻が表にありません",IF(COUNTIF('調整・決定'!$C$6:$H$29,P6)>1,"2か所以上に入っています",IF('計算A'!IO11>0,IF(INDEX('計算A'!$D$4:$EQ$4,'計算A'!IO11)=0,"使えない枠に入っています",IF(INDEX('計算A'!$D$11:$EQ$11,'計算A'!IO11)=1,"×の枠に入っています",IF('計算A'!IV11=0,"（出来れば）兄弟の前後ではありません",IF(AND(RIGHT(D6,4)="空けたい",INDEX('計算A'!$D$106:$EQ$106,'計算A'!IO11)=1,INDEX('計算A'!$D$109:$EQ$109,'計算A'!IO11+1)=1),IF(D6="必ず空けたい","後ろの枠が空いていません","（出来れば）後ろが空いていません"),IF(AND(D6="空けない",INDEX('計算A'!$D$106:$EQ$106,'計算A'!IO11)=1,INDEX('計算A'!$D$109:$EQ$109,'計算A'!IO11+1)=0),"（出来れば）すぐ後が空いています",""))))),IF(OR(Q6="入力済み",Q6="×なし"),"未決定",""))))) | X6: =IF('計算A'!IK11=0,IF('計算A'!IL11=1,"入る枠がありません",""),INDEX('計算A'!$D$8:$EQ$8,'計算A'!IK11)) | Y6: =IF('計算A'!IR11=0,IF('計算A'!IS11=1,"入る枠がありません",""),INDEX('計算A'!$D$8:$EQ$8,'計算A'!IR11)) | Z6: =HYPERLINK("#'×入力'!B33","×入力へ")
P7: =IF(B7="","",IF(COUNTIF($B$5:$B$49,B7)>1,IF(A7="","",A7&" ")&B7,B7)) | Q7: =IF(B7="","",IF('×入力'!F61="未提出","未提出",IF(R7>0,"入力済み",IF('×入力'!F61="×なし（どこでもOK）","×なし","未入力")))) | R7: =IF(B7="","",'計算A'!IN12) | S7: =IF(OR(Q7="入力済み",Q7="×なし"),'計算A'!IM12,"") | T7: =IF('計算A'!C12=1,COUNTIFS('計算A'!$C$10:$C$54,1,'計算A'!$IM$10:$IM$54,"<"&'計算A'!IM12)+1,"") | U7: =IF('計算A'!IO12=0,"",INDEX('設定'!$E$11:$E$16,INDEX('計算A'!$D$2:$EQ$2,'計算A'!IO12))) | V7: =IF('計算A'!IO12=0,"",INDEX('設定'!$I$11:$I$34,INDEX('計算A'!$D$3:$EQ$3,'計算A'!IO12))) | W7: =IF(P7="","",IF('計算A'!JG12=1,"兄弟の日付・時刻が表にありません",IF(COUNTIF('調整・決定'!$C$6:$H$29,P7)>1,"2か所以上に入っています",IF('計算A'!IO12>0,IF(INDEX('計算A'!$D$4:$EQ$4,'計算A'!IO12)=0,"使えない枠に入っています",IF(INDEX('計算A'!$D$12:$EQ$12,'計算A'!IO12)=1,"×の枠に入っています",IF('計算A'!IV12=0,"（出来れば）兄弟の前後ではありません",IF(AND(RIGHT(D7,4)="空けたい",INDEX('計算A'!$D$106:$EQ$106,'計算A'!IO12)=1,INDEX('計算A'!$D$109:$EQ$109,'計算A'!IO12+1)=1),IF(D7="必ず空けたい","後ろの枠が空いていません","（出来れば）後ろが空いていません"),IF(AND(D7="空けない",INDEX('計算A'!$D$106:$EQ$106,'計算A'!IO12)=1,INDEX('計算A'!$D$109:$EQ$109,'計算A'!IO12+1)=0),"（出来れば）すぐ後が空いています",""))))),IF(OR(Q7="入力済み",Q7="×なし"),"未決定",""))))) | X7: =IF('計算A'!IK12=0,IF('計算A'!IL12=1,"入る枠がありません",""),INDEX('計算A'!$D$8:$EQ$8,'計算A'!IK12)) | Y7: =IF('計算A'!IR12=0,IF('計算A'!IS12=1,"入る枠がありません",""),INDEX('計算A'!$D$8:$EQ$8,'計算A'!IR12)) | Z7: =HYPERLINK("#'×入力'!B61","×入力へ")
P8: =IF(B8="","",IF(COUNTIF($B$5:$B$49,B8)>1,IF(A8="","",A8&" ")&B8,B8)) | Q8: =IF(B8="","",IF('×入力'!F89="未提出","未提出",IF(R8>0,"入力済み",IF('×入力'!F89="×なし（どこでもOK）","×なし","未入力")))) | R8: =IF(B8="","",'計算A'!IN13) | S8: =IF(OR(Q8="入力済み",Q8="×なし"),'計算A'!IM13,"") | T8: =IF('計算A'!C13=1,COUNTIFS('計算A'!$C$10:$C$54,1,'計算A'!$IM$10:$IM$54,"<"&'計算A'!IM13)+1,"") | U8: =IF('計算A'!IO13=0,"",INDEX('設定'!$E$11:$E$16,INDEX('計算A'!$D$2:$EQ$2,'計算A'!IO13))) | V8: =IF('計算A'!IO13=0,"",INDEX('設定'!$I$11:$I$34,INDEX('計算A'!$D$3:$EQ$3,'計算A'!IO13))) | W8: =IF(P8="","",IF('計算A'!JG13=1,"兄弟の日付・時刻が表にありません",IF(COUNTIF('調整・決定'!$C$6:$H$29,P8)>1,"2か所以上に入っています",IF('計算A'!IO13>0,IF(INDEX('計算A'!$D$4:$EQ$4,'計算A'!IO13)=0,"使えない枠に入っています",IF(INDEX('計算A'!$D$13:$EQ$13,'計算A'!IO13)=1,"×の枠に入っています",IF('計算A'!IV13=0,"（出来れば）兄弟の前後ではありません",IF(AND(RIGHT(D8,4)="空けたい",INDEX('計算A'!$D$106:$EQ$106,'計算A'!IO13)=1,INDEX('計算A'!$D$109:$EQ$109,'計算A'!IO13+1)=1),IF(D8="必ず空けたい","後ろの枠が空いていません","（出来れば）後ろが空いていません"),IF(AND(D8="空けない",INDEX('計算A'!$D$106:$EQ$106,'計算A'!IO13)=1,INDEX('計算A'!$D$109:$EQ$109,'計算A'!IO13+1)=0),"（出来れば）すぐ後が空いています",""))))),IF(OR(Q8="入力済み",Q8="×なし"),"未決定",""))))) | X8: =IF('計算A'!IK13=0,IF('計算A'!IL13=1,"入る枠がありません",""),INDEX('計算A'!$D$8:$EQ$8,'計算A'!IK13)) | Y8: =IF('計算A'!IR13=0,IF('計算A'!IS13=1,"入る枠がありません",""),INDEX('計算A'!$D$8:$EQ$8,'計算A'!IR13)) | Z8: =HYPERLINK("#'×入力'!B89","×入力へ")
P9: =IF(B9="","",IF(COUNTIF($B$5:$B$49,B9)>1,IF(A9="","",A9&" ")&B9,B9)) | Q9: =IF(B9="","",IF('×入力'!F117="未提出","未提出",IF(R9>0,"入力済み",IF('×入力'!F117="×なし（どこでもOK）","×なし","未入力")))) | R9: =IF(B9="","",'計算A'!IN14) | S9: =IF(OR(Q9="入力済み",Q9="×なし"),'計算A'!IM14,"") | T9: =IF('計算A'!C14=1,COUNTIFS('計算A'!$C$10:$C$54,1,'計算A'!$IM$10:$IM$54,"<"&'計算A'!IM14)+1,"") | U9: =IF('計算A'!IO14=0,"",INDEX('設定'!$E$11:$E$16,INDEX('計算A'!$D$2:$EQ$2,'計算A'!IO14))) | V9: =IF('計算A'!IO14=0,"",INDEX('設定'!$I$11:$I$34,INDEX('計算A'!$D$3:$EQ$3,'計算A'!IO14))) | W9: =IF(P9="","",IF('計算A'!JG14=1,"兄弟の日付・時刻が表にありません",IF(COUNTIF('調整・決定'!$C$6:$H$29,P9)>1,"2か所以上に入っています",IF('計算A'!IO14>0,IF(INDEX('計算A'!$D$4:$EQ$4,'計算A'!IO14)=0,"使えない枠に入っています",IF(INDEX('計算A'!$D$14:$EQ$14,'計算A'!IO14)=1,"×の枠に入っています",IF('計算A'!IV14=0,"（出来れば）兄弟の前後ではありません",IF(AND(RIGHT(D9,4)="空けたい",INDEX('計算A'!$D$106:$EQ$106,'計算A'!IO14)=1,INDEX('計算A'!$D$109:$EQ$109,'計算A'!IO14+1)=1),IF(D9="必ず空けたい","後ろの枠が空いていません","（出来れば）後ろが空いていません"),IF(AND(D9="空けない",INDEX('計算A'!$D$106:$EQ$106,'計算A'!IO14)=1,INDEX('計算A'!$D$109:$EQ$109,'計算A'!IO14+1)=0),"（出来れば）すぐ後が空いています",""))))),IF(OR(Q9="入力済み",Q9="×なし"),"未決定",""))))) | X9: =IF('計算A'!IK14=0,IF('計算A'!IL14=1,"入る枠がありません",""),INDEX('計算A'!$D$8:$EQ$8,'計算A'!IK14)) | Y9: =IF('計算A'!IR14=0,IF('計算A'!IS14=1,"入る枠がありません",""),INDEX('計算A'!$D$8:$EQ$8,'計算A'!IR14)) | Z9: =HYPERLINK("#'×入力'!B117","×入力へ")
P10: =IF(B10="","",IF(COUNTIF($B$5:$B$49,B10)>1,IF(A10="","",A10&" ")&B10,B10)) | Q10: =IF(B10="","",IF('×入力'!F145="未提出","未提出",IF(R10>0,"入力済み",IF('×入力'!F145="×なし（どこでもOK）","×なし","未入力")))) | R10: =IF(B10="","",'計算A'!IN15) | S10: =IF(OR(Q10="入力済み",Q10="×なし"),'計算A'!IM15,"") | T10: =IF('計算A'!C15=1,COUNTIFS('計算A'!$C$10:$C$54,1,'計算A'!$IM$10:$IM$54,"<"&'計算A'!IM15)+1,"") | U10: =IF('計算A'!IO15=0,"",INDEX('設定'!$E$11:$E$16,INDEX('計算A'!$D$2:$EQ$2,'計算A'!IO15))) | V10: =IF('計算A'!IO15=0,"",INDEX('設定'!$I$11:$I$34,INDEX('計算A'!$D$3:$EQ$3,'計算A'!IO15))) | W10: =IF(P10="","",IF('計算A'!JG15=1,"兄弟の日付・時刻が表にありません",IF(COUNTIF('調整・決定'!$C$6:$H$29,P10)>1,"2か所以上に入っています",IF('計算A'!IO15>0,IF(INDEX('計算A'!$D$4:$EQ$4,'計算A'!IO15)=0,"使えない枠に入っています",IF(INDEX('計算A'!$D$15:$EQ$15,'計算A'!IO15)=1,"×の枠に入っています",IF('計算A'!IV15=0,"（出来れば）兄弟の前後ではありません",IF(AND(RIGHT(D10,4)="空けたい",INDEX('計算A'!$D$106:$EQ$106,'計算A'!IO15)=1,INDEX('計算A'!$D$109:$EQ$109,'計算A'!IO15+1)=1),IF(D10="必ず空けたい","後ろの枠が空いていません","（出来れば）後ろが空いていません"),IF(AND(D10="空けない",INDEX('計算A'!$D$106:$EQ$106,'計算A'!IO15)=1,INDEX('計算A'!$D$109:$EQ$109,'計算A'!IO15+1)=0),"（出来れば）すぐ後が空いています",""))))),IF(OR(Q10="入力済み",Q10="×なし"),"未決定",""))))) | X10: =IF('計算A'!IK15=0,IF('計算A'!IL15=1,"入る枠がありません",""),INDEX('計算A'!$D$8:$EQ$8,'計算A'!IK15)) | Y10: =IF('計算A'!IR15=0,IF('計算A'!IS15=1,"入る枠がありません",""),INDEX('計算A'!$D$8:$EQ$8,'計算A'!IR15)) | Z10: =HYPERLINK("#'×入力'!B145","×入力へ")
P11: =IF(B11="","",IF(COUNTIF($B$5:$B$49,B11)>1,IF(A11="","",A11&" ")&B11,B11)) | Q11: =IF(B11="","",IF('×入力'!F173="未提出","未提出",IF(R11>0,"入力済み",IF('×入力'!F173="×なし（どこでもOK）","×なし","未入力")))) | R11: =IF(B11="","",'計算A'!IN16) | S11: =IF(OR(Q11="入力済み",Q11="×なし"),'計算A'!IM16,"") | T11: =IF('計算A'!C16=1,COUNTIFS('計算A'!$C$10:$C$54,1,'計算A'!$IM$10:$IM$54,"<"&'計算A'!IM16)+1,"") | U11: =IF('計算A'!IO16=0,"",INDEX('設定'!$E$11:$E$16,INDEX('計算A'!$D$2:$EQ$2,'計算A'!IO16))) | V11: =IF('計算A'!IO16=0,"",INDEX('設定'!$I$11:$I$34,INDEX('計算A'!$D$3:$EQ$3,'計算A'!IO16))) | W11: =IF(P11="","",IF('計算A'!JG16=1,"兄弟の日付・時刻が表にありません",IF(COUNTIF('調整・決定'!$C$6:$H$29,P11)>1,"2か所以上に入っています",IF('計算A'!IO16>0,IF(INDEX('計算A'!$D$4:$EQ$4,'計算A'!IO16)=0,"使えない枠に入っています",IF(INDEX('計算A'!$D$16:$EQ$16,'計算A'!IO16)=1,"×の枠に入っています",IF('計算A'!IV16=0,"（出来れば）兄弟の前後ではありません",IF(AND(RIGHT(D11,4)="空けたい",INDEX('計算A'!$D$106:$EQ$106,'計算A'!IO16)=1,INDEX('計算A'!$D$109:$EQ$109,'計算A'!IO16+1)=1),IF(D11="必ず空けたい","後ろの枠が空いていません","（出来れば）後ろが空いていません"),IF(AND(D11="空けない",INDEX('計算A'!$D$106:$EQ$106,'計算A'!IO16)=1,INDEX('計算A'!$D$109:$EQ$109,'計算A'!IO16+1)=0),"（出来れば）すぐ後が空いています",""))))),IF(OR(Q11="入力済み",Q11="×なし"),"未決定",""))))) | X11: =IF('計算A'!IK16=0,IF('計算A'!IL16=1,"入る枠がありません",""),INDEX('計算A'!$D$8:$EQ$8,'計算A'!IK16)) | Y11: =IF('計算A'!IR16=0,IF('計算A'!IS16=1,"入る枠がありません",""),INDEX('計算A'!$D$8:$EQ$8,'計算A'!IR16)) | Z11: =HYPERLINK("#'×入力'!B173","×入力へ")
P12: =IF(B12="","",IF(COUNTIF($B$5:$B$49,B12)>1,IF(A12="","",A12&" ")&B12,B12)) | Q12: =IF(B12="","",IF('×入力'!F201="未提出","未提出",IF(R12>0,"入力済み",IF('×入力'!F201="×なし（どこでもOK）","×なし","未入力")))) | R12: =IF(B12="","",'計算A'!IN17) | S12: =IF(OR(Q12="入力済み",Q12="×なし"),'計算A'!IM17,"") | T12: =IF('計算A'!C17=1,COUNTIFS('計算A'!$C$10:$C$54,1,'計算A'!$IM$10:$IM$54,"<"&'計算A'!IM17)+1,"") | U12: =IF('計算A'!IO17=0,"",INDEX('設定'!$E$11:$E$16,INDEX('計算A'!$D$2:$EQ$2,'計算A'!IO17))) | V12: =IF('計算A'!IO17=0,"",INDEX('設定'!$I$11:$I$34,INDEX('計算A'!$D$3:$EQ$3,'計算A'!IO17))) | W12: =IF(P12="","",IF('計算A'!JG17=1,"兄弟の日付・時刻が表にありません",IF(COUNTIF('調整・決定'!$C$6:$H$29,P12)>1,"2か所以上に入っています",IF('計算A'!IO17>0,IF(INDEX('計算A'!$D$4:$EQ$4,'計算A'!IO17)=0,"使えない枠に入っています",IF(INDEX('計算A'!$D$17:$EQ$17,'計算A'!IO17)=1,"×の枠に入っています",IF('計算A'!IV17=0,"（出来れば）兄弟の前後ではありません",IF(AND(RIGHT(D12,4)="空けたい",INDEX('計算A'!$D$106:$EQ$106,'計算A'!IO17)=1,INDEX('計算A'!$D$109:$EQ$109,'計算A'!IO17+1)=1),IF(D12="必ず空けたい","後ろの枠が空いていません","（出来れば）後ろが空いていません"),IF(AND(D12="空けない",INDEX('計算A'!$D$106:$EQ$106,'計算A'!IO17)=1,INDEX('計算A'!$D$109:$EQ$109,'計算A'!IO17+1)=0),"（出来れば）すぐ後が空いています",""))))),IF(OR(Q12="入力済み",Q12="×なし"),"未決定",""))))) | X12: =IF('計算A'!IK17=0,IF('計算A'!IL17=1,"入る枠がありません",""),INDEX('計算A'!$D$8:$EQ$8,'計算A'!IK17)) | Y12: =IF('計算A'!IR17=0,IF('計算A'!IS17=1,"入る枠がありません",""),INDEX('計算A'!$D$8:$EQ$8,'計算A'!IR17)) | Z12: =HYPERLINK("#'×入力'!B201","×入力へ")
P13: =IF(B13="","",IF(COUNTIF($B$5:$B$49,B13)>1,IF(A13="","",A13&" ")&B13,B13)) | Q13: =IF(B13="","",IF('×入力'!F229="未提出","未提出",IF(R13>0,"入力済み",IF('×入力'!F229="×なし（どこでもOK）","×なし","未入力")))) | R13: =IF(B13="","",'計算A'!IN18) | S13: =IF(OR(Q13="入力済み",Q13="×なし"),'計算A'!IM18,"") | T13: =IF('計算A'!C18=1,COUNTIFS('計算A'!$C$10:$C$54,1,'計算A'!$IM$10:$IM$54,"<"&'計算A'!IM18)+1,"") | U13: =IF('計算A'!IO18=0,"",INDEX('設定'!$E$11:$E$16,INDEX('計算A'!$D$2:$EQ$2,'計算A'!IO18))) | V13: =IF('計算A'!IO18=0,"",INDEX('設定'!$I$11:$I$34,INDEX('計算A'!$D$3:$EQ$3,'計算A'!IO18))) | W13: =IF(P13="","",IF('計算A'!JG18=1,"兄弟の日付・時刻が表にありません",IF(COUNTIF('調整・決定'!$C$6:$H$29,P13)>1,"2か所以上に入っています",IF('計算A'!IO18>0,IF(INDEX('計算A'!$D$4:$EQ$4,'計算A'!IO18)=0,"使えない枠に入っています",IF(INDEX('計算A'!$D$18:$EQ$18,'計算A'!IO18)=1,"×の枠に入っています",IF('計算A'!IV18=0,"（出来れば）兄弟の前後ではありません",IF(AND(RIGHT(D13,4)="空けたい",INDEX('計算A'!$D$106:$EQ$106,'計算A'!IO18)=1,INDEX('計算A'!$D$109:$EQ$109,'計算A'!IO18+1)=1),IF(D13="必ず空けたい","後ろの枠が空いていません","（出来れば）後ろが空いていません"),IF(AND(D13="空けない",INDEX('計算A'!$D$106:$EQ$106,'計算A'!IO18)=1,INDEX('計算A'!$D$109:$EQ$109,'計算A'!IO18+1)=0),"（出来れば）すぐ後が空いています",""))))),IF(OR(Q13="入力済み",Q13="×なし"),"未決定",""))))) | X13: =IF('計算A'!IK18=0,IF('計算A'!IL18=1,"入る枠がありません",""),INDEX('計算A'!$D$8:$EQ$8,'計算A'!IK18)) | Y13: =IF('計算A'!IR18=0,IF('計算A'!IS18=1,"入る枠がありません",""),INDEX('計算A'!$D$8:$EQ$8,'計算A'!IR18)) | Z13: =HYPERLINK("#'×入力'!B229","×入力へ")
P14: =IF(B14="","",IF(COUNTIF($B$5:$B$49,B14)>1,IF(A14="","",A14&" ")&B14,B14)) | Q14: =IF(B14="","",IF('×入力'!F257="未提出","未提出",IF(R14>0,"入力済み",IF('×入力'!F257="×なし（どこでもOK）","×なし","未入力")))) | R14: =IF(B14="","",'計算A'!IN19) | S14: =IF(OR(Q14="入力済み",Q14="×なし"),'計算A'!IM19,"") | T14: =IF('計算A'!C19=1,COUNTIFS('計算A'!$C$10:$C$54,1,'計算A'!$IM$10:$IM$54,"<"&'計算A'!IM19)+1,"") | U14: =IF('計算A'!IO19=0,"",INDEX('設定'!$E$11:$E$16,INDEX('計算A'!$D$2:$EQ$2,'計算A'!IO19))) | V14: =IF('計算A'!IO19=0,"",INDEX('設定'!$I$11:$I$34,INDEX('計算A'!$D$3:$EQ$3,'計算A'!IO19))) | W14: =IF(P14="","",IF('計算A'!JG19=1,"兄弟の日付・時刻が表にありません",IF(COUNTIF('調整・決定'!$C$6:$H$29,P14)>1,"2か所以上に入っています",IF('計算A'!IO19>0,IF(INDEX('計算A'!$D$4:$EQ$4,'計算A'!IO19)=0,"使えない枠に入っています",IF(INDEX('計算A'!$D$19:$EQ$19,'計算A'!IO19)=1,"×の枠に入っています",IF('計算A'!IV19=0,"（出来れば）兄弟の前後ではありません",IF(AND(RIGHT(D14,4)="空けたい",INDEX('計算A'!$D$106:$EQ$106,'計算A'!IO19)=1,INDEX('計算A'!$D$109:$EQ$109,'計算A'!IO19+1)=1),IF(D14="必ず空けたい","後ろの枠が空いていません","（出来れば）後ろが空いていません"),IF(AND(D14="空けない",INDEX('計算A'!$D$106:$EQ$106,'計算A'!IO19)=1,INDEX('計算A'!$D$109:$EQ$109,'計算A'!IO19+1)=0),"（出来れば）すぐ後が空いています",""))))),IF(OR(Q14="入力済み",Q14="×なし"),"未決定",""))))) | X14: =IF('計算A'!IK19=0,IF('計算A'!IL19=1,"入る枠がありません",""),INDEX('計算A'!$D$8:$EQ$8,'計算A'!IK19)) | Y14: =IF('計算A'!IR19=0,IF('計算A'!IS19=1,"入る枠がありません",""),INDEX('計算A'!$D$8:$EQ$8,'計算A'!IR19)) | Z14: =HYPERLINK("#'×入力'!B257","×入力へ")
P15: =IF(B15="","",IF(COUNTIF($B$5:$B$49,B15)>1,IF(A15="","",A15&" ")&B15,B15)) | Q15: =IF(B15="","",IF('×入力'!F285="未提出","未提出",IF(R15>0,"入力済み",IF('×入力'!F285="×なし（どこでもOK）","×なし","未入力")))) | R15: =IF(B15="","",'計算A'!IN20) | S15: =IF(OR(Q15="入力済み",Q15="×なし"),'計算A'!IM20,"") | T15: =IF('計算A'!C20=1,COUNTIFS('計算A'!$C$10:$C$54,1,'計算A'!$IM$10:$IM$54,"<"&'計算A'!IM20)+1,"") | U15: =IF('計算A'!IO20=0,"",INDEX('設定'!$E$11:$E$16,INDEX('計算A'!$D$2:$EQ$2,'計算A'!IO20))) | V15: =IF('計算A'!IO20=0,"",INDEX('設定'!$I$11:$I$34,INDEX('計算A'!$D$3:$EQ$3,'計算A'!IO20))) | W15: =IF(P15="","",IF('計算A'!JG20=1,"兄弟の日付・時刻が表にありません",IF(COUNTIF('調整・決定'!$C$6:$H$29,P15)>1,"2か所以上に入っています",IF('計算A'!IO20>0,IF(INDEX('計算A'!$D$4:$EQ$4,'計算A'!IO20)=0,"使えない枠に入っています",IF(INDEX('計算A'!$D$20:$EQ$20,'計算A'!IO20)=1,"×の枠に入っています",IF('計算A'!IV20=0,"（出来れば）兄弟の前後ではありません",IF(AND(RIGHT(D15,4)="空けたい",INDEX('計算A'!$D$106:$EQ$106,'計算A'!IO20)=1,INDEX('計算A'!$D$109:$EQ$109,'計算A'!IO20+1)=1),IF(D15="必ず空けたい","後ろの枠が空いていません","（出来れば）後ろが空いていません"),IF(AND(D15="空けない",INDEX('計算A'!$D$106:$EQ$106,'計算A'!IO20)=1,INDEX('計算A'!$D$109:$EQ$109,'計算A'!IO20+1)=0),"（出来れば）すぐ後が空いています",""))))),IF(OR(Q15="入力済み",Q15="×なし"),"未決定",""))))) | X15: =IF('計算A'!IK20=0,IF('計算A'!IL20=1,"入る枠がありません",""),INDEX('計算A'!$D$8:$EQ$8,'計算A'!IK20)) | Y15: =IF('計算A'!IR20=0,IF('計算A'!IS20=1,"入る枠がありません",""),INDEX('計算A'!$D$8:$EQ$8,'計算A'!IR20)) | Z15: =HYPERLINK("#'×入力'!B285","×入力へ")
P16: =IF(B16="","",IF(COUNTIF($B$5:$B$49,B16)>1,IF(A16="","",A16&" ")&B16,B16)) | Q16: =IF(B16="","",IF('×入力'!F313="未提出","未提出",IF(R16>0,"入力済み",IF('×入力'!F313="×なし（どこでもOK）","×なし","未入力")))) | R16: =IF(B16="","",'計算A'!IN21) | S16: =IF(OR(Q16="入力済み",Q16="×なし"),'計算A'!IM21,"") | T16: =IF('計算A'!C21=1,COUNTIFS('計算A'!$C$10:$C$54,1,'計算A'!$IM$10:$IM$54,"<"&'計算A'!IM21)+1,"") | U16: =IF('計算A'!IO21=0,"",INDEX('設定'!$E$11:$E$16,INDEX('計算A'!$D$2:$EQ$2,'計算A'!IO21))) | V16: =IF('計算A'!IO21=0,"",INDEX('設定'!$I$11:$I$34,INDEX('計算A'!$D$3:$EQ$3,'計算A'!IO21))) | W16: =IF(P16="","",IF('計算A'!JG21=1,"兄弟の日付・時刻が表にありません",IF(COUNTIF('調整・決定'!$C$6:$H$29,P16)>1,"2か所以上に入っています",IF('計算A'!IO21>0,IF(INDEX('計算A'!$D$4:$EQ$4,'計算A'!IO21)=0,"使えない枠に入っています",IF(INDEX('計算A'!$D$21:$EQ$21,'計算A'!IO21)=1,"×の枠に入っています",IF('計算A'!IV21=0,"（出来れば）兄弟の前後ではありません",IF(AND(RIGHT(D16,4)="空けたい",INDEX('計算A'!$D$106:$EQ$106,'計算A'!IO21)=1,INDEX('計算A'!$D$109:$EQ$109,'計算A'!IO21+1)=1),IF(D16="必ず空けたい","後ろの枠が空いていません","（出来れば）後ろが空いていません"),IF(AND(D16="空けない",INDEX('計算A'!$D$106:$EQ$106,'計算A'!IO21)=1,INDEX('計算A'!$D$109:$EQ$109,'計算A'!IO21+1)=0),"（出来れば）すぐ後が空いています",""))))),IF(OR(Q16="入力済み",Q16="×なし"),"未決定",""))))) | X16: =IF('計算A'!IK21=0,IF('計算A'!IL21=1,"入る枠がありません",""),INDEX('計算A'!$D$8:$EQ$8,'計算A'!IK21)) | Y16: =IF('計算A'!IR21=0,IF('計算A'!IS21=1,"入る枠がありません",""),INDEX('計算A'!$D$8:$EQ$8,'計算A'!IR21)) | Z16: =HYPERLINK("#'×入力'!B313","×入力へ")
P17: =IF(B17="","",IF(COUNTIF($B$5:$B$49,B17)>1,IF(A17="","",A17&" ")&B17,B17)) | Q17: =IF(B17="","",IF('×入力'!F341="未提出","未提出",IF(R17>0,"入力済み",IF('×入力'!F341="×なし（どこでもOK）","×なし","未入力")))) | R17: =IF(B17="","",'計算A'!IN22) | S17: =IF(OR(Q17="入力済み",Q17="×なし"),'計算A'!IM22,"") | T17: =IF('計算A'!C22=1,COUNTIFS('計算A'!$C$10:$C$54,1,'計算A'!$IM$10:$IM$54,"<"&'計算A'!IM22)+1,"") | U17: =IF('計算A'!IO22=0,"",INDEX('設定'!$E$11:$E$16,INDEX('計算A'!$D$2:$EQ$2,'計算A'!IO22))) | V17: =IF('計算A'!IO22=0,"",INDEX('設定'!$I$11:$I$34,INDEX('計算A'!$D$3:$EQ$3,'計算A'!IO22))) | W17: =IF(P17="","",IF('計算A'!JG22=1,"兄弟の日付・時刻が表にありません",IF(COUNTIF('調整・決定'!$C$6:$H$29,P17)>1,"2か所以上に入っています",IF('計算A'!IO22>0,IF(INDEX('計算A'!$D$4:$EQ$4,'計算A'!IO22)=0,"使えない枠に入っています",IF(INDEX('計算A'!$D$22:$EQ$22,'計算A'!IO22)=1,"×の枠に入っています",IF('計算A'!IV22=0,"（出来れば）兄弟の前後ではありません",IF(AND(RIGHT(D17,4)="空けたい",INDEX('計算A'!$D$106:$EQ$106,'計算A'!IO22)=1,INDEX('計算A'!$D$109:$EQ$109,'計算A'!IO22+1)=1),IF(D17="必ず空けたい","後ろの枠が空いていません","（出来れば）後ろが空いていません"),IF(AND(D17="空けない",INDEX('計算A'!$D$106:$EQ$106,'計算A'!IO22)=1,INDEX('計算A'!$D$109:$EQ$109,'計算A'!IO22+1)=0),"（出来れば）すぐ後が空いています",""))))),IF(OR(Q17="入力済み",Q17="×なし"),"未決定",""))))) | X17: =IF('計算A'!IK22=0,IF('計算A'!IL22=1,"入る枠がありません",""),INDEX('計算A'!$D$8:$EQ$8,'計算A'!IK22)) | Y17: =IF('計算A'!IR22=0,IF('計算A'!IS22=1,"入る枠がありません",""),INDEX('計算A'!$D$8:$EQ$8,'計算A'!IR22)) | Z17: =HYPERLINK("#'×入力'!B341","×入力へ")
P18: =IF(B18="","",IF(COUNTIF($B$5:$B$49,B18)>1,IF(A18="","",A18&" ")&B18,B18)) | Q18: =IF(B18="","",IF('×入力'!F369="未提出","未提出",IF(R18>0,"入力済み",IF('×入力'!F369="×なし（どこでもOK）","×なし","未入力")))) | R18: =IF(B18="","",'計算A'!IN23) | S18: =IF(OR(Q18="入力済み",Q18="×なし"),'計算A'!IM23,"") | T18: =IF('計算A'!C23=1,COUNTIFS('計算A'!$C$10:$C$54,1,'計算A'!$IM$10:$IM$54,"<"&'計算A'!IM23)+1,"") | U18: =IF('計算A'!IO23=0,"",INDEX('設定'!$E$11:$E$16,INDEX('計算A'!$D$2:$EQ$2,'計算A'!IO23))) | V18: =IF('計算A'!IO23=0,"",INDEX('設定'!$I$11:$I$34,INDEX('計算A'!$D$3:$EQ$3,'計算A'!IO23))) | W18: =IF(P18="","",IF('計算A'!JG23=1,"兄弟の日付・時刻が表にありません",IF(COUNTIF('調整・決定'!$C$6:$H$29,P18)>1,"2か所以上に入っています",IF('計算A'!IO23>0,IF(INDEX('計算A'!$D$4:$EQ$4,'計算A'!IO23)=0,"使えない枠に入っています",IF(INDEX('計算A'!$D$23:$EQ$23,'計算A'!IO23)=1,"×の枠に入っています",IF('計算A'!IV23=0,"（出来れば）兄弟の前後ではありません",IF(AND(RIGHT(D18,4)="空けたい",INDEX('計算A'!$D$106:$EQ$106,'計算A'!IO23)=1,INDEX('計算A'!$D$109:$EQ$109,'計算A'!IO23+1)=1),IF(D18="必ず空けたい","後ろの枠が空いていません","（出来れば）後ろが空いていません"),IF(AND(D18="空けない",INDEX('計算A'!$D$106:$EQ$106,'計算A'!IO23)=1,INDEX('計算A'!$D$109:$EQ$109,'計算A'!IO23+1)=0),"（出来れば）すぐ後が空いています",""))))),IF(OR(Q18="入力済み",Q18="×なし"),"未決定",""))))) | X18: =IF('計算A'!IK23=0,IF('計算A'!IL23=1,"入る枠がありません",""),INDEX('計算A'!$D$8:$EQ$8,'計算A'!IK23)) | Y18: =IF('計算A'!IR23=0,IF('計算A'!IS23=1,"入る枠がありません",""),INDEX('計算A'!$D$8:$EQ$8,'計算A'!IR23)) | Z18: =HYPERLINK("#'×入力'!B369","×入力へ")
P19: =IF(B19="","",IF(COUNTIF($B$5:$B$49,B19)>1,IF(A19="","",A19&" ")&B19,B19)) | Q19: =IF(B19="","",IF('×入力'!F397="未提出","未提出",IF(R19>0,"入力済み",IF('×入力'!F397="×なし（どこでもOK）","×なし","未入力")))) | R19: =IF(B19="","",'計算A'!IN24) | S19: =IF(OR(Q19="入力済み",Q19="×なし"),'計算A'!IM24,"") | T19: =IF('計算A'!C24=1,COUNTIFS('計算A'!$C$10:$C$54,1,'計算A'!$IM$10:$IM$54,"<"&'計算A'!IM24)+1,"") | U19: =IF('計算A'!IO24=0,"",INDEX('設定'!$E$11:$E$16,INDEX('計算A'!$D$2:$EQ$2,'計算A'!IO24))) | V19: =IF('計算A'!IO24=0,"",INDEX('設定'!$I$11:$I$34,INDEX('計算A'!$D$3:$EQ$3,'計算A'!IO24))) | W19: =IF(P19="","",IF('計算A'!JG24=1,"兄弟の日付・時刻が表にありません",IF(COUNTIF('調整・決定'!$C$6:$H$29,P19)>1,"2か所以上に入っています",IF('計算A'!IO24>0,IF(INDEX('計算A'!$D$4:$EQ$4,'計算A'!IO24)=0,"使えない枠に入っています",IF(INDEX('計算A'!$D$24:$EQ$24,'計算A'!IO24)=1,"×の枠に入っています",IF('計算A'!IV24=0,"（出来れば）兄弟の前後ではありません",IF(AND(RIGHT(D19,4)="空けたい",INDEX('計算A'!$D$106:$EQ$106,'計算A'!IO24)=1,INDEX('計算A'!$D$109:$EQ$109,'計算A'!IO24+1)=1),IF(D19="必ず空けたい","後ろの枠が空いていません","（出来れば）後ろが空いていません"),IF(AND(D19="空けない",INDEX('計算A'!$D$106:$EQ$106,'計算A'!IO24)=1,INDEX('計算A'!$D$109:$EQ$109,'計算A'!IO24+1)=0),"（出来れば）すぐ後が空いています",""))))),IF(OR(Q19="入力済み",Q19="×なし"),"未決定",""))))) | X19: =IF('計算A'!IK24=0,IF('計算A'!IL24=1,"入る枠がありません",""),INDEX('計算A'!$D$8:$EQ$8,'計算A'!IK24)) | Y19: =IF('計算A'!IR24=0,IF('計算A'!IS24=1,"入る枠がありません",""),INDEX('計算A'!$D$8:$EQ$8,'計算A'!IR24)) | Z19: =HYPERLINK("#'×入力'!B397","×入力へ")
P20: =IF(B20="","",IF(COUNTIF($B$5:$B$49,B20)>1,IF(A20="","",A20&" ")&B20,B20)) | Q20: =IF(B20="","",IF('×入力'!F425="未提出","未提出",IF(R20>0,"入力済み",IF('×入力'!F425="×なし（どこでもOK）","×なし","未入力")))) | R20: =IF(B20="","",'計算A'!IN25) | S20: =IF(OR(Q20="入力済み",Q20="×なし"),'計算A'!IM25,"") | T20: =IF('計算A'!C25=1,COUNTIFS('計算A'!$C$10:$C$54,1,'計算A'!$IM$10:$IM$54,"<"&'計算A'!IM25)+1,"") | U20: =IF('計算A'!IO25=0,"",INDEX('設定'!$E$11:$E$16,INDEX('計算A'!$D$2:$EQ$2,'計算A'!IO25))) | V20: =IF('計算A'!IO25=0,"",INDEX('設定'!$I$11:$I$34,INDEX('計算A'!$D$3:$EQ$3,'計算A'!IO25))) | W20: =IF(P20="","",IF('計算A'!JG25=1,"兄弟の日付・時刻が表にありません",IF(COUNTIF('調整・決定'!$C$6:$H$29,P20)>1,"2か所以上に入っています",IF('計算A'!IO25>0,IF(INDEX('計算A'!$D$4:$EQ$4,'計算A'!IO25)=0,"使えない枠に入っています",IF(INDEX('計算A'!$D$25:$EQ$25,'計算A'!IO25)=1,"×の枠に入っています",IF('計算A'!IV25=0,"（出来れば）兄弟の前後ではありません",IF(AND(RIGHT(D20,4)="空けたい",INDEX('計算A'!$D$106:$EQ$106,'計算A'!IO25)=1,INDEX('計算A'!$D$109:$EQ$109,'計算A'!IO25+1)=1),IF(D20="必ず空けたい","後ろの枠が空いていません","（出来れば）後ろが空いていません"),IF(AND(D20="空けない",INDEX('計算A'!$D$106:$EQ$106,'計算A'!IO25)=1,INDEX('計算A'!$D$109:$EQ$109,'計算A'!IO25+1)=0),"（出来れば）すぐ後が空いています",""))))),IF(OR(Q20="入力済み",Q20="×なし"),"未決定",""))))) | X20: =IF('計算A'!IK25=0,IF('計算A'!IL25=1,"入る枠がありません",""),INDEX('計算A'!$D$8:$EQ$8,'計算A'!IK25)) | Y20: =IF('計算A'!IR25=0,IF('計算A'!IS25=1,"入る枠がありません",""),INDEX('計算A'!$D$8:$EQ$8,'計算A'!IR25)) | Z20: =HYPERLINK("#'×入力'!B425","×入力へ")
P21: =IF(B21="","",IF(COUNTIF($B$5:$B$49,B21)>1,IF(A21="","",A21&" ")&B21,B21)) | Q21: =IF(B21="","",IF('×入力'!F453="未提出","未提出",IF(R21>0,"入力済み",IF('×入力'!F453="×なし（どこでもOK）","×なし","未入力")))) | R21: =IF(B21="","",'計算A'!IN26) | S21: =IF(OR(Q21="入力済み",Q21="×なし"),'計算A'!IM26,"") | T21: =IF('計算A'!C26=1,COUNTIFS('計算A'!$C$10:$C$54,1,'計算A'!$IM$10:$IM$54,"<"&'計算A'!IM26)+1,"") | U21: =IF('計算A'!IO26=0,"",INDEX('設定'!$E$11:$E$16,INDEX('計算A'!$D$2:$EQ$2,'計算A'!IO26))) | V21: =IF('計算A'!IO26=0,"",INDEX('設定'!$I$11:$I$34,INDEX('計算A'!$D$3:$EQ$3,'計算A'!IO26))) | W21: =IF(P21="","",IF('計算A'!JG26=1,"兄弟の日付・時刻が表にありません",IF(COUNTIF('調整・決定'!$C$6:$H$29,P21)>1,"2か所以上に入っています",IF('計算A'!IO26>0,IF(INDEX('計算A'!$D$4:$EQ$4,'計算A'!IO26)=0,"使えない枠に入っています",IF(INDEX('計算A'!$D$26:$EQ$26,'計算A'!IO26)=1,"×の枠に入っています",IF('計算A'!IV26=0,"（出来れば）兄弟の前後ではありません",IF(AND(RIGHT(D21,4)="空けたい",INDEX('計算A'!$D$106:$EQ$106,'計算A'!IO26)=1,INDEX('計算A'!$D$109:$EQ$109,'計算A'!IO26+1)=1),IF(D21="必ず空けたい","後ろの枠が空いていません","（出来れば）後ろが空いていません"),IF(AND(D21="空けない",INDEX('計算A'!$D$106:$EQ$106,'計算A'!IO26)=1,INDEX('計算A'!$D$109:$EQ$109,'計算A'!IO26+1)=0),"（出来れば）すぐ後が空いています",""))))),IF(OR(Q21="入力済み",Q21="×なし"),"未決定",""))))) | X21: =IF('計算A'!IK26=0,IF('計算A'!IL26=1,"入る枠がありません",""),INDEX('計算A'!$D$8:$EQ$8,'計算A'!IK26)) | Y21: =IF('計算A'!IR26=0,IF('計算A'!IS26=1,"入る枠がありません",""),INDEX('計算A'!$D$8:$EQ$8,'計算A'!IR26)) | Z21: =HYPERLINK("#'×入力'!B453","×入力へ")
P22: =IF(B22="","",IF(COUNTIF($B$5:$B$49,B22)>1,IF(A22="","",A22&" ")&B22,B22)) | Q22: =IF(B22="","",IF('×入力'!F481="未提出","未提出",IF(R22>0,"入力済み",IF('×入力'!F481="×なし（どこでもOK）","×なし","未入力")))) | R22: =IF(B22="","",'計算A'!IN27) | S22: =IF(OR(Q22="入力済み",Q22="×なし"),'計算A'!IM27,"") | T22: =IF('計算A'!C27=1,COUNTIFS('計算A'!$C$10:$C$54,1,'計算A'!$IM$10:$IM$54,"<"&'計算A'!IM27)+1,"") | U22: =IF('計算A'!IO27=0,"",INDEX('設定'!$E$11:$E$16,INDEX('計算A'!$D$2:$EQ$2,'計算A'!IO27))) | V22: =IF('計算A'!IO27=0,"",INDEX('設定'!$I$11:$I$34,INDEX('計算A'!$D$3:$EQ$3,'計算A'!IO27))) | W22: =IF(P22="","",IF('計算A'!JG27=1,"兄弟の日付・時刻が表にありません",IF(COUNTIF('調整・決定'!$C$6:$H$29,P22)>1,"2か所以上に入っています",IF('計算A'!IO27>0,IF(INDEX('計算A'!$D$4:$EQ$4,'計算A'!IO27)=0,"使えない枠に入っています",IF(INDEX('計算A'!$D$27:$EQ$27,'計算A'!IO27)=1,"×の枠に入っています",IF('計算A'!IV27=0,"（出来れば）兄弟の前後ではありません",IF(AND(RIGHT(D22,4)="空けたい",INDEX('計算A'!$D$106:$EQ$106,'計算A'!IO27)=1,INDEX('計算A'!$D$109:$EQ$109,'計算A'!IO27+1)=1),IF(D22="必ず空けたい","後ろの枠が空いていません","（出来れば）後ろが空いていません"),IF(AND(D22="空けない",INDEX('計算A'!$D$106:$EQ$106,'計算A'!IO27)=1,INDEX('計算A'!$D$109:$EQ$109,'計算A'!IO27+1)=0),"（出来れば）すぐ後が空いています",""))))),IF(OR(Q22="入力済み",Q22="×なし"),"未決定",""))))) | X22: =IF('計算A'!IK27=0,IF('計算A'!IL27=1,"入る枠がありません",""),INDEX('計算A'!$D$8:$EQ$8,'計算A'!IK27)) | Y22: =IF('計算A'!IR27=0,IF('計算A'!IS27=1,"入る枠がありません",""),INDEX('計算A'!$D$8:$EQ$8,'計算A'!IR27)) | Z22: =HYPERLINK("#'×入力'!B481","×入力へ")
P23: =IF(B23="","",IF(COUNTIF($B$5:$B$49,B23)>1,IF(A23="","",A23&" ")&B23,B23)) | Q23: =IF(B23="","",IF('×入力'!F509="未提出","未提出",IF(R23>0,"入力済み",IF('×入力'!F509="×なし（どこでもOK）","×なし","未入力")))) | R23: =IF(B23="","",'計算A'!IN28) | S23: =IF(OR(Q23="入力済み",Q23="×なし"),'計算A'!IM28,"") | T23: =IF('計算A'!C28=1,COUNTIFS('計算A'!$C$10:$C$54,1,'計算A'!$IM$10:$IM$54,"<"&'計算A'!IM28)+1,"") | U23: =IF('計算A'!IO28=0,"",INDEX('設定'!$E$11:$E$16,INDEX('計算A'!$D$2:$EQ$2,'計算A'!IO28))) | V23: =IF('計算A'!IO28=0,"",INDEX('設定'!$I$11:$I$34,INDEX('計算A'!$D$3:$EQ$3,'計算A'!IO28))) | W23: =IF(P23="","",IF('計算A'!JG28=1,"兄弟の日付・時刻が表にありません",IF(COUNTIF('調整・決定'!$C$6:$H$29,P23)>1,"2か所以上に入っています",IF('計算A'!IO28>0,IF(INDEX('計算A'!$D$4:$EQ$4,'計算A'!IO28)=0,"使えない枠に入っています",IF(INDEX('計算A'!$D$28:$EQ$28,'計算A'!IO28)=1,"×の枠に入っています",IF('計算A'!IV28=0,"（出来れば）兄弟の前後ではありません",IF(AND(RIGHT(D23,4)="空けたい",INDEX('計算A'!$D$106:$EQ$106,'計算A'!IO28)=1,INDEX('計算A'!$D$109:$EQ$109,'計算A'!IO28+1)=1),IF(D23="必ず空けたい","後ろの枠が空いていません","（出来れば）後ろが空いていません"),IF(AND(D23="空けない",INDEX('計算A'!$D$106:$EQ$106,'計算A'!IO28)=1,INDEX('計算A'!$D$109:$EQ$109,'計算A'!IO28+1)=0),"（出来れば）すぐ後が空いています",""))))),IF(OR(Q23="入力済み",Q23="×なし"),"未決定",""))))) | X23: =IF('計算A'!IK28=0,IF('計算A'!IL28=1,"入る枠がありません",""),INDEX('計算A'!$D$8:$EQ$8,'計算A'!IK28)) | Y23: =IF('計算A'!IR28=0,IF('計算A'!IS28=1,"入る枠がありません",""),INDEX('計算A'!$D$8:$EQ$8,'計算A'!IR28)) | Z23: =HYPERLINK("#'×入力'!B509","×入力へ")
P24: =IF(B24="","",IF(COUNTIF($B$5:$B$49,B24)>1,IF(A24="","",A24&" ")&B24,B24)) | Q24: =IF(B24="","",IF('×入力'!F537="未提出","未提出",IF(R24>0,"入力済み",IF('×入力'!F537="×なし（どこでもOK）","×なし","未入力")))) | R24: =IF(B24="","",'計算A'!IN29) | S24: =IF(OR(Q24="入力済み",Q24="×なし"),'計算A'!IM29,"") | T24: =IF('計算A'!C29=1,COUNTIFS('計算A'!$C$10:$C$54,1,'計算A'!$IM$10:$IM$54,"<"&'計算A'!IM29)+1,"") | U24: =IF('計算A'!IO29=0,"",INDEX('設定'!$E$11:$E$16,INDEX('計算A'!$D$2:$EQ$2,'計算A'!IO29))) | V24: =IF('計算A'!IO29=0,"",INDEX('設定'!$I$11:$I$34,INDEX('計算A'!$D$3:$EQ$3,'計算A'!IO29))) | W24: =IF(P24="","",IF('計算A'!JG29=1,"兄弟の日付・時刻が表にありません",IF(COUNTIF('調整・決定'!$C$6:$H$29,P24)>1,"2か所以上に入っています",IF('計算A'!IO29>0,IF(INDEX('計算A'!$D$4:$EQ$4,'計算A'!IO29)=0,"使えない枠に入っています",IF(INDEX('計算A'!$D$29:$EQ$29,'計算A'!IO29)=1,"×の枠に入っています",IF('計算A'!IV29=0,"（出来れば）兄弟の前後ではありません",IF(AND(RIGHT(D24,4)="空けたい",INDEX('計算A'!$D$106:$EQ$106,'計算A'!IO29)=1,INDEX('計算A'!$D$109:$EQ$109,'計算A'!IO29+1)=1),IF(D24="必ず空けたい","後ろの枠が空いていません","（出来れば）後ろが空いていません"),IF(AND(D24="空けない",INDEX('計算A'!$D$106:$EQ$106,'計算A'!IO29)=1,INDEX('計算A'!$D$109:$EQ$109,'計算A'!IO29+1)=0),"（出来れば）すぐ後が空いています",""))))),IF(OR(Q24="入力済み",Q24="×なし"),"未決定",""))))) | X24: =IF('計算A'!IK29=0,IF('計算A'!IL29=1,"入る枠がありません",""),INDEX('計算A'!$D$8:$EQ$8,'計算A'!IK29)) | Y24: =IF('計算A'!IR29=0,IF('計算A'!IS29=1,"入る枠がありません",""),INDEX('計算A'!$D$8:$EQ$8,'計算A'!IR29)) | Z24: =HYPERLINK("#'×入力'!B537","×入力へ")
P25: =IF(B25="","",IF(COUNTIF($B$5:$B$49,B25)>1,IF(A25="","",A25&" ")&B25,B25)) | Q25: =IF(B25="","",IF('×入力'!F565="未提出","未提出",IF(R25>0,"入力済み",IF('×入力'!F565="×なし（どこでもOK）","×なし","未入力")))) | R25: =IF(B25="","",'計算A'!IN30) | S25: =IF(OR(Q25="入力済み",Q25="×なし"),'計算A'!IM30,"") | T25: =IF('計算A'!C30=1,COUNTIFS('計算A'!$C$10:$C$54,1,'計算A'!$IM$10:$IM$54,"<"&'計算A'!IM30)+1,"") | U25: =IF('計算A'!IO30=0,"",INDEX('設定'!$E$11:$E$16,INDEX('計算A'!$D$2:$EQ$2,'計算A'!IO30))) | V25: =IF('計算A'!IO30=0,"",INDEX('設定'!$I$11:$I$34,INDEX('計算A'!$D$3:$EQ$3,'計算A'!IO30))) | W25: =IF(P25="","",IF('計算A'!JG30=1,"兄弟の日付・時刻が表にありません",IF(COUNTIF('調整・決定'!$C$6:$H$29,P25)>1,"2か所以上に入っています",IF('計算A'!IO30>0,IF(INDEX('計算A'!$D$4:$EQ$4,'計算A'!IO30)=0,"使えない枠に入っています",IF(INDEX('計算A'!$D$30:$EQ$30,'計算A'!IO30)=1,"×の枠に入っています",IF('計算A'!IV30=0,"（出来れば）兄弟の前後ではありません",IF(AND(RIGHT(D25,4)="空けたい",INDEX('計算A'!$D$106:$EQ$106,'計算A'!IO30)=1,INDEX('計算A'!$D$109:$EQ$109,'計算A'!IO30+1)=1),IF(D25="必ず空けたい","後ろの枠が空いていません","（出来れば）後ろが空いていません"),IF(AND(D25="空けない",INDEX('計算A'!$D$106:$EQ$106,'計算A'!IO30)=1,INDEX('計算A'!$D$109:$EQ$109,'計算A'!IO30+1)=0),"（出来れば）すぐ後が空いています",""))))),IF(OR(Q25="入力済み",Q25="×なし"),"未決定",""))))) | X25: =IF('計算A'!IK30=0,IF('計算A'!IL30=1,"入る枠がありません",""),INDEX('計算A'!$D$8:$EQ$8,'計算A'!IK30)) | Y25: =IF('計算A'!IR30=0,IF('計算A'!IS30=1,"入る枠がありません",""),INDEX('計算A'!$D$8:$EQ$8,'計算A'!IR30)) | Z25: =HYPERLINK("#'×入力'!B565","×入力へ")
P26: =IF(B26="","",IF(COUNTIF($B$5:$B$49,B26)>1,IF(A26="","",A26&" ")&B26,B26)) | Q26: =IF(B26="","",IF('×入力'!F593="未提出","未提出",IF(R26>0,"入力済み",IF('×入力'!F593="×なし（どこでもOK）","×なし","未入力")))) | R26: =IF(B26="","",'計算A'!IN31) | S26: =IF(OR(Q26="入力済み",Q26="×なし"),'計算A'!IM31,"") | T26: =IF('計算A'!C31=1,COUNTIFS('計算A'!$C$10:$C$54,1,'計算A'!$IM$10:$IM$54,"<"&'計算A'!IM31)+1,"") | U26: =IF('計算A'!IO31=0,"",INDEX('設定'!$E$11:$E$16,INDEX('計算A'!$D$2:$EQ$2,'計算A'!IO31))) | V26: =IF('計算A'!IO31=0,"",INDEX('設定'!$I$11:$I$34,INDEX('計算A'!$D$3:$EQ$3,'計算A'!IO31))) | W26: =IF(P26="","",IF('計算A'!JG31=1,"兄弟の日付・時刻が表にありません",IF(COUNTIF('調整・決定'!$C$6:$H$29,P26)>1,"2か所以上に入っています",IF('計算A'!IO31>0,IF(INDEX('計算A'!$D$4:$EQ$4,'計算A'!IO31)=0,"使えない枠に入っています",IF(INDEX('計算A'!$D$31:$EQ$31,'計算A'!IO31)=1,"×の枠に入っています",IF('計算A'!IV31=0,"（出来れば）兄弟の前後ではありません",IF(AND(RIGHT(D26,4)="空けたい",INDEX('計算A'!$D$106:$EQ$106,'計算A'!IO31)=1,INDEX('計算A'!$D$109:$EQ$109,'計算A'!IO31+1)=1),IF(D26="必ず空けたい","後ろの枠が空いていません","（出来れば）後ろが空いていません"),IF(AND(D26="空けない",INDEX('計算A'!$D$106:$EQ$106,'計算A'!IO31)=1,INDEX('計算A'!$D$109:$EQ$109,'計算A'!IO31+1)=0),"（出来れば）すぐ後が空いています",""))))),IF(OR(Q26="入力済み",Q26="×なし"),"未決定",""))))) | X26: =IF('計算A'!IK31=0,IF('計算A'!IL31=1,"入る枠がありません",""),INDEX('計算A'!$D$8:$EQ$8,'計算A'!IK31)) | Y26: =IF('計算A'!IR31=0,IF('計算A'!IS31=1,"入る枠がありません",""),INDEX('計算A'!$D$8:$EQ$8,'計算A'!IR31)) | Z26: =HYPERLINK("#'×入力'!B593","×入力へ")
P27: =IF(B27="","",IF(COUNTIF($B$5:$B$49,B27)>1,IF(A27="","",A27&" ")&B27,B27)) | Q27: =IF(B27="","",IF('×入力'!F621="未提出","未提出",IF(R27>0,"入力済み",IF('×入力'!F621="×なし（どこでもOK）","×なし","未入力")))) | R27: =IF(B27="","",'計算A'!IN32) | S27: =IF(OR(Q27="入力済み",Q27="×なし"),'計算A'!IM32,"") | T27: =IF('計算A'!C32=1,COUNTIFS('計算A'!$C$10:$C$54,1,'計算A'!$IM$10:$IM$54,"<"&'計算A'!IM32)+1,"") | U27: =IF('計算A'!IO32=0,"",INDEX('設定'!$E$11:$E$16,INDEX('計算A'!$D$2:$EQ$2,'計算A'!IO32))) | V27: =IF('計算A'!IO32=0,"",INDEX('設定'!$I$11:$I$34,INDEX('計算A'!$D$3:$EQ$3,'計算A'!IO32))) | W27: =IF(P27="","",IF('計算A'!JG32=1,"兄弟の日付・時刻が表にありません",IF(COUNTIF('調整・決定'!$C$6:$H$29,P27)>1,"2か所以上に入っています",IF('計算A'!IO32>0,IF(INDEX('計算A'!$D$4:$EQ$4,'計算A'!IO32)=0,"使えない枠に入っています",IF(INDEX('計算A'!$D$32:$EQ$32,'計算A'!IO32)=1,"×の枠に入っています",IF('計算A'!IV32=0,"（出来れば）兄弟の前後ではありません",IF(AND(RIGHT(D27,4)="空けたい",INDEX('計算A'!$D$106:$EQ$106,'計算A'!IO32)=1,INDEX('計算A'!$D$109:$EQ$109,'計算A'!IO32+1)=1),IF(D27="必ず空けたい","後ろの枠が空いていません","（出来れば）後ろが空いていません"),IF(AND(D27="空けない",INDEX('計算A'!$D$106:$EQ$106,'計算A'!IO32)=1,INDEX('計算A'!$D$109:$EQ$109,'計算A'!IO32+1)=0),"（出来れば）すぐ後が空いています",""))))),IF(OR(Q27="入力済み",Q27="×なし"),"未決定",""))))) | X27: =IF('計算A'!IK32=0,IF('計算A'!IL32=1,"入る枠がありません",""),INDEX('計算A'!$D$8:$EQ$8,'計算A'!IK32)) | Y27: =IF('計算A'!IR32=0,IF('計算A'!IS32=1,"入る枠がありません",""),INDEX('計算A'!$D$8:$EQ$8,'計算A'!IR32)) | Z27: =HYPERLINK("#'×入力'!B621","×入力へ")
P28: =IF(B28="","",IF(COUNTIF($B$5:$B$49,B28)>1,IF(A28="","",A28&" ")&B28,B28)) | Q28: =IF(B28="","",IF('×入力'!F649="未提出","未提出",IF(R28>0,"入力済み",IF('×入力'!F649="×なし（どこでもOK）","×なし","未入力")))) | R28: =IF(B28="","",'計算A'!IN33) | S28: =IF(OR(Q28="入力済み",Q28="×なし"),'計算A'!IM33,"") | T28: =IF('計算A'!C33=1,COUNTIFS('計算A'!$C$10:$C$54,1,'計算A'!$IM$10:$IM$54,"<"&'計算A'!IM33)+1,"") | U28: =IF('計算A'!IO33=0,"",INDEX('設定'!$E$11:$E$16,INDEX('計算A'!$D$2:$EQ$2,'計算A'!IO33))) | V28: =IF('計算A'!IO33=0,"",INDEX('設定'!$I$11:$I$34,INDEX('計算A'!$D$3:$EQ$3,'計算A'!IO33))) | W28: =IF(P28="","",IF('計算A'!JG33=1,"兄弟の日付・時刻が表にありません",IF(COUNTIF('調整・決定'!$C$6:$H$29,P28)>1,"2か所以上に入っています",IF('計算A'!IO33>0,IF(INDEX('計算A'!$D$4:$EQ$4,'計算A'!IO33)=0,"使えない枠に入っています",IF(INDEX('計算A'!$D$33:$EQ$33,'計算A'!IO33)=1,"×の枠に入っています",IF('計算A'!IV33=0,"（出来れば）兄弟の前後ではありません",IF(AND(RIGHT(D28,4)="空けたい",INDEX('計算A'!$D$106:$EQ$106,'計算A'!IO33)=1,INDEX('計算A'!$D$109:$EQ$109,'計算A'!IO33+1)=1),IF(D28="必ず空けたい","後ろの枠が空いていません","（出来れば）後ろが空いていません"),IF(AND(D28="空けない",INDEX('計算A'!$D$106:$EQ$106,'計算A'!IO33)=1,INDEX('計算A'!$D$109:$EQ$109,'計算A'!IO33+1)=0),"（出来れば）すぐ後が空いています",""))))),IF(OR(Q28="入力済み",Q28="×なし"),"未決定",""))))) | X28: =IF('計算A'!IK33=0,IF('計算A'!IL33=1,"入る枠がありません",""),INDEX('計算A'!$D$8:$EQ$8,'計算A'!IK33)) | Y28: =IF('計算A'!IR33=0,IF('計算A'!IS33=1,"入る枠がありません",""),INDEX('計算A'!$D$8:$EQ$8,'計算A'!IR33)) | Z28: =HYPERLINK("#'×入力'!B649","×入力へ")
P29: =IF(B29="","",IF(COUNTIF($B$5:$B$49,B29)>1,IF(A29="","",A29&" ")&B29,B29)) | Q29: =IF(B29="","",IF('×入力'!F677="未提出","未提出",IF(R29>0,"入力済み",IF('×入力'!F677="×なし（どこでもOK）","×なし","未入力")))) | R29: =IF(B29="","",'計算A'!IN34) | S29: =IF(OR(Q29="入力済み",Q29="×なし"),'計算A'!IM34,"") | T29: =IF('計算A'!C34=1,COUNTIFS('計算A'!$C$10:$C$54,1,'計算A'!$IM$10:$IM$54,"<"&'計算A'!IM34)+1,"") | U29: =IF('計算A'!IO34=0,"",INDEX('設定'!$E$11:$E$16,INDEX('計算A'!$D$2:$EQ$2,'計算A'!IO34))) | V29: =IF('計算A'!IO34=0,"",INDEX('設定'!$I$11:$I$34,INDEX('計算A'!$D$3:$EQ$3,'計算A'!IO34))) | W29: =IF(P29="","",IF('計算A'!JG34=1,"兄弟の日付・時刻が表にありません",IF(COUNTIF('調整・決定'!$C$6:$H$29,P29)>1,"2か所以上に入っています",IF('計算A'!IO34>0,IF(INDEX('計算A'!$D$4:$EQ$4,'計算A'!IO34)=0,"使えない枠に入っています",IF(INDEX('計算A'!$D$34:$EQ$34,'計算A'!IO34)=1,"×の枠に入っています",IF('計算A'!IV34=0,"（出来れば）兄弟の前後ではありません",IF(AND(RIGHT(D29,4)="空けたい",INDEX('計算A'!$D$106:$EQ$106,'計算A'!IO34)=1,INDEX('計算A'!$D$109:$EQ$109,'計算A'!IO34+1)=1),IF(D29="必ず空けたい","後ろの枠が空いていません","（出来れば）後ろが空いていません"),IF(AND(D29="空けない",INDEX('計算A'!$D$106:$EQ$106,'計算A'!IO34)=1,INDEX('計算A'!$D$109:$EQ$109,'計算A'!IO34+1)=0),"（出来れば）すぐ後が空いています",""))))),IF(OR(Q29="入力済み",Q29="×なし"),"未決定",""))))) | X29: =IF('計算A'!IK34=0,IF('計算A'!IL34=1,"入る枠がありません",""),INDEX('計算A'!$D$8:$EQ$8,'計算A'!IK34)) | Y29: =IF('計算A'!IR34=0,IF('計算A'!IS34=1,"入る枠がありません",""),INDEX('計算A'!$D$8:$EQ$8,'計算A'!IR34)) | Z29: =HYPERLINK("#'×入力'!B677","×入力へ")
P30: =IF(B30="","",IF(COUNTIF($B$5:$B$49,B30)>1,IF(A30="","",A30&" ")&B30,B30)) | Q30: =IF(B30="","",IF('×入力'!F705="未提出","未提出",IF(R30>0,"入力済み",IF('×入力'!F705="×なし（どこでもOK）","×なし","未入力")))) | R30: =IF(B30="","",'計算A'!IN35) | S30: =IF(OR(Q30="入力済み",Q30="×なし"),'計算A'!IM35,"") | T30: =IF('計算A'!C35=1,COUNTIFS('計算A'!$C$10:$C$54,1,'計算A'!$IM$10:$IM$54,"<"&'計算A'!IM35)+1,"") | U30: =IF('計算A'!IO35=0,"",INDEX('設定'!$E$11:$E$16,INDEX('計算A'!$D$2:$EQ$2,'計算A'!IO35))) | V30: =IF('計算A'!IO35=0,"",INDEX('設定'!$I$11:$I$34,INDEX('計算A'!$D$3:$EQ$3,'計算A'!IO35))) | W30: =IF(P30="","",IF('計算A'!JG35=1,"兄弟の日付・時刻が表にありません",IF(COUNTIF('調整・決定'!$C$6:$H$29,P30)>1,"2か所以上に入っています",IF('計算A'!IO35>0,IF(INDEX('計算A'!$D$4:$EQ$4,'計算A'!IO35)=0,"使えない枠に入っています",IF(INDEX('計算A'!$D$35:$EQ$35,'計算A'!IO35)=1,"×の枠に入っています",IF('計算A'!IV35=0,"（出来れば）兄弟の前後ではありません",IF(AND(RIGHT(D30,4)="空けたい",INDEX('計算A'!$D$106:$EQ$106,'計算A'!IO35)=1,INDEX('計算A'!$D$109:$EQ$109,'計算A'!IO35+1)=1),IF(D30="必ず空けたい","後ろの枠が空いていません","（出来れば）後ろが空いていません"),IF(AND(D30="空けない",INDEX('計算A'!$D$106:$EQ$106,'計算A'!IO35)=1,INDEX('計算A'!$D$109:$EQ$109,'計算A'!IO35+1)=0),"（出来れば）すぐ後が空いています",""))))),IF(OR(Q30="入力済み",Q30="×なし"),"未決定",""))))) | X30: =IF('計算A'!IK35=0,IF('計算A'!IL35=1,"入る枠がありません",""),INDEX('計算A'!$D$8:$EQ$8,'計算A'!IK35)) | Y30: =IF('計算A'!IR35=0,IF('計算A'!IS35=1,"入る枠がありません",""),INDEX('計算A'!$D$8:$EQ$8,'計算A'!IR35)) | Z30: =HYPERLINK("#'×入力'!B705","×入力へ")
P31: =IF(B31="","",IF(COUNTIF($B$5:$B$49,B31)>1,IF(A31="","",A31&" ")&B31,B31)) | Q31: =IF(B31="","",IF('×入力'!F733="未提出","未提出",IF(R31>0,"入力済み",IF('×入力'!F733="×なし（どこでもOK）","×なし","未入力")))) | R31: =IF(B31="","",'計算A'!IN36) | S31: =IF(OR(Q31="入力済み",Q31="×なし"),'計算A'!IM36,"") | T31: =IF('計算A'!C36=1,COUNTIFS('計算A'!$C$10:$C$54,1,'計算A'!$IM$10:$IM$54,"<"&'計算A'!IM36)+1,"") | U31: =IF('計算A'!IO36=0,"",INDEX('設定'!$E$11:$E$16,INDEX('計算A'!$D$2:$EQ$2,'計算A'!IO36))) | V31: =IF('計算A'!IO36=0,"",INDEX('設定'!$I$11:$I$34,INDEX('計算A'!$D$3:$EQ$3,'計算A'!IO36))) | W31: =IF(P31="","",IF('計算A'!JG36=1,"兄弟の日付・時刻が表にありません",IF(COUNTIF('調整・決定'!$C$6:$H$29,P31)>1,"2か所以上に入っています",IF('計算A'!IO36>0,IF(INDEX('計算A'!$D$4:$EQ$4,'計算A'!IO36)=0,"使えない枠に入っています",IF(INDEX('計算A'!$D$36:$EQ$36,'計算A'!IO36)=1,"×の枠に入っています",IF('計算A'!IV36=0,"（出来れば）兄弟の前後ではありません",IF(AND(RIGHT(D31,4)="空けたい",INDEX('計算A'!$D$106:$EQ$106,'計算A'!IO36)=1,INDEX('計算A'!$D$109:$EQ$109,'計算A'!IO36+1)=1),IF(D31="必ず空けたい","後ろの枠が空いていません","（出来れば）後ろが空いていません"),IF(AND(D31="空けない",INDEX('計算A'!$D$106:$EQ$106,'計算A'!IO36)=1,INDEX('計算A'!$D$109:$EQ$109,'計算A'!IO36+1)=0),"（出来れば）すぐ後が空いています",""))))),IF(OR(Q31="入力済み",Q31="×なし"),"未決定",""))))) | X31: =IF('計算A'!IK36=0,IF('計算A'!IL36=1,"入る枠がありません",""),INDEX('計算A'!$D$8:$EQ$8,'計算A'!IK36)) | Y31: =IF('計算A'!IR36=0,IF('計算A'!IS36=1,"入る枠がありません",""),INDEX('計算A'!$D$8:$EQ$8,'計算A'!IR36)) | Z31: =HYPERLINK("#'×入力'!B733","×入力へ")
P32: =IF(B32="","",IF(COUNTIF($B$5:$B$49,B32)>1,IF(A32="","",A32&" ")&B32,B32)) | Q32: =IF(B32="","",IF('×入力'!F761="未提出","未提出",IF(R32>0,"入力済み",IF('×入力'!F761="×なし（どこでもOK）","×なし","未入力")))) | R32: =IF(B32="","",'計算A'!IN37) | S32: =IF(OR(Q32="入力済み",Q32="×なし"),'計算A'!IM37,"") | T32: =IF('計算A'!C37=1,COUNTIFS('計算A'!$C$10:$C$54,1,'計算A'!$IM$10:$IM$54,"<"&'計算A'!IM37)+1,"") | U32: =IF('計算A'!IO37=0,"",INDEX('設定'!$E$11:$E$16,INDEX('計算A'!$D$2:$EQ$2,'計算A'!IO37))) | V32: =IF('計算A'!IO37=0,"",INDEX('設定'!$I$11:$I$34,INDEX('計算A'!$D$3:$EQ$3,'計算A'!IO37))) | W32: =IF(P32="","",IF('計算A'!JG37=1,"兄弟の日付・時刻が表にありません",IF(COUNTIF('調整・決定'!$C$6:$H$29,P32)>1,"2か所以上に入っています",IF('計算A'!IO37>0,IF(INDEX('計算A'!$D$4:$EQ$4,'計算A'!IO37)=0,"使えない枠に入っています",IF(INDEX('計算A'!$D$37:$EQ$37,'計算A'!IO37)=1,"×の枠に入っています",IF('計算A'!IV37=0,"（出来れば）兄弟の前後ではありません",IF(AND(RIGHT(D32,4)="空けたい",INDEX('計算A'!$D$106:$EQ$106,'計算A'!IO37)=1,INDEX('計算A'!$D$109:$EQ$109,'計算A'!IO37+1)=1),IF(D32="必ず空けたい","後ろの枠が空いていません","（出来れば）後ろが空いていません"),IF(AND(D32="空けない",INDEX('計算A'!$D$106:$EQ$106,'計算A'!IO37)=1,INDEX('計算A'!$D$109:$EQ$109,'計算A'!IO37+1)=0),"（出来れば）すぐ後が空いています",""))))),IF(OR(Q32="入力済み",Q32="×なし"),"未決定",""))))) | X32: =IF('計算A'!IK37=0,IF('計算A'!IL37=1,"入る枠がありません",""),INDEX('計算A'!$D$8:$EQ$8,'計算A'!IK37)) | Y32: =IF('計算A'!IR37=0,IF('計算A'!IS37=1,"入る枠がありません",""),INDEX('計算A'!$D$8:$EQ$8,'計算A'!IR37)) | Z32: =HYPERLINK("#'×入力'!B761","×入力へ")
P33: =IF(B33="","",IF(COUNTIF($B$5:$B$49,B33)>1,IF(A33="","",A33&" ")&B33,B33)) | Q33: =IF(B33="","",IF('×入力'!F789="未提出","未提出",IF(R33>0,"入力済み",IF('×入力'!F789="×なし（どこでもOK）","×なし","未入力")))) | R33: =IF(B33="","",'計算A'!IN38) | S33: =IF(OR(Q33="入力済み",Q33="×なし"),'計算A'!IM38,"") | T33: =IF('計算A'!C38=1,COUNTIFS('計算A'!$C$10:$C$54,1,'計算A'!$IM$10:$IM$54,"<"&'計算A'!IM38)+1,"") | U33: =IF('計算A'!IO38=0,"",INDEX('設定'!$E$11:$E$16,INDEX('計算A'!$D$2:$EQ$2,'計算A'!IO38))) | V33: =IF('計算A'!IO38=0,"",INDEX('設定'!$I$11:$I$34,INDEX('計算A'!$D$3:$EQ$3,'計算A'!IO38))) | W33: =IF(P33="","",IF('計算A'!JG38=1,"兄弟の日付・時刻が表にありません",IF(COUNTIF('調整・決定'!$C$6:$H$29,P33)>1,"2か所以上に入っています",IF('計算A'!IO38>0,IF(INDEX('計算A'!$D$4:$EQ$4,'計算A'!IO38)=0,"使えない枠に入っています",IF(INDEX('計算A'!$D$38:$EQ$38,'計算A'!IO38)=1,"×の枠に入っています",IF('計算A'!IV38=0,"（出来れば）兄弟の前後ではありません",IF(AND(RIGHT(D33,4)="空けたい",INDEX('計算A'!$D$106:$EQ$106,'計算A'!IO38)=1,INDEX('計算A'!$D$109:$EQ$109,'計算A'!IO38+1)=1),IF(D33="必ず空けたい","後ろの枠が空いていません","（出来れば）後ろが空いていません"),IF(AND(D33="空けない",INDEX('計算A'!$D$106:$EQ$106,'計算A'!IO38)=1,INDEX('計算A'!$D$109:$EQ$109,'計算A'!IO38+1)=0),"（出来れば）すぐ後が空いています",""))))),IF(OR(Q33="入力済み",Q33="×なし"),"未決定",""))))) | X33: =IF('計算A'!IK38=0,IF('計算A'!IL38=1,"入る枠がありません",""),INDEX('計算A'!$D$8:$EQ$8,'計算A'!IK38)) | Y33: =IF('計算A'!IR38=0,IF('計算A'!IS38=1,"入る枠がありません",""),INDEX('計算A'!$D$8:$EQ$8,'計算A'!IR38)) | Z33: =HYPERLINK("#'×入力'!B789","×入力へ")
P34: =IF(B34="","",IF(COUNTIF($B$5:$B$49,B34)>1,IF(A34="","",A34&" ")&B34,B34)) | Q34: =IF(B34="","",IF('×入力'!F817="未提出","未提出",IF(R34>0,"入力済み",IF('×入力'!F817="×なし（どこでもOK）","×なし","未入力")))) | R34: =IF(B34="","",'計算A'!IN39) | S34: =IF(OR(Q34="入力済み",Q34="×なし"),'計算A'!IM39,"") | T34: =IF('計算A'!C39=1,COUNTIFS('計算A'!$C$10:$C$54,1,'計算A'!$IM$10:$IM$54,"<"&'計算A'!IM39)+1,"") | U34: =IF('計算A'!IO39=0,"",INDEX('設定'!$E$11:$E$16,INDEX('計算A'!$D$2:$EQ$2,'計算A'!IO39))) | V34: =IF('計算A'!IO39=0,"",INDEX('設定'!$I$11:$I$34,INDEX('計算A'!$D$3:$EQ$3,'計算A'!IO39))) | W34: =IF(P34="","",IF('計算A'!JG39=1,"兄弟の日付・時刻が表にありません",IF(COUNTIF('調整・決定'!$C$6:$H$29,P34)>1,"2か所以上に入っています",IF('計算A'!IO39>0,IF(INDEX('計算A'!$D$4:$EQ$4,'計算A'!IO39)=0,"使えない枠に入っています",IF(INDEX('計算A'!$D$39:$EQ$39,'計算A'!IO39)=1,"×の枠に入っています",IF('計算A'!IV39=0,"（出来れば）兄弟の前後ではありません",IF(AND(RIGHT(D34,4)="空けたい",INDEX('計算A'!$D$106:$EQ$106,'計算A'!IO39)=1,INDEX('計算A'!$D$109:$EQ$109,'計算A'!IO39+1)=1),IF(D34="必ず空けたい","後ろの枠が空いていません","（出来れば）後ろが空いていません"),IF(AND(D34="空けない",INDEX('計算A'!$D$106:$EQ$106,'計算A'!IO39)=1,INDEX('計算A'!$D$109:$EQ$109,'計算A'!IO39+1)=0),"（出来れば）すぐ後が空いています",""))))),IF(OR(Q34="入力済み",Q34="×なし"),"未決定",""))))) | X34: =IF('計算A'!IK39=0,IF('計算A'!IL39=1,"入る枠がありません",""),INDEX('計算A'!$D$8:$EQ$8,'計算A'!IK39)) | Y34: =IF('計算A'!IR39=0,IF('計算A'!IS39=1,"入る枠がありません",""),INDEX('計算A'!$D$8:$EQ$8,'計算A'!IR39)) | Z34: =HYPERLINK("#'×入力'!B817","×入力へ")
P35: =IF(B35="","",IF(COUNTIF($B$5:$B$49,B35)>1,IF(A35="","",A35&" ")&B35,B35)) | Q35: =IF(B35="","",IF('×入力'!F845="未提出","未提出",IF(R35>0,"入力済み",IF('×入力'!F845="×なし（どこでもOK）","×なし","未入力")))) | R35: =IF(B35="","",'計算A'!IN40) | S35: =IF(OR(Q35="入力済み",Q35="×なし"),'計算A'!IM40,"") | T35: =IF('計算A'!C40=1,COUNTIFS('計算A'!$C$10:$C$54,1,'計算A'!$IM$10:$IM$54,"<"&'計算A'!IM40)+1,"") | U35: =IF('計算A'!IO40=0,"",INDEX('設定'!$E$11:$E$16,INDEX('計算A'!$D$2:$EQ$2,'計算A'!IO40))) | V35: =IF('計算A'!IO40=0,"",INDEX('設定'!$I$11:$I$34,INDEX('計算A'!$D$3:$EQ$3,'計算A'!IO40))) | W35: =IF(P35="","",IF('計算A'!JG40=1,"兄弟の日付・時刻が表にありません",IF(COUNTIF('調整・決定'!$C$6:$H$29,P35)>1,"2か所以上に入っています",IF('計算A'!IO40>0,IF(INDEX('計算A'!$D$4:$EQ$4,'計算A'!IO40)=0,"使えない枠に入っています",IF(INDEX('計算A'!$D$40:$EQ$40,'計算A'!IO40)=1,"×の枠に入っています",IF('計算A'!IV40=0,"（出来れば）兄弟の前後ではありません",IF(AND(RIGHT(D35,4)="空けたい",INDEX('計算A'!$D$106:$EQ$106,'計算A'!IO40)=1,INDEX('計算A'!$D$109:$EQ$109,'計算A'!IO40+1)=1),IF(D35="必ず空けたい","後ろの枠が空いていません","（出来れば）後ろが空いていません"),IF(AND(D35="空けない",INDEX('計算A'!$D$106:$EQ$106,'計算A'!IO40)=1,INDEX('計算A'!$D$109:$EQ$109,'計算A'!IO40+1)=0),"（出来れば）すぐ後が空いています",""))))),IF(OR(Q35="入力済み",Q35="×なし"),"未決定",""))))) | X35: =IF('計算A'!IK40=0,IF('計算A'!IL40=1,"入る枠がありません",""),INDEX('計算A'!$D$8:$EQ$8,'計算A'!IK40)) | Y35: =IF('計算A'!IR40=0,IF('計算A'!IS40=1,"入る枠がありません",""),INDEX('計算A'!$D$8:$EQ$8,'計算A'!IR40)) | Z35: =HYPERLINK("#'×入力'!B845","×入力へ")
P36: =IF(B36="","",IF(COUNTIF($B$5:$B$49,B36)>1,IF(A36="","",A36&" ")&B36,B36)) | Q36: =IF(B36="","",IF('×入力'!F873="未提出","未提出",IF(R36>0,"入力済み",IF('×入力'!F873="×なし（どこでもOK）","×なし","未入力")))) | R36: =IF(B36="","",'計算A'!IN41) | S36: =IF(OR(Q36="入力済み",Q36="×なし"),'計算A'!IM41,"") | T36: =IF('計算A'!C41=1,COUNTIFS('計算A'!$C$10:$C$54,1,'計算A'!$IM$10:$IM$54,"<"&'計算A'!IM41)+1,"") | U36: =IF('計算A'!IO41=0,"",INDEX('設定'!$E$11:$E$16,INDEX('計算A'!$D$2:$EQ$2,'計算A'!IO41))) | V36: =IF('計算A'!IO41=0,"",INDEX('設定'!$I$11:$I$34,INDEX('計算A'!$D$3:$EQ$3,'計算A'!IO41))) | W36: =IF(P36="","",IF('計算A'!JG41=1,"兄弟の日付・時刻が表にありません",IF(COUNTIF('調整・決定'!$C$6:$H$29,P36)>1,"2か所以上に入っています",IF('計算A'!IO41>0,IF(INDEX('計算A'!$D$4:$EQ$4,'計算A'!IO41)=0,"使えない枠に入っています",IF(INDEX('計算A'!$D$41:$EQ$41,'計算A'!IO41)=1,"×の枠に入っています",IF('計算A'!IV41=0,"（出来れば）兄弟の前後ではありません",IF(AND(RIGHT(D36,4)="空けたい",INDEX('計算A'!$D$106:$EQ$106,'計算A'!IO41)=1,INDEX('計算A'!$D$109:$EQ$109,'計算A'!IO41+1)=1),IF(D36="必ず空けたい","後ろの枠が空いていません","（出来れば）後ろが空いていません"),IF(AND(D36="空けない",INDEX('計算A'!$D$106:$EQ$106,'計算A'!IO41)=1,INDEX('計算A'!$D$109:$EQ$109,'計算A'!IO41+1)=0),"（出来れば）すぐ後が空いています",""))))),IF(OR(Q36="入力済み",Q36="×なし"),"未決定",""))))) | X36: =IF('計算A'!IK41=0,IF('計算A'!IL41=1,"入る枠がありません",""),INDEX('計算A'!$D$8:$EQ$8,'計算A'!IK41)) | Y36: =IF('計算A'!IR41=0,IF('計算A'!IS41=1,"入る枠がありません",""),INDEX('計算A'!$D$8:$EQ$8,'計算A'!IR41)) | Z36: =HYPERLINK("#'×入力'!B873","×入力へ")
P37: =IF(B37="","",IF(COUNTIF($B$5:$B$49,B37)>1,IF(A37="","",A37&" ")&B37,B37)) | Q37: =IF(B37="","",IF('×入力'!F901="未提出","未提出",IF(R37>0,"入力済み",IF('×入力'!F901="×なし（どこでもOK）","×なし","未入力")))) | R37: =IF(B37="","",'計算A'!IN42) | S37: =IF(OR(Q37="入力済み",Q37="×なし"),'計算A'!IM42,"") | T37: =IF('計算A'!C42=1,COUNTIFS('計算A'!$C$10:$C$54,1,'計算A'!$IM$10:$IM$54,"<"&'計算A'!IM42)+1,"") | U37: =IF('計算A'!IO42=0,"",INDEX('設定'!$E$11:$E$16,INDEX('計算A'!$D$2:$EQ$2,'計算A'!IO42))) | V37: =IF('計算A'!IO42=0,"",INDEX('設定'!$I$11:$I$34,INDEX('計算A'!$D$3:$EQ$3,'計算A'!IO42))) | W37: =IF(P37="","",IF('計算A'!JG42=1,"兄弟の日付・時刻が表にありません",IF(COUNTIF('調整・決定'!$C$6:$H$29,P37)>1,"2か所以上に入っています",IF('計算A'!IO42>0,IF(INDEX('計算A'!$D$4:$EQ$4,'計算A'!IO42)=0,"使えない枠に入っています",IF(INDEX('計算A'!$D$42:$EQ$42,'計算A'!IO42)=1,"×の枠に入っています",IF('計算A'!IV42=0,"（出来れば）兄弟の前後ではありません",IF(AND(RIGHT(D37,4)="空けたい",INDEX('計算A'!$D$106:$EQ$106,'計算A'!IO42)=1,INDEX('計算A'!$D$109:$EQ$109,'計算A'!IO42+1)=1),IF(D37="必ず空けたい","後ろの枠が空いていません","（出来れば）後ろが空いていません"),IF(AND(D37="空けない",INDEX('計算A'!$D$106:$EQ$106,'計算A'!IO42)=1,INDEX('計算A'!$D$109:$EQ$109,'計算A'!IO42+1)=0),"（出来れば）すぐ後が空いています",""))))),IF(OR(Q37="入力済み",Q37="×なし"),"未決定",""))))) | X37: =IF('計算A'!IK42=0,IF('計算A'!IL42=1,"入る枠がありません",""),INDEX('計算A'!$D$8:$EQ$8,'計算A'!IK42)) | Y37: =IF('計算A'!IR42=0,IF('計算A'!IS42=1,"入る枠がありません",""),INDEX('計算A'!$D$8:$EQ$8,'計算A'!IR42)) | Z37: =HYPERLINK("#'×入力'!B901","×入力へ")
P38: =IF(B38="","",IF(COUNTIF($B$5:$B$49,B38)>1,IF(A38="","",A38&" ")&B38,B38)) | Q38: =IF(B38="","",IF('×入力'!F929="未提出","未提出",IF(R38>0,"入力済み",IF('×入力'!F929="×なし（どこでもOK）","×なし","未入力")))) | R38: =IF(B38="","",'計算A'!IN43) | S38: =IF(OR(Q38="入力済み",Q38="×なし"),'計算A'!IM43,"") | T38: =IF('計算A'!C43=1,COUNTIFS('計算A'!$C$10:$C$54,1,'計算A'!$IM$10:$IM$54,"<"&'計算A'!IM43)+1,"") | U38: =IF('計算A'!IO43=0,"",INDEX('設定'!$E$11:$E$16,INDEX('計算A'!$D$2:$EQ$2,'計算A'!IO43))) | V38: =IF('計算A'!IO43=0,"",INDEX('設定'!$I$11:$I$34,INDEX('計算A'!$D$3:$EQ$3,'計算A'!IO43))) | W38: =IF(P38="","",IF('計算A'!JG43=1,"兄弟の日付・時刻が表にありません",IF(COUNTIF('調整・決定'!$C$6:$H$29,P38)>1,"2か所以上に入っています",IF('計算A'!IO43>0,IF(INDEX('計算A'!$D$4:$EQ$4,'計算A'!IO43)=0,"使えない枠に入っています",IF(INDEX('計算A'!$D$43:$EQ$43,'計算A'!IO43)=1,"×の枠に入っています",IF('計算A'!IV43=0,"（出来れば）兄弟の前後ではありません",IF(AND(RIGHT(D38,4)="空けたい",INDEX('計算A'!$D$106:$EQ$106,'計算A'!IO43)=1,INDEX('計算A'!$D$109:$EQ$109,'計算A'!IO43+1)=1),IF(D38="必ず空けたい","後ろの枠が空いていません","（出来れば）後ろが空いていません"),IF(AND(D38="空けない",INDEX('計算A'!$D$106:$EQ$106,'計算A'!IO43)=1,INDEX('計算A'!$D$109:$EQ$109,'計算A'!IO43+1)=0),"（出来れば）すぐ後が空いています",""))))),IF(OR(Q38="入力済み",Q38="×なし"),"未決定",""))))) | X38: =IF('計算A'!IK43=0,IF('計算A'!IL43=1,"入る枠がありません",""),INDEX('計算A'!$D$8:$EQ$8,'計算A'!IK43)) | Y38: =IF('計算A'!IR43=0,IF('計算A'!IS43=1,"入る枠がありません",""),INDEX('計算A'!$D$8:$EQ$8,'計算A'!IR43)) | Z38: =HYPERLINK("#'×入力'!B929","×入力へ")
P39: =IF(B39="","",IF(COUNTIF($B$5:$B$49,B39)>1,IF(A39="","",A39&" ")&B39,B39)) | Q39: =IF(B39="","",IF('×入力'!F957="未提出","未提出",IF(R39>0,"入力済み",IF('×入力'!F957="×なし（どこでもOK）","×なし","未入力")))) | R39: =IF(B39="","",'計算A'!IN44) | S39: =IF(OR(Q39="入力済み",Q39="×なし"),'計算A'!IM44,"") | T39: =IF('計算A'!C44=1,COUNTIFS('計算A'!$C$10:$C$54,1,'計算A'!$IM$10:$IM$54,"<"&'計算A'!IM44)+1,"") | U39: =IF('計算A'!IO44=0,"",INDEX('設定'!$E$11:$E$16,INDEX('計算A'!$D$2:$EQ$2,'計算A'!IO44))) | V39: =IF('計算A'!IO44=0,"",INDEX('設定'!$I$11:$I$34,INDEX('計算A'!$D$3:$EQ$3,'計算A'!IO44))) | W39: =IF(P39="","",IF('計算A'!JG44=1,"兄弟の日付・時刻が表にありません",IF(COUNTIF('調整・決定'!$C$6:$H$29,P39)>1,"2か所以上に入っています",IF('計算A'!IO44>0,IF(INDEX('計算A'!$D$4:$EQ$4,'計算A'!IO44)=0,"使えない枠に入っています",IF(INDEX('計算A'!$D$44:$EQ$44,'計算A'!IO44)=1,"×の枠に入っています",IF('計算A'!IV44=0,"（出来れば）兄弟の前後ではありません",IF(AND(RIGHT(D39,4)="空けたい",INDEX('計算A'!$D$106:$EQ$106,'計算A'!IO44)=1,INDEX('計算A'!$D$109:$EQ$109,'計算A'!IO44+1)=1),IF(D39="必ず空けたい","後ろの枠が空いていません","（出来れば）後ろが空いていません"),IF(AND(D39="空けない",INDEX('計算A'!$D$106:$EQ$106,'計算A'!IO44)=1,INDEX('計算A'!$D$109:$EQ$109,'計算A'!IO44+1)=0),"（出来れば）すぐ後が空いています",""))))),IF(OR(Q39="入力済み",Q39="×なし"),"未決定",""))))) | X39: =IF('計算A'!IK44=0,IF('計算A'!IL44=1,"入る枠がありません",""),INDEX('計算A'!$D$8:$EQ$8,'計算A'!IK44)) | Y39: =IF('計算A'!IR44=0,IF('計算A'!IS44=1,"入る枠がありません",""),INDEX('計算A'!$D$8:$EQ$8,'計算A'!IR44)) | Z39: =HYPERLINK("#'×入力'!B957","×入力へ")
P40: =IF(B40="","",IF(COUNTIF($B$5:$B$49,B40)>1,IF(A40="","",A40&" ")&B40,B40)) | Q40: =IF(B40="","",IF('×入力'!F985="未提出","未提出",IF(R40>0,"入力済み",IF('×入力'!F985="×なし（どこでもOK）","×なし","未入力")))) | R40: =IF(B40="","",'計算A'!IN45) | S40: =IF(OR(Q40="入力済み",Q40="×なし"),'計算A'!IM45,"") | T40: =IF('計算A'!C45=1,COUNTIFS('計算A'!$C$10:$C$54,1,'計算A'!$IM$10:$IM$54,"<"&'計算A'!IM45)+1,"") | U40: =IF('計算A'!IO45=0,"",INDEX('設定'!$E$11:$E$16,INDEX('計算A'!$D$2:$EQ$2,'計算A'!IO45))) | V40: =IF('計算A'!IO45=0,"",INDEX('設定'!$I$11:$I$34,INDEX('計算A'!$D$3:$EQ$3,'計算A'!IO45))) | W40: =IF(P40="","",IF('計算A'!JG45=1,"兄弟の日付・時刻が表にありません",IF(COUNTIF('調整・決定'!$C$6:$H$29,P40)>1,"2か所以上に入っています",IF('計算A'!IO45>0,IF(INDEX('計算A'!$D$4:$EQ$4,'計算A'!IO45)=0,"使えない枠に入っています",IF(INDEX('計算A'!$D$45:$EQ$45,'計算A'!IO45)=1,"×の枠に入っています",IF('計算A'!IV45=0,"（出来れば）兄弟の前後ではありません",IF(AND(RIGHT(D40,4)="空けたい",INDEX('計算A'!$D$106:$EQ$106,'計算A'!IO45)=1,INDEX('計算A'!$D$109:$EQ$109,'計算A'!IO45+1)=1),IF(D40="必ず空けたい","後ろの枠が空いていません","（出来れば）後ろが空いていません"),IF(AND(D40="空けない",INDEX('計算A'!$D$106:$EQ$106,'計算A'!IO45)=1,INDEX('計算A'!$D$109:$EQ$109,'計算A'!IO45+1)=0),"（出来れば）すぐ後が空いています",""))))),IF(OR(Q40="入力済み",Q40="×なし"),"未決定",""))))) | X40: =IF('計算A'!IK45=0,IF('計算A'!IL45=1,"入る枠がありません",""),INDEX('計算A'!$D$8:$EQ$8,'計算A'!IK45)) | Y40: =IF('計算A'!IR45=0,IF('計算A'!IS45=1,"入る枠がありません",""),INDEX('計算A'!$D$8:$EQ$8,'計算A'!IR45)) | Z40: =HYPERLINK("#'×入力'!B985","×入力へ")
...

Sheet ×入力
B1: ×入力 | F1: =HYPERLINK("#'ホーム'!A1","ホーム") | G1: =HYPERLINK("#'設定'!A1","① 設定") | H1: =HYPERLINK("#'名簿'!A1","② 名簿") | I1: =HYPERLINK("#'×入力'!A1","③ ×入力") | J1: =HYPERLINK("#'自動案A'!A1","④ 自動案A") | K1: =HYPERLINK("#'自動案B'!A1","④ 自動案B") | L1: =HYPERLINK("#'調整・決定'!A1","⑤ 調整・決定") | M1: =HYPERLINK("#'兄弟確認用'!A1","⑥ 兄弟確認") | N1: =HYPERLINK("#'お手紙（夏）'!A1","⑦ お手紙 夏") | O1: =HYPERLINK("#'お手紙（秋）'!A1","⑧ お手紙 秋")
B2: 都合の悪い枠に「×」。日付の上の欄で「×」→その日全部、時刻の左の欄で「×」→その時間全部が×になります。消すときは Delete。
