Workbook

Sheet ①データ入力
I1: 名簿から名前をコピペして使ってください。３年生以上は性別欄を記入しないと動きません。タイムまで入力したら②のシートへ
A2: No. | B2: 1組 名前 | C2: 性別 (1=男子 2=女子) | D2: タイム (1/100秒) | E2: 赤or白 | G2: 2組 名前 | H2: 性別 (1=男子 2=女子) | I2: タイム (1/100秒) | J2: 赤or白 | L2: 3組 名前 | M2: 性別 (1=男子 2=女子) | N2: タイム (1/100秒) | O2: 赤or白 | Q2: 4組 名前 | R2: 性別 (1=男子 2=女子) | S2: タイム (1/100秒) | T2: 赤or白 | V2: 5組 名前 | W2: 性別 (1=男子 2=女子) | X2: タイム (1/100秒) | Y2: 赤or白
A3: 1 | B3: 木村 りく | C3: 1 | D3: 8.85 | E3: 赤 | G3: 高橋 まお | H3: 2 | I3: 9.58 | J3: 赤 | L3: 藤田 そうた | M3: 1 | N3: 9.37 | O3: 赤 | Q3: 小林 みなと | R3: 1 | S3: 9.11 | T3: 赤
A4: 2 | B4: 木村 ゆな | C4: 2 | D4: 9.76 | E4: 白 | G4: 高橋 ひまり | H4: 2 | I4: 8.97 | J4: 赤 | L4: 伊藤 さくら | M4: 2 | N4: 10.88 | O4: 白 | Q4: 清水 ゆな | R4: 2 | S4: 9.29 | T4: 赤
A5: 3 | B5: 後藤 ひなた | C5: 1 | D5: 9.91 | E5: 赤 | G5: 佐藤 そうた | H5: 1 | I5: 9.34 | J5: 赤 | L5: 木村 ことね | M5: 2 | N5: 8.52 | O5: 白 | Q5: 山田 あおい | R5: 2 | S5: 9.53 | T5: 白
A6: 4 | B6: 井上 かのん | C6: 2 | D6: 9.64 | E6: 白 | G6: 後藤 ゆうと | H6: 1 | I6: 8.47 | J6: 白 | L6: 井上 だいち | M6: 1 | N6: 8.89 | O6: 赤 | Q6: 佐藤 ひまり | R6: 2 | S6: 9.73 | T6: 赤
A7: 5 | B7: 石川 ほのか | C7: 2 | D7: 9.43 | E7: 白 | G7: 後藤 さく | H7: 1 | I7: 9.24 | J7: 白 | L7: 斎藤 いつき | M7: 1 | N7: 8.77 | O7: 白 | Q7: 松本 そうた | R7: 1 | S7: 9.36 | T7: 白
A8: 6 | B8: 山本 かいと | C8: 1 | D8: 8.65 | E8: 白 | G8: 加藤 あおい | H8: 1 | I8: 8.98 | J8: 白 | L8: 木村 みお | M8: 2 | N8: 9.7 | O8: 白 | Q8: 清水 ひな | R8: 2 | S8: 9.21 | T8: 白
A9: 7 | B9: 井上 けんた | C9: 1 | D9: 9.27 | E9: 赤 | G9: 伊藤 りょう | H9: 1 | I9: 8.76 | J9: 赤 | L9: 伊藤 ゆな | M9: 2 | N9: 10.22 | O9: 赤 | Q9: 山田 ひな | R9: 2 | S9: 10.22 | T9: 白
A10: 8 | B10: 佐藤 こはる | C10: 2 | D10: 9.77 | E10: 赤 | G10: 山本 ことね | H10: 2 | I10: 9.83 | J10: 赤 | L10: 吉田 ひなた | M10: 1 | N10: 9.06 | O10: 赤 | Q10: 伊藤 ひまり | R10: 2 | S10: 10.36 | T10: 白
A11: 9 | B11: 小林 けんた | C11: 1 | D11: 9.27 | E11: 赤 | G11: 伊藤 かいと | H11: 1 | I11: 8.54 | J11: 白 | L11: 高橋 ひなた | M11: 1 | N11: 9.94 | O11: 赤 | Q11: 森 ひまり | R11: 2 | S11: 9.83 | T11: 白
A12: 10 | B12: 中村 さら | C12: 2 | D12: 8.37 | E12: 白 | G12: 佐藤 ゆい | H12: 2 | I12: 10.91 | J12: 白 | L12: 小林 めい | M12: 2 | N12: 9.87 | O12: 赤 | Q12: 石川 はると | R12: 1 | S12: 9.67 | T12: 白
A13: 11 | B13: 松本 ゆな | C13: 2 | D13: 9.55 | E13: 白 | G13: 岡田 つむぎ | H13: 2 | I13: 9.33 | J13: 白 | L13: 石川 ほのか | M13: 2 | N13: 10.16 | O13: 赤 | Q13: 村上 りく | R13: 1 | S13: 9.55 | T13: 白
A14: 12 | B14: 山本 りょう | C14: 1 | D14: 8.36 | E14: 赤 | G14: 池田 みなと | H14: 1 | I14: 9.52 | J14: 白 | L14: 近藤 みなと | M14: 1 | N14: 9.11 | O14: 白 | Q14: 清水 めい | R14: 2 | S14: 10.56 | T14: 白
... A24: 22 | B24: 石川 れん | C24: 1 | D24: 8.64 | E24: 白 | G24: 木村 りん | H24: 2 | I24: 9.35 | J24: 白 | L24: 加藤 こうき | M24: 1 | N24: 8.41 | O24: 白 | Q24: 岡田 そうた | R24: 1 | S24: 8.12 | T24: 白
A25: 23 | B25: 岡田 さら | C25: 2 | D25: 9.3 | E25: 赤
A26: 24 | B26: 村上 かいと | C26: 1 | D26: 9.35 | E26: 白
A27: 25
A28: 26
A29: 27
A30: 28
A31: 29
A32: 30
A33: 31
A34: 32
A35: 33
A36: 34
A37: 35
A38: 36
A39: 37

Sheet 組ごとタイム順
A1: 男子 | J1: 女子 | S1: =IF(計算用!$Q$6>0,"※名前はあるのに性別・タイム・赤白のどれかが未入力で、表に出ていない人が"&計算用!$Q$6&"人います","")
B2: 赤組 | F2: 白組 | K2: 赤組 | O2: 白組
B3: 名前 | C3: クラス | D3: タイム | F3: 名前 | G3: クラス | H3: タイム | K3: 名前 | L3: クラス | M3: タイム | O3: 名前 | P3: クラス | Q3: タイム
A4: =IF(ROW()-3<=MAX(計算用!$Q$2,計算用!$Q$3),ROW()-3,"") | B4: =IFERROR(INDEX(計算用!$D$2:$D$186,MATCH("男赤"&$A4,計算用!$L$2:$L$186,0)),"") | C4: =IFERROR(INDEX(計算用!$M$2:$M$186,MATCH("男赤"&$A4,計算用!$L$2:$L$186,0)),"") | D4: =IFERROR(INDEX(計算用!$G$2:$G$186,MATCH("男赤"&$A4,計算用!$L$2:$L$186,0)),"") | F4: =IFERROR(INDEX(計算用!$D$2:$D$186,MATCH("男白"&$A4,計算用!$L$2:$L$186,0)),"") | G4: =IFERROR(INDEX(計算用!$M$2:$M$186,MATCH("男白"&$A4,計算用!$L$2:$L$186,0)),"") | H4: =IFERROR(INDEX(計算用!$G$2:$G$186,MATCH("男白"&$A4,計算用!$L$2:$L$186,0)),"") | J4: =IF(ROW()-3<=MAX(計算用!$Q$4,計算用!$Q$5),ROW()-3,"") | K4: =IFERROR(INDEX(計算用!$D$2:$D$186,MATCH("女赤"&$J4,計算用!$L$2:$L$186,0)),"") | L4: =IFERROR(INDEX(計算用!$M$2:$M$186,MATCH("女赤"&$J4,計算用!$L$2:$L$186,0)),"") | M4: =IFERROR(INDEX(計算用!$G$2:$G$186,MATCH("女赤"&$J4,計算用!$L$2:$L$186,0)),"") | O4: =IFERROR(INDEX(計算用!$D$2:$D$186,MATCH("女白"&$J4,計算用!$L$2:$L$186,0)),"") | P4: =IFERROR(INDEX(計算用!$M$2:$M$186,MATCH("女白"&$J4,計算用!$L$2:$L$186,0)),"") | Q4: =IFERROR(INDEX(計算用!$G$2:$G$186,MATCH("女白"&$J4,計算用!$L$2:$L$186,0)),"")
A5: =IF(ROW()-3<=MAX(計算用!$Q$2,計算用!$Q$3),ROW()-3,"") | B5: =IFERROR(INDEX(計算用!$D$2:$D$186,MATCH("男赤"&$A5,計算用!$L$2:$L$186,0)),"") | C5: =IFERROR(INDEX(計算用!$M$2:$M$186,MATCH("男赤"&$A5,計算用!$L$2:$L$186,0)),"") | D5: =IFERROR(INDEX(計算用!$G$2:$G$186,MATCH("男赤"&$A5,計算用!$L$2:$L$186,0)),"") | F5: =IFERROR(INDEX(計算用!$D$2:$D$186,MATCH("男白"&$A5,計算用!$L$2:$L$186,0)),"") | G5: =IFERROR(INDEX(計算用!$M$2:$M$186,MATCH("男白"&$A5,計算用!$L$2:$L$186,0)),"") | H5: =IFERROR(INDEX(計算用!$G$2:$G$186,MATCH("男白"&$A5,計算用!$L$2:$L$186,0)),"") | J5: =IF(ROW()-3<=MAX(計算用!$Q$4,計算用!$Q$5),ROW()-3,"") | K5: =IFERROR(INDEX(計算用!$D$2:$D$186,MATCH("女赤"&$J5,計算用!$L$2:$L$186,0)),"") | L5: =IFERROR(INDEX(計算用!$M$2:$M$186,MATCH("女赤"&$J5,計算用!$L$2:$L$186,0)),"") | M5: =IFERROR(INDEX(計算用!$G$2:$G$186,MATCH("女赤"&$J5,計算用!$L$2:$L$186,0)),"") | O5: =IFERROR(INDEX(計算用!$D$2:$D$186,MATCH("女白"&$J5,計算用!$L$2:$L$186,0)),"") | P5: =IFERROR(INDEX(計算用!$M$2:$M$186,MATCH("女白"&$J5,計算用!$L$2:$L$186,0)),"") | Q5: =IFERROR(INDEX(計算用!$G$2:$G$186,MATCH("女白"&$J5,計算用!$L$2:$L$186,0)),"")
A6: =IF(ROW()-3<=MAX(計算用!$Q$2,計算用!$Q$3),ROW()-3,"") | B6: =IFERROR(INDEX(計算用!$D$2:$D$186,MATCH("男赤"&$A6,計算用!$L$2:$L$186,0)),"") | C6: =IFERROR(INDEX(計算用!$M$2:$M$186,MATCH("男赤"&$A6,計算用!$L$2:$L$186,0)),"") | D6: =IFERROR(INDEX(計算用!$G$2:$G$186,MATCH("男赤"&$A6,計算用!$L$2:$L$186,0)),"") | F6: =IFERROR(INDEX(計算用!$D$2:$D$186,MATCH("男白"&$A6,計算用!$L$2:$L$186,0)),"") | G6: =IFERROR(INDEX(計算用!$M$2:$M$186,MATCH("男白"&$A6,計算用!$L$2:$L$186,0)),"") | H6: =IFERROR(INDEX(計算用!$G$2:$G$186,MATCH("男白"&$A6,計算用!$L$2:$L$186,0)),"") | J6: =IF(ROW()-3<=MAX(計算用!$Q$4,計算用!$Q$5),ROW()-3,"") | K6: =IFERROR(INDEX(計算用!$D$2:$D$186,MATCH("女赤"&$J6,計算用!$L$2:$L$186,0)),"") | L6: =IFERROR(INDEX(計算用!$M$2:$M$186,MATCH("女赤"&$J6,計算用!$L$2:$L$186,0)),"") | M6: =IFERROR(INDEX(計算用!$G$2:$G$186,MATCH("女赤"&$J6,計算用!$L$2:$L$186,0)),"") | O6: =IFERROR(INDEX(計算用!$D$2:$D$186,MATCH("女白"&$J6,計算用!$L$2:$L$186,0)),"") | P6: =IFERROR(INDEX(計算用!$M$2:$M$186,MATCH("女白"&$J6,計算用!$L$2:$L$186,0)),"") | Q6: =IFERROR(INDEX(計算用!$G$2:$G$186,MATCH("女白"&$J6,計算用!$L$2:$L$186,0)),"")
A7: =IF(ROW()-3<=MAX(計算用!$Q$2,計算用!$Q$3),ROW()-3,"") | B7: =IFERROR(INDEX(計算用!$D$2:$D$186,MATCH("男赤"&$A7,計算用!$L$2:$L$186,0)),"") | C7: =IFERROR(INDEX(計算用!$M$2:$M$186,MATCH("男赤"&$A7,計算用!$L$2:$L$186,0)),"") | D7: =IFERROR(INDEX(計算用!$G$2:$G$186,MATCH("男赤"&$A7,計算用!$L$2:$L$186,0)),"") | F7: =IFERROR(INDEX(計算用!$D$2:$D$186,MATCH("男白"&$A7,計算用!$L$2:$L$186,0)),"") | G7: =IFERROR(INDEX(計算用!$M$2:$M$186,MATCH("男白"&$A7,計算用!$L$2:$L$186,0)),"") | H7: =IFERROR(INDEX(計算用!$G$2:$G$186,MATCH("男白"&$A7,計算用!$L$2:$L$186,0)),"") | J7: =IF(ROW()-3<=MAX(計算用!$Q$4,計算用!$Q$5),ROW()-3,"") | K7: =IFERROR(INDEX(計算用!$D$2:$D$186,MATCH("女赤"&$J7,計算用!$L$2:$L$186,0)),"") | L7: =IFERROR(INDEX(計算用!$M$2:$M$186,MATCH("女赤"&$J7,計算用!$L$2:$L$186,0)),"") | M7: =IFERROR(INDEX(計算用!$G$2:$G$186,MATCH("女赤"&$J7,計算用!$L$2:$L$186,0)),"") | O7: =IFERROR(INDEX(計算用!$D$2:$D$186,MATCH("女白"&$J7,計算用!$L$2:$L$186,0)),"") | P7: =IFERROR(INDEX(計算用!$M$2:$M$186,MATCH("女白"&$J7,計算用!$L$2:$L$186,0)),"") | Q7: =IFERROR(INDEX(計算用!$G$2:$G$186,MATCH("女白"&$J7,計算用!$L$2:$L$186,0)),"")
A8: =IF(ROW()-3<=MAX(計算用!$Q$2,計算用!$Q$3),ROW()-3,"") | B8: =IFERROR(INDEX(計算用!$D$2:$D$186,MATCH("男赤"&$A8,計算用!$L$2:$L$186,0)),"") | C8: =IFERROR(INDEX(計算用!$M$2:$M$186,MATCH("男赤"&$A8,計算用!$L$2:$L$186,0)),"") | D8: =IFERROR(INDEX(計算用!$G$2:$G$186,MATCH("男赤"&$A8,計算用!$L$2:$L$186,0)),"") | F8: =IFERROR(INDEX(計算用!$D$2:$D$186,MATCH("男白"&$A8,計算用!$L$2:$L$186,0)),"") | G8: =IFERROR(INDEX(計算用!$M$2:$M$186,MATCH("男白"&$A8,計算用!$L$2:$L$186,0)),"") | H8: =IFERROR(INDEX(計算用!$G$2:$G$186,MATCH("男白"&$A8,計算用!$L$2:$L$186,0)),"") | J8: =IF(ROW()-3<=MAX(計算用!$Q$4,計算用!$Q$5),ROW()-3,"") | K8: =IFERROR(INDEX(計算用!$D$2:$D$186,MATCH("女赤"&$J8,計算用!$L$2:$L$186,0)),"") | L8: =IFERROR(INDEX(計算用!$M$2:$M$186,MATCH("女赤"&$J8,計算用!$L$2:$L$186,0)),"") | M8: =IFERROR(INDEX(計算用!$G$2:$G$186,MATCH("女赤"&$J8,計算用!$L$2:$L$186,0)),"") | O8: =IFERROR(INDEX(計算用!$D$2:$D$186,MATCH("女白"&$J8,計算用!$L$2:$L$186,0)),"") | P8: =IFERROR(INDEX(計算用!$M$2:$M$186,MATCH("女白"&$J8,計算用!$L$2:$L$186,0)),"") | Q8: =IFERROR(INDEX(計算用!$G$2:$G$186,MATCH("女白"&$J8,計算用!$L$2:$L$186,0)),"")
A9: =IF(ROW()-3<=MAX(計算用!$Q$2,計算用!$Q$3),ROW()-3,"") | B9: =IFERROR(INDEX(計算用!$D$2:$D$186,MATCH("男赤"&$A9,計算用!$L$2:$L$186,0)),"") | C9: =IFERROR(INDEX(計算用!$M$2:$M$186,MATCH("男赤"&$A9,計算用!$L$2:$L$186,0)),"") | D9: =IFERROR(INDEX(計算用!$G$2:$G$186,MATCH("男赤"&$A9,計算用!$L$2:$L$186,0)),"") | F9: =IFERROR(INDEX(計算用!$D$2:$D$186,MATCH("男白"&$A9,計算用!$L$2:$L$186,0)),"") | G9: =IFERROR(INDEX(計算用!$M$2:$M$186,MATCH("男白"&$A9,計算用!$L$2:$L$186,0)),"") | H9: =IFERROR(INDEX(計算用!$G$2:$G$186,MATCH("男白"&$A9,計算用!$L$2:$L$186,0)),"") | J9: =IF(ROW()-3<=MAX(計算用!$Q$4,計算用!$Q$5),ROW()-3,"") | K9: =IFERROR(INDEX(計算用!$D$2:$D$186,MATCH("女赤"&$J9,計算用!$L$2:$L$186,0)),"") | L9: =IFERROR(INDEX(計算用!$M$2:$M$186,MATCH("女赤"&$J9,計算用!$L$2:$L$186,0)),"") | M9: =IFERROR(INDEX(計算用!$G$2:$G$186,MATCH("女赤"&$J9,計算用!$L$2:$L$186,0)),"") | O9: =IFERROR(INDEX(計算用!$D$2:$D$186,MATCH("女白"&$J9,計算用!$L$2:$L$186,0)),"") | P9: =IFERROR(INDEX(計算用!$M$2:$M$186,MATCH("女白"&$J9,計算用!$L$2:$L$186,0)),"") | Q9: =IFERROR(INDEX(計算用!$G$2:$G$186,MATCH("女白"&$J9,計算用!$L$2:$L$186,0)),"")
A10: =IF(ROW()-3<=MAX(計算用!$Q$2,計算用!$Q$3),ROW()-3,"") | B10: =IFERROR(INDEX(計算用!$D$2:$D$186,MATCH("男赤"&$A10,計算用!$L$2:$L$186,0)),"") | C10: =IFERROR(INDEX(計算用!$M$2:$M$186,MATCH("男赤"&$A10,計算用!$L$2:$L$186,0)),"") | D10: =IFERROR(INDEX(計算用!$G$2:$G$186,MATCH("男赤"&$A10,計算用!$L$2:$L$186,0)),"") | F10: =IFERROR(INDEX(計算用!$D$2:$D$186,MATCH("男白"&$A10,計算用!$L$2:$L$186,0)),"") | G10: =IFERROR(INDEX(計算用!$M$2:$M$186,MATCH("男白"&$A10,計算用!$L$2:$L$186,0)),"") | H10: =IFERROR(INDEX(計算用!$G$2:$G$186,MATCH("男白"&$A10,計算用!$L$2:$L$186,0)),"") | J10: =IF(ROW()-3<=MAX(計算用!$Q$4,計算用!$Q$5),ROW()-3,"") | K10: =IFERROR(INDEX(計算用!$D$2:$D$186,MATCH("女赤"&$J10,計算用!$L$2:$L$186,0)),"") | L10: =IFERROR(INDEX(計算用!$M$2:$M$186,MATCH("女赤"&$J10,計算用!$L$2:$L$186,0)),"") | M10: =IFERROR(INDEX(計算用!$G$2:$G$186,MATCH("女赤"&$J10,計算用!$L$2:$L$186,0)),"") | O10: =IFERROR(INDEX(計算用!$D$2:$D$186,MATCH("女白"&$J10,計算用!$L$2:$L$186,0)),"") | P10: =IFERROR(INDEX(計算用!$M$2:$M$186,MATCH("女白"&$J10,計算用!$L$2:$L$186,0)),"") | Q10: =IFERROR(INDEX(計算用!$G$2:$G$186,MATCH("女白"&$J10,計算用!$L$2:$L$186,0)),"")
A11: =IF(ROW()-3<=MAX(計算用!$Q$2,計算用!$Q$3),ROW()-3,"") | B11: =IFERROR(INDEX(計算用!$D$2:$D$186,MATCH("男赤"&$A11,計算用!$L$2:$L$186,0)),"") | C11: =IFERROR(INDEX(計算用!$M$2:$M$186,MATCH("男赤"&$A11,計算用!$L$2:$L$186,0)),"") | D11: =IFERROR(INDEX(計算用!$G$2:$G$186,MATCH("男赤"&$A11,計算用!$L$2:$L$186,0)),"") | F11: =IFERROR(INDEX(計算用!$D$2:$D$186,MATCH("男白"&$A11,計算用!$L$2:$L$186,0)),"") | G11: =IFERROR(INDEX(計算用!$M$2:$M$186,MATCH("男白"&$A11,計算用!$L$2:$L$186,0)),"") | H11: =IFERROR(INDEX(計算用!$G$2:$G$186,MATCH("男白"&$A11,計算用!$L$2:$L$186,0)),"") | J11: =IF(ROW()-3<=MAX(計算用!$Q$4,計算用!$Q$5),ROW()-3,"") | K11: =IFERROR(INDEX(計算用!$D$2:$D$186,MATCH("女赤"&$J11,計算用!$L$2:$L$186,0)),"") | L11: =IFERROR(INDEX(計算用!$M$2:$M$186,MATCH("女赤"&$J11,計算用!$L$2:$L$186,0)),"") | M11: =IFERROR(INDEX(計算用!$G$2:$G$186,MATCH("女赤"&$J11,計算用!$L$2:$L$186,0)),"") | O11: =IFERROR(INDEX(計算用!$D$2:$D$186,MATCH("女白"&$J11,計算用!$L$2:$L$186,0)),"") | P11: =IFERROR(INDEX(計算用!$M$2:$M$186,MATCH("女白"&$J11,計算用!$L$2:$L$186,0)),"") | Q11: =IFERROR(INDEX(計算用!$G$2:$G$186,MATCH("女白"&$J11,計算用!$L$2:$L$186,0)),"")
A12: =IF(ROW()-3<=MAX(計算用!$Q$2,計算用!$Q$3),ROW()-3,"") | B12: =IFERROR(INDEX(計算用!$D$2:$D$186,MATCH("男赤"&$A12,計算用!$L$2:$L$186,0)),"") | C12: =IFERROR(INDEX(計算用!$M$2:$M$186,MATCH("男赤"&$A12,計算用!$L$2:$L$186,0)),"") | D12: =IFERROR(INDEX(計算用!$G$2:$G$186,MATCH("男赤"&$A12,計算用!$L$2:$L$186,0)),"") | F12: =IFERROR(INDEX(計算用!$D$2:$D$186,MATCH("男白"&$A12,計算用!$L$2:$L$186,0)),"") | G12: =IFERROR(INDEX(計算用!$M$2:$M$186,MATCH("男白"&$A12,計算用!$L$2:$L$186,0)),"") | H12: =IFERROR(INDEX(計算用!$G$2:$G$186,MATCH("男白"&$A12,計算用!$L$2:$L$186,0)),"") | J12: =IF(ROW()-3<=MAX(計算用!$Q$4,計算用!$Q$5),ROW()-3,"") | K12: =IFERROR(INDEX(計算用!$D$2:$D$186,MATCH("女赤"&$J12,計算用!$L$2:$L$186,0)),"") | L12: =IFERROR(INDEX(計算用!$M$2:$M$186,MATCH("女赤"&$J12,計算用!$L$2:$L$186,0)),"") | M12: =IFERROR(INDEX(計算用!$G$2:$G$186,MATCH("女赤"&$J12,計算用!$L$2:$L$186,0)),"") | O12: =IFERROR(INDEX(計算用!$D$2:$D$186,MATCH("女白"&$J12,計算用!$L$2:$L$186,0)),"") | P12: =IFERROR(INDEX(計算用!$M$2:$M$186,MATCH("女白"&$J12,計算用!$L$2:$L$186,0)),"") | Q12: =IFERROR(INDEX(計算用!$G$2:$G$186,MATCH("女白"&$J12,計算用!$L$2:$L$186,0)),"")
A13: =IF(ROW()-3<=MAX(計算用!$Q$2,計算用!$Q$3),ROW()-3,"") | B13: =IFERROR(INDEX(計算用!$D$2:$D$186,MATCH("男赤"&$A13,計算用!$L$2:$L$186,0)),"") | C13: =IFERROR(INDEX(計算用!$M$2:$M$186,MATCH("男赤"&$A13,計算用!$L$2:$L$186,0)),"") | D13: =IFERROR(INDEX(計算用!$G$2:$G$186,MATCH("男赤"&$A13,計算用!$L$2:$L$186,0)),"") | F13: =IFERROR(INDEX(計算用!$D$2:$D$186,MATCH("男白"&$A13,計算用!$L$2:$L$186,0)),"") | G13: =IFERROR(INDEX(計算用!$M$2:$M$186,MATCH("男白"&$A13,計算用!$L$2:$L$186,0)),"") | H13: =IFERROR(INDEX(計算用!$G$2:$G$186,MATCH("男白"&$A13,計算用!$L$2:$L$186,0)),"") | J13: =IF(ROW()-3<=MAX(計算用!$Q$4,計算用!$Q$5),ROW()-3,"") | K13: =IFERROR(INDEX(計算用!$D$2:$D$186,MATCH("女赤"&$J13,計算用!$L$2:$L$186,0)),"") | L13: =IFERROR(INDEX(計算用!$M$2:$M$186,MATCH("女赤"&$J13,計算用!$L$2:$L$186,0)),"") | M13: =IFERROR(INDEX(計算用!$G$2:$G$186,MATCH("女赤"&$J13,計算用!$L$2:$L$186,0)),"") | O13: =IFERROR(INDEX(計算用!$D$2:$D$186,MATCH("女白"&$J13,計算用!$L$2:$L$186,0)),"") | P13: =IFERROR(INDEX(計算用!$M$2:$M$186,MATCH("女白"&$J13,計算用!$L$2:$L$186,0)),"") | Q13: =IFERROR(INDEX(計算用!$G$2:$G$186,MATCH("女白"&$J13,計算用!$L$2:$L$186,0)),"")
A14: =IF(ROW()-3<=MAX(計算用!$Q$2,計算用!$Q$3),ROW()-3,"") | B14: =IFERROR(INDEX(計算用!$D$2:$D$186,MATCH("男赤"&$A14,計算用!$L$2:$L$186,0)),"") | C14: =IFERROR(INDEX(計算用!$M$2:$M$186,MATCH("男赤"&$A14,計算用!$L$2:$L$186,0)),"") | D14: =IFERROR(INDEX(計算用!$G$2:$G$186,MATCH("男赤"&$A14,計算用!$L$2:$L$186,0)),"") | F14: =IFERROR(INDEX(計算用!$D$2:$D$186,MATCH("男白"&$A14,計算用!$L$2:$L$186,0)),"") | G14: =IFERROR(INDEX(計算用!$M$2:$M$186,MATCH("男白"&$A14,計算用!$L$2:$L$186,0)),"") | H14: =IFERROR(INDEX(計算用!$G$2:$G$186,MATCH("男白"&$A14,計算用!$L$2:$L$186,0)),"") | J14: =IF(ROW()-3<=MAX(計算用!$Q$4,計算用!$Q$5),ROW()-3,"") | K14: =IFERROR(INDEX(計算用!$D$2:$D$186,MATCH("女赤"&$J14,計算用!$L$2:$L$186,0)),"") | L14: =IFERROR(INDEX(計算用!$M$2:$M$186,MATCH("女赤"&$J14,計算用!$L$2:$L$186,0)),"") | M14: =IFERROR(INDEX(計算用!$G$2:$G$186,MATCH("女赤"&$J14,計算用!$L$2:$L$186,0)),"") | O14: =IFERROR(INDEX(計算用!$D$2:$D$186,MATCH("女白"&$J14,計算用!$L$2:$L$186,0)),"") | P14: =IFERROR(INDEX(計算用!$M$2:$M$186,MATCH("女白"&$J14,計算用!$L$2:$L$186,0)),"") | Q14: =IFERROR(INDEX(計算用!$G$2:$G$186,MATCH("女白"&$J14,計算用!$L$2:$L$186,0)),"")
A15: =IF(ROW()-3<=MAX(計算用!$Q$2,計算用!$Q$3),ROW()-3,"") | B15: =IFERROR(INDEX(計算用!$D$2:$D$186,MATCH("男赤"&$A15,計算用!$L$2:$L$186,0)),"") | C15: =IFERROR(INDEX(計算用!$M$2:$M$186,MATCH("男赤"&$A15,計算用!$L$2:$L$186,0)),"") | D15: =IFERROR(INDEX(計算用!$G$2:$G$186,MATCH("男赤"&$A15,計算用!$L$2:$L$186,0)),"") | F15: =IFERROR(INDEX(計算用!$D$2:$D$186,MATCH("男白"&$A15,計算用!$L$2:$L$186,0)),"") | G15: =IFERROR(INDEX(計算用!$M$2:$M$186,MATCH("男白"&$A15,計算用!$L$2:$L$186,0)),"") | H15: =IFERROR(INDEX(計算用!$G$2:$G$186,MATCH("男白"&$A15,計算用!$L$2:$L$186,0)),"") | J15: =IF(ROW()-3<=MAX(計算用!$Q$4,計算用!$Q$5),ROW()-3,"") | K15: =IFERROR(INDEX(計算用!$D$2:$D$186,MATCH("女赤"&$J15,計算用!$L$2:$L$186,0)),"") | L15: =IFERROR(INDEX(計算用!$M$2:$M$186,MATCH("女赤"&$J15,計算用!$L$2:$L$186,0)),"") | M15: =IFERROR(INDEX(計算用!$G$2:$G$186,MATCH("女赤"&$J15,計算用!$L$2:$L$186,0)),"") | O15: =IFERROR(INDEX(計算用!$D$2:$D$186,MATCH("女白"&$J15,計算用!$L$2:$L$186,0)),"") | P15: =IFERROR(INDEX(計算用!$M$2:$M$186,MATCH("女白"&$J15,計算用!$L$2:$L$186,0)),"") | Q15: =IFERROR(INDEX(計算用!$G$2:$G$186,MATCH("女白"&$J15,計算用!$L$2:$L$186,0)),"")
... A188: =IF(ROW()-3<=MAX(計算用!$Q$2,計算用!$Q$3),ROW()-3,"") | B188: =IFERROR(INDEX(計算用!$D$2:$D$186,MATCH("男赤"&$A188,計算用!$L$2:$L$186,0)),"") | C188: =IFERROR(INDEX(計算用!$M$2:$M$186,MATCH("男赤"&$A188,計算用!$L$2:$L$186,0)),"") | D188: =IFERROR(INDEX(計算用!$G$2:$G$186,MATCH("男赤"&$A188,計算用!$L$2:$L$186,0)),"") | F188: =IFERROR(INDEX(計算用!$D$2:$D$186,MATCH("男白"&$A188,計算用!$L$2:$L$186,0)),"") | G188: =IFERROR(INDEX(計算用!$M$2:$M$186,MATCH("男白"&$A188,計算用!$L$2:$L$186,0)),"") | H188: =IFERROR(INDEX(計算用!$G$2:$G$186,MATCH("男白"&$A188,計算用!$L$2:$L$186,0)),"") | J188: =IF(ROW()-3<=MAX(計算用!$Q$4,計算用!$Q$5),ROW()-3,"") | K188: =IFERROR(INDEX(計算用!$D$2:$D$186,MATCH("女赤"&$J188,計算用!$L$2:$L$186,0)),"") | L188: =IFERROR(INDEX(計算用!$M$2:$M$186,MATCH("女赤"&$J188,計算用!$L$2:$L$186,0)),"") | M188: =IFERROR(INDEX(計算用!$G$2:$G$186,MATCH("女赤"&$J188,計算用!$L$2:$L$186,0)),"") | O188: =IFERROR(INDEX(計算用!$D$2:$D$186,MATCH("女白"&$J188,計算用!$L$2:$L$186,0)),"") | P188: =IFERROR(INDEX(計算用!$M$2:$M$186,MATCH("女白"&$J188,計算用!$L$2:$L$186,0)),"") | Q188: =IFERROR(INDEX(計算用!$G$2:$G$186,MATCH("女白"&$J188,計算用!$L$2:$L$186,0)),"")

Sheet 4人組
A1: 男子 | D1: =IF(SUMPRODUCT((計算用!$T$2:$T$51>0)*(((計算用!$T$2:$T$51<>4)+(計算用!$W$2:$W$51<>2))>0))>0,"※黄色の組は、人数の都合で調整した組です","") | Q1: 女子 | T1: =IF(SUMPRODUCT((計算用!$AC$2:$AC$51>0)*(((計算用!$AC$2:$AC$51<>4)+(計算用!$AF$2:$AF$51<>2))>0))>0,"※黄色の組は、人数の都合で調整した組です","")
A2: 組 | B2: 人数 | C2: 内訳 | D2: 1人目 | G2: 2人目 | J2: 3人目 | M2: 4人目 | Q2: 組 | R2: 人数 | S2: 内訳 | T2: 1人目 | W2: 2人目 | Z2: 3人目 | AC2: 4人目
D3: 名前 | E3: クラス | F3: 色 | G3: 名前 | H3: クラス | I3: 色 | J3: 名前 | K3: クラス | L3: 色 | M3: 名前 | N3: クラス | O3: 色 | T3: 名前 | U3: クラス | V3: 色 | W3: 名前 | X3: クラス | Y3: 色 | Z3: 名前 | AA3: クラス | AB3: 色 | AC3: 名前 | AD3: クラス | AE3: 色
A4: =IF(ROW()-3<=計算用!$Q$9,ROW()-3,"") | B4: =IF($A4="","",INDEX(計算用!$T$2:$T$51,$A4)) | C4: =IF($A4="","","赤"&INDEX(計算用!$W$2:$W$51,$A4)&"白"&INDEX(計算用!$X$2:$X$51,$A4)) | D4: =IF($A4="","",IFERROR(INDEX(計算用!$D$2:$D$186,MATCH("男"&$A4&"-1",計算用!$AN$2:$AN$186,0)),"")) | E4: =IF($A4="","",IFERROR(INDEX(計算用!$M$2:$M$186,MATCH("男"&$A4&"-1",計算用!$AN$2:$AN$186,0)),"")) | F4: =IF($A4="","",IFERROR(INDEX(計算用!$I$2:$I$186,MATCH("男"&$A4&"-1",計算用!$AN$2:$AN$186,0)),"")) | G4: =IF($A4="","",IFERROR(INDEX(計算用!$D$2:$D$186,MATCH("男"&$A4&"-2",計算用!$AN$2:$AN$186,0)),"")) | H4: =IF($A4="","",IFERROR(INDEX(計算用!$M$2:$M$186,MATCH("男"&$A4&"-2",計算用!$AN$2:$AN$186,0)),"")) | I4: =IF($A4="","",IFERROR(INDEX(計算用!$I$2:$I$186,MATCH("男"&$A4&"-2",計算用!$AN$2:$AN$186,0)),"")) | J4: =IF($A4="","",IFERROR(INDEX(計算用!$D$2:$D$186,MATCH("男"&$A4&"-3",計算用!$AN$2:$AN$186,0)),"")) | K4: =IF($A4="","",IFERROR(INDEX(計算用!$M$2:$M$186,MATCH("男"&$A4&"-3",計算用!$AN$2:$AN$186,0)),"")) | L4: =IF($A4="","",IFERROR(INDEX(計算用!$I$2:$I$186,MATCH("男"&$A4&"-3",計算用!$AN$2:$AN$186,0)),"")) | M4: =IF($A4="","",IFERROR(INDEX(計算用!$D$2:$D$186,MATCH("男"&$A4&"-4",計算用!$AN$2:$AN$186,0)),"")) | N4: =IF($A4="","",IFERROR(INDEX(計算用!$M$2:$M$186,MATCH("男"&$A4&"-4",計算用!$AN$2:$AN$186,0)),"")) | O4: =IF($A4="","",IFERROR(INDEX(計算用!$I$2:$I$186,MATCH("男"&$A4&"-4",計算用!$AN$2:$AN$186,0)),"")) | Q4: =IF(ROW()-3<=計算用!$Q$11,ROW()-3,"") | R4: =IF($Q4="","",INDEX(計算用!$AC$2:$AC$51,$Q4)) | S4: =IF($Q4="","","赤"&INDEX(計算用!$AF$2:$AF$51,$Q4)&"白"&INDEX(計算用!$AG$2:$AG$51,$Q4)) | T4: =IF($Q4="","",IFERROR(INDEX(計算用!$D$2:$D$186,MATCH("女"&$Q4&"-1",計算用!$AN$2:$AN$186,0)),"")) | U4: =IF($Q4="","",IFERROR(INDEX(計算用!$M$2:$M$186,MATCH("女"&$Q4&"-1",計算用!$AN$2:$AN$186,0)),"")) | V4: =IF($Q4="","",IFERROR(INDEX(計算用!$I$2:$I$186,MATCH("女"&$Q4&"-1",計算用!$AN$2:$AN$186,0)),"")) | W4: =IF($Q4="","",IFERROR(INDEX(計算用!$D$2:$D$186,MATCH("女"&$Q4&"-2",計算用!$AN$2:$AN$186,0)),"")) | X4: =IF($Q4="","",IFERROR(INDEX(計算用!$M$2:$M$186,MATCH("女"&$Q4&"-2",計算用!$AN$2:$AN$186,0)),"")) | Y4: =IF($Q4="","",IFERROR(INDEX(計算用!$I$2:$I$186,MATCH("女"&$Q4&"-2",計算用!$AN$2:$AN$186,0)),"")) | Z4: =IF($Q4="","",IFERROR(INDEX(計算用!$D$2:$D$186,MATCH("女"&$Q4&"-3",計算用!$AN$2:$AN$186,0)),"")) | AA4: =IF($Q4="","",IFERROR(INDEX(計算用!$M$2:$M$186,MATCH("女"&$Q4&"-3",計算用!$AN$2:$AN$186,0)),"")) | AB4: =IF($Q4="","",IFERROR(INDEX(計算用!$I$2:$I$186,MATCH("女"&$Q4&"-3",計算用!$AN$2:$AN$186,0)),"")) | AC4: =IF($Q4="","",IFERROR(INDEX(計算用!$D$2:$D$186,MATCH("女"&$Q4&"-4",計算用!$AN$2:$AN$186,0)),"")) | AD4: =IF($Q4="","",IFERROR(INDEX(計算用!$M$2:$M$186,MATCH("女"&$Q4&"-4",計算用!$AN$2:$AN$186,0)),"")) | AE4: =IF($Q4="","",IFERROR(INDEX(計算用!$I$2:$I$186,MATCH("女"&$Q4&"-4",計算用!$AN$2:$AN$186,0)),""))
A5: =IF(ROW()-3<=計算用!$Q$9,ROW()-3,"") | B5: =IF($A5="","",INDEX(計算用!$T$2:$T$51,$A5)) | C5: =IF($A5="","","赤"&INDEX(計算用!$W$2:$W$51,$A5)&"白"&INDEX(計算用!$X$2:$X$51,$A5)) | D5: =IF($A5="","",IFERROR(INDEX(計算用!$D$2:$D$186,MATCH("男"&$A5&"-1",計算用!$AN$2:$AN$186,0)),"")) | E5: =IF($A5="","",IFERROR(INDEX(計算用!$M$2:$M$186,MATCH("男"&$A5&"-1",計算用!$AN$2:$AN$186,0)),"")) | F5: =IF($A5="","",IFERROR(INDEX(計算用!$I$2:$I$186,MATCH("男"&$A5&"-1",計算用!$AN$2:$AN$186,0)),"")) | G5: =IF($A5="","",IFERROR(INDEX(計算用!$D$2:$D$186,MATCH("男"&$A5&"-2",計算用!$AN$2:$AN$186,0)),"")) | H5: =IF($A5="","",IFERROR(INDEX(計算用!$M$2:$M$186,MATCH("男"&$A5&"-2",計算用!$AN$2:$AN$186,0)),"")) | I5: =IF($A5="","",IFERROR(INDEX(計算用!$I$2:$I$186,MATCH("男"&$A5&"-2",計算用!$AN$2:$AN$186,0)),"")) | J5: =IF($A5="","",IFERROR(INDEX(計算用!$D$2:$D$186,MATCH("男"&$A5&"-3",計算用!$AN$2:$AN$186,0)),"")) | K5: =IF($A5="","",IFERROR(INDEX(計算用!$M$2:$M$186,MATCH("男"&$A5&"-3",計算用!$AN$2:$AN$186,0)),"")) | L5: =IF($A5="","",IFERROR(INDEX(計算用!$I$2:$I$186,MATCH("男"&$A5&"-3",計算用!$AN$2:$AN$186,0)),"")) | M5: =IF($A5="","",IFERROR(INDEX(計算用!$D$2:$D$186,MATCH("男"&$A5&"-4",計算用!$AN$2:$AN$186,0)),"")) | N5: =IF($A5="","",IFERROR(INDEX(計算用!$M$2:$M$186,MATCH("男"&$A5&"-4",計算用!$AN$2:$AN$186,0)),"")) | O5: =IF($A5="","",IFERROR(INDEX(計算用!$I$2:$I$186,MATCH("男"&$A5&"-4",計算用!$AN$2:$AN$186,0)),"")) | Q5: =IF(ROW()-3<=計算用!$Q$11,ROW()-3,"") | R5: =IF($Q5="","",INDEX(計算用!$AC$2:$AC$51,$Q5)) | S5: =IF($Q5="","","赤"&INDEX(計算用!$AF$2:$AF$51,$Q5)&"白"&INDEX(計算用!$AG$2:$AG$51,$Q5)) | T5: =IF($Q5="","",IFERROR(INDEX(計算用!$D$2:$D$186,MATCH("女"&$Q5&"-1",計算用!$AN$2:$AN$186,0)),"")) | U5: =IF($Q5="","",IFERROR(INDEX(計算用!$M$2:$M$186,MATCH("女"&$Q5&"-1",計算用!$AN$2:$AN$186,0)),"")) | V5: =IF($Q5="","",IFERROR(INDEX(計算用!$I$2:$I$186,MATCH("女"&$Q5&"-1",計算用!$AN$2:$AN$186,0)),"")) | W5: =IF($Q5="","",IFERROR(INDEX(計算用!$D$2:$D$186,MATCH("女"&$Q5&"-2",計算用!$AN$2:$AN$186,0)),"")) | X5: =IF($Q5="","",IFERROR(INDEX(計算用!$M$2:$M$186,MATCH("女"&$Q5&"-2",計算用!$AN$2:$AN$186,0)),"")) | Y5: =IF($Q5="","",IFERROR(INDEX(計算用!$I$2:$I$186,MATCH("女"&$Q5&"-2",計算用!$AN$2:$AN$186,0)),"")) | Z5: =IF($Q5="","",IFERROR(INDEX(計算用!$D$2:$D$186,MATCH("女"&$Q5&"-3",計算用!$AN$2:$AN$186,0)),"")) | AA5: =IF($Q5="","",IFERROR(INDEX(計算用!$M$2:$M$186,MATCH("女"&$Q5&"-3",計算用!$AN$2:$AN$186,0)),"")) | AB5: =IF($Q5="","",IFERROR(INDEX(計算用!$I$2:$I$186,MATCH("女"&$Q5&"-3",計算用!$AN$2:$AN$186,0)),"")) | AC5: =IF($Q5="","",IFERROR(INDEX(計算用!$D$2:$D$186,MATCH("女"&$Q5&"-4",計算用!$AN$2:$AN$186,0)),"")) | AD5: =IF($Q5="","",IFERROR(INDEX(計算用!$M$2:$M$186,MATCH("女"&$Q5&"-4",計算用!$AN$2:$AN$186,0)),"")) | AE5: =IF($Q5="","",IFERROR(INDEX(計算用!$I$2:$I$186,MATCH("女"&$Q5&"-4",計算用!$AN$2:$AN$186,0)),""))
A6: =IF(ROW()-3<=計算用!$Q$9,ROW()-3,"") | B6: =IF($A6="","",INDEX(計算用!$T$2:$T$51,$A6)) | C6: =IF($A6="","","赤"&INDEX(計算用!$W$2:$W$51,$A6)&"白"&INDEX(計算用!$X$2:$X$51,$A6)) | D6: =IF($A6="","",IFERROR(INDEX(計算用!$D$2:$D$186,MATCH("男"&$A6&"-1",計算用!$AN$2:$AN$186,0)),"")) | E6: =IF($A6="","",IFERROR(INDEX(計算用!$M$2:$M$186,MATCH("男"&$A6&"-1",計算用!$AN$2:$AN$186,0)),"")) | F6: =IF($A6="","",IFERROR(INDEX(計算用!$I$2:$I$186,MATCH("男"&$A6&"-1",計算用!$AN$2:$AN$186,0)),"")) | G6: =IF($A6="","",IFERROR(INDEX(計算用!$D$2:$D$186,MATCH("男"&$A6&"-2",計算用!$AN$2:$AN$186,0)),"")) | H6: =IF($A6="","",IFERROR(INDEX(計算用!$M$2:$M$186,MATCH("男"&$A6&"-2",計算用!$AN$2:$AN$186,0)),"")) | I6: =IF($A6="","",IFERROR(INDEX(計算用!$I$2:$I$186,MATCH("男"&$A6&"-2",計算用!$AN$2:$AN$186,0)),"")) | J6: =IF($A6="","",IFERROR(INDEX(計算用!$D$2:$D$186,MATCH("男"&$A6&"-3",計算用!$AN$2:$AN$186,0)),"")) | K6: =IF($A6="","",IFERROR(INDEX(計算用!$M$2:$M$186,MATCH("男"&$A6&"-3",計算用!$AN$2:$AN$186,0)),"")) | L6: =IF($A6="","",IFERROR(INDEX(計算用!$I$2:$I$186,MATCH("男"&$A6&"-3",計算用!$AN$2:$AN$186,0)),"")) | M6: =IF($A6="","",IFERROR(INDEX(計算用!$D$2:$D$186,MATCH("男"&$A6&"-4",計算用!$AN$2:$AN$186,0)),"")) | N6: =IF($A6="","",IFERROR(INDEX(計算用!$M$2:$M$186,MATCH("男"&$A6&"-4",計算用!$AN$2:$AN$186,0)),"")) | O6: =IF($A6="","",IFERROR(INDEX(計算用!$I$2:$I$186,MATCH("男"&$A6&"-4",計算用!$AN$2:$AN$186,0)),"")) | Q6: =IF(ROW()-3<=計算用!$Q$11,ROW()-3,"") | R6: =IF($Q6="","",INDEX(計算用!$AC$2:$AC$51,$Q6)) | S6: =IF($Q6="","","赤"&INDEX(計算用!$AF$2:$AF$51,$Q6)&"白"&INDEX(計算用!$AG$2:$AG$51,$Q6)) | T6: =IF($Q6="","",IFERROR(INDEX(計算用!$D$2:$D$186,MATCH("女"&$Q6&"-1",計算用!$AN$2:$AN$186,0)),"")) | U6: =IF($Q6="","",IFERROR(INDEX(計算用!$M$2:$M$186,MATCH("女"&$Q6&"-1",計算用!$AN$2:$AN$186,0)),"")) | V6: =IF($Q6="","",IFERROR(INDEX(計算用!$I$2:$I$186,MATCH("女"&$Q6&"-1",計算用!$AN$2:$AN$186,0)),"")) | W6: =IF($Q6="","",IFERROR(INDEX(計算用!$D$2:$D$186,MATCH("女"&$Q6&"-2",計算用!$AN$2:$AN$186,0)),"")) | X6: =IF($Q6="","",IFERROR(INDEX(計算用!$M$2:$M$186,MATCH("女"&$Q6&"-2",計算用!$AN$2:$AN$186,0)),"")) | Y6: =IF($Q6="","",IFERROR(INDEX(計算用!$I$2:$I$186,MATCH("女"&$Q6&"-2",計算用!$AN$2:$AN$186,0)),"")) | Z6: =IF($Q6="","",IFERROR(INDEX(計算用!$D$2:$D$186,MATCH("女"&$Q6&"-3",計算用!$AN$2:$AN$186,0)),"")) | AA6: =IF($Q6="","",IFERROR(INDEX(計算用!$M$2:$M$186,MATCH("女"&$Q6&"-3",計算用!$AN$2:$AN$186,0)),"")) | AB6: =IF($Q6="","",IFERROR(INDEX(計算用!$I$2:$I$186,MATCH("女"&$Q6&"-3",計算用!$AN$2:$AN$186,0)),"")) | AC6: =IF($Q6="","",IFERROR(INDEX(計算用!$D$2:$D$186,MATCH("女"&$Q6&"-4",計算用!$AN$2:$AN$186,0)),"")) | AD6: =IF($Q6="","",IFERROR(INDEX(計算用!$M$2:$M$186,MATCH("女"&$Q6&"-4",計算用!$AN$2:$AN$186,0)),"")) | AE6: =IF($Q6="","",IFERROR(INDEX(計算用!$I$2:$I$186,MATCH("女"&$Q6&"-4",計算用!$AN$2:$AN$186,0)),""))
A7: =IF(ROW()-3<=計算用!$Q$9,ROW()-3,"") | B7: =IF($A7="","",INDEX(計算用!$T$2:$T$51,$A7)) | C7: =IF($A7="","","赤"&INDEX(計算用!$W$2:$W$51,$A7)&"白"&INDEX(計算用!$X$2:$X$51,$A7)) | D7: =IF($A7="","",IFERROR(INDEX(計算用!$D$2:$D$186,MATCH("男"&$A7&"-1",計算用!$AN$2:$AN$186,0)),"")) | E7: =IF($A7="","",IFERROR(INDEX(計算用!$M$2:$M$186,MATCH("男"&$A7&"-1",計算用!$AN$2:$AN$186,0)),"")) | F7: =IF($A7="","",IFERROR(INDEX(計算用!$I$2:$I$186,MATCH("男"&$A7&"-1",計算用!$AN$2:$AN$186,0)),"")) | G7: =IF($A7="","",IFERROR(INDEX(計算用!$D$2:$D$186,MATCH("男"&$A7&"-2",計算用!$AN$2:$AN$186,0)),"")) | H7: =IF($A7="","",IFERROR(INDEX(計算用!$M$2:$M$186,MATCH("男"&$A7&"-2",計算用!$AN$2:$AN$186,0)),"")) | I7: =IF($A7="","",IFERROR(INDEX(計算用!$I$2:$I$186,MATCH("男"&$A7&"-2",計算用!$AN$2:$AN$186,0)),"")) | J7: =IF($A7="","",IFERROR(INDEX(計算用!$D$2:$D$186,MATCH("男"&$A7&"-3",計算用!$AN$2:$AN$186,0)),"")) | K7: =IF($A7="","",IFERROR(INDEX(計算用!$M$2:$M$186,MATCH("男"&$A7&"-3",計算用!$AN$2:$AN$186,0)),"")) | L7: =IF($A7="","",IFERROR(INDEX(計算用!$I$2:$I$186,MATCH("男"&$A7&"-3",計算用!$AN$2:$AN$186,0)),"")) | M7: =IF($A7="","",IFERROR(INDEX(計算用!$D$2:$D$186,MATCH("男"&$A7&"-4",計算用!$AN$2:$AN$186,0)),"")) | N7: =IF($A7="","",IFERROR(INDEX(計算用!$M$2:$M$186,MATCH("男"&$A7&"-4",計算用!$AN$2:$AN$186,0)),"")) | O7: =IF($A7="","",IFERROR(INDEX(計算用!$I$2:$I$186,MATCH("男"&$A7&"-4",計算用!$AN$2:$AN$186,0)),"")) | Q7: =IF(ROW()-3<=計算用!$Q$11,ROW()-3,"") | R7: =IF($Q7="","",INDEX(計算用!$AC$2:$AC$51,$Q7)) | S7: =IF($Q7="","","赤"&INDEX(計算用!$AF$2:$AF$51,$Q7)&"白"&INDEX(計算用!$AG$2:$AG$51,$Q7)) | T7: =IF($Q7="","",IFERROR(INDEX(計算用!$D$2:$D$186,MATCH("女"&$Q7&"-1",計算用!$AN$2:$AN$186,0)),"")) | U7: =IF($Q7="","",IFERROR(INDEX(計算用!$M$2:$M$186,MATCH("女"&$Q7&"-1",計算用!$AN$2:$AN$186,0)),"")) | V7: =IF($Q7="","",IFERROR(INDEX(計算用!$I$2:$I$186,MATCH("女"&$Q7&"-1",計算用!$AN$2:$AN$186,0)),"")) | W7: =IF($Q7="","",IFERROR(INDEX(計算用!$D$2:$D$186,MATCH("女"&$Q7&"-2",計算用!$AN$2:$AN$186,0)),"")) | X7: =IF($Q7="","",IFERROR(INDEX(計算用!$M$2:$M$186,MATCH("女"&$Q7&"-2",計算用!$AN$2:$AN$186,0)),"")) | Y7: =IF($Q7="","",IFERROR(INDEX(計算用!$I$2:$I$186,MATCH("女"&$Q7&"-2",計算用!$AN$2:$AN$186,0)),"")) | Z7: =IF($Q7="","",IFERROR(INDEX(計算用!$D$2:$D$186,MATCH("女"&$Q7&"-3",計算用!$AN$2:$AN$186,0)),"")) | AA7: =IF($Q7="","",IFERROR(INDEX(計算用!$M$2:$M$186,MATCH("女"&$Q7&"-3",計算用!$AN$2:$AN$186,0)),"")) | AB7: =IF($Q7="","",IFERROR(INDEX(計算用!$I$2:$I$186,MATCH("女"&$Q7&"-3",計算用!$AN$2:$AN$186,0)),"")) | AC7: =IF($Q7="","",IFERROR(INDEX(計算用!$D$2:$D$186,MATCH("女"&$Q7&"-4",計算用!$AN$2:$AN$186,0)),"")) | AD7: =IF($Q7="","",IFERROR(INDEX(計算用!$M$2:$M$186,MATCH("女"&$Q7&"-4",計算用!$AN$2:$AN$186,0)),"")) | AE7: =IF($Q7="","",IFERROR(INDEX(計算用!$I$2:$I$186,MATCH("女"&$Q7&"-4",計算用!$AN$2:$AN$186,0)),""))
A8: =IF(ROW()-3<=計算用!$Q$9,ROW()-3,"") | B8: =IF($A8="","",INDEX(計算用!$T$2:$T$51,$A8)) | C8: =IF($A8="","","赤"&INDEX(計算用!$W$2:$W$51,$A8)&"白"&INDEX(計算用!$X$2:$X$51,$A8)) | D8: =IF($A8="","",IFERROR(INDEX(計算用!$D$2:$D$186,MATCH("男"&$A8&"-1",計算用!$AN$2:$AN$186,0)),"")) | E8: =IF($A8="","",IFERROR(INDEX(計算用!$M$2:$M$186,MATCH("男"&$A8&"-1",計算用!$AN$2:$AN$186,0)),"")) | F8: =IF($A8="","",IFERROR(INDEX(計算用!$I$2:$I$186,MATCH("男"&$A8&"-1",計算用!$AN$2:$AN$186,0)),"")) | G8: =IF($A8="","",IFERROR(INDEX(計算用!$D$2:$D$186,MATCH("男"&$A8&"-2",計算用!$AN$2:$AN$186,0)),"")) | H8: =IF($A8="","",IFERROR(INDEX(計算用!$M$2:$M$186,MATCH("男"&$A8&"-2",計算用!$AN$2:$AN$186,0)),"")) | I8: =IF($A8="","",IFERROR(INDEX(計算用!$I$2:$I$186,MATCH("男"&$A8&"-2",計算用!$AN$2:$AN$186,0)),"")) | J8: =IF($A8="","",IFERROR(INDEX(計算用!$D$2:$D$186,MATCH("男"&$A8&"-3",計算用!$AN$2:$AN$186,0)),"")) | K8: =IF($A8="","",IFERROR(INDEX(計算用!$M$2:$M$186,MATCH("男"&$A8&"-3",計算用!$AN$2:$AN$186,0)),"")) | L8: =IF($A8="","",IFERROR(INDEX(計算用!$I$2:$I$186,MATCH("男"&$A8&"-3",計算用!$AN$2:$AN$186,0)),"")) | M8: =IF($A8="","",IFERROR(INDEX(計算用!$D$2:$D$186,MATCH("男"&$A8&"-4",計算用!$AN$2:$AN$186,0)),"")) | N8: =IF($A8="","",IFERROR(INDEX(計算用!$M$2:$M$186,MATCH("男"&$A8&"-4",計算用!$AN$2:$AN$186,0)),"")) | O8: =IF($A8="","",IFERROR(INDEX(計算用!$I$2:$I$186,MATCH("男"&$A8&"-4",計算用!$AN$2:$AN$186,0)),"")) | Q8: =IF(ROW()-3<=計算用!$Q$11,ROW()-3,"") | R8: =IF($Q8="","",INDEX(計算用!$AC$2:$AC$51,$Q8)) | S8: =IF($Q8="","","赤"&INDEX(計算用!$AF$2:$AF$51,$Q8)&"白"&INDEX(計算用!$AG$2:$AG$51,$Q8)) | T8: =IF($Q8="","",IFERROR(INDEX(計算用!$D$2:$D$186,MATCH("女"&$Q8&"-1",計算用!$AN$2:$AN$186,0)),"")) | U8: =IF($Q8="","",IFERROR(INDEX(計算用!$M$2:$M$186,MATCH("女"&$Q8&"-1",計算用!$AN$2:$AN$186,0)),"")) | V8: =IF($Q8="","",IFERROR(INDEX(計算用!$I$2:$I$186,MATCH("女"&$Q8&"-1",計算用!$AN$2:$AN$186,0)),"")) | W8: =IF($Q8="","",IFERROR(INDEX(計算用!$D$2:$D$186,MATCH("女"&$Q8&"-2",計算用!$AN$2:$AN$186,0)),"")) | X8: =IF($Q8="","",IFERROR(INDEX(計算用!$M$2:$M$186,MATCH("女"&$Q8&"-2",計算用!$AN$2:$AN$186,0)),"")) | Y8: =IF($Q8="","",IFERROR(INDEX(計算用!$I$2:$I$186,MATCH("女"&$Q8&"-2",計算用!$AN$2:$AN$186,0)),"")) | Z8: =IF($Q8="","",IFERROR(INDEX(計算用!$D$2:$D$186,MATCH("女"&$Q8&"-3",計算用!$AN$2:$AN$186,0)),"")) | AA8: =IF($Q8="","",IFERROR(INDEX(計算用!$M$2:$M$186,MATCH("女"&$Q8&"-3",計算用!$AN$2:$AN$186,0)),"")) | AB8: =IF($Q8="","",IFERROR(INDEX(計算用!$I$2:$I$186,MATCH("女"&$Q8&"-3",計算用!$AN$2:$AN$186,0)),"")) | AC8: =IF($Q8="","",IFERROR(INDEX(計算用!$D$2:$D$186,MATCH("女"&$Q8&"-4",計算用!$AN$2:$AN$186,0)),"")) | AD8: =IF($Q8="","",IFERROR(INDEX(計算用!$M$2:$M$186,MATCH("女"&$Q8&"-4",計算用!$AN$2:$AN$186,0)),"")) | AE8: =IF($Q8="","",IFERROR(INDEX(計算用!$I$2:$I$186,MATCH("女"&$Q8&"-4",計算用!$AN$2:$AN$186,0)),""))
A9: =IF(ROW()-3<=計算用!$Q$9,ROW()-3,"") | B9: =IF($A9="","",INDEX(計算用!$T$2:$T$51,$A9)) | C9: =IF($A9="","","赤"&INDEX(計算用!$W$2:$W$51,$A9)&"白"&INDEX(計算用!$X$2:$X$51,$A9)) | D9: =IF($A9="","",IFERROR(INDEX(計算用!$D$2:$D$186,MATCH("男"&$A9&"-1",計算用!$AN$2:$AN$186,0)),"")) | E9: =IF($A9="","",IFERROR(INDEX(計算用!$M$2:$M$186,MATCH("男"&$A9&"-1",計算用!$AN$2:$AN$186,0)),"")) | F9: =IF($A9="","",IFERROR(INDEX(計算用!$I$2:$I$186,MATCH("男"&$A9&"-1",計算用!$AN$2:$AN$186,0)),"")) | G9: =IF($A9="","",IFERROR(INDEX(計算用!$D$2:$D$186,MATCH("男"&$A9&"-2",計算用!$AN$2:$AN$186,0)),"")) | H9: =IF($A9="","",IFERROR(INDEX(計算用!$M$2:$M$186,MATCH("男"&$A9&"-2",計算用!$AN$2:$AN$186,0)),"")) | I9: =IF($A9="","",IFERROR(INDEX(計算用!$I$2:$I$186,MATCH("男"&$A9&"-2",計算用!$AN$2:$AN$186,0)),"")) | J9: =IF($A9="","",IFERROR(INDEX(計算用!$D$2:$D$186,MATCH("男"&$A9&"-3",計算用!$AN$2:$AN$186,0)),"")) | K9: =IF($A9="","",IFERROR(INDEX(計算用!$M$2:$M$186,MATCH("男"&$A9&"-3",計算用!$AN$2:$AN$186,0)),"")) | L9: =IF($A9="","",IFERROR(INDEX(計算用!$I$2:$I$186,MATCH("男"&$A9&"-3",計算用!$AN$2:$AN$186,0)),"")) | M9: =IF($A9="","",IFERROR(INDEX(計算用!$D$2:$D$186,MATCH("男"&$A9&"-4",計算用!$AN$2:$AN$186,0)),"")) | N9: =IF($A9="","",IFERROR(INDEX(計算用!$M$2:$M$186,MATCH("男"&$A9&"-4",計算用!$AN$2:$AN$186,0)),"")) | O9: =IF($A9="","",IFERROR(INDEX(計算用!$I$2:$I$186,MATCH("男"&$A9&"-4",計算用!$AN$2:$AN$186,0)),"")) | Q9: =IF(ROW()-3<=計算用!$Q$11,ROW()-3,"") | R9: =IF($Q9="","",INDEX(計算用!$AC$2:$AC$51,$Q9)) | S9: =IF($Q9="","","赤"&INDEX(計算用!$AF$2:$AF$51,$Q9)&"白"&INDEX(計算用!$AG$2:$AG$51,$Q9)) | T9: =IF($Q9="","",IFERROR(INDEX(計算用!$D$2:$D$186,MATCH("女"&$Q9&"-1",計算用!$AN$2:$AN$186,0)),"")) | U9: =IF($Q9="","",IFERROR(INDEX(計算用!$M$2:$M$186,MATCH("女"&$Q9&"-1",計算用!$AN$2:$AN$186,0)),"")) | V9: =IF($Q9="","",IFERROR(INDEX(計算用!$I$2:$I$186,MATCH("女"&$Q9&"-1",計算用!$AN$2:$AN$186,0)),"")) | W9: =IF($Q9="","",IFERROR(INDEX(計算用!$D$2:$D$186,MATCH("女"&$Q9&"-2",計算用!$AN$2:$AN$186,0)),"")) | X9: =IF($Q9="","",IFERROR(INDEX(計算用!$M$2:$M$186,MATCH("女"&$Q9&"-2",計算用!$AN$2:$AN$186,0)),"")) | Y9: =IF($Q9="","",IFERROR(INDEX(計算用!$I$2:$I$186,MATCH("女"&$Q9&"-2",計算用!$AN$2:$AN$186,0)),"")) | Z9: =IF($Q9="","",IFERROR(INDEX(計算用!$D$2:$D$186,MATCH("女"&$Q9&"-3",計算用!$AN$2:$AN$186,0)),"")) | AA9: =IF($Q9="","",IFERROR(INDEX(計算用!$M$2:$M$186,MATCH("女"&$Q9&"-3",計算用!$AN$2:$AN$186,0)),"")) | AB9: =IF($Q9="","",IFERROR(INDEX(計算用!$I$2:$I$186,MATCH("女"&$Q9&"-3",計算用!$AN$2:$AN$186,0)),"")) | AC9: =IF($Q9="","",IFERROR(INDEX(計算用!$D$2:$D$186,MATCH("女"&$Q9&"-4",計算用!$AN$2:$AN$186,0)),"")) | AD9: =IF($Q9="","",IFERROR(INDEX(計算用!$M$2:$M$186,MATCH("女"&$Q9&"-4",計算用!$AN$2:$AN$186,0)),"")) | AE9: =IF($Q9="","",IFERROR(INDEX(計算用!$I$2:$I$186,MATCH("女"&$Q9&"-4",計算用!$AN$2:$AN$186,0)),""))
A10: =IF(ROW()-3<=計算用!$Q$9,ROW()-3,"") | B10: =IF($A10="","",INDEX(計算用!$T$2:$T$51,$A10)) | C10: =IF($A10="","","赤"&INDEX(計算用!$W$2:$W$51,$A10)&"白"&INDEX(計算用!$X$2:$X$51,$A10)) | D10: =IF($A10="","",IFERROR(INDEX(計算用!$D$2:$D$186,MATCH("男"&$A10&"-1",計算用!$AN$2:$AN$186,0)),"")) | E10: =IF($A10="","",IFERROR(INDEX(計算用!$M$2:$M$186,MATCH("男"&$A10&"-1",計算用!$AN$2:$AN$186,0)),"")) | F10: =IF($A10="","",IFERROR(INDEX(計算用!$I$2:$I$186,MATCH("男"&$A10&"-1",計算用!$AN$2:$AN$186,0)),"")) | G10: =IF($A10="","",IFERROR(INDEX(計算用!$D$2:$D$186,MATCH("男"&$A10&"-2",計算用!$AN$2:$AN$186,0)),"")) | H10: =IF($A10="","",IFERROR(INDEX(計算用!$M$2:$M$186,MATCH("男"&$A10&"-2",計算用!$AN$2:$AN$186,0)),"")) | I10: =IF($A10="","",IFERROR(INDEX(計算用!$I$2:$I$186,MATCH("男"&$A10&"-2",計算用!$AN$2:$AN$186,0)),"")) | J10: =IF($A10="","",IFERROR(INDEX(計算用!$D$2:$D$186,MATCH("男"&$A10&"-3",計算用!$AN$2:$AN$186,0)),"")) | K10: =IF($A10="","",IFERROR(INDEX(計算用!$M$2:$M$186,MATCH("男"&$A10&"-3",計算用!$AN$2:$AN$186,0)),"")) | L10: =IF($A10="","",IFERROR(INDEX(計算用!$I$2:$I$186,MATCH("男"&$A10&"-3",計算用!$AN$2:$AN$186,0)),"")) | M10: =IF($A10="","",IFERROR(INDEX(計算用!$D$2:$D$186,MATCH("男"&$A10&"-4",計算用!$AN$2:$AN$186,0)),"")) | N10: =IF($A10="","",IFERROR(INDEX(計算用!$M$2:$M$186,MATCH("男"&$A10&"-4",計算用!$AN$2:$AN$186,0)),"")) | O10: =IF($A10="","",IFERROR(INDEX(計算用!$I$2:$I$186,MATCH("男"&$A10&"-4",計算用!$AN$2:$AN$186,0)),"")) | Q10: =IF(ROW()-3<=計算用!$Q$11,ROW()-3,"") | R10: =IF($Q10="","",INDEX(計算用!$AC$2:$AC$51,$Q10)) | S10: =IF($Q10="","","赤"&INDEX(計算用!$AF$2:$AF$51,$Q10)&"白"&INDEX(計算用!$AG$2:$AG$51,$Q10)) | T10: =IF($Q10="","",IFERROR(INDEX(計算用!$D$2:$D$186,MATCH("女"&$Q10&"-1",計算用!$AN$2:$AN$186,0)),"")) | U10: =IF($Q10="","",IFERROR(INDEX(計算用!$M$2:$M$186,MATCH("女"&$Q10&"-1",計算用!$AN$2:$AN$186,0)),"")) | V10: =IF($Q10="","",IFERROR(INDEX(計算用!$I$2:$I$186,MATCH("女"&$Q10&"-1",計算用!$AN$2:$AN$186,0)),"")) | W10: =IF($Q10="","",IFERROR(INDEX(計算用!$D$2:$D$186,MATCH("女"&$Q10&"-2",計算用!$AN$2:$AN$186,0)),"")) | X10: =IF($Q10="","",IFERROR(INDEX(計算用!$M$2:$M$186,MATCH("女"&$Q10&"-2",計算用!$AN$2:$AN$186,0)),"")) | Y10: =IF($Q10="","",IFERROR(INDEX(計算用!$I$2:$I$186,MATCH("女"&$Q10&"-2",計算用!$AN$2:$AN$186,0)),"")) | Z10: =IF($Q10="","",IFERROR(INDEX(計算用!$D$2:$D$186,MATCH("女"&$Q10&"-3",計算用!$AN$2:$AN$186,0)),"")) | AA10: =IF($Q10="","",IFERROR(INDEX(計算用!$M$2:$M$186,MATCH("女"&$Q10&"-3",計算用!$AN$2:$AN$186,0)),"")) | AB10: =IF($Q10="","",IFERROR(INDEX(計算用!$I$2:$I$186,MATCH("女"&$Q10&"-3",計算用!$AN$2:$AN$186,0)),"")) | AC10: =IF($Q10="","",IFERROR(INDEX(計算用!$D$2:$D$186,MATCH("女"&$Q10&"-4",計算用!$AN$2:$AN$186,0)),"")) | AD10: =IF($Q10="","",IFERROR(INDEX(計算用!$M$2:$M$186,MATCH("女"&$Q10&"-4",計算用!$AN$2:$AN$186,0)),"")) | AE10: =IF($Q10="","",IFERROR(INDEX(計算用!$I$2:$I$186,MATCH("女"&$Q10&"-4",計算用!$AN$2:$AN$186,0)),""))
A11: =IF(ROW()-3<=計算用!$Q$9,ROW()-3,"") | B11: =IF($A11="","",INDEX(計算用!$T$2:$T$51,$A11)) | C11: =IF($A11="","","赤"&INDEX(計算用!$W$2:$W$51,$A11)&"白"&INDEX(計算用!$X$2:$X$51,$A11)) | D11: =IF($A11="","",IFERROR(INDEX(計算用!$D$2:$D$186,MATCH("男"&$A11&"-1",計算用!$AN$2:$AN$186,0)),"")) | E11: =IF($A11="","",IFERROR(INDEX(計算用!$M$2:$M$186,MATCH("男"&$A11&"-1",計算用!$AN$2:$AN$186,0)),"")) | F11: =IF($A11="","",IFERROR(INDEX(計算用!$I$2:$I$186,MATCH("男"&$A11&"-1",計算用!$AN$2:$AN$186,0)),"")) | G11: =IF($A11="","",IFERROR(INDEX(計算用!$D$2:$D$186,MATCH("男"&$A11&"-2",計算用!$AN$2:$AN$186,0)),"")) | H11: =IF($A11="","",IFERROR(INDEX(計算用!$M$2:$M$186,MATCH("男"&$A11&"-2",計算用!$AN$2:$AN$186,0)),"")) | I11: =IF($A11="","",IFERROR(INDEX(計算用!$I$2:$I$186,MATCH("男"&$A11&"-2",計算用!$AN$2:$AN$186,0)),"")) | J11: =IF($A11="","",IFERROR(INDEX(計算用!$D$2:$D$186,MATCH("男"&$A11&"-3",計算用!$AN$2:$AN$186,0)),"")) | K11: =IF($A11="","",IFERROR(INDEX(計算用!$M$2:$M$186,MATCH("男"&$A11&"-3",計算用!$AN$2:$AN$186,0)),"")) | L11: =IF($A11="","",IFERROR(INDEX(計算用!$I$2:$I$186,MATCH("男"&$A11&"-3",計算用!$AN$2:$AN$186,0)),"")) | M11: =IF($A11="","",IFERROR(INDEX(計算用!$D$2:$D$186,MATCH("男"&$A11&"-4",計算用!$AN$2:$AN$186,0)),"")) | N11: =IF($A11="","",IFERROR(INDEX(計算用!$M$2:$M$186,MATCH("男"&$A11&"-4",計算用!$AN$2:$AN$186,0)),"")) | O11: =IF($A11="","",IFERROR(INDEX(計算用!$I$2:$I$186,MATCH("男"&$A11&"-4",計算用!$AN$2:$AN$186,0)),"")) | Q11: =IF(ROW()-3<=計算用!$Q$11,ROW()-3,"") | R11: =IF($Q11="","",INDEX(計算用!$AC$2:$AC$51,$Q11)) | S11: =IF($Q11="","","赤"&INDEX(計算用!$AF$2:$AF$51,$Q11)&"白"&INDEX(計算用!$AG$2:$AG$51,$Q11)) | T11: =IF($Q11="","",IFERROR(INDEX(計算用!$D$2:$D$186,MATCH("女"&$Q11&"-1",計算用!$AN$2:$AN$186,0)),"")) | U11: =IF($Q11="","",IFERROR(INDEX(計算用!$M$2:$M$186,MATCH("女"&$Q11&"-1",計算用!$AN$2:$AN$186,0)),"")) | V11: =IF($Q11="","",IFERROR(INDEX(計算用!$I$2:$I$186,MATCH("女"&$Q11&"-1",計算用!$AN$2:$AN$186,0)),"")) | W11: =IF($Q11="","",IFERROR(INDEX(計算用!$D$2:$D$186,MATCH("女"&$Q11&"-2",計算用!$AN$2:$AN$186,0)),"")) | X11: =IF($Q11="","",IFERROR(INDEX(計算用!$M$2:$M$186,MATCH("女"&$Q11&"-2",計算用!$AN$2:$AN$186,0)),"")) | Y11: =IF($Q11="","",IFERROR(INDEX(計算用!$I$2:$I$186,MATCH("女"&$Q11&"-2",計算用!$AN$2:$AN$186,0)),"")) | Z11: =IF($Q11="","",IFERROR(INDEX(計算用!$D$2:$D$186,MATCH("女"&$Q11&"-3",計算用!$AN$2:$AN$186,0)),"")) | AA11: =IF($Q11="","",IFERROR(INDEX(計算用!$M$2:$M$186,MATCH("女"&$Q11&"-3",計算用!$AN$2:$AN$186,0)),"")) | AB11: =IF($Q11="","",IFERROR(INDEX(計算用!$I$2:$I$186,MATCH("女"&$Q11&"-3",計算用!$AN$2:$AN$186,0)),"")) | AC11: =IF($Q11="","",IFERROR(INDEX(計算用!$D$2:$D$186,MATCH("女"&$Q11&"-4",計算用!$AN$2:$AN$186,0)),"")) | AD11: =IF($Q11="","",IFERROR(INDEX(計算用!$M$2:$M$186,MATCH("女"&$Q11&"-4",計算用!$AN$2:$AN$186,0)),"")) | AE11: =IF($Q11="","",IFERROR(INDEX(計算用!$I$2:$I$186,MATCH("女"&$Q11&"-4",計算用!$AN$2:$AN$186,0)),""))
A12: =IF(ROW()-3<=計算用!$Q$9,ROW()-3,"") | B12: =IF($A12="","",INDEX(計算用!$T$2:$T$51,$A12)) | C12: =IF($A12="","","赤"&INDEX(計算用!$W$2:$W$51,$A12)&"白"&INDEX(計算用!$X$2:$X$51,$A12)) | D12: =IF($A12="","",IFERROR(INDEX(計算用!$D$2:$D$186,MATCH("男"&$A12&"-1",計算用!$AN$2:$AN$186,0)),"")) | E12: =IF($A12="","",IFERROR(INDEX(計算用!$M$2:$M$186,MATCH("男"&$A12&"-1",計算用!$AN$2:$AN$186,0)),"")) | F12: =IF($A12="","",IFERROR(INDEX(計算用!$I$2:$I$186,MATCH("男"&$A12&"-1",計算用!$AN$2:$AN$186,0)),"")) | G12: =IF($A12="","",IFERROR(INDEX(計算用!$D$2:$D$186,MATCH("男"&$A12&"-2",計算用!$AN$2:$AN$186,0)),"")) | H12: =IF($A12="","",IFERROR(INDEX(計算用!$M$2:$M$186,MATCH("男"&$A12&"-2",計算用!$AN$2:$AN$186,0)),"")) | I12: =IF($A12="","",IFERROR(INDEX(計算用!$I$2:$I$186,MATCH("男"&$A12&"-2",計算用!$AN$2:$AN$186,0)),"")) | J12: =IF($A12="","",IFERROR(INDEX(計算用!$D$2:$D$186,MATCH("男"&$A12&"-3",計算用!$AN$2:$AN$186,0)),"")) | K12: =IF($A12="","",IFERROR(INDEX(計算用!$M$2:$M$186,MATCH("男"&$A12&"-3",計算用!$AN$2:$AN$186,0)),"")) | L12: =IF($A12="","",IFERROR(INDEX(計算用!$I$2:$I$186,MATCH("男"&$A12&"-3",計算用!$AN$2:$AN$186,0)),"")) | M12: =IF($A12="","",IFERROR(INDEX(計算用!$D$2:$D$186,MATCH("男"&$A12&"-4",計算用!$AN$2:$AN$186,0)),"")) | N12: =IF($A12="","",IFERROR(INDEX(計算用!$M$2:$M$186,MATCH("男"&$A12&"-4",計算用!$AN$2:$AN$186,0)),"")) | O12: =IF($A12="","",IFERROR(INDEX(計算用!$I$2:$I$186,MATCH("男"&$A12&"-4",計算用!$AN$2:$AN$186,0)),"")) | Q12: =IF(ROW()-3<=計算用!$Q$11,ROW()-3,"") | R12: =IF($Q12="","",INDEX(計算用!$AC$2:$AC$51,$Q12)) | S12: =IF($Q12="","","赤"&INDEX(計算用!$AF$2:$AF$51,$Q12)&"白"&INDEX(計算用!$AG$2:$AG$51,$Q12)) | T12: =IF($Q12="","",IFERROR(INDEX(計算用!$D$2:$D$186,MATCH("女"&$Q12&"-1",計算用!$AN$2:$AN$186,0)),"")) | U12: =IF($Q12="","",IFERROR(INDEX(計算用!$M$2:$M$186,MATCH("女"&$Q12&"-1",計算用!$AN$2:$AN$186,0)),"")) | V12: =IF($Q12="","",IFERROR(INDEX(計算用!$I$2:$I$186,MATCH("女"&$Q12&"-1",計算用!$AN$2:$AN$186,0)),"")) | W12: =IF($Q12="","",IFERROR(INDEX(計算用!$D$2:$D$186,MATCH("女"&$Q12&"-2",計算用!$AN$2:$AN$186,0)),"")) | X12: =IF($Q12="","",IFERROR(INDEX(計算用!$M$2:$M$186,MATCH("女"&$Q12&"-2",計算用!$AN$2:$AN$186,0)),"")) | Y12: =IF($Q12="","",IFERROR(INDEX(計算用!$I$2:$I$186,MATCH("女"&$Q12&"-2",計算用!$AN$2:$AN$186,0)),"")) | Z12: =IF($Q12="","",IFERROR(INDEX(計算用!$D$2:$D$186,MATCH("女"&$Q12&"-3",計算用!$AN$2:$AN$186,0)),"")) | AA12: =IF($Q12="","",IFERROR(INDEX(計算用!$M$2:$M$186,MATCH("女"&$Q12&"-3",計算用!$AN$2:$AN$186,0)),"")) | AB12: =IF($Q12="","",IFERROR(INDEX(計算用!$I$2:$I$186,MATCH("女"&$Q12&"-3",計算用!$AN$2:$AN$186,0)),"")) | AC12: =IF($Q12="","",IFERROR(INDEX(計算用!$D$2:$D$186,MATCH("女"&$Q12&"-4",計算用!$AN$2:$AN$186,0)),"")) | AD12: =IF($Q12="","",IFERROR(INDEX(計算用!$M$2:$M$186,MATCH("女"&$Q12&"-4",計算用!$AN$2:$AN$186,0)),"")) | AE12: =IF($Q12="","",IFERROR(INDEX(計算用!$I$2:$I$186,MATCH("女"&$Q12&"-4",計算用!$AN$2:$AN$186,0)),""))
A13: =IF(ROW()-3<=計算用!$Q$9,ROW()-3,"") | B13: =IF($A13="","",INDEX(計算用!$T$2:$T$51,$A13)) | C13: =IF($A13="","","赤"&INDEX(計算用!$W$2:$W$51,$A13)&"白"&INDEX(計算用!$X$2:$X$51,$A13)) | D13: =IF($A13="","",IFERROR(INDEX(計算用!$D$2:$D$186,MATCH("男"&$A13&"-1",計算用!$AN$2:$AN$186,0)),"")) | E13: =IF($A13="","",IFERROR(INDEX(計算用!$M$2:$M$186,MATCH("男"&$A13&"-1",計算用!$AN$2:$AN$186,0)),"")) | F13: =IF($A13="","",IFERROR(INDEX(計算用!$I$2:$I$186,MATCH("男"&$A13&"-1",計算用!$AN$2:$AN$186,0)),"")) | G13: =IF($A13="","",IFERROR(INDEX(計算用!$D$2:$D$186,MATCH("男"&$A13&"-2",計算用!$AN$2:$AN$186,0)),"")) | H13: =IF($A13="","",IFERROR(INDEX(計算用!$M$2:$M$186,MATCH("男"&$A13&"-2",計算用!$AN$2:$AN$186,0)),"")) | I13: =IF($A13="","",IFERROR(INDEX(計算用!$I$2:$I$186,MATCH("男"&$A13&"-2",計算用!$AN$2:$AN$186,0)),"")) | J13: =IF($A13="","",IFERROR(INDEX(計算用!$D$2:$D$186,MATCH("男"&$A13&"-3",計算用!$AN$2:$AN$186,0)),"")) | K13: =IF($A13="","",IFERROR(INDEX(計算用!$M$2:$M$186,MATCH("男"&$A13&"-3",計算用!$AN$2:$AN$186,0)),"")) | L13: =IF($A13="","",IFERROR(INDEX(計算用!$I$2:$I$186,MATCH("男"&$A13&"-3",計算用!$AN$2:$AN$186,0)),"")) | M13: =IF($A13="","",IFERROR(INDEX(計算用!$D$2:$D$186,MATCH("男"&$A13&"-4",計算用!$AN$2:$AN$186,0)),"")) | N13: =IF($A13="","",IFERROR(INDEX(計算用!$M$2:$M$186,MATCH("男"&$A13&"-4",計算用!$AN$2:$AN$186,0)),"")) | O13: =IF($A13="","",IFERROR(INDEX(計算用!$I$2:$I$186,MATCH("男"&$A13&"-4",計算用!$AN$2:$AN$186,0)),"")) | Q13: =IF(ROW()-3<=計算用!$Q$11,ROW()-3,"") | R13: =IF($Q13="","",INDEX(計算用!$AC$2:$AC$51,$Q13)) | S13: =IF($Q13="","","赤"&INDEX(計算用!$AF$2:$AF$51,$Q13)&"白"&INDEX(計算用!$AG$2:$AG$51,$Q13)) | T13: =IF($Q13="","",IFERROR(INDEX(計算用!$D$2:$D$186,MATCH("女"&$Q13&"-1",計算用!$AN$2:$AN$186,0)),"")) | U13: =IF($Q13="","",IFERROR(INDEX(計算用!$M$2:$M$186,MATCH("女"&$Q13&"-1",計算用!$AN$2:$AN$186,0)),"")) | V13: =IF($Q13="","",IFERROR(INDEX(計算用!$I$2:$I$186,MATCH("女"&$Q13&"-1",計算用!$AN$2:$AN$186,0)),"")) | W13: =IF($Q13="","",IFERROR(INDEX(計算用!$D$2:$D$186,MATCH("女"&$Q13&"-2",計算用!$AN$2:$AN$186,0)),"")) | X13: =IF($Q13="","",IFERROR(INDEX(計算用!$M$2:$M$186,MATCH("女"&$Q13&"-2",計算用!$AN$2:$AN$186,0)),"")) | Y13: =IF($Q13="","",IFERROR(INDEX(計算用!$I$2:$I$186,MATCH("女"&$Q13&"-2",計算用!$AN$2:$AN$186,0)),"")) | Z13: =IF($Q13="","",IFERROR(INDEX(計算用!$D$2:$D$186,MATCH("女"&$Q13&"-3",計算用!$AN$2:$AN$186,0)),"")) | AA13: =IF($Q13="","",IFERROR(INDEX(計算用!$M$2:$M$186,MATCH("女"&$Q13&"-3",計算用!$AN$2:$AN$186,0)),"")) | AB13: =IF($Q13="","",IFERROR(INDEX(計算用!$I$2:$I$186,MATCH("女"&$Q13&"-3",計算用!$AN$2:$AN$186,0)),"")) | AC13: =IF($Q13="","",IFERROR(INDEX(計算用!$D$2:$D$186,MATCH("女"&$Q13&"-4",計算用!$AN$2:$AN$186,0)),"")) | AD13: =IF($Q13="","",IFERROR(INDEX(計算用!$M$2:$M$186,MATCH("女"&$Q13&"-4",計算用!$AN$2:$AN$186,0)),"")) | AE13: =IF($Q13="","",IFERROR(INDEX(計算用!$I$2:$I$186,MATCH("女"&$Q13&"-4",計算用!$AN$2:$AN$186,0)),""))
A14: =IF(ROW()-3<=計算用!$Q$9,ROW()-3,"") | B14: =IF($A14="","",INDEX(計算用!$T$2:$T$51,$A14)) | C14: =IF($A14="","","赤"&INDEX(計算用!$W$2:$W$51,$A14)&"白"&INDEX(計算用!$X$2:$X$51,$A14)) | D14: =IF($A14="","",IFERROR(INDEX(計算用!$D$2:$D$186,MATCH("男"&$A14&"-1",計算用!$AN$2:$AN$186,0)),"")) | E14: =IF($A14="","",IFERROR(INDEX(計算用!$M$2:$M$186,MATCH("男"&$A14&"-1",計算用!$AN$2:$AN$186,0)),"")) | F14: =IF($A14="","",IFERROR(INDEX(計算用!$I$2:$I$186,MATCH("男"&$A14&"-1",計算用!$AN$2:$AN$186,0)),"")) | G14: =IF($A14="","",IFERROR(INDEX(計算用!$D$2:$D$186,MATCH("男"&$A14&"-2",計算用!$AN$2:$AN$186,0)),"")) | H14: =IF($A14="","",IFERROR(INDEX(計算用!$M$2:$M$186,MATCH("男"&$A14&"-2",計算用!$AN$2:$AN$186,0)),"")) | I14: =IF($A14="","",IFERROR(INDEX(計算用!$I$2:$I$186,MATCH("男"&$A14&"-2",計算用!$AN$2:$AN$186,0)),"")) | J14: =IF($A14="","",IFERROR(INDEX(計算用!$D$2:$D$186,MATCH("男"&$A14&"-3",計算用!$AN$2:$AN$186,0)),"")) | K14: =IF($A14="","",IFERROR(INDEX(計算用!$M$2:$M$186,MATCH("男"&$A14&"-3",計算用!$AN$2:$AN$186,0)),"")) | L14: =IF($A14="","",IFERROR(INDEX(計算用!$I$2:$I$186,MATCH("男"&$A14&"-3",計算用!$AN$2:$AN$186,0)),"")) | M14: =IF($A14="","",IFERROR(INDEX(計算用!$D$2:$D$186,MATCH("男"&$A14&"-4",計算用!$AN$2:$AN$186,0)),"")) | N14: =IF($A14="","",IFERROR(INDEX(計算用!$M$2:$M$186,MATCH("男"&$A14&"-4",計算用!$AN$2:$AN$186,0)),"")) | O14: =IF($A14="","",IFERROR(INDEX(計算用!$I$2:$I$186,MATCH("男"&$A14&"-4",計算用!$AN$2:$AN$186,0)),"")) | Q14: =IF(ROW()-3<=計算用!$Q$11,ROW()-3,"") | R14: =IF($Q14="","",INDEX(計算用!$AC$2:$AC$51,$Q14)) | S14: =IF($Q14="","","赤"&INDEX(計算用!$AF$2:$AF$51,$Q14)&"白"&INDEX(計算用!$AG$2:$AG$51,$Q14)) | T14: =IF($Q14="","",IFERROR(INDEX(計算用!$D$2:$D$186,MATCH("女"&$Q14&"-1",計算用!$AN$2:$AN$186,0)),"")) | U14: =IF($Q14="","",IFERROR(INDEX(計算用!$M$2:$M$186,MATCH("女"&$Q14&"-1",計算用!$AN$2:$AN$186,0)),"")) | V14: =IF($Q14="","",IFERROR(INDEX(計算用!$I$2:$I$186,MATCH("女"&$Q14&"-1",計算用!$AN$2:$AN$186,0)),"")) | W14: =IF($Q14="","",IFERROR(INDEX(計算用!$D$2:$D$186,MATCH("女"&$Q14&"-2",計算用!$AN$2:$AN$186,0)),"")) | X14: =IF($Q14="","",IFERROR(INDEX(計算用!$M$2:$M$186,MATCH("女"&$Q14&"-2",計算用!$AN$2:$AN$186,0)),"")) | Y14: =IF($Q14="","",IFERROR(INDEX(計算用!$I$2:$I$186,MATCH("女"&$Q14&"-2",計算用!$AN$2:$AN$186,0)),"")) | Z14: =IF($Q14="","",IFERROR(INDEX(計算用!$D$2:$D$186,MATCH("女"&$Q14&"-3",計算用!$AN$2:$AN$186,0)),"")) | AA14: =IF($Q14="","",IFERROR(INDEX(計算用!$M$2:$M$186,MATCH("女"&$Q14&"-3",計算用!$AN$2:$AN$186,0)),"")) | AB14: =IF($Q14="","",IFERROR(INDEX(計算用!$I$2:$I$186,MATCH("女"&$Q14&"-3",計算用!$AN$2:$AN$186,0)),"")) | AC14: =IF($Q14="","",IFERROR(INDEX(計算用!$D$2:$D$186,MATCH("女"&$Q14&"-4",計算用!$AN$2:$AN$186,0)),"")) | AD14: =IF($Q14="","",IFERROR(INDEX(計算用!$M$2:$M$186,MATCH("女"&$Q14&"-4",計算用!$AN$2:$AN$186,0)),"")) | AE14: =IF($Q14="","",IFERROR(INDEX(計算用!$I$2:$I$186,MATCH("女"&$Q14&"-4",計算用!$AN$2:$AN$186,0)),""))
A15: =IF(ROW()-3<=計算用!$Q$9,ROW()-3,"") | B15: =IF($A15="","",INDEX(計算用!$T$2:$T$51,$A15)) | C15: =IF($A15="","","赤"&INDEX(計算用!$W$2:$W$51,$A15)&"白"&INDEX(計算用!$X$2:$X$51,$A15)) | D15: =IF($A15="","",IFERROR(INDEX(計算用!$D$2:$D$186,MATCH("男"&$A15&"-1",計算用!$AN$2:$AN$186,0)),"")) | E15: =IF($A15="","",IFERROR(INDEX(計算用!$M$2:$M$186,MATCH("男"&$A15&"-1",計算用!$AN$2:$AN$186,0)),"")) | F15: =IF($A15="","",IFERROR(INDEX(計算用!$I$2:$I$186,MATCH("男"&$A15&"-1",計算用!$AN$2:$AN$186,0)),"")) | G15: =IF($A15="","",IFERROR(INDEX(計算用!$D$2:$D$186,MATCH("男"&$A15&"-2",計算用!$AN$2:$AN$186,0)),"")) | H15: =IF($A15="","",IFERROR(INDEX(計算用!$M$2:$M$186,MATCH("男"&$A15&"-2",計算用!$AN$2:$AN$186,0)),"")) | I15: =IF($A15="","",IFERROR(INDEX(計算用!$I$2:$I$186,MATCH("男"&$A15&"-2",計算用!$AN$2:$AN$186,0)),"")) | J15: =IF($A15="","",IFERROR(INDEX(計算用!$D$2:$D$186,MATCH("男"&$A15&"-3",計算用!$AN$2:$AN$186,0)),"")) | K15: =IF($A15="","",IFERROR(INDEX(計算用!$M$2:$M$186,MATCH("男"&$A15&"-3",計算用!$AN$2:$AN$186,0)),"")) | L15: =IF($A15="","",IFERROR(INDEX(計算用!$I$2:$I$186,MATCH("男"&$A15&"-3",計算用!$AN$2:$AN$186,0)),"")) | M15: =IF($A15="","",IFERROR(INDEX(計算用!$D$2:$D$186,MATCH("男"&$A15&"-4",計算用!$AN$2:$AN$186,0)),"")) | N15: =IF($A15="","",IFERROR(INDEX(計算用!$M$2:$M$186,MATCH("男"&$A15&"-4",計算用!$AN$2:$AN$186,0)),"")) | O15: =IF($A15="","",IFERROR(INDEX(計算用!$I$2:$I$186,MATCH("男"&$A15&"-4",計算用!$AN$2:$AN$186,0)),"")) | Q15: =IF(ROW()-3<=計算用!$Q$11,ROW()-3,"") | R15: =IF($Q15="","",INDEX(計算用!$AC$2:$AC$51,$Q15)) | S15: =IF($Q15="","","赤"&INDEX(計算用!$AF$2:$AF$51,$Q15)&"白"&INDEX(計算用!$AG$2:$AG$51,$Q15)) | T15: =IF($Q15="","",IFERROR(INDEX(計算用!$D$2:$D$186,MATCH("女"&$Q15&"-1",計算用!$AN$2:$AN$186,0)),"")) | U15: =IF($Q15="","",IFERROR(INDEX(計算用!$M$2:$M$186,MATCH("女"&$Q15&"-1",計算用!$AN$2:$AN$186,0)),"")) | V15: =IF($Q15="","",IFERROR(INDEX(計算用!$I$2:$I$186,MATCH("女"&$Q15&"-1",計算用!$AN$2:$AN$186,0)),"")) | W15: =IF($Q15="","",IFERROR(INDEX(計算用!$D$2:$D$186,MATCH("女"&$Q15&"-2",計算用!$AN$2:$AN$186,0)),"")) | X15: =IF($Q15="","",IFERROR(INDEX(計算用!$M$2:$M$186,MATCH("女"&$Q15&"-2",計算用!$AN$2:$AN$186,0)),"")) | Y15: =IF($Q15="","",IFERROR(INDEX(計算用!$I$2:$I$186,MATCH("女"&$Q15&"-2",計算用!$AN$2:$AN$186,0)),"")) | Z15: =IF($Q15="","",IFERROR(INDEX(計算用!$D$2:$D$186,MATCH("女"&$Q15&"-3",計算用!$AN$2:$AN$186,0)),"")) | AA15: =IF($Q15="","",IFERROR(INDEX(計算用!$M$2:$M$186,MATCH("女"&$Q15&"-3",計算用!$AN$2:$AN$186,0)),"")) | AB15: =IF($Q15="","",IFERROR(INDEX(計算用!$I$2:$I$186,MATCH("女"&$Q15&"-3",計算用!$AN$2:$AN$186,0)),"")) | AC15: =IF($Q15="","",IFERROR(INDEX(計算用!$D$2:$D$186,MATCH("女"&$Q15&"-4",計算用!$AN$2:$AN$186,0)),"")) | AD15: =IF($Q15="","",IFERROR(INDEX(計算用!$M$2:$M$186,MATCH("女"&$Q15&"-4",計算用!$AN$2:$AN$186,0)),"")) | AE15: =IF($Q15="","",IFERROR(INDEX(計算用!$I$2:$I$186,MATCH("女"&$Q15&"-4",計算用!$AN$2:$AN$186,0)),""))
... A53: =IF(ROW()-3<=計算用!$Q$9,ROW()-3,"") | B53: =IF($A53="","",INDEX(計算用!$T$2:$T$51,$A53)) | C53: =IF($A53="","","赤"&INDEX(計算用!$W$2:$W$51,$A53)&"白"&INDEX(計算用!$X$2:$X$51,$A53)) | D53: =IF($A53="","",IFERROR(INDEX(計算用!$D$2:$D$186,MATCH("男"&$A53&"-1",計算用!$AN$2:$AN$186,0)),"")) | E53: =IF($A53="","",IFERROR(INDEX(計算用!$M$2:$M$186,MATCH("男"&$A53&"-1",計算用!$AN$2:$AN$186,0)),"")) | F53: =IF($A53="","",IFERROR(INDEX(計算用!$I$2:$I$186,MATCH("男"&$A53&"-1",計算用!$AN$2:$AN$186,0)),"")) | G53: =IF($A53="","",IFERROR(INDEX(計算用!$D$2:$D$186,MATCH("男"&$A53&"-2",計算用!$AN$2:$AN$186,0)),"")) | H53: =IF($A53="","",IFERROR(INDEX(計算用!$M$2:$M$186,MATCH("男"&$A53&"-2",計算用!$AN$2:$AN$186,0)),"")) | I53: =IF($A53="","",IFERROR(INDEX(計算用!$I$2:$I$186,MATCH("男"&$A53&"-2",計算用!$AN$2:$AN$186,0)),"")) | J53: =IF($A53="","",IFERROR(INDEX(計算用!$D$2:$D$186,MATCH("男"&$A53&"-3",計算用!$AN$2:$AN$186,0)),"")) | K53: =IF($A53="","",IFERROR(INDEX(計算用!$M$2:$M$186,MATCH("男"&$A53&"-3",計算用!$AN$2:$AN$186,0)),"")) | L53: =IF($A53="","",IFERROR(INDEX(計算用!$I$2:$I$186,MATCH("男"&$A53&"-3",計算用!$AN$2:$AN$186,0)),"")) | M53: =IF($A53="","",IFERROR(INDEX(計算用!$D$2:$D$186,MATCH("男"&$A53&"-4",計算用!$AN$2:$AN$186,0)),"")) | N53: =IF($A53="","",IFERROR(INDEX(計算用!$M$2:$M$186,MATCH("男"&$A53&"-4",計算用!$AN$2:$AN$186,0)),"")) | O53: =IF($A53="","",IFERROR(INDEX(計算用!$I$2:$I$186,MATCH("男"&$A53&"-4",計算用!$AN$2:$AN$186,0)),"")) | Q53: =IF(ROW()-3<=計算用!$Q$11,ROW()-3,"") | R53: =IF($Q53="","",INDEX(計算用!$AC$2:$AC$51,$Q53)) | S53: =IF($Q53="","","赤"&INDEX(計算用!$AF$2:$AF$51,$Q53)&"白"&INDEX(計算用!$AG$2:$AG$51,$Q53)) | T53: =IF($Q53="","",IFERROR(INDEX(計算用!$D$2:$D$186,MATCH("女"&$Q53&"-1",計算用!$AN$2:$AN$186,0)),"")) | U53: =IF($Q53="","",IFERROR(INDEX(計算用!$M$2:$M$186,MATCH("女"&$Q53&"-1",計算用!$AN$2:$AN$186,0)),"")) | V53: =IF($Q53="","",IFERROR(INDEX(計算用!$I$2:$I$186,MATCH("女"&$Q53&"-1",計算用!$AN$2:$AN$186,0)),"")) | W53: =IF($Q53="","",IFERROR(INDEX(計算用!$D$2:$D$186,MATCH("女"&$Q53&"-2",計算用!$AN$2:$AN$186,0)),"")) | X53: =IF($Q53="","",IFERROR(INDEX(計算用!$M$2:$M$186,MATCH("女"&$Q53&"-2",計算用!$AN$2:$AN$186,0)),"")) | Y53: =IF($Q53="","",IFERROR(INDEX(計算用!$I$2:$I$186,MATCH("女"&$Q53&"-2",計算用!$AN$2:$AN$186,0)),"")) | Z53: =IF($Q53="","",IFERROR(INDEX(計算用!$D$2:$D$186,MATCH("女"&$Q53&"-3",計算用!$AN$2:$AN$186,0)),"")) | AA53: =IF($Q53="","",IFERROR(INDEX(計算用!$M$2:$M$186,MATCH("女"&$Q53&"-3",計算用!$AN$2:$AN$186,0)),"")) | AB53: =IF($Q53="","",IFERROR(INDEX(計算用!$I$2:$I$186,MATCH("女"&$Q53&"-3",計算用!$AN$2:$AN$186,0)),"")) | AC53: =IF($Q53="","",IFERROR(INDEX(計算用!$D$2:$D$186,MATCH("女"&$Q53&"-4",計算用!$AN$2:$AN$186,0)),"")) | AD53: =IF($Q53="","",IFERROR(INDEX(計算用!$M$2:$M$186,MATCH("女"&$Q53&"-4",計算用!$AN$2:$AN$186,0)),"")) | AE53: =IF($Q53="","",IFERROR(INDEX(計算用!$I$2:$I$186,MATCH("女"&$Q53&"-4",計算用!$AN$2:$AN$186,0)),""))

Sheet 計算用
A1: 通し番号 | B1: クラス番号 | C1: クラス内行 | D1: 名前 | E1: 性別(入力) | F1: 性別 | G1: タイム | H1: 赤白(入力) | I1: 赤白 | J1: 区分 | K1: 区分内順位 | L1: 検索キー | M1: クラス | N1: 入力不足 | P1: 区分 | Q1: 人数 | S1: 男組 | T1: 男人数 | U1: 男赤残り | V1: 男白残り | W1: 男赤人数 | X1: 男白人数 | Y1: 男赤累計 | Z1: 男白累計 | AB1: 女組 | AC1: 女人数 | AD1: 女赤残り | AE1: 女白残り | AF1: 女赤人数 | AG1: 女白人数 | AH1: 女赤累計 | AI1: 女白累計 | AK1: 組 | AL1: 前の組までの人数 | AM1: 組内番号 | AN1: 組キー
A2: =ROW()-1 | B2: =INT((A2-1)/37)+1 | C2: =MOD(A2-1,37)+1 | D2: =INDEX(①データ入力!$B$3:$Y$39,C2,(B2-1)*5+1)&"" | E2: =INDEX(①データ入力!$B$3:$Y$39,C2,(B2-1)*5+2)&"" | F2: =IF(OR(E2="1",E2="１",E2="男"),"男",IF(OR(E2="2",E2="２",E2="女"),"女","")) | G2: =INDEX(①データ入力!$B$3:$Y$39,C2,(B2-1)*5+3) | H2: =INDEX(①データ入力!$B$3:$Y$39,C2,(B2-1)*5+4)&"" | I2: =IF(LEFT(TRIM(H2),1)="赤","赤",IF(LEFT(TRIM(H2),1)="白","白","")) | J2: =IF(AND(D2<>"",F2<>"",I2<>"",ISNUMBER(G2)),F2&I2,"") | K2: =IF(J2="","",COUNTIFS($J$2:$J$186,J2,$G$2:$G$186,"<"&G2)+COUNTIFS($J$2:$J$186,J2,$G$2:$G$186,G2,$A$2:$A$186,"<"&A2)+1) | L2: =IF(J2="","",J2&K2) | M2: =B2&"組" | N2: =IF(AND(D2<>"",J2=""),1,0) | P2: 男赤 | Q2: =COUNTIF($J$2:$J$186,P2) | S2: 1 | T2: =IF(OR($Q$9=0,S2>$Q$9),0,INT($Q$8/$Q$9)+IF(S2<=MOD($Q$8,$Q$9),1,0)) | U2: =$Q$2 | V2: =$Q$3 | W2: =IF(T2=0,0,MIN(U2,MAX(IF(MOD(T2,2)=0,T2/2,IF(U2>=V2,(T2+1)/2,(T2-1)/2)),T2-V2))) | X2: =T2-W2 | Y2: =0+W2 | Z2: =0+X2 | AB2: 1 | AC2: =IF(OR($Q$11=0,AB2>$Q$11),0,INT($Q$10/$Q$11)+IF(AB2<=MOD($Q$10,$Q$11),1,0)) | AD2: =$Q$4 | AE2: =$Q$5 | AF2: =IF(AC2=0,0,MIN(AD2,MAX(IF(MOD(AC2,2)=0,AC2/2,IF(AD2>=AE2,(AC2+1)/2,(AC2-1)/2)),AC2-AE2))) | AG2: =AC2-AF2 | AH2: =0+AF2 | AI2: =0+AG2 | AK2: =IF(J2="","",IF(J2="男赤",COUNTIF($Y$2:$Y$51,"<"&K2),IF(J2="男白",COUNTIF($Z$2:$Z$51,"<"&K2),IF(J2="女赤",COUNTIF($AH$2:$AH$51,"<"&K2),COUNTIF($AI$2:$AI$51,"<"&K2))))+1) | AL2: =IF(AK2="","",IF(AK2=1,0,IF(J2="男赤",INDEX($Y$2:$Y$51,AK2-1),IF(J2="男白",INDEX($Z$2:$Z$51,AK2-1),IF(J2="女赤",INDEX($AH$2:$AH$51,AK2-1),INDEX($AI$2:$AI$51,AK2-1)))))) | AM2: =IF(AK2="","",IF(RIGHT(J2,1)="赤",K2-AL2,IF(LEFT(J2,1)="男",INDEX($W$2:$W$51,AK2),INDEX($AF$2:$AF$51,AK2))+K2-AL2)) | AN2: =IF(AK2="","",F2&AK2&"-"&AM2)
A3: =ROW()-1 | B3: =INT((A3-1)/37)+1 | C3: =MOD(A3-1,37)+1 | D3: =INDEX(①データ入力!$B$3:$Y$39,C3,(B3-1)*5+1)&"" | E3: =INDEX(①データ入力!$B$3:$Y$39,C3,(B3-1)*5+2)&"" | F3: =IF(OR(E3="1",E3="１",E3="男"),"男",IF(OR(E3="2",E3="２",E3="女"),"女","")) | G3: =INDEX(①データ入力!$B$3:$Y$39,C3,(B3-1)*5+3) | H3: =INDEX(①データ入力!$B$3:$Y$39,C3,(B3-1)*5+4)&"" | I3: =IF(LEFT(TRIM(H3),1)="赤","赤",IF(LEFT(TRIM(H3),1)="白","白","")) | J3: =IF(AND(D3<>"",F3<>"",I3<>"",ISNUMBER(G3)),F3&I3,"") | K3: =IF(J3="","",COUNTIFS($J$2:$J$186,J3,$G$2:$G$186,"<"&G3)+COUNTIFS($J$2:$J$186,J3,$G$2:$G$186,G3,$A$2:$A$186,"<"&A3)+1) | L3: =IF(J3="","",J3&K3) | M3: =B3&"組" | N3: =IF(AND(D3<>"",J3=""),1,0) | P3: 男白 | Q3: =COUNTIF($J$2:$J$186,P3) | S3: 2 | T3: =IF(OR($Q$9=0,S3>$Q$9),0,INT($Q$8/$Q$9)+IF(S3<=MOD($Q$8,$Q$9),1,0)) | U3: =$Q$2-Y2 | V3: =$Q$3-Z2 | W3: =IF(T3=0,0,MIN(U3,MAX(IF(MOD(T3,2)=0,T3/2,IF(U3>=V3,(T3+1)/2,(T3-1)/2)),T3-V3))) | X3: =T3-W3 | Y3: =Y2+W3 | Z3: =Z2+X3 | AB3: 2 | AC3: =IF(OR($Q$11=0,AB3>$Q$11),0,INT($Q$10/$Q$11)+IF(AB3<=MOD($Q$10,$Q$11),1,0)) | AD3: =$Q$4-AH2 | AE3: =$Q$5-AI2 | AF3: =IF(AC3=0,0,MIN(AD3,MAX(IF(MOD(AC3,2)=0,AC3/2,IF(AD3>=AE3,(AC3+1)/2,(AC3-1)/2)),AC3-AE3))) | AG3: =AC3-AF3 | AH3: =AH2+AF3 | AI3: =AI2+AG3 | AK3: =IF(J3="","",IF(J3="男赤",COUNTIF($Y$2:$Y$51,"<"&K3),IF(J3="男白",COUNTIF($Z$2:$Z$51,"<"&K3),IF(J3="女赤",COUNTIF($AH$2:$AH$51,"<"&K3),COUNTIF($AI$2:$AI$51,"<"&K3))))+1) | AL3: =IF(AK3="","",IF(AK3=1,0,IF(J3="男赤",INDEX($Y$2:$Y$51,AK3-1),IF(J3="男白",INDEX($Z$2:$Z$51,AK3-1),IF(J3="女赤",INDEX($AH$2:$AH$51,AK3-1),INDEX($AI$2:$AI$51,AK3-1)))))) | AM3: =IF(AK3="","",IF(RIGHT(J3,1)="赤",K3-AL3,IF(LEFT(J3,1)="男",INDEX($W$2:$W$51,AK3),INDEX($AF$2:$AF$51,AK3))+K3-AL3)) | AN3: =IF(AK3="","",F3&AK3&"-"&AM3)
A4: =ROW()-1 | B4: =INT((A4-1)/37)+1 | C4: =MOD(A4-1,37)+1 | D4: =INDEX(①データ入力!$B$3:$Y$39,C4,(B4-1)*5+1)&"" | E4: =INDEX(①データ入力!$B$3:$Y$39,C4,(B4-1)*5+2)&"" | F4: =IF(OR(E4="1",E4="１",E4="男"),"男",IF(OR(E4="2",E4="２",E4="女"),"女","")) | G4: =INDEX(①データ入力!$B$3:$Y$39,C4,(B4-1)*5+3) | H4: =INDEX(①データ入力!$B$3:$Y$39,C4,(B4-1)*5+4)&"" | I4: =IF(LEFT(TRIM(H4),1)="赤","赤",IF(LEFT(TRIM(H4),1)="白","白","")) | J4: =IF(AND(D4<>"",F4<>"",I4<>"",ISNUMBER(G4)),F4&I4,"") | K4: =IF(J4="","",COUNTIFS($J$2:$J$186,J4,$G$2:$G$186,"<"&G4)+COUNTIFS($J$2:$J$186,J4,$G$2:$G$186,G4,$A$2:$A$186,"<"&A4)+1) | L4: =IF(J4="","",J4&K4) | M4: =B4&"組" | N4: =IF(AND(D4<>"",J4=""),1,0) | P4: 女赤 | Q4: =COUNTIF($J$2:$J$186,P4) | S4: 3 | T4: =IF(OR($Q$9=0,S4>$Q$9),0,INT($Q$8/$Q$9)+IF(S4<=MOD($Q$8,$Q$9),1,0)) | U4: =$Q$2-Y3 | V4: =$Q$3-Z3 | W4: =IF(T4=0,0,MIN(U4,MAX(IF(MOD(T4,2)=0,T4/2,IF(U4>=V4,(T4+1)/2,(T4-1)/2)),T4-V4))) | X4: =T4-W4 | Y4: =Y3+W4 | Z4: =Z3+X4 | AB4: 3 | AC4: =IF(OR($Q$11=0,AB4>$Q$11),0,INT($Q$10/$Q$11)+IF(AB4<=MOD($Q$10,$Q$11),1,0)) | AD4: =$Q$4-AH3 | AE4: =$Q$5-AI3 | AF4: =IF(AC4=0,0,MIN(AD4,MAX(IF(MOD(AC4,2)=0,AC4/2,IF(AD4>=AE4,(AC4+1)/2,(AC4-1)/2)),AC4-AE4))) | AG4: =AC4-AF4 | AH4: =AH3+AF4 | AI4: =AI3+AG4 | AK4: =IF(J4="","",IF(J4="男赤",COUNTIF($Y$2:$Y$51,"<"&K4),IF(J4="男白",COUNTIF($Z$2:$Z$51,"<"&K4),IF(J4="女赤",COUNTIF($AH$2:$AH$51,"<"&K4),COUNTIF($AI$2:$AI$51,"<"&K4))))+1) | AL4: =IF(AK4="","",IF(AK4=1,0,IF(J4="男赤",INDEX($Y$2:$Y$51,AK4-1),IF(J4="男白",INDEX($Z$2:$Z$51,AK4-1),IF(J4="女赤",INDEX($AH$2:$AH$51,AK4-1),INDEX($AI$2:$AI$51,AK4-1)))))) | AM4: =IF(AK4="","",IF(RIGHT(J4,1)="赤",K4-AL4,IF(LEFT(J4,1)="男",INDEX($W$2:$W$51,AK4),INDEX($AF$2:$AF$51,AK4))+K4-AL4)) | AN4: =IF(AK4="","",F4&AK4&"-"&AM4)
A5: =ROW()-1 | B5: =INT((A5-1)/37)+1 | C5: =MOD(A5-1,37)+1 | D5: =INDEX(①データ入力!$B$3:$Y$39,C5,(B5-1)*5+1)&"" | E5: =INDEX(①データ入力!$B$3:$Y$39,C5,(B5-1)*5+2)&"" | F5: =IF(OR(E5="1",E5="１",E5="男"),"男",IF(OR(E5="2",E5="２",E5="女"),"女","")) | G5: =INDEX(①データ入力!$B$3:$Y$39,C5,(B5-1)*5+3) | H5: =INDEX(①データ入力!$B$3:$Y$39,C5,(B5-1)*5+4)&"" | I5: =IF(LEFT(TRIM(H5),1)="赤","赤",IF(LEFT(TRIM(H5),1)="白","白","")) | J5: =IF(AND(D5<>"",F5<>"",I5<>"",ISNUMBER(G5)),F5&I5,"") | K5: =IF(J5="","",COUNTIFS($J$2:$J$186,J5,$G$2:$G$186,"<"&G5)+COUNTIFS($J$2:$J$186,J5,$G$2:$G$186,G5,$A$2:$A$186,"<"&A5)+1) | L5: =IF(J5="","",J5&K5) | M5: =B5&"組" | N5: =IF(AND(D5<>"",J5=""),1,0) | P5: 女白 | Q5: =COUNTIF($J$2:$J$186,P5) | S5: 4 | T5: =IF(OR($Q$9=0,S5>$Q$9),0,INT($Q$8/$Q$9)+IF(S5<=MOD($Q$8,$Q$9),1,0)) | U5: =$Q$2-Y4 | V5: =$Q$3-Z4 | W5: =IF(T5=0,0,MIN(U5,MAX(IF(MOD(T5,2)=0,T5/2,IF(U5>=V5,(T5+1)/2,(T5-1)/2)),T5-V5))) | X5: =T5-W5 | Y5: =Y4+W5 | Z5: =Z4+X5 | AB5: 4 | AC5: =IF(OR($Q$11=0,AB5>$Q$11),0,INT($Q$10/$Q$11)+IF(AB5<=MOD($Q$10,$Q$11),1,0)) | AD5: =$Q$4-AH4 | AE5: =$Q$5-AI4 | AF5: =IF(AC5=0,0,MIN(AD5,MAX(IF(MOD(AC5,2)=0,AC5/2,IF(AD5>=AE5,(AC5+1)/2,(AC5-1)/2)),AC5-AE5))) | AG5: =AC5-AF5 | AH5: =AH4+AF5 | AI5: =AI4+AG5 | AK5: =IF(J5="","",IF(J5="男赤",COUNTIF($Y$2:$Y$51,"<"&K5),IF(J5="男白",COUNTIF($Z$2:$Z$51,"<"&K5),IF(J5="女赤",COUNTIF($AH$2:$AH$51,"<"&K5),COUNTIF($AI$2:$AI$51,"<"&K5))))+1) | AL5: =IF(AK5="","",IF(AK5=1,0,IF(J5="男赤",INDEX($Y$2:$Y$51,AK5-1),IF(J5="男白",INDEX($Z$2:$Z$51,AK5-1),IF(J5="女赤",INDEX($AH$2:$AH$51,AK5-1),INDEX($AI$2:$AI$51,AK5-1)))))) | AM5: =IF(AK5="","",IF(RIGHT(J5,1)="赤",K5-AL5,IF(LEFT(J5,1)="男",INDEX($W$2:$W$51,AK5),INDEX($AF$2:$AF$51,AK5))+K5-AL5)) | AN5: =IF(AK5="","",F5&AK5&"-"&AM5)
