Workbook

Sheet ①データ入力
B1: 1組の人数 男子 | C1: 4 | D1: 女子 | E1: 5 | I1: 名簿から名前をコピペして使ってください。３年生以上は性別欄を記入しないと動きません。タイムまで入力したら②のシートへ
A2: No. | B2: 1組 名前 | C2: 性別 (1=男子 2=女子) | D2: タイム (1/100秒) | E2: 赤or白 | G2: 2組 名前 | H2: 性別 (1=男子 2=女子) | I2: タイム (1/100秒) | J2: 赤or白 | L2: 3組 名前 | M2: 性別 (1=男子 2=女子) | N2: タイム (1/100秒) | O2: 赤or白 | Q2: 4組 名前 | R2: 性別 (1=男子 2=女子) | S2: タイム (1/100秒) | T2: 赤or白 | V2: 5組 名前 | W2: 性別 (1=男子 2=女子) | X2: タイム (1/100秒) | Y2: 赤or白
A3: 1 | B3: 近藤 りく | C3: 1 | D3: 8.89 | E3: 赤 | G3: 木村 ひまり | H3: 2 | I3: 9.58 | J3: 赤 | L3: 鈴木 たいが | M3: 1 | N3: 10.43 | O3: 赤 | Q3: 山口 しょう | R3: 1 | S3: 9.57 | T3: 赤
A4: 2 | B4: 小林 ゆな | C4: 2 | D4: 9.63 | E4: 白 | G4: 高橋 ひまり | H4: 2 | I4: 8.97 | J4: 赤 | L4: 伊藤 たいが | M4: 1 | N4: 8.05 | O4: 白 | Q4: 池田 ゆい | R4: 2 | S4: 10.31 | T4: 白
A5: 3 | B5: 木村 ひなた | C5: 1 | D5: 9.34 | E5: 赤 | G5: 鈴木 はると | H5: 1 | I5: 9.34 | J5: 赤 | L5: 木村 さく | M5: 1 | N5: 8.47 | O5: 白 | Q5: 清水 そら | R5: 1 | S5: 9.11 | T5: 赤
A6: 4 | B6: 後藤 かのん | C6: 2 | D6: 9.31 | E6: 白 | G6: 高橋 さく | H6: 1 | I6: 8.47 | J6: 白 | L6: 井上 いつき | M6: 1 | N6: 8.82 | O6: 赤 | Q6: 後藤 ゆな | R6: 2 | S6: 9.29 | T6: 白
A7: 5 | B7: 井上 ほのか | C7: 2 | D7: 9.3 | E7: 白 | G7: 後藤 けんた | H7: 1 | I7: 9.71 | J7: 白 | L7: 斎藤 だいち | M7: 1 | N7: 10.02 | O7: 白 | Q7: 清水 しょう | R7: 1 | S7: 8.73 | T7: 白
A8: 6 | B8: 前田 かいと | C8: 1 | D8: 8.36 | E8: 白 | G8: 松本 かいと | H8: 1 | I8: 9.42 | J8: 白 | L8: 木村 ゆな | M8: 2 | N8: 9.49 | O8: 白 | Q8: 長谷川 ひまり | R8: 2 | S8: 10.17 | T8: 白
A9: 7 | B9: 山本 けんた | C9: 1 | D9: 8.37 | E9: 赤 | G9: 松本 たいが | H9: 1 | I9: 9.61 | J9: 赤 | L9: 伊藤 つむぎ | M9: 2 | N9: 10.12 | O9: 赤 | Q9: 佐藤 そうた | R9: 1 | S9: 10.24 | T9: 白
A10: 8 | B10: 清水 こはる | C10: 2 | D10: 9.93 | E10: 赤 | G10: 伊藤 ゆな | H10: 2 | I10: 11.04 | J10: 赤 | L10: 橋本 ひなた | M10: 1 | N10: 10.03 | O10: 赤 | Q10: 山本 つばさ | R10: 1 | S10: 8.85 | T10: 白
A11: 9 | B11: 佐藤 けんた | C11: 1 | D11: 9.17 | E11: 赤 | G11: 渡辺 みなと | H11: 1 | I11: 9.81 | J11: 白 | L11: 吉田 ひなた | M11: 1 | N11: 9.63 | O11: 赤 | Q11: 清水 ひな | R11: 2 | S11: 9.24 | T11: 白
A12: 10 | B12: 岡田 さら | C12: 2 | D12: 10.33 | E12: 白 | G12: 山田 あかり | H12: 2 | I12: 9.67 | J12: 白 | L12: 石川 めい | M12: 2 | N12: 9.84 | O12: 赤 | Q12: 伊藤 ひまり | R12: 2 | S12: 10.05 | T12: 赤
A13: 11 | B13: 中村 ゆな | C13: 2 | D13: 8.62 | E13: 白 | G13: 山本 かのん | H13: 2 | I13: 9.29 | J13: 白 | L13: 小林 ほのか | M13: 2 | N13: 9.51 | O13: 赤 | Q13: 森 りく | R13: 1 | S13: 8.5 | T13: 赤
A14: 12 | B14: 木村 りょう | C14: 1 | D14: 9.62 | E14: 赤 | G14: 中村 りく | H14: 1 | I14: 9 | J14: 白 | L14: 森 みなと | M14: 1 | N14: 8.74 | O14: 白 | Q14: 石川 あかり | R14: 2 | S14: 10.83 | T14: 赤
... A24: 22 | B24: 佐藤 れん | C24: 1 | D24: 8.86 | E24: 白 | G24: 加藤 ことね | H24: 2 | I24: 9.42 | J24: 白 | L24: 森 みお | M24: 2 | N24: 9.19 | O24: 白 | Q24: 田中 こうき | R24: 1 | S24: 8.68 | T24: 白
A25: 23 | B25: 石川 さら | C25: 2 | D25: 10.04 | E25: 赤
A26: 24 | B26: 村上 かいと | C26: 1 | D26: 7.97 | E26: 白
A27: 25
A28: 26
A29: 27
A30: 28
A31: 29
A32: 30
A33: 31
A34: 32
A35: 33
A36: 34
A37: 35
A38: 36
A39: 37

Sheet 組ごとタイム順
A1: 男子 | J1: 女子 | S1: =IF(計算用!$Q$6>0,"※名前はあるのに性別・タイム・赤白のどれかが未入力で、表に出ていない人が"&計算用!$Q$6&"人います","")
B2: 赤組 | F2: 白組 | K2: 赤組 | O2: 白組
B3: 名前 | C3: クラス | D3: タイム | F3: 名前 | G3: クラス | H3: タイム | K3: 名前 | L3: クラス | M3: タイム | O3: 名前 | P3: クラス | Q3: タイム
A4: =IF(ROW()-3<=MAX(計算用!$Q$2,計算用!$Q$3),ROW()-3,"") | B4: =IFERROR(INDEX(計算用!$D$2:$D$186,MATCH("男赤"&$A4,計算用!$L$2:$L$186,0)),"") | C4: =IFERROR(INDEX(計算用!$M$2:$M$186,MATCH("男赤"&$A4,計算用!$L$2:$L$186,0)),"") | D4: =IFERROR(INDEX(計算用!$G$2:$G$186,MATCH("男赤"&$A4,計算用!$L$2:$L$186,0)),"") | F4: =IFERROR(INDEX(計算用!$D$2:$D$186,MATCH("男白"&$A4,計算用!$L$2:$L$186,0)),"") | G4: =IFERROR(INDEX(計算用!$M$2:$M$186,MATCH("男白"&$A4,計算用!$L$2:$L$186,0)),"") | H4: =IFERROR(INDEX(計算用!$G$2:$G$186,MATCH("男白"&$A4,計算用!$L$2:$L$186,0)),"") | J4: =IF(ROW()-3<=MAX(計算用!$Q$4,計算用!$Q$5),ROW()-3,"") | K4: =IFERROR(INDEX(計算用!$D$2:$D$186,MATCH("女赤"&$J4,計算用!$L$2:$L$186,0)),"") | L4: =IFERROR(INDEX(計算用!$M$2:$M$186,MATCH("女赤"&$J4,計算用!$L$2:$L$186,0)),"") | M4: =IFERROR(INDEX(計算用!$G$2:$G$186,MATCH("女赤"&$J4,計算用!$L$2:$L$186,0)),"") | O4: =IFERROR(INDEX(計算用!$D$2:$D$186,MATCH("女白"&$J4,計算用!$L$2:$L$186,0)),"") | P4: =IFERROR(INDEX(計算用!$M$2:$M$186,MATCH("女白"&$J4,計算用!$L$2:$L$186,0)),"") | Q4: =IFERROR(INDEX(計算用!$G$2:$G$186,MATCH("女白"&$J4,計算用!$L$2:$L$186,0)),"")
A5: =IF(ROW()-3<=MAX(計算用!$Q$2,計算用!$Q$3),ROW()-3,"") | B5: =IFERROR(INDEX(計算用!$D$2:$D$186,MATCH("男赤"&$A5,計算用!$L$2:$L$186,0)),"") | C5: =IFERROR(INDEX(計算用!$M$2:$M$186,MATCH("男赤"&$A5,計算用!$L$2:$L$186,0)),"") | D5: =IFERROR(INDEX(計算用!$G$2:$G$186,MATCH("男赤"&$A5,計算用!$L$2:$L$186,0)),"") | F5: =IFERROR(INDEX(計算用!$D$2:$D$186,MATCH("男白"&$A5,計算用!$L$2:$L$186,0)),"") | G5: =IFERROR(INDEX(計算用!$M$2:$M$186,MATCH("男白"&$A5,計算用!$L$2:$L$186,0)),"") | H5: =IFERROR(INDEX(計算用!$G$2:$G$186,MATCH("男白"&$A5,計算用!$L$2:$L$186,0)),"") | J5: =IF(ROW()-3<=MAX(計算用!$Q$4,計算用!$Q$5),ROW()-3,"") | K5: =IFERROR(INDEX(計算用!$D$2:$D$186,MATCH("女赤"&$J5,計算用!$L$2:$L$186,0)),"") | L5: =IFERROR(INDEX(計算用!$M$2:$M$186,MATCH("女赤"&$J5,計算用!$L$2:$L$186,0)),"") | M5: =IFERROR(INDEX(計算用!$G$2:$G$186,MATCH("女赤"&$J5,計算用!$L$2:$L$186,0)),"") | O5: =IFERROR(INDEX(計算用!$D$2:$D$186,MATCH("女白"&$J5,計算用!$L$2:$L$186,0)),"") | P5: =IFERROR(INDEX(計算用!$M$2:$M$186,MATCH("女白"&$J5,計算用!$L$2:$L$186,0)),"") | Q5: =IFERROR(INDEX(計算用!$G$2:$G$186,MATCH("女白"&$J5,計算用!$L$2:$L$186,0)),"")
A6: =IF(ROW()-3<=MAX(計算用!$Q$2,計算用!$Q$3),ROW()-3,"") | B6: =IFERROR(INDEX(計算用!$D$2:$D$186,MATCH("男赤"&$A6,計算用!$L$2:$L$186,0)),"") | C6: =IFERROR(INDEX(計算用!$M$2:$M$186,MATCH("男赤"&$A6,計算用!$L$2:$L$186,0)),"") | D6: =IFERROR(INDEX(計算用!$G$2:$G$186,MATCH("男赤"&$A6,計算用!$L$2:$L$186,0)),"") | F6: =IFERROR(INDEX(計算用!$D$2:$D$186,MATCH("男白"&$A6,計算用!$L$2:$L$186,0)),"") | G6: =IFERROR(INDEX(計算用!$M$2:$M$186,MATCH("男白"&$A6,計算用!$L$2:$L$186,0)),"") | H6: =IFERROR(INDEX(計算用!$G$2:$G$186,MATCH("男白"&$A6,計算用!$L$2:$L$186,0)),"") | J6: =IF(ROW()-3<=MAX(計算用!$Q$4,計算用!$Q$5),ROW()-3,"") | K6: =IFERROR(INDEX(計算用!$D$2:$D$186,MATCH("女赤"&$J6,計算用!$L$2:$L$186,0)),"") | L6: =IFERROR(INDEX(計算用!$M$2:$M$186,MATCH("女赤"&$J6,計算用!$L$2:$L$186,0)),"") | M6: =IFERROR(INDEX(計算用!$G$2:$G$186,MATCH("女赤"&$J6,計算用!$L$2:$L$186,0)),"") | O6: =IFERROR(INDEX(計算用!$D$2:$D$186,MATCH("女白"&$J6,計算用!$L$2:$L$186,0)),"") | P6: =IFERROR(INDEX(計算用!$M$2:$M$186,MATCH("女白"&$J6,計算用!$L$2:$L$186,0)),"") | Q6: =IFERROR(INDEX(計算用!$G$2:$G$186,MATCH("女白"&$J6,計算用!$L$2:$L$186,0)),"")
A7: =IF(ROW()-3<=MAX(計算用!$Q$2,計算用!$Q$3),ROW()-3,"") | B7: =IFERROR(INDEX(計算用!$D$2:$D$186,MATCH("男赤"&$A7,計算用!$L$2:$L$186,0)),"") | C7: =IFERROR(INDEX(計算用!$M$2:$M$186,MATCH("男赤"&$A7,計算用!$L$2:$L$186,0)),"") | D7: =IFERROR(INDEX(計算用!$G$2:$G$186,MATCH("男赤"&$A7,計算用!$L$2:$L$186,0)),"") | F7: =IFERROR(INDEX(計算用!$D$2:$D$186,MATCH("男白"&$A7,計算用!$L$2:$L$186,0)),"") | G7: =IFERROR(INDEX(計算用!$M$2:$M$186,MATCH("男白"&$A7,計算用!$L$2:$L$186,0)),"") | H7: =IFERROR(INDEX(計算用!$G$2:$G$186,MATCH("男白"&$A7,計算用!$L$2:$L$186,0)),"") | J7: =IF(ROW()-3<=MAX(計算用!$Q$4,計算用!$Q$5),ROW()-3,"") | K7: =IFERROR(INDEX(計算用!$D$2:$D$186,MATCH("女赤"&$J7,計算用!$L$2:$L$186,0)),"") | L7: =IFERROR(INDEX(計算用!$M$2:$M$186,MATCH("女赤"&$J7,計算用!$L$2:$L$186,0)),"") | M7: =IFERROR(INDEX(計算用!$G$2:$G$186,MATCH("女赤"&$J7,計算用!$L$2:$L$186,0)),"") | O7: =IFERROR(INDEX(計算用!$D$2:$D$186,MATCH("女白"&$J7,計算用!$L$2:$L$186,0)),"") | P7: =IFERROR(INDEX(計算用!$M$2:$M$186,MATCH("女白"&$J7,計算用!$L$2:$L$186,0)),"") | Q7: =IFERROR(INDEX(計算用!$G$2:$G$186,MATCH("女白"&$J7,計算用!$L$2:$L$186,0)),"")
A8: =IF(ROW()-3<=MAX(計算用!$Q$2,計算用!$Q$3),ROW()-3,"") | B8: =IFERROR(INDEX(計算用!$D$2:$D$186,MATCH("男赤"&$A8,計算用!$L$2:$L$186,0)),"") | C8: =IFERROR(INDEX(計算用!$M$2:$M$186,MATCH("男赤"&$A8,計算用!$L$2:$L$186,0)),"") | D8: =IFERROR(INDEX(計算用!$G$2:$G$186,MATCH("男赤"&$A8,計算用!$L$2:$L$186,0)),"") | F8: =IFERROR(INDEX(計算用!$D$2:$D$186,MATCH("男白"&$A8,計算用!$L$2:$L$186,0)),"") | G8: =IFERROR(INDEX(計算用!$M$2:$M$186,MATCH("男白"&$A8,計算用!$L$2:$L$186,0)),"") | H8: =IFERROR(INDEX(計算用!$G$2:$G$186,MATCH("男白"&$A8,計算用!$L$2:$L$186,0)),"") | J8: =IF(ROW()-3<=MAX(計算用!$Q$4,計算用!$Q$5),ROW()-3,"") | K8: =IFERROR(INDEX(計算用!$D$2:$D$186,MATCH("女赤"&$J8,計算用!$L$2:$L$186,0)),"") | L8: =IFERROR(INDEX(計算用!$M$2:$M$186,MATCH("女赤"&$J8,計算用!$L$2:$L$186,0)),"") | M8: =IFERROR(INDEX(計算用!$G$2:$G$186,MATCH("女赤"&$J8,計算用!$L$2:$L$186,0)),"") | O8: =IFERROR(INDEX(計算用!$D$2:$D$186,MATCH("女白"&$J8,計算用!$L$2:$L$186,0)),"") | P8: =IFERROR(INDEX(計算用!$M$2:$M$186,MATCH("女白"&$J8,計算用!$L$2:$L$186,0)),"") | Q8: =IFERROR(INDEX(計算用!$G$2:$G$186,MATCH("女白"&$J8,計算用!$L$2:$L$186,0)),"")
A9: =IF(ROW()-3<=MAX(計算用!$Q$2,計算用!$Q$3),ROW()-3,"") | B9: =IFERROR(INDEX(計算用!$D$2:$D$186,MATCH("男赤"&$A9,計算用!$L$2:$L$186,0)),"") | C9: =IFERROR(INDEX(計算用!$M$2:$M$186,MATCH("男赤"&$A9,計算用!$L$2:$L$186,0)),"") | D9: =IFERROR(INDEX(計算用!$G$2:$G$186,MATCH("男赤"&$A9,計算用!$L$2:$L$186,0)),"") | F9: =IFERROR(INDEX(計算用!$D$2:$D$186,MATCH("男白"&$A9,計算用!$L$2:$L$186,0)),"") | G9: =IFERROR(INDEX(計算用!$M$2:$M$186,MATCH("男白"&$A9,計算用!$L$2:$L$186,0)),"") | H9: =IFERROR(INDEX(計算用!$G$2:$G$186,MATCH("男白"&$A9,計算用!$L$2:$L$186,0)),"") | J9: =IF(ROW()-3<=MAX(計算用!$Q$4,計算用!$Q$5),ROW()-3,"") | K9: =IFERROR(INDEX(計算用!$D$2:$D$186,MATCH("女赤"&$J9,計算用!$L$2:$L$186,0)),"") | L9: =IFERROR(INDEX(計算用!$M$2:$M$186,MATCH("女赤"&$J9,計算用!$L$2:$L$186,0)),"") | M9: =IFERROR(INDEX(計算用!$G$2:$G$186,MATCH("女赤"&$J9,計算用!$L$2:$L$186,0)),"") | O9: =IFERROR(INDEX(計算用!$D$2:$D$186,MATCH("女白"&$J9,計算用!$L$2:$L$186,0)),"") | P9: =IFERROR(INDEX(計算用!$M$2:$M$186,MATCH("女白"&$J9,計算用!$L$2:$L$186,0)),"") | Q9: =IFERROR(INDEX(計算用!$G$2:$G$186,MATCH("女白"&$J9,計算用!$L$2:$L$186,0)),"")
A10: =IF(ROW()-3<=MAX(計算用!$Q$2,計算用!$Q$3),ROW()-3,"") | B10: =IFERROR(INDEX(計算用!$D$2:$D$186,MATCH("男赤"&$A10,計算用!$L$2:$L$186,0)),"") | C10: =IFERROR(INDEX(計算用!$M$2:$M$186,MATCH("男赤"&$A10,計算用!$L$2:$L$186,0)),"") | D10: =IFERROR(INDEX(計算用!$G$2:$G$186,MATCH("男赤"&$A10,計算用!$L$2:$L$186,0)),"") | F10: =IFERROR(INDEX(計算用!$D$2:$D$186,MATCH("男白"&$A10,計算用!$L$2:$L$186,0)),"") | G10: =IFERROR(INDEX(計算用!$M$2:$M$186,MATCH("男白"&$A10,計算用!$L$2:$L$186,0)),"") | H10: =IFERROR(INDEX(計算用!$G$2:$G$186,MATCH("男白"&$A10,計算用!$L$2:$L$186,0)),"") | J10: =IF(ROW()-3<=MAX(計算用!$Q$4,計算用!$Q$5),ROW()-3,"") | K10: =IFERROR(INDEX(計算用!$D$2:$D$186,MATCH("女赤"&$J10,計算用!$L$2:$L$186,0)),"") | L10: =IFERROR(INDEX(計算用!$M$2:$M$186,MATCH("女赤"&$J10,計算用!$L$2:$L$186,0)),"") | M10: =IFERROR(INDEX(計算用!$G$2:$G$186,MATCH("女赤"&$J10,計算用!$L$2:$L$186,0)),"") | O10: =IFERROR(INDEX(計算用!$D$2:$D$186,MATCH("女白"&$J10,計算用!$L$2:$L$186,0)),"") | P10: =IFERROR(INDEX(計算用!$M$2:$M$186,MATCH("女白"&$J10,計算用!$L$2:$L$186,0)),"") | Q10: =IFERROR(INDEX(計算用!$G$2:$G$186,MATCH("女白"&$J10,計算用!$L$2:$L$186,0)),"")
A11: =IF(ROW()-3<=MAX(計算用!$Q$2,計算用!$Q$3),ROW()-3,"") | B11: =IFERROR(INDEX(計算用!$D$2:$D$186,MATCH("男赤"&$A11,計算用!$L$2:$L$186,0)),"") | C11: =IFERROR(INDEX(計算用!$M$2:$M$186,MATCH("男赤"&$A11,計算用!$L$2:$L$186,0)),"") | D11: =IFERROR(INDEX(計算用!$G$2:$G$186,MATCH("男赤"&$A11,計算用!$L$2:$L$186,0)),"") | F11: =IFERROR(INDEX(計算用!$D$2:$D$186,MATCH("男白"&$A11,計算用!$L$2:$L$186,0)),"") | G11: =IFERROR(INDEX(計算用!$M$2:$M$186,MATCH("男白"&$A11,計算用!$L$2:$L$186,0)),"") | H11: =IFERROR(INDEX(計算用!$G$2:$G$186,MATCH("男白"&$A11,計算用!$L$2:$L$186,0)),"") | J11: =IF(ROW()-3<=MAX(計算用!$Q$4,計算用!$Q$5),ROW()-3,"") | K11: =IFERROR(INDEX(計算用!$D$2:$D$186,MATCH("女赤"&$J11,計算用!$L$2:$L$186,0)),"") | L11: =IFERROR(INDEX(計算用!$M$2:$M$186,MATCH("女赤"&$J11,計算用!$L$2:$L$186,0)),"") | M11: =IFERROR(INDEX(計算用!$G$2:$G$186,MATCH("女赤"&$J11,計算用!$L$2:$L$186,0)),"") | O11: =IFERROR(INDEX(計算用!$D$2:$D$186,MATCH("女白"&$J11,計算用!$L$2:$L$186,0)),"") | P11: =IFERROR(INDEX(計算用!$M$2:$M$186,MATCH("女白"&$J11,計算用!$L$2:$L$186,0)),"") | Q11: =IFERROR(INDEX(計算用!$G$2:$G$186,MATCH("女白"&$J11,計算用!$L$2:$L$186,0)),"")
A12: =IF(ROW()-3<=MAX(計算用!$Q$2,計算用!$Q$3),ROW()-3,"") | B12: =IFERROR(INDEX(計算用!$D$2:$D$186,MATCH("男赤"&$A12,計算用!$L$2:$L$186,0)),"") | C12: =IFERROR(INDEX(計算用!$M$2:$M$186,MATCH("男赤"&$A12,計算用!$L$2:$L$186,0)),"") | D12: =IFERROR(INDEX(計算用!$G$2:$G$186,MATCH("男赤"&$A12,計算用!$L$2:$L$186,0)),"") | F12: =IFERROR(INDEX(計算用!$D$2:$D$186,MATCH("男白"&$A12,計算用!$L$2:$L$186,0)),"") | G12: =IFERROR(INDEX(計算用!$M$2:$M$186,MATCH("男白"&$A12,計算用!$L$2:$L$186,0)),"") | H12: =IFERROR(INDEX(計算用!$G$2:$G$186,MATCH("男白"&$A12,計算用!$L$2:$L$186,0)),"") | J12: =IF(ROW()-3<=MAX(計算用!$Q$4,計算用!$Q$5),ROW()-3,"") | K12: =IFERROR(INDEX(計算用!$D$2:$D$186,MATCH("女赤"&$J12,計算用!$L$2:$L$186,0)),"") | L12: =IFERROR(INDEX(計算用!$M$2:$M$186,MATCH("女赤"&$J12,計算用!$L$2:$L$186,0)),"") | M12: =IFERROR(INDEX(計算用!$G$2:$G$186,MATCH("女赤"&$J12,計算用!$L$2:$L$186,0)),"") | O12: =IFERROR(INDEX(計算用!$D$2:$D$186,MATCH("女白"&$J12,計算用!$L$2:$L$186,0)),"") | P12: =IFERROR(INDEX(計算用!$M$2:$M$186,MATCH("女白"&$J12,計算用!$L$2:$L$186,0)),"") | Q12: =IFERROR(INDEX(計算用!$G$2:$G$186,MATCH("女白"&$J12,計算用!$L$2:$L$186,0)),"")
A13: =IF(ROW()-3<=MAX(計算用!$Q$2,計算用!$Q$3),ROW()-3,"") | B13: =IFERROR(INDEX(計算用!$D$2:$D$186,MATCH("男赤"&$A13,計算用!$L$2:$L$186,0)),"") | C13: =IFERROR(INDEX(計算用!$M$2:$M$186,MATCH("男赤"&$A13,計算用!$L$2:$L$186,0)),"") | D13: =IFERROR(INDEX(計算用!$G$2:$G$186,MATCH("男赤"&$A13,計算用!$L$2:$L$186,0)),"") | F13: =IFERROR(INDEX(計算用!$D$2:$D$186,MATCH("男白"&$A13,計算用!$L$2:$L$186,0)),"") | G13: =IFERROR(INDEX(計算用!$M$2:$M$186,MATCH("男白"&$A13,計算用!$L$2:$L$186,0)),"") | H13: =IFERROR(INDEX(計算用!$G$2:$G$186,MATCH("男白"&$A13,計算用!$L$2:$L$186,0)),"") | J13: =IF(ROW()-3<=MAX(計算用!$Q$4,計算用!$Q$5),ROW()-3,"") | K13: =IFERROR(INDEX(計算用!$D$2:$D$186,MATCH("女赤"&$J13,計算用!$L$2:$L$186,0)),"") | L13: =IFERROR(INDEX(計算用!$M$2:$M$186,MATCH("女赤"&$J13,計算用!$L$2:$L$186,0)),"") | M13: =IFERROR(INDEX(計算用!$G$2:$G$186,MATCH("女赤"&$J13,計算用!$L$2:$L$186,0)),"") | O13: =IFERROR(INDEX(計算用!$D$2:$D$186,MATCH("女白"&$J13,計算用!$L$2:$L$186,0)),"") | P13: =IFERROR(INDEX(計算用!$M$2:$M$186,MATCH("女白"&$J13,計算用!$L$2:$L$186,0)),"") | Q13: =IFERROR(INDEX(計算用!$G$2:$G$186,MATCH("女白"&$J13,計算用!$L$2:$L$186,0)),"")
A14: =IF(ROW()-3<=MAX(計算用!$Q$2,計算用!$Q$3),ROW()-3,"") | B14: =IFERROR(INDEX(計算用!$D$2:$D$186,MATCH("男赤"&$A14,計算用!$L$2:$L$186,0)),"") | C14: =IFERROR(INDEX(計算用!$M$2:$M$186,MATCH("男赤"&$A14,計算用!$L$2:$L$186,0)),"") | D14: =IFERROR(INDEX(計算用!$G$2:$G$186,MATCH("男赤"&$A14,計算用!$L$2:$L$186,0)),"") | F14: =IFERROR(INDEX(計算用!$D$2:$D$186,MATCH("男白"&$A14,計算用!$L$2:$L$186,0)),"") | G14: =IFERROR(INDEX(計算用!$M$2:$M$186,MATCH("男白"&$A14,計算用!$L$2:$L$186,0)),"") | H14: =IFERROR(INDEX(計算用!$G$2:$G$186,MATCH("男白"&$A14,計算用!$L$2:$L$186,0)),"") | J14: =IF(ROW()-3<=MAX(計算用!$Q$4,計算用!$Q$5),ROW()-3,"") | K14: =IFERROR(INDEX(計算用!$D$2:$D$186,MATCH("女赤"&$J14,計算用!$L$2:$L$186,0)),"") | L14: =IFERROR(INDEX(計算用!$M$2:$M$186,MATCH("女赤"&$J14,計算用!$L$2:$L$186,0)),"") | M14: =IFERROR(INDEX(計算用!$G$2:$G$186,MATCH("女赤"&$J14,計算用!$L$2:$L$186,0)),"") | O14: =IFERROR(INDEX(計算用!$D$2:$D$186,MATCH("女白"&$J14,計算用!$L$2:$L$186,0)),"") | P14: =IFERROR(INDEX(計算用!$M$2:$M$186,MATCH("女白"&$J14,計算用!$L$2:$L$186,0)),"") | Q14: =IFERROR(INDEX(計算用!$G$2:$G$186,MATCH("女白"&$J14,計算用!$L$2:$L$186,0)),"")
A15: =IF(ROW()-3<=MAX(計算用!$Q$2,計算用!$Q$3),ROW()-3,"") | B15: =IFERROR(INDEX(計算用!$D$2:$D$186,MATCH("男赤"&$A15,計算用!$L$2:$L$186,0)),"") | C15: =IFERROR(INDEX(計算用!$M$2:$M$186,MATCH("男赤"&$A15,計算用!$L$2:$L$186,0)),"") | D15: =IFERROR(INDEX(計算用!$G$2:$G$186,MATCH("男赤"&$A15,計算用!$L$2:$L$186,0)),"") | F15: =IFERROR(INDEX(計算用!$D$2:$D$186,MATCH("男白"&$A15,計算用!$L$2:$L$186,0)),"") | G15: =IFERROR(INDEX(計算用!$M$2:$M$186,MATCH("男白"&$A15,計算用!$L$2:$L$186,0)),"") | H15: =IFERROR(INDEX(計算用!$G$2:$G$186,MATCH("男白"&$A15,計算用!$L$2:$L$186,0)),"") | J15: =IF(ROW()-3<=MAX(計算用!$Q$4,計算用!$Q$5),ROW()-3,"") | K15: =IFERROR(INDEX(計算用!$D$2:$D$186,MATCH("女赤"&$J15,計算用!$L$2:$L$186,0)),"") | L15: =IFERROR(INDEX(計算用!$M$2:$M$186,MATCH("女赤"&$J15,計算用!$L$2:$L$186,0)),"") | M15: =IFERROR(INDEX(計算用!$G$2:$G$186,MATCH("女赤"&$J15,計算用!$L$2:$L$186,0)),"") | O15: =IFERROR(INDEX(計算用!$D$2:$D$186,MATCH("女白"&$J15,計算用!$L$2:$L$186,0)),"") | P15: =IFERROR(INDEX(計算用!$M$2:$M$186,MATCH("女白"&$J15,計算用!$L$2:$L$186,0)),"") | Q15: =IFERROR(INDEX(計算用!$G$2:$G$186,MATCH("女白"&$J15,計算用!$L$2:$L$186,0)),"")
... A188: =IF(ROW()-3<=MAX(計算用!$Q$2,計算用!$Q$3),ROW()-3,"") | B188: =IFERROR(INDEX(計算用!$D$2:$D$186,MATCH("男赤"&$A188,計算用!$L$2:$L$186,0)),"") | C188: =IFERROR(INDEX(計算用!$M$2:$M$186,MATCH("男赤"&$A188,計算用!$L$2:$L$186,0)),"") | D188: =IFERROR(INDEX(計算用!$G$2:$G$186,MATCH("男赤"&$A188,計算用!$L$2:$L$186,0)),"") | F188: =IFERROR(INDEX(計算用!$D$2:$D$186,MATCH("男白"&$A188,計算用!$L$2:$L$186,0)),"") | G188: =IFERROR(INDEX(計算用!$M$2:$M$186,MATCH("男白"&$A188,計算用!$L$2:$L$186,0)),"") | H188: =IFERROR(INDEX(計算用!$G$2:$G$186,MATCH("男白"&$A188,計算用!$L$2:$L$186,0)),"") | J188: =IF(ROW()-3<=MAX(計算用!$Q$4,計算用!$Q$5),ROW()-3,"") | K188: =IFERROR(INDEX(計算用!$D$2:$D$186,MATCH("女赤"&$J188,計算用!$L$2:$L$186,0)),"") | L188: =IFERROR(INDEX(計算用!$M$2:$M$186,MATCH("女赤"&$J188,計算用!$L$2:$L$186,0)),"") | M188: =IFERROR(INDEX(計算用!$G$2:$G$186,MATCH("女赤"&$J188,計算用!$L$2:$L$186,0)),"") | O188: =IFERROR(INDEX(計算用!$D$2:$D$186,MATCH("女白"&$J188,計算用!$L$2:$L$186,0)),"") | P188: =IFERROR(INDEX(計算用!$M$2:$M$186,MATCH("女白"&$J188,計算用!$L$2:$L$186,0)),"") | Q188: =IFERROR(INDEX(計算用!$G$2:$G$186,MATCH("女白"&$J188,計算用!$L$2:$L$186,0)),"")

Sheet 組分け
A1: 男子 | D1: =IF(SUMPRODUCT((計算用!$T$2:$T$51>0)*(((計算用!$T$2:$T$51<>計算用!$Q$32)+(ABS(計算用!$W$2:$W$51-計算用!$X$2:$X$51)>1))>0))>0,"※黄色の組は、人数の都合で調整した組です","") | O1: ="1組 "&計算用!$Q$32&"人" | T1: 女子 | W1: =IF(SUMPRODUCT((計算用!$AC$2:$AC$51>0)*(((計算用!$AC$2:$AC$51<>計算用!$Q$33)+(ABS(計算用!$AF$2:$AF$51-計算用!$AG$2:$AG$51)>1))>0))>0,"※黄色の組は、人数の都合で調整した組です","") | AH1: ="1組 "&計算用!$Q$33&"人"
A2: 組 | B2: 人数 | C2: 内訳 | D2: 1人目 | G2: 2人目 | J2: 3人目 | M2: 4人目 | P2: 5人目 | T2: 組 | U2: 人数 | V2: 内訳 | W2: 1人目 | Z2: 2人目 | AC2: 3人目 | AF2: 4人目 | AI2: 5人目
D3: 名前 | E3: クラス | F3: 色 | G3: 名前 | H3: クラス | I3: 色 | J3: 名前 | K3: クラス | L3: 色 | M3: 名前 | N3: クラス | O3: 色 | P3: 名前 | Q3: クラス | R3: 色 | W3: 名前 | X3: クラス | Y3: 色 | Z3: 名前 | AA3: クラス | AB3: 色 | AC3: 名前 | AD3: クラス | AE3: 色 | AF3: 名前 | AG3: クラス | AH3: 色 | AI3: 名前 | AJ3: クラス | AK3: 色
A4: =IF(ROW()-3<=計算用!$Q$9,ROW()-3,"") | B4: =IF($A4="","",INDEX(計算用!$T$2:$T$51,$A4)) | C4: =IF($A4="","","赤"&INDEX(計算用!$W$2:$W$51,$A4)&"白"&INDEX(計算用!$X$2:$X$51,$A4)) | D4: =IF($A4="","",IFERROR(INDEX(計算用!$D$2:$D$186,MATCH("男"&$A4&"-1",計算用!$AN$2:$AN$186,0)),"")) | E4: =IF($A4="","",IFERROR(INDEX(計算用!$M$2:$M$186,MATCH("男"&$A4&"-1",計算用!$AN$2:$AN$186,0)),"")) | F4: =IF($A4="","",IFERROR(INDEX(計算用!$I$2:$I$186,MATCH("男"&$A4&"-1",計算用!$AN$2:$AN$186,0)),"")) | G4: =IF($A4="","",IFERROR(INDEX(計算用!$D$2:$D$186,MATCH("男"&$A4&"-2",計算用!$AN$2:$AN$186,0)),"")) | H4: =IF($A4="","",IFERROR(INDEX(計算用!$M$2:$M$186,MATCH("男"&$A4&"-2",計算用!$AN$2:$AN$186,0)),"")) | I4: =IF($A4="","",IFERROR(INDEX(計算用!$I$2:$I$186,MATCH("男"&$A4&"-2",計算用!$AN$2:$AN$186,0)),"")) | J4: =IF($A4="","",IFERROR(INDEX(計算用!$D$2:$D$186,MATCH("男"&$A4&"-3",計算用!$AN$2:$AN$186,0)),"")) | K4: =IF($A4="","",IFERROR(INDEX(計算用!$M$2:$M$186,MATCH("男"&$A4&"-3",計算用!$AN$2:$AN$186,0)),"")) | L4: =IF($A4="","",IFERROR(INDEX(計算用!$I$2:$I$186,MATCH("男"&$A4&"-3",計算用!$AN$2:$AN$186,0)),"")) | M4: =IF($A4="","",IFERROR(INDEX(計算用!$D$2:$D$186,MATCH("男"&$A4&"-4",計算用!$AN$2:$AN$186,0)),"")) | N4: =IF($A4="","",IFERROR(INDEX(計算用!$M$2:$M$186,MATCH("男"&$A4&"-4",計算用!$AN$2:$AN$186,0)),"")) | O4: =IF($A4="","",IFERROR(INDEX(計算用!$I$2:$I$186,MATCH("男"&$A4&"-4",計算用!$AN$2:$AN$186,0)),"")) | P4: =IF($A4="","",IFERROR(INDEX(計算用!$D$2:$D$186,MATCH("男"&$A4&"-5",計算用!$AN$2:$AN$186,0)),"")) | Q4: =IF($A4="","",IFERROR(INDEX(計算用!$M$2:$M$186,MATCH("男"&$A4&"-5",計算用!$AN$2:$AN$186,0)),"")) | R4: =IF($A4="","",IFERROR(INDEX(計算用!$I$2:$I$186,MATCH("男"&$A4&"-5",計算用!$AN$2:$AN$186,0)),"")) | T4: =IF(ROW()-3<=計算用!$Q$11,ROW()-3,"") | U4: =IF($T4="","",INDEX(計算用!$AC$2:$AC$51,$T4)) | V4: =IF($T4="","","赤"&INDEX(計算用!$AF$2:$AF$51,$T4)&"白"&INDEX(計算用!$AG$2:$AG$51,$T4)) | W4: =IF($T4="","",IFERROR(INDEX(計算用!$D$2:$D$186,MATCH("女"&$T4&"-1",計算用!$AN$2:$AN$186,0)),"")) | X4: =IF($T4="","",IFERROR(INDEX(計算用!$M$2:$M$186,MATCH("女"&$T4&"-1",計算用!$AN$2:$AN$186,0)),"")) | Y4: =IF($T4="","",IFERROR(INDEX(計算用!$I$2:$I$186,MATCH("女"&$T4&"-1",計算用!$AN$2:$AN$186,0)),"")) | Z4: =IF($T4="","",IFERROR(INDEX(計算用!$D$2:$D$186,MATCH("女"&$T4&"-2",計算用!$AN$2:$AN$186,0)),"")) | AA4: =IF($T4="","",IFERROR(INDEX(計算用!$M$2:$M$186,MATCH("女"&$T4&"-2",計算用!$AN$2:$AN$186,0)),"")) | AB4: =IF($T4="","",IFERROR(INDEX(計算用!$I$2:$I$186,MATCH("女"&$T4&"-2",計算用!$AN$2:$AN$186,0)),"")) | AC4: =IF($T4="","",IFERROR(INDEX(計算用!$D$2:$D$186,MATCH("女"&$T4&"-3",計算用!$AN$2:$AN$186,0)),"")) | AD4: =IF($T4="","",IFERROR(INDEX(計算用!$M$2:$M$186,MATCH("女"&$T4&"-3",計算用!$AN$2:$AN$186,0)),"")) | AE4: =IF($T4="","",IFERROR(INDEX(計算用!$I$2:$I$186,MATCH("女"&$T4&"-3",計算用!$AN$2:$AN$186,0)),"")) | AF4: =IF($T4="","",IFERROR(INDEX(計算用!$D$2:$D$186,MATCH("女"&$T4&"-4",計算用!$AN$2:$AN$186,0)),"")) | AG4: =IF($T4="","",IFERROR(INDEX(計算用!$M$2:$M$186,MATCH("女"&$T4&"-4",計算用!$AN$2:$AN$186,0)),"")) | AH4: =IF($T4="","",IFERROR(INDEX(計算用!$I$2:$I$186,MATCH("女"&$T4&"-4",計算用!$AN$2:$AN$186,0)),"")) | AI4: =IF($T4="","",IFERROR(INDEX(計算用!$D$2:$D$186,MATCH("女"&$T4&"-5",計算用!$AN$2:$AN$186,0)),"")) | AJ4: =IF($T4="","",IFERROR(INDEX(計算用!$M$2:$M$186,MATCH("女"&$T4&"-5",計算用!$AN$2:$AN$186,0)),"")) | AK4: =IF($T4="","",IFERROR(INDEX(計算用!$I$2:$I$186,MATCH("女"&$T4&"-5",計算用!$AN$2:$AN$186,0)),""))
A5: =IF(ROW()-3<=計算用!$Q$9,ROW()-3,"") | B5: =IF($A5="","",INDEX(計算用!$T$2:$T$51,$A5)) | C5: =IF($A5="","","赤"&INDEX(計算用!$W$2:$W$51,$A5)&"白"&INDEX(計算用!$X$2:$X$51,$A5)) | D5: =IF($A5="","",IFERROR(INDEX(計算用!$D$2:$D$186,MATCH("男"&$A5&"-1",計算用!$AN$2:$AN$186,0)),"")) | E5: =IF($A5="","",IFERROR(INDEX(計算用!$M$2:$M$186,MATCH("男"&$A5&"-1",計算用!$AN$2:$AN$186,0)),"")) | F5: =IF($A5="","",IFERROR(INDEX(計算用!$I$2:$I$186,MATCH("男"&$A5&"-1",計算用!$AN$2:$AN$186,0)),"")) | G5: =IF($A5="","",IFERROR(INDEX(計算用!$D$2:$D$186,MATCH("男"&$A5&"-2",計算用!$AN$2:$AN$186,0)),"")) | H5: =IF($A5="","",IFERROR(INDEX(計算用!$M$2:$M$186,MATCH("男"&$A5&"-2",計算用!$AN$2:$AN$186,0)),"")) | I5: =IF($A5="","",IFERROR(INDEX(計算用!$I$2:$I$186,MATCH("男"&$A5&"-2",計算用!$AN$2:$AN$186,0)),"")) | J5: =IF($A5="","",IFERROR(INDEX(計算用!$D$2:$D$186,MATCH("男"&$A5&"-3",計算用!$AN$2:$AN$186,0)),"")) | K5: =IF($A5="","",IFERROR(INDEX(計算用!$M$2:$M$186,MATCH("男"&$A5&"-3",計算用!$AN$2:$AN$186,0)),"")) | L5: =IF($A5="","",IFERROR(INDEX(計算用!$I$2:$I$186,MATCH("男"&$A5&"-3",計算用!$AN$2:$AN$186,0)),"")) | M5: =IF($A5="","",IFERROR(INDEX(計算用!$D$2:$D$186,MATCH("男"&$A5&"-4",計算用!$AN$2:$AN$186,0)),"")) | N5: =IF($A5="","",IFERROR(INDEX(計算用!$M$2:$M$186,MATCH("男"&$A5&"-4",計算用!$AN$2:$AN$186,0)),"")) | O5: =IF($A5="","",IFERROR(INDEX(計算用!$I$2:$I$186,MATCH("男"&$A5&"-4",計算用!$AN$2:$AN$186,0)),"")) | P5: =IF($A5="","",IFERROR(INDEX(計算用!$D$2:$D$186,MATCH("男"&$A5&"-5",計算用!$AN$2:$AN$186,0)),"")) | Q5: =IF($A5="","",IFERROR(INDEX(計算用!$M$2:$M$186,MATCH("男"&$A5&"-5",計算用!$AN$2:$AN$186,0)),"")) | R5: =IF($A5="","",IFERROR(INDEX(計算用!$I$2:$I$186,MATCH("男"&$A5&"-5",計算用!$AN$2:$AN$186,0)),"")) | T5: =IF(ROW()-3<=計算用!$Q$11,ROW()-3,"") | U5: =IF($T5="","",INDEX(計算用!$AC$2:$AC$51,$T5)) | V5: =IF($T5="","","赤"&INDEX(計算用!$AF$2:$AF$51,$T5)&"白"&INDEX(計算用!$AG$2:$AG$51,$T5)) | W5: =IF($T5="","",IFERROR(INDEX(計算用!$D$2:$D$186,MATCH("女"&$T5&"-1",計算用!$AN$2:$AN$186,0)),"")) | X5: =IF($T5="","",IFERROR(INDEX(計算用!$M$2:$M$186,MATCH("女"&$T5&"-1",計算用!$AN$2:$AN$186,0)),"")) | Y5: =IF($T5="","",IFERROR(INDEX(計算用!$I$2:$I$186,MATCH("女"&$T5&"-1",計算用!$AN$2:$AN$186,0)),"")) | Z5: =IF($T5="","",IFERROR(INDEX(計算用!$D$2:$D$186,MATCH("女"&$T5&"-2",計算用!$AN$2:$AN$186,0)),"")) | AA5: =IF($T5="","",IFERROR(INDEX(計算用!$M$2:$M$186,MATCH("女"&$T5&"-2",計算用!$AN$2:$AN$186,0)),"")) | AB5: =IF($T5="","",IFERROR(INDEX(計算用!$I$2:$I$186,MATCH("女"&$T5&"-2",計算用!$AN$2:$AN$186,0)),"")) | AC5: =IF($T5="","",IFERROR(INDEX(計算用!$D$2:$D$186,MATCH("女"&$T5&"-3",計算用!$AN$2:$AN$186,0)),"")) | AD5: =IF($T5="","",IFERROR(INDEX(計算用!$M$2:$M$186,MATCH("女"&$T5&"-3",計算用!$AN$2:$AN$186,0)),"")) | AE5: =IF($T5="","",IFERROR(INDEX(計算用!$I$2:$I$186,MATCH("女"&$T5&"-3",計算用!$AN$2:$AN$186,0)),"")) | AF5: =IF($T5="","",IFERROR(INDEX(計算用!$D$2:$D$186,MATCH("女"&$T5&"-4",計算用!$AN$2:$AN$186,0)),"")) | AG5: =IF($T5="","",IFERROR(INDEX(計算用!$M$2:$M$186,MATCH("女"&$T5&"-4",計算用!$AN$2:$AN$186,0)),"")) | AH5: =IF($T5="","",IFERROR(INDEX(計算用!$I$2:$I$186,MATCH("女"&$T5&"-4",計算用!$AN$2:$AN$186,0)),"")) | AI5: =IF($T5="","",IFERROR(INDEX(計算用!$D$2:$D$186,MATCH("女"&$T5&"-5",計算用!$AN$2:$AN$186,0)),"")) | AJ5: =IF($T5="","",IFERROR(INDEX(計算用!$M$2:$M$186,MATCH("女"&$T5&"-5",計算用!$AN$2:$AN$186,0)),"")) | AK5: =IF($T5="","",IFERROR(INDEX(計算用!$I$2:$I$186,MATCH("女"&$T5&"-5",計算用!$AN$2:$AN$186,0)),""))
A6: =IF(ROW()-3<=計算用!$Q$9,ROW()-3,"") | B6: =IF($A6="","",INDEX(計算用!$T$2:$T$51,$A6)) | C6: =IF($A6="","","赤"&INDEX(計算用!$W$2:$W$51,$A6)&"白"&INDEX(計算用!$X$2:$X$51,$A6)) | D6: =IF($A6="","",IFERROR(INDEX(計算用!$D$2:$D$186,MATCH("男"&$A6&"-1",計算用!$AN$2:$AN$186,0)),"")) | E6: =IF($A6="","",IFERROR(INDEX(計算用!$M$2:$M$186,MATCH("男"&$A6&"-1",計算用!$AN$2:$AN$186,0)),"")) | F6: =IF($A6="","",IFERROR(INDEX(計算用!$I$2:$I$186,MATCH("男"&$A6&"-1",計算用!$AN$2:$AN$186,0)),"")) | G6: =IF($A6="","",IFERROR(INDEX(計算用!$D$2:$D$186,MATCH("男"&$A6&"-2",計算用!$AN$2:$AN$186,0)),"")) | H6: =IF($A6="","",IFERROR(INDEX(計算用!$M$2:$M$186,MATCH("男"&$A6&"-2",計算用!$AN$2:$AN$186,0)),"")) | I6: =IF($A6="","",IFERROR(INDEX(計算用!$I$2:$I$186,MATCH("男"&$A6&"-2",計算用!$AN$2:$AN$186,0)),"")) | J6: =IF($A6="","",IFERROR(INDEX(計算用!$D$2:$D$186,MATCH("男"&$A6&"-3",計算用!$AN$2:$AN$186,0)),"")) | K6: =IF($A6="","",IFERROR(INDEX(計算用!$M$2:$M$186,MATCH("男"&$A6&"-3",計算用!$AN$2:$AN$186,0)),"")) | L6: =IF($A6="","",IFERROR(INDEX(計算用!$I$2:$I$186,MATCH("男"&$A6&"-3",計算用!$AN$2:$AN$186,0)),"")) | M6: =IF($A6="","",IFERROR(INDEX(計算用!$D$2:$D$186,MATCH("男"&$A6&"-4",計算用!$AN$2:$AN$186,0)),"")) | N6: =IF($A6="","",IFERROR(INDEX(計算用!$M$2:$M$186,MATCH("男"&$A6&"-4",計算用!$AN$2:$AN$186,0)),"")) | O6: =IF($A6="","",IFERROR(INDEX(計算用!$I$2:$I$186,MATCH("男"&$A6&"-4",計算用!$AN$2:$AN$186,0)),"")) | P6: =IF($A6="","",IFERROR(INDEX(計算用!$D$2:$D$186,MATCH("男"&$A6&"-5",計算用!$AN$2:$AN$186,0)),"")) | Q6: =IF($A6="","",IFERROR(INDEX(計算用!$M$2:$M$186,MATCH("男"&$A6&"-5",計算用!$AN$2:$AN$186,0)),"")) | R6: =IF($A6="","",IFERROR(INDEX(計算用!$I$2:$I$186,MATCH("男"&$A6&"-5",計算用!$AN$2:$AN$186,0)),"")) | T6: =IF(ROW()-3<=計算用!$Q$11,ROW()-3,"") | U6: =IF($T6="","",INDEX(計算用!$AC$2:$AC$51,$T6)) | V6: =IF($T6="","","赤"&INDEX(計算用!$AF$2:$AF$51,$T6)&"白"&INDEX(計算用!$AG$2:$AG$51,$T6)) | W6: =IF($T6="","",IFERROR(INDEX(計算用!$D$2:$D$186,MATCH("女"&$T6&"-1",計算用!$AN$2:$AN$186,0)),"")) | X6: =IF($T6="","",IFERROR(INDEX(計算用!$M$2:$M$186,MATCH("女"&$T6&"-1",計算用!$AN$2:$AN$186,0)),"")) | Y6: =IF($T6="","",IFERROR(INDEX(計算用!$I$2:$I$186,MATCH("女"&$T6&"-1",計算用!$AN$2:$AN$186,0)),"")) | Z6: =IF($T6="","",IFERROR(INDEX(計算用!$D$2:$D$186,MATCH("女"&$T6&"-2",計算用!$AN$2:$AN$186,0)),"")) | AA6: =IF($T6="","",IFERROR(INDEX(計算用!$M$2:$M$186,MATCH("女"&$T6&"-2",計算用!$AN$2:$AN$186,0)),"")) | AB6: =IF($T6="","",IFERROR(INDEX(計算用!$I$2:$I$186,MATCH("女"&$T6&"-2",計算用!$AN$2:$AN$186,0)),"")) | AC6: =IF($T6="","",IFERROR(INDEX(計算用!$D$2:$D$186,MATCH("女"&$T6&"-3",計算用!$AN$2:$AN$186,0)),"")) | AD6: =IF($T6="","",IFERROR(INDEX(計算用!$M$2:$M$186,MATCH("女"&$T6&"-3",計算用!$AN$2:$AN$186,0)),"")) | AE6: =IF($T6="","",IFERROR(INDEX(計算用!$I$2:$I$186,MATCH("女"&$T6&"-3",計算用!$AN$2:$AN$186,0)),"")) | AF6: =IF($T6="","",IFERROR(INDEX(計算用!$D$2:$D$186,MATCH("女"&$T6&"-4",計算用!$AN$2:$AN$186,0)),"")) | AG6: =IF($T6="","",IFERROR(INDEX(計算用!$M$2:$M$186,MATCH("女"&$T6&"-4",計算用!$AN$2:$AN$186,0)),"")) | AH6: =IF($T6="","",IFERROR(INDEX(計算用!$I$2:$I$186,MATCH("女"&$T6&"-4",計算用!$AN$2:$AN$186,0)),"")) | AI6: =IF($T6="","",IFERROR(INDEX(計算用!$D$2:$D$186,MATCH("女"&$T6&"-5",計算用!$AN$2:$AN$186,0)),"")) | AJ6: =IF($T6="","",IFERROR(INDEX(計算用!$M$2:$M$186,MATCH("女"&$T6&"-5",計算用!$AN$2:$AN$186,0)),"")) | AK6: =IF($T6="","",IFERROR(INDEX(計算用!$I$2:$I$186,MATCH("女"&$T6&"-5",計算用!$AN$2:$AN$186,0)),""))
A7: =IF(ROW()-3<=計算用!$Q$9,ROW()-3,"") | B7: =IF($A7="","",INDEX(計算用!$T$2:$T$51,$A7)) | C7: =IF($A7="","","赤"&INDEX(計算用!$W$2:$W$51,$A7)&"白"&INDEX(計算用!$X$2:$X$51,$A7)) | D7: =IF($A7="","",IFERROR(INDEX(計算用!$D$2:$D$186,MATCH("男"&$A7&"-1",計算用!$AN$2:$AN$186,0)),"")) | E7: =IF($A7="","",IFERROR(INDEX(計算用!$M$2:$M$186,MATCH("男"&$A7&"-1",計算用!$AN$2:$AN$186,0)),"")) | F7: =IF($A7="","",IFERROR(INDEX(計算用!$I$2:$I$186,MATCH("男"&$A7&"-1",計算用!$AN$2:$AN$186,0)),"")) | G7: =IF($A7="","",IFERROR(INDEX(計算用!$D$2:$D$186,MATCH("男"&$A7&"-2",計算用!$AN$2:$AN$186,0)),"")) | H7: =IF($A7="","",IFERROR(INDEX(計算用!$M$2:$M$186,MATCH("男"&$A7&"-2",計算用!$AN$2:$AN$186,0)),"")) | I7: =IF($A7="","",IFERROR(INDEX(計算用!$I$2:$I$186,MATCH("男"&$A7&"-2",計算用!$AN$2:$AN$186,0)),"")) | J7: =IF($A7="","",IFERROR(INDEX(計算用!$D$2:$D$186,MATCH("男"&$A7&"-3",計算用!$AN$2:$AN$186,0)),"")) | K7: =IF($A7="","",IFERROR(INDEX(計算用!$M$2:$M$186,MATCH("男"&$A7&"-3",計算用!$AN$2:$AN$186,0)),"")) | L7: =IF($A7="","",IFERROR(INDEX(計算用!$I$2:$I$186,MATCH("男"&$A7&"-3",計算用!$AN$2:$AN$186,0)),"")) | M7: =IF($A7="","",IFERROR(INDEX(計算用!$D$2:$D$186,MATCH("男"&$A7&"-4",計算用!$AN$2:$AN$186,0)),"")) | N7: =IF($A7="","",IFERROR(INDEX(計算用!$M$2:$M$186,MATCH("男"&$A7&"-4",計算用!$AN$2:$AN$186,0)),"")) | O7: =IF($A7="","",IFERROR(INDEX(計算用!$I$2:$I$186,MATCH("男"&$A7&"-4",計算用!$AN$2:$AN$186,0)),"")) | P7: =IF($A7="","",IFERROR(INDEX(計算用!$D$2:$D$186,MATCH("男"&$A7&"-5",計算用!$AN$2:$AN$186,0)),"")) | Q7: =IF($A7="","",IFERROR(INDEX(計算用!$M$2:$M$186,MATCH("男"&$A7&"-5",計算用!$AN$2:$AN$186,0)),"")) | R7: =IF($A7="","",IFERROR(INDEX(計算用!$I$2:$I$186,MATCH("男"&$A7&"-5",計算用!$AN$2:$AN$186,0)),"")) | T7: =IF(ROW()-3<=計算用!$Q$11,ROW()-3,"") | U7: =IF($T7="","",INDEX(計算用!$AC$2:$AC$51,$T7)) | V7: =IF($T7="","","赤"&INDEX(計算用!$AF$2:$AF$51,$T7)&"白"&INDEX(計算用!$AG$2:$AG$51,$T7)) | W7: =IF($T7="","",IFERROR(INDEX(計算用!$D$2:$D$186,MATCH("女"&$T7&"-1",計算用!$AN$2:$AN$186,0)),"")) | X7: =IF($T7="","",IFERROR(INDEX(計算用!$M$2:$M$186,MATCH("女"&$T7&"-1",計算用!$AN$2:$AN$186,0)),"")) | Y7: =IF($T7="","",IFERROR(INDEX(計算用!$I$2:$I$186,MATCH("女"&$T7&"-1",計算用!$AN$2:$AN$186,0)),"")) | Z7: =IF($T7="","",IFERROR(INDEX(計算用!$D$2:$D$186,MATCH("女"&$T7&"-2",計算用!$AN$2:$AN$186,0)),"")) | AA7: =IF($T7="","",IFERROR(INDEX(計算用!$M$2:$M$186,MATCH("女"&$T7&"-2",計算用!$AN$2:$AN$186,0)),"")) | AB7: =IF($T7="","",IFERROR(INDEX(計算用!$I$2:$I$186,MATCH("女"&$T7&"-2",計算用!$AN$2:$AN$186,0)),"")) | AC7: =IF($T7="","",IFERROR(INDEX(計算用!$D$2:$D$186,MATCH("女"&$T7&"-3",計算用!$AN$2:$AN$186,0)),"")) | AD7: =IF($T7="","",IFERROR(INDEX(計算用!$M$2:$M$186,MATCH("女"&$T7&"-3",計算用!$AN$2:$AN$186,0)),"")) | AE7: =IF($T7="","",IFERROR(INDEX(計算用!$I$2:$I$186,MATCH("女"&$T7&"-3",計算用!$AN$2:$AN$186,0)),"")) | AF7: =IF($T7="","",IFERROR(INDEX(計算用!$D$2:$D$186,MATCH("女"&$T7&"-4",計算用!$AN$2:$AN$186,0)),"")) | AG7: =IF($T7="","",IFERROR(INDEX(計算用!$M$2:$M$186,MATCH("女"&$T7&"-4",計算用!$AN$2:$AN$186,0)),"")) | AH7: =IF($T7="","",IFERROR(INDEX(計算用!$I$2:$I$186,MATCH("女"&$T7&"-4",計算用!$AN$2:$AN$186,0)),"")) | AI7: =IF($T7="","",IFERROR(INDEX(計算用!$D$2:$D$186,MATCH("女"&$T7&"-5",計算用!$AN$2:$AN$186,0)),"")) | AJ7: =IF($T7="","",IFERROR(INDEX(計算用!$M$2:$M$186,MATCH("女"&$T7&"-5",計算用!$AN$2:$AN$186,0)),"")) | AK7: =IF($T7="","",IFERROR(INDEX(計算用!$I$2:$I$186,MATCH("女"&$T7&"-5",計算用!$AN$2:$AN$186,0)),""))
A8: =IF(ROW()-3<=計算用!$Q$9,ROW()-3,"") | B8: =IF($A8="","",INDEX(計算用!$T$2:$T$51,$A8)) | C8: =IF($A8="","","赤"&INDEX(計算用!$W$2:$W$51,$A8)&"白"&INDEX(計算用!$X$2:$X$51,$A8)) | D8: =IF($A8="","",IFERROR(INDEX(計算用!$D$2:$D$186,MATCH("男"&$A8&"-1",計算用!$AN$2:$AN$186,0)),"")) | E8: =IF($A8="","",IFERROR(INDEX(計算用!$M$2:$M$186,MATCH("男"&$A8&"-1",計算用!$AN$2:$AN$186,0)),"")) | F8: =IF($A8="","",IFERROR(INDEX(計算用!$I$2:$I$186,MATCH("男"&$A8&"-1",計算用!$AN$2:$AN$186,0)),"")) | G8: =IF($A8="","",IFERROR(INDEX(計算用!$D$2:$D$186,MATCH("男"&$A8&"-2",計算用!$AN$2:$AN$186,0)),"")) | H8: =IF($A8="","",IFERROR(INDEX(計算用!$M$2:$M$186,MATCH("男"&$A8&"-2",計算用!$AN$2:$AN$186,0)),"")) | I8: =IF($A8="","",IFERROR(INDEX(計算用!$I$2:$I$186,MATCH("男"&$A8&"-2",計算用!$AN$2:$AN$186,0)),"")) | J8: =IF($A8="","",IFERROR(INDEX(計算用!$D$2:$D$186,MATCH("男"&$A8&"-3",計算用!$AN$2:$AN$186,0)),"")) | K8: =IF($A8="","",IFERROR(INDEX(計算用!$M$2:$M$186,MATCH("男"&$A8&"-3",計算用!$AN$2:$AN$186,0)),"")) | L8: =IF($A8="","",IFERROR(INDEX(計算用!$I$2:$I$186,MATCH("男"&$A8&"-3",計算用!$AN$2:$AN$186,0)),"")) | M8: =IF($A8="","",IFERROR(INDEX(計算用!$D$2:$D$186,MATCH("男"&$A8&"-4",計算用!$AN$2:$AN$186,0)),"")) | N8: =IF($A8="","",IFERROR(INDEX(計算用!$M$2:$M$186,MATCH("男"&$A8&"-4",計算用!$AN$2:$AN$186,0)),"")) | O8: =IF($A8="","",IFERROR(INDEX(計算用!$I$2:$I$186,MATCH("男"&$A8&"-4",計算用!$AN$2:$AN$186,0)),"")) | P8: =IF($A8="","",IFERROR(INDEX(計算用!$D$2:$D$186,MATCH("男"&$A8&"-5",計算用!$AN$2:$AN$186,0)),"")) | Q8: =IF($A8="","",IFERROR(INDEX(計算用!$M$2:$M$186,MATCH("男"&$A8&"-5",計算用!$AN$2:$AN$186,0)),"")) | R8: =IF($A8="","",IFERROR(INDEX(計算用!$I$2:$I$186,MATCH("男"&$A8&"-5",計算用!$AN$2:$AN$186,0)),"")) | T8: =IF(ROW()-3<=計算用!$Q$11,ROW()-3,"") | U8: =IF($T8="","",INDEX(計算用!$AC$2:$AC$51,$T8)) | V8: =IF($T8="","","赤"&INDEX(計算用!$AF$2:$AF$51,$T8)&"白"&INDEX(計算用!$AG$2:$AG$51,$T8)) | W8: =IF($T8="","",IFERROR(INDEX(計算用!$D$2:$D$186,MATCH("女"&$T8&"-1",計算用!$AN$2:$AN$186,0)),"")) | X8: =IF($T8="","",IFERROR(INDEX(計算用!$M$2:$M$186,MATCH("女"&$T8&"-1",計算用!$AN$2:$AN$186,0)),"")) | Y8: =IF($T8="","",IFERROR(INDEX(計算用!$I$2:$I$186,MATCH("女"&$T8&"-1",計算用!$AN$2:$AN$186,0)),"")) | Z8: =IF($T8="","",IFERROR(INDEX(計算用!$D$2:$D$186,MATCH("女"&$T8&"-2",計算用!$AN$2:$AN$186,0)),"")) | AA8: =IF($T8="","",IFERROR(INDEX(計算用!$M$2:$M$186,MATCH("女"&$T8&"-2",計算用!$AN$2:$AN$186,0)),"")) | AB8: =IF($T8="","",IFERROR(INDEX(計算用!$I$2:$I$186,MATCH("女"&$T8&"-2",計算用!$AN$2:$AN$186,0)),"")) | AC8: =IF($T8="","",IFERROR(INDEX(計算用!$D$2:$D$186,MATCH("女"&$T8&"-3",計算用!$AN$2:$AN$186,0)),"")) | AD8: =IF($T8="","",IFERROR(INDEX(計算用!$M$2:$M$186,MATCH("女"&$T8&"-3",計算用!$AN$2:$AN$186,0)),"")) | AE8: =IF($T8="","",IFERROR(INDEX(計算用!$I$2:$I$186,MATCH("女"&$T8&"-3",計算用!$AN$2:$AN$186,0)),"")) | AF8: =IF($T8="","",IFERROR(INDEX(計算用!$D$2:$D$186,MATCH("女"&$T8&"-4",計算用!$AN$2:$AN$186,0)),"")) | AG8: =IF($T8="","",IFERROR(INDEX(計算用!$M$2:$M$186,MATCH("女"&$T8&"-4",計算用!$AN$2:$AN$186,0)),"")) | AH8: =IF($T8="","",IFERROR(INDEX(計算用!$I$2:$I$186,MATCH("女"&$T8&"-4",計算用!$AN$2:$AN$186,0)),"")) | AI8: =IF($T8="","",IFERROR(INDEX(計算用!$D$2:$D$186,MATCH("女"&$T8&"-5",計算用!$AN$2:$AN$186,0)),"")) | AJ8: =IF($T8="","",IFERROR(INDEX(計算用!$M$2:$M$186,MATCH("女"&$T8&"-5",計算用!$AN$2:$AN$186,0)),"")) | AK8: =IF($T8="","",IFERROR(INDEX(計算用!$I$2:$I$186,MATCH("女"&$T8&"-5",計算用!$AN$2:$AN$186,0)),""))
A9: =IF(ROW()-3<=計算用!$Q$9,ROW()-3,"") | B9: =IF($A9="","",INDEX(計算用!$T$2:$T$51,$A9)) | C9: =IF($A9="","","赤"&INDEX(計算用!$W$2:$W$51,$A9)&"白"&INDEX(計算用!$X$2:$X$51,$A9)) | D9: =IF($A9="","",IFERROR(INDEX(計算用!$D$2:$D$186,MATCH("男"&$A9&"-1",計算用!$AN$2:$AN$186,0)),"")) | E9: =IF($A9="","",IFERROR(INDEX(計算用!$M$2:$M$186,MATCH("男"&$A9&"-1",計算用!$AN$2:$AN$186,0)),"")) | F9: =IF($A9="","",IFERROR(INDEX(計算用!$I$2:$I$186,MATCH("男"&$A9&"-1",計算用!$AN$2:$AN$186,0)),"")) | G9: =IF($A9="","",IFERROR(INDEX(計算用!$D$2:$D$186,MATCH("男"&$A9&"-2",計算用!$AN$2:$AN$186,0)),"")) | H9: =IF($A9="","",IFERROR(INDEX(計算用!$M$2:$M$186,MATCH("男"&$A9&"-2",計算用!$AN$2:$AN$186,0)),"")) | I9: =IF($A9="","",IFERROR(INDEX(計算用!$I$2:$I$186,MATCH("男"&$A9&"-2",計算用!$AN$2:$AN$186,0)),"")) | J9: =IF($A9="","",IFERROR(INDEX(計算用!$D$2:$D$186,MATCH("男"&$A9&"-3",計算用!$AN$2:$AN$186,0)),"")) | K9: =IF($A9="","",IFERROR(INDEX(計算用!$M$2:$M$186,MATCH("男"&$A9&"-3",計算用!$AN$2:$AN$186,0)),"")) | L9: =IF($A9="","",IFERROR(INDEX(計算用!$I$2:$I$186,MATCH("男"&$A9&"-3",計算用!$AN$2:$AN$186,0)),"")) | M9: =IF($A9="","",IFERROR(INDEX(計算用!$D$2:$D$186,MATCH("男"&$A9&"-4",計算用!$AN$2:$AN$186,0)),"")) | N9: =IF($A9="","",IFERROR(INDEX(計算用!$M$2:$M$186,MATCH("男"&$A9&"-4",計算用!$AN$2:$AN$186,0)),"")) | O9: =IF($A9="","",IFERROR(INDEX(計算用!$I$2:$I$186,MATCH("男"&$A9&"-4",計算用!$AN$2:$AN$186,0)),"")) | P9: =IF($A9="","",IFERROR(INDEX(計算用!$D$2:$D$186,MATCH("男"&$A9&"-5",計算用!$AN$2:$AN$186,0)),"")) | Q9: =IF($A9="","",IFERROR(INDEX(計算用!$M$2:$M$186,MATCH("男"&$A9&"-5",計算用!$AN$2:$AN$186,0)),"")) | R9: =IF($A9="","",IFERROR(INDEX(計算用!$I$2:$I$186,MATCH("男"&$A9&"-5",計算用!$AN$2:$AN$186,0)),"")) | T9: =IF(ROW()-3<=計算用!$Q$11,ROW()-3,"") | U9: =IF($T9="","",INDEX(計算用!$AC$2:$AC$51,$T9)) | V9: =IF($T9="","","赤"&INDEX(計算用!$AF$2:$AF$51,$T9)&"白"&INDEX(計算用!$AG$2:$AG$51,$T9)) | W9: =IF($T9="","",IFERROR(INDEX(計算用!$D$2:$D$186,MATCH("女"&$T9&"-1",計算用!$AN$2:$AN$186,0)),"")) | X9: =IF($T9="","",IFERROR(INDEX(計算用!$M$2:$M$186,MATCH("女"&$T9&"-1",計算用!$AN$2:$AN$186,0)),"")) | Y9: =IF($T9="","",IFERROR(INDEX(計算用!$I$2:$I$186,MATCH("女"&$T9&"-1",計算用!$AN$2:$AN$186,0)),"")) | Z9: =IF($T9="","",IFERROR(INDEX(計算用!$D$2:$D$186,MATCH("女"&$T9&"-2",計算用!$AN$2:$AN$186,0)),"")) | AA9: =IF($T9="","",IFERROR(INDEX(計算用!$M$2:$M$186,MATCH("女"&$T9&"-2",計算用!$AN$2:$AN$186,0)),"")) | AB9: =IF($T9="","",IFERROR(INDEX(計算用!$I$2:$I$186,MATCH("女"&$T9&"-2",計算用!$AN$2:$AN$186,0)),"")) | AC9: =IF($T9="","",IFERROR(INDEX(計算用!$D$2:$D$186,MATCH("女"&$T9&"-3",計算用!$AN$2:$AN$186,0)),"")) | AD9: =IF($T9="","",IFERROR(INDEX(計算用!$M$2:$M$186,MATCH("女"&$T9&"-3",計算用!$AN$2:$AN$186,0)),"")) | AE9: =IF($T9="","",IFERROR(INDEX(計算用!$I$2:$I$186,MATCH("女"&$T9&"-3",計算用!$AN$2:$AN$186,0)),"")) | AF9: =IF($T9="","",IFERROR(INDEX(計算用!$D$2:$D$186,MATCH("女"&$T9&"-4",計算用!$AN$2:$AN$186,0)),"")) | AG9: =IF($T9="","",IFERROR(INDEX(計算用!$M$2:$M$186,MATCH("女"&$T9&"-4",計算用!$AN$2:$AN$186,0)),"")) | AH9: =IF($T9="","",IFERROR(INDEX(計算用!$I$2:$I$186,MATCH("女"&$T9&"-4",計算用!$AN$2:$AN$186,0)),"")) | AI9: =IF($T9="","",IFERROR(INDEX(計算用!$D$2:$D$186,MATCH("女"&$T9&"-5",計算用!$AN$2:$AN$186,0)),"")) | AJ9: =IF($T9="","",IFERROR(INDEX(計算用!$M$2:$M$186,MATCH("女"&$T9&"-5",計算用!$AN$2:$AN$186,0)),"")) | AK9: =IF($T9="","",IFERROR(INDEX(計算用!$I$2:$I$186,MATCH("女"&$T9&"-5",計算用!$AN$2:$AN$186,0)),""))
A10: =IF(ROW()-3<=計算用!$Q$9,ROW()-3,"") | B10: =IF($A10="","",INDEX(計算用!$T$2:$T$51,$A10)) | C10: =IF($A10="","","赤"&INDEX(計算用!$W$2:$W$51,$A10)&"白"&INDEX(計算用!$X$2:$X$51,$A10)) | D10: =IF($A10="","",IFERROR(INDEX(計算用!$D$2:$D$186,MATCH("男"&$A10&"-1",計算用!$AN$2:$AN$186,0)),"")) | E10: =IF($A10="","",IFERROR(INDEX(計算用!$M$2:$M$186,MATCH("男"&$A10&"-1",計算用!$AN$2:$AN$186,0)),"")) | F10: =IF($A10="","",IFERROR(INDEX(計算用!$I$2:$I$186,MATCH("男"&$A10&"-1",計算用!$AN$2:$AN$186,0)),"")) | G10: =IF($A10="","",IFERROR(INDEX(計算用!$D$2:$D$186,MATCH("男"&$A10&"-2",計算用!$AN$2:$AN$186,0)),"")) | H10: =IF($A10="","",IFERROR(INDEX(計算用!$M$2:$M$186,MATCH("男"&$A10&"-2",計算用!$AN$2:$AN$186,0)),"")) | I10: =IF($A10="","",IFERROR(INDEX(計算用!$I$2:$I$186,MATCH("男"&$A10&"-2",計算用!$AN$2:$AN$186,0)),"")) | J10: =IF($A10="","",IFERROR(INDEX(計算用!$D$2:$D$186,MATCH("男"&$A10&"-3",計算用!$AN$2:$AN$186,0)),"")) | K10: =IF($A10="","",IFERROR(INDEX(計算用!$M$2:$M$186,MATCH("男"&$A10&"-3",計算用!$AN$2:$AN$186,0)),"")) | L10: =IF($A10="","",IFERROR(INDEX(計算用!$I$2:$I$186,MATCH("男"&$A10&"-3",計算用!$AN$2:$AN$186,0)),"")) | M10: =IF($A10="","",IFERROR(INDEX(計算用!$D$2:$D$186,MATCH("男"&$A10&"-4",計算用!$AN$2:$AN$186,0)),"")) | N10: =IF($A10="","",IFERROR(INDEX(計算用!$M$2:$M$186,MATCH("男"&$A10&"-4",計算用!$AN$2:$AN$186,0)),"")) | O10: =IF($A10="","",IFERROR(INDEX(計算用!$I$2:$I$186,MATCH("男"&$A10&"-4",計算用!$AN$2:$AN$186,0)),"")) | P10: =IF($A10="","",IFERROR(INDEX(計算用!$D$2:$D$186,MATCH("男"&$A10&"-5",計算用!$AN$2:$AN$186,0)),"")) | Q10: =IF($A10="","",IFERROR(INDEX(計算用!$M$2:$M$186,MATCH("男"&$A10&"-5",計算用!$AN$2:$AN$186,0)),"")) | R10: =IF($A10="","",IFERROR(INDEX(計算用!$I$2:$I$186,MATCH("男"&$A10&"-5",計算用!$AN$2:$AN$186,0)),"")) | T10: =IF(ROW()-3<=計算用!$Q$11,ROW()-3,"") | U10: =IF($T10="","",INDEX(計算用!$AC$2:$AC$51,$T10)) | V10: =IF($T10="","","赤"&INDEX(計算用!$AF$2:$AF$51,$T10)&"白"&INDEX(計算用!$AG$2:$AG$51,$T10)) | W10: =IF($T10="","",IFERROR(INDEX(計算用!$D$2:$D$186,MATCH("女"&$T10&"-1",計算用!$AN$2:$AN$186,0)),"")) | X10: =IF($T10="","",IFERROR(INDEX(計算用!$M$2:$M$186,MATCH("女"&$T10&"-1",計算用!$AN$2:$AN$186,0)),"")) | Y10: =IF($T10="","",IFERROR(INDEX(計算用!$I$2:$I$186,MATCH("女"&$T10&"-1",計算用!$AN$2:$AN$186,0)),"")) | Z10: =IF($T10="","",IFERROR(INDEX(計算用!$D$2:$D$186,MATCH("女"&$T10&"-2",計算用!$AN$2:$AN$186,0)),"")) | AA10: =IF($T10="","",IFERROR(INDEX(計算用!$M$2:$M$186,MATCH("女"&$T10&"-2",計算用!$AN$2:$AN$186,0)),"")) | AB10: =IF($T10="","",IFERROR(INDEX(計算用!$I$2:$I$186,MATCH("女"&$T10&"-2",計算用!$AN$2:$AN$186,0)),"")) | AC10: =IF($T10="","",IFERROR(INDEX(計算用!$D$2:$D$186,MATCH("女"&$T10&"-3",計算用!$AN$2:$AN$186,0)),"")) | AD10: =IF($T10="","",IFERROR(INDEX(計算用!$M$2:$M$186,MATCH("女"&$T10&"-3",計算用!$AN$2:$AN$186,0)),"")) | AE10: =IF($T10="","",IFERROR(INDEX(計算用!$I$2:$I$186,MATCH("女"&$T10&"-3",計算用!$AN$2:$AN$186,0)),"")) | AF10: =IF($T10="","",IFERROR(INDEX(計算用!$D$2:$D$186,MATCH("女"&$T10&"-4",計算用!$AN$2:$AN$186,0)),"")) | AG10: =IF($T10="","",IFERROR(INDEX(計算用!$M$2:$M$186,MATCH("女"&$T10&"-4",計算用!$AN$2:$AN$186,0)),"")) | AH10: =IF($T10="","",IFERROR(INDEX(計算用!$I$2:$I$186,MATCH("女"&$T10&"-4",計算用!$AN$2:$AN$186,0)),"")) | AI10: =IF($T10="","",IFERROR(INDEX(計算用!$D$2:$D$186,MATCH("女"&$T10&"-5",計算用!$AN$2:$AN$186,0)),"")) | AJ10: =IF($T10="","",IFERROR(INDEX(計算用!$M$2:$M$186,MATCH("女"&$T10&"-5",計算用!$AN$2:$AN$186,0)),"")) | AK10: =IF($T10="","",IFERROR(INDEX(計算用!$I$2:$I$186,MATCH("女"&$T10&"-5",計算用!$AN$2:$AN$186,0)),""))
A11: =IF(ROW()-3<=計算用!$Q$9,ROW()-3,"") | B11: =IF($A11="","",INDEX(計算用!$T$2:$T$51,$A11)) | C11: =IF($A11="","","赤"&INDEX(計算用!$W$2:$W$51,$A11)&"白"&INDEX(計算用!$X$2:$X$51,$A11)) | D11: =IF($A11="","",IFERROR(INDEX(計算用!$D$2:$D$186,MATCH("男"&$A11&"-1",計算用!$AN$2:$AN$186,0)),"")) | E11: =IF($A11="","",IFERROR(INDEX(計算用!$M$2:$M$186,MATCH("男"&$A11&"-1",計算用!$AN$2:$AN$186,0)),"")) | F11: =IF($A11="","",IFERROR(INDEX(計算用!$I$2:$I$186,MATCH("男"&$A11&"-1",計算用!$AN$2:$AN$186,0)),"")) | G11: =IF($A11="","",IFERROR(INDEX(計算用!$D$2:$D$186,MATCH("男"&$A11&"-2",計算用!$AN$2:$AN$186,0)),"")) | H11: =IF($A11="","",IFERROR(INDEX(計算用!$M$2:$M$186,MATCH("男"&$A11&"-2",計算用!$AN$2:$AN$186,0)),"")) | I11: =IF($A11="","",IFERROR(INDEX(計算用!$I$2:$I$186,MATCH("男"&$A11&"-2",計算用!$AN$2:$AN$186,0)),"")) | J11: =IF($A11="","",IFERROR(INDEX(計算用!$D$2:$D$186,MATCH("男"&$A11&"-3",計算用!$AN$2:$AN$186,0)),"")) | K11: =IF($A11="","",IFERROR(INDEX(計算用!$M$2:$M$186,MATCH("男"&$A11&"-3",計算用!$AN$2:$AN$186,0)),"")) | L11: =IF($A11="","",IFERROR(INDEX(計算用!$I$2:$I$186,MATCH("男"&$A11&"-3",計算用!$AN$2:$AN$186,0)),"")) | M11: =IF($A11="","",IFERROR(INDEX(計算用!$D$2:$D$186,MATCH("男"&$A11&"-4",計算用!$AN$2:$AN$186,0)),"")) | N11: =IF($A11="","",IFERROR(INDEX(計算用!$M$2:$M$186,MATCH("男"&$A11&"-4",計算用!$AN$2:$AN$186,0)),"")) | O11: =IF($A11="","",IFERROR(INDEX(計算用!$I$2:$I$186,MATCH("男"&$A11&"-4",計算用!$AN$2:$AN$186,0)),"")) | P11: =IF($A11="","",IFERROR(INDEX(計算用!$D$2:$D$186,MATCH("男"&$A11&"-5",計算用!$AN$2:$AN$186,0)),"")) | Q11: =IF($A11="","",IFERROR(INDEX(計算用!$M$2:$M$186,MATCH("男"&$A11&"-5",計算用!$AN$2:$AN$186,0)),"")) | R11: =IF($A11="","",IFERROR(INDEX(計算用!$I$2:$I$186,MATCH("男"&$A11&"-5",計算用!$AN$2:$AN$186,0)),"")) | T11: =IF(ROW()-3<=計算用!$Q$11,ROW()-3,"") | U11: =IF($T11="","",INDEX(計算用!$AC$2:$AC$51,$T11)) | V11: =IF($T11="","","赤"&INDEX(計算用!$AF$2:$AF$51,$T11)&"白"&INDEX(計算用!$AG$2:$AG$51,$T11)) | W11: =IF($T11="","",IFERROR(INDEX(計算用!$D$2:$D$186,MATCH("女"&$T11&"-1",計算用!$AN$2:$AN$186,0)),"")) | X11: =IF($T11="","",IFERROR(INDEX(計算用!$M$2:$M$186,MATCH("女"&$T11&"-1",計算用!$AN$2:$AN$186,0)),"")) | Y11: =IF($T11="","",IFERROR(INDEX(計算用!$I$2:$I$186,MATCH("女"&$T11&"-1",計算用!$AN$2:$AN$186,0)),"")) | Z11: =IF($T11="","",IFERROR(INDEX(計算用!$D$2:$D$186,MATCH("女"&$T11&"-2",計算用!$AN$2:$AN$186,0)),"")) | AA11: =IF($T11="","",IFERROR(INDEX(計算用!$M$2:$M$186,MATCH("女"&$T11&"-2",計算用!$AN$2:$AN$186,0)),"")) | AB11: =IF($T11="","",IFERROR(INDEX(計算用!$I$2:$I$186,MATCH("女"&$T11&"-2",計算用!$AN$2:$AN$186,0)),"")) | AC11: =IF($T11="","",IFERROR(INDEX(計算用!$D$2:$D$186,MATCH("女"&$T11&"-3",計算用!$AN$2:$AN$186,0)),"")) | AD11: =IF($T11="","",IFERROR(INDEX(計算用!$M$2:$M$186,MATCH("女"&$T11&"-3",計算用!$AN$2:$AN$186,0)),"")) | AE11: =IF($T11="","",IFERROR(INDEX(計算用!$I$2:$I$186,MATCH("女"&$T11&"-3",計算用!$AN$2:$AN$186,0)),"")) | AF11: =IF($T11="","",IFERROR(INDEX(計算用!$D$2:$D$186,MATCH("女"&$T11&"-4",計算用!$AN$2:$AN$186,0)),"")) | AG11: =IF($T11="","",IFERROR(INDEX(計算用!$M$2:$M$186,MATCH("女"&$T11&"-4",計算用!$AN$2:$AN$186,0)),"")) | AH11: =IF($T11="","",IFERROR(INDEX(計算用!$I$2:$I$186,MATCH("女"&$T11&"-4",計算用!$AN$2:$AN$186,0)),"")) | AI11: =IF($T11="","",IFERROR(INDEX(計算用!$D$2:$D$186,MATCH("女"&$T11&"-5",計算用!$AN$2:$AN$186,0)),"")) | AJ11: =IF($T11="","",IFERROR(INDEX(計算用!$M$2:$M$186,MATCH("女"&$T11&"-5",計算用!$AN$2:$AN$186,0)),"")) | AK11: =IF($T11="","",IFERROR(INDEX(計算用!$I$2:$I$186,MATCH("女"&$T11&"-5",計算用!$AN$2:$AN$186,0)),""))
A12: =IF(ROW()-3<=計算用!$Q$9,ROW()-3,"") | B12: =IF($A12="","",INDEX(計算用!$T$2:$T$51,$A12)) | C12: =IF($A12="","","赤"&INDEX(計算用!$W$2:$W$51,$A12)&"白"&INDEX(計算用!$X$2:$X$51,$A12)) | D12: =IF($A12="","",IFERROR(INDEX(計算用!$D$2:$D$186,MATCH("男"&$A12&"-1",計算用!$AN$2:$AN$186,0)),"")) | E12: =IF($A12="","",IFERROR(INDEX(計算用!$M$2:$M$186,MATCH("男"&$A12&"-1",計算用!$AN$2:$AN$186,0)),"")) | F12: =IF($A12="","",IFERROR(INDEX(計算用!$I$2:$I$186,MATCH("男"&$A12&"-1",計算用!$AN$2:$AN$186,0)),"")) | G12: =IF($A12="","",IFERROR(INDEX(計算用!$D$2:$D$186,MATCH("男"&$A12&"-2",計算用!$AN$2:$AN$186,0)),"")) | H12: =IF($A12="","",IFERROR(INDEX(計算用!$M$2:$M$186,MATCH("男"&$A12&"-2",計算用!$AN$2:$AN$186,0)),"")) | I12: =IF($A12="","",IFERROR(INDEX(計算用!$I$2:$I$186,MATCH("男"&$A12&"-2",計算用!$AN$2:$AN$186,0)),"")) | J12: =IF($A12="","",IFERROR(INDEX(計算用!$D$2:$D$186,MATCH("男"&$A12&"-3",計算用!$AN$2:$AN$186,0)),"")) | K12: =IF($A12="","",IFERROR(INDEX(計算用!$M$2:$M$186,MATCH("男"&$A12&"-3",計算用!$AN$2:$AN$186,0)),"")) | L12: =IF($A12="","",IFERROR(INDEX(計算用!$I$2:$I$186,MATCH("男"&$A12&"-3",計算用!$AN$2:$AN$186,0)),"")) | M12: =IF($A12="","",IFERROR(INDEX(計算用!$D$2:$D$186,MATCH("男"&$A12&"-4",計算用!$AN$2:$AN$186,0)),"")) | N12: =IF($A12="","",IFERROR(INDEX(計算用!$M$2:$M$186,MATCH("男"&$A12&"-4",計算用!$AN$2:$AN$186,0)),"")) | O12: =IF($A12="","",IFERROR(INDEX(計算用!$I$2:$I$186,MATCH("男"&$A12&"-4",計算用!$AN$2:$AN$186,0)),"")) | P12: =IF($A12="","",IFERROR(INDEX(計算用!$D$2:$D$186,MATCH("男"&$A12&"-5",計算用!$AN$2:$AN$186,0)),"")) | Q12: =IF($A12="","",IFERROR(INDEX(計算用!$M$2:$M$186,MATCH("男"&$A12&"-5",計算用!$AN$2:$AN$186,0)),"")) | R12: =IF($A12="","",IFERROR(INDEX(計算用!$I$2:$I$186,MATCH("男"&$A12&"-5",計算用!$AN$2:$AN$186,0)),"")) | T12: =IF(ROW()-3<=計算用!$Q$11,ROW()-3,"") | U12: =IF($T12="","",INDEX(計算用!$AC$2:$AC$51,$T12)) | V12: =IF($T12="","","赤"&INDEX(計算用!$AF$2:$AF$51,$T12)&"白"&INDEX(計算用!$AG$2:$AG$51,$T12)) | W12: =IF($T12="","",IFERROR(INDEX(計算用!$D$2:$D$186,MATCH("女"&$T12&"-1",計算用!$AN$2:$AN$186,0)),"")) | X12: =IF($T12="","",IFERROR(INDEX(計算用!$M$2:$M$186,MATCH("女"&$T12&"-1",計算用!$AN$2:$AN$186,0)),"")) | Y12: =IF($T12="","",IFERROR(INDEX(計算用!$I$2:$I$186,MATCH("女"&$T12&"-1",計算用!$AN$2:$AN$186,0)),"")) | Z12: =IF($T12="","",IFERROR(INDEX(計算用!$D$2:$D$186,MATCH("女"&$T12&"-2",計算用!$AN$2:$AN$186,0)),"")) | AA12: =IF($T12="","",IFERROR(INDEX(計算用!$M$2:$M$186,MATCH("女"&$T12&"-2",計算用!$AN$2:$AN$186,0)),"")) | AB12: =IF($T12="","",IFERROR(INDEX(計算用!$I$2:$I$186,MATCH("女"&$T12&"-2",計算用!$AN$2:$AN$186,0)),"")) | AC12: =IF($T12="","",IFERROR(INDEX(計算用!$D$2:$D$186,MATCH("女"&$T12&"-3",計算用!$AN$2:$AN$186,0)),"")) | AD12: =IF($T12="","",IFERROR(INDEX(計算用!$M$2:$M$186,MATCH("女"&$T12&"-3",計算用!$AN$2:$AN$186,0)),"")) | AE12: =IF($T12="","",IFERROR(INDEX(計算用!$I$2:$I$186,MATCH("女"&$T12&"-3",計算用!$AN$2:$AN$186,0)),"")) | AF12: =IF($T12="","",IFERROR(INDEX(計算用!$D$2:$D$186,MATCH("女"&$T12&"-4",計算用!$AN$2:$AN$186,0)),"")) | AG12: =IF($T12="","",IFERROR(INDEX(計算用!$M$2:$M$186,MATCH("女"&$T12&"-4",計算用!$AN$2:$AN$186,0)),"")) | AH12: =IF($T12="","",IFERROR(INDEX(計算用!$I$2:$I$186,MATCH("女"&$T12&"-4",計算用!$AN$2:$AN$186,0)),"")) | AI12: =IF($T12="","",IFERROR(INDEX(計算用!$D$2:$D$186,MATCH("女"&$T12&"-5",計算用!$AN$2:$AN$186,0)),"")) | AJ12: =IF($T12="","",IFERROR(INDEX(計算用!$M$2:$M$186,MATCH("女"&$T12&"-5",計算用!$AN$2:$AN$186,0)),"")) | AK12: =IF($T12="","",IFERROR(INDEX(計算用!$I$2:$I$186,MATCH("女"&$T12&"-5",計算用!$AN$2:$AN$186,0)),""))
A13: =IF(ROW()-3<=計算用!$Q$9,ROW()-3,"") | B13: =IF($A13="","",INDEX(計算用!$T$2:$T$51,$A13)) | C13: =IF($A13="","","赤"&INDEX(計算用!$W$2:$W$51,$A13)&"白"&INDEX(計算用!$X$2:$X$51,$A13)) | D13: =IF($A13="","",IFERROR(INDEX(計算用!$D$2:$D$186,MATCH("男"&$A13&"-1",計算用!$AN$2:$AN$186,0)),"")) | E13: =IF($A13="","",IFERROR(INDEX(計算用!$M$2:$M$186,MATCH("男"&$A13&"-1",計算用!$AN$2:$AN$186,0)),"")) | F13: =IF($A13="","",IFERROR(INDEX(計算用!$I$2:$I$186,MATCH("男"&$A13&"-1",計算用!$AN$2:$AN$186,0)),"")) | G13: =IF($A13="","",IFERROR(INDEX(計算用!$D$2:$D$186,MATCH("男"&$A13&"-2",計算用!$AN$2:$AN$186,0)),"")) | H13: =IF($A13="","",IFERROR(INDEX(計算用!$M$2:$M$186,MATCH("男"&$A13&"-2",計算用!$AN$2:$AN$186,0)),"")) | I13: =IF($A13="","",IFERROR(INDEX(計算用!$I$2:$I$186,MATCH("男"&$A13&"-2",計算用!$AN$2:$AN$186,0)),"")) | J13: =IF($A13="","",IFERROR(INDEX(計算用!$D$2:$D$186,MATCH("男"&$A13&"-3",計算用!$AN$2:$AN$186,0)),"")) | K13: =IF($A13="","",IFERROR(INDEX(計算用!$M$2:$M$186,MATCH("男"&$A13&"-3",計算用!$AN$2:$AN$186,0)),"")) | L13: =IF($A13="","",IFERROR(INDEX(計算用!$I$2:$I$186,MATCH("男"&$A13&"-3",計算用!$AN$2:$AN$186,0)),"")) | M13: =IF($A13="","",IFERROR(INDEX(計算用!$D$2:$D$186,MATCH("男"&$A13&"-4",計算用!$AN$2:$AN$186,0)),"")) | N13: =IF($A13="","",IFERROR(INDEX(計算用!$M$2:$M$186,MATCH("男"&$A13&"-4",計算用!$AN$2:$AN$186,0)),"")) | O13: =IF($A13="","",IFERROR(INDEX(計算用!$I$2:$I$186,MATCH("男"&$A13&"-4",計算用!$AN$2:$AN$186,0)),"")) | P13: =IF($A13="","",IFERROR(INDEX(計算用!$D$2:$D$186,MATCH("男"&$A13&"-5",計算用!$AN$2:$AN$186,0)),"")) | Q13: =IF($A13="","",IFERROR(INDEX(計算用!$M$2:$M$186,MATCH("男"&$A13&"-5",計算用!$AN$2:$AN$186,0)),"")) | R13: =IF($A13="","",IFERROR(INDEX(計算用!$I$2:$I$186,MATCH("男"&$A13&"-5",計算用!$AN$2:$AN$186,0)),"")) | T13: =IF(ROW()-3<=計算用!$Q$11,ROW()-3,"") | U13: =IF($T13="","",INDEX(計算用!$AC$2:$AC$51,$T13)) | V13: =IF($T13="","","赤"&INDEX(計算用!$AF$2:$AF$51,$T13)&"白"&INDEX(計算用!$AG$2:$AG$51,$T13)) | W13: =IF($T13="","",IFERROR(INDEX(計算用!$D$2:$D$186,MATCH("女"&$T13&"-1",計算用!$AN$2:$AN$186,0)),"")) | X13: =IF($T13="","",IFERROR(INDEX(計算用!$M$2:$M$186,MATCH("女"&$T13&"-1",計算用!$AN$2:$AN$186,0)),"")) | Y13: =IF($T13="","",IFERROR(INDEX(計算用!$I$2:$I$186,MATCH("女"&$T13&"-1",計算用!$AN$2:$AN$186,0)),"")) | Z13: =IF($T13="","",IFERROR(INDEX(計算用!$D$2:$D$186,MATCH("女"&$T13&"-2",計算用!$AN$2:$AN$186,0)),"")) | AA13: =IF($T13="","",IFERROR(INDEX(計算用!$M$2:$M$186,MATCH("女"&$T13&"-2",計算用!$AN$2:$AN$186,0)),"")) | AB13: =IF($T13="","",IFERROR(INDEX(計算用!$I$2:$I$186,MATCH("女"&$T13&"-2",計算用!$AN$2:$AN$186,0)),"")) | AC13: =IF($T13="","",IFERROR(INDEX(計算用!$D$2:$D$186,MATCH("女"&$T13&"-3",計算用!$AN$2:$AN$186,0)),"")) | AD13: =IF($T13="","",IFERROR(INDEX(計算用!$M$2:$M$186,MATCH("女"&$T13&"-3",計算用!$AN$2:$AN$186,0)),"")) | AE13: =IF($T13="","",IFERROR(INDEX(計算用!$I$2:$I$186,MATCH("女"&$T13&"-3",計算用!$AN$2:$AN$186,0)),"")) | AF13: =IF($T13="","",IFERROR(INDEX(計算用!$D$2:$D$186,MATCH("女"&$T13&"-4",計算用!$AN$2:$AN$186,0)),"")) | AG13: =IF($T13="","",IFERROR(INDEX(計算用!$M$2:$M$186,MATCH("女"&$T13&"-4",計算用!$AN$2:$AN$186,0)),"")) | AH13: =IF($T13="","",IFERROR(INDEX(計算用!$I$2:$I$186,MATCH("女"&$T13&"-4",計算用!$AN$2:$AN$186,0)),"")) | AI13: =IF($T13="","",IFERROR(INDEX(計算用!$D$2:$D$186,MATCH("女"&$T13&"-5",計算用!$AN$2:$AN$186,0)),"")) | AJ13: =IF($T13="","",IFERROR(INDEX(計算用!$M$2:$M$186,MATCH("女"&$T13&"-5",計算用!$AN$2:$AN$186,0)),"")) | AK13: =IF($T13="","",IFERROR(INDEX(計算用!$I$2:$I$186,MATCH("女"&$T13&"-5",計算用!$AN$2:$AN$186,0)),""))
A14: =IF(ROW()-3<=計算用!$Q$9,ROW()-3,"") | B14: =IF($A14="","",INDEX(計算用!$T$2:$T$51,$A14)) | C14: =IF($A14="","","赤"&INDEX(計算用!$W$2:$W$51,$A14)&"白"&INDEX(計算用!$X$2:$X$51,$A14)) | D14: =IF($A14="","",IFERROR(INDEX(計算用!$D$2:$D$186,MATCH("男"&$A14&"-1",計算用!$AN$2:$AN$186,0)),"")) | E14: =IF($A14="","",IFERROR(INDEX(計算用!$M$2:$M$186,MATCH("男"&$A14&"-1",計算用!$AN$2:$AN$186,0)),"")) | F14: =IF($A14="","",IFERROR(INDEX(計算用!$I$2:$I$186,MATCH("男"&$A14&"-1",計算用!$AN$2:$AN$186,0)),"")) | G14: =IF($A14="","",IFERROR(INDEX(計算用!$D$2:$D$186,MATCH("男"&$A14&"-2",計算用!$AN$2:$AN$186,0)),"")) | H14: =IF($A14="","",IFERROR(INDEX(計算用!$M$2:$M$186,MATCH("男"&$A14&"-2",計算用!$AN$2:$AN$186,0)),"")) | I14: =IF($A14="","",IFERROR(INDEX(計算用!$I$2:$I$186,MATCH("男"&$A14&"-2",計算用!$AN$2:$AN$186,0)),"")) | J14: =IF($A14="","",IFERROR(INDEX(計算用!$D$2:$D$186,MATCH("男"&$A14&"-3",計算用!$AN$2:$AN$186,0)),"")) | K14: =IF($A14="","",IFERROR(INDEX(計算用!$M$2:$M$186,MATCH("男"&$A14&"-3",計算用!$AN$2:$AN$186,0)),"")) | L14: =IF($A14="","",IFERROR(INDEX(計算用!$I$2:$I$186,MATCH("男"&$A14&"-3",計算用!$AN$2:$AN$186,0)),"")) | M14: =IF($A14="","",IFERROR(INDEX(計算用!$D$2:$D$186,MATCH("男"&$A14&"-4",計算用!$AN$2:$AN$186,0)),"")) | N14: =IF($A14="","",IFERROR(INDEX(計算用!$M$2:$M$186,MATCH("男"&$A14&"-4",計算用!$AN$2:$AN$186,0)),"")) | O14: =IF($A14="","",IFERROR(INDEX(計算用!$I$2:$I$186,MATCH("男"&$A14&"-4",計算用!$AN$2:$AN$186,0)),"")) | P14: =IF($A14="","",IFERROR(INDEX(計算用!$D$2:$D$186,MATCH("男"&$A14&"-5",計算用!$AN$2:$AN$186,0)),"")) | Q14: =IF($A14="","",IFERROR(INDEX(計算用!$M$2:$M$186,MATCH("男"&$A14&"-5",計算用!$AN$2:$AN$186,0)),"")) | R14: =IF($A14="","",IFERROR(INDEX(計算用!$I$2:$I$186,MATCH("男"&$A14&"-5",計算用!$AN$2:$AN$186,0)),"")) | T14: =IF(ROW()-3<=計算用!$Q$11,ROW()-3,"") | U14: =IF($T14="","",INDEX(計算用!$AC$2:$AC$51,$T14)) | V14: =IF($T14="","","赤"&INDEX(計算用!$AF$2:$AF$51,$T14)&"白"&INDEX(計算用!$AG$2:$AG$51,$T14)) | W14: =IF($T14="","",IFERROR(INDEX(計算用!$D$2:$D$186,MATCH("女"&$T14&"-1",計算用!$AN$2:$AN$186,0)),"")) | X14: =IF($T14="","",IFERROR(INDEX(計算用!$M$2:$M$186,MATCH("女"&$T14&"-1",計算用!$AN$2:$AN$186,0)),"")) | Y14: =IF($T14="","",IFERROR(INDEX(計算用!$I$2:$I$186,MATCH("女"&$T14&"-1",計算用!$AN$2:$AN$186,0)),"")) | Z14: =IF($T14="","",IFERROR(INDEX(計算用!$D$2:$D$186,MATCH("女"&$T14&"-2",計算用!$AN$2:$AN$186,0)),"")) | AA14: =IF($T14="","",IFERROR(INDEX(計算用!$M$2:$M$186,MATCH("女"&$T14&"-2",計算用!$AN$2:$AN$186,0)),"")) | AB14: =IF($T14="","",IFERROR(INDEX(計算用!$I$2:$I$186,MATCH("女"&$T14&"-2",計算用!$AN$2:$AN$186,0)),"")) | AC14: =IF($T14="","",IFERROR(INDEX(計算用!$D$2:$D$186,MATCH("女"&$T14&"-3",計算用!$AN$2:$AN$186,0)),"")) | AD14: =IF($T14="","",IFERROR(INDEX(計算用!$M$2:$M$186,MATCH("女"&$T14&"-3",計算用!$AN$2:$AN$186,0)),"")) | AE14: =IF($T14="","",IFERROR(INDEX(計算用!$I$2:$I$186,MATCH("女"&$T14&"-3",計算用!$AN$2:$AN$186,0)),"")) | AF14: =IF($T14="","",IFERROR(INDEX(計算用!$D$2:$D$186,MATCH("女"&$T14&"-4",計算用!$AN$2:$AN$186,0)),"")) | AG14: =IF($T14="","",IFERROR(INDEX(計算用!$M$2:$M$186,MATCH("女"&$T14&"-4",計算用!$AN$2:$AN$186,0)),"")) | AH14: =IF($T14="","",IFERROR(INDEX(計算用!$I$2:$I$186,MATCH("女"&$T14&"-4",計算用!$AN$2:$AN$186,0)),"")) | AI14: =IF($T14="","",IFERROR(INDEX(計算用!$D$2:$D$186,MATCH("女"&$T14&"-5",計算用!$AN$2:$AN$186,0)),"")) | AJ14: =IF($T14="","",IFERROR(INDEX(計算用!$M$2:$M$186,MATCH("女"&$T14&"-5",計算用!$AN$2:$AN$186,0)),"")) | AK14: =IF($T14="","",IFERROR(INDEX(計算用!$I$2:$I$186,MATCH("女"&$T14&"-5",計算用!$AN$2:$AN$186,0)),""))
A15: =IF(ROW()-3<=計算用!$Q$9,ROW()-3,"") | B15: =IF($A15="","",INDEX(計算用!$T$2:$T$51,$A15)) | C15: =IF($A15="","","赤"&INDEX(計算用!$W$2:$W$51,$A15)&"白"&INDEX(計算用!$X$2:$X$51,$A15)) | D15: =IF($A15="","",IFERROR(INDEX(計算用!$D$2:$D$186,MATCH("男"&$A15&"-1",計算用!$AN$2:$AN$186,0)),"")) | E15: =IF($A15="","",IFERROR(INDEX(計算用!$M$2:$M$186,MATCH("男"&$A15&"-1",計算用!$AN$2:$AN$186,0)),"")) | F15: =IF($A15="","",IFERROR(INDEX(計算用!$I$2:$I$186,MATCH("男"&$A15&"-1",計算用!$AN$2:$AN$186,0)),"")) | G15: =IF($A15="","",IFERROR(INDEX(計算用!$D$2:$D$186,MATCH("男"&$A15&"-2",計算用!$AN$2:$AN$186,0)),"")) | H15: =IF($A15="","",IFERROR(INDEX(計算用!$M$2:$M$186,MATCH("男"&$A15&"-2",計算用!$AN$2:$AN$186,0)),"")) | I15: =IF($A15="","",IFERROR(INDEX(計算用!$I$2:$I$186,MATCH("男"&$A15&"-2",計算用!$AN$2:$AN$186,0)),"")) | J15: =IF($A15="","",IFERROR(INDEX(計算用!$D$2:$D$186,MATCH("男"&$A15&"-3",計算用!$AN$2:$AN$186,0)),"")) | K15: =IF($A15="","",IFERROR(INDEX(計算用!$M$2:$M$186,MATCH("男"&$A15&"-3",計算用!$AN$2:$AN$186,0)),"")) | L15: =IF($A15="","",IFERROR(INDEX(計算用!$I$2:$I$186,MATCH("男"&$A15&"-3",計算用!$AN$2:$AN$186,0)),"")) | M15: =IF($A15="","",IFERROR(INDEX(計算用!$D$2:$D$186,MATCH("男"&$A15&"-4",計算用!$AN$2:$AN$186,0)),"")) | N15: =IF($A15="","",IFERROR(INDEX(計算用!$M$2:$M$186,MATCH("男"&$A15&"-4",計算用!$AN$2:$AN$186,0)),"")) | O15: =IF($A15="","",IFERROR(INDEX(計算用!$I$2:$I$186,MATCH("男"&$A15&"-4",計算用!$AN$2:$AN$186,0)),"")) | P15: =IF($A15="","",IFERROR(INDEX(計算用!$D$2:$D$186,MATCH("男"&$A15&"-5",計算用!$AN$2:$AN$186,0)),"")) | Q15: =IF($A15="","",IFERROR(INDEX(計算用!$M$2:$M$186,MATCH("男"&$A15&"-5",計算用!$AN$2:$AN$186,0)),"")) | R15: =IF($A15="","",IFERROR(INDEX(計算用!$I$2:$I$186,MATCH("男"&$A15&"-5",計算用!$AN$2:$AN$186,0)),"")) | T15: =IF(ROW()-3<=計算用!$Q$11,ROW()-3,"") | U15: =IF($T15="","",INDEX(計算用!$AC$2:$AC$51,$T15)) | V15: =IF($T15="","","赤"&INDEX(計算用!$AF$2:$AF$51,$T15)&"白"&INDEX(計算用!$AG$2:$AG$51,$T15)) | W15: =IF($T15="","",IFERROR(INDEX(計算用!$D$2:$D$186,MATCH("女"&$T15&"-1",計算用!$AN$2:$AN$186,0)),"")) | X15: =IF($T15="","",IFERROR(INDEX(計算用!$M$2:$M$186,MATCH("女"&$T15&"-1",計算用!$AN$2:$AN$186,0)),"")) | Y15: =IF($T15="","",IFERROR(INDEX(計算用!$I$2:$I$186,MATCH("女"&$T15&"-1",計算用!$AN$2:$AN$186,0)),"")) | Z15: =IF($T15="","",IFERROR(INDEX(計算用!$D$2:$D$186,MATCH("女"&$T15&"-2",計算用!$AN$2:$AN$186,0)),"")) | AA15: =IF($T15="","",IFERROR(INDEX(計算用!$M$2:$M$186,MATCH("女"&$T15&"-2",計算用!$AN$2:$AN$186,0)),"")) | AB15: =IF($T15="","",IFERROR(INDEX(計算用!$I$2:$I$186,MATCH("女"&$T15&"-2",計算用!$AN$2:$AN$186,0)),"")) | AC15: =IF($T15="","",IFERROR(INDEX(計算用!$D$2:$D$186,MATCH("女"&$T15&"-3",計算用!$AN$2:$AN$186,0)),"")) | AD15: =IF($T15="","",IFERROR(INDEX(計算用!$M$2:$M$186,MATCH("女"&$T15&"-3",計算用!$AN$2:$AN$186,0)),"")) | AE15: =IF($T15="","",IFERROR(INDEX(計算用!$I$2:$I$186,MATCH("女"&$T15&"-3",計算用!$AN$2:$AN$186,0)),"")) | AF15: =IF($T15="","",IFERROR(INDEX(計算用!$D$2:$D$186,MATCH("女"&$T15&"-4",計算用!$AN$2:$AN$186,0)),"")) | AG15: =IF($T15="","",IFERROR(INDEX(計算用!$M$2:$M$186,MATCH("女"&$T15&"-4",計算用!$AN$2:$AN$186,0)),"")) | AH15: =IF($T15="","",IFERROR(INDEX(計算用!$I$2:$I$186,MATCH("女"&$T15&"-4",計算用!$AN$2:$AN$186,0)),"")) | AI15: =IF($T15="","",IFERROR(INDEX(計算用!$D$2:$D$186,MATCH("女"&$T15&"-5",計算用!$AN$2:$AN$186,0)),"")) | AJ15: =IF($T15="","",IFERROR(INDEX(計算用!$M$2:$M$186,MATCH("女"&$T15&"-5",計算用!$AN$2:$AN$186,0)),"")) | AK15: =IF($T15="","",IFERROR(INDEX(計算用!$I$2:$I$186,MATCH("女"&$T15&"-5",計算用!$AN$2:$AN$186,0)),""))
