Workbook

Sheet ①データ入力
I1: 名簿から名前をコピペして使ってください。３年生以上は性別欄を記入しないと動きません。タイムまで入力したら②のシートへ
A2: No. | B2: 1組 名前 | C2: 性別 (1=男子 2=女子) | D2: タイム (1/100秒) | E2: 赤or白 | G2: 2組 名前 | H2: 性別 (1=男子 2=女子) | I2: タイム (1/100秒) | J2: 赤or白 | L2: 3組 名前 | M2: 性別 (1=男子 2=女子) | N2: タイム (1/100秒) | O2: 赤or白 | Q2: 4組 名前 | R2: 性別 (1=男子 2=女子) | S2: タイム (1/100秒) | T2: 赤or白 | V2: 5組 名前 | W2: 性別 (1=男子 2=女子) | X2: タイム (1/100秒) | Y2: 赤or白
A3: 1
A4: 2
A5: 3
A6: 4
A7: 5
A8: 6
A9: 7
A10: 8
A11: 9
A12: 10
A13: 11
A14: 12
... A39: 37

Sheet 組ごとタイム順
A1: 男子 | J1: 女子 | S1: =IF(計算用!$Q$6>0,"※名前はあるのに性別・タイム・赤白のどれかが未入力で、表に出ていない人が"&計算用!$Q$6&"人います","")
B2: 赤組 | F2: 白組 | K2: 赤組 | O2: 白組
B3: 名前 | C3: クラス | D3: タイム | F3: 名前 | G3: クラス | H3: タイム | K3: 名前 | L3: クラス | M3: タイム | O3: 名前 | P3: クラス | Q3: タイム
A4: =IF(ROW()-3<=MAX(計算用!$Q$2,計算用!$Q$3),ROW()-3,"") | B4: =IFERROR(INDEX(計算用!$D$2:$D$186,MATCH("男赤"&$A4,計算用!$L$2:$L$186,0)),"") | C4: =IFERROR(INDEX(計算用!$M$2:$M$186,MATCH("男赤"&$A4,計算用!$L$2:$L$186,0)),"") | D4: =IFERROR(INDEX(計算用!$G$2:$G$186,MATCH("男赤"&$A4,計算用!$L$2:$L$186,0)),"") | F4: =IFERROR(INDEX(計算用!$D$2:$D$186,MATCH("男白"&$A4,計算用!$L$2:$L$186,0)),"") | G4: =IFERROR(INDEX(計算用!$M$2:$M$186,MATCH("男白"&$A4,計算用!$L$2:$L$186,0)),"") | H4: =IFERROR(INDEX(計算用!$G$2:$G$186,MATCH("男白"&$A4,計算用!$L$2:$L$186,0)),"") | J4: =IF(ROW()-3<=MAX(計算用!$Q$4,計算用!$Q$5),ROW()-3,"") | K4: =IFERROR(INDEX(計算用!$D$2:$D$186,MATCH("女赤"&$J4,計算用!$L$2:$L$186,0)),"") | L4: =IFERROR(INDEX(計算用!$M$2:$M$186,MATCH("女赤"&$J4,計算用!$L$2:$L$186,0)),"") | M4: =IFERROR(INDEX(計算用!$G$2:$G$186,MATCH("女赤"&$J4,計算用!$L$2:$L$186,0)),"") | O4: =IFERROR(INDEX(計算用!$D$2:$D$186,MATCH("女白"&$J4,計算用!$L$2:$L$186,0)),"") | P4: =IFERROR(INDEX(計算用!$M$2:$M$186,MATCH("女白"&$J4,計算用!$L$2:$L$186,0)),"") | Q4: =IFERROR(INDEX(計算用!$G$2:$G$186,MATCH("女白"&$J4,計算用!$L$2:$L$186,0)),"")
A5: =IF(ROW()-3<=MAX(計算用!$Q$2,計算用!$Q$3),ROW()-3,"") | B5: =IFERROR(INDEX(計算用!$D$2:$D$186,MATCH("男赤"&$A5,計算用!$L$2:$L$186,0)),"") | C5: =IFERROR(INDEX(計算用!$M$2:$M$186,MATCH("男赤"&$A5,計算用!$L$2:$L$186,0)),"") | D5: =IFERROR(INDEX(計算用!$G$2:$G$186,MATCH("男赤"&$A5,計算用!$L$2:$L$186,0)),"") | F5: =IFERROR(INDEX(計算用!$D$2:$D$186,MATCH("男白"&$A5,計算用!$L$2:$L$186,0)),"") | G5: =IFERROR(INDEX(計算用!$M$2:$M$186,MATCH("男白"&$A5,計算用!$L$2:$L$186,0)),"") | H5: =IFERROR(INDEX(計算用!$G$2:$G$186,MATCH("男白"&$A5,計算用!$L$2:$L$186,0)),"") | J5: =IF(ROW()-3<=MAX(計算用!$Q$4,計算用!$Q$5),ROW()-3,"") | K5: =IFERROR(INDEX(計算用!$D$2:$D$186,MATCH("女赤"&$J5,計算用!$L$2:$L$186,0)),"") | L5: =IFERROR(INDEX(計算用!$M$2:$M$186,MATCH("女赤"&$J5,計算用!$L$2:$L$186,0)),"") | M5: =IFERROR(INDEX(計算用!$G$2:$G$186,MATCH("女赤"&$J5,計算用!$L$2:$L$186,0)),"") | O5: =IFERROR(INDEX(計算用!$D$2:$D$186,MATCH("女白"&$J5,計算用!$L$2:$L$186,0)),"") | P5: =IFERROR(INDEX(計算用!$M$2:$M$186,MATCH("女白"&$J5,計算用!$L$2:$L$186,0)),"") | Q5: =IFERROR(INDEX(計算用!$G$2:$G$186,MATCH("女白"&$J5,計算用!$L$2:$L$186,0)),"")
A6: =IF(ROW()-3<=MAX(計算用!$Q$2,計算用!$Q$3),ROW()-3,"") | B6: =IFERROR(INDEX(計算用!$D$2:$D$186,MATCH("男赤"&$A6,計算用!$L$2:$L$186,0)),"") | C6: =IFERROR(INDEX(計算用!$M$2:$M$186,MATCH("男赤"&$A6,計算用!$L$2:$L$186,0)),"") | D6: =IFERROR(INDEX(計算用!$G$2:$G$186,MATCH("男赤"&$A6,計算用!$L$2:$L$186,0)),"") | F6: =IFERROR(INDEX(計算用!$D$2:$D$186,MATCH("男白"&$A6,計算用!$L$2:$L$186,0)),"") | G6: =IFERROR(INDEX(計算用!$M$2:$M$186,MATCH("男白"&$A6,計算用!$L$2:$L$186,0)),"") | H6: =IFERROR(INDEX(計算用!$G$2:$G$186,MATCH("男白"&$A6,計算用!$L$2:$L$186,0)),"") | J6: =IF(ROW()-3<=MAX(計算用!$Q$4,計算用!$Q$5),ROW()-3,"") | K6: =IFERROR(INDEX(計算用!$D$2:$D$186,MATCH("女赤"&$J6,計算用!$L$2:$L$186,0)),"") | L6: =IFERROR(INDEX(計算用!$M$2:$M$186,MATCH("女赤"&$J6,計算用!$L$2:$L$186,0)),"") | M6: =IFERROR(INDEX(計算用!$G$2:$G$186,MATCH("女赤"&$J6,計算用!$L$2:$L$186,0)),"") | O6: =IFERROR(INDEX(計算用!$D$2:$D$186,MATCH("女白"&$J6,計算用!$L$2:$L$186,0)),"") | P6: =IFERROR(INDEX(計算用!$M$2:$M$186,MATCH("女白"&$J6,計算用!$L$2:$L$186,0)),"") | Q6: =IFERROR(INDEX(計算用!$G$2:$G$186,MATCH("女白"&$J6,計算用!$L$2:$L$186,0)),"")
A7: =IF(ROW()-3<=MAX(計算用!$Q$2,計算用!$Q$3),ROW()-3,"") | B7: =IFERROR(INDEX(計算用!$D$2:$D$186,MATCH("男赤"&$A7,計算用!$L$2:$L$186,0)),"") | C7: =IFERROR(INDEX(計算用!$M$2:$M$186,MATCH("男赤"&$A7,計算用!$L$2:$L$186,0)),"") | D7: =IFERROR(INDEX(計算用!$G$2:$G$186,MATCH("男赤"&$A7,計算用!$L$2:$L$186,0)),"") | F7: =IFERROR(INDEX(計算用!$D$2:$D$186,MATCH("男白"&$A7,計算用!$L$2:$L$186,0)),"") | G7: =IFERROR(INDEX(計算用!$M$2:$M$186,MATCH("男白"&$A7,計算用!$L$2:$L$186,0)),"") | H7: =IFERROR(INDEX(計算用!$G$2:$G$186,MATCH("男白"&$A7,計算用!$L$2:$L$186,0)),"") | J7: =IF(ROW()-3<=MAX(計算用!$Q$4,計算用!$Q$5),ROW()-3,"") | K7: =IFERROR(INDEX(計算用!$D$2:$D$186,MATCH("女赤"&$J7,計算用!$L$2:$L$186,0)),"") | L7: =IFERROR(INDEX(計算用!$M$2:$M$186,MATCH("女赤"&$J7,計算用!$L$2:$L$186,0)),"") | M7: =IFERROR(INDEX(計算用!$G$2:$G$186,MATCH("女赤"&$J7,計算用!$L$2:$L$186,0)),"") | O7: =IFERROR(INDEX(計算用!$D$2:$D$186,MATCH("女白"&$J7,計算用!$L$2:$L$186,0)),"") | P7: =IFERROR(INDEX(計算用!$M$2:$M$186,MATCH("女白"&$J7,計算用!$L$2:$L$186,0)),"") | Q7: =IFERROR(INDEX(計算用!$G$2:$G$186,MATCH("女白"&$J7,計算用!$L$2:$L$186,0)),"")
A8: =IF(ROW()-3<=MAX(計算用!$Q$2,計算用!$Q$3),ROW()-3,"") | B8: =IFERROR(INDEX(計算用!$D$2:$D$186,MATCH("男赤"&$A8,計算用!$L$2:$L$186,0)),"") | C8: =IFERROR(INDEX(計算用!$M$2:$M$186,MATCH("男赤"&$A8,計算用!$L$2:$L$186,0)),"") | D8: =IFERROR(INDEX(計算用!$G$2:$G$186,MATCH("男赤"&$A8,計算用!$L$2:$L$186,0)),"") | F8: =IFERROR(INDEX(計算用!$D$2:$D$186,MATCH("男白"&$A8,計算用!$L$2:$L$186,0)),"") | G8: =IFERROR(INDEX(計算用!$M$2:$M$186,MATCH("男白"&$A8,計算用!$L$2:$L$186,0)),"") | H8: =IFERROR(INDEX(計算用!$G$2:$G$186,MATCH("男白"&$A8,計算用!$L$2:$L$186,0)),"") | J8: =IF(ROW()-3<=MAX(計算用!$Q$4,計算用!$Q$5),ROW()-3,"") | K8: =IFERROR(INDEX(計算用!$D$2:$D$186,MATCH("女赤"&$J8,計算用!$L$2:$L$186,0)),"") | L8: =IFERROR(INDEX(計算用!$M$2:$M$186,MATCH("女赤"&$J8,計算用!$L$2:$L$186,0)),"") | M8: =IFERROR(INDEX(計算用!$G$2:$G$186,MATCH("女赤"&$J8,計算用!$L$2:$L$186,0)),"") | O8: =IFERROR(INDEX(計算用!$D$2:$D$186,MATCH("女白"&$J8,計算用!$L$2:$L$186,0)),"") | P8: =IFERROR(INDEX(計算用!$M$2:$M$186,MATCH("女白"&$J8,計算用!$L$2:$L$186,0)),"") | Q8: =IFERROR(INDEX(計算用!$G$2:$G$186,MATCH("女白"&$J8,計算用!$L$2:$L$186,0)),"")
A9: =IF(ROW()-3<=MAX(計算用!$Q$2,計算用!$Q$3),ROW()-3,"") | B9: =IFERROR(INDEX(計算用!$D$2:$D$186,MATCH("男赤"&$A9,計算用!$L$2:$L$186,0)),"") | C9: =IFERROR(INDEX(計算用!$M$2:$M$186,MATCH("男赤"&$A9,計算用!$L$2:$L$186,0)),"") | D9: =IFERROR(INDEX(計算用!$G$2:$G$186,MATCH("男赤"&$A9,計算用!$L$2:$L$186,0)),"") | F9: =IFERROR(INDEX(計算用!$D$2:$D$186,MATCH("男白"&$A9,計算用!$L$2:$L$186,0)),"") | G9: =IFERROR(INDEX(計算用!$M$2:$M$186,MATCH("男白"&$A9,計算用!$L$2:$L$186,0)),"") | H9: =IFERROR(INDEX(計算用!$G$2:$G$186,MATCH("男白"&$A9,計算用!$L$2:$L$186,0)),"") | J9: =IF(ROW()-3<=MAX(計算用!$Q$4,計算用!$Q$5),ROW()-3,"") | K9: =IFERROR(INDEX(計算用!$D$2:$D$186,MATCH("女赤"&$J9,計算用!$L$2:$L$186,0)),"") | L9: =IFERROR(INDEX(計算用!$M$2:$M$186,MATCH("女赤"&$J9,計算用!$L$2:$L$186,0)),"") | M9: =IFERROR(INDEX(計算用!$G$2:$G$186,MATCH("女赤"&$J9,計算用!$L$2:$L$186,0)),"") | O9: =IFERROR(INDEX(計算用!$D$2:$D$186,MATCH("女白"&$J9,計算用!$L$2:$L$186,0)),"") | P9: =IFERROR(INDEX(計算用!$M$2:$M$186,MATCH("女白"&$J9,計算用!$L$2:$L$186,0)),"") | Q9: =IFERROR(INDEX(計算用!$G$2:$G$186,MATCH("女白"&$J9,計算用!$L$2:$L$186,0)),"")
A10: =IF(ROW()-3<=MAX(計算用!$Q$2,計算用!$Q$3),ROW()-3,"") | B10: =IFERROR(INDEX(計算用!$D$2:$D$186,MATCH("男赤"&$A10,計算用!$L$2:$L$186,0)),"") | C10: =IFERROR(INDEX(計算用!$M$2:$M$186,MATCH("男赤"&$A10,計算用!$L$2:$L$186,0)),"") | D10: =IFERROR(INDEX(計算用!$G$2:$G$186,MATCH("男赤"&$A10,計算用!$L$2:$L$186,0)),"") | F10: =IFERROR(INDEX(計算用!$D$2:$D$186,MATCH("男白"&$A10,計算用!$L$2:$L$186,0)),"") | G10: =IFERROR(INDEX(計算用!$M$2:$M$186,MATCH("男白"&$A10,計算用!$L$2:$L$186,0)),"") | H10: =IFERROR(INDEX(計算用!$G$2:$G$186,MATCH("男白"&$A10,計算用!$L$2:$L$186,0)),"") | J10: =IF(ROW()-3<=MAX(計算用!$Q$4,計算用!$Q$5),ROW()-3,"") | K10: =IFERROR(INDEX(計算用!$D$2:$D$186,MATCH("女赤"&$J10,計算用!$L$2:$L$186,0)),"") | L10: =IFERROR(INDEX(計算用!$M$2:$M$186,MATCH("女赤"&$J10,計算用!$L$2:$L$186,0)),"") | M10: =IFERROR(INDEX(計算用!$G$2:$G$186,MATCH("女赤"&$J10,計算用!$L$2:$L$186,0)),"") | O10: =IFERROR(INDEX(計算用!$D$2:$D$186,MATCH("女白"&$J10,計算用!$L$2:$L$186,0)),"") | P10: =IFERROR(INDEX(計算用!$M$2:$M$186,MATCH("女白"&$J10,計算用!$L$2:$L$186,0)),"") | Q10: =IFERROR(INDEX(計算用!$G$2:$G$186,MATCH("女白"&$J10,計算用!$L$2:$L$186,0)),"")
A11: =IF(ROW()-3<=MAX(計算用!$Q$2,計算用!$Q$3),ROW()-3,"") | B11: =IFERROR(INDEX(計算用!$D$2:$D$186,MATCH("男赤"&$A11,計算用!$L$2:$L$186,0)),"") | C11: =IFERROR(INDEX(計算用!$M$2:$M$186,MATCH("男赤"&$A11,計算用!$L$2:$L$186,0)),"") | D11: =IFERROR(INDEX(計算用!$G$2:$G$186,MATCH("男赤"&$A11,計算用!$L$2:$L$186,0)),"") | F11: =IFERROR(INDEX(計算用!$D$2:$D$186,MATCH("男白"&$A11,計算用!$L$2:$L$186,0)),"") | G11: =IFERROR(INDEX(計算用!$M$2:$M$186,MATCH("男白"&$A11,計算用!$L$2:$L$186,0)),"") | H11: =IFERROR(INDEX(計算用!$G$2:$G$186,MATCH("男白"&$A11,計算用!$L$2:$L$186,0)),"") | J11: =IF(ROW()-3<=MAX(計算用!$Q$4,計算用!$Q$5),ROW()-3,"") | K11: =IFERROR(INDEX(計算用!$D$2:$D$186,MATCH("女赤"&$J11,計算用!$L$2:$L$186,0)),"") | L11: =IFERROR(INDEX(計算用!$M$2:$M$186,MATCH("女赤"&$J11,計算用!$L$2:$L$186,0)),"") | M11: =IFERROR(INDEX(計算用!$G$2:$G$186,MATCH("女赤"&$J11,計算用!$L$2:$L$186,0)),"") | O11: =IFERROR(INDEX(計算用!$D$2:$D$186,MATCH("女白"&$J11,計算用!$L$2:$L$186,0)),"") | P11: =IFERROR(INDEX(計算用!$M$2:$M$186,MATCH("女白"&$J11,計算用!$L$2:$L$186,0)),"") | Q11: =IFERROR(INDEX(計算用!$G$2:$G$186,MATCH("女白"&$J11,計算用!$L$2:$L$186,0)),"")
A12: =IF(ROW()-3<=MAX(計算用!$Q$2,計算用!$Q$3),ROW()-3,"") | B12: =IFERROR(INDEX(計算用!$D$2:$D$186,MATCH("男赤"&$A12,計算用!$L$2:$L$186,0)),"") | C12: =IFERROR(INDEX(計算用!$M$2:$M$186,MATCH("男赤"&$A12,計算用!$L$2:$L$186,0)),"") | D12: =IFERROR(INDEX(計算用!$G$2:$G$186,MATCH("男赤"&$A12,計算用!$L$2:$L$186,0)),"") | F12: =IFERROR(INDEX(計算用!$D$2:$D$186,MATCH("男白"&$A12,計算用!$L$2:$L$186,0)),"") | G12: =IFERROR(INDEX(計算用!$M$2:$M$186,MATCH("男白"&$A12,計算用!$L$2:$L$186,0)),"") | H12: =IFERROR(INDEX(計算用!$G$2:$G$186,MATCH("男白"&$A12,計算用!$L$2:$L$186,0)),"") | J12: =IF(ROW()-3<=MAX(計算用!$Q$4,計算用!$Q$5),ROW()-3,"") | K12: =IFERROR(INDEX(計算用!$D$2:$D$186,MATCH("女赤"&$J12,計算用!$L$2:$L$186,0)),"") | L12: =IFERROR(INDEX(計算用!$M$2:$M$186,MATCH("女赤"&$J12,計算用!$L$2:$L$186,0)),"") | M12: =IFERROR(INDEX(計算用!$G$2:$G$186,MATCH("女赤"&$J12,計算用!$L$2:$L$186,0)),"") | O12: =IFERROR(INDEX(計算用!$D$2:$D$186,MATCH("女白"&$J12,計算用!$L$2:$L$186,0)),"") | P12: =IFERROR(INDEX(計算用!$M$2:$M$186,MATCH("女白"&$J12,計算用!$L$2:$L$186,0)),"") | Q12: =IFERROR(INDEX(計算用!$G$2:$G$186,MATCH("女白"&$J12,計算用!$L$2:$L$186,0)),"")
A13: =IF(ROW()-3<=MAX(計算用!$Q$2,計算用!$Q$3),ROW()-3,"") | B13: =IFERROR(INDEX(計算用!$D$2:$D$186,MATCH("男赤"&$A13,計算用!$L$2:$L$186,0)),"") | C13: =IFERROR(INDEX(計算用!$M$2:$M$186,MATCH("男赤"&$A13,計算用!$L$2:$L$186,0)),"") | D13: =IFERROR(INDEX(計算用!$G$2:$G$186,MATCH("男赤"&$A13,計算用!$L$2:$L$186,0)),"") | F13: =IFERROR(INDEX(計算用!$D$2:$D$186,MATCH("男白"&$A13,計算用!$L$2:$L$186,0)),"") | G13: =IFERROR(INDEX(計算用!$M$2:$M$186,MATCH("男白"&$A13,計算用!$L$2:$L$186,0)),"") | H13: =IFERROR(INDEX(計算用!$G$2:$G$186,MATCH("男白"&$A13,計算用!$L$2:$L$186,0)),"") | J13: =IF(ROW()-3<=MAX(計算用!$Q$4,計算用!$Q$5),ROW()-3,"") | K13: =IFERROR(INDEX(計算用!$D$2:$D$186,MATCH("女赤"&$J13,計算用!$L$2:$L$186,0)),"") | L13: =IFERROR(INDEX(計算用!$M$2:$M$186,MATCH("女赤"&$J13,計算用!$L$2:$L$186,0)),"") | M13: =IFERROR(INDEX(計算用!$G$2:$G$186,MATCH("女赤"&$J13,計算用!$L$2:$L$186,0)),"") | O13: =IFERROR(INDEX(計算用!$D$2:$D$186,MATCH("女白"&$J13,計算用!$L$2:$L$186,0)),"") | P13: =IFERROR(INDEX(計算用!$M$2:$M$186,MATCH("女白"&$J13,計算用!$L$2:$L$186,0)),"") | Q13: =IFERROR(INDEX(計算用!$G$2:$G$186,MATCH("女白"&$J13,計算用!$L$2:$L$186,0)),"")
A14: =IF(ROW()-3<=MAX(計算用!$Q$2,計算用!$Q$3),ROW()-3,"") | B14: =IFERROR(INDEX(計算用!$D$2:$D$186,MATCH("男赤"&$A14,計算用!$L$2:$L$186,0)),"") | C14: =IFERROR(INDEX(計算用!$M$2:$M$186,MATCH("男赤"&$A14,計算用!$L$2:$L$186,0)),"") | D14: =IFERROR(INDEX(計算用!$G$2:$G$186,MATCH("男赤"&$A14,計算用!$L$2:$L$186,0)),"") | F14: =IFERROR(INDEX(計算用!$D$2:$D$186,MATCH("男白"&$A14,計算用!$L$2:$L$186,0)),"") | G14: =IFERROR(INDEX(計算用!$M$2:$M$186,MATCH("男白"&$A14,計算用!$L$2:$L$186,0)),"") | H14: =IFERROR(INDEX(計算用!$G$2:$G$186,MATCH("男白"&$A14,計算用!$L$2:$L$186,0)),"") | J14: =IF(ROW()-3<=MAX(計算用!$Q$4,計算用!$Q$5),ROW()-3,"") | K14: =IFERROR(INDEX(計算用!$D$2:$D$186,MATCH("女赤"&$J14,計算用!$L$2:$L$186,0)),"") | L14: =IFERROR(INDEX(計算用!$M$2:$M$186,MATCH("女赤"&$J14,計算用!$L$2:$L$186,0)),"") | M14: =IFERROR(INDEX(計算用!$G$2:$G$186,MATCH("女赤"&$J14,計算用!$L$2:$L$186,0)),"") | O14: =IFERROR(INDEX(計算用!$D$2:$D$186,MATCH("女白"&$J14,計算用!$L$2:$L$186,0)),"") | P14: =IFERROR(INDEX(計算用!$M$2:$M$186,MATCH("女白"&$J14,計算用!$L$2:$L$186,0)),"") | Q14: =IFERROR(INDEX(計算用!$G$2:$G$186,MATCH("女白"&$J14,計算用!$L$2:$L$186,0)),"")
A15: =IF(ROW()-3<=MAX(計算用!$Q$2,計算用!$Q$3),ROW()-3,"") | B15: =IFERROR(INDEX(計算用!$D$2:$D$186,MATCH("男赤"&$A15,計算用!$L$2:$L$186,0)),"") | C15: =IFERROR(INDEX(計算用!$M$2:$M$186,MATCH("男赤"&$A15,計算用!$L$2:$L$186,0)),"") | D15: =IFERROR(INDEX(計算用!$G$2:$G$186,MATCH("男赤"&$A15,計算用!$L$2:$L$186,0)),"") | F15: =IFERROR(INDEX(計算用!$D$2:$D$186,MATCH("男白"&$A15,計算用!$L$2:$L$186,0)),"") | G15: =IFERROR(INDEX(計算用!$M$2:$M$186,MATCH("男白"&$A15,計算用!$L$2:$L$186,0)),"") | H15: =IFERROR(INDEX(計算用!$G$2:$G$186,MATCH("男白"&$A15,計算用!$L$2:$L$186,0)),"") | J15: =IF(ROW()-3<=MAX(計算用!$Q$4,計算用!$Q$5),ROW()-3,"") | K15: =IFERROR(INDEX(計算用!$D$2:$D$186,MATCH("女赤"&$J15,計算用!$L$2:$L$186,0)),"") | L15: =IFERROR(INDEX(計算用!$M$2:$M$186,MATCH("女赤"&$J15,計算用!$L$2:$L$186,0)),"") | M15: =IFERROR(INDEX(計算用!$G$2:$G$186,MATCH("女赤"&$J15,計算用!$L$2:$L$186,0)),"") | O15: =IFERROR(INDEX(計算用!$D$2:$D$186,MATCH("女白"&$J15,計算用!$L$2:$L$186,0)),"") | P15: =IFERROR(INDEX(計算用!$M$2:$M$186,MATCH("女白"&$J15,計算用!$L$2:$L$186,0)),"") | Q15: =IFERROR(INDEX(計算用!$G$2:$G$186,MATCH("女白"&$J15,計算用!$L$2:$L$186,0)),"")
... A188: =IF(ROW()-3<=MAX(計算用!$Q$2,計算用!$Q$3),ROW()-3,"") | B188: =IFERROR(INDEX(計算用!$D$2:$D$186,MATCH("男赤"&$A188,計算用!$L$2:$L$186,0)),"") | C188: =IFERROR(INDEX(計算用!$M$2:$M$186,MATCH("男赤"&$A188,計算用!$L$2:$L$186,0)),"") | D188: =IFERROR(INDEX(計算用!$G$2:$G$186,MATCH("男赤"&$A188,計算用!$L$2:$L$186,0)),"") | F188: =IFERROR(INDEX(計算用!$D$2:$D$186,MATCH("男白"&$A188,計算用!$L$2:$L$186,0)),"") | G188: =IFERROR(INDEX(計算用!$M$2:$M$186,MATCH("男白"&$A188,計算用!$L$2:$L$186,0)),"") | H188: =IFERROR(INDEX(計算用!$G$2:$G$186,MATCH("男白"&$A188,計算用!$L$2:$L$186,0)),"") | J188: =IF(ROW()-3<=MAX(計算用!$Q$4,計算用!$Q$5),ROW()-3,"") | K188: =IFERROR(INDEX(計算用!$D$2:$D$186,MATCH("女赤"&$J188,計算用!$L$2:$L$186,0)),"") | L188: =IFERROR(INDEX(計算用!$M$2:$M$186,MATCH("女赤"&$J188,計算用!$L$2:$L$186,0)),"") | M188: =IFERROR(INDEX(計算用!$G$2:$G$186,MATCH("女赤"&$J188,計算用!$L$2:$L$186,0)),"") | O188: =IFERROR(INDEX(計算用!$D$2:$D$186,MATCH("女白"&$J188,計算用!$L$2:$L$186,0)),"") | P188: =IFERROR(INDEX(計算用!$M$2:$M$186,MATCH("女白"&$J188,計算用!$L$2:$L$186,0)),"") | Q188: =IFERROR(INDEX(計算用!$G$2:$G$186,MATCH("女白"&$J188,計算用!$L$2:$L$186,0)),"")

Sheet 4人組
A1: 男子 | D1: =IF(SUMPRODUCT((計算用!$T$2:$T$51>0)*(((計算用!$T$2:$T$51<>4)+(計算用!$W$2:$W$51<>2))>0))>0,"※黄色の組は、人数の都合で調整した組です","") | Q1: 女子 | T1: =IF(SUMPRODUCT((計算用!$AC$2:$AC$51>0)*(((計算用!$AC$2:$AC$51<>4)+(計算用!$AF$2:$AF$51<>2))>0))>0,"※黄色の組は、人数の都合で調整した組です","")
A2: 組 | B2: 人数 | C2: 内訳 | D2: 1人目 | G2: 2人目 | J2: 3人目 | M2: 4人目 | Q2: 組 | R2: 人数 | S2: 内訳 | T2: 1人目 | W2: 2人目 | Z2: 3人目 | AC2: 4人目
D3: 名前 | E3: クラス | F3: 色 | G3: 名前 | H3: クラス | I3: 色 | J3: 名前 | K3: クラス | L3: 色 | M3: 名前 | N3: クラス | O3: 色 | T3: 名前 | U3: クラス | V3: 色 | W3: 名前 | X3: クラス | Y3: 色 | Z3: 名前 | AA3: クラス | AB3: 色 | AC3: 名前 | AD3: クラス | AE3: 色
A4: =IF(ROW()-3<=計算用!$Q$9,ROW()-3,"") | B4: =IF($A4="","",INDEX(計算用!$T$2:$T$51,$A4)) | C4: =IF($A4="","","赤"&INDEX(計算用!$W$2:$W$51,$A4)&"白"&INDEX(計算用!$X$2:$X$51,$A4)) | D4: =IF($A4="","",IFERROR(INDEX(計算用!$D$2:$D$186,MATCH("男"&$A4&"-1",計算用!$AN$2:$AN$186,0)),"")) | E4: =IF($A4="","",IFERROR(INDEX(計算用!$M$2:$M$186,MATCH("男"&$A4&"-1",計算用!$AN$2:$AN$186,0)),"")) | F4: =IF($A4="","",IFERROR(INDEX(計算用!$I$2:$I$186,MATCH("男"&$A4&"-1",計算用!$AN$2:$AN$186,0)),"")) | G4: =IF($A4="","",IFERROR(INDEX(計算用!$D$2:$D$186,MATCH("男"&$A4&"-2",計算用!$AN$2:$AN$186,0)),"")) | H4: =IF($A4="","",IFERROR(INDEX(計算用!$M$2:$M$186,MATCH("男"&$A4&"-2",計算用!$AN$2:$AN$186,0)),"")) | I4: =IF($A4="","",IFERROR(INDEX(計算用!$I$2:$I$186,MATCH("男"&$A4&"-2",計算用!$AN$2:$AN$186,0)),"")) | J4: =IF($A4="","",IFERROR(INDEX(計算用!$D$2:$D$186,MATCH("男"&$A4&"-3",計算用!$AN$2:$AN$186,0)),"")) | K4: =IF($A4="","",IFERROR(INDEX(計算用!$M$2:$M$186,MATCH("男"&$A4&"-3",計算用!$AN$2:$AN$186,0)),"")) | L4: =IF($A4="","",IFERROR(INDEX(計算用!$I$2:$I$186,MATCH("男"&$A4&"-3",計算用!$AN$2:$AN$186,0)),"")) | M4: =IF($A4="","",IFERROR(INDEX(計算用!$D$2:$D$186,MATCH("男"&$A4&"-4",計算用!$AN$2:$AN$186,0)),"")) | N4: =IF($A4="","",IFERROR(INDEX(計算用!$M$2:$M$186,MATCH("男"&$A4&"-4",計算用!$AN$2:$AN$186,0)),"")) | O4: =IF($A4="","",IFERROR(INDEX(計算用!$I$2:$I$186,MATCH("男"&$A4&"-4",計算用!$AN$2:$AN$186,0)),"")) | Q4: =IF(ROW()-3<=計算用!$Q$11,ROW()-3,"") | R4: =IF($Q4="","",INDEX(計算用!$AC$2:$AC$51,$Q4)) | S4: =IF($Q4="","","赤"&INDEX(計算用!$AF$2:$AF$51,$Q4)&"白"&INDEX(計算用!$AG$2:$AG$51,$Q4)) | T4: =IF($Q4="","",IFERROR(INDEX(計算用!$D$2:$D$186,MATCH("女"&$Q4&"-1",計算用!$AN$2:$AN$186,0)),"")) | U4: =IF($Q4="","",IFERROR(INDEX(計算用!$M$2:$M$186,MATCH("女"&$Q4&"-1",計算用!$AN$2:$AN$186,0)),"")) | V4: =IF($Q4="","",IFERROR(INDEX(計算用!$I$2:$I$186,MATCH("女"&$Q4&"-1",計算用!$AN$2:$AN$186,0)),"")) | W4: =IF($Q4="","",IFERROR(INDEX(計算用!$D$2:$D$186,MATCH("女"&$Q4&"-2",計算用!$AN$2:$AN$186,0)),"")) | X4: =IF($Q4="","",IFERROR(INDEX(計算用!$M$2:$M$186,MATCH("女"&$Q4&"-2",計算用!$AN$2:$AN$186,0)),"")) | Y4: =IF($Q4="","",IFERROR(INDEX(計算用!$I$2:$I$186,MATCH("女"&$Q4&"-2",計算用!$AN$2:$AN$186,0)),"")) | Z4: =IF($Q4="","",IFERROR(INDEX(計算用!$D$2:$D$186,MATCH("女"&$Q4&"-3",計算用!$AN$2:$AN$186,0)),"")) | AA4: =IF($Q4="","",IFERROR(INDEX(計算用!$M$2:$M$186,MATCH("女"&$Q4&"-3",計算用!$AN$2:$AN$186,0)),"")) | AB4: =IF($Q4="","",IFERROR(INDEX(計算用!$I$2:$I$186,MATCH("女"&$Q4&"-3",計算用!$AN$2:$AN$186,0)),"")) | AC4: =IF($Q4="","",IFERROR(INDEX(計算用!$D$2:$D$186,MATCH("女"&$Q4&"-4",計算用!$AN$2:$AN$186,0)),"")) | AD4: =IF($Q4="","",IFERROR(INDEX(計算用!$M$2:$M$186,MATCH("女"&$Q4&"-4",計算用!$AN$2:$AN$186,0)),"")) | AE4: =IF($Q4="","",IFERROR(INDEX(計算用!$I$2:$I$186,MATCH("女"&$Q4&"-4",計算用!$AN$2:$AN$186,0)),""))
A5: =IF(ROW()-3<=計算用!$Q$9,ROW()-3,"") | B5: =IF($A5="","",INDEX(計算用!$T$2:$T$51,$A5)) | C5: =IF($A5="","","赤"&INDEX(計算用!$W$2:$W$51,$A5)&"白"&INDEX(計算用!$X$2:$X$51,$A5)) | D5: =IF($A5="","",IFERROR(INDEX(計算用!$D$2:$D$186,MATCH("男"&$A5&"-1",計算用!$AN$2:$AN$186,0)),"")) | E5: =IF($A5="","",IFERROR(INDEX(計算用!$M$2:$M$186,MATCH("男"&$A5&"-1",計算用!$AN$2:$AN$186,0)),"")) | F5: =IF($A5="","",IFERROR(INDEX(計算用!$I$2:$I$186,MATCH("男"&$A5&"-1",計算用!$AN$2:$AN$186,0)),"")) | G5: =IF($A5="","",IFERROR(INDEX(計算用!$D$2:$D$186,MATCH("男"&$A5&"-2",計算用!$AN$2:$AN$186,0)),"")) | H5: =IF($A5="","",IFERROR(INDEX(計算用!$M$2:$M$186,MATCH("男"&$A5&"-2",計算用!$AN$2:$AN$186,0)),"")) | I5: =IF($A5="","",IFERROR(INDEX(計算用!$I$2:$I$186,MATCH("男"&$A5&"-2",計算用!$AN$2:$AN$186,0)),"")) | J5: =IF($A5="","",IFERROR(INDEX(計算用!$D$2:$D$186,MATCH("男"&$A5&"-3",計算用!$AN$2:$AN$186,0)),"")) | K5: =IF($A5="","",IFERROR(INDEX(計算用!$M$2:$M$186,MATCH("男"&$A5&"-3",計算用!$AN$2:$AN$186,0)),"")) | L5: =IF($A5="","",IFERROR(INDEX(計算用!$I$2:$I$186,MATCH("男"&$A5&"-3",計算用!$AN$2:$AN$186,0)),"")) | M5: =IF($A5="","",IFERROR(INDEX(計算用!$D$2:$D$186,MATCH("男"&$A5&"-4",計算用!$AN$2:$AN$186,0)),"")) | N5: =IF($A5="","",IFERROR(INDEX(計算用!$M$2:$M$186,MATCH("男"&$A5&"-4",計算用!$AN$2:$AN$186,0)),"")) | O5: =IF($A5="","",IFERROR(INDEX(計算用!$I$2:$I$186,MATCH("男"&$A5&"-4",計算用!$AN$2:$AN$186,0)),"")) | Q5: =IF(ROW()-3<=計算用!$Q$11,ROW()-3,"") | R5: =IF($Q5="","",INDEX(計算用!$AC$2:$AC$51,$Q5)) | S5: =IF($Q5="","","赤"&INDEX(計算用!$AF$2:$AF$51,$Q5)&"白"&INDEX(計算用!$AG$2:$AG$51,$Q5)) | T5: =IF($Q5="","",IFERROR(INDEX(計算用!$D$2:$D$186,MATCH("女"&$Q5&"-1",計算用!$AN$2:$AN$186,0)),"")) | U5: =IF($Q5="","",IFERROR(INDEX(計算用!$M$2:$M$186,MATCH("女"&$Q5&"-1",計算用!$AN$2:$AN$186,0)),"")) | V5: =IF($Q5="","",IFERROR(INDEX(計算用!$I$2:$I$186,MATCH("女"&$Q5&"-1",計算用!$AN$2:$AN$186,0)),"")) | W5: =IF($Q5="","",IFERROR(INDEX(計算用!$D$2:$D$186,MATCH("女"&$Q5&"-2",計算用!$AN$2:$AN$186,0)),"")) | X5: =IF($Q5="","",IFERROR(INDEX(計算用!$M$2:$M$186,MATCH("女"&$Q5&"-2",計算用!$AN$2:$AN$186,0)),"")) | Y5: =IF($Q5="","",IFERROR(INDEX(計算用!$I$2:$I$186,MATCH("女"&$Q5&"-2",計算用!$AN$2:$AN$186,0)),"")) | Z5: =IF($Q5="","",IFERROR(INDEX(計算用!$D$2:$D$186,MATCH("女"&$Q5&"-3",計算用!$AN$2:$AN$186,0)),"")) | AA5: =IF($Q5="","",IFERROR(INDEX(計算用!$M$2:$M$186,MATCH("女"&$Q5&"-3",計算用!$AN$2:$AN$186,0)),"")) | AB5: =IF($Q5="","",IFERROR(INDEX(計算用!$I$2:$I$186,MATCH("女"&$Q5&"-3",計算用!$AN$2:$AN$186,0)),"")) | AC5: =IF($Q5="","",IFERROR(INDEX(計算用!$D$2:$D$186,MATCH("女"&$Q5&"-4",計算用!$AN$2:$AN$186,0)),"")) | AD5: =IF($Q5="","",IFERROR(INDEX(計算用!$M$2:$M$186,MATCH("女"&$Q5&"-4",計算用!$AN$2:$AN$186,0)),"")) | AE5: =IF($Q5="","",IFERROR(INDEX(計算用!$I$2:$I$186,MATCH("女"&$Q5&"-4",計算用!$AN$2:$AN$186,0)),""))
A6: =IF(ROW()-3<=計算用!$Q$9,ROW()-3,"") | B6: =IF($A6="","",INDEX(計算用!$T$2:$T$51,$A6)) | C6: =IF($A6="","","赤"&INDEX(計算用!$W$2:$W$51,$A6)&"白"&INDEX(計算用!$X$2:$X$51,$A6)) | D6: =IF($A6="","",IFERROR(INDEX(計算用!$D$2:$D$186,MATCH("男"&$A6&"-1",計算用!$AN$2:$AN$186,0)),"")) | E6: =IF($A6="","",IFERROR(INDEX(計算用!$M$2:$M$186,MATCH("男"&$A6&"-1",計算用!$AN$2:$AN$186,0)),"")) | F6: =IF($A6="","",IFERROR(INDEX(計算用!$I$2:$I$186,MATCH("男"&$A6&"-1",計算用!$AN$2:$AN$186,0)),"")) | G6: =IF($A6="","",IFERROR(INDEX(計算用!$D$2:$D$186,MATCH("男"&$A6&"-2",計算用!$AN$2:$AN$186,0)),"")) | H6: =IF($A6="","",IFERROR(INDEX(計算用!$M$2:$M$186,MATCH("男"&$A6&"-2",計算用!$AN$2:$AN$186,0)),"")) | I6: =IF($A6="","",IFERROR(INDEX(計算用!$I$2:$I$186,MATCH("男"&$A6&"-2",計算用!$AN$2:$AN$186,0)),"")) | J6: =IF($A6="","",IFERROR(INDEX(計算用!$D$2:$D$186,MATCH("男"&$A6&"-3",計算用!$AN$2:$AN$186,0)),"")) | K6: =IF($A6="","",IFERROR(INDEX(計算用!$M$2:$M$186,MATCH("男"&$A6&"-3",計算用!$AN$2:$AN$186,0)),"")) | L6: =IF($A6="","",IFERROR(INDEX(計算用!$I$2:$I$186,MATCH("男"&$A6&"-3",計算用!$AN$2:$AN$186,0)),"")) | M6: =IF($A6="","",IFERROR(INDEX(計算用!$D$2:$D$186,MATCH("男"&$A6&"-4",計算用!$AN$2:$AN$186,0)),"")) | N6: =IF($A6="","",IFERROR(INDEX(計算用!$M$2:$M$186,MATCH("男"&$A6&"-4",計算用!$AN$2:$AN$186,0)),"")) | O6: =IF($A6="","",IFERROR(INDEX(計算用!$I$2:$I$186,MATCH("男"&$A6&"-4",計算用!$AN$2:$AN$186,0)),"")) | Q6: =IF(ROW()-3<=計算用!$Q$11,ROW()-3,"") | R6: =IF($Q6="","",INDEX(計算用!$AC$2:$AC$51,$Q6)) | S6: =IF($Q6="","","赤"&INDEX(計算用!$AF$2:$AF$51,$Q6)&"白"&INDEX(計算用!$AG$2:$AG$51,$Q6)) | T6: =IF($Q6="","",IFERROR(INDEX(計算用!$D$2:$D$186,MATCH("女"&$Q6&"-1",計算用!$AN$2:$AN$186,0)),"")) | U6: =IF($Q6="","",IFERROR(INDEX(計算用!$M$2:$M$186,MATCH("女"&$Q6&"-1",計算用!$AN$2:$AN$186,0)),"")) | V6: =IF($Q6="","",IFERROR(INDEX(計算用!$I$2:$I$186,MATCH("女"&$Q6&"-1",計算用!$AN$2:$AN$186,0)),"")) | W6: =IF($Q6="","",IFERROR(INDEX(計算用!$D$2:$D$186,MATCH("女"&$Q6&"-2",計算用!$AN$2:$AN$186,0)),"")) | X6: =IF($Q6="","",IFERROR(INDEX(計算用!$M$2:$M$186,MATCH("女"&$Q6&"-2",計算用!$AN$2:$AN$186,0)),"")) | Y6: =IF($Q6="","",IFERROR(INDEX(計算用!$I$2:$I$186,MATCH("女"&$Q6&"-2",計算用!$AN$2:$AN$186,0)),"")) | Z6: =IF($Q6="","",IFERROR(INDEX(計算用!$D$2:$D$186,MATCH("女"&$Q6&"-3",計算用!$AN$2:$AN$186,0)),"")) | AA6: =IF($Q6="","",IFERROR(INDEX(計算用!$M$2:$M$186,MATCH("女"&$Q6&"-3",計算用!$AN$2:$AN$186,0)),"")) | AB6: =IF($Q6="","",IFERROR(INDEX(計算用!$I$2:$I$186,MATCH("女"&$Q6&"-3",計算用!$AN$2:$AN$186,0)),"")) | AC6: =IF($Q6="","",IFERROR(INDEX(計算用!$D$2:$D$186,MATCH("女"&$Q6&"-4",計算用!$AN$2:$AN$186,0)),"")) | AD6: =IF($Q6="","",IFERROR(INDEX(計算用!$M$2:$M$186,MATCH("女"&$Q6&"-4",計算用!$AN$2:$AN$186,0)),"")) | AE6: =IF($Q6="","",IFERROR(INDEX(計算用!$I$2:$I$186,MATCH("女"&$Q6&"-4",計算用!$AN$2:$AN$186,0)),""))
A7: =IF(ROW()-3<=計算用!$Q$9,ROW()-3,"") | B7: =IF($A7="","",INDEX(計算用!$T$2:$T$51,$A7)) | C7: =IF($A7="","","赤"&INDEX(計算用!$W$2:$W$51,$A7)&"白"&INDEX(計算用!$X$2:$X$51,$A7)) | D7: =IF($A7="","",IFERROR(INDEX(計算用!$D$2:$D$186,MATCH("男"&$A7&"-1",計算用!$AN$2:$AN$186,0)),"")) | E7: =IF($A7="","",IFERROR(INDEX(計算用!$M$2:$M$186,MATCH("男"&$A7&"-1",計算用!$AN$2:$AN$186,0)),"")) | F7: =IF($A7="","",IFERROR(INDEX(計算用!$I$2:$I$186,MATCH("男"&$A7&"-1",計算用!$AN$2:$AN$186,0)),"")) | G7: =IF($A7="","",IFERROR(INDEX(計算用!$D$2:$D$186,MATCH("男"&$A7&"-2",計算用!$AN$2:$AN$186,0)),"")) | H7: =IF($A7="","",IFERROR(INDEX(計算用!$M$2:$M$186,MATCH("男"&$A7&"-2",計算用!$AN$2:$AN$186,0)),"")) | I7: =IF($A7="","",IFERROR(INDEX(計算用!$I$2:$I$186,MATCH("男"&$A7&"-2",計算用!$AN$2:$AN$186,0)),"")) | J7: =IF($A7="","",IFERROR(INDEX(計算用!$D$2:$D$186,MATCH("男"&$A7&"-3",計算用!$AN$2:$AN$186,0)),"")) | K7: =IF($A7="","",IFERROR(INDEX(計算用!$M$2:$M$186,MATCH("男"&$A7&"-3",計算用!$AN$2:$AN$186,0)),"")) | L7: =IF($A7="","",IFERROR(INDEX(計算用!$I$2:$I$186,MATCH("男"&$A7&"-3",計算用!$AN$2:$AN$186,0)),"")) | M7: =IF($A7="","",IFERROR(INDEX(計算用!$D$2:$D$186,MATCH("男"&$A7&"-4",計算用!$AN$2:$AN$186,0)),"")) | N7: =IF($A7="","",IFERROR(INDEX(計算用!$M$2:$M$186,MATCH("男"&$A7&"-4",計算用!$AN$2:$AN$186,0)),"")) | O7: =IF($A7="","",IFERROR(INDEX(計算用!$I$2:$I$186,MATCH("男"&$A7&"-4",計算用!$AN$2:$AN$186,0)),"")) | Q7: =IF(ROW()-3<=計算用!$Q$11,ROW()-3,"") | R7: =IF($Q7="","",INDEX(計算用!$AC$2:$AC$51,$Q7)) | S7: =IF($Q7="","","赤"&INDEX(計算用!$AF$2:$AF$51,$Q7)&"白"&INDEX(計算用!$AG$2:$AG$51,$Q7)) | T7: =IF($Q7="","",IFERROR(INDEX(計算用!$D$2:$D$186,MATCH("女"&$Q7&"-1",計算用!$AN$2:$AN$186,0)),"")) | U7: =IF($Q7="","",IFERROR(INDEX(計算用!$M$2:$M$186,MATCH("女"&$Q7&"-1",計算用!$AN$2:$AN$186,0)),"")) | V7: =IF($Q7="","",IFERROR(INDEX(計算用!$I$2:$I$186,MATCH("女"&$Q7&"-1",計算用!$AN$2:$AN$186,0)),"")) | W7: =IF($Q7="","",IFERROR(INDEX(計算用!$D$2:$D$186,MATCH("女"&$Q7&"-2",計算用!$AN$2:$AN$186,0)),"")) | X7: =IF($Q7="","",IFERROR(INDEX(計算用!$M$2:$M$186,MATCH("女"&$Q7&"-2",計算用!$AN$2:$AN$186,0)),"")) | Y7: =IF($Q7="","",IFERROR(INDEX(計算用!$I$2:$I$186,MATCH("女"&$Q7&"-2",計算用!$AN$2:$AN$186,0)),"")) | Z7: =IF($Q7="","",IFERROR(INDEX(計算用!$D$2:$D$186,MATCH("女"&$Q7&"-3",計算用!$AN$2:$AN$186,0)),"")) | AA7: =IF($Q7="","",IFERROR(INDEX(計算用!$M$2:$M$186,MATCH("女"&$Q7&"-3",計算用!$AN$2:$AN$186,0)),"")) | AB7: =IF($Q7="","",IFERROR(INDEX(計算用!$I$2:$I$186,MATCH("女"&$Q7&"-3",計算用!$AN$2:$AN$186,0)),"")) | AC7: =IF($Q7="","",IFERROR(INDEX(計算用!$D$2:$D$186,MATCH("女"&$Q7&"-4",計算用!$AN$2:$AN$186,0)),"")) | AD7: =IF($Q7="","",IFERROR(INDEX(計算用!$M$2:$M$186,MATCH("女"&$Q7&"-4",計算用!$AN$2:$AN$186,0)),"")) | AE7: =IF($Q7="","",IFERROR(INDEX(計算用!$I$2:$I$186,MATCH("女"&$Q7&"-4",計算用!$AN$2:$AN$186,0)),""))
A8: =IF(ROW()-3<=計算用!$Q$9,ROW()-3,"") | B8: =IF($A8="","",INDEX(計算用!$T$2:$T$51,$A8)) | C8: =IF($A8="","","赤"&INDEX(計算用!$W$2:$W$51,$A8)&"白"&INDEX(計算用!$X$2:$X$51,$A8)) | D8: =IF($A8="","",IFERROR(INDEX(計算用!$D$2:$D$186,MATCH("男"&$A8&"-1",計算用!$AN$2:$AN$186,0)),"")) | E8: =IF($A8="","",IFERROR(INDEX(計算用!$M$2:$M$186,MATCH("男"&$A8&"-1",計算用!$AN$2:$AN$186,0)),"")) | F8: =IF($A8="","",IFERROR(INDEX(計算用!$I$2:$I$186,MATCH("男"&$A8&"-1",計算用!$AN$2:$AN$186,0)),"")) | G8: =IF($A8="","",IFERROR(INDEX(計算用!$D$2:$D$186,MATCH("男"&$A8&"-2",計算用!$AN$2:$AN$186,0)),"")) | H8: =IF($A8="","",IFERROR(INDEX(計算用!$M$2:$M$186,MATCH("男"&$A8&"-2",計算用!$AN$2:$AN$186,0)),"")) | I8: =IF($A8="","",IFERROR(INDEX(計算用!$I$2:$I$186,MATCH("男"&$A8&"-2",計算用!$AN$2:$AN$186,0)),"")) | J8: =IF($A8="","",IFERROR(INDEX(計算用!$D$2:$D$186,MATCH("男"&$A8&"-3",計算用!$AN$2:$AN$186,0)),"")) | K8: =IF($A8="","",IFERROR(INDEX(計算用!$M$2:$M$186,MATCH("男"&$A8&"-3",計算用!$AN$2:$AN$186,0)),"")) | L8: =IF($A8="","",IFERROR(INDEX(計算用!$I$2:$I$186,MATCH("男"&$A8&"-3",計算用!$AN$2:$AN$186,0)),"")) | M8: =IF($A8="","",IFERROR(INDEX(計算用!$D$2:$D$186,MATCH("男"&$A8&"-4",計算用!$AN$2:$AN$186,0)),"")) | N8: =IF($A8="","",IFERROR(INDEX(計算用!$M$2:$M$186,MATCH("男"&$A8&"-4",計算用!$AN$2:$AN$186,0)),"")) | O8: =IF($A8="","",IFERROR(INDEX(計算用!$I$2:$I$186,MATCH("男"&$A8&"-4",計算用!$AN$2:$AN$186,0)),"")) | Q8: =IF(ROW()-3<=計算用!$Q$11,ROW()-3,"") | R8: =IF($Q8="","",INDEX(計算用!$AC$2:$AC$51,$Q8)) | S8: =IF($Q8="","","赤"&INDEX(計算用!$AF$2:$AF$51,$Q8)&"白"&INDEX(計算用!$AG$2:$AG$51,$Q8)) | T8: =IF($Q8="","",IFERROR(INDEX(計算用!$D$2:$D$186,MATCH("女"&$Q8&"-1",計算用!$AN$2:$AN$186,0)),"")) | U8: =IF($Q8="","",IFERROR(INDEX(計算用!$M$2:$M$186,MATCH("女"&$Q8&"-1",計算用!$AN$2:$AN$186,0)),"")) | V8: =IF($Q8="","",IFERROR(INDEX(計算用!$I$2:$I$186,MATCH("女"&$Q8&"-1",計算用!$AN$2:$AN$186,0)),"")) | W8: =IF($Q8="","",IFERROR(INDEX(計算用!$D$2:$D$186,MATCH("女"&$Q8&"-2",計算用!$AN$2:$AN$186,0)),"")) | X8: =IF($Q8="","",IFERROR(INDEX(計算用!$M$2:$M$186,MATCH("女"&$Q8&"-2",計算用!$AN$2:$AN$186,0)),"")) | Y8: =IF($Q8="","",IFERROR(INDEX(計算用!$I$2:$I$186,MATCH("女"&$Q8&"-2",計算用!$AN$2:$AN$186,0)),"")) | Z8: =IF($Q8="","",IFERROR(INDEX(計算用!$D$2:$D$186,MATCH("女"&$Q8&"-3",計算用!$AN$2:$AN$186,0)),"")) | AA8: =IF($Q8="","",IFERROR(INDEX(計算用!$M$2:$M$186,MATCH("女"&$Q8&"-3",計算用!$AN$2:$AN$186,0)),"")) | AB8: =IF($Q8="","",IFERROR(INDEX(計算用!$I$2:$I$186,MATCH("女"&$Q8&"-3",計算用!$AN$2:$AN$186,0)),"")) | AC8: =IF($Q8="","",IFERROR(INDEX(計算用!$D$2:$D$186,MATCH("女"&$Q8&"-4",計算用!$AN$2:$AN$186,0)),"")) | AD8: =IF($Q8="","",IFERROR(INDEX(計算用!$M$2:$M$186,MATCH("女"&$Q8&"-4",計算用!$AN$2:$AN$186,0)),"")) | AE8: =IF($Q8="","",IFERROR(INDEX(計算用!$I$2:$I$186,MATCH("女"&$Q8&"-4",計算用!$AN$2:$AN$186,0)),""))
A9: =IF(ROW()-3<=計算用!$Q$9,ROW()-3,"") | B9: =IF($A9="","",INDEX(計算用!$T$2:$T$51,$A9)) | C9: =IF($A9="","","赤"&INDEX(計算用!$W$2:$W$51,$A9)&"白"&INDEX(計算用!$X$2:$X$51,$A9)) | D9: =IF($A9="","",IFERROR(INDEX(計算用!$D$2:$D$186,MATCH("男"&$A9&"-1",計算用!$AN$2:$AN$186,0)),"")) | E9: =IF($A9="","",IFERROR(INDEX(計算用!$M$2:$M$186,MATCH("男"&$A9&"-1",計算用!$AN$2:$AN$186,0)),"")) | F9: =IF($A9="","",IFERROR(INDEX(計算用!$I$2:$I$186,MATCH("男"&$A9&"-1",計算用!$AN$2:$AN$186,0)),"")) | G9: =IF($A9="","",IFERROR(INDEX(計算用!$D$2:$D$186,MATCH("男"&$A9&"-2",計算用!$AN$2:$AN$186,0)),"")) | H9: =IF($A9="","",IFERROR(INDEX(計算用!$M$2:$M$186,MATCH("男"&$A9&"-2",計算用!$AN$2:$AN$186,0)),"")) | I9: =IF($A9="","",IFERROR(INDEX(計算用!$I$2:$I$186,MATCH("男"&$A9&"-2",計算用!$AN$2:$AN$186,0)),"")) | J9: =IF($A9="","",IFERROR(INDEX(計算用!$D$2:$D$186,MATCH("男"&$A9&"-3",計算用!$AN$2:$AN$186,0)),"")) | K9: =IF($A9="","",IFERROR(INDEX(計算用!$M$2:$M$186,MATCH("男"&$A9&"-3",計算用!$AN$2:$AN$186,0)),"")) | L9: =IF($A9="","",IFERROR(INDEX(計算用!$I$2:$I$186,MATCH("男"&$A9&"-3",計算用!$AN$2:$AN$186,0)),"")) | M9: =IF($A9="","",IFERROR(INDEX(計算用!$D$2:$D$186,MATCH("男"&$A9&"-4",計算用!$AN$2:$AN$186,0)),"")) | N9: =IF($A9="","",IFERROR(INDEX(計算用!$M$2:$M$186,MATCH("男"&$A9&"-4",計算用!$AN$2:$AN$186,0)),"")) | O9: =IF($A9="","",IFERROR(INDEX(計算用!$I$2:$I$186,MATCH("男"&$A9&"-4",計算用!$AN$2:$AN$186,0)),"")) | Q9: =IF(ROW()-3<=計算用!$Q$11,ROW()-3,"") | R9: =IF($Q9="","",INDEX(計算用!$AC$2:$AC$51,$Q9)) | S9: =IF($Q9="","","赤"&INDEX(計算用!$AF$2:$AF$51,$Q9)&"白"&INDEX(計算用!$AG$2:$AG$51,$Q9)) | T9: =IF($Q9="","",IFERROR(INDEX(計算用!$D$2:$D$186,MATCH("女"&$Q9&"-1",計算用!$AN$2:$AN$186,0)),"")) | U9: =IF($Q9="","",IFERROR(INDEX(計算用!$M$2:$M$186,MATCH("女"&$Q9&"-1",計算用!$AN$2:$AN$186,0)),"")) | V9: =IF($Q9="","",IFERROR(INDEX(計算用!$I$2:$I$186,MATCH("女"&$Q9&"-1",計算用!$AN$2:$AN$186,0)),"")) | W9: =IF($Q9="","",IFERROR(INDEX(計算用!$D$2:$D$186,MATCH("女"&$Q9&"-2",計算用!$AN$2:$AN$186,0)),"")) | X9: =IF($Q9="","",IFERROR(INDEX(計算用!$M$2:$M$186,MATCH("女"&$Q9&"-2",計算用!$AN$2:$AN$186,0)),"")) | Y9: =IF($Q9="","",IFERROR(INDEX(計算用!$I$2:$I$186,MATCH("女"&$Q9&"-2",計算用!$AN$2:$AN$186,0)),"")) | Z9: =IF($Q9="","",IFERROR(INDEX(計算用!$D$2:$D$186,MATCH("女"&$Q9&"-3",計算用!$AN$2:$AN$186,0)),"")) | AA9: =IF($Q9="","",IFERROR(INDEX(計算用!$M$2:$M$186,MATCH("女"&$Q9&"-3",計算用!$AN$2:$AN$186,0)),"")) | AB9: =IF($Q9="","",IFERROR(INDEX(計算用!$I$2:$I$186,MATCH("女"&$Q9&"-3",計算用!$AN$2:$AN$186,0)),"")) | AC9: =IF($Q9="","",IFERROR(INDEX(計算用!$D$2:$D$186,MATCH("女"&$Q9&"-4",計算用!$AN$2:$AN$186,0)),"")) | AD9: =IF($Q9="","",IFERROR(INDEX(計算用!$M$2:$M$186,MATCH("女"&$Q9&"-4",計算用!$AN$2:$AN$186,0)),"")) | AE9: =IF($Q9="","",IFERROR(INDEX(計算用!$I$2:$I$186,MATCH("女"&$Q9&"-4",計算用!$AN$2:$AN$186,0)),""))
A10: =IF(ROW()-3<=計算用!$Q$9,ROW()-3,"") | B10: =IF($A10="","",INDEX(計算用!$T$2:$T$51,$A10)) | C10: =IF($A10="","","赤"&INDEX(計算用!$W$2:$W$51,$A10)&"白"&INDEX(計算用!$X$2:$X$51,$A10)) | D10: =IF($A10="","",IFERROR(INDEX(計算用!$D$2:$D$186,MATCH("男"&$A10&"-1",計算用!$AN$2:$AN$186,0)),"")) | E10: =IF($A10="","",IFERROR(INDEX(計算用!$M$2:$M$186,MATCH("男"&$A10&"-1",計算用!$AN$2:$AN$186,0)),"")) | F10: =IF($A10="","",IFERROR(INDEX(計算用!$I$2:$I$186,MATCH("男"&$A10&"-1",計算用!$AN$2:$AN$186,0)),"")) | G10: =IF($A10="","",IFERROR(INDEX(計算用!$D$2:$D$186,MATCH("男"&$A10&"-2",計算用!$AN$2:$AN$186,0)),"")) | H10: =IF($A10="","",IFERROR(INDEX(計算用!$M$2:$M$186,MATCH("男"&$A10&"-2",計算用!$AN$2:$AN$186,0)),"")) | I10: =IF($A10="","",IFERROR(INDEX(計算用!$I$2:$I$186,MATCH("男"&$A10&"-2",計算用!$AN$2:$AN$186,0)),"")) | J10: =IF($A10="","",IFERROR(INDEX(計算用!$D$2:$D$186,MATCH("男"&$A10&"-3",計算用!$AN$2:$AN$186,0)),"")) | K10: =IF($A10="","",IFERROR(INDEX(計算用!$M$2:$M$186,MATCH("男"&$A10&"-3",計算用!$AN$2:$AN$186,0)),"")) | L10: =IF($A10="","",IFERROR(INDEX(計算用!$I$2:$I$186,MATCH("男"&$A10&"-3",計算用!$AN$2:$AN$186,0)),"")) | M10: =IF($A10="","",IFERROR(INDEX(計算用!$D$2:$D$186,MATCH("男"&$A10&"-4",計算用!$AN$2:$AN$186,0)),"")) | N10: =IF($A10="","",IFERROR(INDEX(計算用!$M$2:$M$186,MATCH("男"&$A10&"-4",計算用!$AN$2:$AN$186,0)),"")) | O10: =IF($A10="","",IFERROR(INDEX(計算用!$I$2:$I$186,MATCH("男"&$A10&"-4",計算用!$AN$2:$AN$186,0)),"")) | Q10: =IF(ROW()-3<=計算用!$Q$11,ROW()-3,"") | R10: =IF($Q10="","",INDEX(計算用!$AC$2:$AC$51,$Q10)) | S10: =IF($Q10="","","赤"&INDEX(計算用!$AF$2:$AF$51,$Q10)&"白"&INDEX(計算用!$AG$2:$AG$51,$Q10)) | T10: =IF($Q10="","",IFERROR(INDEX(計算用!$D$2:$D$186,MATCH("女"&$Q10&"-1",計算用!$AN$2:$AN$186,0)),"")) | U10: =IF($Q10="","",IFERROR(INDEX(計算用!$M$2:$M$186,MATCH("女"&$Q10&"-1",計算用!$AN$2:$AN$186,0)),"")) | V10: =IF($Q10="","",IFERROR(INDEX(計算用!$I$2:$I$186,MATCH("女"&$Q10&"-1",計算用!$AN$2:$AN$186,0)),"")) | W10: =IF($Q10="","",IFERROR(INDEX(計算用!$D$2:$D$186,MATCH("女"&$Q10&"-2",計算用!$AN$2:$AN$186,0)),"")) | X10: =IF($Q10="","",IFERROR(INDEX(計算用!$M$2:$M$186,MATCH("女"&$Q10&"-2",計算用!$AN$2:$AN$186,0)),"")) | Y10: =IF($Q10="","",IFERROR(INDEX(計算用!$I$2:$I$186,MATCH("女"&$Q10&"-2",計算用!$AN$2:$AN$186,0)),"")) | Z10: =IF($Q10="","",IFERROR(INDEX(計算用!$D$2:$D$186,MATCH("女"&$Q10&"-3",計算用!$AN$2:$AN$186,0)),"")) | AA10: =IF($Q10="","",IFERROR(INDEX(計算用!$M$2:$M$186,MATCH("女"&$Q10&"-3",計算用!$AN$2:$AN$186,0)),"")) | AB10: =IF($Q10="","",IFERROR(INDEX(計算用!$I$2:$I$186,MATCH("女"&$Q10&"-3",計算用!$AN$2:$AN$186,0)),"")) | AC10: =IF($Q10="","",IFERROR(INDEX(計算用!$D$2:$D$186,MATCH("女"&$Q10&"-4",計算用!$AN$2:$AN$186,0)),"")) | AD10: =IF($Q10="","",IFERROR(INDEX(計算用!$M$2:$M$186,MATCH("女"&$Q10&"-4",計算用!$AN$2:$AN$186,0)),"")) | AE10: =IF($Q10="","",IFERROR(INDEX(計算用!$I$2:$I$186,MATCH("女"&$Q10&"-4",計算用!$AN$2:$AN$186,0)),""))
A11: =IF(ROW()-3<=計算用!$Q$9,ROW()-3,"") | B11: =IF($A11="","",INDEX(計算用!$T$2:$T$51,$A11)) | C11: =IF($A11="","","赤"&INDEX(計算用!$W$2:$W$51,$A11)&"白"&INDEX(計算用!$X$2:$X$51,$A11)) | D11: =IF($A11="","",IFERROR(INDEX(計算用!$D$2:$D$186,MATCH("男"&$A11&"-1",計算用!$AN$2:$AN$186,0)),"")) | E11: =IF($A11="","",IFERROR(INDEX(計算用!$M$2:$M$186,MATCH("男"&$A11&"-1",計算用!$AN$2:$AN$186,0)),"")) | F11: =IF($A11="","",IFERROR(INDEX(計算用!$I$2:$I$186,MATCH("男"&$A11&"-1",計算用!$AN$2:$AN$186,0)),"")) | G11: =IF($A11="","",IFERROR(INDEX(計算用!$D$2:$D$186,MATCH("男"&$A11&"-2",計算用!$AN$2:$AN$186,0)),"")) | H11: =IF($A11="","",IFERROR(INDEX(計算用!$M$2:$M$186,MATCH("男"&$A11&"-2",計算用!$AN$2:$AN$186,0)),"")) | I11: =IF($A11="","",IFERROR(INDEX(計算用!$I$2:$I$186,MATCH("男"&$A11&"-2",計算用!$AN$2:$AN$186,0)),"")) | J11: =IF($A11="","",IFERROR(INDEX(計算用!$D$2:$D$186,MATCH("男"&$A11&"-3",計算用!$AN$2:$AN$186,0)),"")) | K11: =IF($A11="","",IFERROR(INDEX(計算用!$M$2:$M$186,MATCH("男"&$A11&"-3",計算用!$AN$2:$AN$186,0)),"")) | L11: =IF($A11="","",IFERROR(INDEX(計算用!$I$2:$I$186,MATCH("男"&$A11&"-3",計算用!$AN$2:$AN$186,0)),"")) | M11: =IF($A11="","",IFERROR(INDEX(計算用!$D$2:$D$186,MATCH("男"&$A11&"-4",計算用!$AN$2:$AN$186,0)),"")) | N11: =IF($A11="","",IFERROR(INDEX(計算用!$M$2:$M$186,MATCH("男"&$A11&"-4",計算用!$AN$2:$AN$186,0)),"")) | O11: =IF($A11="","",IFERROR(INDEX(計算用!$I$2:$I$186,MATCH("男"&$A11&"-4",計算用!$AN$2:$AN$186,0)),"")) | Q11: =IF(ROW()-3<=計算用!$Q$11,ROW()-3,"") | R11: =IF($Q11="","",INDEX(計算用!$AC$2:$AC$51,$Q11)) | S11: =IF($Q11="","","赤"&INDEX(計算用!$AF$2:$AF$51,$Q11)&"白"&INDEX(計算用!$AG$2:$AG$51,$Q11)) | T11: =IF($Q11="","",IFERROR(INDEX(計算用!$D$2:$D$186,MATCH("女"&$Q11&"-1",計算用!$AN$2:$AN$186,0)),"")) | U11: =IF($Q11="","",IFERROR(INDEX(計算用!$M$2:$M$186,MATCH("女"&$Q11&"-1",計算用!$AN$2:$AN$186,0)),"")) | V11: =IF($Q11="","",IFERROR(INDEX(計算用!$I$2:$I$186,MATCH("女"&$Q11&"-1",計算用!$AN$2:$AN$186,0)),"")) | W11: =IF($Q11="","",IFERROR(INDEX(計算用!$D$2:$D$186,MATCH("女"&$Q11&"-2",計算用!$AN$2:$AN$186,0)),"")) | X11: =IF($Q11="","",IFERROR(INDEX(計算用!$M$2:$M$186,MATCH("女"&$Q11&"-2",計算用!$AN$2:$AN$186,0)),"")) | Y11: =IF($Q11="","",IFERROR(INDEX(計算用!$I$2:$I$186,MATCH("女"&$Q11&"-2",計算用!$AN$2:$AN$186,0)),"")) | Z11: =IF($Q11="","",IFERROR(INDEX(計算用!$D$2:$D$186,MATCH("女"&$Q11&"-3",計算用!$AN$2:$AN$186,0)),"")) | AA11: =IF($Q11="","",IFERROR(INDEX(計算用!$M$2:$M$186,MATCH("女"&$Q11&"-3",計算用!$AN$2:$AN$186,0)),"")) | AB11: =IF($Q11="","",IFERROR(INDEX(計算用!$I$2:$I$186,MATCH("女"&$Q11&"-3",計算用!$AN$2:$AN$186,0)),"")) | AC11: =IF($Q11="","",IFERROR(INDEX(計算用!$D$2:$D$186,MATCH("女"&$Q11&"-4",計算用!$AN$2:$AN$186,0)),"")) | AD11: =IF($Q11="","",IFERROR(INDEX(計算用!$M$2:$M$186,MATCH("女"&$Q11&"-4",計算用!$AN$2:$AN$186,0)),"")) | AE11: =IF($Q11="","",IFERROR(INDEX(計算用!$I$2:$I$186,MATCH("女"&$Q11&"-4",計算用!$AN$2:$AN$186,0)),""))
A12: =IF(ROW()-3<=計算用!$Q$9,ROW()-3,"") | B12: =IF($A12="","",INDEX(計算用!$T$2:$T$51,$A12)) | C12: =IF($A12="","","赤"&INDEX(計算用!$W$2:$W$51,$A12)&"白"&INDEX(計算用!$X$2:$X$51,$A12)) | D12: =IF($A12="","",IFERROR(INDEX(計算用!$D$2:$D$186,MATCH("男"&$A12&"-1",計算用!$AN$2:$AN$186,0)),"")) | E12: =IF($A12="","",IFERROR(INDEX(計算用!$M$2:$M$186,MATCH("男"&$A12&"-1",計算用!$AN$2:$AN$186,0)),"")) | F12: =IF($A12="","",IFERROR(INDEX(計算用!$I$2:$I$186,MATCH("男"&$A12&"-1",計算用!$AN$2:$AN$186,0)),"")) | G12: =IF($A12="","",IFERROR(INDEX(計算用!$D$2:$D$186,MATCH("男"&$A12&"-2",計算用!$AN$2:$AN$186,0)),"")) | H12: =IF($A12="","",IFERROR(INDEX(計算用!$M$2:$M$186,MATCH("男"&$A12&"-2",計算用!$AN$2:$AN$186,0)),"")) | I12: =IF($A12="","",IFERROR(INDEX(計算用!$I$2:$I$186,MATCH("男"&$A12&"-2",計算用!$AN$2:$AN$186,0)),"")) | J12: =IF($A12="","",IFERROR(INDEX(計算用!$D$2:$D$186,MATCH("男"&$A12&"-3",計算用!$AN$2:$AN$186,0)),"")) | K12: =IF($A12="","",IFERROR(INDEX(計算用!$M$2:$M$186,MATCH("男"&$A12&"-3",計算用!$AN$2:$AN$186,0)),"")) | L12: =IF($A12="","",IFERROR(INDEX(計算用!$I$2:$I$186,MATCH("男"&$A12&"-3",計算用!$AN$2:$AN$186,0)),"")) | M12: =IF($A12="","",IFERROR(INDEX(計算用!$D$2:$D$186,MATCH("男"&$A12&"-4",計算用!$AN$2:$AN$186,0)),"")) | N12: =IF($A12="","",IFERROR(INDEX(計算用!$M$2:$M$186,MATCH("男"&$A12&"-4",計算用!$AN$2:$AN$186,0)),"")) | O12: =IF($A12="","",IFERROR(INDEX(計算用!$I$2:$I$186,MATCH("男"&$A12&"-4",計算用!$AN$2:$AN$186,0)),"")) | Q12: =IF(ROW()-3<=計算用!$Q$11,ROW()-3,"") | R12: =IF($Q12="","",INDEX(計算用!$AC$2:$AC$51,$Q12)) | S12: =IF($Q12="","","赤"&INDEX(計算用!$AF$2:$AF$51,$Q12)&"白"&INDEX(計算用!$AG$2:$AG$51,$Q12)) | T12: =IF($Q12="","",IFERROR(INDEX(計算用!$D$2:$D$186,MATCH("女"&$Q12&"-1",計算用!$AN$2:$AN$186,0)),"")) | U12: =IF($Q12="","",IFERROR(INDEX(計算用!$M$2:$M$186,MATCH("女"&$Q12&"-1",計算用!$AN$2:$AN$186,0)),"")) | V12: =IF($Q12="","",IFERROR(INDEX(計算用!$I$2:$I$186,MATCH("女"&$Q12&"-1",計算用!$AN$2:$AN$186,0)),"")) | W12: =IF($Q12="","",IFERROR(INDEX(計算用!$D$2:$D$186,MATCH("女"&$Q12&"-2",計算用!$AN$2:$AN$186,0)),"")) | X12: =IF($Q12="","",IFERROR(INDEX(計算用!$M$2:$M$186,MATCH("女"&$Q12&"-2",計算用!$AN$2:$AN$186,0)),"")) | Y12: =IF($Q12="","",IFERROR(INDEX(計算用!$I$2:$I$186,MATCH("女"&$Q12&"-2",計算用!$AN$2:$AN$186,0)),"")) | Z12: =IF($Q12="","",IFERROR(INDEX(計算用!$D$2:$D$186,MATCH("女"&$Q12&"-3",計算用!$AN$2:$AN$186,0)),"")) | AA12: =IF($Q12="","",IFERROR(INDEX(計算用!$M$2:$M$186,MATCH("女"&$Q12&"-3",計算用!$AN$2:$AN$186,0)),"")) | AB12: =IF($Q12="","",IFERROR(INDEX(計算用!$I$2:$I$186,MATCH("女"&$Q12&"-3",計算用!$AN$2:$AN$186,0)),"")) | AC12: =IF($Q12="","",IFERROR(INDEX(計算用!$D$2:$D$186,MATCH("女"&$Q12&"-4",計算用!$AN$2:$AN$186,0)),"")) | AD12: =IF($Q12="","",IFERROR(INDEX(計算用!$M$2:$M$186,MATCH("女"&$Q12&"-4",計算用!$AN$2:$AN$186,0)),"")) | AE12: =IF($Q12="","",IFERROR(INDEX(計算用!$I$2:$I$186,MATCH("女"&$Q12&"-4",計算用!$AN$2:$AN$186,0)),""))
A13: =IF(ROW()-3<=計算用!$Q$9,ROW()-3,"") | B13: =IF($A13="","",INDEX(計算用!$T$2:$T$51,$A13)) | C13: =IF($A13="","","赤"&INDEX(計算用!$W$2:$W$51,$A13)&"白"&INDEX(計算用!$X$2:$X$51,$A13)) | D13: =IF($A13="","",IFERROR(INDEX(計算用!$D$2:$D$186,MATCH("男"&$A13&"-1",計算用!$AN$2:$AN$186,0)),"")) | E13: =IF($A13="","",IFERROR(INDEX(計算用!$M$2:$M$186,MATCH("男"&$A13&"-1",計算用!$AN$2:$AN$186,0)),"")) | F13: =IF($A13="","",IFERROR(INDEX(計算用!$I$2:$I$186,MATCH("男"&$A13&"-1",計算用!$AN$2:$AN$186,0)),"")) | G13: =IF($A13="","",IFERROR(INDEX(計算用!$D$2:$D$186,MATCH("男"&$A13&"-2",計算用!$AN$2:$AN$186,0)),"")) | H13: =IF($A13="","",IFERROR(INDEX(計算用!$M$2:$M$186,MATCH("男"&$A13&"-2",計算用!$AN$2:$AN$186,0)),"")) | I13: =IF($A13="","",IFERROR(INDEX(計算用!$I$2:$I$186,MATCH("男"&$A13&"-2",計算用!$AN$2:$AN$186,0)),"")) | J13: =IF($A13="","",IFERROR(INDEX(計算用!$D$2:$D$186,MATCH("男"&$A13&"-3",計算用!$AN$2:$AN$186,0)),"")) | K13: =IF($A13="","",IFERROR(INDEX(計算用!$M$2:$M$186,MATCH("男"&$A13&"-3",計算用!$AN$2:$AN$186,0)),"")) | L13: =IF($A13="","",IFERROR(INDEX(計算用!$I$2:$I$186,MATCH("男"&$A13&"-3",計算用!$AN$2:$AN$186,0)),"")) | M13: =IF($A13="","",IFERROR(INDEX(計算用!$D$2:$D$186,MATCH("男"&$A13&"-4",計算用!$AN$2:$AN$186,0)),"")) | N13: =IF($A13="","",IFERROR(INDEX(計算用!$M$2:$M$186,MATCH("男"&$A13&"-4",計算用!$AN$2:$AN$186,0)),"")) | O13: =IF($A13="","",IFERROR(INDEX(計算用!$I$2:$I$186,MATCH("男"&$A13&"-4",計算用!$AN$2:$AN$186,0)),"")) | Q13: =IF(ROW()-3<=計算用!$Q$11,ROW()-3,"") | R13: =IF($Q13="","",INDEX(計算用!$AC$2:$AC$51,$Q13)) | S13: =IF($Q13="","","赤"&INDEX(計算用!$AF$2:$AF$51,$Q13)&"白"&INDEX(計算用!$AG$2:$AG$51,$Q13)) | T13: =IF($Q13="","",IFERROR(INDEX(計算用!$D$2:$D$186,MATCH("女"&$Q13&"-1",計算用!$AN$2:$AN$186,0)),"")) | U13: =IF($Q13="","",IFERROR(INDEX(計算用!$M$2:$M$186,MATCH("女"&$Q13&"-1",計算用!$AN$2:$AN$186,0)),"")) | V13: =IF($Q13="","",IFERROR(INDEX(計算用!$I$2:$I$186,MATCH("女"&$Q13&"-1",計算用!$AN$2:$AN$186,0)),"")) | W13: =IF($Q13="","",IFERROR(INDEX(計算用!$D$2:$D$186,MATCH("女"&$Q13&"-2",計算用!$AN$2:$AN$186,0)),"")) | X13: =IF($Q13="","",IFERROR(INDEX(計算用!$M$2:$M$186,MATCH("女"&$Q13&"-2",計算用!$AN$2:$AN$186,0)),"")) | Y13: =IF($Q13="","",IFERROR(INDEX(計算用!$I$2:$I$186,MATCH("女"&$Q13&"-2",計算用!$AN$2:$AN$186,0)),"")) | Z13: =IF($Q13="","",IFERROR(INDEX(計算用!$D$2:$D$186,MATCH("女"&$Q13&"-3",計算用!$AN$2:$AN$186,0)),"")) | AA13: =IF($Q13="","",IFERROR(INDEX(計算用!$M$2:$M$186,MATCH("女"&$Q13&"-3",計算用!$AN$2:$AN$186,0)),"")) | AB13: =IF($Q13="","",IFERROR(INDEX(計算用!$I$2:$I$186,MATCH("女"&$Q13&"-3",計算用!$AN$2:$AN$186,0)),"")) | AC13: =IF($Q13="","",IFERROR(INDEX(計算用!$D$2:$D$186,MATCH("女"&$Q13&"-4",計算用!$AN$2:$AN$186,0)),"")) | AD13: =IF($Q13="","",IFERROR(INDEX(計算用!$M$2:$M$186,MATCH("女"&$Q13&"-4",計算用!$AN$2:$AN$186,0)),"")) | AE13: =IF($Q13="","",IFERROR(INDEX(計算用!$I$2:$I$186,MATCH("女"&$Q13&"-4",計算用!$AN$2:$AN$186,0)),""))
A14: =IF(ROW()-3<=計算用!$Q$9,ROW()-3,"") | B14: =IF($A14="","",INDEX(計算用!$T$2:$T$51,$A14)) | C14: =IF($A14="","","赤"&INDEX(計算用!$W$2:$W$51,$A14)&"白"&INDEX(計算用!$X$2:$X$51,$A14)) | D14: =IF($A14="","",IFERROR(INDEX(計算用!$D$2:$D$186,MATCH("男"&$A14&"-1",計算用!$AN$2:$AN$186,0)),"")) | E14: =IF($A14="","",IFERROR(INDEX(計算用!$M$2:$M$186,MATCH("男"&$A14&"-1",計算用!$AN$2:$AN$186,0)),"")) | F14: =IF($A14="","",IFERROR(INDEX(計算用!$I$2:$I$186,MATCH("男"&$A14&"-1",計算用!$AN$2:$AN$186,0)),"")) | G14: =IF($A14="","",IFERROR(INDEX(計算用!$D$2:$D$186,MATCH("男"&$A14&"-2",計算用!$AN$2:$AN$186,0)),"")) | H14: =IF($A14="","",IFERROR(INDEX(計算用!$M$2:$M$186,MATCH("男"&$A14&"-2",計算用!$AN$2:$AN$186,0)),"")) | I14: =IF($A14="","",IFERROR(INDEX(計算用!$I$2:$I$186,MATCH("男"&$A14&"-2",計算用!$AN$2:$AN$186,0)),"")) | J14: =IF($A14="","",IFERROR(INDEX(計算用!$D$2:$D$186,MATCH("男"&$A14&"-3",計算用!$AN$2:$AN$186,0)),"")) | K14: =IF($A14="","",IFERROR(INDEX(計算用!$M$2:$M$186,MATCH("男"&$A14&"-3",計算用!$AN$2:$AN$186,0)),"")) | L14: =IF($A14="","",IFERROR(INDEX(計算用!$I$2:$I$186,MATCH("男"&$A14&"-3",計算用!$AN$2:$AN$186,0)),"")) | M14: =IF($A14="","",IFERROR(INDEX(計算用!$D$2:$D$186,MATCH("男"&$A14&"-4",計算用!$AN$2:$AN$186,0)),"")) | N14: =IF($A14="","",IFERROR(INDEX(計算用!$M$2:$M$186,MATCH("男"&$A14&"-4",計算用!$AN$2:$AN$186,0)),"")) | O14: =IF($A14="","",IFERROR(INDEX(計算用!$I$2:$I$186,MATCH("男"&$A14&"-4",計算用!$AN$2:$AN$186,0)),"")) | Q14: =IF(ROW()-3<=計算用!$Q$11,ROW()-3,"") | R14: =IF($Q14="","",INDEX(計算用!$AC$2:$AC$51,$Q14)) | S14: =IF($Q14="","","赤"&INDEX(計算用!$AF$2:$AF$51,$Q14)&"白"&INDEX(計算用!$AG$2:$AG$51,$Q14)) | T14: =IF($Q14="","",IFERROR(INDEX(計算用!$D$2:$D$186,MATCH("女"&$Q14&"-1",計算用!$AN$2:$AN$186,0)),"")) | U14: =IF($Q14="","",IFERROR(INDEX(計算用!$M$2:$M$186,MATCH("女"&$Q14&"-1",計算用!$AN$2:$AN$186,0)),"")) | V14: =IF($Q14="","",IFERROR(INDEX(計算用!$I$2:$I$186,MATCH("女"&$Q14&"-1",計算用!$AN$2:$AN$186,0)),"")) | W14: =IF($Q14="","",IFERROR(INDEX(計算用!$D$2:$D$186,MATCH("女"&$Q14&"-2",計算用!$AN$2:$AN$186,0)),"")) | X14: =IF($Q14="","",IFERROR(INDEX(計算用!$M$2:$M$186,MATCH("女"&$Q14&"-2",計算用!$AN$2:$AN$186,0)),"")) | Y14: =IF($Q14="","",IFERROR(INDEX(計算用!$I$2:$I$186,MATCH("女"&$Q14&"-2",計算用!$AN$2:$AN$186,0)),"")) | Z14: =IF($Q14="","",IFERROR(INDEX(計算用!$D$2:$D$186,MATCH("女"&$Q14&"-3",計算用!$AN$2:$AN$186,0)),"")) | AA14: =IF($Q14="","",IFERROR(INDEX(計算用!$M$2:$M$186,MATCH("女"&$Q14&"-3",計算用!$AN$2:$AN$186,0)),"")) | AB14: =IF($Q14="","",IFERROR(INDEX(計算用!$I$2:$I$186,MATCH("女"&$Q14&"-3",計算用!$AN$2:$AN$186,0)),"")) | AC14: =IF($Q14="","",IFERROR(INDEX(計算用!$D$2:$D$186,MATCH("女"&$Q14&"-4",計算用!$AN$2:$AN$186,0)),"")) | AD14: =IF($Q14="","",IFERROR(INDEX(計算用!$M$2:$M$186,MATCH("女"&$Q14&"-4",計算用!$AN$2:$AN$186,0)),"")) | AE14: =IF($Q14="","",IFERROR(INDEX(計算用!$I$2:$I$186,MATCH("女"&$Q14&"-4",計算用!$AN$2:$AN$186,0)),""))
A15: =IF(ROW()-3<=計算用!$Q$9,ROW()-3,"") | B15: =IF($A15="","",INDEX(計算用!$T$2:$T$51,$A15)) | C15: =IF($A15="","","赤"&INDEX(計算用!$W$2:$W$51,$A15)&"白"&INDEX(計算用!$X$2:$X$51,$A15)) | D15: =IF($A15="","",IFERROR(INDEX(計算用!$D$2:$D$186,MATCH("男"&$A15&"-1",計算用!$AN$2:$AN$186,0)),"")) | E15: =IF($A15="","",IFERROR(INDEX(計算用!$M$2:$M$186,MATCH("男"&$A15&"-1",計算用!$AN$2:$AN$186,0)),"")) | F15: =IF($A15="","",IFERROR(INDEX(計算用!$I$2:$I$186,MATCH("男"&$A15&"-1",計算用!$AN$2:$AN$186,0)),"")) | G15: =IF($A15="","",IFERROR(INDEX(計算用!$D$2:$D$186,MATCH("男"&$A15&"-2",計算用!$AN$2:$AN$186,0)),"")) | H15: =IF($A15="","",IFERROR(INDEX(計算用!$M$2:$M$186,MATCH("男"&$A15&"-2",計算用!$AN$2:$AN$186,0)),"")) | I15: =IF($A15="","",IFERROR(INDEX(計算用!$I$2:$I$186,MATCH("男"&$A15&"-2",計算用!$AN$2:$AN$186,0)),"")) | J15: =IF($A15="","",IFERROR(INDEX(計算用!$D$2:$D$186,MATCH("男"&$A15&"-3",計算用!$AN$2:$AN$186,0)),"")) | K15: =IF($A15="","",IFERROR(INDEX(計算用!$M$2:$M$186,MATCH("男"&$A15&"-3",計算用!$AN$2:$AN$186,0)),"")) | L15: =IF($A15="","",IFERROR(INDEX(計算用!$I$2:$I$186,MATCH("男"&$A15&"-3",計算用!$AN$2:$AN$186,0)),"")) | M15: =IF($A15="","",IFERROR(INDEX(計算用!$D$2:$D$186,MATCH("男"&$A15&"-4",計算用!$AN$2:$AN$186,0)),"")) | N15: =IF($A15="","",IFERROR(INDEX(計算用!$M$2:$M$186,MATCH("男"&$A15&"-4",計算用!$AN$2:$AN$186,0)),"")) | O15: =IF($A15="","",IFERROR(INDEX(計算用!$I$2:$I$186,MATCH("男"&$A15&"-4",計算用!$AN$2:$AN$186,0)),"")) | Q15: =IF(ROW()-3<=計算用!$Q$11,ROW()-3,"") | R15: =IF($Q15="","",INDEX(計算用!$AC$2:$AC$51,$Q15)) | S15: =IF($Q15="","","赤"&INDEX(計算用!$AF$2:$AF$51,$Q15)&"白"&INDEX(計算用!$AG$2:$AG$51,$Q15)) | T15: =IF($Q15="","",IFERROR(INDEX(計算用!$D$2:$D$186,MATCH("女"&$Q15&"-1",計算用!$AN$2:$AN$186,0)),"")) | U15: =IF($Q15="","",IFERROR(INDEX(計算用!$M$2:$M$186,MATCH("女"&$Q15&"-1",計算用!$AN$2:$AN$186,0)),"")) | V15: =IF($Q15="","",IFERROR(INDEX(計算用!$I$2:$I$186,MATCH("女"&$Q15&"-1",計算用!$AN$2:$AN$186,0)),"")) | W15: =IF($Q15="","",IFERROR(INDEX(計算用!$D$2:$D$186,MATCH("女"&$Q15&"-2",計算用!$AN$2:$AN$186,0)),"")) | X15: =IF($Q15="","",IFERROR(INDEX(計算用!$M$2:$M$186,MATCH("女"&$Q15&"-2",計算用!$AN$2:$AN$186,0)),"")) | Y15: =IF($Q15="","",IFERROR(INDEX(計算用!$I$2:$I$186,MATCH("女"&$Q15&"-2",計算用!$AN$2:$AN$186,0)),"")) | Z15: =IF($Q15="","",IFERROR(INDEX(計算用!$D$2:$D$186,MATCH("女"&$Q15&"-3",計算用!$AN$2:$AN$186,0)),"")) | AA15: =IF($Q15="","",IFERROR(INDEX(計算用!$M$2:$M$186,MATCH("女"&$Q15&"-3",計算用!$AN$2:$AN$186,0)),"")) | AB15: =IF($Q15="","",IFERROR(INDEX(計算用!$I$2:$I$186,MATCH("女"&$Q15&"-3",計算用!$AN$2:$AN$186,0)),"")) | AC15: =IF($Q15="","",IFERROR(INDEX(計算用!$D$2:$D$186,MATCH("女"&$Q15&"-4",計算用!$AN$2:$AN$186,0)),"")) | AD15: =IF($Q15="","",IFERROR(INDEX(計算用!$M$2:$M$186,MATCH("女"&$Q15&"-4",計算用!$AN$2:$AN$186,0)),"")) | AE15: =IF($Q15="","",IFERROR(INDEX(計算用!$I$2:$I$186,MATCH("女"&$Q15&"-4",計算用!$AN$2:$AN$186,0)),""))
... A53: =IF(ROW()-3<=計算用!$Q$9,ROW()-3,"") | B53: =IF($A53="","",INDEX(計算用!$T$2:$T$51,$A53)) | C53: =IF($A53="","","赤"&INDEX(計算用!$W$2:$W$51,$A53)&"白"&INDEX(計算用!$X$2:$X$51,$A53)) | D53: =IF($A53="","",IFERROR(INDEX(計算用!$D$2:$D$186,MATCH("男"&$A53&"-1",計算用!$AN$2:$AN$186,0)),"")) | E53: =IF($A53="","",IFERROR(INDEX(計算用!$M$2:$M$186,MATCH("男"&$A53&"-1",計算用!$AN$2:$AN$186,0)),"")) | F53: =IF($A53="","",IFERROR(INDEX(計算用!$I$2:$I$186,MATCH("男"&$A53&"-1",計算用!$AN$2:$AN$186,0)),"")) | G53: =IF($A53="","",IFERROR(INDEX(計算用!$D$2:$D$186,MATCH("男"&$A53&"-2",計算用!$AN$2:$AN$186,0)),"")) | H53: =IF($A53="","",IFERROR(INDEX(計算用!$M$2:$M$186,MATCH("男"&$A53&"-2",計算用!$AN$2:$AN$186,0)),"")) | I53: =IF($A53="","",IFERROR(INDEX(計算用!$I$2:$I$186,MATCH("男"&$A53&"-2",計算用!$AN$2:$AN$186,0)),"")) | J53: =IF($A53="","",IFERROR(INDEX(計算用!$D$2:$D$186,MATCH("男"&$A53&"-3",計算用!$AN$2:$AN$186,0)),"")) | K53: =IF($A53="","",IFERROR(INDEX(計算用!$M$2:$M$186,MATCH("男"&$A53&"-3",計算用!$AN$2:$AN$186,0)),"")) | L53: =IF($A53="","",IFERROR(INDEX(計算用!$I$2:$I$186,MATCH("男"&$A53&"-3",計算用!$AN$2:$AN$186,0)),"")) | M53: =IF($A53="","",IFERROR(INDEX(計算用!$D$2:$D$186,MATCH("男"&$A53&"-4",計算用!$AN$2:$AN$186,0)),"")) | N53: =IF($A53="","",IFERROR(INDEX(計算用!$M$2:$M$186,MATCH("男"&$A53&"-4",計算用!$AN$2:$AN$186,0)),"")) | O53: =IF($A53="","",IFERROR(INDEX(計算用!$I$2:$I$186,MATCH("男"&$A53&"-4",計算用!$AN$2:$AN$186,0)),"")) | Q53: =IF(ROW()-3<=計算用!$Q$11,ROW()-3,"") | R53: =IF($Q53="","",INDEX(計算用!$AC$2:$AC$51,$Q53)) | S53: =IF($Q53="","","赤"&INDEX(計算用!$AF$2:$AF$51,$Q53)&"白"&INDEX(計算用!$AG$2:$AG$51,$Q53)) | T53: =IF($Q53="","",IFERROR(INDEX(計算用!$D$2:$D$186,MATCH("女"&$Q53&"-1",計算用!$AN$2:$AN$186,0)),"")) | U53: =IF($Q53="","",IFERROR(INDEX(計算用!$M$2:$M$186,MATCH("女"&$Q53&"-1",計算用!$AN$2:$AN$186,0)),"")) | V53: =IF($Q53="","",IFERROR(INDEX(計算用!$I$2:$I$186,MATCH("女"&$Q53&"-1",計算用!$AN$2:$AN$186,0)),"")) | W53: =IF($Q53="","",IFERROR(INDEX(計算用!$D$2:$D$186,MATCH("女"&$Q53&"-2",計算用!$AN$2:$AN$186,0)),"")) | X53: =IF($Q53="","",IFERROR(INDEX(計算用!$M$2:$M$186,MATCH("女"&$Q53&"-2",計算用!$AN$2:$AN$186,0)),"")) | Y53: =IF($Q53="","",IFERROR(INDEX(計算用!$I$2:$I$186,MATCH("女"&$Q53&"-2",計算用!$AN$2:$AN$186,0)),"")) | Z53: =IF($Q53="","",IFERROR(INDEX(計算用!$D$2:$D$186,MATCH("女"&$Q53&"-3",計算用!$AN$2:$AN$186,0)),"")) | AA53: =IF($Q53="","",IFERROR(INDEX(計算用!$M$2:$M$186,MATCH("女"&$Q53&"-3",計算用!$AN$2:$AN$186,0)),"")) | AB53: =IF($Q53="","",IFERROR(INDEX(計算用!$I$2:$I$186,MATCH("女"&$Q53&"-3",計算用!$AN$2:$AN$186,0)),"")) | AC53: =IF($Q53="","",IFERROR(INDEX(計算用!$D$2:$D$186,MATCH("女"&$Q53&"-4",計算用!$AN$2:$AN$186,0)),"")) | AD53: =IF($Q53="","",IFERROR(INDEX(計算用!$M$2:$M$186,MATCH("女"&$Q53&"-4",計算用!$AN$2:$AN$186,0)),"")) | AE53: =IF($Q53="","",IFERROR(INDEX(計算用!$I$2:$I$186,MATCH("女"&$Q53&"-4",計算用!$AN$2:$AN$186,0)),""))

Sheet 手動調整
A1: 手動調整 | C1: 組を変えたい子だけ、「変更後の組」に組の番号を入れてください。「何人目」は組の中で並べたい順番です（空いていれば自動の順番）。結果は「決定版」シートに出ます。※このシートは並べかえないでください。
C2: ="男子：自動 "&計算用!$Q$9&"組 → 決定版 "&計算用!$Q$13&"組"&IF(SUMPRODUCT((計算用!$BB$2:$BB$51>4)*1)>0," 5人以上の組 "&SUMPRODUCT((計算用!$BB$2:$BB$51>4)*1)&"つ","")&IF(SUMPRODUCT((計算用!$BA$2:$BA$51<=計算用!$Q$13)*(計算用!$BB$2:$BB$51=0))>0," だれもいない組 "&SUMPRODUCT((計算用!$BA$2:$BA$51<=計算用!$Q$13)*(計算用!$BB$2:$BB$51=0))&"つ","") | I2: ="女子：自動 "&計算用!$Q$11&"組 → 決定版 "&計算用!$Q$14&"組"&IF(SUMPRODUCT((計算用!$BG$2:$BG$51>4)*1)>0," 5人以上の組 "&SUMPRODUCT((計算用!$BG$2:$BG$51>4)*1)&"つ","")&IF(SUMPRODUCT((計算用!$BF$2:$BF$51<=計算用!$Q$14)*(計算用!$BG$2:$BG$51=0))>0," だれもいない組 "&SUMPRODUCT((計算用!$BF$2:$BF$51<=計算用!$Q$14)*(計算用!$BG$2:$BG$51=0))&"つ","")
A3: クラス | B3: No. | C3: 名前 | D3: 性別 | E3: 色 | F3: タイム | G3: 自動の組 | H3: 自動の 何人目 | I3: 変更後の組 | J3: 何人目 | K3: 決定の組 | L3: 決定の 何人目 | M3: 確認
A4: =IF(計算用!$D$2="","",計算用!$M$2) | B4: =IF(計算用!$D$2="","",計算用!$C$2) | C4: =IF(計算用!$D$2="","",計算用!$D$2) | D4: =IF(計算用!$D$2="","",計算用!$F$2) | E4: =IF(計算用!$D$2="","",計算用!$I$2) | F4: =IF(計算用!$D$2="","",計算用!$G$2) | G4: =IF(計算用!$D$2="","",計算用!$AK$2) | H4: =IF(計算用!$D$2="","",計算用!$AM$2) | K4: =IF(計算用!$D$2="","",計算用!$AP$2) | L4: =IF(計算用!$D$2="","",計算用!$AR$2) | M4: =IF(計算用!$D$2="",IF(OR(I4<>"",J4<>""),"名前がありません",""),IF(計算用!$J$2="",IF(OR(I4<>"",J4<>""),"入力不足のため組に入りません","入力不足"),IF(AND(I4<>"",I4<>G4),"組を変更",IF(J4<>"","順番を指定",""))))
A5: =IF(計算用!$D$3="","",計算用!$M$3) | B5: =IF(計算用!$D$3="","",計算用!$C$3) | C5: =IF(計算用!$D$3="","",計算用!$D$3) | D5: =IF(計算用!$D$3="","",計算用!$F$3) | E5: =IF(計算用!$D$3="","",計算用!$I$3) | F5: =IF(計算用!$D$3="","",計算用!$G$3) | G5: =IF(計算用!$D$3="","",計算用!$AK$3) | H5: =IF(計算用!$D$3="","",計算用!$AM$3) | K5: =IF(計算用!$D$3="","",計算用!$AP$3) | L5: =IF(計算用!$D$3="","",計算用!$AR$3) | M5: =IF(計算用!$D$3="",IF(OR(I5<>"",J5<>""),"名前がありません",""),IF(計算用!$J$3="",IF(OR(I5<>"",J5<>""),"入力不足のため組に入りません","入力不足"),IF(AND(I5<>"",I5<>G5),"組を変更",IF(J5<>"","順番を指定",""))))
A6: =IF(計算用!$D$4="","",計算用!$M$4) | B6: =IF(計算用!$D$4="","",計算用!$C$4) | C6: =IF(計算用!$D$4="","",計算用!$D$4) | D6: =IF(計算用!$D$4="","",計算用!$F$4) | E6: =IF(計算用!$D$4="","",計算用!$I$4) | F6: =IF(計算用!$D$4="","",計算用!$G$4) | G6: =IF(計算用!$D$4="","",計算用!$AK$4) | H6: =IF(計算用!$D$4="","",計算用!$AM$4) | K6: =IF(計算用!$D$4="","",計算用!$AP$4) | L6: =IF(計算用!$D$4="","",計算用!$AR$4) | M6: =IF(計算用!$D$4="",IF(OR(I6<>"",J6<>""),"名前がありません",""),IF(計算用!$J$4="",IF(OR(I6<>"",J6<>""),"入力不足のため組に入りません","入力不足"),IF(AND(I6<>"",I6<>G6),"組を変更",IF(J6<>"","順番を指定",""))))
A7: =IF(計算用!$D$5="","",計算用!$M$5) | B7: =IF(計算用!$D$5="","",計算用!$C$5) | C7: =IF(計算用!$D$5="","",計算用!$D$5) | D7: =IF(計算用!$D$5="","",計算用!$F$5) | E7: =IF(計算用!$D$5="","",計算用!$I$5) | F7: =IF(計算用!$D$5="","",計算用!$G$5) | G7: =IF(計算用!$D$5="","",計算用!$AK$5) | H7: =IF(計算用!$D$5="","",計算用!$AM$5) | K7: =IF(計算用!$D$5="","",計算用!$AP$5) | L7: =IF(計算用!$D$5="","",計算用!$AR$5) | M7: =IF(計算用!$D$5="",IF(OR(I7<>"",J7<>""),"名前がありません",""),IF(計算用!$J$5="",IF(OR(I7<>"",J7<>""),"入力不足のため組に入りません","入力不足"),IF(AND(I7<>"",I7<>G7),"組を変更",IF(J7<>"","順番を指定",""))))
A8: =IF(計算用!$D$6="","",計算用!$M$6) | B8: =IF(計算用!$D$6="","",計算用!$C$6) | C8: =IF(計算用!$D$6="","",計算用!$D$6) | D8: =IF(計算用!$D$6="","",計算用!$F$6) | E8: =IF(計算用!$D$6="","",計算用!$I$6) | F8: =IF(計算用!$D$6="","",計算用!$G$6) | G8: =IF(計算用!$D$6="","",計算用!$AK$6) | H8: =IF(計算用!$D$6="","",計算用!$AM$6) | K8: =IF(計算用!$D$6="","",計算用!$AP$6) | L8: =IF(計算用!$D$6="","",計算用!$AR$6) | M8: =IF(計算用!$D$6="",IF(OR(I8<>"",J8<>""),"名前がありません",""),IF(計算用!$J$6="",IF(OR(I8<>"",J8<>""),"入力不足のため組に入りません","入力不足"),IF(AND(I8<>"",I8<>G8),"組を変更",IF(J8<>"","順番を指定",""))))
A9: =IF(計算用!$D$7="","",計算用!$M$7) | B9: =IF(計算用!$D$7="","",計算用!$C$7) | C9: =IF(計算用!$D$7="","",計算用!$D$7) | D9: =IF(計算用!$D$7="","",計算用!$F$7) | E9: =IF(計算用!$D$7="","",計算用!$I$7) | F9: =IF(計算用!$D$7="","",計算用!$G$7) | G9: =IF(計算用!$D$7="","",計算用!$AK$7) | H9: =IF(計算用!$D$7="","",計算用!$AM$7) | K9: =IF(計算用!$D$7="","",計算用!$AP$7) | L9: =IF(計算用!$D$7="","",計算用!$AR$7) | M9: =IF(計算用!$D$7="",IF(OR(I9<>"",J9<>""),"名前がありません",""),IF(計算用!$J$7="",IF(OR(I9<>"",J9<>""),"入力不足のため組に入りません","入力不足"),IF(AND(I9<>"",I9<>G9),"組を変更",IF(J9<>"","順番を指定",""))))
A10: =IF(計算用!$D$8="","",計算用!$M$8) | B10: =IF(計算用!$D$8="","",計算用!$C$8) | C10: =IF(計算用!$D$8="","",計算用!$D$8) | D10: =IF(計算用!$D$8="","",計算用!$F$8) | E10: =IF(計算用!$D$8="","",計算用!$I$8) | F10: =IF(計算用!$D$8="","",計算用!$G$8) | G10: =IF(計算用!$D$8="","",計算用!$AK$8) | H10: =IF(計算用!$D$8="","",計算用!$AM$8) | K10: =IF(計算用!$D$8="","",計算用!$AP$8) | L10: =IF(計算用!$D$8="","",計算用!$AR$8) | M10: =IF(計算用!$D$8="",IF(OR(I10<>"",J10<>""),"名前がありません",""),IF(計算用!$J$8="",IF(OR(I10<>"",J10<>""),"入力不足のため組に入りません","入力不足"),IF(AND(I10<>"",I10<>G10),"組を変更",IF(J10<>"","順番を指定",""))))
A11: =IF(計算用!$D$9="","",計算用!$M$9) | B11: =IF(計算用!$D$9="","",計算用!$C$9) | C11: =IF(計算用!$D$9="","",計算用!$D$9) | D11: =IF(計算用!$D$9="","",計算用!$F$9) | E11: =IF(計算用!$D$9="","",計算用!$I$9) | F11: =IF(計算用!$D$9="","",計算用!$G$9) | G11: =IF(計算用!$D$9="","",計算用!$AK$9) | H11: =IF(計算用!$D$9="","",計算用!$AM$9) | K11: =IF(計算用!$D$9="","",計算用!$AP$9) | L11: =IF(計算用!$D$9="","",計算用!$AR$9) | M11: =IF(計算用!$D$9="",IF(OR(I11<>"",J11<>""),"名前がありません",""),IF(計算用!$J$9="",IF(OR(I11<>"",J11<>""),"入力不足のため組に入りません","入力不足"),IF(AND(I11<>"",I11<>G11),"組を変更",IF(J11<>"","順番を指定",""))))
A12: =IF(計算用!$D$10="","",計算用!$M$10) | B12: =IF(計算用!$D$10="","",計算用!$C$10) | C12: =IF(計算用!$D$10="","",計算用!$D$10) | D12: =IF(計算用!$D$10="","",計算用!$F$10) | E12: =IF(計算用!$D$10="","",計算用!$I$10) | F12: =IF(計算用!$D$10="","",計算用!$G$10) | G12: =IF(計算用!$D$10="","",計算用!$AK$10) | H12: =IF(計算用!$D$10="","",計算用!$AM$10) | K12: =IF(計算用!$D$10="","",計算用!$AP$10) | L12: =IF(計算用!$D$10="","",計算用!$AR$10) | M12: =IF(計算用!$D$10="",IF(OR(I12<>"",J12<>""),"名前がありません",""),IF(計算用!$J$10="",IF(OR(I12<>"",J12<>""),"入力不足のため組に入りません","入力不足"),IF(AND(I12<>"",I12<>G12),"組を変更",IF(J12<>"","順番を指定",""))))
A13: =IF(計算用!$D$11="","",計算用!$M$11) | B13: =IF(計算用!$D$11="","",計算用!$C$11) | C13: =IF(計算用!$D$11="","",計算用!$D$11) | D13: =IF(計算用!$D$11="","",計算用!$F$11) | E13: =IF(計算用!$D$11="","",計算用!$I$11) | F13: =IF(計算用!$D$11="","",計算用!$G$11) | G13: =IF(計算用!$D$11="","",計算用!$AK$11) | H13: =IF(計算用!$D$11="","",計算用!$AM$11) | K13: =IF(計算用!$D$11="","",計算用!$AP$11) | L13: =IF(計算用!$D$11="","",計算用!$AR$11) | M13: =IF(計算用!$D$11="",IF(OR(I13<>"",J13<>""),"名前がありません",""),IF(計算用!$J$11="",IF(OR(I13<>"",J13<>""),"入力不足のため組に入りません","入力不足"),IF(AND(I13<>"",I13<>G13),"組を変更",IF(J13<>"","順番を指定",""))))
A14: =IF(計算用!$D$12="","",計算用!$M$12) | B14: =IF(計算用!$D$12="","",計算用!$C$12) | C14: =IF(計算用!$D$12="","",計算用!$D$12) | D14: =IF(計算用!$D$12="","",計算用!$F$12) | E14: =IF(計算用!$D$12="","",計算用!$I$12) | F14: =IF(計算用!$D$12="","",計算用!$G$12) | G14: =IF(計算用!$D$12="","",計算用!$AK$12) | H14: =IF(計算用!$D$12="","",計算用!$AM$12) | K14: =IF(計算用!$D$12="","",計算用!$AP$12) | L14: =IF(計算用!$D$12="","",計算用!$AR$12) | M14: =IF(計算用!$D$12="",IF(OR(I14<>"",J14<>""),"名前がありません",""),IF(計算用!$J$12="",IF(OR(I14<>"",J14<>""),"入力不足のため組に入りません","入力不足"),IF(AND(I14<>"",I14<>G14),"組を変更",IF(J14<>"","順番を指定",""))))
A15: =IF(計算用!$D$13="","",計算用!$M$13) | B15: =IF(計算用!$D$13="","",計算用!$C$13) | C15: =IF(計算用!$D$13="","",計算用!$D$13) | D15: =IF(計算用!$D$13="","",計算用!$F$13) | E15: =IF(計算用!$D$13="","",計算用!$I$13) | F15: =IF(計算用!$D$13="","",計算用!$G$13) | G15: =IF(計算用!$D$13="","",計算用!$AK$13) | H15: =IF(計算用!$D$13="","",計算用!$AM$13) | K15: =IF(計算用!$D$13="","",計算用!$AP$13) | L15: =IF(計算用!$D$13="","",計算用!$AR$13) | M15: =IF(計算用!$D$13="",IF(OR(I15<>"",J15<>""),"名前がありません",""),IF(計算用!$J$13="",IF(OR(I15<>"",J15<>""),"入力不足のため組に入りません","入力不足"),IF(AND(I15<>"",I15<>G15),"組を変更",IF(J15<>"","順番を指定",""))))
A16: =IF(計算用!$D$14="","",計算用!$M$14) | B16: =IF(計算用!$D$14="","",計算用!$C$14) | C16: =IF(計算用!$D$14="","",計算用!$D$14) | D16: =IF(計算用!$D$14="","",計算用!$F$14) | E16: =IF(計算用!$D$14="","",計算用!$I$14) | F16: =IF(計算用!$D$14="","",計算用!$G$14) | G16: =IF(計算用!$D$14="","",計算用!$AK$14) | H16: =IF(計算用!$D$14="","",計算用!$AM$14) | K16: =IF(計算用!$D$14="","",計算用!$AP$14) | L16: =IF(計算用!$D$14="","",計算用!$AR$14) | M16: =IF(計算用!$D$14="",IF(OR(I16<>"",J16<>""),"名前がありません",""),IF(計算用!$J$14="",IF(OR(I16<>"",J16<>""),"入力不足のため組に入りません","入力不足"),IF(AND(I16<>"",I16<>G16),"組を変更",IF(J16<>"","順番を指定",""))))
A17: =IF(計算用!$D$15="","",計算用!$M$15) | B17: =IF(計算用!$D$15="","",計算用!$C$15) | C17: =IF(計算用!$D$15="","",計算用!$D$15) | D17: =IF(計算用!$D$15="","",計算用!$F$15) | E17: =IF(計算用!$D$15="","",計算用!$I$15) | F17: =IF(計算用!$D$15="","",計算用!$G$15) | G17: =IF(計算用!$D$15="","",計算用!$AK$15) | H17: =IF(計算用!$D$15="","",計算用!$AM$15) | K17: =IF(計算用!$D$15="","",計算用!$AP$15) | L17: =IF(計算用!$D$15="","",計算用!$AR$15) | M17: =IF(計算用!$D$15="",IF(OR(I17<>"",J17<>""),"名前がありません",""),IF(計算用!$J$15="",IF(OR(I17<>"",J17<>""),"入力不足のため組に入りません","入力不足"),IF(AND(I17<>"",I17<>G17),"組を変更",IF(J17<>"","順番を指定",""))))
A18: =IF(計算用!$D$16="","",計算用!$M$16) | B18: =IF(計算用!$D$16="","",計算用!$C$16) | C18: =IF(計算用!$D$16="","",計算用!$D$16) | D18: =IF(計算用!$D$16="","",計算用!$F$16) | E18: =IF(計算用!$D$16="","",計算用!$I$16) | F18: =IF(計算用!$D$16="","",計算用!$G$16) | G18: =IF(計算用!$D$16="","",計算用!$AK$16) | H18: =IF(計算用!$D$16="","",計算用!$AM$16) | K18: =IF(計算用!$D$16="","",計算用!$AP$16) | L18: =IF(計算用!$D$16="","",計算用!$AR$16) | M18: =IF(計算用!$D$16="",IF(OR(I18<>"",J18<>""),"名前がありません",""),IF(計算用!$J$16="",IF(OR(I18<>"",J18<>""),"入力不足のため組に入りません","入力不足"),IF(AND(I18<>"",I18<>G18),"組を変更",IF(J18<>"","順番を指定",""))))
A19: =IF(計算用!$D$17="","",計算用!$M$17) | B19: =IF(計算用!$D$17="","",計算用!$C$17) | C19: =IF(計算用!$D$17="","",計算用!$D$17) | D19: =IF(計算用!$D$17="","",計算用!$F$17) | E19: =IF(計算用!$D$17="","",計算用!$I$17) | F19: =IF(計算用!$D$17="","",計算用!$G$17) | G19: =IF(計算用!$D$17="","",計算用!$AK$17) | H19: =IF(計算用!$D$17="","",計算用!$AM$17) | K19: =IF(計算用!$D$17="","",計算用!$AP$17) | L19: =IF(計算用!$D$17="","",計算用!$AR$17) | M19: =IF(計算用!$D$17="",IF(OR(I19<>"",J19<>""),"名前がありません",""),IF(計算用!$J$17="",IF(OR(I19<>"",J19<>""),"入力不足のため組に入りません","入力不足"),IF(AND(I19<>"",I19<>G19),"組を変更",IF(J19<>"","順番を指定",""))))
