Workbook

Sheet ①データ入力
I1: 名簿から名前をコピペして使ってください。３年生以上は性別欄を記入しないと動きません。タイムまで入力したら②のシートへ
A2: No. | B2: 1組 名前 | C2: 性別 (1=男子 2=女子) | D2: タイム (1/100秒) | E2: 赤or白 | G2: 2組 名前 | H2: 性別 (1=男子 2=女子) | I2: タイム (1/100秒) | J2: 赤or白 | L2: 3組 名前 | M2: 性別 (1=男子 2=女子) | N2: タイム (1/100秒) | O2: 赤or白 | Q2: 4組 名前 | R2: 性別 (1=男子 2=女子) | S2: タイム (1/100秒) | T2: 赤or白 | V2: 5組 名前 | W2: 性別 (1=男子 2=女子) | X2: タイム (1/100秒) | Y2: 赤or白
A3: 1 | B3: 近藤 りく | C3: 1 | D3: 8.89 | E3: 赤 | G3: 木村 ひまり | H3: 2 | I3: 9.58 | J3: 赤 | L3: 鈴木 たいが | M3: 1 | N3: 10.43 | O3: 赤 | Q3: 山口 しょう | R3: 1 | S3: 9.57 | T3: 赤
A4: 2 | B4: 小林 ゆな | C4: 2 | D4: 9.63 | E4: 白 | G4: 高橋 ひまり | H4: 2 | I4: 8.97 | J4: 赤 | L4: 伊藤 たいが | M4: 1 | N4: 8.05 | O4: 白 | Q4: 池田 ゆい | R4: 2 | S4: 10.31 | T4: 白
A5: 3 | B5: 木村 ひなた | C5: 1 | D5: 9.34 | E5: 赤 | G5: 鈴木 はると | H5: 1 | I5: 9.34 | J5: 赤 | L5: 木村 さく | M5: 1 | N5: 8.47 | O5: 白 | Q5: 清水 そら | R5: 1 | S5: 9.11 | T5: 赤
A6: 4 | B6: 後藤 かのん | C6: 2 | D6: 9.31 | E6: 白 | G6: 高橋 さく | H6: 1 | I6: 8.47 | J6: 白 | L6: 井上 いつき | M6: 1 | N6: 8.82 | O6: 赤 | Q6: 後藤 ゆな | R6: 2 | S6: 9.29 | T6: 白
A7: 5 | B7: 井上 ほのか | C7: 2 | D7: 9.3 | E7: 白 | G7: 後藤 けんた | H7: 1 | I7: 9.71 | J7: 白 | L7: 斎藤 だいち | M7: 1 | N7: 10.02 | O7: 白 | Q7: 清水 しょう | R7: 1 | S7: 8.73 | T7: 白
A8: 6 | B8: 前田 かいと | C8: 1 | D8: 8.36 | E8: 白 | G8: 松本 かいと | H8: 1 | I8: 9.42 | J8: 白 | L8: 木村 ゆな | M8: 2 | N8: 9.49 | O8: 白 | Q8: 長谷川 ひまり | R8: 2 | S8: 10.17 | T8: 白
A9: 7 | B9: 山本 けんた | C9: 1 | D9: 8.37 | E9: 赤 | G9: 松本 たいが | H9: 1 | I9: 9.61 | J9: 赤 | L9: 伊藤 つむぎ | M9: 2 | N9: 10.12 | O9: 赤 | Q9: 佐藤 そうた | R9: 1 | S9: 10.24 | T9: 白
A10: 8 | B10: 清水 こはる | C10: 2 | D10: 9.93 | E10: 赤 | G10: 伊藤 ゆな | H10: 2 | I10: 11.04 | J10: 赤 | L10: 橋本 ひなた | M10: 1 | N10: 10.03 | O10: 赤 | Q10: 山本 つばさ | R10: 1 | S10: 8.85 | T10: 白
A11: 9 | B11: 佐藤 けんた | C11: 1 | D11: 9.17 | E11: 赤 | G11: 渡辺 みなと | H11: 1 | I11: 9.81 | J11: 白 | L11: 吉田 ひなた | M11: 1 | N11: 9.63 | O11: 赤 | Q11: 清水 ひな | R11: 2 | S11: 9.24 | T11: 白
A12: 10 | B12: 岡田 さら | C12: 2 | D12: 10.33 | E12: 白 | G12: 山田 あかり | H12: 2 | I12: 9.67 | J12: 白 | L12: 石川 めい | M12: 2 | N12: 9.84 | O12: 赤 | Q12: 伊藤 ひまり | R12: 2 | S12: 10.05 | T12: 赤
A13: 11 | B13: 中村 ゆな | C13: 2 | D13: 8.62 | E13: 白 | G13: 山本 かのん | H13: 2 | I13: 9.29 | J13: 白 | L13: 小林 ほのか | M13: 2 | N13: 9.51 | O13: 赤 | Q13: 森 りく | R13: 1 | S13: 8.5 | T13: 赤
A14: 12 | B14: 木村 りょう | C14: 1 | D14: 9.62 | E14: 赤 | G14: 中村 りく | H14: 1 | I14: 9 | J14: 白 | L14: 森 みなと | M14: 1 | N14: 8.74 | O14: 白 | Q14: 石川 あかり | R14: 2 | S14: 10.83 | T14: 赤
... A24: 22 | B24: 佐藤 れん | C24: 1 | D24: 8.86 | E24: 白 | G24: 加藤 ことね | H24: 2 | I24: 9.42 | J24: 白 | L24: 森 みお | M24: 2 | N24: 9.19 | O24: 白 | Q24: 田中 こうき | R24: 1 | S24: 8.68 | T24: 白
A25: 23 | B25: 石川 さら | C25: 2 | D25: 10.04 | E25: 赤
A26: 24 | B26: 村上 かいと | C26: 1 | D26: 7.97 | E26: 白
A27: 25
A28: 26
A29: 27
A30: 28
A31: 29
A32: 30
A33: 31
A34: 32
A35: 33
A36: 34
A37: 35
A38: 36
A39: 37

Sheet 組ごとタイム順
A1: 男子 | J1: 女子 | S1: =IF(計算用!$Q$6>0,"※名前はあるのに性別・タイム・赤白のどれかが未入力で、表に出ていない人が"&計算用!$Q$6&"人います","")
B2: 赤組 | F2: 白組 | K2: 赤組 | O2: 白組
B3: 名前 | C3: クラス | D3: タイム | F3: 名前 | G3: クラス | H3: タイム | K3: 名前 | L3: クラス | M3: タイム | O3: 名前 | P3: クラス | Q3: タイム
A4: =IF(ROW()-3<=MAX(計算用!$Q$2,計算用!$Q$3),ROW()-3,"") | B4: =IFERROR(INDEX(計算用!$D$2:$D$186,MATCH("男赤"&$A4,計算用!$L$2:$L$186,0)),"") | C4: =IFERROR(INDEX(計算用!$M$2:$M$186,MATCH("男赤"&$A4,計算用!$L$2:$L$186,0)),"") | D4: =IFERROR(INDEX(計算用!$G$2:$G$186,MATCH("男赤"&$A4,計算用!$L$2:$L$186,0)),"") | F4: =IFERROR(INDEX(計算用!$D$2:$D$186,MATCH("男白"&$A4,計算用!$L$2:$L$186,0)),"") | G4: =IFERROR(INDEX(計算用!$M$2:$M$186,MATCH("男白"&$A4,計算用!$L$2:$L$186,0)),"") | H4: =IFERROR(INDEX(計算用!$G$2:$G$186,MATCH("男白"&$A4,計算用!$L$2:$L$186,0)),"") | J4: =IF(ROW()-3<=MAX(計算用!$Q$4,計算用!$Q$5),ROW()-3,"") | K4: =IFERROR(INDEX(計算用!$D$2:$D$186,MATCH("女赤"&$J4,計算用!$L$2:$L$186,0)),"") | L4: =IFERROR(INDEX(計算用!$M$2:$M$186,MATCH("女赤"&$J4,計算用!$L$2:$L$186,0)),"") | M4: =IFERROR(INDEX(計算用!$G$2:$G$186,MATCH("女赤"&$J4,計算用!$L$2:$L$186,0)),"") | O4: =IFERROR(INDEX(計算用!$D$2:$D$186,MATCH("女白"&$J4,計算用!$L$2:$L$186,0)),"") | P4: =IFERROR(INDEX(計算用!$M$2:$M$186,MATCH("女白"&$J4,計算用!$L$2:$L$186,0)),"") | Q4: =IFERROR(INDEX(計算用!$G$2:$G$186,MATCH("女白"&$J4,計算用!$L$2:$L$186,0)),"")
A5: =IF(ROW()-3<=MAX(計算用!$Q$2,計算用!$Q$3),ROW()-3,"") | B5: =IFERROR(INDEX(計算用!$D$2:$D$186,MATCH("男赤"&$A5,計算用!$L$2:$L$186,0)),"") | C5: =IFERROR(INDEX(計算用!$M$2:$M$186,MATCH("男赤"&$A5,計算用!$L$2:$L$186,0)),"") | D5: =IFERROR(INDEX(計算用!$G$2:$G$186,MATCH("男赤"&$A5,計算用!$L$2:$L$186,0)),"") | F5: =IFERROR(INDEX(計算用!$D$2:$D$186,MATCH("男白"&$A5,計算用!$L$2:$L$186,0)),"") | G5: =IFERROR(INDEX(計算用!$M$2:$M$186,MATCH("男白"&$A5,計算用!$L$2:$L$186,0)),"") | H5: =IFERROR(INDEX(計算用!$G$2:$G$186,MATCH("男白"&$A5,計算用!$L$2:$L$186,0)),"") | J5: =IF(ROW()-3<=MAX(計算用!$Q$4,計算用!$Q$5),ROW()-3,"") | K5: =IFERROR(INDEX(計算用!$D$2:$D$186,MATCH("女赤"&$J5,計算用!$L$2:$L$186,0)),"") | L5: =IFERROR(INDEX(計算用!$M$2:$M$186,MATCH("女赤"&$J5,計算用!$L$2:$L$186,0)),"") | M5: =IFERROR(INDEX(計算用!$G$2:$G$186,MATCH("女赤"&$J5,計算用!$L$2:$L$186,0)),"") | O5: =IFERROR(INDEX(計算用!$D$2:$D$186,MATCH("女白"&$J5,計算用!$L$2:$L$186,0)),"") | P5: =IFERROR(INDEX(計算用!$M$2:$M$186,MATCH("女白"&$J5,計算用!$L$2:$L$186,0)),"") | Q5: =IFERROR(INDEX(計算用!$G$2:$G$186,MATCH("女白"&$J5,計算用!$L$2:$L$186,0)),"")
A6: =IF(ROW()-3<=MAX(計算用!$Q$2,計算用!$Q$3),ROW()-3,"") | B6: =IFERROR(INDEX(計算用!$D$2:$D$186,MATCH("男赤"&$A6,計算用!$L$2:$L$186,0)),"") | C6: =IFERROR(INDEX(計算用!$M$2:$M$186,MATCH("男赤"&$A6,計算用!$L$2:$L$186,0)),"") | D6: =IFERROR(INDEX(計算用!$G$2:$G$186,MATCH("男赤"&$A6,計算用!$L$2:$L$186,0)),"") | F6: =IFERROR(INDEX(計算用!$D$2:$D$186,MATCH("男白"&$A6,計算用!$L$2:$L$186,0)),"") | G6: =IFERROR(INDEX(計算用!$M$2:$M$186,MATCH("男白"&$A6,計算用!$L$2:$L$186,0)),"") | H6: =IFERROR(INDEX(計算用!$G$2:$G$186,MATCH("男白"&$A6,計算用!$L$2:$L$186,0)),"") | J6: =IF(ROW()-3<=MAX(計算用!$Q$4,計算用!$Q$5),ROW()-3,"") | K6: =IFERROR(INDEX(計算用!$D$2:$D$186,MATCH("女赤"&$J6,計算用!$L$2:$L$186,0)),"") | L6: =IFERROR(INDEX(計算用!$M$2:$M$186,MATCH("女赤"&$J6,計算用!$L$2:$L$186,0)),"") | M6: =IFERROR(INDEX(計算用!$G$2:$G$186,MATCH("女赤"&$J6,計算用!$L$2:$L$186,0)),"") | O6: =IFERROR(INDEX(計算用!$D$2:$D$186,MATCH("女白"&$J6,計算用!$L$2:$L$186,0)),"") | P6: =IFERROR(INDEX(計算用!$M$2:$M$186,MATCH("女白"&$J6,計算用!$L$2:$L$186,0)),"") | Q6: =IFERROR(INDEX(計算用!$G$2:$G$186,MATCH("女白"&$J6,計算用!$L$2:$L$186,0)),"")
A7: =IF(ROW()-3<=MAX(計算用!$Q$2,計算用!$Q$3),ROW()-3,"") | B7: =IFERROR(INDEX(計算用!$D$2:$D$186,MATCH("男赤"&$A7,計算用!$L$2:$L$186,0)),"") | C7: =IFERROR(INDEX(計算用!$M$2:$M$186,MATCH("男赤"&$A7,計算用!$L$2:$L$186,0)),"") | D7: =IFERROR(INDEX(計算用!$G$2:$G$186,MATCH("男赤"&$A7,計算用!$L$2:$L$186,0)),"") | F7: =IFERROR(INDEX(計算用!$D$2:$D$186,MATCH("男白"&$A7,計算用!$L$2:$L$186,0)),"") | G7: =IFERROR(INDEX(計算用!$M$2:$M$186,MATCH("男白"&$A7,計算用!$L$2:$L$186,0)),"") | H7: =IFERROR(INDEX(計算用!$G$2:$G$186,MATCH("男白"&$A7,計算用!$L$2:$L$186,0)),"") | J7: =IF(ROW()-3<=MAX(計算用!$Q$4,計算用!$Q$5),ROW()-3,"") | K7: =IFERROR(INDEX(計算用!$D$2:$D$186,MATCH("女赤"&$J7,計算用!$L$2:$L$186,0)),"") | L7: =IFERROR(INDEX(計算用!$M$2:$M$186,MATCH("女赤"&$J7,計算用!$L$2:$L$186,0)),"") | M7: =IFERROR(INDEX(計算用!$G$2:$G$186,MATCH("女赤"&$J7,計算用!$L$2:$L$186,0)),"") | O7: =IFERROR(INDEX(計算用!$D$2:$D$186,MATCH("女白"&$J7,計算用!$L$2:$L$186,0)),"") | P7: =IFERROR(INDEX(計算用!$M$2:$M$186,MATCH("女白"&$J7,計算用!$L$2:$L$186,0)),"") | Q7: =IFERROR(INDEX(計算用!$G$2:$G$186,MATCH("女白"&$J7,計算用!$L$2:$L$186,0)),"")
A8: =IF(ROW()-3<=MAX(計算用!$Q$2,計算用!$Q$3),ROW()-3,"") | B8: =IFERROR(INDEX(計算用!$D$2:$D$186,MATCH("男赤"&$A8,計算用!$L$2:$L$186,0)),"") | C8: =IFERROR(INDEX(計算用!$M$2:$M$186,MATCH("男赤"&$A8,計算用!$L$2:$L$186,0)),"") | D8: =IFERROR(INDEX(計算用!$G$2:$G$186,MATCH("男赤"&$A8,計算用!$L$2:$L$186,0)),"") | F8: =IFERROR(INDEX(計算用!$D$2:$D$186,MATCH("男白"&$A8,計算用!$L$2:$L$186,0)),"") | G8: =IFERROR(INDEX(計算用!$M$2:$M$186,MATCH("男白"&$A8,計算用!$L$2:$L$186,0)),"") | H8: =IFERROR(INDEX(計算用!$G$2:$G$186,MATCH("男白"&$A8,計算用!$L$2:$L$186,0)),"") | J8: =IF(ROW()-3<=MAX(計算用!$Q$4,計算用!$Q$5),ROW()-3,"") | K8: =IFERROR(INDEX(計算用!$D$2:$D$186,MATCH("女赤"&$J8,計算用!$L$2:$L$186,0)),"") | L8: =IFERROR(INDEX(計算用!$M$2:$M$186,MATCH("女赤"&$J8,計算用!$L$2:$L$186,0)),"") | M8: =IFERROR(INDEX(計算用!$G$2:$G$186,MATCH("女赤"&$J8,計算用!$L$2:$L$186,0)),"") | O8: =IFERROR(INDEX(計算用!$D$2:$D$186,MATCH("女白"&$J8,計算用!$L$2:$L$186,0)),"") | P8: =IFERROR(INDEX(計算用!$M$2:$M$186,MATCH("女白"&$J8,計算用!$L$2:$L$186,0)),"") | Q8: =IFERROR(INDEX(計算用!$G$2:$G$186,MATCH("女白"&$J8,計算用!$L$2:$L$186,0)),"")
A9: =IF(ROW()-3<=MAX(計算用!$Q$2,計算用!$Q$3),ROW()-3,"") | B9: =IFERROR(INDEX(計算用!$D$2:$D$186,MATCH("男赤"&$A9,計算用!$L$2:$L$186,0)),"") | C9: =IFERROR(INDEX(計算用!$M$2:$M$186,MATCH("男赤"&$A9,計算用!$L$2:$L$186,0)),"") | D9: =IFERROR(INDEX(計算用!$G$2:$G$186,MATCH("男赤"&$A9,計算用!$L$2:$L$186,0)),"") | F9: =IFERROR(INDEX(計算用!$D$2:$D$186,MATCH("男白"&$A9,計算用!$L$2:$L$186,0)),"") | G9: =IFERROR(INDEX(計算用!$M$2:$M$186,MATCH("男白"&$A9,計算用!$L$2:$L$186,0)),"") | H9: =IFERROR(INDEX(計算用!$G$2:$G$186,MATCH("男白"&$A9,計算用!$L$2:$L$186,0)),"") | J9: =IF(ROW()-3<=MAX(計算用!$Q$4,計算用!$Q$5),ROW()-3,"") | K9: =IFERROR(INDEX(計算用!$D$2:$D$186,MATCH("女赤"&$J9,計算用!$L$2:$L$186,0)),"") | L9: =IFERROR(INDEX(計算用!$M$2:$M$186,MATCH("女赤"&$J9,計算用!$L$2:$L$186,0)),"") | M9: =IFERROR(INDEX(計算用!$G$2:$G$186,MATCH("女赤"&$J9,計算用!$L$2:$L$186,0)),"") | O9: =IFERROR(INDEX(計算用!$D$2:$D$186,MATCH("女白"&$J9,計算用!$L$2:$L$186,0)),"") | P9: =IFERROR(INDEX(計算用!$M$2:$M$186,MATCH("女白"&$J9,計算用!$L$2:$L$186,0)),"") | Q9: =IFERROR(INDEX(計算用!$G$2:$G$186,MATCH("女白"&$J9,計算用!$L$2:$L$186,0)),"")
A10: =IF(ROW()-3<=MAX(計算用!$Q$2,計算用!$Q$3),ROW()-3,"") | B10: =IFERROR(INDEX(計算用!$D$2:$D$186,MATCH("男赤"&$A10,計算用!$L$2:$L$186,0)),"") | C10: =IFERROR(INDEX(計算用!$M$2:$M$186,MATCH("男赤"&$A10,計算用!$L$2:$L$186,0)),"") | D10: =IFERROR(INDEX(計算用!$G$2:$G$186,MATCH("男赤"&$A10,計算用!$L$2:$L$186,0)),"") | F10: =IFERROR(INDEX(計算用!$D$2:$D$186,MATCH("男白"&$A10,計算用!$L$2:$L$186,0)),"") | G10: =IFERROR(INDEX(計算用!$M$2:$M$186,MATCH("男白"&$A10,計算用!$L$2:$L$186,0)),"") | H10: =IFERROR(INDEX(計算用!$G$2:$G$186,MATCH("男白"&$A10,計算用!$L$2:$L$186,0)),"") | J10: =IF(ROW()-3<=MAX(計算用!$Q$4,計算用!$Q$5),ROW()-3,"") | K10: =IFERROR(INDEX(計算用!$D$2:$D$186,MATCH("女赤"&$J10,計算用!$L$2:$L$186,0)),"") | L10: =IFERROR(INDEX(計算用!$M$2:$M$186,MATCH("女赤"&$J10,計算用!$L$2:$L$186,0)),"") | M10: =IFERROR(INDEX(計算用!$G$2:$G$186,MATCH("女赤"&$J10,計算用!$L$2:$L$186,0)),"") | O10: =IFERROR(INDEX(計算用!$D$2:$D$186,MATCH("女白"&$J10,計算用!$L$2:$L$186,0)),"") | P10: =IFERROR(INDEX(計算用!$M$2:$M$186,MATCH("女白"&$J10,計算用!$L$2:$L$186,0)),"") | Q10: =IFERROR(INDEX(計算用!$G$2:$G$186,MATCH("女白"&$J10,計算用!$L$2:$L$186,0)),"")
A11: =IF(ROW()-3<=MAX(計算用!$Q$2,計算用!$Q$3),ROW()-3,"") | B11: =IFERROR(INDEX(計算用!$D$2:$D$186,MATCH("男赤"&$A11,計算用!$L$2:$L$186,0)),"") | C11: =IFERROR(INDEX(計算用!$M$2:$M$186,MATCH("男赤"&$A11,計算用!$L$2:$L$186,0)),"") | D11: =IFERROR(INDEX(計算用!$G$2:$G$186,MATCH("男赤"&$A11,計算用!$L$2:$L$186,0)),"") | F11: =IFERROR(INDEX(計算用!$D$2:$D$186,MATCH("男白"&$A11,計算用!$L$2:$L$186,0)),"") | G11: =IFERROR(INDEX(計算用!$M$2:$M$186,MATCH("男白"&$A11,計算用!$L$2:$L$186,0)),"") | H11: =IFERROR(INDEX(計算用!$G$2:$G$186,MATCH("男白"&$A11,計算用!$L$2:$L$186,0)),"") | J11: =IF(ROW()-3<=MAX(計算用!$Q$4,計算用!$Q$5),ROW()-3,"") | K11: =IFERROR(INDEX(計算用!$D$2:$D$186,MATCH("女赤"&$J11,計算用!$L$2:$L$186,0)),"") | L11: =IFERROR(INDEX(計算用!$M$2:$M$186,MATCH("女赤"&$J11,計算用!$L$2:$L$186,0)),"") | M11: =IFERROR(INDEX(計算用!$G$2:$G$186,MATCH("女赤"&$J11,計算用!$L$2:$L$186,0)),"") | O11: =IFERROR(INDEX(計算用!$D$2:$D$186,MATCH("女白"&$J11,計算用!$L$2:$L$186,0)),"") | P11: =IFERROR(INDEX(計算用!$M$2:$M$186,MATCH("女白"&$J11,計算用!$L$2:$L$186,0)),"") | Q11: =IFERROR(INDEX(計算用!$G$2:$G$186,MATCH("女白"&$J11,計算用!$L$2:$L$186,0)),"")
A12: =IF(ROW()-3<=MAX(計算用!$Q$2,計算用!$Q$3),ROW()-3,"") | B12: =IFERROR(INDEX(計算用!$D$2:$D$186,MATCH("男赤"&$A12,計算用!$L$2:$L$186,0)),"") | C12: =IFERROR(INDEX(計算用!$M$2:$M$186,MATCH("男赤"&$A12,計算用!$L$2:$L$186,0)),"") | D12: =IFERROR(INDEX(計算用!$G$2:$G$186,MATCH("男赤"&$A12,計算用!$L$2:$L$186,0)),"") | F12: =IFERROR(INDEX(計算用!$D$2:$D$186,MATCH("男白"&$A12,計算用!$L$2:$L$186,0)),"") | G12: =IFERROR(INDEX(計算用!$M$2:$M$186,MATCH("男白"&$A12,計算用!$L$2:$L$186,0)),"") | H12: =IFERROR(INDEX(計算用!$G$2:$G$186,MATCH("男白"&$A12,計算用!$L$2:$L$186,0)),"") | J12: =IF(ROW()-3<=MAX(計算用!$Q$4,計算用!$Q$5),ROW()-3,"") | K12: =IFERROR(INDEX(計算用!$D$2:$D$186,MATCH("女赤"&$J12,計算用!$L$2:$L$186,0)),"") | L12: =IFERROR(INDEX(計算用!$M$2:$M$186,MATCH("女赤"&$J12,計算用!$L$2:$L$186,0)),"") | M12: =IFERROR(INDEX(計算用!$G$2:$G$186,MATCH("女赤"&$J12,計算用!$L$2:$L$186,0)),"") | O12: =IFERROR(INDEX(計算用!$D$2:$D$186,MATCH("女白"&$J12,計算用!$L$2:$L$186,0)),"") | P12: =IFERROR(INDEX(計算用!$M$2:$M$186,MATCH("女白"&$J12,計算用!$L$2:$L$186,0)),"") | Q12: =IFERROR(INDEX(計算用!$G$2:$G$186,MATCH("女白"&$J12,計算用!$L$2:$L$186,0)),"")
A13: =IF(ROW()-3<=MAX(計算用!$Q$2,計算用!$Q$3),ROW()-3,"") | B13: =IFERROR(INDEX(計算用!$D$2:$D$186,MATCH("男赤"&$A13,計算用!$L$2:$L$186,0)),"") | C13: =IFERROR(INDEX(計算用!$M$2:$M$186,MATCH("男赤"&$A13,計算用!$L$2:$L$186,0)),"") | D13: =IFERROR(INDEX(計算用!$G$2:$G$186,MATCH("男赤"&$A13,計算用!$L$2:$L$186,0)),"") | F13: =IFERROR(INDEX(計算用!$D$2:$D$186,MATCH("男白"&$A13,計算用!$L$2:$L$186,0)),"") | G13: =IFERROR(INDEX(計算用!$M$2:$M$186,MATCH("男白"&$A13,計算用!$L$2:$L$186,0)),"") | H13: =IFERROR(INDEX(計算用!$G$2:$G$186,MATCH("男白"&$A13,計算用!$L$2:$L$186,0)),"") | J13: =IF(ROW()-3<=MAX(計算用!$Q$4,計算用!$Q$5),ROW()-3,"") | K13: =IFERROR(INDEX(計算用!$D$2:$D$186,MATCH("女赤"&$J13,計算用!$L$2:$L$186,0)),"") | L13: =IFERROR(INDEX(計算用!$M$2:$M$186,MATCH("女赤"&$J13,計算用!$L$2:$L$186,0)),"") | M13: =IFERROR(INDEX(計算用!$G$2:$G$186,MATCH("女赤"&$J13,計算用!$L$2:$L$186,0)),"") | O13: =IFERROR(INDEX(計算用!$D$2:$D$186,MATCH("女白"&$J13,計算用!$L$2:$L$186,0)),"") | P13: =IFERROR(INDEX(計算用!$M$2:$M$186,MATCH("女白"&$J13,計算用!$L$2:$L$186,0)),"") | Q13: =IFERROR(INDEX(計算用!$G$2:$G$186,MATCH("女白"&$J13,計算用!$L$2:$L$186,0)),"")
A14: =IF(ROW()-3<=MAX(計算用!$Q$2,計算用!$Q$3),ROW()-3,"") | B14: =IFERROR(INDEX(計算用!$D$2:$D$186,MATCH("男赤"&$A14,計算用!$L$2:$L$186,0)),"") | C14: =IFERROR(INDEX(計算用!$M$2:$M$186,MATCH("男赤"&$A14,計算用!$L$2:$L$186,0)),"") | D14: =IFERROR(INDEX(計算用!$G$2:$G$186,MATCH("男赤"&$A14,計算用!$L$2:$L$186,0)),"") | F14: =IFERROR(INDEX(計算用!$D$2:$D$186,MATCH("男白"&$A14,計算用!$L$2:$L$186,0)),"") | G14: =IFERROR(INDEX(計算用!$M$2:$M$186,MATCH("男白"&$A14,計算用!$L$2:$L$186,0)),"") | H14: =IFERROR(INDEX(計算用!$G$2:$G$186,MATCH("男白"&$A14,計算用!$L$2:$L$186,0)),"") | J14: =IF(ROW()-3<=MAX(計算用!$Q$4,計算用!$Q$5),ROW()-3,"") | K14: =IFERROR(INDEX(計算用!$D$2:$D$186,MATCH("女赤"&$J14,計算用!$L$2:$L$186,0)),"") | L14: =IFERROR(INDEX(計算用!$M$2:$M$186,MATCH("女赤"&$J14,計算用!$L$2:$L$186,0)),"") | M14: =IFERROR(INDEX(計算用!$G$2:$G$186,MATCH("女赤"&$J14,計算用!$L$2:$L$186,0)),"") | O14: =IFERROR(INDEX(計算用!$D$2:$D$186,MATCH("女白"&$J14,計算用!$L$2:$L$186,0)),"") | P14: =IFERROR(INDEX(計算用!$M$2:$M$186,MATCH("女白"&$J14,計算用!$L$2:$L$186,0)),"") | Q14: =IFERROR(INDEX(計算用!$G$2:$G$186,MATCH("女白"&$J14,計算用!$L$2:$L$186,0)),"")
A15: =IF(ROW()-3<=MAX(計算用!$Q$2,計算用!$Q$3),ROW()-3,"") | B15: =IFERROR(INDEX(計算用!$D$2:$D$186,MATCH("男赤"&$A15,計算用!$L$2:$L$186,0)),"") | C15: =IFERROR(INDEX(計算用!$M$2:$M$186,MATCH("男赤"&$A15,計算用!$L$2:$L$186,0)),"") | D15: =IFERROR(INDEX(計算用!$G$2:$G$186,MATCH("男赤"&$A15,計算用!$L$2:$L$186,0)),"") | F15: =IFERROR(INDEX(計算用!$D$2:$D$186,MATCH("男白"&$A15,計算用!$L$2:$L$186,0)),"") | G15: =IFERROR(INDEX(計算用!$M$2:$M$186,MATCH("男白"&$A15,計算用!$L$2:$L$186,0)),"") | H15: =IFERROR(INDEX(計算用!$G$2:$G$186,MATCH("男白"&$A15,計算用!$L$2:$L$186,0)),"") | J15: =IF(ROW()-3<=MAX(計算用!$Q$4,計算用!$Q$5),ROW()-3,"") | K15: =IFERROR(INDEX(計算用!$D$2:$D$186,MATCH("女赤"&$J15,計算用!$L$2:$L$186,0)),"") | L15: =IFERROR(INDEX(計算用!$M$2:$M$186,MATCH("女赤"&$J15,計算用!$L$2:$L$186,0)),"") | M15: =IFERROR(INDEX(計算用!$G$2:$G$186,MATCH("女赤"&$J15,計算用!$L$2:$L$186,0)),"") | O15: =IFERROR(INDEX(計算用!$D$2:$D$186,MATCH("女白"&$J15,計算用!$L$2:$L$186,0)),"") | P15: =IFERROR(INDEX(計算用!$M$2:$M$186,MATCH("女白"&$J15,計算用!$L$2:$L$186,0)),"") | Q15: =IFERROR(INDEX(計算用!$G$2:$G$186,MATCH("女白"&$J15,計算用!$L$2:$L$186,0)),"")
... A188: =IF(ROW()-3<=MAX(計算用!$Q$2,計算用!$Q$3),ROW()-3,"") | B188: =IFERROR(INDEX(計算用!$D$2:$D$186,MATCH("男赤"&$A188,計算用!$L$2:$L$186,0)),"") | C188: =IFERROR(INDEX(計算用!$M$2:$M$186,MATCH("男赤"&$A188,計算用!$L$2:$L$186,0)),"") | D188: =IFERROR(INDEX(計算用!$G$2:$G$186,MATCH("男赤"&$A188,計算用!$L$2:$L$186,0)),"") | F188: =IFERROR(INDEX(計算用!$D$2:$D$186,MATCH("男白"&$A188,計算用!$L$2:$L$186,0)),"") | G188: =IFERROR(INDEX(計算用!$M$2:$M$186,MATCH("男白"&$A188,計算用!$L$2:$L$186,0)),"") | H188: =IFERROR(INDEX(計算用!$G$2:$G$186,MATCH("男白"&$A188,計算用!$L$2:$L$186,0)),"") | J188: =IF(ROW()-3<=MAX(計算用!$Q$4,計算用!$Q$5),ROW()-3,"") | K188: =IFERROR(INDEX(計算用!$D$2:$D$186,MATCH("女赤"&$J188,計算用!$L$2:$L$186,0)),"") | L188: =IFERROR(INDEX(計算用!$M$2:$M$186,MATCH("女赤"&$J188,計算用!$L$2:$L$186,0)),"") | M188: =IFERROR(INDEX(計算用!$G$2:$G$186,MATCH("女赤"&$J188,計算用!$L$2:$L$186,0)),"") | O188: =IFERROR(INDEX(計算用!$D$2:$D$186,MATCH("女白"&$J188,計算用!$L$2:$L$186,0)),"") | P188: =IFERROR(INDEX(計算用!$M$2:$M$186,MATCH("女白"&$J188,計算用!$L$2:$L$186,0)),"") | Q188: =IFERROR(INDEX(計算用!$G$2:$G$186,MATCH("女白"&$J188,計算用!$L$2:$L$186,0)),"")

Sheet 4人組
A1: 男子 | D1: =IF(SUMPRODUCT((計算用!$T$2:$T$51>0)*(((計算用!$T$2:$T$51<>4)+(計算用!$W$2:$W$51<>2))>0))>0,"※黄色の組は、人数の都合で調整した組です","") | Q1: 女子 | T1: =IF(SUMPRODUCT((計算用!$AC$2:$AC$51>0)*(((計算用!$AC$2:$AC$51<>4)+(計算用!$AF$2:$AF$51<>2))>0))>0,"※黄色の組は、人数の都合で調整した組です","")
A2: 組 | B2: 人数 | C2: 内訳 | D2: 1人目 | G2: 2人目 | J2: 3人目 | M2: 4人目 | Q2: 組 | R2: 人数 | S2: 内訳 | T2: 1人目 | W2: 2人目 | Z2: 3人目 | AC2: 4人目
D3: 名前 | E3: クラス | F3: 色 | G3: 名前 | H3: クラス | I3: 色 | J3: 名前 | K3: クラス | L3: 色 | M3: 名前 | N3: クラス | O3: 色 | T3: 名前 | U3: クラス | V3: 色 | W3: 名前 | X3: クラス | Y3: 色 | Z3: 名前 | AA3: クラス | AB3: 色 | AC3: 名前 | AD3: クラス | AE3: 色
A4: =IF(ROW()-3<=計算用!$Q$9,ROW()-3,"") | B4: =IF($A4="","",INDEX(計算用!$T$2:$T$51,$A4)) | C4: =IF($A4="","","赤"&INDEX(計算用!$W$2:$W$51,$A4)&"白"&INDEX(計算用!$X$2:$X$51,$A4)) | D4: =IF($A4="","",IFERROR(INDEX(計算用!$D$2:$D$186,MATCH("男"&$A4&"-1",計算用!$AN$2:$AN$186,0)),"")) | E4: =IF($A4="","",IFERROR(INDEX(計算用!$M$2:$M$186,MATCH("男"&$A4&"-1",計算用!$AN$2:$AN$186,0)),"")) | F4: =IF($A4="","",IFERROR(INDEX(計算用!$I$2:$I$186,MATCH("男"&$A4&"-1",計算用!$AN$2:$AN$186,0)),"")) | G4: =IF($A4="","",IFERROR(INDEX(計算用!$D$2:$D$186,MATCH("男"&$A4&"-2",計算用!$AN$2:$AN$186,0)),"")) | H4: =IF($A4="","",IFERROR(INDEX(計算用!$M$2:$M$186,MATCH("男"&$A4&"-2",計算用!$AN$2:$AN$186,0)),"")) | I4: =IF($A4="","",IFERROR(INDEX(計算用!$I$2:$I$186,MATCH("男"&$A4&"-2",計算用!$AN$2:$AN$186,0)),"")) | J4: =IF($A4="","",IFERROR(INDEX(計算用!$D$2:$D$186,MATCH("男"&$A4&"-3",計算用!$AN$2:$AN$186,0)),"")) | K4: =IF($A4="","",IFERROR(INDEX(計算用!$M$2:$M$186,MATCH("男"&$A4&"-3",計算用!$AN$2:$AN$186,0)),"")) | L4: =IF($A4="","",IFERROR(INDEX(計算用!$I$2:$I$186,MATCH("男"&$A4&"-3",計算用!$AN$2:$AN$186,0)),"")) | M4: =IF($A4="","",IFERROR(INDEX(計算用!$D$2:$D$186,MATCH("男"&$A4&"-4",計算用!$AN$2:$AN$186,0)),"")) | N4: =IF($A4="","",IFERROR(INDEX(計算用!$M$2:$M$186,MATCH("男"&$A4&"-4",計算用!$AN$2:$AN$186,0)),"")) | O4: =IF($A4="","",IFERROR(INDEX(計算用!$I$2:$I$186,MATCH("男"&$A4&"-4",計算用!$AN$2:$AN$186,0)),"")) | Q4: =IF(ROW()-3<=計算用!$Q$11,ROW()-3,"") | R4: =IF($Q4="","",INDEX(計算用!$AC$2:$AC$51,$Q4)) | S4: =IF($Q4="","","赤"&INDEX(計算用!$AF$2:$AF$51,$Q4)&"白"&INDEX(計算用!$AG$2:$AG$51,$Q4)) | T4: =IF($Q4="","",IFERROR(INDEX(計算用!$D$2:$D$186,MATCH("女"&$Q4&"-1",計算用!$AN$2:$AN$186,0)),"")) | U4: =IF($Q4="","",IFERROR(INDEX(計算用!$M$2:$M$186,MATCH("女"&$Q4&"-1",計算用!$AN$2:$AN$186,0)),"")) | V4: =IF($Q4="","",IFERROR(INDEX(計算用!$I$2:$I$186,MATCH("女"&$Q4&"-1",計算用!$AN$2:$AN$186,0)),"")) | W4: =IF($Q4="","",IFERROR(INDEX(計算用!$D$2:$D$186,MATCH("女"&$Q4&"-2",計算用!$AN$2:$AN$186,0)),"")) | X4: =IF($Q4="","",IFERROR(INDEX(計算用!$M$2:$M$186,MATCH("女"&$Q4&"-2",計算用!$AN$2:$AN$186,0)),"")) | Y4: =IF($Q4="","",IFERROR(INDEX(計算用!$I$2:$I$186,MATCH("女"&$Q4&"-2",計算用!$AN$2:$AN$186,0)),"")) | Z4: =IF($Q4="","",IFERROR(INDEX(計算用!$D$2:$D$186,MATCH("女"&$Q4&"-3",計算用!$AN$2:$AN$186,0)),"")) | AA4: =IF($Q4="","",IFERROR(INDEX(計算用!$M$2:$M$186,MATCH("女"&$Q4&"-3",計算用!$AN$2:$AN$186,0)),"")) | AB4: =IF($Q4="","",IFERROR(INDEX(計算用!$I$2:$I$186,MATCH("女"&$Q4&"-3",計算用!$AN$2:$AN$186,0)),"")) | AC4: =IF($Q4="","",IFERROR(INDEX(計算用!$D$2:$D$186,MATCH("女"&$Q4&"-4",計算用!$AN$2:$AN$186,0)),"")) | AD4: =IF($Q4="","",IFERROR(INDEX(計算用!$M$2:$M$186,MATCH("女"&$Q4&"-4",計算用!$AN$2:$AN$186,0)),"")) | AE4: =IF($Q4="","",IFERROR(INDEX(計算用!$I$2:$I$186,MATCH("女"&$Q4&"-4",計算用!$AN$2:$AN$186,0)),""))
A5: =IF(ROW()-3<=計算用!$Q$9,ROW()-3,"") | B5: =IF($A5="","",INDEX(計算用!$T$2:$T$51,$A5)) | C5: =IF($A5="","","赤"&INDEX(計算用!$W$2:$W$51,$A5)&"白"&INDEX(計算用!$X$2:$X$51,$A5)) | D5: =IF($A5="","",IFERROR(INDEX(計算用!$D$2:$D$186,MATCH("男"&$A5&"-1",計算用!$AN$2:$AN$186,0)),"")) | E5: =IF($A5="","",IFERROR(INDEX(計算用!$M$2:$M$186,MATCH("男"&$A5&"-1",計算用!$AN$2:$AN$186,0)),"")) | F5: =IF($A5="","",IFERROR(INDEX(計算用!$I$2:$I$186,MATCH("男"&$A5&"-1",計算用!$AN$2:$AN$186,0)),"")) | G5: =IF($A5="","",IFERROR(INDEX(計算用!$D$2:$D$186,MATCH("男"&$A5&"-2",計算用!$AN$2:$AN$186,0)),"")) | H5: =IF($A5="","",IFERROR(INDEX(計算用!$M$2:$M$186,MATCH("男"&$A5&"-2",計算用!$AN$2:$AN$186,0)),"")) | I5: =IF($A5="","",IFERROR(INDEX(計算用!$I$2:$I$186,MATCH("男"&$A5&"-2",計算用!$AN$2:$AN$186,0)),"")) | J5: =IF($A5="","",IFERROR(INDEX(計算用!$D$2:$D$186,MATCH("男"&$A5&"-3",計算用!$AN$2:$AN$186,0)),"")) | K5: =IF($A5="","",IFERROR(INDEX(計算用!$M$2:$M$186,MATCH("男"&$A5&"-3",計算用!$AN$2:$AN$186,0)),"")) | L5: =IF($A5="","",IFERROR(INDEX(計算用!$I$2:$I$186,MATCH("男"&$A5&"-3",計算用!$AN$2:$AN$186,0)),"")) | M5: =IF($A5="","",IFERROR(INDEX(計算用!$D$2:$D$186,MATCH("男"&$A5&"-4",計算用!$AN$2:$AN$186,0)),"")) | N5: =IF($A5="","",IFERROR(INDEX(計算用!$M$2:$M$186,MATCH("男"&$A5&"-4",計算用!$AN$2:$AN$186,0)),"")) | O5: =IF($A5="","",IFERROR(INDEX(計算用!$I$2:$I$186,MATCH("男"&$A5&"-4",計算用!$AN$2:$AN$186,0)),"")) | Q5: =IF(ROW()-3<=計算用!$Q$11,ROW()-3,"") | R5: =IF($Q5="","",INDEX(計算用!$AC$2:$AC$51,$Q5)) | S5: =IF($Q5="","","赤"&INDEX(計算用!$AF$2:$AF$51,$Q5)&"白"&INDEX(計算用!$AG$2:$AG$51,$Q5)) | T5: =IF($Q5="","",IFERROR(INDEX(計算用!$D$2:$D$186,MATCH("女"&$Q5&"-1",計算用!$AN$2:$AN$186,0)),"")) | U5: =IF($Q5="","",IFERROR(INDEX(計算用!$M$2:$M$186,MATCH("女"&$Q5&"-1",計算用!$AN$2:$AN$186,0)),"")) | V5: =IF($Q5="","",IFERROR(INDEX(計算用!$I$2:$I$186,MATCH("女"&$Q5&"-1",計算用!$AN$2:$AN$186,0)),"")) | W5: =IF($Q5="","",IFERROR(INDEX(計算用!$D$2:$D$186,MATCH("女"&$Q5&"-2",計算用!$AN$2:$AN$186,0)),"")) | X5: =IF($Q5="","",IFERROR(INDEX(計算用!$M$2:$M$186,MATCH("女"&$Q5&"-2",計算用!$AN$2:$AN$186,0)),"")) | Y5: =IF($Q5="","",IFERROR(INDEX(計算用!$I$2:$I$186,MATCH("女"&$Q5&"-2",計算用!$AN$2:$AN$186,0)),"")) | Z5: =IF($Q5="","",IFERROR(INDEX(計算用!$D$2:$D$186,MATCH("女"&$Q5&"-3",計算用!$AN$2:$AN$186,0)),"")) | AA5: =IF($Q5="","",IFERROR(INDEX(計算用!$M$2:$M$186,MATCH("女"&$Q5&"-3",計算用!$AN$2:$AN$186,0)),"")) | AB5: =IF($Q5="","",IFERROR(INDEX(計算用!$I$2:$I$186,MATCH("女"&$Q5&"-3",計算用!$AN$2:$AN$186,0)),"")) | AC5: =IF($Q5="","",IFERROR(INDEX(計算用!$D$2:$D$186,MATCH("女"&$Q5&"-4",計算用!$AN$2:$AN$186,0)),"")) | AD5: =IF($Q5="","",IFERROR(INDEX(計算用!$M$2:$M$186,MATCH("女"&$Q5&"-4",計算用!$AN$2:$AN$186,0)),"")) | AE5: =IF($Q5="","",IFERROR(INDEX(計算用!$I$2:$I$186,MATCH("女"&$Q5&"-4",計算用!$AN$2:$AN$186,0)),""))
A6: =IF(ROW()-3<=計算用!$Q$9,ROW()-3,"") | B6: =IF($A6="","",INDEX(計算用!$T$2:$T$51,$A6)) | C6: =IF($A6="","","赤"&INDEX(計算用!$W$2:$W$51,$A6)&"白"&INDEX(計算用!$X$2:$X$51,$A6)) | D6: =IF($A6="","",IFERROR(INDEX(計算用!$D$2:$D$186,MATCH("男"&$A6&"-1",計算用!$AN$2:$AN$186,0)),"")) | E6: =IF($A6="","",IFERROR(INDEX(計算用!$M$2:$M$186,MATCH("男"&$A6&"-1",計算用!$AN$2:$AN$186,0)),"")) | F6: =IF($A6="","",IFERROR(INDEX(計算用!$I$2:$I$186,MATCH("男"&$A6&"-1",計算用!$AN$2:$AN$186,0)),"")) | G6: =IF($A6="","",IFERROR(INDEX(計算用!$D$2:$D$186,MATCH("男"&$A6&"-2",計算用!$AN$2:$AN$186,0)),"")) | H6: =IF($A6="","",IFERROR(INDEX(計算用!$M$2:$M$186,MATCH("男"&$A6&"-2",計算用!$AN$2:$AN$186,0)),"")) | I6: =IF($A6="","",IFERROR(INDEX(計算用!$I$2:$I$186,MATCH("男"&$A6&"-2",計算用!$AN$2:$AN$186,0)),"")) | J6: =IF($A6="","",IFERROR(INDEX(計算用!$D$2:$D$186,MATCH("男"&$A6&"-3",計算用!$AN$2:$AN$186,0)),"")) | K6: =IF($A6="","",IFERROR(INDEX(計算用!$M$2:$M$186,MATCH("男"&$A6&"-3",計算用!$AN$2:$AN$186,0)),"")) | L6: =IF($A6="","",IFERROR(INDEX(計算用!$I$2:$I$186,MATCH("男"&$A6&"-3",計算用!$AN$2:$AN$186,0)),"")) | M6: =IF($A6="","",IFERROR(INDEX(計算用!$D$2:$D$186,MATCH("男"&$A6&"-4",計算用!$AN$2:$AN$186,0)),"")) | N6: =IF($A6="","",IFERROR(INDEX(計算用!$M$2:$M$186,MATCH("男"&$A6&"-4",計算用!$AN$2:$AN$186,0)),"")) | O6: =IF($A6="","",IFERROR(INDEX(計算用!$I$2:$I$186,MATCH("男"&$A6&"-4",計算用!$AN$2:$AN$186,0)),"")) | Q6: =IF(ROW()-3<=計算用!$Q$11,ROW()-3,"") | R6: =IF($Q6="","",INDEX(計算用!$AC$2:$AC$51,$Q6)) | S6: =IF($Q6="","","赤"&INDEX(計算用!$AF$2:$AF$51,$Q6)&"白"&INDEX(計算用!$AG$2:$AG$51,$Q6)) | T6: =IF($Q6="","",IFERROR(INDEX(計算用!$D$2:$D$186,MATCH("女"&$Q6&"-1",計算用!$AN$2:$AN$186,0)),"")) | U6: =IF($Q6="","",IFERROR(INDEX(計算用!$M$2:$M$186,MATCH("女"&$Q6&"-1",計算用!$AN$2:$AN$186,0)),"")) | V6: =IF($Q6="","",IFERROR(INDEX(計算用!$I$2:$I$186,MATCH("女"&$Q6&"-1",計算用!$AN$2:$AN$186,0)),"")) | W6: =IF($Q6="","",IFERROR(INDEX(計算用!$D$2:$D$186,MATCH("女"&$Q6&"-2",計算用!$AN$2:$AN$186,0)),"")) | X6: =IF($Q6="","",IFERROR(INDEX(計算用!$M$2:$M$186,MATCH("女"&$Q6&"-2",計算用!$AN$2:$AN$186,0)),"")) | Y6: =IF($Q6="","",IFERROR(INDEX(計算用!$I$2:$I$186,MATCH("女"&$Q6&"-2",計算用!$AN$2:$AN$186,0)),"")) | Z6: =IF($Q6="","",IFERROR(INDEX(計算用!$D$2:$D$186,MATCH("女"&$Q6&"-3",計算用!$AN$2:$AN$186,0)),"")) | AA6: =IF($Q6="","",IFERROR(INDEX(計算用!$M$2:$M$186,MATCH("女"&$Q6&"-3",計算用!$AN$2:$AN$186,0)),"")) | AB6: =IF($Q6="","",IFERROR(INDEX(計算用!$I$2:$I$186,MATCH("女"&$Q6&"-3",計算用!$AN$2:$AN$186,0)),"")) | AC6: =IF($Q6="","",IFERROR(INDEX(計算用!$D$2:$D$186,MATCH("女"&$Q6&"-4",計算用!$AN$2:$AN$186,0)),"")) | AD6: =IF($Q6="","",IFERROR(INDEX(計算用!$M$2:$M$186,MATCH("女"&$Q6&"-4",計算用!$AN$2:$AN$186,0)),"")) | AE6: =IF($Q6="","",IFERROR(INDEX(計算用!$I$2:$I$186,MATCH("女"&$Q6&"-4",計算用!$AN$2:$AN$186,0)),""))
A7: =IF(ROW()-3<=計算用!$Q$9,ROW()-3,"") | B7: =IF($A7="","",INDEX(計算用!$T$2:$T$51,$A7)) | C7: =IF($A7="","","赤"&INDEX(計算用!$W$2:$W$51,$A7)&"白"&INDEX(計算用!$X$2:$X$51,$A7)) | D7: =IF($A7="","",IFERROR(INDEX(計算用!$D$2:$D$186,MATCH("男"&$A7&"-1",計算用!$AN$2:$AN$186,0)),"")) | E7: =IF($A7="","",IFERROR(INDEX(計算用!$M$2:$M$186,MATCH("男"&$A7&"-1",計算用!$AN$2:$AN$186,0)),"")) | F7: =IF($A7="","",IFERROR(INDEX(計算用!$I$2:$I$186,MATCH("男"&$A7&"-1",計算用!$AN$2:$AN$186,0)),"")) | G7: =IF($A7="","",IFERROR(INDEX(計算用!$D$2:$D$186,MATCH("男"&$A7&"-2",計算用!$AN$2:$AN$186,0)),"")) | H7: =IF($A7="","",IFERROR(INDEX(計算用!$M$2:$M$186,MATCH("男"&$A7&"-2",計算用!$AN$2:$AN$186,0)),"")) | I7: =IF($A7="","",IFERROR(INDEX(計算用!$I$2:$I$186,MATCH("男"&$A7&"-2",計算用!$AN$2:$AN$186,0)),"")) | J7: =IF($A7="","",IFERROR(INDEX(計算用!$D$2:$D$186,MATCH("男"&$A7&"-3",計算用!$AN$2:$AN$186,0)),"")) | K7: =IF($A7="","",IFERROR(INDEX(計算用!$M$2:$M$186,MATCH("男"&$A7&"-3",計算用!$AN$2:$AN$186,0)),"")) | L7: =IF($A7="","",IFERROR(INDEX(計算用!$I$2:$I$186,MATCH("男"&$A7&"-3",計算用!$AN$2:$AN$186,0)),"")) | M7: =IF($A7="","",IFERROR(INDEX(計算用!$D$2:$D$186,MATCH("男"&$A7&"-4",計算用!$AN$2:$AN$186,0)),"")) | N7: =IF($A7="","",IFERROR(INDEX(計算用!$M$2:$M$186,MATCH("男"&$A7&"-4",計算用!$AN$2:$AN$186,0)),"")) | O7: =IF($A7="","",IFERROR(INDEX(計算用!$I$2:$I$186,MATCH("男"&$A7&"-4",計算用!$AN$2:$AN$186,0)),"")) | Q7: =IF(ROW()-3<=計算用!$Q$11,ROW()-3,"") | R7: =IF($Q7="","",INDEX(計算用!$AC$2:$AC$51,$Q7)) | S7: =IF($Q7="","","赤"&INDEX(計算用!$AF$2:$AF$51,$Q7)&"白"&INDEX(計算用!$AG$2:$AG$51,$Q7)) | T7: =IF($Q7="","",IFERROR(INDEX(計算用!$D$2:$D$186,MATCH("女"&$Q7&"-1",計算用!$AN$2:$AN$186,0)),"")) | U7: =IF($Q7="","",IFERROR(INDEX(計算用!$M$2:$M$186,MATCH("女"&$Q7&"-1",計算用!$AN$2:$AN$186,0)),"")) | V7: =IF($Q7="","",IFERROR(INDEX(計算用!$I$2:$I$186,MATCH("女"&$Q7&"-1",計算用!$AN$2:$AN$186,0)),"")) | W7: =IF($Q7="","",IFERROR(INDEX(計算用!$D$2:$D$186,MATCH("女"&$Q7&"-2",計算用!$AN$2:$AN$186,0)),"")) | X7: =IF($Q7="","",IFERROR(INDEX(計算用!$M$2:$M$186,MATCH("女"&$Q7&"-2",計算用!$AN$2:$AN$186,0)),"")) | Y7: =IF($Q7="","",IFERROR(INDEX(計算用!$I$2:$I$186,MATCH("女"&$Q7&"-2",計算用!$AN$2:$AN$186,0)),"")) | Z7: =IF($Q7="","",IFERROR(INDEX(計算用!$D$2:$D$186,MATCH("女"&$Q7&"-3",計算用!$AN$2:$AN$186,0)),"")) | AA7: =IF($Q7="","",IFERROR(INDEX(計算用!$M$2:$M$186,MATCH("女"&$Q7&"-3",計算用!$AN$2:$AN$186,0)),"")) | AB7: =IF($Q7="","",IFERROR(INDEX(計算用!$I$2:$I$186,MATCH("女"&$Q7&"-3",計算用!$AN$2:$AN$186,0)),"")) | AC7: =IF($Q7="","",IFERROR(INDEX(計算用!$D$2:$D$186,MATCH("女"&$Q7&"-4",計算用!$AN$2:$AN$186,0)),"")) | AD7: =IF($Q7="","",IFERROR(INDEX(計算用!$M$2:$M$186,MATCH("女"&$Q7&"-4",計算用!$AN$2:$AN$186,0)),"")) | AE7: =IF($Q7="","",IFERROR(INDEX(計算用!$I$2:$I$186,MATCH("女"&$Q7&"-4",計算用!$AN$2:$AN$186,0)),""))
A8: =IF(ROW()-3<=計算用!$Q$9,ROW()-3,"") | B8: =IF($A8="","",INDEX(計算用!$T$2:$T$51,$A8)) | C8: =IF($A8="","","赤"&INDEX(計算用!$W$2:$W$51,$A8)&"白"&INDEX(計算用!$X$2:$X$51,$A8)) | D8: =IF($A8="","",IFERROR(INDEX(計算用!$D$2:$D$186,MATCH("男"&$A8&"-1",計算用!$AN$2:$AN$186,0)),"")) | E8: =IF($A8="","",IFERROR(INDEX(計算用!$M$2:$M$186,MATCH("男"&$A8&"-1",計算用!$AN$2:$AN$186,0)),"")) | F8: =IF($A8="","",IFERROR(INDEX(計算用!$I$2:$I$186,MATCH("男"&$A8&"-1",計算用!$AN$2:$AN$186,0)),"")) | G8: =IF($A8="","",IFERROR(INDEX(計算用!$D$2:$D$186,MATCH("男"&$A8&"-2",計算用!$AN$2:$AN$186,0)),"")) | H8: =IF($A8="","",IFERROR(INDEX(計算用!$M$2:$M$186,MATCH("男"&$A8&"-2",計算用!$AN$2:$AN$186,0)),"")) | I8: =IF($A8="","",IFERROR(INDEX(計算用!$I$2:$I$186,MATCH("男"&$A8&"-2",計算用!$AN$2:$AN$186,0)),"")) | J8: =IF($A8="","",IFERROR(INDEX(計算用!$D$2:$D$186,MATCH("男"&$A8&"-3",計算用!$AN$2:$AN$186,0)),"")) | K8: =IF($A8="","",IFERROR(INDEX(計算用!$M$2:$M$186,MATCH("男"&$A8&"-3",計算用!$AN$2:$AN$186,0)),"")) | L8: =IF($A8="","",IFERROR(INDEX(計算用!$I$2:$I$186,MATCH("男"&$A8&"-3",計算用!$AN$2:$AN$186,0)),"")) | M8: =IF($A8="","",IFERROR(INDEX(計算用!$D$2:$D$186,MATCH("男"&$A8&"-4",計算用!$AN$2:$AN$186,0)),"")) | N8: =IF($A8="","",IFERROR(INDEX(計算用!$M$2:$M$186,MATCH("男"&$A8&"-4",計算用!$AN$2:$AN$186,0)),"")) | O8: =IF($A8="","",IFERROR(INDEX(計算用!$I$2:$I$186,MATCH("男"&$A8&"-4",計算用!$AN$2:$AN$186,0)),"")) | Q8: =IF(ROW()-3<=計算用!$Q$11,ROW()-3,"") | R8: =IF($Q8="","",INDEX(計算用!$AC$2:$AC$51,$Q8)) | S8: =IF($Q8="","","赤"&INDEX(計算用!$AF$2:$AF$51,$Q8)&"白"&INDEX(計算用!$AG$2:$AG$51,$Q8)) | T8: =IF($Q8="","",IFERROR(INDEX(計算用!$D$2:$D$186,MATCH("女"&$Q8&"-1",計算用!$AN$2:$AN$186,0)),"")) | U8: =IF($Q8="","",IFERROR(INDEX(計算用!$M$2:$M$186,MATCH("女"&$Q8&"-1",計算用!$AN$2:$AN$186,0)),"")) | V8: =IF($Q8="","",IFERROR(INDEX(計算用!$I$2:$I$186,MATCH("女"&$Q8&"-1",計算用!$AN$2:$AN$186,0)),"")) | W8: =IF($Q8="","",IFERROR(INDEX(計算用!$D$2:$D$186,MATCH("女"&$Q8&"-2",計算用!$AN$2:$AN$186,0)),"")) | X8: =IF($Q8="","",IFERROR(INDEX(計算用!$M$2:$M$186,MATCH("女"&$Q8&"-2",計算用!$AN$2:$AN$186,0)),"")) | Y8: =IF($Q8="","",IFERROR(INDEX(計算用!$I$2:$I$186,MATCH("女"&$Q8&"-2",計算用!$AN$2:$AN$186,0)),"")) | Z8: =IF($Q8="","",IFERROR(INDEX(計算用!$D$2:$D$186,MATCH("女"&$Q8&"-3",計算用!$AN$2:$AN$186,0)),"")) | AA8: =IF($Q8="","",IFERROR(INDEX(計算用!$M$2:$M$186,MATCH("女"&$Q8&"-3",計算用!$AN$2:$AN$186,0)),"")) | AB8: =IF($Q8="","",IFERROR(INDEX(計算用!$I$2:$I$186,MATCH("女"&$Q8&"-3",計算用!$AN$2:$AN$186,0)),"")) | AC8: =IF($Q8="","",IFERROR(INDEX(計算用!$D$2:$D$186,MATCH("女"&$Q8&"-4",計算用!$AN$2:$AN$186,0)),"")) | AD8: =IF($Q8="","",IFERROR(INDEX(計算用!$M$2:$M$186,MATCH("女"&$Q8&"-4",計算用!$AN$2:$AN$186,0)),"")) | AE8: =IF($Q8="","",IFERROR(INDEX(計算用!$I$2:$I$186,MATCH("女"&$Q8&"-4",計算用!$AN$2:$AN$186,0)),""))
A9: =IF(ROW()-3<=計算用!$Q$9,ROW()-3,"") | B9: =IF($A9="","",INDEX(計算用!$T$2:$T$51,$A9)) | C9: =IF($A9="","","赤"&INDEX(計算用!$W$2:$W$51,$A9)&"白"&INDEX(計算用!$X$2:$X$51,$A9)) | D9: =IF($A9="","",IFERROR(INDEX(計算用!$D$2:$D$186,MATCH("男"&$A9&"-1",計算用!$AN$2:$AN$186,0)),"")) | E9: =IF($A9="","",IFERROR(INDEX(計算用!$M$2:$M$186,MATCH("男"&$A9&"-1",計算用!$AN$2:$AN$186,0)),"")) | F9: =IF($A9="","",IFERROR(INDEX(計算用!$I$2:$I$186,MATCH("男"&$A9&"-1",計算用!$AN$2:$AN$186,0)),"")) | G9: =IF($A9="","",IFERROR(INDEX(計算用!$D$2:$D$186,MATCH("男"&$A9&"-2",計算用!$AN$2:$AN$186,0)),"")) | H9: =IF($A9="","",IFERROR(INDEX(計算用!$M$2:$M$186,MATCH("男"&$A9&"-2",計算用!$AN$2:$AN$186,0)),"")) | I9: =IF($A9="","",IFERROR(INDEX(計算用!$I$2:$I$186,MATCH("男"&$A9&"-2",計算用!$AN$2:$AN$186,0)),"")) | J9: =IF($A9="","",IFERROR(INDEX(計算用!$D$2:$D$186,MATCH("男"&$A9&"-3",計算用!$AN$2:$AN$186,0)),"")) | K9: =IF($A9="","",IFERROR(INDEX(計算用!$M$2:$M$186,MATCH("男"&$A9&"-3",計算用!$AN$2:$AN$186,0)),"")) | L9: =IF($A9="","",IFERROR(INDEX(計算用!$I$2:$I$186,MATCH("男"&$A9&"-3",計算用!$AN$2:$AN$186,0)),"")) | M9: =IF($A9="","",IFERROR(INDEX(計算用!$D$2:$D$186,MATCH("男"&$A9&"-4",計算用!$AN$2:$AN$186,0)),"")) | N9: =IF($A9="","",IFERROR(INDEX(計算用!$M$2:$M$186,MATCH("男"&$A9&"-4",計算用!$AN$2:$AN$186,0)),"")) | O9: =IF($A9="","",IFERROR(INDEX(計算用!$I$2:$I$186,MATCH("男"&$A9&"-4",計算用!$AN$2:$AN$186,0)),"")) | Q9: =IF(ROW()-3<=計算用!$Q$11,ROW()-3,"") | R9: =IF($Q9="","",INDEX(計算用!$AC$2:$AC$51,$Q9)) | S9: =IF($Q9="","","赤"&INDEX(計算用!$AF$2:$AF$51,$Q9)&"白"&INDEX(計算用!$AG$2:$AG$51,$Q9)) | T9: =IF($Q9="","",IFERROR(INDEX(計算用!$D$2:$D$186,MATCH("女"&$Q9&"-1",計算用!$AN$2:$AN$186,0)),"")) | U9: =IF($Q9="","",IFERROR(INDEX(計算用!$M$2:$M$186,MATCH("女"&$Q9&"-1",計算用!$AN$2:$AN$186,0)),"")) | V9: =IF($Q9="","",IFERROR(INDEX(計算用!$I$2:$I$186,MATCH("女"&$Q9&"-1",計算用!$AN$2:$AN$186,0)),"")) | W9: =IF($Q9="","",IFERROR(INDEX(計算用!$D$2:$D$186,MATCH("女"&$Q9&"-2",計算用!$AN$2:$AN$186,0)),"")) | X9: =IF($Q9="","",IFERROR(INDEX(計算用!$M$2:$M$186,MATCH("女"&$Q9&"-2",計算用!$AN$2:$AN$186,0)),"")) | Y9: =IF($Q9="","",IFERROR(INDEX(計算用!$I$2:$I$186,MATCH("女"&$Q9&"-2",計算用!$AN$2:$AN$186,0)),"")) | Z9: =IF($Q9="","",IFERROR(INDEX(計算用!$D$2:$D$186,MATCH("女"&$Q9&"-3",計算用!$AN$2:$AN$186,0)),"")) | AA9: =IF($Q9="","",IFERROR(INDEX(計算用!$M$2:$M$186,MATCH("女"&$Q9&"-3",計算用!$AN$2:$AN$186,0)),"")) | AB9: =IF($Q9="","",IFERROR(INDEX(計算用!$I$2:$I$186,MATCH("女"&$Q9&"-3",計算用!$AN$2:$AN$186,0)),"")) | AC9: =IF($Q9="","",IFERROR(INDEX(計算用!$D$2:$D$186,MATCH("女"&$Q9&"-4",計算用!$AN$2:$AN$186,0)),"")) | AD9: =IF($Q9="","",IFERROR(INDEX(計算用!$M$2:$M$186,MATCH("女"&$Q9&"-4",計算用!$AN$2:$AN$186,0)),"")) | AE9: =IF($Q9="","",IFERROR(INDEX(計算用!$I$2:$I$186,MATCH("女"&$Q9&"-4",計算用!$AN$2:$AN$186,0)),""))
A10: =IF(ROW()-3<=計算用!$Q$9,ROW()-3,"") | B10: =IF($A10="","",INDEX(計算用!$T$2:$T$51,$A10)) | C10: =IF($A10="","","赤"&INDEX(計算用!$W$2:$W$51,$A10)&"白"&INDEX(計算用!$X$2:$X$51,$A10)) | D10: =IF($A10="","",IFERROR(INDEX(計算用!$D$2:$D$186,MATCH("男"&$A10&"-1",計算用!$AN$2:$AN$186,0)),"")) | E10: =IF($A10="","",IFERROR(INDEX(計算用!$M$2:$M$186,MATCH("男"&$A10&"-1",計算用!$AN$2:$AN$186,0)),"")) | F10: =IF($A10="","",IFERROR(INDEX(計算用!$I$2:$I$186,MATCH("男"&$A10&"-1",計算用!$AN$2:$AN$186,0)),"")) | G10: =IF($A10="","",IFERROR(INDEX(計算用!$D$2:$D$186,MATCH("男"&$A10&"-2",計算用!$AN$2:$AN$186,0)),"")) | H10: =IF($A10="","",IFERROR(INDEX(計算用!$M$2:$M$186,MATCH("男"&$A10&"-2",計算用!$AN$2:$AN$186,0)),"")) | I10: =IF($A10="","",IFERROR(INDEX(計算用!$I$2:$I$186,MATCH("男"&$A10&"-2",計算用!$AN$2:$AN$186,0)),"")) | J10: =IF($A10="","",IFERROR(INDEX(計算用!$D$2:$D$186,MATCH("男"&$A10&"-3",計算用!$AN$2:$AN$186,0)),"")) | K10: =IF($A10="","",IFERROR(INDEX(計算用!$M$2:$M$186,MATCH("男"&$A10&"-3",計算用!$AN$2:$AN$186,0)),"")) | L10: =IF($A10="","",IFERROR(INDEX(計算用!$I$2:$I$186,MATCH("男"&$A10&"-3",計算用!$AN$2:$AN$186,0)),"")) | M10: =IF($A10="","",IFERROR(INDEX(計算用!$D$2:$D$186,MATCH("男"&$A10&"-4",計算用!$AN$2:$AN$186,0)),"")) | N10: =IF($A10="","",IFERROR(INDEX(計算用!$M$2:$M$186,MATCH("男"&$A10&"-4",計算用!$AN$2:$AN$186,0)),"")) | O10: =IF($A10="","",IFERROR(INDEX(計算用!$I$2:$I$186,MATCH("男"&$A10&"-4",計算用!$AN$2:$AN$186,0)),"")) | Q10: =IF(ROW()-3<=計算用!$Q$11,ROW()-3,"") | R10: =IF($Q10="","",INDEX(計算用!$AC$2:$AC$51,$Q10)) | S10: =IF($Q10="","","赤"&INDEX(計算用!$AF$2:$AF$51,$Q10)&"白"&INDEX(計算用!$AG$2:$AG$51,$Q10)) | T10: =IF($Q10="","",IFERROR(INDEX(計算用!$D$2:$D$186,MATCH("女"&$Q10&"-1",計算用!$AN$2:$AN$186,0)),"")) | U10: =IF($Q10="","",IFERROR(INDEX(計算用!$M$2:$M$186,MATCH("女"&$Q10&"-1",計算用!$AN$2:$AN$186,0)),"")) | V10: =IF($Q10="","",IFERROR(INDEX(計算用!$I$2:$I$186,MATCH("女"&$Q10&"-1",計算用!$AN$2:$AN$186,0)),"")) | W10: =IF($Q10="","",IFERROR(INDEX(計算用!$D$2:$D$186,MATCH("女"&$Q10&"-2",計算用!$AN$2:$AN$186,0)),"")) | X10: =IF($Q10="","",IFERROR(INDEX(計算用!$M$2:$M$186,MATCH("女"&$Q10&"-2",計算用!$AN$2:$AN$186,0)),"")) | Y10: =IF($Q10="","",IFERROR(INDEX(計算用!$I$2:$I$186,MATCH("女"&$Q10&"-2",計算用!$AN$2:$AN$186,0)),"")) | Z10: =IF($Q10="","",IFERROR(INDEX(計算用!$D$2:$D$186,MATCH("女"&$Q10&"-3",計算用!$AN$2:$AN$186,0)),"")) | AA10: =IF($Q10="","",IFERROR(INDEX(計算用!$M$2:$M$186,MATCH("女"&$Q10&"-3",計算用!$AN$2:$AN$186,0)),"")) | AB10: =IF($Q10="","",IFERROR(INDEX(計算用!$I$2:$I$186,MATCH("女"&$Q10&"-3",計算用!$AN$2:$AN$186,0)),"")) | AC10: =IF($Q10="","",IFERROR(INDEX(計算用!$D$2:$D$186,MATCH("女"&$Q10&"-4",計算用!$AN$2:$AN$186,0)),"")) | AD10: =IF($Q10="","",IFERROR(INDEX(計算用!$M$2:$M$186,MATCH("女"&$Q10&"-4",計算用!$AN$2:$AN$186,0)),"")) | AE10: =IF($Q10="","",IFERROR(INDEX(計算用!$I$2:$I$186,MATCH("女"&$Q10&"-4",計算用!$AN$2:$AN$186,0)),""))
A11: =IF(ROW()-3<=計算用!$Q$9,ROW()-3,"") | B11: =IF($A11="","",INDEX(計算用!$T$2:$T$51,$A11)) | C11: =IF($A11="","","赤"&INDEX(計算用!$W$2:$W$51,$A11)&"白"&INDEX(計算用!$X$2:$X$51,$A11)) | D11: =IF($A11="","",IFERROR(INDEX(計算用!$D$2:$D$186,MATCH("男"&$A11&"-1",計算用!$AN$2:$AN$186,0)),"")) | E11: =IF($A11="","",IFERROR(INDEX(計算用!$M$2:$M$186,MATCH("男"&$A11&"-1",計算用!$AN$2:$AN$186,0)),"")) | F11: =IF($A11="","",IFERROR(INDEX(計算用!$I$2:$I$186,MATCH("男"&$A11&"-1",計算用!$AN$2:$AN$186,0)),"")) | G11: =IF($A11="","",IFERROR(INDEX(計算用!$D$2:$D$186,MATCH("男"&$A11&"-2",計算用!$AN$2:$AN$186,0)),"")) | H11: =IF($A11="","",IFERROR(INDEX(計算用!$M$2:$M$186,MATCH("男"&$A11&"-2",計算用!$AN$2:$AN$186,0)),"")) | I11: =IF($A11="","",IFERROR(INDEX(計算用!$I$2:$I$186,MATCH("男"&$A11&"-2",計算用!$AN$2:$AN$186,0)),"")) | J11: =IF($A11="","",IFERROR(INDEX(計算用!$D$2:$D$186,MATCH("男"&$A11&"-3",計算用!$AN$2:$AN$186,0)),"")) | K11: =IF($A11="","",IFERROR(INDEX(計算用!$M$2:$M$186,MATCH("男"&$A11&"-3",計算用!$AN$2:$AN$186,0)),"")) | L11: =IF($A11="","",IFERROR(INDEX(計算用!$I$2:$I$186,MATCH("男"&$A11&"-3",計算用!$AN$2:$AN$186,0)),"")) | M11: =IF($A11="","",IFERROR(INDEX(計算用!$D$2:$D$186,MATCH("男"&$A11&"-4",計算用!$AN$2:$AN$186,0)),"")) | N11: =IF($A11="","",IFERROR(INDEX(計算用!$M$2:$M$186,MATCH("男"&$A11&"-4",計算用!$AN$2:$AN$186,0)),"")) | O11: =IF($A11="","",IFERROR(INDEX(計算用!$I$2:$I$186,MATCH("男"&$A11&"-4",計算用!$AN$2:$AN$186,0)),"")) | Q11: =IF(ROW()-3<=計算用!$Q$11,ROW()-3,"") | R11: =IF($Q11="","",INDEX(計算用!$AC$2:$AC$51,$Q11)) | S11: =IF($Q11="","","赤"&INDEX(計算用!$AF$2:$AF$51,$Q11)&"白"&INDEX(計算用!$AG$2:$AG$51,$Q11)) | T11: =IF($Q11="","",IFERROR(INDEX(計算用!$D$2:$D$186,MATCH("女"&$Q11&"-1",計算用!$AN$2:$AN$186,0)),"")) | U11: =IF($Q11="","",IFERROR(INDEX(計算用!$M$2:$M$186,MATCH("女"&$Q11&"-1",計算用!$AN$2:$AN$186,0)),"")) | V11: =IF($Q11="","",IFERROR(INDEX(計算用!$I$2:$I$186,MATCH("女"&$Q11&"-1",計算用!$AN$2:$AN$186,0)),"")) | W11: =IF($Q11="","",IFERROR(INDEX(計算用!$D$2:$D$186,MATCH("女"&$Q11&"-2",計算用!$AN$2:$AN$186,0)),"")) | X11: =IF($Q11="","",IFERROR(INDEX(計算用!$M$2:$M$186,MATCH("女"&$Q11&"-2",計算用!$AN$2:$AN$186,0)),"")) | Y11: =IF($Q11="","",IFERROR(INDEX(計算用!$I$2:$I$186,MATCH("女"&$Q11&"-2",計算用!$AN$2:$AN$186,0)),"")) | Z11: =IF($Q11="","",IFERROR(INDEX(計算用!$D$2:$D$186,MATCH("女"&$Q11&"-3",計算用!$AN$2:$AN$186,0)),"")) | AA11: =IF($Q11="","",IFERROR(INDEX(計算用!$M$2:$M$186,MATCH("女"&$Q11&"-3",計算用!$AN$2:$AN$186,0)),"")) | AB11: =IF($Q11="","",IFERROR(INDEX(計算用!$I$2:$I$186,MATCH("女"&$Q11&"-3",計算用!$AN$2:$AN$186,0)),"")) | AC11: =IF($Q11="","",IFERROR(INDEX(計算用!$D$2:$D$186,MATCH("女"&$Q11&"-4",計算用!$AN$2:$AN$186,0)),"")) | AD11: =IF($Q11="","",IFERROR(INDEX(計算用!$M$2:$M$186,MATCH("女"&$Q11&"-4",計算用!$AN$2:$AN$186,0)),"")) | AE11: =IF($Q11="","",IFERROR(INDEX(計算用!$I$2:$I$186,MATCH("女"&$Q11&"-4",計算用!$AN$2:$AN$186,0)),""))
A12: =IF(ROW()-3<=計算用!$Q$9,ROW()-3,"") | B12: =IF($A12="","",INDEX(計算用!$T$2:$T$51,$A12)) | C12: =IF($A12="","","赤"&INDEX(計算用!$W$2:$W$51,$A12)&"白"&INDEX(計算用!$X$2:$X$51,$A12)) | D12: =IF($A12="","",IFERROR(INDEX(計算用!$D$2:$D$186,MATCH("男"&$A12&"-1",計算用!$AN$2:$AN$186,0)),"")) | E12: =IF($A12="","",IFERROR(INDEX(計算用!$M$2:$M$186,MATCH("男"&$A12&"-1",計算用!$AN$2:$AN$186,0)),"")) | F12: =IF($A12="","",IFERROR(INDEX(計算用!$I$2:$I$186,MATCH("男"&$A12&"-1",計算用!$AN$2:$AN$186,0)),"")) | G12: =IF($A12="","",IFERROR(INDEX(計算用!$D$2:$D$186,MATCH("男"&$A12&"-2",計算用!$AN$2:$AN$186,0)),"")) | H12: =IF($A12="","",IFERROR(INDEX(計算用!$M$2:$M$186,MATCH("男"&$A12&"-2",計算用!$AN$2:$AN$186,0)),"")) | I12: =IF($A12="","",IFERROR(INDEX(計算用!$I$2:$I$186,MATCH("男"&$A12&"-2",計算用!$AN$2:$AN$186,0)),"")) | J12: =IF($A12="","",IFERROR(INDEX(計算用!$D$2:$D$186,MATCH("男"&$A12&"-3",計算用!$AN$2:$AN$186,0)),"")) | K12: =IF($A12="","",IFERROR(INDEX(計算用!$M$2:$M$186,MATCH("男"&$A12&"-3",計算用!$AN$2:$AN$186,0)),"")) | L12: =IF($A12="","",IFERROR(INDEX(計算用!$I$2:$I$186,MATCH("男"&$A12&"-3",計算用!$AN$2:$AN$186,0)),"")) | M12: =IF($A12="","",IFERROR(INDEX(計算用!$D$2:$D$186,MATCH("男"&$A12&"-4",計算用!$AN$2:$AN$186,0)),"")) | N12: =IF($A12="","",IFERROR(INDEX(計算用!$M$2:$M$186,MATCH("男"&$A12&"-4",計算用!$AN$2:$AN$186,0)),"")) | O12: =IF($A12="","",IFERROR(INDEX(計算用!$I$2:$I$186,MATCH("男"&$A12&"-4",計算用!$AN$2:$AN$186,0)),"")) | Q12: =IF(ROW()-3<=計算用!$Q$11,ROW()-3,"") | R12: =IF($Q12="","",INDEX(計算用!$AC$2:$AC$51,$Q12)) | S12: =IF($Q12="","","赤"&INDEX(計算用!$AF$2:$AF$51,$Q12)&"白"&INDEX(計算用!$AG$2:$AG$51,$Q12)) | T12: =IF($Q12="","",IFERROR(INDEX(計算用!$D$2:$D$186,MATCH("女"&$Q12&"-1",計算用!$AN$2:$AN$186,0)),"")) | U12: =IF($Q12="","",IFERROR(INDEX(計算用!$M$2:$M$186,MATCH("女"&$Q12&"-1",計算用!$AN$2:$AN$186,0)),"")) | V12: =IF($Q12="","",IFERROR(INDEX(計算用!$I$2:$I$186,MATCH("女"&$Q12&"-1",計算用!$AN$2:$AN$186,0)),"")) | W12: =IF($Q12="","",IFERROR(INDEX(計算用!$D$2:$D$186,MATCH("女"&$Q12&"-2",計算用!$AN$2:$AN$186,0)),"")) | X12: =IF($Q12="","",IFERROR(INDEX(計算用!$M$2:$M$186,MATCH("女"&$Q12&"-2",計算用!$AN$2:$AN$186,0)),"")) | Y12: =IF($Q12="","",IFERROR(INDEX(計算用!$I$2:$I$186,MATCH("女"&$Q12&"-2",計算用!$AN$2:$AN$186,0)),"")) | Z12: =IF($Q12="","",IFERROR(INDEX(計算用!$D$2:$D$186,MATCH("女"&$Q12&"-3",計算用!$AN$2:$AN$186,0)),"")) | AA12: =IF($Q12="","",IFERROR(INDEX(計算用!$M$2:$M$186,MATCH("女"&$Q12&"-3",計算用!$AN$2:$AN$186,0)),"")) | AB12: =IF($Q12="","",IFERROR(INDEX(計算用!$I$2:$I$186,MATCH("女"&$Q12&"-3",計算用!$AN$2:$AN$186,0)),"")) | AC12: =IF($Q12="","",IFERROR(INDEX(計算用!$D$2:$D$186,MATCH("女"&$Q12&"-4",計算用!$AN$2:$AN$186,0)),"")) | AD12: =IF($Q12="","",IFERROR(INDEX(計算用!$M$2:$M$186,MATCH("女"&$Q12&"-4",計算用!$AN$2:$AN$186,0)),"")) | AE12: =IF($Q12="","",IFERROR(INDEX(計算用!$I$2:$I$186,MATCH("女"&$Q12&"-4",計算用!$AN$2:$AN$186,0)),""))
A13: =IF(ROW()-3<=計算用!$Q$9,ROW()-3,"") | B13: =IF($A13="","",INDEX(計算用!$T$2:$T$51,$A13)) | C13: =IF($A13="","","赤"&INDEX(計算用!$W$2:$W$51,$A13)&"白"&INDEX(計算用!$X$2:$X$51,$A13)) | D13: =IF($A13="","",IFERROR(INDEX(計算用!$D$2:$D$186,MATCH("男"&$A13&"-1",計算用!$AN$2:$AN$186,0)),"")) | E13: =IF($A13="","",IFERROR(INDEX(計算用!$M$2:$M$186,MATCH("男"&$A13&"-1",計算用!$AN$2:$AN$186,0)),"")) | F13: =IF($A13="","",IFERROR(INDEX(計算用!$I$2:$I$186,MATCH("男"&$A13&"-1",計算用!$AN$2:$AN$186,0)),"")) | G13: =IF($A13="","",IFERROR(INDEX(計算用!$D$2:$D$186,MATCH("男"&$A13&"-2",計算用!$AN$2:$AN$186,0)),"")) | H13: =IF($A13="","",IFERROR(INDEX(計算用!$M$2:$M$186,MATCH("男"&$A13&"-2",計算用!$AN$2:$AN$186,0)),"")) | I13: =IF($A13="","",IFERROR(INDEX(計算用!$I$2:$I$186,MATCH("男"&$A13&"-2",計算用!$AN$2:$AN$186,0)),"")) | J13: =IF($A13="","",IFERROR(INDEX(計算用!$D$2:$D$186,MATCH("男"&$A13&"-3",計算用!$AN$2:$AN$186,0)),"")) | K13: =IF($A13="","",IFERROR(INDEX(計算用!$M$2:$M$186,MATCH("男"&$A13&"-3",計算用!$AN$2:$AN$186,0)),"")) | L13: =IF($A13="","",IFERROR(INDEX(計算用!$I$2:$I$186,MATCH("男"&$A13&"-3",計算用!$AN$2:$AN$186,0)),"")) | M13: =IF($A13="","",IFERROR(INDEX(計算用!$D$2:$D$186,MATCH("男"&$A13&"-4",計算用!$AN$2:$AN$186,0)),"")) | N13: =IF($A13="","",IFERROR(INDEX(計算用!$M$2:$M$186,MATCH("男"&$A13&"-4",計算用!$AN$2:$AN$186,0)),"")) | O13: =IF($A13="","",IFERROR(INDEX(計算用!$I$2:$I$186,MATCH("男"&$A13&"-4",計算用!$AN$2:$AN$186,0)),"")) | Q13: =IF(ROW()-3<=計算用!$Q$11,ROW()-3,"") | R13: =IF($Q13="","",INDEX(計算用!$AC$2:$AC$51,$Q13)) | S13: =IF($Q13="","","赤"&INDEX(計算用!$AF$2:$AF$51,$Q13)&"白"&INDEX(計算用!$AG$2:$AG$51,$Q13)) | T13: =IF($Q13="","",IFERROR(INDEX(計算用!$D$2:$D$186,MATCH("女"&$Q13&"-1",計算用!$AN$2:$AN$186,0)),"")) | U13: =IF($Q13="","",IFERROR(INDEX(計算用!$M$2:$M$186,MATCH("女"&$Q13&"-1",計算用!$AN$2:$AN$186,0)),"")) | V13: =IF($Q13="","",IFERROR(INDEX(計算用!$I$2:$I$186,MATCH("女"&$Q13&"-1",計算用!$AN$2:$AN$186,0)),"")) | W13: =IF($Q13="","",IFERROR(INDEX(計算用!$D$2:$D$186,MATCH("女"&$Q13&"-2",計算用!$AN$2:$AN$186,0)),"")) | X13: =IF($Q13="","",IFERROR(INDEX(計算用!$M$2:$M$186,MATCH("女"&$Q13&"-2",計算用!$AN$2:$AN$186,0)),"")) | Y13: =IF($Q13="","",IFERROR(INDEX(計算用!$I$2:$I$186,MATCH("女"&$Q13&"-2",計算用!$AN$2:$AN$186,0)),"")) | Z13: =IF($Q13="","",IFERROR(INDEX(計算用!$D$2:$D$186,MATCH("女"&$Q13&"-3",計算用!$AN$2:$AN$186,0)),"")) | AA13: =IF($Q13="","",IFERROR(INDEX(計算用!$M$2:$M$186,MATCH("女"&$Q13&"-3",計算用!$AN$2:$AN$186,0)),"")) | AB13: =IF($Q13="","",IFERROR(INDEX(計算用!$I$2:$I$186,MATCH("女"&$Q13&"-3",計算用!$AN$2:$AN$186,0)),"")) | AC13: =IF($Q13="","",IFERROR(INDEX(計算用!$D$2:$D$186,MATCH("女"&$Q13&"-4",計算用!$AN$2:$AN$186,0)),"")) | AD13: =IF($Q13="","",IFERROR(INDEX(計算用!$M$2:$M$186,MATCH("女"&$Q13&"-4",計算用!$AN$2:$AN$186,0)),"")) | AE13: =IF($Q13="","",IFERROR(INDEX(計算用!$I$2:$I$186,MATCH("女"&$Q13&"-4",計算用!$AN$2:$AN$186,0)),""))
A14: =IF(ROW()-3<=計算用!$Q$9,ROW()-3,"") | B14: =IF($A14="","",INDEX(計算用!$T$2:$T$51,$A14)) | C14: =IF($A14="","","赤"&INDEX(計算用!$W$2:$W$51,$A14)&"白"&INDEX(計算用!$X$2:$X$51,$A14)) | D14: =IF($A14="","",IFERROR(INDEX(計算用!$D$2:$D$186,MATCH("男"&$A14&"-1",計算用!$AN$2:$AN$186,0)),"")) | E14: =IF($A14="","",IFERROR(INDEX(計算用!$M$2:$M$186,MATCH("男"&$A14&"-1",計算用!$AN$2:$AN$186,0)),"")) | F14: =IF($A14="","",IFERROR(INDEX(計算用!$I$2:$I$186,MATCH("男"&$A14&"-1",計算用!$AN$2:$AN$186,0)),"")) | G14: =IF($A14="","",IFERROR(INDEX(計算用!$D$2:$D$186,MATCH("男"&$A14&"-2",計算用!$AN$2:$AN$186,0)),"")) | H14: =IF($A14="","",IFERROR(INDEX(計算用!$M$2:$M$186,MATCH("男"&$A14&"-2",計算用!$AN$2:$AN$186,0)),"")) | I14: =IF($A14="","",IFERROR(INDEX(計算用!$I$2:$I$186,MATCH("男"&$A14&"-2",計算用!$AN$2:$AN$186,0)),"")) | J14: =IF($A14="","",IFERROR(INDEX(計算用!$D$2:$D$186,MATCH("男"&$A14&"-3",計算用!$AN$2:$AN$186,0)),"")) | K14: =IF($A14="","",IFERROR(INDEX(計算用!$M$2:$M$186,MATCH("男"&$A14&"-3",計算用!$AN$2:$AN$186,0)),"")) | L14: =IF($A14="","",IFERROR(INDEX(計算用!$I$2:$I$186,MATCH("男"&$A14&"-3",計算用!$AN$2:$AN$186,0)),"")) | M14: =IF($A14="","",IFERROR(INDEX(計算用!$D$2:$D$186,MATCH("男"&$A14&"-4",計算用!$AN$2:$AN$186,0)),"")) | N14: =IF($A14="","",IFERROR(INDEX(計算用!$M$2:$M$186,MATCH("男"&$A14&"-4",計算用!$AN$2:$AN$186,0)),"")) | O14: =IF($A14="","",IFERROR(INDEX(計算用!$I$2:$I$186,MATCH("男"&$A14&"-4",計算用!$AN$2:$AN$186,0)),"")) | Q14: =IF(ROW()-3<=計算用!$Q$11,ROW()-3,"") | R14: =IF($Q14="","",INDEX(計算用!$AC$2:$AC$51,$Q14)) | S14: =IF($Q14="","","赤"&INDEX(計算用!$AF$2:$AF$51,$Q14)&"白"&INDEX(計算用!$AG$2:$AG$51,$Q14)) | T14: =IF($Q14="","",IFERROR(INDEX(計算用!$D$2:$D$186,MATCH("女"&$Q14&"-1",計算用!$AN$2:$AN$186,0)),"")) | U14: =IF($Q14="","",IFERROR(INDEX(計算用!$M$2:$M$186,MATCH("女"&$Q14&"-1",計算用!$AN$2:$AN$186,0)),"")) | V14: =IF($Q14="","",IFERROR(INDEX(計算用!$I$2:$I$186,MATCH("女"&$Q14&"-1",計算用!$AN$2:$AN$186,0)),"")) | W14: =IF($Q14="","",IFERROR(INDEX(計算用!$D$2:$D$186,MATCH("女"&$Q14&"-2",計算用!$AN$2:$AN$186,0)),"")) | X14: =IF($Q14="","",IFERROR(INDEX(計算用!$M$2:$M$186,MATCH("女"&$Q14&"-2",計算用!$AN$2:$AN$186,0)),"")) | Y14: =IF($Q14="","",IFERROR(INDEX(計算用!$I$2:$I$186,MATCH("女"&$Q14&"-2",計算用!$AN$2:$AN$186,0)),"")) | Z14: =IF($Q14="","",IFERROR(INDEX(計算用!$D$2:$D$186,MATCH("女"&$Q14&"-3",計算用!$AN$2:$AN$186,0)),"")) | AA14: =IF($Q14="","",IFERROR(INDEX(計算用!$M$2:$M$186,MATCH("女"&$Q14&"-3",計算用!$AN$2:$AN$186,0)),"")) | AB14: =IF($Q14="","",IFERROR(INDEX(計算用!$I$2:$I$186,MATCH("女"&$Q14&"-3",計算用!$AN$2:$AN$186,0)),"")) | AC14: =IF($Q14="","",IFERROR(INDEX(計算用!$D$2:$D$186,MATCH("女"&$Q14&"-4",計算用!$AN$2:$AN$186,0)),"")) | AD14: =IF($Q14="","",IFERROR(INDEX(計算用!$M$2:$M$186,MATCH("女"&$Q14&"-4",計算用!$AN$2:$AN$186,0)),"")) | AE14: =IF($Q14="","",IFERROR(INDEX(計算用!$I$2:$I$186,MATCH("女"&$Q14&"-4",計算用!$AN$2:$AN$186,0)),""))
A15: =IF(ROW()-3<=計算用!$Q$9,ROW()-3,"") | B15: =IF($A15="","",INDEX(計算用!$T$2:$T$51,$A15)) | C15: =IF($A15="","","赤"&INDEX(計算用!$W$2:$W$51,$A15)&"白"&INDEX(計算用!$X$2:$X$51,$A15)) | D15: =IF($A15="","",IFERROR(INDEX(計算用!$D$2:$D$186,MATCH("男"&$A15&"-1",計算用!$AN$2:$AN$186,0)),"")) | E15: =IF($A15="","",IFERROR(INDEX(計算用!$M$2:$M$186,MATCH("男"&$A15&"-1",計算用!$AN$2:$AN$186,0)),"")) | F15: =IF($A15="","",IFERROR(INDEX(計算用!$I$2:$I$186,MATCH("男"&$A15&"-1",計算用!$AN$2:$AN$186,0)),"")) | G15: =IF($A15="","",IFERROR(INDEX(計算用!$D$2:$D$186,MATCH("男"&$A15&"-2",計算用!$AN$2:$AN$186,0)),"")) | H15: =IF($A15="","",IFERROR(INDEX(計算用!$M$2:$M$186,MATCH("男"&$A15&"-2",計算用!$AN$2:$AN$186,0)),"")) | I15: =IF($A15="","",IFERROR(INDEX(計算用!$I$2:$I$186,MATCH("男"&$A15&"-2",計算用!$AN$2:$AN$186,0)),"")) | J15: =IF($A15="","",IFERROR(INDEX(計算用!$D$2:$D$186,MATCH("男"&$A15&"-3",計算用!$AN$2:$AN$186,0)),"")) | K15: =IF($A15="","",IFERROR(INDEX(計算用!$M$2:$M$186,MATCH("男"&$A15&"-3",計算用!$AN$2:$AN$186,0)),"")) | L15: =IF($A15="","",IFERROR(INDEX(計算用!$I$2:$I$186,MATCH("男"&$A15&"-3",計算用!$AN$2:$AN$186,0)),"")) | M15: =IF($A15="","",IFERROR(INDEX(計算用!$D$2:$D$186,MATCH("男"&$A15&"-4",計算用!$AN$2:$AN$186,0)),"")) | N15: =IF($A15="","",IFERROR(INDEX(計算用!$M$2:$M$186,MATCH("男"&$A15&"-4",計算用!$AN$2:$AN$186,0)),"")) | O15: =IF($A15="","",IFERROR(INDEX(計算用!$I$2:$I$186,MATCH("男"&$A15&"-4",計算用!$AN$2:$AN$186,0)),"")) | Q15: =IF(ROW()-3<=計算用!$Q$11,ROW()-3,"") | R15: =IF($Q15="","",INDEX(計算用!$AC$2:$AC$51,$Q15)) | S15: =IF($Q15="","","赤"&INDEX(計算用!$AF$2:$AF$51,$Q15)&"白"&INDEX(計算用!$AG$2:$AG$51,$Q15)) | T15: =IF($Q15="","",IFERROR(INDEX(計算用!$D$2:$D$186,MATCH("女"&$Q15&"-1",計算用!$AN$2:$AN$186,0)),"")) | U15: =IF($Q15="","",IFERROR(INDEX(計算用!$M$2:$M$186,MATCH("女"&$Q15&"-1",計算用!$AN$2:$AN$186,0)),"")) | V15: =IF($Q15="","",IFERROR(INDEX(計算用!$I$2:$I$186,MATCH("女"&$Q15&"-1",計算用!$AN$2:$AN$186,0)),"")) | W15: =IF($Q15="","",IFERROR(INDEX(計算用!$D$2:$D$186,MATCH("女"&$Q15&"-2",計算用!$AN$2:$AN$186,0)),"")) | X15: =IF($Q15="","",IFERROR(INDEX(計算用!$M$2:$M$186,MATCH("女"&$Q15&"-2",計算用!$AN$2:$AN$186,0)),"")) | Y15: =IF($Q15="","",IFERROR(INDEX(計算用!$I$2:$I$186,MATCH("女"&$Q15&"-2",計算用!$AN$2:$AN$186,0)),"")) | Z15: =IF($Q15="","",IFERROR(INDEX(計算用!$D$2:$D$186,MATCH("女"&$Q15&"-3",計算用!$AN$2:$AN$186,0)),"")) | AA15: =IF($Q15="","",IFERROR(INDEX(計算用!$M$2:$M$186,MATCH("女"&$Q15&"-3",計算用!$AN$2:$AN$186,0)),"")) | AB15: =IF($Q15="","",IFERROR(INDEX(計算用!$I$2:$I$186,MATCH("女"&$Q15&"-3",計算用!$AN$2:$AN$186,0)),"")) | AC15: =IF($Q15="","",IFERROR(INDEX(計算用!$D$2:$D$186,MATCH("女"&$Q15&"-4",計算用!$AN$2:$AN$186,0)),"")) | AD15: =IF($Q15="","",IFERROR(INDEX(計算用!$M$2:$M$186,MATCH("女"&$Q15&"-4",計算用!$AN$2:$AN$186,0)),"")) | AE15: =IF($Q15="","",IFERROR(INDEX(計算用!$I$2:$I$186,MATCH("女"&$Q15&"-4",計算用!$AN$2:$AN$186,0)),""))
... A53: =IF(ROW()-3<=計算用!$Q$9,ROW()-3,"") | B53: =IF($A53="","",INDEX(計算用!$T$2:$T$51,$A53)) | C53: =IF($A53="","","赤"&INDEX(計算用!$W$2:$W$51,$A53)&"白"&INDEX(計算用!$X$2:$X$51,$A53)) | D53: =IF($A53="","",IFERROR(INDEX(計算用!$D$2:$D$186,MATCH("男"&$A53&"-1",計算用!$AN$2:$AN$186,0)),"")) | E53: =IF($A53="","",IFERROR(INDEX(計算用!$M$2:$M$186,MATCH("男"&$A53&"-1",計算用!$AN$2:$AN$186,0)),"")) | F53: =IF($A53="","",IFERROR(INDEX(計算用!$I$2:$I$186,MATCH("男"&$A53&"-1",計算用!$AN$2:$AN$186,0)),"")) | G53: =IF($A53="","",IFERROR(INDEX(計算用!$D$2:$D$186,MATCH("男"&$A53&"-2",計算用!$AN$2:$AN$186,0)),"")) | H53: =IF($A53="","",IFERROR(INDEX(計算用!$M$2:$M$186,MATCH("男"&$A53&"-2",計算用!$AN$2:$AN$186,0)),"")) | I53: =IF($A53="","",IFERROR(INDEX(計算用!$I$2:$I$186,MATCH("男"&$A53&"-2",計算用!$AN$2:$AN$186,0)),"")) | J53: =IF($A53="","",IFERROR(INDEX(計算用!$D$2:$D$186,MATCH("男"&$A53&"-3",計算用!$AN$2:$AN$186,0)),"")) | K53: =IF($A53="","",IFERROR(INDEX(計算用!$M$2:$M$186,MATCH("男"&$A53&"-3",計算用!$AN$2:$AN$186,0)),"")) | L53: =IF($A53="","",IFERROR(INDEX(計算用!$I$2:$I$186,MATCH("男"&$A53&"-3",計算用!$AN$2:$AN$186,0)),"")) | M53: =IF($A53="","",IFERROR(INDEX(計算用!$D$2:$D$186,MATCH("男"&$A53&"-4",計算用!$AN$2:$AN$186,0)),"")) | N53: =IF($A53="","",IFERROR(INDEX(計算用!$M$2:$M$186,MATCH("男"&$A53&"-4",計算用!$AN$2:$AN$186,0)),"")) | O53: =IF($A53="","",IFERROR(INDEX(計算用!$I$2:$I$186,MATCH("男"&$A53&"-4",計算用!$AN$2:$AN$186,0)),"")) | Q53: =IF(ROW()-3<=計算用!$Q$11,ROW()-3,"") | R53: =IF($Q53="","",INDEX(計算用!$AC$2:$AC$51,$Q53)) | S53: =IF($Q53="","","赤"&INDEX(計算用!$AF$2:$AF$51,$Q53)&"白"&INDEX(計算用!$AG$2:$AG$51,$Q53)) | T53: =IF($Q53="","",IFERROR(INDEX(計算用!$D$2:$D$186,MATCH("女"&$Q53&"-1",計算用!$AN$2:$AN$186,0)),"")) | U53: =IF($Q53="","",IFERROR(INDEX(計算用!$M$2:$M$186,MATCH("女"&$Q53&"-1",計算用!$AN$2:$AN$186,0)),"")) | V53: =IF($Q53="","",IFERROR(INDEX(計算用!$I$2:$I$186,MATCH("女"&$Q53&"-1",計算用!$AN$2:$AN$186,0)),"")) | W53: =IF($Q53="","",IFERROR(INDEX(計算用!$D$2:$D$186,MATCH("女"&$Q53&"-2",計算用!$AN$2:$AN$186,0)),"")) | X53: =IF($Q53="","",IFERROR(INDEX(計算用!$M$2:$M$186,MATCH("女"&$Q53&"-2",計算用!$AN$2:$AN$186,0)),"")) | Y53: =IF($Q53="","",IFERROR(INDEX(計算用!$I$2:$I$186,MATCH("女"&$Q53&"-2",計算用!$AN$2:$AN$186,0)),"")) | Z53: =IF($Q53="","",IFERROR(INDEX(計算用!$D$2:$D$186,MATCH("女"&$Q53&"-3",計算用!$AN$2:$AN$186,0)),"")) | AA53: =IF($Q53="","",IFERROR(INDEX(計算用!$M$2:$M$186,MATCH("女"&$Q53&"-3",計算用!$AN$2:$AN$186,0)),"")) | AB53: =IF($Q53="","",IFERROR(INDEX(計算用!$I$2:$I$186,MATCH("女"&$Q53&"-3",計算用!$AN$2:$AN$186,0)),"")) | AC53: =IF($Q53="","",IFERROR(INDEX(計算用!$D$2:$D$186,MATCH("女"&$Q53&"-4",計算用!$AN$2:$AN$186,0)),"")) | AD53: =IF($Q53="","",IFERROR(INDEX(計算用!$M$2:$M$186,MATCH("女"&$Q53&"-4",計算用!$AN$2:$AN$186,0)),"")) | AE53: =IF($Q53="","",IFERROR(INDEX(計算用!$I$2:$I$186,MATCH("女"&$Q53&"-4",計算用!$AN$2:$AN$186,0)),""))

Sheet 手直し
A1: 手直し | C1: ① 右の「自動の組（コピー用）」S6:Z55 をコピーし、B6 に「値として貼り付け」します（右クリック →「貼り付けのオプション」の「値」）。 ② 名前を切り取り・貼り付けして、組を直します。結果は「決定版」シートに出ます。 ※名簿やタイムを直したときは、もう一度①からやり直してください。
B2: ="男子：自動 "&計算用!$Q$9&"組 → 手直し "&計算用!$Q$13&"組" | E2: =IF(計算用!$Q$15=0,IF(計算用!$Q$13=0,"","確認：問題なし"),"確認："&IF(計算用!$Q$17>0,"入っていない人 "&計算用!$Q$17&"人 ","")&IF(計算用!$Q$19>0,"2回以上入っている人 "&計算用!$Q$19&"人 ","")&IF(計算用!$Q$21>0,"名簿にない名前 "&計算用!$Q$21&"こ ","")&IF(計算用!$Q$23>0,"同じ名前の人がいます（区別できません）",""))
B3: ="女子：自動 "&計算用!$Q$11&"組 → 手直し "&計算用!$Q$14&"組" | E3: =IF(計算用!$Q$16=0,IF(計算用!$Q$14=0,"","確認：問題なし"),"確認："&IF(計算用!$Q$18>0,"入っていない人 "&計算用!$Q$18&"人 ","")&IF(計算用!$Q$20>0,"2回以上入っている人 "&計算用!$Q$20&"人 ","")&IF(計算用!$Q$22>0,"名簿にない名前 "&計算用!$Q$22&"こ ","")&IF(計算用!$Q$24>0,"同じ名前の人がいます（区別できません）","")) | S3: 自動の組（コピー用）
A4: 組 | B4: 男子 | F4: 女子 | K4: 男子 | M4: 女子 | P4: 入っていない人 | S4: 男子 | W4: 女子
B5: 1人目 | C5: 2人目 | D5: 3人目 | E5: 4人目 | F5: 1人目 | G5: 2人目 | H5: 3人目 | I5: 4人目 | K5: 人数 | L5: 内訳 | M5: 人数 | N5: 内訳 | P5: 男子 | Q5: 女子 | S5: 1人目 | T5: 2人目 | U5: 3人目 | V5: 4人目 | W5: 1人目 | X5: 2人目 | Y5: 3人目 | Z5: 4人目
A6: 1 | B6: 山本 けんた | C6: 森 りく | D6: 村上 かいと | E6: 伊藤 たいが | F6: 田中 あおい | G6: 高橋 ひまり | H6: 中村 ゆな | I6: 森 みお | K6: =COUNTIF(B6:E6,"?*") | L6: =IF(K6=0,"","赤"&SUMPRODUCT(COUNTIFS(計算用!$AO$2:$AO$186,"男"&B6:E6,計算用!$I$2:$I$186,"赤"))&"白"&SUMPRODUCT(COUNTIFS(計算用!$AO$2:$AO$186,"男"&B6:E6,計算用!$I$2:$I$186,"白"))) | M6: =COUNTIF(F6:I6,"?*") | N6: =IF(M6=0,"","赤"&SUMPRODUCT(COUNTIFS(計算用!$AO$2:$AO$186,"女"&F6:I6,計算用!$I$2:$I$186,"赤"))&"白"&SUMPRODUCT(COUNTIFS(計算用!$AO$2:$AO$186,"女"&F6:I6,計算用!$I$2:$I$186,"白"))) | P6: =IFERROR(INDEX(計算用!$D$2:$D$186,MATCH(1,計算用!$AR$2:$AR$186,0))&"（"&INDEX(計算用!$M$2:$M$186,MATCH(1,計算用!$AR$2:$AR$186,0))&"）","") | Q6: =IFERROR(INDEX(計算用!$D$2:$D$186,MATCH(1,計算用!$AS$2:$AS$186,0))&"（"&INDEX(計算用!$M$2:$M$186,MATCH(1,計算用!$AS$2:$AS$186,0))&"）","") | S6: ='4人組'!D4&"" | T6: ='4人組'!G4&"" | U6: ='4人組'!J4&"" | V6: ='4人組'!M4&"" | W6: ='4人組'!T4&"" | X6: ='4人組'!W4&"" | Y6: ='4人組'!Z4&"" | Z6: ='4人組'!AC4&""
A7: 2 | B7: 吉田 あおい | C7: 井上 いつき | D7: 前田 かいと | E7: 高橋 さく | F7: 渡辺 めい | G7: 小林 ほのか | H7: 清水 ひな | I7: 山田 ゆな | K7: =COUNTIF(B7:E7,"?*") | L7: =IF(K7=0,"","赤"&SUMPRODUCT(COUNTIFS(計算用!$AO$2:$AO$186,"男"&B7:E7,計算用!$I$2:$I$186,"赤"))&"白"&SUMPRODUCT(COUNTIFS(計算用!$AO$2:$AO$186,"男"&B7:E7,計算用!$I$2:$I$186,"白"))) | M7: =COUNTIF(F7:I7,"?*") | N7: =IF(M7=0,"","赤"&SUMPRODUCT(COUNTIFS(計算用!$AO$2:$AO$186,"女"&F7:I7,計算用!$I$2:$I$186,"赤"))&"白"&SUMPRODUCT(COUNTIFS(計算用!$AO$2:$AO$186,"女"&F7:I7,計算用!$I$2:$I$186,"白"))) | P7: =IFERROR(INDEX(計算用!$D$2:$D$186,MATCH(2,計算用!$AR$2:$AR$186,0))&"（"&INDEX(計算用!$M$2:$M$186,MATCH(2,計算用!$AR$2:$AR$186,0))&"）","") | Q7: =IFERROR(INDEX(計算用!$D$2:$D$186,MATCH(2,計算用!$AS$2:$AS$186,0))&"（"&INDEX(計算用!$M$2:$M$186,MATCH(2,計算用!$AS$2:$AS$186,0))&"）","") | S7: ='4人組'!D5&"" | T7: ='4人組'!G5&"" | U7: ='4人組'!J5&"" | V7: ='4人組'!M5&"" | W7: ='4人組'!T5&"" | X7: ='4人組'!W5&"" | Y7: ='4人組'!Z5&"" | Z7: ='4人組'!AC5&""
A8: 3 | B8: 近藤 りく | C8: 高橋 ひなた | D8: 木村 さく | E8: 田中 こうき | F8: 木村 ひまり | G8: 加藤 ひな | H8: 山本 かのん | I8: 後藤 ゆな | K8: =COUNTIF(B8:E8,"?*") | L8: =IF(K8=0,"","赤"&SUMPRODUCT(COUNTIFS(計算用!$AO$2:$AO$186,"男"&B8:E8,計算用!$I$2:$I$186,"赤"))&"白"&SUMPRODUCT(COUNTIFS(計算用!$AO$2:$AO$186,"男"&B8:E8,計算用!$I$2:$I$186,"白"))) | M8: =COUNTIF(F8:I8,"?*") | N8: =IF(M8=0,"","赤"&SUMPRODUCT(COUNTIFS(計算用!$AO$2:$AO$186,"女"&F8:I8,計算用!$I$2:$I$186,"赤"))&"白"&SUMPRODUCT(COUNTIFS(計算用!$AO$2:$AO$186,"女"&F8:I8,計算用!$I$2:$I$186,"白"))) | P8: =IFERROR(INDEX(計算用!$D$2:$D$186,MATCH(3,計算用!$AR$2:$AR$186,0))&"（"&INDEX(計算用!$M$2:$M$186,MATCH(3,計算用!$AR$2:$AR$186,0))&"）","") | Q8: =IFERROR(INDEX(計算用!$D$2:$D$186,MATCH(3,計算用!$AS$2:$AS$186,0))&"（"&INDEX(計算用!$M$2:$M$186,MATCH(3,計算用!$AS$2:$AS$186,0))&"）","") | S8: ='4人組'!D6&"" | T8: ='4人組'!G6&"" | U8: ='4人組'!J6&"" | V8: ='4人組'!M6&"" | W8: ='4人組'!T6&"" | X8: ='4人組'!W6&"" | Y8: ='4人組'!Z6&"" | Z8: ='4人組'!AC6&""
A9: 4 | B9: 伊藤 りょう | C9: 清水 そら | D9: 清水 しょう | E9: 森 みなと | F9: 前田 ひな | G9: 前田 えま | H9: 井上 ほのか | I9: 後藤 かのん | K9: =COUNTIF(B9:E9,"?*") | L9: =IF(K9=0,"","赤"&SUMPRODUCT(COUNTIFS(計算用!$AO$2:$AO$186,"男"&B9:E9,計算用!$I$2:$I$186,"赤"))&"白"&SUMPRODUCT(COUNTIFS(計算用!$AO$2:$AO$186,"男"&B9:E9,計算用!$I$2:$I$186,"白"))) | M9: =COUNTIF(F9:I9,"?*") | N9: =IF(M9=0,"","赤"&SUMPRODUCT(COUNTIFS(計算用!$AO$2:$AO$186,"女"&F9:I9,計算用!$I$2:$I$186,"赤"))&"白"&SUMPRODUCT(COUNTIFS(計算用!$AO$2:$AO$186,"女"&F9:I9,計算用!$I$2:$I$186,"白"))) | P9: =IFERROR(INDEX(計算用!$D$2:$D$186,MATCH(4,計算用!$AR$2:$AR$186,0))&"（"&INDEX(計算用!$M$2:$M$186,MATCH(4,計算用!$AR$2:$AR$186,0))&"）","") | Q9: =IFERROR(INDEX(計算用!$D$2:$D$186,MATCH(4,計算用!$AS$2:$AS$186,0))&"（"&INDEX(計算用!$M$2:$M$186,MATCH(4,計算用!$AS$2:$AS$186,0))&"）","") | S9: ='4人組'!D7&"" | T9: ='4人組'!G7&"" | U9: ='4人組'!J7&"" | V9: ='4人組'!M7&"" | W9: ='4人組'!T7&"" | X9: ='4人組'!W7&"" | Y9: ='4人組'!Z7&"" | Z9: ='4人組'!AC7&""
A10: 5 | B10: 石川 みなと | C10: 佐藤 けんた | D10: 山本 つばさ | E10: 佐藤 れん | F10: 中村 はな | G10: 石川 めい | H10: 加藤 ことね | I10: 木村 ゆな | K10: =COUNTIF(B10:E10,"?*") | L10: =IF(K10=0,"","赤"&SUMPRODUCT(COUNTIFS(計算用!$AO$2:$AO$186,"男"&B10:E10,計算用!$I$2:$I$186,"赤"))&"白"&SUMPRODUCT(COUNTIFS(計算用!$AO$2:$AO$186,"男"&B10:E10,計算用!$I$2:$I$186,"白"))) | M10: =COUNTIF(F10:I10,"?*") | N10: =IF(M10=0,"","赤"&SUMPRODUCT(COUNTIFS(計算用!$AO$2:$AO$186,"女"&F10:I10,計算用!$I$2:$I$186,"赤"))&"白"&SUMPRODUCT(COUNTIFS(計算用!$AO$2:$AO$186,"女"&F10:I10,計算用!$I$2:$I$186,"白"))) | P10: =IFERROR(INDEX(計算用!$D$2:$D$186,MATCH(5,計算用!$AR$2:$AR$186,0))&"（"&INDEX(計算用!$M$2:$M$186,MATCH(5,計算用!$AR$2:$AR$186,0))&"）","") | Q10: =IFERROR(INDEX(計算用!$D$2:$D$186,MATCH(5,計算用!$AS$2:$AS$186,0))&"（"&INDEX(計算用!$M$2:$M$186,MATCH(5,計算用!$AS$2:$AS$186,0))&"）","") | S10: ='4人組'!D8&"" | T10: ='4人組'!G8&"" | U10: ='4人組'!J8&"" | V10: ='4人組'!M8&"" | W10: ='4人組'!T8&"" | X10: ='4人組'!W8&"" | Y10: ='4人組'!Z8&"" | Z10: ='4人組'!AC8&""
A11: 6 | B11: 佐藤 しょう | C11: 木村 ひなた | D11: 中村 りく | E11: 鈴木 りく | F11: 清水 こはる | G11: 石川 さら | H11: 斎藤 みお | I11: 小林 ゆな | K11: =COUNTIF(B11:E11,"?*") | L11: =IF(K11=0,"","赤"&SUMPRODUCT(COUNTIFS(計算用!$AO$2:$AO$186,"男"&B11:E11,計算用!$I$2:$I$186,"赤"))&"白"&SUMPRODUCT(COUNTIFS(計算用!$AO$2:$AO$186,"男"&B11:E11,計算用!$I$2:$I$186,"白"))) | M11: =COUNTIF(F11:I11,"?*") | N11: =IF(M11=0,"","赤"&SUMPRODUCT(COUNTIFS(計算用!$AO$2:$AO$186,"女"&F11:I11,計算用!$I$2:$I$186,"赤"))&"白"&SUMPRODUCT(COUNTIFS(計算用!$AO$2:$AO$186,"女"&F11:I11,計算用!$I$2:$I$186,"白"))) | P11: =IFERROR(INDEX(計算用!$D$2:$D$186,MATCH(6,計算用!$AR$2:$AR$186,0))&"（"&INDEX(計算用!$M$2:$M$186,MATCH(6,計算用!$AR$2:$AR$186,0))&"）","") | Q11: =IFERROR(INDEX(計算用!$D$2:$D$186,MATCH(6,計算用!$AS$2:$AS$186,0))&"（"&INDEX(計算用!$M$2:$M$186,MATCH(6,計算用!$AS$2:$AS$186,0))&"）","") | S11: ='4人組'!D9&"" | T11: ='4人組'!G9&"" | U11: ='4人組'!J9&"" | V11: ='4人組'!M9&"" | W11: ='4人組'!T9&"" | X11: ='4人組'!W9&"" | Y11: ='4人組'!Z9&"" | Z11: ='4人組'!AC9&""
A12: 7 | B12: 鈴木 はると | C12: 高橋 たいが | D12: 鈴木 つばさ | E12: 橋本 あおい | F12: 井上 ひまり | G12: 伊藤 ひまり | H12: 山田 あかり | I12: 伊藤 りん | K12: =COUNTIF(B12:E12,"?*") | L12: =IF(K12=0,"","赤"&SUMPRODUCT(COUNTIFS(計算用!$AO$2:$AO$186,"男"&B12:E12,計算用!$I$2:$I$186,"赤"))&"白"&SUMPRODUCT(COUNTIFS(計算用!$AO$2:$AO$186,"男"&B12:E12,計算用!$I$2:$I$186,"白"))) | M12: =COUNTIF(F12:I12,"?*") | N12: =IF(M12=0,"","赤"&SUMPRODUCT(COUNTIFS(計算用!$AO$2:$AO$186,"女"&F12:I12,計算用!$I$2:$I$186,"赤"))&"白"&SUMPRODUCT(COUNTIFS(計算用!$AO$2:$AO$186,"女"&F12:I12,計算用!$I$2:$I$186,"白"))) | P12: =IFERROR(INDEX(計算用!$D$2:$D$186,MATCH(7,計算用!$AR$2:$AR$186,0))&"（"&INDEX(計算用!$M$2:$M$186,MATCH(7,計算用!$AR$2:$AR$186,0))&"）","") | Q12: =IFERROR(INDEX(計算用!$D$2:$D$186,MATCH(7,計算用!$AS$2:$AS$186,0))&"（"&INDEX(計算用!$M$2:$M$186,MATCH(7,計算用!$AS$2:$AS$186,0))&"）","") | S12: ='4人組'!D10&"" | T12: ='4人組'!G10&"" | U12: ='4人組'!J10&"" | V12: ='4人組'!M10&"" | W12: ='4人組'!T10&"" | X12: ='4人組'!W10&"" | Y12: ='4人組'!Z10&"" | Z12: ='4人組'!AC10&""
