Workbook

Sheet 使い方
B1: 委員会名簿作成ツール 使い方
B3: ■ 色のきまり（入力する人で色が分かれています）
B4: うす紫 | C4: ＝委員会担当が入力する所（設定）
B5: 黄色 | C5: ＝担任が入力する所（6年・5年シートの名前と委員会）
B6: それ以外のセルには数式が入っているので保護しています（「校閲」→「シート保護の解除」で外せます。パスワードなし）。各シートの左上にも、だれが入力するシートかを表示しています。
B8: ■ 【委員会担当】新年度のはじめにすること
B9: ① 【設定】年度、学年（6・5）、組（名前・色・人数）、委員会（名前・担当・活動場所）を入力します。
C10: ・組の表に書いた組の数だけ、6年・5年シートに組の枠ができます。「人数」の数だけ、番号の枠ができます。
C11: ・委員会を増やす：空いている行に書きこむ 減らす：行の中身を消す 名前を変える：書きかえる
B13: ■ 【担任】クラスで委員会を決めたらすること
B14: ② 【6年】【5年】自分の組の列に、子どもの「名前」と「委員会」（プルダウン）を入れます。番号は自動で入ります。
C15: ・名前は、名簿からコピーして「値の貼り付け」をしてもかまいません。
C16: ・名前があるのに委員会が空欄の所は、うすい赤になります。設定にない委員会名は赤になります。
B18: ■ 【委員会担当】全部の組が入力し終わったらすること
B19: ③ 【人数チェック】委員会ごとの人数（6年・5年）と、委員会が未入力の子の数を確かめます。
B20: ④ 【一覧名簿】【委員会①〜⑳】を印刷します。6年→5年、組の順、番号順に並びます。
C21: ・一覧名簿はA3横。上段（①〜⑩）が1ページ目、下段（⑪〜⑳）が2ページ目です。委員会が10以下なら1ページ目だけ印刷します。
C22: ・委員会①〜⑳のタブ名は、右クリック→「名前の変更」で「飼育」などに変えてもかまいません。
B24: ■ 上限
B25: 委員会 20／1学年の組 8／1組 45人／1つの委員会 50人
B27: ■ このファイルについて
B28: これは白紙のファイルです。設定シートから入力してください。

Sheet 設定
A1: 設定 | D1: 【入力：委員会担当】うす紫のセル
A3: 年度
A4: 呼び名 | B4: 委員会
A6: 学年の設定
A7: 上の学年 | B7: 6
A8: 下の学年 | B8: 5
A9: 組の設定（上から並び順。学年ごとに最大8組） | H9: 委員会の設定（上から順に「委員会①、②…」のシートに入ります）
A10: 学年 | B10: 組 | C10: 名簿での表示 | D10: 色 | E10: 人数 | H10: No. | I10: 委員会名 | J10: 担当 | K10: 活動場所
A11: =$B$7 | C11: =IF(B11="","",A11&B11) | H11: 1
A12: =$B$7 | C12: =IF(B12="","",A12&B12) | H12: 2
A13: =$B$7 | C13: =IF(B13="","",A13&B13) | H13: 3
A14: =$B$7 | C14: =IF(B14="","",A14&B14) | H14: 4
A15: =$B$7 | C15: =IF(B15="","",A15&B15) | H15: 5
A16: =$B$7 | C16: =IF(B16="","",A16&B16) | H16: 6
A17: =$B$7 | C17: =IF(B17="","",A17&B17) | H17: 7
A18: =$B$7 | C18: =IF(B18="","",A18&B18) | H18: 8
A19: =$B$8 | C19: =IF(B19="","",A19&B19) | H19: 9
A20: =$B$8 | C20: =IF(B20="","",A20&B20) | H20: 10
A21: =$B$8 | C21: =IF(B21="","",A21&B21) | H21: 11
A22: =$B$8 | C22: =IF(B22="","",A22&B22) | H22: 12
A23: =$B$8 | C23: =IF(B23="","",A23&B23) | H23: 13
A24: =$B$8 | C24: =IF(B24="","",A24&B24) | H24: 14
A25: =$B$8 | C25: =IF(B25="","",A25&B25) | H25: 15
A26: =$B$8 | C26: =IF(B26="","",A26&B26) | H26: 16
H27: 17
A28: ※ 書いた組の数がクラス数になります。「人数」の数だけ番号の枠ができます（最大45人）。 | H28: 18
A29: ※「名簿での表示」は「6-1」などに書きかえてもかまいません。「色」は組の文字の色です（空欄なら黒）。 | H29: 19
H30: 20

Sheet 6年
A1: =設定!$B$3&" "&設定!$B$7&"年 "&設定!$B$4&"入力" | E1: 【入力：担任】黄色のセル
A3: =IF(設定!$B$11="","",設定!$C$11) | D3: =IF(設定!$B$12="","",設定!$C$12) | G3: =IF(設定!$B$13="","",設定!$C$13) | J3: =IF(設定!$B$14="","",設定!$C$14) | M3: =IF(設定!$B$15="","",設定!$C$15) | P3: =IF(設定!$B$16="","",設定!$C$16) | S3: =IF(設定!$B$17="","",設定!$C$17) | V3: =IF(設定!$B$18="","",設定!$C$18)
A4: 番号 | B4: 名前 | C4: 委員会 | D4: 番号 | E4: 名前 | F4: 委員会 | G4: 番号 | H4: 名前 | I4: 委員会 | J4: 番号 | K4: 名前 | L4: 委員会 | M4: 番号 | N4: 名前 | O4: 委員会 | P4: 番号 | Q4: 名前 | R4: 委員会 | S4: 番号 | T4: 名前 | U4: 委員会 | V4: 番号 | W4: 名前 | X4: 委員会
A5: =IF(AND(設定!$B$11<>"",1<=N(設定!$E$11)),1,"") | D5: =IF(AND(設定!$B$12<>"",1<=N(設定!$E$12)),1,"") | G5: =IF(AND(設定!$B$13<>"",1<=N(設定!$E$13)),1,"") | J5: =IF(AND(設定!$B$14<>"",1<=N(設定!$E$14)),1,"") | M5: =IF(AND(設定!$B$15<>"",1<=N(設定!$E$15)),1,"") | P5: =IF(AND(設定!$B$16<>"",1<=N(設定!$E$16)),1,"") | S5: =IF(AND(設定!$B$17<>"",1<=N(設定!$E$17)),1,"") | V5: =IF(AND(設定!$B$18<>"",1<=N(設定!$E$18)),1,"")
A6: =IF(AND(設定!$B$11<>"",2<=N(設定!$E$11)),2,"") | D6: =IF(AND(設定!$B$12<>"",2<=N(設定!$E$12)),2,"") | G6: =IF(AND(設定!$B$13<>"",2<=N(設定!$E$13)),2,"") | J6: =IF(AND(設定!$B$14<>"",2<=N(設定!$E$14)),2,"") | M6: =IF(AND(設定!$B$15<>"",2<=N(設定!$E$15)),2,"") | P6: =IF(AND(設定!$B$16<>"",2<=N(設定!$E$16)),2,"") | S6: =IF(AND(設定!$B$17<>"",2<=N(設定!$E$17)),2,"") | V6: =IF(AND(設定!$B$18<>"",2<=N(設定!$E$18)),2,"")
A7: =IF(AND(設定!$B$11<>"",3<=N(設定!$E$11)),3,"") | D7: =IF(AND(設定!$B$12<>"",3<=N(設定!$E$12)),3,"") | G7: =IF(AND(設定!$B$13<>"",3<=N(設定!$E$13)),3,"") | J7: =IF(AND(設定!$B$14<>"",3<=N(設定!$E$14)),3,"") | M7: =IF(AND(設定!$B$15<>"",3<=N(設定!$E$15)),3,"") | P7: =IF(AND(設定!$B$16<>"",3<=N(設定!$E$16)),3,"") | S7: =IF(AND(設定!$B$17<>"",3<=N(設定!$E$17)),3,"") | V7: =IF(AND(設定!$B$18<>"",3<=N(設定!$E$18)),3,"")
A8: =IF(AND(設定!$B$11<>"",4<=N(設定!$E$11)),4,"") | D8: =IF(AND(設定!$B$12<>"",4<=N(設定!$E$12)),4,"") | G8: =IF(AND(設定!$B$13<>"",4<=N(設定!$E$13)),4,"") | J8: =IF(AND(設定!$B$14<>"",4<=N(設定!$E$14)),4,"") | M8: =IF(AND(設定!$B$15<>"",4<=N(設定!$E$15)),4,"") | P8: =IF(AND(設定!$B$16<>"",4<=N(設定!$E$16)),4,"") | S8: =IF(AND(設定!$B$17<>"",4<=N(設定!$E$17)),4,"") | V8: =IF(AND(設定!$B$18<>"",4<=N(設定!$E$18)),4,"")
A9: =IF(AND(設定!$B$11<>"",5<=N(設定!$E$11)),5,"") | D9: =IF(AND(設定!$B$12<>"",5<=N(設定!$E$12)),5,"") | G9: =IF(AND(設定!$B$13<>"",5<=N(設定!$E$13)),5,"") | J9: =IF(AND(設定!$B$14<>"",5<=N(設定!$E$14)),5,"") | M9: =IF(AND(設定!$B$15<>"",5<=N(設定!$E$15)),5,"") | P9: =IF(AND(設定!$B$16<>"",5<=N(設定!$E$16)),5,"") | S9: =IF(AND(設定!$B$17<>"",5<=N(設定!$E$17)),5,"") | V9: =IF(AND(設定!$B$18<>"",5<=N(設定!$E$18)),5,"")
A10: =IF(AND(設定!$B$11<>"",6<=N(設定!$E$11)),6,"") | D10: =IF(AND(設定!$B$12<>"",6<=N(設定!$E$12)),6,"") | G10: =IF(AND(設定!$B$13<>"",6<=N(設定!$E$13)),6,"") | J10: =IF(AND(設定!$B$14<>"",6<=N(設定!$E$14)),6,"") | M10: =IF(AND(設定!$B$15<>"",6<=N(設定!$E$15)),6,"") | P10: =IF(AND(設定!$B$16<>"",6<=N(設定!$E$16)),6,"") | S10: =IF(AND(設定!$B$17<>"",6<=N(設定!$E$17)),6,"") | V10: =IF(AND(設定!$B$18<>"",6<=N(設定!$E$18)),6,"")
A11: =IF(AND(設定!$B$11<>"",7<=N(設定!$E$11)),7,"") | D11: =IF(AND(設定!$B$12<>"",7<=N(設定!$E$12)),7,"") | G11: =IF(AND(設定!$B$13<>"",7<=N(設定!$E$13)),7,"") | J11: =IF(AND(設定!$B$14<>"",7<=N(設定!$E$14)),7,"") | M11: =IF(AND(設定!$B$15<>"",7<=N(設定!$E$15)),7,"") | P11: =IF(AND(設定!$B$16<>"",7<=N(設定!$E$16)),7,"") | S11: =IF(AND(設定!$B$17<>"",7<=N(設定!$E$17)),7,"") | V11: =IF(AND(設定!$B$18<>"",7<=N(設定!$E$18)),7,"")
A12: =IF(AND(設定!$B$11<>"",8<=N(設定!$E$11)),8,"") | D12: =IF(AND(設定!$B$12<>"",8<=N(設定!$E$12)),8,"") | G12: =IF(AND(設定!$B$13<>"",8<=N(設定!$E$13)),8,"") | J12: =IF(AND(設定!$B$14<>"",8<=N(設定!$E$14)),8,"") | M12: =IF(AND(設定!$B$15<>"",8<=N(設定!$E$15)),8,"") | P12: =IF(AND(設定!$B$16<>"",8<=N(設定!$E$16)),8,"") | S12: =IF(AND(設定!$B$17<>"",8<=N(設定!$E$17)),8,"") | V12: =IF(AND(設定!$B$18<>"",8<=N(設定!$E$18)),8,"")
A13: =IF(AND(設定!$B$11<>"",9<=N(設定!$E$11)),9,"") | D13: =IF(AND(設定!$B$12<>"",9<=N(設定!$E$12)),9,"") | G13: =IF(AND(設定!$B$13<>"",9<=N(設定!$E$13)),9,"") | J13: =IF(AND(設定!$B$14<>"",9<=N(設定!$E$14)),9,"") | M13: =IF(AND(設定!$B$15<>"",9<=N(設定!$E$15)),9,"") | P13: =IF(AND(設定!$B$16<>"",9<=N(設定!$E$16)),9,"") | S13: =IF(AND(設定!$B$17<>"",9<=N(設定!$E$17)),9,"") | V13: =IF(AND(設定!$B$18<>"",9<=N(設定!$E$18)),9,"")
A14: =IF(AND(設定!$B$11<>"",10<=N(設定!$E$11)),10,"") | D14: =IF(AND(設定!$B$12<>"",10<=N(設定!$E$12)),10,"") | G14: =IF(AND(設定!$B$13<>"",10<=N(設定!$E$13)),10,"") | J14: =IF(AND(設定!$B$14<>"",10<=N(設定!$E$14)),10,"") | M14: =IF(AND(設定!$B$15<>"",10<=N(設定!$E$15)),10,"") | P14: =IF(AND(設定!$B$16<>"",10<=N(設定!$E$16)),10,"") | S14: =IF(AND(設定!$B$17<>"",10<=N(設定!$E$17)),10,"") | V14: =IF(AND(設定!$B$18<>"",10<=N(設定!$E$18)),10,"")
A15: =IF(AND(設定!$B$11<>"",11<=N(設定!$E$11)),11,"") | D15: =IF(AND(設定!$B$12<>"",11<=N(設定!$E$12)),11,"") | G15: =IF(AND(設定!$B$13<>"",11<=N(設定!$E$13)),11,"") | J15: =IF(AND(設定!$B$14<>"",11<=N(設定!$E$14)),11,"") | M15: =IF(AND(設定!$B$15<>"",11<=N(設定!$E$15)),11,"") | P15: =IF(AND(設定!$B$16<>"",11<=N(設定!$E$16)),11,"") | S15: =IF(AND(設定!$B$17<>"",11<=N(設定!$E$17)),11,"") | V15: =IF(AND(設定!$B$18<>"",11<=N(設定!$E$18)),11,"")
A16: =IF(AND(設定!$B$11<>"",12<=N(設定!$E$11)),12,"") | D16: =IF(AND(設定!$B$12<>"",12<=N(設定!$E$12)),12,"") | G16: =IF(AND(設定!$B$13<>"",12<=N(設定!$E$13)),12,"") | J16: =IF(AND(設定!$B$14<>"",12<=N(設定!$E$14)),12,"") | M16: =IF(AND(設定!$B$15<>"",12<=N(設定!$E$15)),12,"") | P16: =IF(AND(設定!$B$16<>"",12<=N(設定!$E$16)),12,"") | S16: =IF(AND(設定!$B$17<>"",12<=N(設定!$E$17)),12,"") | V16: =IF(AND(設定!$B$18<>"",12<=N(設定!$E$18)),12,"")
A17: =IF(AND(設定!$B$11<>"",13<=N(設定!$E$11)),13,"") | D17: =IF(AND(設定!$B$12<>"",13<=N(設定!$E$12)),13,"") | G17: =IF(AND(設定!$B$13<>"",13<=N(設定!$E$13)),13,"") | J17: =IF(AND(設定!$B$14<>"",13<=N(設定!$E$14)),13,"") | M17: =IF(AND(設定!$B$15<>"",13<=N(設定!$E$15)),13,"") | P17: =IF(AND(設定!$B$16<>"",13<=N(設定!$E$16)),13,"") | S17: =IF(AND(設定!$B$17<>"",13<=N(設定!$E$17)),13,"") | V17: =IF(AND(設定!$B$18<>"",13<=N(設定!$E$18)),13,"")
A18: =IF(AND(設定!$B$11<>"",14<=N(設定!$E$11)),14,"") | D18: =IF(AND(設定!$B$12<>"",14<=N(設定!$E$12)),14,"") | G18: =IF(AND(設定!$B$13<>"",14<=N(設定!$E$13)),14,"") | J18: =IF(AND(設定!$B$14<>"",14<=N(設定!$E$14)),14,"") | M18: =IF(AND(設定!$B$15<>"",14<=N(設定!$E$15)),14,"") | P18: =IF(AND(設定!$B$16<>"",14<=N(設定!$E$16)),14,"") | S18: =IF(AND(設定!$B$17<>"",14<=N(設定!$E$17)),14,"") | V18: =IF(AND(設定!$B$18<>"",14<=N(設定!$E$18)),14,"")
A19: =IF(AND(設定!$B$11<>"",15<=N(設定!$E$11)),15,"") | D19: =IF(AND(設定!$B$12<>"",15<=N(設定!$E$12)),15,"") | G19: =IF(AND(設定!$B$13<>"",15<=N(設定!$E$13)),15,"") | J19: =IF(AND(設定!$B$14<>"",15<=N(設定!$E$14)),15,"") | M19: =IF(AND(設定!$B$15<>"",15<=N(設定!$E$15)),15,"") | P19: =IF(AND(設定!$B$16<>"",15<=N(設定!$E$16)),15,"") | S19: =IF(AND(設定!$B$17<>"",15<=N(設定!$E$17)),15,"") | V19: =IF(AND(設定!$B$18<>"",15<=N(設定!$E$18)),15,"")
A20: =IF(AND(設定!$B$11<>"",16<=N(設定!$E$11)),16,"") | D20: =IF(AND(設定!$B$12<>"",16<=N(設定!$E$12)),16,"") | G20: =IF(AND(設定!$B$13<>"",16<=N(設定!$E$13)),16,"") | J20: =IF(AND(設定!$B$14<>"",16<=N(設定!$E$14)),16,"") | M20: =IF(AND(設定!$B$15<>"",16<=N(設定!$E$15)),16,"") | P20: =IF(AND(設定!$B$16<>"",16<=N(設定!$E$16)),16,"") | S20: =IF(AND(設定!$B$17<>"",16<=N(設定!$E$17)),16,"") | V20: =IF(AND(設定!$B$18<>"",16<=N(設定!$E$18)),16,"")
A21: =IF(AND(設定!$B$11<>"",17<=N(設定!$E$11)),17,"") | D21: =IF(AND(設定!$B$12<>"",17<=N(設定!$E$12)),17,"") | G21: =IF(AND(設定!$B$13<>"",17<=N(設定!$E$13)),17,"") | J21: =IF(AND(設定!$B$14<>"",17<=N(設定!$E$14)),17,"") | M21: =IF(AND(設定!$B$15<>"",17<=N(設定!$E$15)),17,"") | P21: =IF(AND(設定!$B$16<>"",17<=N(設定!$E$16)),17,"") | S21: =IF(AND(設定!$B$17<>"",17<=N(設定!$E$17)),17,"") | V21: =IF(AND(設定!$B$18<>"",17<=N(設定!$E$18)),17,"")
A22: =IF(AND(設定!$B$11<>"",18<=N(設定!$E$11)),18,"") | D22: =IF(AND(設定!$B$12<>"",18<=N(設定!$E$12)),18,"") | G22: =IF(AND(設定!$B$13<>"",18<=N(設定!$E$13)),18,"") | J22: =IF(AND(設定!$B$14<>"",18<=N(設定!$E$14)),18,"") | M22: =IF(AND(設定!$B$15<>"",18<=N(設定!$E$15)),18,"") | P22: =IF(AND(設定!$B$16<>"",18<=N(設定!$E$16)),18,"") | S22: =IF(AND(設定!$B$17<>"",18<=N(設定!$E$17)),18,"") | V22: =IF(AND(設定!$B$18<>"",18<=N(設定!$E$18)),18,"")
A23: =IF(AND(設定!$B$11<>"",19<=N(設定!$E$11)),19,"") | D23: =IF(AND(設定!$B$12<>"",19<=N(設定!$E$12)),19,"") | G23: =IF(AND(設定!$B$13<>"",19<=N(設定!$E$13)),19,"") | J23: =IF(AND(設定!$B$14<>"",19<=N(設定!$E$14)),19,"") | M23: =IF(AND(設定!$B$15<>"",19<=N(設定!$E$15)),19,"") | P23: =IF(AND(設定!$B$16<>"",19<=N(設定!$E$16)),19,"") | S23: =IF(AND(設定!$B$17<>"",19<=N(設定!$E$17)),19,"") | V23: =IF(AND(設定!$B$18<>"",19<=N(設定!$E$18)),19,"")
A24: =IF(AND(設定!$B$11<>"",20<=N(設定!$E$11)),20,"") | D24: =IF(AND(設定!$B$12<>"",20<=N(設定!$E$12)),20,"") | G24: =IF(AND(設定!$B$13<>"",20<=N(設定!$E$13)),20,"") | J24: =IF(AND(設定!$B$14<>"",20<=N(設定!$E$14)),20,"") | M24: =IF(AND(設定!$B$15<>"",20<=N(設定!$E$15)),20,"") | P24: =IF(AND(設定!$B$16<>"",20<=N(設定!$E$16)),20,"") | S24: =IF(AND(設定!$B$17<>"",20<=N(設定!$E$17)),20,"") | V24: =IF(AND(設定!$B$18<>"",20<=N(設定!$E$18)),20,"")
A25: =IF(AND(設定!$B$11<>"",21<=N(設定!$E$11)),21,"") | D25: =IF(AND(設定!$B$12<>"",21<=N(設定!$E$12)),21,"") | G25: =IF(AND(設定!$B$13<>"",21<=N(設定!$E$13)),21,"") | J25: =IF(AND(設定!$B$14<>"",21<=N(設定!$E$14)),21,"") | M25: =IF(AND(設定!$B$15<>"",21<=N(設定!$E$15)),21,"") | P25: =IF(AND(設定!$B$16<>"",21<=N(設定!$E$16)),21,"") | S25: =IF(AND(設定!$B$17<>"",21<=N(設定!$E$17)),21,"") | V25: =IF(AND(設定!$B$18<>"",21<=N(設定!$E$18)),21,"")
A26: =IF(AND(設定!$B$11<>"",22<=N(設定!$E$11)),22,"") | D26: =IF(AND(設定!$B$12<>"",22<=N(設定!$E$12)),22,"") | G26: =IF(AND(設定!$B$13<>"",22<=N(設定!$E$13)),22,"") | J26: =IF(AND(設定!$B$14<>"",22<=N(設定!$E$14)),22,"") | M26: =IF(AND(設定!$B$15<>"",22<=N(設定!$E$15)),22,"") | P26: =IF(AND(設定!$B$16<>"",22<=N(設定!$E$16)),22,"") | S26: =IF(AND(設定!$B$17<>"",22<=N(設定!$E$17)),22,"") | V26: =IF(AND(設定!$B$18<>"",22<=N(設定!$E$18)),22,"")
A27: =IF(AND(設定!$B$11<>"",23<=N(設定!$E$11)),23,"") | D27: =IF(AND(設定!$B$12<>"",23<=N(設定!$E$12)),23,"") | G27: =IF(AND(設定!$B$13<>"",23<=N(設定!$E$13)),23,"") | J27: =IF(AND(設定!$B$14<>"",23<=N(設定!$E$14)),23,"") | M27: =IF(AND(設定!$B$15<>"",23<=N(設定!$E$15)),23,"") | P27: =IF(AND(設定!$B$16<>"",23<=N(設定!$E$16)),23,"") | S27: =IF(AND(設定!$B$17<>"",23<=N(設定!$E$17)),23,"") | V27: =IF(AND(設定!$B$18<>"",23<=N(設定!$E$18)),23,"")
A28: =IF(AND(設定!$B$11<>"",24<=N(設定!$E$11)),24,"") | D28: =IF(AND(設定!$B$12<>"",24<=N(設定!$E$12)),24,"") | G28: =IF(AND(設定!$B$13<>"",24<=N(設定!$E$13)),24,"") | J28: =IF(AND(設定!$B$14<>"",24<=N(設定!$E$14)),24,"") | M28: =IF(AND(設定!$B$15<>"",24<=N(設定!$E$15)),24,"") | P28: =IF(AND(設定!$B$16<>"",24<=N(設定!$E$16)),24,"") | S28: =IF(AND(設定!$B$17<>"",24<=N(設定!$E$17)),24,"") | V28: =IF(AND(設定!$B$18<>"",24<=N(設定!$E$18)),24,"")
A29: =IF(AND(設定!$B$11<>"",25<=N(設定!$E$11)),25,"") | D29: =IF(AND(設定!$B$12<>"",25<=N(設定!$E$12)),25,"") | G29: =IF(AND(設定!$B$13<>"",25<=N(設定!$E$13)),25,"") | J29: =IF(AND(設定!$B$14<>"",25<=N(設定!$E$14)),25,"") | M29: =IF(AND(設定!$B$15<>"",25<=N(設定!$E$15)),25,"") | P29: =IF(AND(設定!$B$16<>"",25<=N(設定!$E$16)),25,"") | S29: =IF(AND(設定!$B$17<>"",25<=N(設定!$E$17)),25,"") | V29: =IF(AND(設定!$B$18<>"",25<=N(設定!$E$18)),25,"")
A30: =IF(AND(設定!$B$11<>"",26<=N(設定!$E$11)),26,"") | D30: =IF(AND(設定!$B$12<>"",26<=N(設定!$E$12)),26,"") | G30: =IF(AND(設定!$B$13<>"",26<=N(設定!$E$13)),26,"") | J30: =IF(AND(設定!$B$14<>"",26<=N(設定!$E$14)),26,"") | M30: =IF(AND(設定!$B$15<>"",26<=N(設定!$E$15)),26,"") | P30: =IF(AND(設定!$B$16<>"",26<=N(設定!$E$16)),26,"") | S30: =IF(AND(設定!$B$17<>"",26<=N(設定!$E$17)),26,"") | V30: =IF(AND(設定!$B$18<>"",26<=N(設定!$E$18)),26,"")
A31: =IF(AND(設定!$B$11<>"",27<=N(設定!$E$11)),27,"") | D31: =IF(AND(設定!$B$12<>"",27<=N(設定!$E$12)),27,"") | G31: =IF(AND(設定!$B$13<>"",27<=N(設定!$E$13)),27,"") | J31: =IF(AND(設定!$B$14<>"",27<=N(設定!$E$14)),27,"") | M31: =IF(AND(設定!$B$15<>"",27<=N(設定!$E$15)),27,"") | P31: =IF(AND(設定!$B$16<>"",27<=N(設定!$E$16)),27,"") | S31: =IF(AND(設定!$B$17<>"",27<=N(設定!$E$17)),27,"") | V31: =IF(AND(設定!$B$18<>"",27<=N(設定!$E$18)),27,"")
A32: =IF(AND(設定!$B$11<>"",28<=N(設定!$E$11)),28,"") | D32: =IF(AND(設定!$B$12<>"",28<=N(設定!$E$12)),28,"") | G32: =IF(AND(設定!$B$13<>"",28<=N(設定!$E$13)),28,"") | J32: =IF(AND(設定!$B$14<>"",28<=N(設定!$E$14)),28,"") | M32: =IF(AND(設定!$B$15<>"",28<=N(設定!$E$15)),28,"") | P32: =IF(AND(設定!$B$16<>"",28<=N(設定!$E$16)),28,"") | S32: =IF(AND(設定!$B$17<>"",28<=N(設定!$E$17)),28,"") | V32: =IF(AND(設定!$B$18<>"",28<=N(設定!$E$18)),28,"")
A33: =IF(AND(設定!$B$11<>"",29<=N(設定!$E$11)),29,"") | D33: =IF(AND(設定!$B$12<>"",29<=N(設定!$E$12)),29,"") | G33: =IF(AND(設定!$B$13<>"",29<=N(設定!$E$13)),29,"") | J33: =IF(AND(設定!$B$14<>"",29<=N(設定!$E$14)),29,"") | M33: =IF(AND(設定!$B$15<>"",29<=N(設定!$E$15)),29,"") | P33: =IF(AND(設定!$B$16<>"",29<=N(設定!$E$16)),29,"") | S33: =IF(AND(設定!$B$17<>"",29<=N(設定!$E$17)),29,"") | V33: =IF(AND(設定!$B$18<>"",29<=N(設定!$E$18)),29,"")
A34: =IF(AND(設定!$B$11<>"",30<=N(設定!$E$11)),30,"") | D34: =IF(AND(設定!$B$12<>"",30<=N(設定!$E$12)),30,"") | G34: =IF(AND(設定!$B$13<>"",30<=N(設定!$E$13)),30,"") | J34: =IF(AND(設定!$B$14<>"",30<=N(設定!$E$14)),30,"") | M34: =IF(AND(設定!$B$15<>"",30<=N(設定!$E$15)),30,"") | P34: =IF(AND(設定!$B$16<>"",30<=N(設定!$E$16)),30,"") | S34: =IF(AND(設定!$B$17<>"",30<=N(設定!$E$17)),30,"") | V34: =IF(AND(設定!$B$18<>"",30<=N(設定!$E$18)),30,"")
A35: =IF(AND(設定!$B$11<>"",31<=N(設定!$E$11)),31,"") | D35: =IF(AND(設定!$B$12<>"",31<=N(設定!$E$12)),31,"") | G35: =IF(AND(設定!$B$13<>"",31<=N(設定!$E$13)),31,"") | J35: =IF(AND(設定!$B$14<>"",31<=N(設定!$E$14)),31,"") | M35: =IF(AND(設定!$B$15<>"",31<=N(設定!$E$15)),31,"") | P35: =IF(AND(設定!$B$16<>"",31<=N(設定!$E$16)),31,"") | S35: =IF(AND(設定!$B$17<>"",31<=N(設定!$E$17)),31,"") | V35: =IF(AND(設定!$B$18<>"",31<=N(設定!$E$18)),31,"")
A36: =IF(AND(設定!$B$11<>"",32<=N(設定!$E$11)),32,"") | D36: =IF(AND(設定!$B$12<>"",32<=N(設定!$E$12)),32,"") | G36: =IF(AND(設定!$B$13<>"",32<=N(設定!$E$13)),32,"") | J36: =IF(AND(設定!$B$14<>"",32<=N(設定!$E$14)),32,"") | M36: =IF(AND(設定!$B$15<>"",32<=N(設定!$E$15)),32,"") | P36: =IF(AND(設定!$B$16<>"",32<=N(設定!$E$16)),32,"") | S36: =IF(AND(設定!$B$17<>"",32<=N(設定!$E$17)),32,"") | V36: =IF(AND(設定!$B$18<>"",32<=N(設定!$E$18)),32,"")
A37: =IF(AND(設定!$B$11<>"",33<=N(設定!$E$11)),33,"") | D37: =IF(AND(設定!$B$12<>"",33<=N(設定!$E$12)),33,"") | G37: =IF(AND(設定!$B$13<>"",33<=N(設定!$E$13)),33,"") | J37: =IF(AND(設定!$B$14<>"",33<=N(設定!$E$14)),33,"") | M37: =IF(AND(設定!$B$15<>"",33<=N(設定!$E$15)),33,"") | P37: =IF(AND(設定!$B$16<>"",33<=N(設定!$E$16)),33,"") | S37: =IF(AND(設定!$B$17<>"",33<=N(設定!$E$17)),33,"") | V37: =IF(AND(設定!$B$18<>"",33<=N(設定!$E$18)),33,"")
A38: =IF(AND(設定!$B$11<>"",34<=N(設定!$E$11)),34,"") | D38: =IF(AND(設定!$B$12<>"",34<=N(設定!$E$12)),34,"") | G38: =IF(AND(設定!$B$13<>"",34<=N(設定!$E$13)),34,"") | J38: =IF(AND(設定!$B$14<>"",34<=N(設定!$E$14)),34,"") | M38: =IF(AND(設定!$B$15<>"",34<=N(設定!$E$15)),34,"") | P38: =IF(AND(設定!$B$16<>"",34<=N(設定!$E$16)),34,"") | S38: =IF(AND(設定!$B$17<>"",34<=N(設定!$E$17)),34,"") | V38: =IF(AND(設定!$B$18<>"",34<=N(設定!$E$18)),34,"")
A39: =IF(AND(設定!$B$11<>"",35<=N(設定!$E$11)),35,"") | D39: =IF(AND(設定!$B$12<>"",35<=N(設定!$E$12)),35,"") | G39: =IF(AND(設定!$B$13<>"",35<=N(設定!$E$13)),35,"") | J39: =IF(AND(設定!$B$14<>"",35<=N(設定!$E$14)),35,"") | M39: =IF(AND(設定!$B$15<>"",35<=N(設定!$E$15)),35,"") | P39: =IF(AND(設定!$B$16<>"",35<=N(設定!$E$16)),35,"") | S39: =IF(AND(設定!$B$17<>"",35<=N(設定!$E$17)),35,"") | V39: =IF(AND(設定!$B$18<>"",35<=N(設定!$E$18)),35,"")
A40: =IF(AND(設定!$B$11<>"",36<=N(設定!$E$11)),36,"") | D40: =IF(AND(設定!$B$12<>"",36<=N(設定!$E$12)),36,"") | G40: =IF(AND(設定!$B$13<>"",36<=N(設定!$E$13)),36,"") | J40: =IF(AND(設定!$B$14<>"",36<=N(設定!$E$14)),36,"") | M40: =IF(AND(設定!$B$15<>"",36<=N(設定!$E$15)),36,"") | P40: =IF(AND(設定!$B$16<>"",36<=N(設定!$E$16)),36,"") | S40: =IF(AND(設定!$B$17<>"",36<=N(設定!$E$17)),36,"") | V40: =IF(AND(設定!$B$18<>"",36<=N(設定!$E$18)),36,"")
A41: =IF(AND(設定!$B$11<>"",37<=N(設定!$E$11)),37,"") | D41: =IF(AND(設定!$B$12<>"",37<=N(設定!$E$12)),37,"") | G41: =IF(AND(設定!$B$13<>"",37<=N(設定!$E$13)),37,"") | J41: =IF(AND(設定!$B$14<>"",37<=N(設定!$E$14)),37,"") | M41: =IF(AND(設定!$B$15<>"",37<=N(設定!$E$15)),37,"") | P41: =IF(AND(設定!$B$16<>"",37<=N(設定!$E$16)),37,"") | S41: =IF(AND(設定!$B$17<>"",37<=N(設定!$E$17)),37,"") | V41: =IF(AND(設定!$B$18<>"",37<=N(設定!$E$18)),37,"")
...

Sheet 5年
A1: =設定!$B$3&" "&設定!$B$8&"年 "&設定!$B$4&"入力" | E1: 【入力：担任】黄色のセル
A3: =IF(設定!$B$19="","",設定!$C$19) | D3: =IF(設定!$B$20="","",設定!$C$20) | G3: =IF(設定!$B$21="","",設定!$C$21) | J3: =IF(設定!$B$22="","",設定!$C$22) | M3: =IF(設定!$B$23="","",設定!$C$23) | P3: =IF(設定!$B$24="","",設定!$C$24) | S3: =IF(設定!$B$25="","",設定!$C$25) | V3: =IF(設定!$B$26="","",設定!$C$26)
A4: 番号 | B4: 名前 | C4: 委員会 | D4: 番号 | E4: 名前 | F4: 委員会 | G4: 番号 | H4: 名前 | I4: 委員会 | J4: 番号 | K4: 名前 | L4: 委員会 | M4: 番号 | N4: 名前 | O4: 委員会 | P4: 番号 | Q4: 名前 | R4: 委員会 | S4: 番号 | T4: 名前 | U4: 委員会 | V4: 番号 | W4: 名前 | X4: 委員会
A5: =IF(AND(設定!$B$19<>"",1<=N(設定!$E$19)),1,"") | D5: =IF(AND(設定!$B$20<>"",1<=N(設定!$E$20)),1,"") | G5: =IF(AND(設定!$B$21<>"",1<=N(設定!$E$21)),1,"") | J5: =IF(AND(設定!$B$22<>"",1<=N(設定!$E$22)),1,"") | M5: =IF(AND(設定!$B$23<>"",1<=N(設定!$E$23)),1,"") | P5: =IF(AND(設定!$B$24<>"",1<=N(設定!$E$24)),1,"") | S5: =IF(AND(設定!$B$25<>"",1<=N(設定!$E$25)),1,"") | V5: =IF(AND(設定!$B$26<>"",1<=N(設定!$E$26)),1,"")
A6: =IF(AND(設定!$B$19<>"",2<=N(設定!$E$19)),2,"") | D6: =IF(AND(設定!$B$20<>"",2<=N(設定!$E$20)),2,"") | G6: =IF(AND(設定!$B$21<>"",2<=N(設定!$E$21)),2,"") | J6: =IF(AND(設定!$B$22<>"",2<=N(設定!$E$22)),2,"") | M6: =IF(AND(設定!$B$23<>"",2<=N(設定!$E$23)),2,"") | P6: =IF(AND(設定!$B$24<>"",2<=N(設定!$E$24)),2,"") | S6: =IF(AND(設定!$B$25<>"",2<=N(設定!$E$25)),2,"") | V6: =IF(AND(設定!$B$26<>"",2<=N(設定!$E$26)),2,"")
A7: =IF(AND(設定!$B$19<>"",3<=N(設定!$E$19)),3,"") | D7: =IF(AND(設定!$B$20<>"",3<=N(設定!$E$20)),3,"") | G7: =IF(AND(設定!$B$21<>"",3<=N(設定!$E$21)),3,"") | J7: =IF(AND(設定!$B$22<>"",3<=N(設定!$E$22)),3,"") | M7: =IF(AND(設定!$B$23<>"",3<=N(設定!$E$23)),3,"") | P7: =IF(AND(設定!$B$24<>"",3<=N(設定!$E$24)),3,"") | S7: =IF(AND(設定!$B$25<>"",3<=N(設定!$E$25)),3,"") | V7: =IF(AND(設定!$B$26<>"",3<=N(設定!$E$26)),3,"")
A8: =IF(AND(設定!$B$19<>"",4<=N(設定!$E$19)),4,"") | D8: =IF(AND(設定!$B$20<>"",4<=N(設定!$E$20)),4,"") | G8: =IF(AND(設定!$B$21<>"",4<=N(設定!$E$21)),4,"") | J8: =IF(AND(設定!$B$22<>"",4<=N(設定!$E$22)),4,"") | M8: =IF(AND(設定!$B$23<>"",4<=N(設定!$E$23)),4,"") | P8: =IF(AND(設定!$B$24<>"",4<=N(設定!$E$24)),4,"") | S8: =IF(AND(設定!$B$25<>"",4<=N(設定!$E$25)),4,"") | V8: =IF(AND(設定!$B$26<>"",4<=N(設定!$E$26)),4,"")
A9: =IF(AND(設定!$B$19<>"",5<=N(設定!$E$19)),5,"") | D9: =IF(AND(設定!$B$20<>"",5<=N(設定!$E$20)),5,"") | G9: =IF(AND(設定!$B$21<>"",5<=N(設定!$E$21)),5,"") | J9: =IF(AND(設定!$B$22<>"",5<=N(設定!$E$22)),5,"") | M9: =IF(AND(設定!$B$23<>"",5<=N(設定!$E$23)),5,"") | P9: =IF(AND(設定!$B$24<>"",5<=N(設定!$E$24)),5,"") | S9: =IF(AND(設定!$B$25<>"",5<=N(設定!$E$25)),5,"") | V9: =IF(AND(設定!$B$26<>"",5<=N(設定!$E$26)),5,"")
A10: =IF(AND(設定!$B$19<>"",6<=N(設定!$E$19)),6,"") | D10: =IF(AND(設定!$B$20<>"",6<=N(設定!$E$20)),6,"") | G10: =IF(AND(設定!$B$21<>"",6<=N(設定!$E$21)),6,"") | J10: =IF(AND(設定!$B$22<>"",6<=N(設定!$E$22)),6,"") | M10: =IF(AND(設定!$B$23<>"",6<=N(設定!$E$23)),6,"") | P10: =IF(AND(設定!$B$24<>"",6<=N(設定!$E$24)),6,"") | S10: =IF(AND(設定!$B$25<>"",6<=N(設定!$E$25)),6,"") | V10: =IF(AND(設定!$B$26<>"",6<=N(設定!$E$26)),6,"")
A11: =IF(AND(設定!$B$19<>"",7<=N(設定!$E$19)),7,"") | D11: =IF(AND(設定!$B$20<>"",7<=N(設定!$E$20)),7,"") | G11: =IF(AND(設定!$B$21<>"",7<=N(設定!$E$21)),7,"") | J11: =IF(AND(設定!$B$22<>"",7<=N(設定!$E$22)),7,"") | M11: =IF(AND(設定!$B$23<>"",7<=N(設定!$E$23)),7,"") | P11: =IF(AND(設定!$B$24<>"",7<=N(設定!$E$24)),7,"") | S11: =IF(AND(設定!$B$25<>"",7<=N(設定!$E$25)),7,"") | V11: =IF(AND(設定!$B$26<>"",7<=N(設定!$E$26)),7,"")
A12: =IF(AND(設定!$B$19<>"",8<=N(設定!$E$19)),8,"") | D12: =IF(AND(設定!$B$20<>"",8<=N(設定!$E$20)),8,"") | G12: =IF(AND(設定!$B$21<>"",8<=N(設定!$E$21)),8,"") | J12: =IF(AND(設定!$B$22<>"",8<=N(設定!$E$22)),8,"") | M12: =IF(AND(設定!$B$23<>"",8<=N(設定!$E$23)),8,"") | P12: =IF(AND(設定!$B$24<>"",8<=N(設定!$E$24)),8,"") | S12: =IF(AND(設定!$B$25<>"",8<=N(設定!$E$25)),8,"") | V12: =IF(AND(設定!$B$26<>"",8<=N(設定!$E$26)),8,"")
A13: =IF(AND(設定!$B$19<>"",9<=N(設定!$E$19)),9,"") | D13: =IF(AND(設定!$B$20<>"",9<=N(設定!$E$20)),9,"") | G13: =IF(AND(設定!$B$21<>"",9<=N(設定!$E$21)),9,"") | J13: =IF(AND(設定!$B$22<>"",9<=N(設定!$E$22)),9,"") | M13: =IF(AND(設定!$B$23<>"",9<=N(設定!$E$23)),9,"") | P13: =IF(AND(設定!$B$24<>"",9<=N(設定!$E$24)),9,"") | S13: =IF(AND(設定!$B$25<>"",9<=N(設定!$E$25)),9,"") | V13: =IF(AND(設定!$B$26<>"",9<=N(設定!$E$26)),9,"")
A14: =IF(AND(設定!$B$19<>"",10<=N(設定!$E$19)),10,"") | D14: =IF(AND(設定!$B$20<>"",10<=N(設定!$E$20)),10,"") | G14: =IF(AND(設定!$B$21<>"",10<=N(設定!$E$21)),10,"") | J14: =IF(AND(設定!$B$22<>"",10<=N(設定!$E$22)),10,"") | M14: =IF(AND(設定!$B$23<>"",10<=N(設定!$E$23)),10,"") | P14: =IF(AND(設定!$B$24<>"",10<=N(設定!$E$24)),10,"") | S14: =IF(AND(設定!$B$25<>"",10<=N(設定!$E$25)),10,"") | V14: =IF(AND(設定!$B$26<>"",10<=N(設定!$E$26)),10,"")
A15: =IF(AND(設定!$B$19<>"",11<=N(設定!$E$19)),11,"") | D15: =IF(AND(設定!$B$20<>"",11<=N(設定!$E$20)),11,"") | G15: =IF(AND(設定!$B$21<>"",11<=N(設定!$E$21)),11,"") | J15: =IF(AND(設定!$B$22<>"",11<=N(設定!$E$22)),11,"") | M15: =IF(AND(設定!$B$23<>"",11<=N(設定!$E$23)),11,"") | P15: =IF(AND(設定!$B$24<>"",11<=N(設定!$E$24)),11,"") | S15: =IF(AND(設定!$B$25<>"",11<=N(設定!$E$25)),11,"") | V15: =IF(AND(設定!$B$26<>"",11<=N(設定!$E$26)),11,"")
A16: =IF(AND(設定!$B$19<>"",12<=N(設定!$E$19)),12,"") | D16: =IF(AND(設定!$B$20<>"",12<=N(設定!$E$20)),12,"") | G16: =IF(AND(設定!$B$21<>"",12<=N(設定!$E$21)),12,"") | J16: =IF(AND(設定!$B$22<>"",12<=N(設定!$E$22)),12,"") | M16: =IF(AND(設定!$B$23<>"",12<=N(設定!$E$23)),12,"") | P16: =IF(AND(設定!$B$24<>"",12<=N(設定!$E$24)),12,"") | S16: =IF(AND(設定!$B$25<>"",12<=N(設定!$E$25)),12,"") | V16: =IF(AND(設定!$B$26<>"",12<=N(設定!$E$26)),12,"")
A17: =IF(AND(設定!$B$19<>"",13<=N(設定!$E$19)),13,"") | D17: =IF(AND(設定!$B$20<>"",13<=N(設定!$E$20)),13,"") | G17: =IF(AND(設定!$B$21<>"",13<=N(設定!$E$21)),13,"") | J17: =IF(AND(設定!$B$22<>"",13<=N(設定!$E$22)),13,"") | M17: =IF(AND(設定!$B$23<>"",13<=N(設定!$E$23)),13,"") | P17: =IF(AND(設定!$B$24<>"",13<=N(設定!$E$24)),13,"") | S17: =IF(AND(設定!$B$25<>"",13<=N(設定!$E$25)),13,"") | V17: =IF(AND(設定!$B$26<>"",13<=N(設定!$E$26)),13,"")
A18: =IF(AND(設定!$B$19<>"",14<=N(設定!$E$19)),14,"") | D18: =IF(AND(設定!$B$20<>"",14<=N(設定!$E$20)),14,"") | G18: =IF(AND(設定!$B$21<>"",14<=N(設定!$E$21)),14,"") | J18: =IF(AND(設定!$B$22<>"",14<=N(設定!$E$22)),14,"") | M18: =IF(AND(設定!$B$23<>"",14<=N(設定!$E$23)),14,"") | P18: =IF(AND(設定!$B$24<>"",14<=N(設定!$E$24)),14,"") | S18: =IF(AND(設定!$B$25<>"",14<=N(設定!$E$25)),14,"") | V18: =IF(AND(設定!$B$26<>"",14<=N(設定!$E$26)),14,"")
A19: =IF(AND(設定!$B$19<>"",15<=N(設定!$E$19)),15,"") | D19: =IF(AND(設定!$B$20<>"",15<=N(設定!$E$20)),15,"") | G19: =IF(AND(設定!$B$21<>"",15<=N(設定!$E$21)),15,"") | J19: =IF(AND(設定!$B$22<>"",15<=N(設定!$E$22)),15,"") | M19: =IF(AND(設定!$B$23<>"",15<=N(設定!$E$23)),15,"") | P19: =IF(AND(設定!$B$24<>"",15<=N(設定!$E$24)),15,"") | S19: =IF(AND(設定!$B$25<>"",15<=N(設定!$E$25)),15,"") | V19: =IF(AND(設定!$B$26<>"",15<=N(設定!$E$26)),15,"")
A20: =IF(AND(設定!$B$19<>"",16<=N(設定!$E$19)),16,"") | D20: =IF(AND(設定!$B$20<>"",16<=N(設定!$E$20)),16,"") | G20: =IF(AND(設定!$B$21<>"",16<=N(設定!$E$21)),16,"") | J20: =IF(AND(設定!$B$22<>"",16<=N(設定!$E$22)),16,"") | M20: =IF(AND(設定!$B$23<>"",16<=N(設定!$E$23)),16,"") | P20: =IF(AND(設定!$B$24<>"",16<=N(設定!$E$24)),16,"") | S20: =IF(AND(設定!$B$25<>"",16<=N(設定!$E$25)),16,"") | V20: =IF(AND(設定!$B$26<>"",16<=N(設定!$E$26)),16,"")
A21: =IF(AND(設定!$B$19<>"",17<=N(設定!$E$19)),17,"") | D21: =IF(AND(設定!$B$20<>"",17<=N(設定!$E$20)),17,"") | G21: =IF(AND(設定!$B$21<>"",17<=N(設定!$E$21)),17,"") | J21: =IF(AND(設定!$B$22<>"",17<=N(設定!$E$22)),17,"") | M21: =IF(AND(設定!$B$23<>"",17<=N(設定!$E$23)),17,"") | P21: =IF(AND(設定!$B$24<>"",17<=N(設定!$E$24)),17,"") | S21: =IF(AND(設定!$B$25<>"",17<=N(設定!$E$25)),17,"") | V21: =IF(AND(設定!$B$26<>"",17<=N(設定!$E$26)),17,"")
A22: =IF(AND(設定!$B$19<>"",18<=N(設定!$E$19)),18,"") | D22: =IF(AND(設定!$B$20<>"",18<=N(設定!$E$20)),18,"") | G22: =IF(AND(設定!$B$21<>"",18<=N(設定!$E$21)),18,"") | J22: =IF(AND(設定!$B$22<>"",18<=N(設定!$E$22)),18,"") | M22: =IF(AND(設定!$B$23<>"",18<=N(設定!$E$23)),18,"") | P22: =IF(AND(設定!$B$24<>"",18<=N(設定!$E$24)),18,"") | S22: =IF(AND(設定!$B$25<>"",18<=N(設定!$E$25)),18,"") | V22: =IF(AND(設定!$B$26<>"",18<=N(設定!$E$26)),18,"")
A23: =IF(AND(設定!$B$19<>"",19<=N(設定!$E$19)),19,"") | D23: =IF(AND(設定!$B$20<>"",19<=N(設定!$E$20)),19,"") | G23: =IF(AND(設定!$B$21<>"",19<=N(設定!$E$21)),19,"") | J23: =IF(AND(設定!$B$22<>"",19<=N(設定!$E$22)),19,"") | M23: =IF(AND(設定!$B$23<>"",19<=N(設定!$E$23)),19,"") | P23: =IF(AND(設定!$B$24<>"",19<=N(設定!$E$24)),19,"") | S23: =IF(AND(設定!$B$25<>"",19<=N(設定!$E$25)),19,"") | V23: =IF(AND(設定!$B$26<>"",19<=N(設定!$E$26)),19,"")
A24: =IF(AND(設定!$B$19<>"",20<=N(設定!$E$19)),20,"") | D24: =IF(AND(設定!$B$20<>"",20<=N(設定!$E$20)),20,"") | G24: =IF(AND(設定!$B$21<>"",20<=N(設定!$E$21)),20,"") | J24: =IF(AND(設定!$B$22<>"",20<=N(設定!$E$22)),20,"") | M24: =IF(AND(設定!$B$23<>"",20<=N(設定!$E$23)),20,"") | P24: =IF(AND(設定!$B$24<>"",20<=N(設定!$E$24)),20,"") | S24: =IF(AND(設定!$B$25<>"",20<=N(設定!$E$25)),20,"") | V24: =IF(AND(設定!$B$26<>"",20<=N(設定!$E$26)),20,"")
A25: =IF(AND(設定!$B$19<>"",21<=N(設定!$E$19)),21,"") | D25: =IF(AND(設定!$B$20<>"",21<=N(設定!$E$20)),21,"") | G25: =IF(AND(設定!$B$21<>"",21<=N(設定!$E$21)),21,"") | J25: =IF(AND(設定!$B$22<>"",21<=N(設定!$E$22)),21,"") | M25: =IF(AND(設定!$B$23<>"",21<=N(設定!$E$23)),21,"") | P25: =IF(AND(設定!$B$24<>"",21<=N(設定!$E$24)),21,"") | S25: =IF(AND(設定!$B$25<>"",21<=N(設定!$E$25)),21,"") | V25: =IF(AND(設定!$B$26<>"",21<=N(設定!$E$26)),21,"")
A26: =IF(AND(設定!$B$19<>"",22<=N(設定!$E$19)),22,"") | D26: =IF(AND(設定!$B$20<>"",22<=N(設定!$E$20)),22,"") | G26: =IF(AND(設定!$B$21<>"",22<=N(設定!$E$21)),22,"") | J26: =IF(AND(設定!$B$22<>"",22<=N(設定!$E$22)),22,"") | M26: =IF(AND(設定!$B$23<>"",22<=N(設定!$E$23)),22,"") | P26: =IF(AND(設定!$B$24<>"",22<=N(設定!$E$24)),22,"") | S26: =IF(AND(設定!$B$25<>"",22<=N(設定!$E$25)),22,"") | V26: =IF(AND(設定!$B$26<>"",22<=N(設定!$E$26)),22,"")
A27: =IF(AND(設定!$B$19<>"",23<=N(設定!$E$19)),23,"") | D27: =IF(AND(設定!$B$20<>"",23<=N(設定!$E$20)),23,"") | G27: =IF(AND(設定!$B$21<>"",23<=N(設定!$E$21)),23,"") | J27: =IF(AND(設定!$B$22<>"",23<=N(設定!$E$22)),23,"") | M27: =IF(AND(設定!$B$23<>"",23<=N(設定!$E$23)),23,"") | P27: =IF(AND(設定!$B$24<>"",23<=N(設定!$E$24)),23,"") | S27: =IF(AND(設定!$B$25<>"",23<=N(設定!$E$25)),23,"") | V27: =IF(AND(設定!$B$26<>"",23<=N(設定!$E$26)),23,"")
A28: =IF(AND(設定!$B$19<>"",24<=N(設定!$E$19)),24,"") | D28: =IF(AND(設定!$B$20<>"",24<=N(設定!$E$20)),24,"") | G28: =IF(AND(設定!$B$21<>"",24<=N(設定!$E$21)),24,"") | J28: =IF(AND(設定!$B$22<>"",24<=N(設定!$E$22)),24,"") | M28: =IF(AND(設定!$B$23<>"",24<=N(設定!$E$23)),24,"") | P28: =IF(AND(設定!$B$24<>"",24<=N(設定!$E$24)),24,"") | S28: =IF(AND(設定!$B$25<>"",24<=N(設定!$E$25)),24,"") | V28: =IF(AND(設定!$B$26<>"",24<=N(設定!$E$26)),24,"")
A29: =IF(AND(設定!$B$19<>"",25<=N(設定!$E$19)),25,"") | D29: =IF(AND(設定!$B$20<>"",25<=N(設定!$E$20)),25,"") | G29: =IF(AND(設定!$B$21<>"",25<=N(設定!$E$21)),25,"") | J29: =IF(AND(設定!$B$22<>"",25<=N(設定!$E$22)),25,"") | M29: =IF(AND(設定!$B$23<>"",25<=N(設定!$E$23)),25,"") | P29: =IF(AND(設定!$B$24<>"",25<=N(設定!$E$24)),25,"") | S29: =IF(AND(設定!$B$25<>"",25<=N(設定!$E$25)),25,"") | V29: =IF(AND(設定!$B$26<>"",25<=N(設定!$E$26)),25,"")
A30: =IF(AND(設定!$B$19<>"",26<=N(設定!$E$19)),26,"") | D30: =IF(AND(設定!$B$20<>"",26<=N(設定!$E$20)),26,"") | G30: =IF(AND(設定!$B$21<>"",26<=N(設定!$E$21)),26,"") | J30: =IF(AND(設定!$B$22<>"",26<=N(設定!$E$22)),26,"") | M30: =IF(AND(設定!$B$23<>"",26<=N(設定!$E$23)),26,"") | P30: =IF(AND(設定!$B$24<>"",26<=N(設定!$E$24)),26,"") | S30: =IF(AND(設定!$B$25<>"",26<=N(設定!$E$25)),26,"") | V30: =IF(AND(設定!$B$26<>"",26<=N(設定!$E$26)),26,"")
A31: =IF(AND(設定!$B$19<>"",27<=N(設定!$E$19)),27,"") | D31: =IF(AND(設定!$B$20<>"",27<=N(設定!$E$20)),27,"") | G31: =IF(AND(設定!$B$21<>"",27<=N(設定!$E$21)),27,"") | J31: =IF(AND(設定!$B$22<>"",27<=N(設定!$E$22)),27,"") | M31: =IF(AND(設定!$B$23<>"",27<=N(設定!$E$23)),27,"") | P31: =IF(AND(設定!$B$24<>"",27<=N(設定!$E$24)),27,"") | S31: =IF(AND(設定!$B$25<>"",27<=N(設定!$E$25)),27,"") | V31: =IF(AND(設定!$B$26<>"",27<=N(設定!$E$26)),27,"")
A32: =IF(AND(設定!$B$19<>"",28<=N(設定!$E$19)),28,"") | D32: =IF(AND(設定!$B$20<>"",28<=N(設定!$E$20)),28,"") | G32: =IF(AND(設定!$B$21<>"",28<=N(設定!$E$21)),28,"") | J32: =IF(AND(設定!$B$22<>"",28<=N(設定!$E$22)),28,"") | M32: =IF(AND(設定!$B$23<>"",28<=N(設定!$E$23)),28,"") | P32: =IF(AND(設定!$B$24<>"",28<=N(設定!$E$24)),28,"") | S32: =IF(AND(設定!$B$25<>"",28<=N(設定!$E$25)),28,"") | V32: =IF(AND(設定!$B$26<>"",28<=N(設定!$E$26)),28,"")
A33: =IF(AND(設定!$B$19<>"",29<=N(設定!$E$19)),29,"") | D33: =IF(AND(設定!$B$20<>"",29<=N(設定!$E$20)),29,"") | G33: =IF(AND(設定!$B$21<>"",29<=N(設定!$E$21)),29,"") | J33: =IF(AND(設定!$B$22<>"",29<=N(設定!$E$22)),29,"") | M33: =IF(AND(設定!$B$23<>"",29<=N(設定!$E$23)),29,"") | P33: =IF(AND(設定!$B$24<>"",29<=N(設定!$E$24)),29,"") | S33: =IF(AND(設定!$B$25<>"",29<=N(設定!$E$25)),29,"") | V33: =IF(AND(設定!$B$26<>"",29<=N(設定!$E$26)),29,"")
A34: =IF(AND(設定!$B$19<>"",30<=N(設定!$E$19)),30,"") | D34: =IF(AND(設定!$B$20<>"",30<=N(設定!$E$20)),30,"") | G34: =IF(AND(設定!$B$21<>"",30<=N(設定!$E$21)),30,"") | J34: =IF(AND(設定!$B$22<>"",30<=N(設定!$E$22)),30,"") | M34: =IF(AND(設定!$B$23<>"",30<=N(設定!$E$23)),30,"") | P34: =IF(AND(設定!$B$24<>"",30<=N(設定!$E$24)),30,"") | S34: =IF(AND(設定!$B$25<>"",30<=N(設定!$E$25)),30,"") | V34: =IF(AND(設定!$B$26<>"",30<=N(設定!$E$26)),30,"")
A35: =IF(AND(設定!$B$19<>"",31<=N(設定!$E$19)),31,"") | D35: =IF(AND(設定!$B$20<>"",31<=N(設定!$E$20)),31,"") | G35: =IF(AND(設定!$B$21<>"",31<=N(設定!$E$21)),31,"") | J35: =IF(AND(設定!$B$22<>"",31<=N(設定!$E$22)),31,"") | M35: =IF(AND(設定!$B$23<>"",31<=N(設定!$E$23)),31,"") | P35: =IF(AND(設定!$B$24<>"",31<=N(設定!$E$24)),31,"") | S35: =IF(AND(設定!$B$25<>"",31<=N(設定!$E$25)),31,"") | V35: =IF(AND(設定!$B$26<>"",31<=N(設定!$E$26)),31,"")
A36: =IF(AND(設定!$B$19<>"",32<=N(設定!$E$19)),32,"") | D36: =IF(AND(設定!$B$20<>"",32<=N(設定!$E$20)),32,"") | G36: =IF(AND(設定!$B$21<>"",32<=N(設定!$E$21)),32,"") | J36: =IF(AND(設定!$B$22<>"",32<=N(設定!$E$22)),32,"") | M36: =IF(AND(設定!$B$23<>"",32<=N(設定!$E$23)),32,"") | P36: =IF(AND(設定!$B$24<>"",32<=N(設定!$E$24)),32,"") | S36: =IF(AND(設定!$B$25<>"",32<=N(設定!$E$25)),32,"") | V36: =IF(AND(設定!$B$26<>"",32<=N(設定!$E$26)),32,"")
A37: =IF(AND(設定!$B$19<>"",33<=N(設定!$E$19)),33,"") | D37: =IF(AND(設定!$B$20<>"",33<=N(設定!$E$20)),33,"") | G37: =IF(AND(設定!$B$21<>"",33<=N(設定!$E$21)),33,"") | J37: =IF(AND(設定!$B$22<>"",33<=N(設定!$E$22)),33,"") | M37: =IF(AND(設定!$B$23<>"",33<=N(設定!$E$23)),33,"") | P37: =IF(AND(設定!$B$24<>"",33<=N(設定!$E$24)),33,"") | S37: =IF(AND(設定!$B$25<>"",33<=N(設定!$E$25)),33,"") | V37: =IF(AND(設定!$B$26<>"",33<=N(設定!$E$26)),33,"")
A38: =IF(AND(設定!$B$19<>"",34<=N(設定!$E$19)),34,"") | D38: =IF(AND(設定!$B$20<>"",34<=N(設定!$E$20)),34,"") | G38: =IF(AND(設定!$B$21<>"",34<=N(設定!$E$21)),34,"") | J38: =IF(AND(設定!$B$22<>"",34<=N(設定!$E$22)),34,"") | M38: =IF(AND(設定!$B$23<>"",34<=N(設定!$E$23)),34,"") | P38: =IF(AND(設定!$B$24<>"",34<=N(設定!$E$24)),34,"") | S38: =IF(AND(設定!$B$25<>"",34<=N(設定!$E$25)),34,"") | V38: =IF(AND(設定!$B$26<>"",34<=N(設定!$E$26)),34,"")
A39: =IF(AND(設定!$B$19<>"",35<=N(設定!$E$19)),35,"") | D39: =IF(AND(設定!$B$20<>"",35<=N(設定!$E$20)),35,"") | G39: =IF(AND(設定!$B$21<>"",35<=N(設定!$E$21)),35,"") | J39: =IF(AND(設定!$B$22<>"",35<=N(設定!$E$22)),35,"") | M39: =IF(AND(設定!$B$23<>"",35<=N(設定!$E$23)),35,"") | P39: =IF(AND(設定!$B$24<>"",35<=N(設定!$E$24)),35,"") | S39: =IF(AND(設定!$B$25<>"",35<=N(設定!$E$25)),35,"") | V39: =IF(AND(設定!$B$26<>"",35<=N(設定!$E$26)),35,"")
A40: =IF(AND(設定!$B$19<>"",36<=N(設定!$E$19)),36,"") | D40: =IF(AND(設定!$B$20<>"",36<=N(設定!$E$20)),36,"") | G40: =IF(AND(設定!$B$21<>"",36<=N(設定!$E$21)),36,"") | J40: =IF(AND(設定!$B$22<>"",36<=N(設定!$E$22)),36,"") | M40: =IF(AND(設定!$B$23<>"",36<=N(設定!$E$23)),36,"") | P40: =IF(AND(設定!$B$24<>"",36<=N(設定!$E$24)),36,"") | S40: =IF(AND(設定!$B$25<>"",36<=N(設定!$E$25)),36,"") | V40: =IF(AND(設定!$B$26<>"",36<=N(設定!$E$26)),36,"")
A41: =IF(AND(設定!$B$19<>"",37<=N(設定!$E$19)),37,"") | D41: =IF(AND(設定!$B$20<>"",37<=N(設定!$E$20)),37,"") | G41: =IF(AND(設定!$B$21<>"",37<=N(設定!$E$21)),37,"") | J41: =IF(AND(設定!$B$22<>"",37<=N(設定!$E$22)),37,"") | M41: =IF(AND(設定!$B$23<>"",37<=N(設定!$E$23)),37,"") | P41: =IF(AND(設定!$B$24<>"",37<=N(設定!$E$24)),37,"") | S41: =IF(AND(設定!$B$25<>"",37<=N(設定!$E$25)),37,"") | V41: =IF(AND(設定!$B$26<>"",37<=N(設定!$E$26)),37,"")
...

Sheet 人数チェック
A1: 人数チェック | D1: 【入力なし】見る・印刷するだけ
B3: 委員会が未入力の子 | C3: =設定!$B$7&"年 "&SUMIFS(計算用!$I$2:$I$721,計算用!$H$2:$H$721,設定!$B$7)&"人" | D3: =設定!$B$8&"年 "&SUMIFS(計算用!$I$2:$I$721,計算用!$H$2:$H$721,設定!$B$8)&"人"
B4: 設定にない委員会名 | C4: =SUM(計算用!$J$2:$J$721)&"件"
A6: No. | B6: 委員会 | C6: =設定!$B$7&"年" | D6: =設定!$B$8&"年" | E6: 合計
A7: 1 | B7: =IF(設定!I11="","",設定!I11) | C7: =IF(B7="","",COUNTIFS(計算用!$H$2:$H$721,設定!$B$7,計算用!$D$2:$D$721,B7)) | D7: =IF(B7="","",COUNTIFS(計算用!$H$2:$H$721,設定!$B$8,計算用!$D$2:$D$721,B7)) | E7: =IF(B7="","",C7+D7)
A8: 2 | B8: =IF(設定!I12="","",設定!I12) | C8: =IF(B8="","",COUNTIFS(計算用!$H$2:$H$721,設定!$B$7,計算用!$D$2:$D$721,B8)) | D8: =IF(B8="","",COUNTIFS(計算用!$H$2:$H$721,設定!$B$8,計算用!$D$2:$D$721,B8)) | E8: =IF(B8="","",C8+D8)
A9: 3 | B9: =IF(設定!I13="","",設定!I13) | C9: =IF(B9="","",COUNTIFS(計算用!$H$2:$H$721,設定!$B$7,計算用!$D$2:$D$721,B9)) | D9: =IF(B9="","",COUNTIFS(計算用!$H$2:$H$721,設定!$B$8,計算用!$D$2:$D$721,B9)) | E9: =IF(B9="","",C9+D9)
A10: 4 | B10: =IF(設定!I14="","",設定!I14) | C10: =IF(B10="","",COUNTIFS(計算用!$H$2:$H$721,設定!$B$7,計算用!$D$2:$D$721,B10)) | D10: =IF(B10="","",COUNTIFS(計算用!$H$2:$H$721,設定!$B$8,計算用!$D$2:$D$721,B10)) | E10: =IF(B10="","",C10+D10)
A11: 5 | B11: =IF(設定!I15="","",設定!I15) | C11: =IF(B11="","",COUNTIFS(計算用!$H$2:$H$721,設定!$B$7,計算用!$D$2:$D$721,B11)) | D11: =IF(B11="","",COUNTIFS(計算用!$H$2:$H$721,設定!$B$8,計算用!$D$2:$D$721,B11)) | E11: =IF(B11="","",C11+D11)
A12: 6 | B12: =IF(設定!I16="","",設定!I16) | C12: =IF(B12="","",COUNTIFS(計算用!$H$2:$H$721,設定!$B$7,計算用!$D$2:$D$721,B12)) | D12: =IF(B12="","",COUNTIFS(計算用!$H$2:$H$721,設定!$B$8,計算用!$D$2:$D$721,B12)) | E12: =IF(B12="","",C12+D12)
A13: 7 | B13: =IF(設定!I17="","",設定!I17) | C13: =IF(B13="","",COUNTIFS(計算用!$H$2:$H$721,設定!$B$7,計算用!$D$2:$D$721,B13)) | D13: =IF(B13="","",COUNTIFS(計算用!$H$2:$H$721,設定!$B$8,計算用!$D$2:$D$721,B13)) | E13: =IF(B13="","",C13+D13)
A14: 8 | B14: =IF(設定!I18="","",設定!I18) | C14: =IF(B14="","",COUNTIFS(計算用!$H$2:$H$721,設定!$B$7,計算用!$D$2:$D$721,B14)) | D14: =IF(B14="","",COUNTIFS(計算用!$H$2:$H$721,設定!$B$8,計算用!$D$2:$D$721,B14)) | E14: =IF(B14="","",C14+D14)
A15: 9 | B15: =IF(設定!I19="","",設定!I19) | C15: =IF(B15="","",COUNTIFS(計算用!$H$2:$H$721,設定!$B$7,計算用!$D$2:$D$721,B15)) | D15: =IF(B15="","",COUNTIFS(計算用!$H$2:$H$721,設定!$B$8,計算用!$D$2:$D$721,B15)) | E15: =IF(B15="","",C15+D15)
A16: 10 | B16: =IF(設定!I20="","",設定!I20) | C16: =IF(B16="","",COUNTIFS(計算用!$H$2:$H$721,設定!$B$7,計算用!$D$2:$D$721,B16)) | D16: =IF(B16="","",COUNTIFS(計算用!$H$2:$H$721,設定!$B$8,計算用!$D$2:$D$721,B16)) | E16: =IF(B16="","",C16+D16)
A17: 11 | B17: =IF(設定!I21="","",設定!I21) | C17: =IF(B17="","",COUNTIFS(計算用!$H$2:$H$721,設定!$B$7,計算用!$D$2:$D$721,B17)) | D17: =IF(B17="","",COUNTIFS(計算用!$H$2:$H$721,設定!$B$8,計算用!$D$2:$D$721,B17)) | E17: =IF(B17="","",C17+D17)
A18: 12 | B18: =IF(設定!I22="","",設定!I22) | C18: =IF(B18="","",COUNTIFS(計算用!$H$2:$H$721,設定!$B$7,計算用!$D$2:$D$721,B18)) | D18: =IF(B18="","",COUNTIFS(計算用!$H$2:$H$721,設定!$B$8,計算用!$D$2:$D$721,B18)) | E18: =IF(B18="","",C18+D18)
... A26: 20 | B26: =IF(設定!I30="","",設定!I30) | C26: =IF(B26="","",COUNTIFS(計算用!$H$2:$H$721,設定!$B$7,計算用!$D$2:$D$721,B26)) | D26: =IF(B26="","",COUNTIFS(計算用!$H$2:$H$721,設定!$B$8,計算用!$D$2:$D$721,B26)) | E26: =IF(B26="","",C26+D26)
A28: ※ 未入力の子や設定にない委員会名は、6年・5年シートでうすい赤・赤になっています。

Sheet 一覧名簿
A1: =設定!B3&" 全"&設定!B4&"担当者および児童名簿" | V1: 【入力なし】見る・印刷するだけ
A3: =IF(設定!$I$11="","",設定!$I$11&"（"&人数チェック!$E$7&"名）") | C3: =IF(設定!$I$12="","",設定!$I$12&"（"&人数チェック!$E$8&"名）") | E3: =IF(設定!$I$13="","",設定!$I$13&"（"&人数チェック!$E$9&"名）") | G3: =IF(設定!$I$14="","",設定!$I$14&"（"&人数チェック!$E$10&"名）") | I3: =IF(設定!$I$15="","",設定!$I$15&"（"&人数チェック!$E$11&"名）") | K3: =IF(設定!$I$16="","",設定!$I$16&"（"&人数チェック!$E$12&"名）") | M3: =IF(設定!$I$17="","",設定!$I$17&"（"&人数チェック!$E$13&"名）") | O3: =IF(設定!$I$18="","",設定!$I$18&"（"&人数チェック!$E$14&"名）") | Q3: =IF(設定!$I$19="","",設定!$I$19&"（"&人数チェック!$E$15&"名）") | S3: =IF(設定!$I$20="","",設定!$I$20&"（"&人数チェック!$E$16&"名）")
A4: =IF(設定!$I$11="","","担当："&設定!$J$11) | C4: =IF(設定!$I$12="","","担当："&設定!$J$12) | E4: =IF(設定!$I$13="","","担当："&設定!$J$13) | G4: =IF(設定!$I$14="","","担当："&設定!$J$14) | I4: =IF(設定!$I$15="","","担当："&設定!$J$15) | K4: =IF(設定!$I$16="","","担当："&設定!$J$16) | M4: =IF(設定!$I$17="","","担当："&設定!$J$17) | O4: =IF(設定!$I$18="","","担当："&設定!$J$18) | Q4: =IF(設定!$I$19="","","担当："&設定!$J$19) | S4: =IF(設定!$I$20="","","担当："&設定!$J$20)
A5: =IF(設定!$I$11="","","場所："&設定!$K$11) | C5: =IF(設定!$I$12="","","場所："&設定!$K$12) | E5: =IF(設定!$I$13="","","場所："&設定!$K$13) | G5: =IF(設定!$I$14="","","場所："&設定!$K$14) | I5: =IF(設定!$I$15="","","場所："&設定!$K$15) | K5: =IF(設定!$I$16="","","場所："&設定!$K$16) | M5: =IF(設定!$I$17="","","場所："&設定!$K$17) | O5: =IF(設定!$I$18="","","場所："&設定!$K$18) | Q5: =IF(設定!$I$19="","","場所："&設定!$K$19) | S5: =IF(設定!$I$20="","","場所："&設定!$K$20)
A6: 組 | B6: 名前 | C6: 組 | D6: 名前 | E6: 組 | F6: 名前 | G6: 組 | H6: 名前 | I6: 組 | J6: 名前 | K6: 組 | L6: 名前 | M6: 組 | N6: 名前 | O6: 組 | P6: 名前 | Q6: 組 | R6: 名前 | S6: 組 | T6: 名前
A7: =IF(計算用!$M$2="","",INDEX(計算用!$A$2:$A$721,計算用!$M$2)) | B7: =IF(計算用!$M$2="","",INDEX(計算用!$C$2:$C$721,計算用!$M$2)) | C7: =IF(計算用!$N$2="","",INDEX(計算用!$A$2:$A$721,計算用!$N$2)) | D7: =IF(計算用!$N$2="","",INDEX(計算用!$C$2:$C$721,計算用!$N$2)) | E7: =IF(計算用!$O$2="","",INDEX(計算用!$A$2:$A$721,計算用!$O$2)) | F7: =IF(計算用!$O$2="","",INDEX(計算用!$C$2:$C$721,計算用!$O$2)) | G7: =IF(計算用!$P$2="","",INDEX(計算用!$A$2:$A$721,計算用!$P$2)) | H7: =IF(計算用!$P$2="","",INDEX(計算用!$C$2:$C$721,計算用!$P$2)) | I7: =IF(計算用!$Q$2="","",INDEX(計算用!$A$2:$A$721,計算用!$Q$2)) | J7: =IF(計算用!$Q$2="","",INDEX(計算用!$C$2:$C$721,計算用!$Q$2)) | K7: =IF(計算用!$R$2="","",INDEX(計算用!$A$2:$A$721,計算用!$R$2)) | L7: =IF(計算用!$R$2="","",INDEX(計算用!$C$2:$C$721,計算用!$R$2)) | M7: =IF(計算用!$S$2="","",INDEX(計算用!$A$2:$A$721,計算用!$S$2)) | N7: =IF(計算用!$S$2="","",INDEX(計算用!$C$2:$C$721,計算用!$S$2)) | O7: =IF(計算用!$T$2="","",INDEX(計算用!$A$2:$A$721,計算用!$T$2)) | P7: =IF(計算用!$T$2="","",INDEX(計算用!$C$2:$C$721,計算用!$T$2)) | Q7: =IF(計算用!$U$2="","",INDEX(計算用!$A$2:$A$721,計算用!$U$2)) | R7: =IF(計算用!$U$2="","",INDEX(計算用!$C$2:$C$721,計算用!$U$2)) | S7: =IF(計算用!$V$2="","",INDEX(計算用!$A$2:$A$721,計算用!$V$2)) | T7: =IF(計算用!$V$2="","",INDEX(計算用!$C$2:$C$721,計算用!$V$2))
A8: =IF(計算用!$M$3="","",INDEX(計算用!$A$2:$A$721,計算用!$M$3)) | B8: =IF(計算用!$M$3="","",INDEX(計算用!$C$2:$C$721,計算用!$M$3)) | C8: =IF(計算用!$N$3="","",INDEX(計算用!$A$2:$A$721,計算用!$N$3)) | D8: =IF(計算用!$N$3="","",INDEX(計算用!$C$2:$C$721,計算用!$N$3)) | E8: =IF(計算用!$O$3="","",INDEX(計算用!$A$2:$A$721,計算用!$O$3)) | F8: =IF(計算用!$O$3="","",INDEX(計算用!$C$2:$C$721,計算用!$O$3)) | G8: =IF(計算用!$P$3="","",INDEX(計算用!$A$2:$A$721,計算用!$P$3)) | H8: =IF(計算用!$P$3="","",INDEX(計算用!$C$2:$C$721,計算用!$P$3)) | I8: =IF(計算用!$Q$3="","",INDEX(計算用!$A$2:$A$721,計算用!$Q$3)) | J8: =IF(計算用!$Q$3="","",INDEX(計算用!$C$2:$C$721,計算用!$Q$3)) | K8: =IF(計算用!$R$3="","",INDEX(計算用!$A$2:$A$721,計算用!$R$3)) | L8: =IF(計算用!$R$3="","",INDEX(計算用!$C$2:$C$721,計算用!$R$3)) | M8: =IF(計算用!$S$3="","",INDEX(計算用!$A$2:$A$721,計算用!$S$3)) | N8: =IF(計算用!$S$3="","",INDEX(計算用!$C$2:$C$721,計算用!$S$3)) | O8: =IF(計算用!$T$3="","",INDEX(計算用!$A$2:$A$721,計算用!$T$3)) | P8: =IF(計算用!$T$3="","",INDEX(計算用!$C$2:$C$721,計算用!$T$3)) | Q8: =IF(計算用!$U$3="","",INDEX(計算用!$A$2:$A$721,計算用!$U$3)) | R8: =IF(計算用!$U$3="","",INDEX(計算用!$C$2:$C$721,計算用!$U$3)) | S8: =IF(計算用!$V$3="","",INDEX(計算用!$A$2:$A$721,計算用!$V$3)) | T8: =IF(計算用!$V$3="","",INDEX(計算用!$C$2:$C$721,計算用!$V$3))
A9: =IF(計算用!$M$4="","",INDEX(計算用!$A$2:$A$721,計算用!$M$4)) | B9: =IF(計算用!$M$4="","",INDEX(計算用!$C$2:$C$721,計算用!$M$4)) | C9: =IF(計算用!$N$4="","",INDEX(計算用!$A$2:$A$721,計算用!$N$4)) | D9: =IF(計算用!$N$4="","",INDEX(計算用!$C$2:$C$721,計算用!$N$4)) | E9: =IF(計算用!$O$4="","",INDEX(計算用!$A$2:$A$721,計算用!$O$4)) | F9: =IF(計算用!$O$4="","",INDEX(計算用!$C$2:$C$721,計算用!$O$4)) | G9: =IF(計算用!$P$4="","",INDEX(計算用!$A$2:$A$721,計算用!$P$4)) | H9: =IF(計算用!$P$4="","",INDEX(計算用!$C$2:$C$721,計算用!$P$4)) | I9: =IF(計算用!$Q$4="","",INDEX(計算用!$A$2:$A$721,計算用!$Q$4)) | J9: =IF(計算用!$Q$4="","",INDEX(計算用!$C$2:$C$721,計算用!$Q$4)) | K9: =IF(計算用!$R$4="","",INDEX(計算用!$A$2:$A$721,計算用!$R$4)) | L9: =IF(計算用!$R$4="","",INDEX(計算用!$C$2:$C$721,計算用!$R$4)) | M9: =IF(計算用!$S$4="","",INDEX(計算用!$A$2:$A$721,計算用!$S$4)) | N9: =IF(計算用!$S$4="","",INDEX(計算用!$C$2:$C$721,計算用!$S$4)) | O9: =IF(計算用!$T$4="","",INDEX(計算用!$A$2:$A$721,計算用!$T$4)) | P9: =IF(計算用!$T$4="","",INDEX(計算用!$C$2:$C$721,計算用!$T$4)) | Q9: =IF(計算用!$U$4="","",INDEX(計算用!$A$2:$A$721,計算用!$U$4)) | R9: =IF(計算用!$U$4="","",INDEX(計算用!$C$2:$C$721,計算用!$U$4)) | S9: =IF(計算用!$V$4="","",INDEX(計算用!$A$2:$A$721,計算用!$V$4)) | T9: =IF(計算用!$V$4="","",INDEX(計算用!$C$2:$C$721,計算用!$V$4))
A10: =IF(計算用!$M$5="","",INDEX(計算用!$A$2:$A$721,計算用!$M$5)) | B10: =IF(計算用!$M$5="","",INDEX(計算用!$C$2:$C$721,計算用!$M$5)) | C10: =IF(計算用!$N$5="","",INDEX(計算用!$A$2:$A$721,計算用!$N$5)) | D10: =IF(計算用!$N$5="","",INDEX(計算用!$C$2:$C$721,計算用!$N$5)) | E10: =IF(計算用!$O$5="","",INDEX(計算用!$A$2:$A$721,計算用!$O$5)) | F10: =IF(計算用!$O$5="","",INDEX(計算用!$C$2:$C$721,計算用!$O$5)) | G10: =IF(計算用!$P$5="","",INDEX(計算用!$A$2:$A$721,計算用!$P$5)) | H10: =IF(計算用!$P$5="","",INDEX(計算用!$C$2:$C$721,計算用!$P$5)) | I10: =IF(計算用!$Q$5="","",INDEX(計算用!$A$2:$A$721,計算用!$Q$5)) | J10: =IF(計算用!$Q$5="","",INDEX(計算用!$C$2:$C$721,計算用!$Q$5)) | K10: =IF(計算用!$R$5="","",INDEX(計算用!$A$2:$A$721,計算用!$R$5)) | L10: =IF(計算用!$R$5="","",INDEX(計算用!$C$2:$C$721,計算用!$R$5)) | M10: =IF(計算用!$S$5="","",INDEX(計算用!$A$2:$A$721,計算用!$S$5)) | N10: =IF(計算用!$S$5="","",INDEX(計算用!$C$2:$C$721,計算用!$S$5)) | O10: =IF(計算用!$T$5="","",INDEX(計算用!$A$2:$A$721,計算用!$T$5)) | P10: =IF(計算用!$T$5="","",INDEX(計算用!$C$2:$C$721,計算用!$T$5)) | Q10: =IF(計算用!$U$5="","",INDEX(計算用!$A$2:$A$721,計算用!$U$5)) | R10: =IF(計算用!$U$5="","",INDEX(計算用!$C$2:$C$721,計算用!$U$5)) | S10: =IF(計算用!$V$5="","",INDEX(計算用!$A$2:$A$721,計算用!$V$5)) | T10: =IF(計算用!$V$5="","",INDEX(計算用!$C$2:$C$721,計算用!$V$5))
A11: =IF(計算用!$M$6="","",INDEX(計算用!$A$2:$A$721,計算用!$M$6)) | B11: =IF(計算用!$M$6="","",INDEX(計算用!$C$2:$C$721,計算用!$M$6)) | C11: =IF(計算用!$N$6="","",INDEX(計算用!$A$2:$A$721,計算用!$N$6)) | D11: =IF(計算用!$N$6="","",INDEX(計算用!$C$2:$C$721,計算用!$N$6)) | E11: =IF(計算用!$O$6="","",INDEX(計算用!$A$2:$A$721,計算用!$O$6)) | F11: =IF(計算用!$O$6="","",INDEX(計算用!$C$2:$C$721,計算用!$O$6)) | G11: =IF(計算用!$P$6="","",INDEX(計算用!$A$2:$A$721,計算用!$P$6)) | H11: =IF(計算用!$P$6="","",INDEX(計算用!$C$2:$C$721,計算用!$P$6)) | I11: =IF(計算用!$Q$6="","",INDEX(計算用!$A$2:$A$721,計算用!$Q$6)) | J11: =IF(計算用!$Q$6="","",INDEX(計算用!$C$2:$C$721,計算用!$Q$6)) | K11: =IF(計算用!$R$6="","",INDEX(計算用!$A$2:$A$721,計算用!$R$6)) | L11: =IF(計算用!$R$6="","",INDEX(計算用!$C$2:$C$721,計算用!$R$6)) | M11: =IF(計算用!$S$6="","",INDEX(計算用!$A$2:$A$721,計算用!$S$6)) | N11: =IF(計算用!$S$6="","",INDEX(計算用!$C$2:$C$721,計算用!$S$6)) | O11: =IF(計算用!$T$6="","",INDEX(計算用!$A$2:$A$721,計算用!$T$6)) | P11: =IF(計算用!$T$6="","",INDEX(計算用!$C$2:$C$721,計算用!$T$6)) | Q11: =IF(計算用!$U$6="","",INDEX(計算用!$A$2:$A$721,計算用!$U$6)) | R11: =IF(計算用!$U$6="","",INDEX(計算用!$C$2:$C$721,計算用!$U$6)) | S11: =IF(計算用!$V$6="","",INDEX(計算用!$A$2:$A$721,計算用!$V$6)) | T11: =IF(計算用!$V$6="","",INDEX(計算用!$C$2:$C$721,計算用!$V$6))
A12: =IF(計算用!$M$7="","",INDEX(計算用!$A$2:$A$721,計算用!$M$7)) | B12: =IF(計算用!$M$7="","",INDEX(計算用!$C$2:$C$721,計算用!$M$7)) | C12: =IF(計算用!$N$7="","",INDEX(計算用!$A$2:$A$721,計算用!$N$7)) | D12: =IF(計算用!$N$7="","",INDEX(計算用!$C$2:$C$721,計算用!$N$7)) | E12: =IF(計算用!$O$7="","",INDEX(計算用!$A$2:$A$721,計算用!$O$7)) | F12: =IF(計算用!$O$7="","",INDEX(計算用!$C$2:$C$721,計算用!$O$7)) | G12: =IF(計算用!$P$7="","",INDEX(計算用!$A$2:$A$721,計算用!$P$7)) | H12: =IF(計算用!$P$7="","",INDEX(計算用!$C$2:$C$721,計算用!$P$7)) | I12: =IF(計算用!$Q$7="","",INDEX(計算用!$A$2:$A$721,計算用!$Q$7)) | J12: =IF(計算用!$Q$7="","",INDEX(計算用!$C$2:$C$721,計算用!$Q$7)) | K12: =IF(計算用!$R$7="","",INDEX(計算用!$A$2:$A$721,計算用!$R$7)) | L12: =IF(計算用!$R$7="","",INDEX(計算用!$C$2:$C$721,計算用!$R$7)) | M12: =IF(計算用!$S$7="","",INDEX(計算用!$A$2:$A$721,計算用!$S$7)) | N12: =IF(計算用!$S$7="","",INDEX(計算用!$C$2:$C$721,計算用!$S$7)) | O12: =IF(計算用!$T$7="","",INDEX(計算用!$A$2:$A$721,計算用!$T$7)) | P12: =IF(計算用!$T$7="","",INDEX(計算用!$C$2:$C$721,計算用!$T$7)) | Q12: =IF(計算用!$U$7="","",INDEX(計算用!$A$2:$A$721,計算用!$U$7)) | R12: =IF(計算用!$U$7="","",INDEX(計算用!$C$2:$C$721,計算用!$U$7)) | S12: =IF(計算用!$V$7="","",INDEX(計算用!$A$2:$A$721,計算用!$V$7)) | T12: =IF(計算用!$V$7="","",INDEX(計算用!$C$2:$C$721,計算用!$V$7))
A13: =IF(計算用!$M$8="","",INDEX(計算用!$A$2:$A$721,計算用!$M$8)) | B13: =IF(計算用!$M$8="","",INDEX(計算用!$C$2:$C$721,計算用!$M$8)) | C13: =IF(計算用!$N$8="","",INDEX(計算用!$A$2:$A$721,計算用!$N$8)) | D13: =IF(計算用!$N$8="","",INDEX(計算用!$C$2:$C$721,計算用!$N$8)) | E13: =IF(計算用!$O$8="","",INDEX(計算用!$A$2:$A$721,計算用!$O$8)) | F13: =IF(計算用!$O$8="","",INDEX(計算用!$C$2:$C$721,計算用!$O$8)) | G13: =IF(計算用!$P$8="","",INDEX(計算用!$A$2:$A$721,計算用!$P$8)) | H13: =IF(計算用!$P$8="","",INDEX(計算用!$C$2:$C$721,計算用!$P$8)) | I13: =IF(計算用!$Q$8="","",INDEX(計算用!$A$2:$A$721,計算用!$Q$8)) | J13: =IF(計算用!$Q$8="","",INDEX(計算用!$C$2:$C$721,計算用!$Q$8)) | K13: =IF(計算用!$R$8="","",INDEX(計算用!$A$2:$A$721,計算用!$R$8)) | L13: =IF(計算用!$R$8="","",INDEX(計算用!$C$2:$C$721,計算用!$R$8)) | M13: =IF(計算用!$S$8="","",INDEX(計算用!$A$2:$A$721,計算用!$S$8)) | N13: =IF(計算用!$S$8="","",INDEX(計算用!$C$2:$C$721,計算用!$S$8)) | O13: =IF(計算用!$T$8="","",INDEX(計算用!$A$2:$A$721,計算用!$T$8)) | P13: =IF(計算用!$T$8="","",INDEX(計算用!$C$2:$C$721,計算用!$T$8)) | Q13: =IF(計算用!$U$8="","",INDEX(計算用!$A$2:$A$721,計算用!$U$8)) | R13: =IF(計算用!$U$8="","",INDEX(計算用!$C$2:$C$721,計算用!$U$8)) | S13: =IF(計算用!$V$8="","",INDEX(計算用!$A$2:$A$721,計算用!$V$8)) | T13: =IF(計算用!$V$8="","",INDEX(計算用!$C$2:$C$721,計算用!$V$8))
A14: =IF(計算用!$M$9="","",INDEX(計算用!$A$2:$A$721,計算用!$M$9)) | B14: =IF(計算用!$M$9="","",INDEX(計算用!$C$2:$C$721,計算用!$M$9)) | C14: =IF(計算用!$N$9="","",INDEX(計算用!$A$2:$A$721,計算用!$N$9)) | D14: =IF(計算用!$N$9="","",INDEX(計算用!$C$2:$C$721,計算用!$N$9)) | E14: =IF(計算用!$O$9="","",INDEX(計算用!$A$2:$A$721,計算用!$O$9)) | F14: =IF(計算用!$O$9="","",INDEX(計算用!$C$2:$C$721,計算用!$O$9)) | G14: =IF(計算用!$P$9="","",INDEX(計算用!$A$2:$A$721,計算用!$P$9)) | H14: =IF(計算用!$P$9="","",INDEX(計算用!$C$2:$C$721,計算用!$P$9)) | I14: =IF(計算用!$Q$9="","",INDEX(計算用!$A$2:$A$721,計算用!$Q$9)) | J14: =IF(計算用!$Q$9="","",INDEX(計算用!$C$2:$C$721,計算用!$Q$9)) | K14: =IF(計算用!$R$9="","",INDEX(計算用!$A$2:$A$721,計算用!$R$9)) | L14: =IF(計算用!$R$9="","",INDEX(計算用!$C$2:$C$721,計算用!$R$9)) | M14: =IF(計算用!$S$9="","",INDEX(計算用!$A$2:$A$721,計算用!$S$9)) | N14: =IF(計算用!$S$9="","",INDEX(計算用!$C$2:$C$721,計算用!$S$9)) | O14: =IF(計算用!$T$9="","",INDEX(計算用!$A$2:$A$721,計算用!$T$9)) | P14: =IF(計算用!$T$9="","",INDEX(計算用!$C$2:$C$721,計算用!$T$9)) | Q14: =IF(計算用!$U$9="","",INDEX(計算用!$A$2:$A$721,計算用!$U$9)) | R14: =IF(計算用!$U$9="","",INDEX(計算用!$C$2:$C$721,計算用!$U$9)) | S14: =IF(計算用!$V$9="","",INDEX(計算用!$A$2:$A$721,計算用!$V$9)) | T14: =IF(計算用!$V$9="","",INDEX(計算用!$C$2:$C$721,計算用!$V$9))
A15: =IF(計算用!$M$10="","",INDEX(計算用!$A$2:$A$721,計算用!$M$10)) | B15: =IF(計算用!$M$10="","",INDEX(計算用!$C$2:$C$721,計算用!$M$10)) | C15: =IF(計算用!$N$10="","",INDEX(計算用!$A$2:$A$721,計算用!$N$10)) | D15: =IF(計算用!$N$10="","",INDEX(計算用!$C$2:$C$721,計算用!$N$10)) | E15: =IF(計算用!$O$10="","",INDEX(計算用!$A$2:$A$721,計算用!$O$10)) | F15: =IF(計算用!$O$10="","",INDEX(計算用!$C$2:$C$721,計算用!$O$10)) | G15: =IF(計算用!$P$10="","",INDEX(計算用!$A$2:$A$721,計算用!$P$10)) | H15: =IF(計算用!$P$10="","",INDEX(計算用!$C$2:$C$721,計算用!$P$10)) | I15: =IF(計算用!$Q$10="","",INDEX(計算用!$A$2:$A$721,計算用!$Q$10)) | J15: =IF(計算用!$Q$10="","",INDEX(計算用!$C$2:$C$721,計算用!$Q$10)) | K15: =IF(計算用!$R$10="","",INDEX(計算用!$A$2:$A$721,計算用!$R$10)) | L15: =IF(計算用!$R$10="","",INDEX(計算用!$C$2:$C$721,計算用!$R$10)) | M15: =IF(計算用!$S$10="","",INDEX(計算用!$A$2:$A$721,計算用!$S$10)) | N15: =IF(計算用!$S$10="","",INDEX(計算用!$C$2:$C$721,計算用!$S$10)) | O15: =IF(計算用!$T$10="","",INDEX(計算用!$A$2:$A$721,計算用!$T$10)) | P15: =IF(計算用!$T$10="","",INDEX(計算用!$C$2:$C$721,計算用!$T$10)) | Q15: =IF(計算用!$U$10="","",INDEX(計算用!$A$2:$A$721,計算用!$U$10)) | R15: =IF(計算用!$U$10="","",INDEX(計算用!$C$2:$C$721,計算用!$U$10)) | S15: =IF(計算用!$V$10="","",INDEX(計算用!$A$2:$A$721,計算用!$V$10)) | T15: =IF(計算用!$V$10="","",INDEX(計算用!$C$2:$C$721,計算用!$V$10))
A16: =IF(計算用!$M$11="","",INDEX(計算用!$A$2:$A$721,計算用!$M$11)) | B16: =IF(計算用!$M$11="","",INDEX(計算用!$C$2:$C$721,計算用!$M$11)) | C16: =IF(計算用!$N$11="","",INDEX(計算用!$A$2:$A$721,計算用!$N$11)) | D16: =IF(計算用!$N$11="","",INDEX(計算用!$C$2:$C$721,計算用!$N$11)) | E16: =IF(計算用!$O$11="","",INDEX(計算用!$A$2:$A$721,計算用!$O$11)) | F16: =IF(計算用!$O$11="","",INDEX(計算用!$C$2:$C$721,計算用!$O$11)) | G16: =IF(計算用!$P$11="","",INDEX(計算用!$A$2:$A$721,計算用!$P$11)) | H16: =IF(計算用!$P$11="","",INDEX(計算用!$C$2:$C$721,計算用!$P$11)) | I16: =IF(計算用!$Q$11="","",INDEX(計算用!$A$2:$A$721,計算用!$Q$11)) | J16: =IF(計算用!$Q$11="","",INDEX(計算用!$C$2:$C$721,計算用!$Q$11)) | K16: =IF(計算用!$R$11="","",INDEX(計算用!$A$2:$A$721,計算用!$R$11)) | L16: =IF(計算用!$R$11="","",INDEX(計算用!$C$2:$C$721,計算用!$R$11)) | M16: =IF(計算用!$S$11="","",INDEX(計算用!$A$2:$A$721,計算用!$S$11)) | N16: =IF(計算用!$S$11="","",INDEX(計算用!$C$2:$C$721,計算用!$S$11)) | O16: =IF(計算用!$T$11="","",INDEX(計算用!$A$2:$A$721,計算用!$T$11)) | P16: =IF(計算用!$T$11="","",INDEX(計算用!$C$2:$C$721,計算用!$T$11)) | Q16: =IF(計算用!$U$11="","",INDEX(計算用!$A$2:$A$721,計算用!$U$11)) | R16: =IF(計算用!$U$11="","",INDEX(計算用!$C$2:$C$721,計算用!$U$11)) | S16: =IF(計算用!$V$11="","",INDEX(計算用!$A$2:$A$721,計算用!$V$11)) | T16: =IF(計算用!$V$11="","",INDEX(計算用!$C$2:$C$721,計算用!$V$11))
A17: =IF(計算用!$M$12="","",INDEX(計算用!$A$2:$A$721,計算用!$M$12)) | B17: =IF(計算用!$M$12="","",INDEX(計算用!$C$2:$C$721,計算用!$M$12)) | C17: =IF(計算用!$N$12="","",INDEX(計算用!$A$2:$A$721,計算用!$N$12)) | D17: =IF(計算用!$N$12="","",INDEX(計算用!$C$2:$C$721,計算用!$N$12)) | E17: =IF(計算用!$O$12="","",INDEX(計算用!$A$2:$A$721,計算用!$O$12)) | F17: =IF(計算用!$O$12="","",INDEX(計算用!$C$2:$C$721,計算用!$O$12)) | G17: =IF(計算用!$P$12="","",INDEX(計算用!$A$2:$A$721,計算用!$P$12)) | H17: =IF(計算用!$P$12="","",INDEX(計算用!$C$2:$C$721,計算用!$P$12)) | I17: =IF(計算用!$Q$12="","",INDEX(計算用!$A$2:$A$721,計算用!$Q$12)) | J17: =IF(計算用!$Q$12="","",INDEX(計算用!$C$2:$C$721,計算用!$Q$12)) | K17: =IF(計算用!$R$12="","",INDEX(計算用!$A$2:$A$721,計算用!$R$12)) | L17: =IF(計算用!$R$12="","",INDEX(計算用!$C$2:$C$721,計算用!$R$12)) | M17: =IF(計算用!$S$12="","",INDEX(計算用!$A$2:$A$721,計算用!$S$12)) | N17: =IF(計算用!$S$12="","",INDEX(計算用!$C$2:$C$721,計算用!$S$12)) | O17: =IF(計算用!$T$12="","",INDEX(計算用!$A$2:$A$721,計算用!$T$12)) | P17: =IF(計算用!$T$12="","",INDEX(計算用!$C$2:$C$721,計算用!$T$12)) | Q17: =IF(計算用!$U$12="","",INDEX(計算用!$A$2:$A$721,計算用!$U$12)) | R17: =IF(計算用!$U$12="","",INDEX(計算用!$C$2:$C$721,計算用!$U$12)) | S17: =IF(計算用!$V$12="","",INDEX(計算用!$A$2:$A$721,計算用!$V$12)) | T17: =IF(計算用!$V$12="","",INDEX(計算用!$C$2:$C$721,計算用!$V$12))
A18: =IF(計算用!$M$13="","",INDEX(計算用!$A$2:$A$721,計算用!$M$13)) | B18: =IF(計算用!$M$13="","",INDEX(計算用!$C$2:$C$721,計算用!$M$13)) | C18: =IF(計算用!$N$13="","",INDEX(計算用!$A$2:$A$721,計算用!$N$13)) | D18: =IF(計算用!$N$13="","",INDEX(計算用!$C$2:$C$721,計算用!$N$13)) | E18: =IF(計算用!$O$13="","",INDEX(計算用!$A$2:$A$721,計算用!$O$13)) | F18: =IF(計算用!$O$13="","",INDEX(計算用!$C$2:$C$721,計算用!$O$13)) | G18: =IF(計算用!$P$13="","",INDEX(計算用!$A$2:$A$721,計算用!$P$13)) | H18: =IF(計算用!$P$13="","",INDEX(計算用!$C$2:$C$721,計算用!$P$13)) | I18: =IF(計算用!$Q$13="","",INDEX(計算用!$A$2:$A$721,計算用!$Q$13)) | J18: =IF(計算用!$Q$13="","",INDEX(計算用!$C$2:$C$721,計算用!$Q$13)) | K18: =IF(計算用!$R$13="","",INDEX(計算用!$A$2:$A$721,計算用!$R$13)) | L18: =IF(計算用!$R$13="","",INDEX(計算用!$C$2:$C$721,計算用!$R$13)) | M18: =IF(計算用!$S$13="","",INDEX(計算用!$A$2:$A$721,計算用!$S$13)) | N18: =IF(計算用!$S$13="","",INDEX(計算用!$C$2:$C$721,計算用!$S$13)) | O18: =IF(計算用!$T$13="","",INDEX(計算用!$A$2:$A$721,計算用!$T$13)) | P18: =IF(計算用!$T$13="","",INDEX(計算用!$C$2:$C$721,計算用!$T$13)) | Q18: =IF(計算用!$U$13="","",INDEX(計算用!$A$2:$A$721,計算用!$U$13)) | R18: =IF(計算用!$U$13="","",INDEX(計算用!$C$2:$C$721,計算用!$U$13)) | S18: =IF(計算用!$V$13="","",INDEX(計算用!$A$2:$A$721,計算用!$V$13)) | T18: =IF(計算用!$V$13="","",INDEX(計算用!$C$2:$C$721,計算用!$V$13))
A19: =IF(計算用!$M$14="","",INDEX(計算用!$A$2:$A$721,計算用!$M$14)) | B19: =IF(計算用!$M$14="","",INDEX(計算用!$C$2:$C$721,計算用!$M$14)) | C19: =IF(計算用!$N$14="","",INDEX(計算用!$A$2:$A$721,計算用!$N$14)) | D19: =IF(計算用!$N$14="","",INDEX(計算用!$C$2:$C$721,計算用!$N$14)) | E19: =IF(計算用!$O$14="","",INDEX(計算用!$A$2:$A$721,計算用!$O$14)) | F19: =IF(計算用!$O$14="","",INDEX(計算用!$C$2:$C$721,計算用!$O$14)) | G19: =IF(計算用!$P$14="","",INDEX(計算用!$A$2:$A$721,計算用!$P$14)) | H19: =IF(計算用!$P$14="","",INDEX(計算用!$C$2:$C$721,計算用!$P$14)) | I19: =IF(計算用!$Q$14="","",INDEX(計算用!$A$2:$A$721,計算用!$Q$14)) | J19: =IF(計算用!$Q$14="","",INDEX(計算用!$C$2:$C$721,計算用!$Q$14)) | K19: =IF(計算用!$R$14="","",INDEX(計算用!$A$2:$A$721,計算用!$R$14)) | L19: =IF(計算用!$R$14="","",INDEX(計算用!$C$2:$C$721,計算用!$R$14)) | M19: =IF(計算用!$S$14="","",INDEX(計算用!$A$2:$A$721,計算用!$S$14)) | N19: =IF(計算用!$S$14="","",INDEX(計算用!$C$2:$C$721,計算用!$S$14)) | O19: =IF(計算用!$T$14="","",INDEX(計算用!$A$2:$A$721,計算用!$T$14)) | P19: =IF(計算用!$T$14="","",INDEX(計算用!$C$2:$C$721,計算用!$T$14)) | Q19: =IF(計算用!$U$14="","",INDEX(計算用!$A$2:$A$721,計算用!$U$14)) | R19: =IF(計算用!$U$14="","",INDEX(計算用!$C$2:$C$721,計算用!$U$14)) | S19: =IF(計算用!$V$14="","",INDEX(計算用!$A$2:$A$721,計算用!$V$14)) | T19: =IF(計算用!$V$14="","",INDEX(計算用!$C$2:$C$721,計算用!$V$14))
A20: =IF(計算用!$M$15="","",INDEX(計算用!$A$2:$A$721,計算用!$M$15)) | B20: =IF(計算用!$M$15="","",INDEX(計算用!$C$2:$C$721,計算用!$M$15)) | C20: =IF(計算用!$N$15="","",INDEX(計算用!$A$2:$A$721,計算用!$N$15)) | D20: =IF(計算用!$N$15="","",INDEX(計算用!$C$2:$C$721,計算用!$N$15)) | E20: =IF(計算用!$O$15="","",INDEX(計算用!$A$2:$A$721,計算用!$O$15)) | F20: =IF(計算用!$O$15="","",INDEX(計算用!$C$2:$C$721,計算用!$O$15)) | G20: =IF(計算用!$P$15="","",INDEX(計算用!$A$2:$A$721,計算用!$P$15)) | H20: =IF(計算用!$P$15="","",INDEX(計算用!$C$2:$C$721,計算用!$P$15)) | I20: =IF(計算用!$Q$15="","",INDEX(計算用!$A$2:$A$721,計算用!$Q$15)) | J20: =IF(計算用!$Q$15="","",INDEX(計算用!$C$2:$C$721,計算用!$Q$15)) | K20: =IF(計算用!$R$15="","",INDEX(計算用!$A$2:$A$721,計算用!$R$15)) | L20: =IF(計算用!$R$15="","",INDEX(計算用!$C$2:$C$721,計算用!$R$15)) | M20: =IF(計算用!$S$15="","",INDEX(計算用!$A$2:$A$721,計算用!$S$15)) | N20: =IF(計算用!$S$15="","",INDEX(計算用!$C$2:$C$721,計算用!$S$15)) | O20: =IF(計算用!$T$15="","",INDEX(計算用!$A$2:$A$721,計算用!$T$15)) | P20: =IF(計算用!$T$15="","",INDEX(計算用!$C$2:$C$721,計算用!$T$15)) | Q20: =IF(計算用!$U$15="","",INDEX(計算用!$A$2:$A$721,計算用!$U$15)) | R20: =IF(計算用!$U$15="","",INDEX(計算用!$C$2:$C$721,計算用!$U$15)) | S20: =IF(計算用!$V$15="","",INDEX(計算用!$A$2:$A$721,計算用!$V$15)) | T20: =IF(計算用!$V$15="","",INDEX(計算用!$C$2:$C$721,計算用!$V$15))
A21: =IF(計算用!$M$16="","",INDEX(計算用!$A$2:$A$721,計算用!$M$16)) | B21: =IF(計算用!$M$16="","",INDEX(計算用!$C$2:$C$721,計算用!$M$16)) | C21: =IF(計算用!$N$16="","",INDEX(計算用!$A$2:$A$721,計算用!$N$16)) | D21: =IF(計算用!$N$16="","",INDEX(計算用!$C$2:$C$721,計算用!$N$16)) | E21: =IF(計算用!$O$16="","",INDEX(計算用!$A$2:$A$721,計算用!$O$16)) | F21: =IF(計算用!$O$16="","",INDEX(計算用!$C$2:$C$721,計算用!$O$16)) | G21: =IF(計算用!$P$16="","",INDEX(計算用!$A$2:$A$721,計算用!$P$16)) | H21: =IF(計算用!$P$16="","",INDEX(計算用!$C$2:$C$721,計算用!$P$16)) | I21: =IF(計算用!$Q$16="","",INDEX(計算用!$A$2:$A$721,計算用!$Q$16)) | J21: =IF(計算用!$Q$16="","",INDEX(計算用!$C$2:$C$721,計算用!$Q$16)) | K21: =IF(計算用!$R$16="","",INDEX(計算用!$A$2:$A$721,計算用!$R$16)) | L21: =IF(計算用!$R$16="","",INDEX(計算用!$C$2:$C$721,計算用!$R$16)) | M21: =IF(計算用!$S$16="","",INDEX(計算用!$A$2:$A$721,計算用!$S$16)) | N21: =IF(計算用!$S$16="","",INDEX(計算用!$C$2:$C$721,計算用!$S$16)) | O21: =IF(計算用!$T$16="","",INDEX(計算用!$A$2:$A$721,計算用!$T$16)) | P21: =IF(計算用!$T$16="","",INDEX(計算用!$C$2:$C$721,計算用!$T$16)) | Q21: =IF(計算用!$U$16="","",INDEX(計算用!$A$2:$A$721,計算用!$U$16)) | R21: =IF(計算用!$U$16="","",INDEX(計算用!$C$2:$C$721,計算用!$U$16)) | S21: =IF(計算用!$V$16="","",INDEX(計算用!$A$2:$A$721,計算用!$V$16)) | T21: =IF(計算用!$V$16="","",INDEX(計算用!$C$2:$C$721,計算用!$V$16))
A22: =IF(計算用!$M$17="","",INDEX(計算用!$A$2:$A$721,計算用!$M$17)) | B22: =IF(計算用!$M$17="","",INDEX(計算用!$C$2:$C$721,計算用!$M$17)) | C22: =IF(計算用!$N$17="","",INDEX(計算用!$A$2:$A$721,計算用!$N$17)) | D22: =IF(計算用!$N$17="","",INDEX(計算用!$C$2:$C$721,計算用!$N$17)) | E22: =IF(計算用!$O$17="","",INDEX(計算用!$A$2:$A$721,計算用!$O$17)) | F22: =IF(計算用!$O$17="","",INDEX(計算用!$C$2:$C$721,計算用!$O$17)) | G22: =IF(計算用!$P$17="","",INDEX(計算用!$A$2:$A$721,計算用!$P$17)) | H22: =IF(計算用!$P$17="","",INDEX(計算用!$C$2:$C$721,計算用!$P$17)) | I22: =IF(計算用!$Q$17="","",INDEX(計算用!$A$2:$A$721,計算用!$Q$17)) | J22: =IF(計算用!$Q$17="","",INDEX(計算用!$C$2:$C$721,計算用!$Q$17)) | K22: =IF(計算用!$R$17="","",INDEX(計算用!$A$2:$A$721,計算用!$R$17)) | L22: =IF(計算用!$R$17="","",INDEX(計算用!$C$2:$C$721,計算用!$R$17)) | M22: =IF(計算用!$S$17="","",INDEX(計算用!$A$2:$A$721,計算用!$S$17)) | N22: =IF(計算用!$S$17="","",INDEX(計算用!$C$2:$C$721,計算用!$S$17)) | O22: =IF(計算用!$T$17="","",INDEX(計算用!$A$2:$A$721,計算用!$T$17)) | P22: =IF(計算用!$T$17="","",INDEX(計算用!$C$2:$C$721,計算用!$T$17)) | Q22: =IF(計算用!$U$17="","",INDEX(計算用!$A$2:$A$721,計算用!$U$17)) | R22: =IF(計算用!$U$17="","",INDEX(計算用!$C$2:$C$721,計算用!$U$17)) | S22: =IF(計算用!$V$17="","",INDEX(計算用!$A$2:$A$721,計算用!$V$17)) | T22: =IF(計算用!$V$17="","",INDEX(計算用!$C$2:$C$721,計算用!$V$17))
A23: =IF(計算用!$M$18="","",INDEX(計算用!$A$2:$A$721,計算用!$M$18)) | B23: =IF(計算用!$M$18="","",INDEX(計算用!$C$2:$C$721,計算用!$M$18)) | C23: =IF(計算用!$N$18="","",INDEX(計算用!$A$2:$A$721,計算用!$N$18)) | D23: =IF(計算用!$N$18="","",INDEX(計算用!$C$2:$C$721,計算用!$N$18)) | E23: =IF(計算用!$O$18="","",INDEX(計算用!$A$2:$A$721,計算用!$O$18)) | F23: =IF(計算用!$O$18="","",INDEX(計算用!$C$2:$C$721,計算用!$O$18)) | G23: =IF(計算用!$P$18="","",INDEX(計算用!$A$2:$A$721,計算用!$P$18)) | H23: =IF(計算用!$P$18="","",INDEX(計算用!$C$2:$C$721,計算用!$P$18)) | I23: =IF(計算用!$Q$18="","",INDEX(計算用!$A$2:$A$721,計算用!$Q$18)) | J23: =IF(計算用!$Q$18="","",INDEX(計算用!$C$2:$C$721,計算用!$Q$18)) | K23: =IF(計算用!$R$18="","",INDEX(計算用!$A$2:$A$721,計算用!$R$18)) | L23: =IF(計算用!$R$18="","",INDEX(計算用!$C$2:$C$721,計算用!$R$18)) | M23: =IF(計算用!$S$18="","",INDEX(計算用!$A$2:$A$721,計算用!$S$18)) | N23: =IF(計算用!$S$18="","",INDEX(計算用!$C$2:$C$721,計算用!$S$18)) | O23: =IF(計算用!$T$18="","",INDEX(計算用!$A$2:$A$721,計算用!$T$18)) | P23: =IF(計算用!$T$18="","",INDEX(計算用!$C$2:$C$721,計算用!$T$18)) | Q23: =IF(計算用!$U$18="","",INDEX(計算用!$A$2:$A$721,計算用!$U$18)) | R23: =IF(計算用!$U$18="","",INDEX(計算用!$C$2:$C$721,計算用!$U$18)) | S23: =IF(計算用!$V$18="","",INDEX(計算用!$A$2:$A$721,計算用!$V$18)) | T23: =IF(計算用!$V$18="","",INDEX(計算用!$C$2:$C$721,計算用!$V$18))
A24: =IF(計算用!$M$19="","",INDEX(計算用!$A$2:$A$721,計算用!$M$19)) | B24: =IF(計算用!$M$19="","",INDEX(計算用!$C$2:$C$721,計算用!$M$19)) | C24: =IF(計算用!$N$19="","",INDEX(計算用!$A$2:$A$721,計算用!$N$19)) | D24: =IF(計算用!$N$19="","",INDEX(計算用!$C$2:$C$721,計算用!$N$19)) | E24: =IF(計算用!$O$19="","",INDEX(計算用!$A$2:$A$721,計算用!$O$19)) | F24: =IF(計算用!$O$19="","",INDEX(計算用!$C$2:$C$721,計算用!$O$19)) | G24: =IF(計算用!$P$19="","",INDEX(計算用!$A$2:$A$721,計算用!$P$19)) | H24: =IF(計算用!$P$19="","",INDEX(計算用!$C$2:$C$721,計算用!$P$19)) | I24: =IF(計算用!$Q$19="","",INDEX(計算用!$A$2:$A$721,計算用!$Q$19)) | J24: =IF(計算用!$Q$19="","",INDEX(計算用!$C$2:$C$721,計算用!$Q$19)) | K24: =IF(計算用!$R$19="","",INDEX(計算用!$A$2:$A$721,計算用!$R$19)) | L24: =IF(計算用!$R$19="","",INDEX(計算用!$C$2:$C$721,計算用!$R$19)) | M24: =IF(計算用!$S$19="","",INDEX(計算用!$A$2:$A$721,計算用!$S$19)) | N24: =IF(計算用!$S$19="","",INDEX(計算用!$C$2:$C$721,計算用!$S$19)) | O24: =IF(計算用!$T$19="","",INDEX(計算用!$A$2:$A$721,計算用!$T$19)) | P24: =IF(計算用!$T$19="","",INDEX(計算用!$C$2:$C$721,計算用!$T$19)) | Q24: =IF(計算用!$U$19="","",INDEX(計算用!$A$2:$A$721,計算用!$U$19)) | R24: =IF(計算用!$U$19="","",INDEX(計算用!$C$2:$C$721,計算用!$U$19)) | S24: =IF(計算用!$V$19="","",INDEX(計算用!$A$2:$A$721,計算用!$V$19)) | T24: =IF(計算用!$V$19="","",INDEX(計算用!$C$2:$C$721,計算用!$V$19))
